Workbook

Sheet Budget Summary
A1: PARTNERS OF THE AMERICAS
A2: SUMMARY BUDGET FOR MEXICO MIGRATION MESSAGING
B3: Year 1 | E3: Year 2 | H3: Total
A4: BUDGET SUMMARY CATEGORIES | B4: Grant | C4: Cost Share | D4: Total | E4: Grant | F4: Cost Share | G4: Total | H4: Grant | I4: Cost Share | J4: Total
A5: A. Personnel | B5: ='Line Item Budget'!K19 -> 80210 | C5: ='Line Item Budget'!L19 -> 0 | D5: =B5+C5 -> 80210 | E5: ='Line Item Budget'!Q19 -> 83418.4 | F5: ='Line Item Budget'!R19 -> 0 | G5: =E5+F5 -> 83418.4 | H5: =E5+B5 -> 163628.4 | I5: =F5+C5 -> 0 | J5: =I5+H5 -> 163628.4
A6: B. Fringe Benefits | B6: ='Line Item Budget'!K25 -> 27988.691 | C6: ='Line Item Budget'!L25 -> 0 | D6: =B6+C6 -> 27988.691 | E6: ='Line Item Budget'!Q25 -> 29108.239 | F6: ='Line Item Budget'!R25 -> 0 | G6: =E6+F6 -> 29108.239 | H6: =E6+B6 -> 57096.93 | I6: =F6+C6 -> 0 | J6: =I6+H6 -> 57096.93
A7: C. Travel | B7: ='Line Item Budget'!K37 -> 7135 | C7: ='Line Item Budget'!L37 -> 0 | D7: =B7+C7 -> 7135 | E7: ='Line Item Budget'!Q37 -> 7420.4 | F7: ='Line Item Budget'!R37 -> 0 | G7: =E7+F7 -> 7420.4 | H7: =E7+B7 -> 14555.4 | I7: =F7+C7 -> 0 | J7: =I7+H7 -> 14555.4
A8: D. Equipment
A9: E. Supplies | B9: ='Line Item Budget'!K42 -> 3600 | C9: ='Line Item Budget'!L42 -> 0 | D9: =B9+C9 -> 3600 | E9: ='Line Item Budget'!Q42 -> 624 | F9: ='Line Item Budget'!R42 -> 0 | G9: =E9+F9 -> 624 | H9: =E9+B9 -> 4224 | I9: =F9+C9 -> 0 | J9: =I9+H9 -> 4224
A10: F. Contractual and Subawards | B10: ='Line Item Budget'!K52 -> 115900 | C10: ='Line Item Budget'!L52 -> 0 | D10: =B10+C10 -> 115900 | E10: ='Line Item Budget'!Q52 -> 70900 | F10: ='Line Item Budget'!R52 -> 0 | G10: =E10+F10 -> 70900 | H10: =E10+B10 -> 186800 | I10: =F10+C10 -> 0 | J10: =I10+H10 -> 186800
A11: G. Construction
A12: H. Other Direct Costs | B12: ='Line Item Budget'!K74 -> 39031 | C12: ='Line Item Budget'!L74 -> 0 | D12: =B12+C12 -> 39031 | E12: ='Line Item Budget'!Q74 -> 34352.24 | F12: ='Line Item Budget'!R74 -> 0 | G12: =E12+F12 -> 34352.24 | H12: =E12+B12 -> 73383.24 | I12: =F12+C12 -> 0 | J12: =I12+H12 -> 73383.24
A13: I. Total Direct Costs | B13: ='Line Item Budget'!K75 -> 273864.69 | C13: ='Line Item Budget'!L75 -> 0 | D13: =B13+C13 -> 273864.69 | E13: ='Line Item Budget'!Q75 -> 225823.28 | F13: ='Line Item Budget'!R75 -> 0 | G13: =E13+F13 -> 225823.28 | H13: =E13+B13 -> 499687.97 | I13: =F13+C13 -> 0 | J13: =I13+H13 -> 499687.97
A14: J. Indirect Costs | B14: ='Line Item Budget'!K77 -> 77448.935 | C14: ='Line Item Budget'!L77 -> 0 | D14: =B14+C14 -> 77448.935 | E14: ='Line Item Budget'!Q77 -> 63862.823 | F14: ='Line Item Budget'!R77 -> 0 | G14: =E14+F14 -> 63862.823 | H14: =E14+B14 -> 141311.76 | I14: =F14+C14 -> 0 | J14: =I14+H14 -> 141311.76
A15: K. Total Costs | B15: =B13+B14 -> 351313.63 | C15: =C13+C14 -> 0 | D15: =D13+D14 -> 351313.63 | E15: =E13+E14 -> 289686.1 | F15: =F13+F14 -> 0 | G15: =G13+G14 -> 289686.1 | H15: =E15+B15 -> 640999.73 | I15: =F15+C15 -> 0 | J15: =I15+H15 -> 640999.73

Sheet Line Item Budget
D1: PARTNERS OF THE AMERICAS - MEXICO MIGRATION MESSAGING BUDGET
A2: Entity: | B2: P | D2: Merit and Cost of Living Increases - 4% | E2: 1.04
A3: Program/Dept.: | B3: 20200 | D3: Inflation - 4% | E3: 1.04
A4: Funder-Grant: | B4: DOS453 | D4: *Key Personnel
A5: Budget Code | B5: Account Code | C5: Country Code | D5: All costs in US$ | E5: Year 1 | M5: Year 2 | S5: Total
D6: Budget Line Items | E6: No. | F6: Unit Type | G6: Freq. | H6: % | I6: Rate | J6: Total | K6: Federal | L6: Cost Share | M6: No. | N6: Freq. | O6: Rate | P6: Total | Q6: Federal | R6: Cost Share | S6: Federal | T6: Cost Share | U6: Grand Total
D7: A. Personnel
D8: A.1 Field Staff Salaries
A9: PERSNL-CDM | B9: 70000 | C9: MEX | D9: A.1.1 Country Director Mexico (5%) | E9: 1 | F9: Month | G9: 12 | H9: 0.05 | I9: 13450 | J9: =E9*I9*G9*H9 -> 8070 | K9: =J9 -> 8070 | L9: =J9-K9 -> 0 | M9: =E9 -> 1 | N9: 12 | O9: =I9*$E$2 -> 13988 | P9: =M9*O9*N9*H9 -> 8392.8 | Q9: =P9 -> 8392.8 | R9: =P9-Q9 -> 0 | S9: =K9+Q9 -> 16462.8 | T9: =L9+R9 -> 0 | U9: =S9+T9 -> 16462.8
A10: PERSNL-PD | B10: 70000 | C10: MEX | D10: A.1.2 Program Director (10%)* | E10: 1 | F10: Month | G10: 12 | H10: 0.1 | I10: 8650 | J10: =E10*I10*G10*H10 -> 10380 | K10: =J10 -> 10380 | L10: =J10-K10 -> 0 | M10: =E10 -> 1 | N10: 12 | O10: =I10*$E$2 -> 8996 | P10: =M10*O10*N10*H10 -> 10795.2 | Q10: =P10 -> 10795.2 | R10: =P10-Q10 -> 0 | S10: =K10+Q10 -> 21175.2 | T10: =L10+R10 -> 0 | U10: =S10+T10 -> 21175.2
A11: PERSNL-SCS | B11: 70000 | C11: MEX | D11: A.1.3 Senior Communications Specialist (30%) | E11: 1 | F11: Month | G11: 12 | H11: 0.3 | I11: 4100 | J11: =E11*I11*G11*H11 -> 14760 | K11: =J11 -> 14760 | L11: =J11-K11 -> 0 | M11: =E11 -> 1 | N11: 12 | O11: =I11*$E$2 -> 4264 | P11: =M11*O11*N11*H11 -> 15350.4 | Q11: =P11 -> 15350.4 | R11: =P11-Q11 -> 0 | S11: =K11+Q11 -> 30110.4 | T11: =L11+R11 -> 0 | U11: =S11+T11 -> 30110.4
A12: PERSNL-COM | B12: 70000 | C12: MEX | D12: A.1.4 Communications Specialist (30%) | E12: 1 | F12: Month | G12: 12 | H12: 0.3 | I12: 3000 | J12: =E12*I12*G12*H12 -> 10800 | K12: =J12 -> 10800 | L12: =J12-K12 -> 0 | M12: =E12 -> 1 | N12: 12 | O12: =I12*$E$2 -> 3120 | P12: =M12*O12*N12*H12 -> 11232 | Q12: =P12 -> 11232 | R12: =P12-Q12 -> 0 | S12: =K12+Q12 -> 22032 | T12: =L12+R12 -> 0 | U12: =S12+T12 -> 22032
A13: PERSNL-SMA | B13: 70000 | C13: MEX | D13: A.1.5 Social Media Analyst (30%)* | E13: 1 | F13: Month | G13: 12 | H13: 0.3 | I13: 2100 | J13: =E13*I13*G13*H13 -> 7560 | K13: =J13 -> 7560 | L13: =J13-K13 -> 0 | M13: =E13 -> 1 | N13: 12 | O13: =I13*$E$2 -> 2184 | P13: =M13*O13*N13*H13 -> 7862.4 | Q13: =P13 -> 7862.4 | R13: =P13-Q13 -> 0 | S13: =K13+Q13 -> 15422.4 | T13: =L13+R13 -> 0 | U13: =S13+T13 -> 15422.4
A14: PERSNL-M&E | B14: 70000 | C14: MEX | D14: A.1.6 Monitoring, Evaluation, and Learning Officer (25%) | E14: 1 | F14: Month | G14: 12 | H14: 0.25 | I14: 3100 | J14: =E14*I14*G14*H14 -> 9300 | K14: =J14 -> 9300 | L14: =J14-K14 -> 0 | M14: =E14 -> 1 | N14: 12 | O14: =I14*$E$2 -> 3224 | P14: =M14*O14*N14*H14 -> 9672 | Q14: =P14 -> 9672 | R14: =P14-Q14 -> 0 | S14: =K14+Q14 -> 18972 | T14: =L14+R14 -> 0 | U14: =S14+T14 -> 18972
A15: PERSNL-F&A | B15: 70000 | C15: MEX | D15: A.1.7 Finance & Administration Director (5%) | E15: 1 | F15: Month | G15: 12 | H15: 0.05 | I15: 5500 | J15: =E15*I15*G15*H15 -> 3300 | K15: =J15 -> 3300 | L15: =J15-K15 -> 0 | M15: =E15 -> 1 | N15: 12 | O15: =I15*$E$2 -> 5720 | P15: =M15*O15*N15*H15 -> 3432 | Q15: =P15 -> 3432 | R15: =P15-Q15 -> 0 | S15: =K15+Q15 -> 6732 | T15: =L15+R15 -> 0 | U15: =S15+T15 -> 6732
A16: PERSNL-F&A | B16: 70000 | C16: MEX | D16: A.1.8 Finance & Administration Officer (20%) | E16: 1 | F16: Month | G16: 12 | H16: 0.2 | I16: 2100 | J16: =E16*I16*G16*H16 -> 5040 | K16: =J16 -> 5040 | L16: =J16-K16 -> 0 | M16: =E16 -> 1 | N16: 12 | O16: =I16*$E$2 -> 2184 | P16: =M16*O16*N16*H16 -> 5241.6 | Q16: =P16 -> 5241.6 | R16: =P16-Q16 -> 0 | S16: =K16+Q16 -> 10281.6 | T16: =L16+R16 -> 0 | U16: =S16+T16 -> 10281.6
B17: 70000 | C17: MEX | D17: A.2 HQ Staff Salaries
A18: PERSNL | B18: 50000 | C18: USA | D18: A.2.1 Program Manager (HQ) (20%) | E18: 1 | F18: Month | G18: 12 | H18: 0.2 | I18: =55000/12 -> 4583.3333 | J18: =E18*I18*G18*H18 -> 11000 | K18: =J18 -> 11000 | L18: =J18-K18 -> 0 | M18: 1 | N18: =G18 -> 12 | O18: =I18*$E$2 -> 4766.6667 | P18: =M18*O18*N18*H18 -> 11440 | Q18: =P18 -> 11440 | R18: =P18-Q18 -> 0 | S18: =K18+Q18 -> 22440 | T18: =L18+R18 -> 0 | U18: =S18+T18 -> 22440
D19: Subtotal Personnel | J19: =SUM(J9:J18) -> 80210 | K19: =SUM(K9:K18) -> 80210 | L19: =SUM(L9:L18) -> 0 | P19: =SUM(P9:P18) -> 83418.4 | Q19: =SUM(Q9:Q18) -> 83418.4 | R19: =SUM(R9:R18) -> 0 | S19: =SUM(S9:S18) -> 163628.4 | T19: =SUM(T9:T18) -> 0 | U19: =SUM(U9:U18) -> 163628.4
D20: B. Fringe Benefits
D21: B.1 HQ Fringe Benefits
A22: FRINGE | B22: 50900 | C22: USA | D22: B.1.1 U.S.-Based Personnel Fringe Benefits | F22: % | H22: 0.2347 | J22: =J18*H22 -> 2581.7 | K22: =J22 -> 2581.7 | L22: 0 | O22: =O18 -> 4766.6667 | P22: =P18*H22 -> 2684.968 | Q22: =P22 -> 2684.968 | R22: =P22-Q22 -> 0 | S22: =K22+Q22 -> 5266.668 | T22: =L22+R22 -> 0 | U22: =S22+T22 -> 5266.668
D23: B.2 Field Fringe Benefits
A24: FRINGE-MX | B24: 70015 | C24: MEX | D24: B.2.1 Mexico Field Staff Fringe Benefits | F24: % | H24: 0.3671 | J24: =(SUM(J9:J16))*$H$24 -> 25406.991 | K24: =J24 -> 25406.991 | L24: 0 | O24: =O10 -> 8996 | P24: =(SUM(P9:P16))*$H$24 -> 26423.271 | Q24: =P24 -> 26423.271 | R24: =P24-Q24 -> 0 | S24: =K24+Q24 -> 51830.262 | T24: =L24+R24 -> 0 | U24: =S24+T24 -> 51830.262
D25: Subtotal Fringe Benefits | J25: =SUM(J22:J24) -> 27988.691 | K25: =SUM(K22:K24) -> 27988.691 | L25: =SUM(L22:L24) -> 0 | P25: =SUM(P22:P24) -> 29108.239 | Q25: =SUM(Q22:Q24) -> 29108.239 | R25: =SUM(R22:R24) -> 0 | S25: =SUM(S22:S24) -> 57096.93 | T25: =SUM(T22:T24) -> 0 | U25: =SUM(U22:U24) -> 57096.93
D26: C. Travel
D27: C.1 HQ Staff International Travel
A28: STFTRAVEL | B28: 86040 | C28: USA | D28: C.1.1 International Airfare (DC-MX) | E28: 1 | F28: Flight | G28: 1 | H28: 1 | I28: 700 | J28: =E28*I28*G28 -> 700 | K28: =J28 -> 700 | L28: =J28-K28 -> 0 | M28: 1 | N28: 1 | O28: =I28*$E$3 -> 728 | P28: =M28*O28*N28*H28 -> 728 | Q28: =P28 -> 728 | R28: =P28-Q28 -> 0 | S28: =K28+Q28 -> 1428 | T28: =L28+R28 -> 0 | U28: =S28+T28 -> 1428
A29: GROUNDTRAN | B29: 86000 | C29: USA | D29: C.1.2 Ground Transportation | E29: 1 | F29: Trip | G29: 1 | H29: 1 | I29: 100 | J29: =E29*I29*G29 -> 100 | K29: =J29 -> 100 | L29: =J29-K29 -> 0 | M29: 1 | N29: 1 | O29: =I29*$E$3 -> 104 | P29: =M29*O29*N29*H29 -> 104 | Q29: =P29 -> 104 | R29: =P29-Q29 -> 0 | S29: =K29+Q29 -> 204 | T29: =L29+R29 -> 0 | U29: =S29+T29 -> 204
A30: LODGING | B30: 86030 | C30: USA | D30: C.1.3 Lodging | E30: 1 | F30: Night | G30: 4 | H30: 1 | I30: 120 | J30: =E30*I30*G30 -> 480 | K30: =J30 -> 480 | L30: =J30-K30 -> 0 | M30: 1 | N30: 4 | O30: =I30*$E$3 -> 124.8 | P30: =M30*O30*N30*H30 -> 499.2 | Q30: =P30 -> 499.2 | R30: =P30-Q30 -> 0 | S30: =K30+Q30 -> 979.2 | T30: =L30+R30 -> 0 | U30: =S30+T30 -> 979.2
A31: STFCN DIEM | B31: 86050 | C31: USA | D31: C.1.4 M&IE | E31: 1 | F31: Day | G31: 5 | H31: 1 | I31: 95 | J31: =E31*I31*G31 -> 475 | K31: =J31 -> 475 | L31: =J31-K31 -> 0 | M31: 1 | N31: 5 | O31: =I31*$E$3 -> 98.8 | P31: =M31*O31*N31*H31 -> 494 | Q31: =P31 -> 494 | R31: =P31-Q31 -> 0 | S31: =K31+Q31 -> 969 | T31: =L31+R31 -> 0 | U31: =S31+T31 -> 969
D32: C.2 Local Staff In-Country Travel to Target Geographic Regions
A33: LSLODGING | B33: 86030 | C33: MEX | D33: C.2.1 Domestic Airfare | E33: 2 | F33: Flight | G33: 1 | H33: 1 | I33: 200 | J33: =E33*I33*G33 -> 400 | K33: =J33 -> 400 | L33: =J33-K33 -> 0 | M33: 2 | N33: 1 | O33: =I33*$E$3 -> 208 | P33: =M33*O33*N33*H33 -> 416 | Q33: =P33 -> 416 | R33: =P33-Q33 -> 0 | S33: =K33+Q33 -> 816 | T33: =L33+R33 -> 0 | U33: =S33+T33 -> 816
A34: LSM&IE | B34: 86050 | C34: MEX | D34: C.2.2 Lodging | E34: 6 | F34: Night | G34: 3 | H34: 1 | I34: 100 | J34: =E34*I34*G34 -> 1800 | K34: =J34 -> 1800 | L34: =J34-K34 -> 0 | M34: 6 | N34: 3 | O34: =I34*$E$3 -> 104 | P34: =M34*O34*N34*H34 -> 1872 | Q34: =P34 -> 1872 | R34: =P34-Q34 -> 0 | S34: =K34+Q34 -> 3672 | T34: =L34+R34 -> 0 | U34: =S34+T34 -> 3672
A35: LSTRANS | B35: 86000 | C35: MEX | D35: C.2.3 M&IE | E35: 6 | F35: Day | G35: 4 | H35: 1 | I35: 70 | J35: =E35*I35*G35 -> 1680 | K35: =J35 -> 1680 | L35: =J35-K35 -> 0 | M35: 6 | N35: 4 | O35: =I35*$E$3 -> 72.8 | P35: =M35*O35*N35*H35 -> 1747.2 | Q35: =P35 -> 1747.2 | R35: =P35-Q35 -> 0 | S35: =K35+Q35 -> 3427.2 | T35: =L35+R35 -> 0 | U35: =S35+T35 -> 3427.2
A36: LSDOMAIR | B36: 86040 | C36: MEX | D36: C.2.4 Ground Transportation | E36: 1 | F36: Month | G36: 10 | H36: 1 | I36: 150 | J36: =E36*I36*G36 -> 1500 | K36: =J36 -> 1500 | L36: =J36-K36 -> 0 | M36: 1 | N36: 10 | O36: =I36*$E$3 -> 156 | P36: =M36*O36*N36*H36 -> 1560 | Q36: =P36 -> 1560 | R36: =P36-Q36 -> 0 | S36: =K36+Q36 -> 3060 | T36: =L36+R36 -> 0 | U36: =S36+T36 -> 3060
D37: Subtotal Travel | J37: =SUM(J28:J36) -> 7135 | K37: =SUM(K28:K36) -> 7135 | L37: =SUM(L28:L36) -> 0 | P37: =SUM(P28:P36) -> 7420.4 | Q37: =SUM(Q28:Q36) -> 7420.4 | R37: =SUM(R28:R36) -> 0 | S37: =SUM(S28:S36) -> 14555.4 | T37: =SUM(T28:T36) -> 0 | U37: =SUM(U28:U36) -> 14555.4
D38: D. Equipment
D39: E. Supplies
A40: SUPPLIES | B40: 82401 | C40: MEX | D40: E.1 Office Supplies | E40: 1 | F40: Month | G40: 12 | H40: 1 | I40: 50 | J40: =E40*I40*G40*H40 -> 600 | K40: =J40 -> 600 | L40: =J40-K40 -> 0 | M40: 1 | N40: 12 | O40: =I40*$E$3 -> 52 | P40: =M40*O40*N40*H40 -> 624 | Q40: =P40 -> 624 | R40: =P40-Q40 -> 0 | S40: =K40+Q40 -> 1224 | T40: =L40+R40 -> 0 | U40: =S40+T40 -> 1224
...

Sheet Line Item Budget Monthly
D1: PARTNERS OF THE AMERICAS - MEXICO MIGRATION MESSAGING BUDGET
A2: Entity: | B2: P | D2: Merit and Cost of Living Increases - 4% | E2: 1.04
A3: Program/Dept.: | B3: 20200 | D3: Inflation - 4% | E3: 1.04
A4: Funder-Grant: | B4: DOS453 | D4: *Key Personnel
A5: Budget Code | B5: Account Code | C5: Country Code | D5: All costs in US$ | E5: Year 1 | Z5: Year 2 | AT5: Total
D6: Budget Line Items | E6: No. | F6: Unit Type | G6: Freq. | H6: % | I6: Rate | J6: Jan 24 | K6: 45323 | L6: 45352 | M6: 45383 | N6: 45413 | O6: 45444 | P6: 45474 | Q6: 45505 | R6: 45536 | S6: 45566 | T6: 45597 | U6: 45627 | V6: Total | W6: Total Original Budget | X6: Federal | Y6: Cost Share | Z6: No. | AA6: Freq. | AB6: Rate | AC6: Jan 25 | AD6: 45689 | AE6: 45717 | AF6: 45748 | AG6: 45778 | AH6: 45809 | AI6: 45839 | AJ6: 45870 | AK6: 45901 | AL6: 45931 | AM6: 45962 | AN6: 45992 | AO6: Total | AP6: Total | AQ6: Federal | AR6: Cost Share | AS6: Total Projected | AT6: Federal | AU6: Cost Share | AV6: Grand Total
D7: A. Personnel
D8: A.1 Field Staff Salaries
A9: PERSNL-CDM | B9: 70000 | C9: MEX | D9: A.1.1 Country Director Mexico (5%) | E9: 1 | F9: Month | G9: 12 | H9: 0.05 | I9: 13450 | J9: =(((3560.09/8)*31)/17.078)*1.0375 -> 838.07673 | K9: =(((3560.09/8)*31)/17.078)*1.0375 -> 838.07673 | L9: =(((3560.09/8)*31)/17.078)*1.0375 -> 838.07673 | M9: =(((3560.09/8)*35)/17.078)*1.0375 -> 946.21566 | N9: =(((3560.09/8)*31)/17.078)*1.0375 -> 838.07673 | O9: =(((3560.09/8)*31)/17.078)*1.0375 -> 838.07673 | P9: =(((3560.09/8)*31)/17.078)*1.0375 -> 838.07673 | Q9: =(((3560.09/8)*31)/17.078)*1.0375 -> 838.07673 | R9: =(((3560.09/8)*31)/17.078)*1.0375 -> 838.07673 | S9: =(((3560.09/8)*31)/17.078)*1.0375 -> 838.07673 | T9: =(((3560.09/8)*31)/17.078)*1.0375 -> 838.07673 | U9: =(((3560.09/8)*31)/17.078)*1.0375+T9*0.5 -> 1257.1151 | V9: =SUM(J9:U9) -> 10584.098 | W9: =E9*I9*G9*H9 -> 8070 | X9: =W9 -> 8070 | Y9: =W9-X9 -> 0 | Z9: =E9 -> 1 | AA9: 12 | AB9: =I9*$E$2 -> 13988 | AC9: =+T9*1.0375 -> 869.5046 | AD9: =+AC9 -> 869.5046 | AE9: =+AD9 -> 869.5046 | AF9: =+AE9+AC9/30.4*4.5 -> 998.21417 | AG9: =+AE9 -> 869.5046 | AH9: =+AG9 -> 869.5046 | AI9: =+AH9 -> 869.5046 | AJ9: =+AI9 -> 869.5046 | AK9: =+AJ9 -> 869.5046 | AL9: =+AK9 -> 869.5046 | AM9: =+AL9 -> 869.5046 | AN9: =+AM9*1.5 -> 1304.2569 | AO9: =SUM(AC9:AN9) -> 10997.517 | AP9: =Z9*AB9*AA9*H9 -> 8392.8 | AQ9: =AP9 -> 8392.8 | AR9: =AP9-AQ9 -> 0 | AS9: =+AO9+V9 -> 21581.615 | AT9: =X9+AQ9 -> 16462.8 | AU9: =Y9+AR9 -> 0 | AV9: =AT9+AU9 -> 16462.8
A10: PERSNL-PD | B10: 70000 | C10: MEX | D10: A.1.2 Program Director (10%)* | E10: 1 | F10: Month | G10: 12 | H10: 0.1 | I10: 8650 | J10: =(77351.04/17.078) -> 4529.2798 | K10: =(77351.04/17.078) -> 4529.2798 | L10: =(77351.04/17.078) -> 4529.2798 | M10: =(77351.04/17.078) -> 4529.2798 | N10: =(77351.04/17.078) -> 4529.2798 | O10: =(77351.04/17.078) -> 4529.2798 | P10: =(77351.04/17.078) -> 4529.2798 | Q10: =(77351.04/17.078) -> 4529.2798 | ... T10: =(77351.04/17.078) -> 4529.2798 | U10: =(77351.04/17.078)+T10*0.5 -> 6793.9197 | V10: =SUM(J10:U10) -> 56615.997 | W10: =E10*I10*G10*H10 -> 10380 | X10: =W10 -> 10380 | Y10: =W10-X10 -> 0 | Z10: =E10 -> 1 | AA10: 12 | AB10: =I10*$E$2 -> 8996 | AC10: =+T10*1.0375+T10/30.4*16*0.25 -> 5295.0856 | AD10: =+T10*1.0375 -> 4699.1278 | AE10: =+AD10 -> 4699.1278 | AF10: =+AE10 -> 4699.1278 | AG10: =+AF10 -> 4699.1278 | AH10: =+AG10 -> 4699.1278 | AI10: =+AH10 -> 4699.1278 | AJ10: =+AI10 -> 4699.1278 | AK10: =+AJ10 -> 4699.1278 | AL10: =+AK10 -> 4699.1278 | AM10: =+AL10 -> 4699.1278 | AN10: =+AM10*1.5 -> 7048.6917 | AO10: =SUM(AC10:AN10) -> 59335.055 | AP10: =Z10*AB10*AA10*H10 -> 10795.2 | AQ10: =AP10 -> 10795.2 | AR10: =AP10-AQ10 -> 0 | AS10: =+AO10+V10 -> 115951.05 | AT10: =X10+AQ10 -> 21175.2 | AU10: =Y10+AR10 -> 0 | AV10: =AT10+AU10 -> 21175.2
A11: PERSNL-SCS | B11: 70000 | C11: MEX | D11: A.1.3 Senior Communications Specialist (30%) | E11: 1 | F11: Month | G11: 12 | H11: 0.3 | I11: 4100 | V11: =SUM(J11:U11) -> 0 | W11: =E11*I11*G11*H11 -> 14760 | X11: =W11 -> 14760 | Y11: =W11-X11 -> 0 | Z11: =E11 -> 1 | AA11: 12 | AB11: =I11*$E$2 -> 4264 | AO11: =SUM(AC11:AN11) -> 0 | AP11: =Z11*AB11*AA11*H11 -> 15350.4 | AQ11: =AP11 -> 15350.4 | AR11: =AP11-AQ11 -> 0 | AS11: =+AO11+V11 -> 0 | AT11: =X11+AQ11 -> 30110.4 | AU11: =Y11+AR11 -> 0 | AV11: =AT11+AU11 -> 30110.4
A12: PERSNL-COM | B12: 70000 | C12: MEX | D12: A.1.4 Communications Specialist (30%) | E12: 1 | F12: Month | G12: 12 | H12: 0.3 | I12: 3000 | V12: =SUM(J12:U12) -> 0 | W12: =E12*I12*G12*H12 -> 10800 | X12: =W12 -> 10800 | Y12: =W12-X12 -> 0 | Z12: =E12 -> 1 | AA12: 12 | AB12: =I12*$E$2 -> 3120 | AO12: =SUM(AC12:AN12) -> 0 | AP12: =Z12*AB12*AA12*H12 -> 11232 | AQ12: =AP12 -> 11232 | AR12: =AP12-AQ12 -> 0 | AS12: =+AO12+V12 -> 0 | AT12: =X12+AQ12 -> 22032 | AU12: =Y12+AR12 -> 0 | AV12: =AT12+AU12 -> 22032
A13: PERSNL-SMA | B13: 70000 | C13: MEX | D13: A.1.5 Social Media Analyst (30%)* | E13: 1 | F13: Month | G13: 12 | H13: 0.3 | I13: 2100 | V13: =SUM(J13:U13) -> 0 | W13: =E13*I13*G13*H13 -> 7560 | X13: =W13 -> 7560 | Y13: =W13-X13 -> 0 | Z13: =E13 -> 1 | AA13: 12 | AB13: =I13*$E$2 -> 2184 | AO13: =SUM(AC13:AN13) -> 0 | AP13: =Z13*AB13*AA13*H13 -> 7862.4 | AQ13: =AP13 -> 7862.4 | AR13: =AP13-AQ13 -> 0 | AS13: =+AO13+V13 -> 0 | AT13: =X13+AQ13 -> 15422.4 | AU13: =Y13+AR13 -> 0 | AV13: =AT13+AU13 -> 15422.4
A14: PERSNL-M&E | B14: 70000 | C14: MEX | D14: A.1.6 Monitoring, Evaluation, and Learning Officer (25%) | E14: 1 | F14: Month | G14: 12 | H14: 0.25 | I14: 3100 | V14: =SUM(J14:U14) -> 0 | W14: =E14*I14*G14*H14 -> 9300 | X14: =W14 -> 9300 | Y14: =W14-X14 -> 0 | Z14: =E14 -> 1 | AA14: 12 | AB14: =I14*$E$2 -> 3224 | AO14: =SUM(AC14:AN14) -> 0 | AP14: =Z14*AB14*AA14*H14 -> 9672 | AQ14: =AP14 -> 9672 | AR14: =AP14-AQ14 -> 0 | AS14: =+AO14+V14 -> 0 | AT14: =X14+AQ14 -> 18972 | AU14: =Y14+AR14 -> 0 | AV14: =AT14+AU14 -> 18972
A15: PERSNL-F&A | B15: 70000 | C15: MEX | D15: A.1.7 Finance & Administration Director (5%) | E15: 1 | F15: Month | G15: 12 | H15: 0.05 | I15: 5500 | J15: =(((2722.16/8)*31)/17.078)*1.0375 -> 640.82058 | K15: =(((2722.16/8)*33)/17.078)*1.0375 -> 682.16384 | L15: =(((2722.16/8)*31)/17.078)*1.0375 -> 640.82058 | M15: =(((2722.16/8)*31)/17.078)*1.0375 -> 640.82058 | N15: =(((2722.16/8)*31)/17.078)*1.0375 -> 640.82058 | O15: =(((2722.16/8)*31)/17.078)*1.0375 -> 640.82058 | P15: =(((2722.16/8)*31)/17.078)*1.0375 -> 640.82058 | Q15: =(((2722.16/8)*31)/17.078)*1.0375 -> 640.82058 | R15: =(((2722.16/8)*31)/17.078)*1.0375 -> 640.82058 | S15: =(((2722.16/8)*31)/17.078)*1.0375 -> 640.82058 | T15: =(((2722.16/8)*31)/17.078)*1.0375+((1466.04/8*18/17.078)*1.0375)*0.25 -> 690.91847 | U15: =(((2722.16/8)*31)/17.078)*1.0375+T15*0.5 -> 986.27982 | V15: =SUM(J15:U15) -> 8126.7474 | W15: =E15*I15*G15*H15 -> 3300 | X15: =W15 -> 3300 | Y15: =W15-X15 -> 0 | Z15: =E15 -> 1 | AA15: 12 | AB15: =I15*$E$2 -> 5720 | AC15: =+T15*1.0375 -> 716.82791 | AD15: =+AC15/30.4*33 -> 778.13556 | AE15: =+AC15 -> 716.82791 | AF15: =+AE15 -> 716.82791 | AG15: =+AF15 -> 716.82791 | AH15: =+AG15 -> 716.82791 | AI15: =+AH15 -> 716.82791 | AJ15: =+AI15 -> 716.82791 | AK15: =+AJ15 -> 716.82791 | AL15: =+AK15 -> 716.82791 | AM15: =+AL15+((1466.04/8*18/17.078)*1.0375)*0.25*1.0375 -> 768.80448 | AN15: =+AM15*1.5 -> 1153.2067 | AO15: =SUM(AC15:AN15) -> 9151.598 | AP15: =Z15*AB15*AA15*H15 -> 3432 | AQ15: =AP15 -> 3432 | AR15: =AP15-AQ15 -> 0 | AS15: =+AO15+V15 -> 17278.345 | AT15: =X15+AQ15 -> 6732 | AU15: =Y15+AR15 -> 0 | AV15: =AT15+AU15 -> 6732
A16: PERSNL-FO | B16: 70000 | C16: MEX | D16: A.1.8 Finance & Administration Officer (20%) | E16: 1 | F16: Month | G16: 12 | H16: 0.2 | I16: 2100 | V16: =SUM(J16:U16) -> 0 | W16: =E16*I16*G16*H16 -> 5040 | X16: =W16 -> 5040 | Y16: =W16-X16 -> 0 | Z16: =E16 -> 1 | AA16: 12 | AB16: =I16*$E$2 -> 2184 | AO16: =SUM(AC16:AN16) -> 0 | AP16: =Z16*AB16*AA16*H16 -> 5241.6 | AQ16: =AP16 -> 5241.6 | AR16: =AP16-AQ16 -> 0 | AS16: =+AO16+V16 -> 0 | AT16: =X16+AQ16 -> 10281.6 | AU16: =Y16+AR16 -> 0 | AV16: =AT16+AU16 -> 10281.6
D17: A.2 HQ Staff Salaries | V17: =SUM(J17:U17) -> 0 | AO17: =SUM(AC17:AN17) -> 0 | AS17: =SUM(AG17:AR17) -> 0
A18: PERSNL | B18: 50000 | C18: USA | D18: A.2.1 Program Manager (HQ) (20%) | E18: 1 | F18: Month | G18: 12 | H18: 0.2 | I18: =55000/12 -> 4583.3333 | J18: =+W18/12 -> 916.66667 | K18: =+J18 -> 916.66667 | L18: =+K18 -> 916.66667 | M18: =+L18 -> 916.66667 | N18: =+M18 -> 916.66667 | O18: =+N18 -> 916.66667 | P18: =+O18 -> 916.66667 | Q18: =+P18 -> 916.66667 | R18: =+Q18 -> 916.66667 | ... U18: =+T18 -> 916.66667 | V18: =SUM(J18:U18) -> 11000 | W18: =E18*I18*G18*H18 -> 11000 | X18: =W18 -> 11000 | Y18: =W18-X18 -> 0 | Z18: 1 | AA18: =G18 -> 12 | AB18: =I18*$E$2 -> 4766.6667 | AC18: =+AP18/12 -> 953.33333 | AD18: =+AC18 -> 953.33333 | AE18: =+AD18 -> 953.33333 | AF18: =+AE18 -> 953.33333 | AG18: =+AF18 -> 953.33333 | AH18: =+AG18 -> 953.33333 | AI18: =+AH18 -> 953.33333 | AJ18: =+AI18 -> 953.33333 | AK18: =+AJ18 -> 953.33333 | ... AN18: =+AM18 -> 953.33333 | AO18: =SUM(AC18:AN18) -> 11440 | AP18: =Z18*AB18*AA18*H18 -> 11440 | AQ18: =AP18 -> 11440 | AR18: =AP18-AQ18 -> 0 | AS18: =+AO18+V18 -> 22440 | AT18: =X18+AQ18 -> 22440 | AU18: =Y18+AR18 -> 0 | AV18: =AT18+AU18 -> 22440
D19: Subtotal Personnel | J19: =SUM(J9:J18) -> 6924.8437 | K19: =SUM(K9:K18) -> 6966.187 | L19: =SUM(L9:L18) -> 6924.8437 | M19: =SUM(M9:M18) -> 7032.9827 | N19: =SUM(N9:N18) -> 6924.8437 | O19: =SUM(O9:O18) -> 6924.8437 | P19: =SUM(P9:P18) -> 6924.8437 | Q19: =SUM(Q9:Q18) -> 6924.8437 | ... Y19: =SUM(Y9:Y18) -> 0 | AC19: =SUM(AC9:AC18) -> 7834.7515 | AD19: =SUM(AD9:AD18) -> 7300.1013 | AE19: =SUM(AE9:AE18) -> 7238.7936 | AF19: =SUM(AF9:AF18) -> 7367.5032 | AG19: =SUM(AG9:AG18) -> 7238.7936 | AH19: =SUM(AH9:AH18) -> 7238.7936 | AI19: =SUM(AI9:AI18) -> 7238.7936 | AJ19: =SUM(AJ9:AJ18) -> 7238.7936 | ... AV19: =SUM(AV9:AV18) -> 163628.4
D20: B. Fringe Benefits
D21: B.1 HQ Fringe Benefits
A22: FRINGE | B22: 50900 | C22: USA | D22: B.1.1 U.S.-Based Personnel Fringe Benefits | F22: % | H22: 0.2347 | J22: =+W22/12 -> 215.14167 | K22: =+J22 -> 215.14167 | L22: =+K22 -> 215.14167 | M22: =+L22 -> 215.14167 | N22: =+M22 -> 215.14167 | O22: =+N22 -> 215.14167 | P22: =+O22 -> 215.14167 | Q22: =+P22 -> 215.14167 | R22: =+Q22 -> 215.14167 | ... U22: =+T22 -> 215.14167 | V22: =SUM(J22:U22) -> 2581.7 | W22: =W18*H22 -> 2581.7 | X22: =W22 -> 2581.7 | Y22: 0 | AB22: =AB18 -> 4766.6667 | AC22: =+AP22/12 -> 223.74733 | AD22: =+AC22 -> 223.74733 | AE22: =+AD22 -> 223.74733 | AF22: =+AE22 -> 223.74733 | AG22: =+AF22 -> 223.74733 | AH22: =+AG22 -> 223.74733 | AI22: =+AH22 -> 223.74733 | AJ22: =+AI22 -> 223.74733 | AK22: =+AJ22 -> 223.74733 | ... AN22: =+AM22 -> 223.74733 | AO22: =SUM(AC22:AN22) -> 2684.968 | AP22: =AP18*H22 -> 2684.968 | AQ22: =AP22 -> 2684.968 | AR22: =AP22-AQ22 -> 0 | AS22: =+AO22+V22 -> 5266.668 | AT22: =X22+AQ22 -> 5266.668 | AU22: =Y22+AR22 -> 0 | AV22: =AT22+AU22 -> 5266.668
D23: B.2 Field Fringe Benefits
A24: FRINGE-MX | B24: 70015 | C24: MEX | D24: B.2.1 Mexico Field Staff Fringe Benefits | F24: % | H24: 0.3671 | J24: =(+J19-J18)*0.03+((7699.09+900)/12)*1.15 -> 1004.3248 | K24: =(+K19-K18)*0.03+((7699.09+900)/12)*1.15 -> 1005.5651 | L24: =(+L19-L18)*0.03+((7699.09+900)/12)*1.15 -> 1004.3248 | M24: =(+M19-M18)*0.03+((7699.09+900)/12)*1.15 -> 1007.5689 | N24: =(+N19-N18)*0.03+((7699.09+900)/12)*1.15 -> 1004.3248 | O24: =(+O19-O18)*0.03+((7699.09+900)/12)*1.15 -> 1004.3248 | P24: =(+P19-P18)*0.03+((7699.09+900)/12)*1.15 -> 1004.3248 | Q24: =(+Q19-Q18)*0.03+((7699.09+900)/12)*1.15 -> 1004.3248 | ... U24: =(+U19-U18)*0.03+((7699.09+900)/12)*1.15 -> 1095.1989 | V24: =SUM(J24:U24) -> 12148.759 | W24: =(SUM(W9:W16))*$H$24 -> 25406.991 | X24: =W24 -> 25406.991 | Y24: 0 | AB24: =AB10 -> 8996 | AC24: =(+AC19-AC18)*0.03+((7699.09+900)/12)*1.15 -> 1030.522 | AD24: =(+AD19-AD18)*0.03+((7699.09+900)/12)*1.15 -> 1014.4825 | AE24: =(+AE19-AE18)*0.03+((7699.09+900)/12)*1.15 -> 1012.6433 | AF24: =(+AF19-AF18)*0.03+((7699.09+900)/12)*1.15 -> 1016.5046 | AG24: =(+AG19-AG18)*0.03+((7699.09+900)/12)*1.15 -> 1012.6433 | AH24: =(+AH19-AH18)*0.03+((7699.09+900)/12)*1.15 -> 1012.6433 | AI24: =(+AI19-AI18)*0.03+((7699.09+900)/12)*1.15 -> 1012.6433 | AJ24: =(+AJ19-AJ18)*0.03+((7699.09+900)/12)*1.15 -> 1012.6433 | ... AM24: =(+AM19-AM18)*0.03+((7699.09+900)/12)*1.15 -> 1014.2026 | AN24: =(+AN19-AN18)*0.03+((7699.09+900)/12)*1.15+(7291/30.4*130) -> 32287.883 | AO24: =SUM(AC24:AN24) -> 43452.097 | AP24: =(SUM(AP9:AP16))*$H$24 -> 26423.271 | AQ24: =AP24 -> 26423.271 | AR24: =AP24-AQ24 -> 0 | AS24: =+AO24+V24 -> 55600.856 | AT24: =X24+AQ24 -> 51830.262 | AU24: =Y24+AR24 -> 0 | AV24: =AT24+AU24 -> 51830.262
D25: Subtotal Fringe Benefits | J25: =SUM(J22:J24) -> 1219.4664 | K25: =SUM(K22:K24) -> 1220.7067 | L25: =SUM(L22:L24) -> 1219.4664 | M25: =SUM(M22:M24) -> 1222.7106 | N25: =SUM(N22:N24) -> 1219.4664 | O25: =SUM(O22:O24) -> 1219.4664 | P25: =SUM(P22:P24) -> 1219.4664 | Q25: =SUM(Q22:Q24) -> 1219.4664 | ... Y25: =SUM(Y22:Y24) -> 0 | AC25: =SUM(AC22:AC24) -> 1254.2693 | AD25: =SUM(AD22:AD24) -> 1238.2298 | AE25: =SUM(AE22:AE24) -> 1236.3906 | AF25: =SUM(AF22:AF24) -> 1240.2519 | AG25: =SUM(AG22:AG24) -> 1236.3906 | AH25: =SUM(AH22:AH24) -> 1236.3906 | AI25: =SUM(AI22:AI24) -> 1236.3906 | AJ25: =SUM(AJ22:AJ24) -> 1236.3906 | ... AV25: =SUM(AV22:AV24) -> 57096.93
D26: C. Travel
D27: C.1 HQ Staff International Travel
A28: STFTRAVEL | B28: 86040 | C28: USA | D28: C.1.1 International Airfare (DC-MX) | E28: 1 | F28: Flight | G28: 1 | H28: 1 | I28: 700 | V28: =SUM(J28:U28) -> 0 | W28: =E28*I28*G28 -> 700 | X28: =W28 -> 700 | Y28: =W28-X28 -> 0 | Z28: 1 | AA28: 1 | AB28: =I28*$E$3 -> 728 | AO28: =SUM(AC28:AN28) -> 0 | AP28: =Z28*AB28*AA28*H28 -> 728 | AQ28: =AP28 -> 728 | AR28: =AP28-AQ28 -> 0 | AS28: =+AO28+V28 -> 0 | AT28: =X28+AQ28 -> 1428 | AU28: =Y28+AR28 -> 0 | AV28: =AT28+AU28 -> 1428
A29: GROUNDTRAN | B29: 86000 | C29: USA | D29: C.1.2 Ground Transportation | E29: 1 | F29: Trip | G29: 1 | H29: 1 | I29: 100 | V29: =SUM(J29:U29) -> 0 | W29: =E29*I29*G29 -> 100 | X29: =W29 -> 100 | Y29: =W29-X29 -> 0 | Z29: 1 | AA29: 1 | AB29: =I29*$E$3 -> 104 | AO29: =SUM(AC29:AN29) -> 0 | AP29: =Z29*AB29*AA29*H29 -> 104 | AQ29: =AP29 -> 104 | AR29: =AP29-AQ29 -> 0 | AS29: =+AO29+V29 -> 0 | AT29: =X29+AQ29 -> 204 | AU29: =Y29+AR29 -> 0 | AV29: =AT29+AU29 -> 204
A30: LODGING | B30: 86030 | C30: USA | D30: C.1.3 Lodging | E30: 1 | F30: Night | G30: 4 | H30: 1 | I30: 120 | V30: =SUM(J30:U30) -> 0 | W30: =E30*I30*G30 -> 480 | X30: =W30 -> 480 | Y30: =W30-X30 -> 0 | Z30: 1 | AA30: 4 | AB30: =I30*$E$3 -> 124.8 | AO30: =SUM(AC30:AN30) -> 0 | AP30: =Z30*AB30*AA30*H30 -> 499.2 | AQ30: =AP30 -> 499.2 | AR30: =AP30-AQ30 -> 0 | AS30: =+AO30+V30 -> 0 | AT30: =X30+AQ30 -> 979.2 | AU30: =Y30+AR30 -> 0 | AV30: =AT30+AU30 -> 979.2
A31: STFCN DIEM | B31: 86050 | C31: USA | D31: C.1.4 M&IE | E31: 1 | F31: Day | G31: 5 | H31: 1 | I31: 95 | V31: =SUM(J31:U31) -> 0 | W31: =E31*I31*G31 -> 475 | X31: =W31 -> 475 | Y31: =W31-X31 -> 0 | Z31: 1 | AA31: 5 | AB31: =I31*$E$3 -> 98.8 | AO31: =SUM(AC31:AN31) -> 0 | AP31: =Z31*AB31*AA31*H31 -> 494 | AQ31: =AP31 -> 494 | AR31: =AP31-AQ31 -> 0 | AS31: =+AO31+V31 -> 0 | AT31: =X31+AQ31 -> 969 | AU31: =Y31+AR31 -> 0 | AV31: =AT31+AU31 -> 969
D32: C.2 Local Staff In-Country Travel to Target Geographic Regions
A33: LSLODGING | B33: 86030 | C33: MEX | D33: C.2.1 Domestic Airfare | E33: 2 | F33: Flight | G33: 1 | H33: 1 | I33: 200 | V33: =SUM(J33:U33) -> 0 | W33: =E33*I33*G33 -> 400 | X33: =W33 -> 400 | Y33: =W33-X33 -> 0 | Z33: 2 | AA33: 1 | AB33: =I33*$E$3 -> 208 | AO33: =SUM(AC33:AN33) -> 0 | AP33: =Z33*AB33*AA33*H33 -> 416 | AQ33: =AP33 -> 416 | AR33: =AP33-AQ33 -> 0 | AS33: =+AO33+V33 -> 0 | AT33: =X33+AQ33 -> 816 | AU33: =Y33+AR33 -> 0 | AV33: =AT33+AU33 -> 816
A34: LSM&IE | B34: 86050 | C34: MEX | D34: C.2.2 Lodging | E34: 6 | F34: Night | G34: 3 | H34: 1 | I34: 100 | V34: =SUM(J34:U34) -> 0 | W34: =E34*I34*G34 -> 1800 | X34: =W34 -> 1800 | Y34: =W34-X34 -> 0 | Z34: 6 | AA34: 3 | AB34: =I34*$E$3 -> 104 | AO34: =SUM(AC34:AN34) -> 0 | AP34: =Z34*AB34*AA34*H34 -> 1872 | AQ34: =AP34 -> 1872 | AR34: =AP34-AQ34 -> 0 | AS34: =+AO34+V34 -> 0 | AT34: =X34+AQ34 -> 3672 | AU34: =Y34+AR34 -> 0 | AV34: =AT34+AU34 -> 3672
A35: LSTRANS | B35: 86000 | C35: MEX | D35: C.2.3 M&IE | E35: 6 | F35: Day | G35: 4 | H35: 1 | I35: 70 | V35: =SUM(J35:U35) -> 0 | W35: =E35*I35*G35 -> 1680 | X35: =W35 -> 1680 | Y35: =W35-X35 -> 0 | Z35: 6 | AA35: 4 | AB35: =I35*$E$3 -> 72.8 | AO35: =SUM(AC35:AN35) -> 0 | AP35: =Z35*AB35*AA35*H35 -> 1747.2 | AQ35: =AP35 -> 1747.2 | AR35: =AP35-AQ35 -> 0 | AS35: =+AO35+V35 -> 0 | AT35: =X35+AQ35 -> 3427.2 | AU35: =Y35+AR35 -> 0 | AV35: =AT35+AU35 -> 3427.2
A36: LSDOMAIR | B36: 86040 | C36: MEX | D36: C.2.4 Ground Transportation | E36: 1 | F36: Month | G36: 10 | H36: 1 | I36: 150 | V36: =SUM(J36:U36) -> 0 | W36: =E36*I36*G36 -> 1500 | X36: =W36 -> 1500 | Y36: =W36-X36 -> 0 | Z36: 1 | AA36: 10 | AB36: =I36*$E$3 -> 156 | AO36: =SUM(AC36:AN36) -> 0 | AP36: =Z36*AB36*AA36*H36 -> 1560 | AQ36: =AP36 -> 1560 | AR36: =AP36-AQ36 -> 0 | AS36: =+AO36+V36 -> 0 | AT36: =X36+AQ36 -> 3060 | AU36: =Y36+AR36 -> 0 | AV36: =AT36+AU36 -> 3060
D37: Subtotal Travel | J37: =SUM(J28:J36) -> 0 | K37: =SUM(K28:K36) -> 0 | L37: =SUM(L28:L36) -> 0 | M37: =SUM(M28:M36) -> 0 | N37: =SUM(N28:N36) -> 0 | O37: =SUM(O28:O36) -> 0 | P37: =SUM(P28:P36) -> 0 | Q37: =SUM(Q28:Q36) -> 0 | ... Y37: =SUM(Y28:Y36) -> 0 | AC37: =SUM(AC28:AC36) -> 0 | AD37: =SUM(AD28:AD36) -> 0 | AE37: =SUM(AE28:AE36) -> 0 | AF37: =SUM(AF28:AF36) -> 0 | AG37: =SUM(AG28:AG36) -> 0 | AH37: =SUM(AH28:AH36) -> 0 | AI37: =SUM(AI28:AI36) -> 0 | AJ37: =SUM(AJ28:AJ36) -> 0 | ... AV37: =SUM(AV28:AV36) -> 14555.4
D38: D. Equipment
D39: E. Supplies
A40: SUPPLIES | B40: 82401 | C40: MEX | D40: E.1 Office Supplies | E40: 1 | F40: Month | G40: 12 | H40: 1 | I40: 50 | J40: =+W40/12 -> 50 | K40: =+J40 -> 50 | L40: =+K40 -> 50 | M40: =+L40 -> 50 | N40: =+M40 -> 50 | O40: =+N40 -> 50 | P40: =+O40 -> 50 | Q40: =+P40 -> 50 | R40: =+Q40 -> 50 | ... U40: =+T40 -> 50 | V40: =SUM(J40:U40) -> 600 | W40: =E40*I40*G40*H40 -> 600 | X40: =W40 -> 600 | Y40: =W40-X40 -> 0 | Z40: 1 | AA40: 12 | AB40: =I40*$E$3 -> 52 | AC40: =+AP40/12 -> 52 | AD40: =+AC40 -> 52 | AE40: =+AD40 -> 52 | AF40: =+AE40 -> 52 | AG40: =+AF40 -> 52 | AH40: =+AG40 -> 52 | AI40: =+AH40 -> 52 | AJ40: =+AI40 -> 52 | AK40: =+AJ40 -> 52 | ... AN40: =+AM40 -> 52 | AO40: =SUM(AC40:AN40) -> 624 | AP40: =Z40*AB40*AA40*H40 -> 624 | AQ40: =AP40 -> 624 | AR40: =AP40-AQ40 -> 0 | AS40: =+AO40+V40 -> 1224 | AT40: =X40+AQ40 -> 1224 | AU40: =Y40+AR40 -> 0 | AV40: =AT40+AU40 -> 1224
...
