Workbook

Sheet Pwin Parameters
A1: Pwin Parameter Instructions:
A2: 1. Hover over column headings for pop-up help.
A3: 2. Modify or enter win factors only in gray-shaded cells.
A4: 3. Modify factor ratings to match organizational criteria, with most favorable rating on top, least favorable on bottom.
A5: 4. If other factors are entered, four ratings must be defined for each, with most favorable rating on top, least favorable on bottom.
A6: 5. The Points column cannot be modified.
A7: 6. Change breakpoint values based on organizational aggressiveness. Lowering breakpoint values will encourage pursuit of less favorable opportunities.
A9: Probability Parameters:
A10: Win Factors | B10: Win Factor Ratings (Modify to Meet Organizational Criteria) | C10: Points | D10: Breakpoints | E10: Values
A11: Incumbency | B11: We are a strong incumbent or can team with a strong incumbent | C11: 4
B12: We are an incumbent | C12: 3
B13: There is no incumbent | C13: 2
B14: A competitor is a strong incumbent | C14: 1
A16: Experience | B16: We have sold the same or similar product/service to this customer in the past | C16: 4
B17: We will be selling an existing product/service to a new customer | C17: 3
B18: We will be selling a new product/service to an existing customer | C18: 2
B19: We will be selling a new product/service to a new customer | C19: 1
A21: Past Performance | B21: We provided outstanding services in an earlier phase leading to this procurement | C21: 4
B22: We provided services in an earlier phase with moderate success | C22: 3
B23: A competitor provided services in an earlier phase with moderate success | C23: 2
B24: A competitor provided service in an earlier phase with outstanding results | C24: 1
A26: Contract Risk | B26: Risk is ordinary for our industry with no special considerations or liabilities | C26: 4
B27: Risk is moderate because of special considerations or liabilities | C27: 3
B28: Risk is high with very attractive rewards | C28: 2
B29: Risk is high with only moderate or poor rewards | C29: 1
A31: Contract Size | B31: Contract size is larger than our typical contract but within our capabilities | C31: 4
B32: Contract size is beyond our capabilities but justified by strategic importance of contract | C32: 3
B33: Contract size is typical for our industry and organization | C33: 2
B34: Contract size will challenge our organization to deliver or impose delivery risk | C34: 1
A36: Competitor Rating | B36: Compared to our competitors, the customer rates us as among the best or the best | C36: 4
B37: Compared to our competitors, the customer rates us as average | C37: 3
B38: Compared to our competitors, the customer rates us as lower than average | C38: 2
B39: Our customers know our competitors but don't know us | C39: 1
A41: Other | B41: A rating that increases the pursuit indication the most | C41: 4
B42: A rating that increases the pursuit indication moderately | C42: 3
B43: A rating that decreases the pursuit indication | C43: 2
B44: A rating that makes pursuit unwise | C44: 1

Sheet Pwin Calculator
A1: NOTICE: This Pwin Calculator is intended solely as an aid in evaluating the advisability of pursuing business opportunities and should be used in conjunction with other means of research and analysis.
A3: Worksheet Instructions:
A4: 1. Enter information and view result in the Pwin Calculator on this worksheet.
A5: 2. Customize the tool for your organization's pipeline management preferences on the Pwin Parameters worksheet.
A6: 3. Hover over table headings to view pop-up help.
A7: 4. Completed chart may be printed or saved.
A8: 5. Worksheet Instructions will not print on completed chart.
A9: 6. Chart can be copied and pasted onto a PowerPoint slide.
A10: 7. Calculated scores appear in gray-shaded cells.
A11: 8. Strong Pwin indication will shade Result cell GREEN. Moderate indication will show YELLOW, recommended abandonment RED.
C13: Pwin Calculator
A14: Opportunity:
A15: Anticipated Value:
A16: Win Factor | B16: Wt. Inc. | C16: Win Factor Rating (Select one from drop-down list) | D16: Points | E16: Score | G16: ='Pwin Parameters'!#REF! -> #REF! | H16: 4 | I16: ='Pwin Parameters'!#REF! -> #REF!
A17: ='Pwin Parameters'!$A$11 -> Incumbency | D17: =IF(C17>0,VLOOKUP($C17,$G$16:$H$73,2,FALSE),0) -> 0 | E17: =IF(C17>0,(1+0.1*B17)*(D17-'Pwin Parameters'!#REF!),"") | G17: ='Pwin Parameters'!#REF! -> #REF! | H17: 2
A18: ='Pwin Parameters'!$A$16 -> Experience | D18: =IF(C18>0,VLOOKUP($C18,$G$16:$H$73,2,FALSE),0) -> 0 | E18: =IF(C18>0,(1+0.1*B18)*(D18-'Pwin Parameters'!#REF!),"") | G18: ='Pwin Parameters'!#REF! -> #REF! | H18: 1
A19: ='Pwin Parameters'!$A$21 -> Past Performance | D19: =IF(C19>0,VLOOKUP($C19,$G$16:$H$73,2,FALSE),0) -> 0 | E19: =IF(C19>0,(1+0.1*B19)*(D19-'Pwin Parameters'!#REF!),"")
A20: ='Pwin Parameters'!$A$26 -> Contract Risk | D20: =IF(C20>0,VLOOKUP($C20,$G$16:$H$73,2,FALSE),0) -> 0 | E20: =IF(C20>0,(1+0.1*B20)*(D20-'Pwin Parameters'!#REF!),"") | G20: ='Pwin Parameters'!#REF! -> #REF! | H20: 4
A21: ='Pwin Parameters'!$A$31 -> Contract Size | D21: =IF(C21>0,VLOOKUP($C21,$G$16:$H$73,2,FALSE),0) -> 0 | E21: =IF(C21>0,(1+0.1*B21)*(D21-'Pwin Parameters'!#REF!),"") | G21: ='Pwin Parameters'!#REF! -> #REF! | H21: 3
A22: ='Pwin Parameters'!$A$36 -> Competitor Rating | D22: =IF(C22>0,VLOOKUP($C22,$G$16:$H$73,2,FALSE),0) -> 0 | E22: =IF(C22>0,(1+0.1*B22)*(D22-'Pwin Parameters'!#REF!),"") | G22: ='Pwin Parameters'!#REF! -> #REF! | H22: 2
A23: ='Pwin Parameters'!A41 -> Other | D23: =IF(C23>0,VLOOKUP($C23,$G$16:$H$73,2,FALSE),0) -> 0 | E23: =IF(C23>0,(1+0.1*B23)*(D23-'Pwin Parameters'!#REF!),"") | G23: ='Pwin Parameters'!#REF! -> #REF! | H23: 1
D24: Result | E24: =AVERAGEIF(C17:C23,"<>""",E17:E23)+'Pwin Parameters'!#REF! -> #DIV/0!
A25: Key: 4 = Strong Pwin 3 = Moderate Pwin 2 = Moderate Avoidance 1 = Strong Avoidance | G25: ='Pwin Parameters'!#REF! -> #REF! | H25: 4
G26: ='Pwin Parameters'!#REF! -> #REF! | H26: 3
G27: ='Pwin Parameters'!#REF! -> #REF! | H27: 2
G28: ='Pwin Parameters'!#REF! -> #REF! | H28: 1
G30: ='Pwin Parameters'!#REF! -> #REF! | H30: 4
G31: ='Pwin Parameters'!#REF! -> #REF! | H31: 3
G32: ='Pwin Parameters'!#REF! -> #REF! | H32: 2
G33: ='Pwin Parameters'!#REF! -> #REF! | H33: 1
G35: ='Pwin Parameters'!#REF! -> #REF! | H35: 4
G36: ='Pwin Parameters'!#REF! -> #REF! | H36: 3
G37: ='Pwin Parameters'!#REF! -> #REF! | H37: 2
G38: ='Pwin Parameters'!#REF! -> #REF! | H38: 1
G40: ='Pwin Parameters'!B11 -> We are a strong incumbent or can team with a strong incumbent | H40: 4
G41: ='Pwin Parameters'!B12 -> We are an incumbent | H41: 3
G42: ='Pwin Parameters'!B13 -> There is no incumbent | H42: 2
G43: ='Pwin Parameters'!B14 -> A competitor is a strong incumbent | H43: 1
G45: ='Pwin Parameters'!B16 -> We have sold the same or similar product/service to this customer in the past | H45: 4
G46: ='Pwin Parameters'!B17 -> We will be selling an existing product/service to a new customer | H46: 3
...
