Workbook

Sheet SF424
B1: Application for Federal Assistance SF-424
B2: * 1.Type of Submission: | F2: * 2. Type of Application | H2: * If Revision, select appropriate letter(s):
B3: Preapplication | F3: New | H3: Response to Issues Letter
B4: Application | F4: Continuation | H4: * Other (Specify)
B5: Changed/Corrected Application | F5: Revision
B7: * 3. Date Received: | F7: 4. Applicant Identifier:
B8: Completed by Grants.gov upon submission.
B10: 5a. Federal Entity Identifier: | F10: * 5b. Federal Award Identifier:
B13: State Use Only:
B15: 6. Date Received by State: | F15: 7. State Application Identifier:
B17: 8. APPLICANT INFORMATION:
B19: * a. Legal Name: | C19: Catholic Relief Services - United States Conference of Catholic Bishops
B21: * b. Employer/Taxpayer Identification Number (EIN/TIN): | F21: * c. Organizational DUNS:
B22: 13-5563422 | F22: 68205541
B24: d. Address:
B26: * Street 1: | C26: 228 West Lexington Street
B28: Street 2:
B30: * City: | C30: Baltimore
B32: County:
B34: * State: | C34: Maryland
B36: Province:
B38: * Country: | C38: USA
B40: * Zip / Postal Code: | C40: 21201
B42: e. Organization Unit:
B44: Department Name: | F44: Division Name:
B47: f. Name and contact information of person to be contacted on matters involving this application:
B49: Prefix: | C49: Ms. | F49: First Name: | G49: Chelsea
B51: Middle Name:
B53: Last Name: | C53: Treadwell
B55: Suffix:
B58: Title: | C58: Public Donor Liaison - Asia
B60: Organizational Affiliation:
B61: Catholic Relief Services
B64: * Telephone Number: | C64: 410-951-7468 | G64: Fax Number:
B67: * Email: | C67: chelsea.treadwell@crs.org
B70: Application for Federal Assistance SF-424
B71: 9. Type of Applicant 1: Select Applicant Type:
B72: M: Nonprofit with 501C3 IRS Status (Other than Institution of Higher Education)
B74: Type of Applicant 2: Select Applicant Type:
B77: Type of Applicant 3: Select Applicant Type:
...

Sheet SF424A
B1: Standard Form 424A
B2: OMB Approval No. 0348-0044
B4: Budget Information - Non-Construction Programs
A6: SECTION A - BUDGET SUMMARY
A7: Grant Program | C7: Catalog of Federal | D7: Estimated Unobligated Funds | F7: New or Revised Budget
A8: Function | C8: Domestic Assistance
A9: or Activity | C9: Number | D9: Federal | E9: Non-Federal | F9: Federal | G9: Non-Federal | H9: Total
A10: {a} | C10: {b} | D10: {c} | E10: {d} | F10: {e} | G10: {f} | H10: {g}
A11: 1 | B11: Anti-Trafficking Program | C11: 19.019 | F11: ='Budget Summary'!L19 -> 617282.95 | G11: ='Budget Summary'!M19 -> 0 | H11: =F11+G11 -> 617282.95
A12: 2 | H12: =F12+G12 -> 0
A13: 4 | H13: =F13+G13 -> 0
A14: 3 | H14: =F14+G14 -> 0
A15: 4 | H15: =F15+G15 -> 0
A16: 5 | B16: TOTALS | D16: =SUM(D11:D14) -> 0 | E16: =SUM(E11:E14) -> 0 | F16: =SUM(F11:F15) -> 617282.95 | G16: =SUM(G11:G15) -> 0 | H16: =SUM(H11:H15) -> 617282.95
A17: SECTION B - BUDGET CATEGORIES
C18: Grant Program, Function or Activity | H18: Total
A19: 6. | B19: Object Class Categories | C19: {1} | D19: {2} | E19: {3} | F19: {4} | G19: {5} | H19: {6}
A20: a. Personnel | B20: a. Personnel | C20: ='Budget Summary'!N6 -> 141278.49 | H20: =SUM(C20:G20) -> 141278.49
A21: b. Fringe Benefits | B21: b. Fringe Benefits | C21: ='Budget Summary'!N7 -> 64661.997 | H21: =SUM(C21:G21) -> 64661.997
A22: c. Travel | B22: c. Travel | C22: ='Budget Summary'!N8 -> 23907.682 | H22: =SUM(C22:G22) -> 23907.682
A23: d. Equipment | B23: d. Equipment | C23: 0 | H23: =SUM(C23:G23) -> 0
A24: e. Supplies | B24: e. Supplies | C24: ='Budget Summary'!N10 -> 18370 | H24: =SUM(C24:G24) -> 18370
A25: f. Contractual | B25: f. Contractual | C25: ='Budget Summary'!N11 -> 199312.63 | H25: =SUM(C25:G25) -> 199312.63
A26: g. Construction | B26: g. Construction | C26: 0 | H26: =SUM(C26:G26) -> 0
A27: h. Other | B27: h. Other | C27: ='Budget Summary'!N13 -> 34721.5 | H27: =SUM(C27:G27) -> 34721.5
A28: i. Total Direct Charges (sum of 6a-6h) | B28: i. Total Direct Charges (sum of 6a-6h) | C28: =SUM(C20:C27) -> 482252.31 | H28: =SUM(C28:G28) -> 482252.31
A29: j. Indirect Charges | B29: j. Indirect Charges | C29: ='Budget Summary'!N17 -> 135030.65 | H29: =SUM(C29:G29) -> 135030.65
A30: k. TOTALS (sum of 6i and 6j) | B30: k. TOTALS (sum of 6i and 6j) | C30: =C28+C29 -> 617282.95 | D30: =D28+D29 -> 0 | E30: =E28+E29 -> 0 | F30: =F28+F29 -> 0 | G30: =G28+G29 -> 0 | H30: =SUM(C30:G30) -> 617282.95
A32: 7. | B32: Program Income | C32: 0 | D32: 0 | E32: 0 | F32: 0 | H32: 0
A34: Previous Edition Usable | D34: Authorized for Local Reproduction | G34: Standard Form 424 A (Rev. 4-92)
A37: Standard Form 424A (cont'd)
A38: SECTION C - NON-FEDERAL RESOURCES
A39: (a) Grant Program | E39: (b) Applicant | F39: (c) State | G39: (d) Other Sources | H39: (e) TOTALS
A40: 8. | B40: Anti-Trafficking Program | E40: ='Budget Summary'!M19 -> 0 | H40: =SUM(E40:G40) -> 0
A41: 9. | H41: =SUM(E41:G41) -> 0
A42: 10. | H42: =SUM(E42:G42) -> 0
A43: 11. | H43: =SUM(E43:G43) -> 0
A44: 12. | B44: TOTAL (sum of lines 8 - 11) | E44: =SUM(E40:E43) -> 0 | F44: =SUM(F40:F43) -> 0 | G44: =SUM(G40:G43) -> 0 | H44: =SUM(H40:H43) -> 0
A45: SECTION D - FORCASTED CASH NEEDS
D46: Total for 1st Year | E46: 1st Quarter | F46: 2nd Quarter | G46: 3rd Quarter | H46: 4th Quarter
...

Sheet Budget Summary
B2: PARTNERS OF THE AMERICAS
B3: SUMMARY BUDGET FOR MEXICO UNITED 2026
C4: Year 1 | F4: Year 2 | I4: Year 3 | L4: Total
B5: BUDGET SUMMARY CATEGORIES | C5: Grant | D5: Cost Share | E5: Total | F5: Grant | G5: Cost Share | H5: Total | I5: Grant | J5: Cost Share | K5: Total | L5: Grant | M5: Cost Share | N5: Total
B6: A. Personnel | C6: ='Line Item Budget'!L15 -> 54250 | D6: ='Line Item Budget'!M15 -> 0 | E6: =C6+D6 -> 54250 | F6: ='Line Item Budget'!R15 -> 59926.5 | G6: ='Line Item Budget'!S15 -> 0 | H6: =F6+G6 -> 59926.5 | I6: ='Line Item Budget'!X15 -> 27101.992 | J6: ='Line Item Budget'!Y15 -> 0 | K6: =I6+J6 -> 27101.992 | L6: ='Line Item Budget'!Z15 -> 141278.49 | M6: ='Line Item Budget'!AA15 -> 0 | N6: =L6+M6 -> 141278.49
B7: B. Fringe Benefits | C7: ='Line Item Budget'!L24 -> 24793.82 | D7: ='Line Item Budget'!M24 -> 0 | E7: =C7+D7 -> 24793.82 | F7: ='Line Item Budget'!R24 -> 27582.212 | G7: ='Line Item Budget'!S24 -> 0 | H7: =F7+G7 -> 27582.212 | I7: ='Line Item Budget'!X24 -> 12285.965 | J7: ='Line Item Budget'!Y24 -> 0 | K7: =I7+J7 -> 12285.965 | L7: ='Line Item Budget'!Z24 -> 64661.997 | M7: ='Line Item Budget'!AA24 -> 0 | N7: =L7+M7 -> 64661.997
B8: C. Travel | C8: ='Line Item Budget'!L38 -> 12429 | D8: ='Line Item Budget'!M38 -> 0 | E8: =C8+D8 -> 12429 | F8: ='Line Item Budget'!R38 -> 7883.58 | G8: ='Line Item Budget'!S38 -> 0 | H8: =F8+G8 -> 7883.58 | I8: ='Line Item Budget'!X38 -> 3595.1022 | J8: ='Line Item Budget'!Y38 -> 0 | K8: =I8+J8 -> 3595.1022 | L8: ='Line Item Budget'!Z38 -> 23907.682 | M8: ='Line Item Budget'!AA38 -> 0 | N8: =L8+M8 -> 23907.682
B9: D. Equipment
B10: E. Supplies | C10: ='Line Item Budget'!L48 -> 8550 | D10: ='Line Item Budget'!M48 -> 0 | E10: =C10+D10 -> 8550 | F10: ='Line Item Budget'!R48 -> 7440 | G10: ='Line Item Budget'!S48 -> 0 | H10: =F10+G10 -> 7440 | I10: ='Line Item Budget'!X48 -> 2380 | J10: ='Line Item Budget'!Y48 -> 0 | K10: =I10+J10 -> 2380 | L10: ='Line Item Budget'!Z48 -> 18370 | M10: ='Line Item Budget'!AA48 -> 0 | N10: =L10+M10 -> 18370
B11: F. Contractual and Subawards | C11: ='Line Item Budget'!L57 -> 72393.76 | D11: ='Line Item Budget'!M57 -> 0 | E11: =C11+D11 -> 72393.76 | F11: ='Line Item Budget'!R57 -> 103345.74 | G11: ='Line Item Budget'!S57 -> 0 | H11: =F11+G11 -> 103345.74 | I11: ='Line Item Budget'!X57 -> 23573.137 | J11: ='Line Item Budget'!Y57 -> 0 | K11: =I11+J11 -> 23573.137 | L11: ='Line Item Budget'!Z57 -> 199312.63 | M11: ='Line Item Budget'!AA57 -> 0 | N11: =L11+M11 -> 199312.63
B12: G. Construction
B13: H. Other Direct Costs | C13: ='Line Item Budget'!L89 -> 12075 | D13: ='Line Item Budget'!M89 -> 0 | E13: =C13+D13 -> 12075 | F13: ='Line Item Budget'!R89 -> 20371.5 | G13: ='Line Item Budget'!S89 -> 0 | H13: =F13+G13 -> 20371.5 | I13: ='Line Item Budget'!X89 -> 2275 | J13: ='Line Item Budget'!Y89 -> 0 | K13: =I13+J13 -> 2275 | L13: ='Line Item Budget'!Z89 -> 34721.5 | M13: ='Line Item Budget'!AA89 -> 0 | N13: =L13+M13 -> 34721.5
B15: I. Total Direct Costs | C15: ='Line Item Budget'!L90 -> 184491.58 | D15: ='Line Item Budget'!M90 -> 0 | E15: =C15+D15 -> 184491.58 | F15: ='Line Item Budget'!R90 -> 226549.53 | G15: ='Line Item Budget'!S90 -> 0 | H15: =F15+G15 -> 226549.53 | I15: ='Line Item Budget'!W90 -> 71211.197 | J15: ='Line Item Budget'!Y90 -> 0 | K15: =I15+J15 -> 71211.197 | L15: ='Line Item Budget'!Z90 -> 482252.31 | M15: =SUM(M6:M13) -> 0 | N15: =L15+M15 -> 482252.31
B17: J. Indirect Costs | C17: ='Line Item Budget'!L92 -> 51657.642 | D17: ='Line Item Budget'!M92 -> 0 | E17: =C17+D17 -> 51657.642 | F17: ='Line Item Budget'!R92 -> 63433.868 | G17: ='Line Item Budget'!S92 -> 0 | H17: =F17+G17 -> 63433.868 | I17: ='Line Item Budget'!X92 -> 19939.135 | J17: ='Line Item Budget'!Y92 -> 0 | K17: =I17+J17 -> 19939.135 | L17: ='Line Item Budget'!Z92 -> 135030.65 | M17: ='Line Item Budget'!AA92 -> 0 | N17: =L17+M17 -> 135030.65
B19: K. Total Costs | C19: =C15+C17 -> 236149.22 | D19: =D15+D17 -> 0 | E19: =E15+E17 -> 236149.22 | F19: =F15+F17 -> 289983.4 | G19: =G15+G17 -> 0 | H19: =H15+H17 -> 289983.4 | I19: =I15+I17 -> 91150.333 | J19: =J15+J17 -> 0 | ... N19: =N15+N17 -> 617282.95
B24: SAMPLE

Sheet Line Item Budget
A1: Entity: | B1: P
A2: Program/Dept.: | B2: 20200 | E2: SAMPLE
A3: Funder-Grant: | B3: DOS452 | E3: *Key Personnel
E4: PARTNERS OF THE AMERICAS - MEXICO UNITED 2026
A5: Activity Code | B5: Object Code | C5: Country Code | D5: Office Code | E5: All costs in US$ | F5: Year 1 | N5: Year 2 | T5: Year 3 | Z5: Total
E6: Budget Line Items | F6: No. | G6: Unit Type | H6: Freq. | I6: % | J6: Rate | K6: Total | L6: DRL | M6: Cost Share | N6: No. | O6: Freq. | P6: Rate | Q6: Total | R6: DRL | S6: Cost Share | T6: No. | U6: Freq. | V6: Rate | W6: Total | X6: DRL | Y6: Cost Share | Z6: DRL | AA6: Cost Share | AB6: Grand Total
E7: A. Personnel
E8: A.1 Field Staff Salaries
A9: PERSNL-CD | B9: 70000 (Personnel)/ 81000 (Consultant) | C9: MEX | D9: MEX | E9: A.1.1 Program Coordinator (100%)* | F9: 1 | G9: Month | H9: 12 | I9: 1 | M9: =K9-L9 -> 0 | N9: =F9 -> 1 | O9: =H9 -> 12 | P9: =J9*1.035 -> 0 | Q9: =N9*P9*O9*I9 -> 0 | R9: =Q9 -> 0 | S9: =Q9-R9 -> 0 | T9: =N9 -> 1 | U9: 6 | V9: =P9*1.035 -> 0 | W9: =T9*V9*U9*I9 -> 0 | X9: =W9 -> 0 | Y9: =W9-X9 -> 0 | Z9: =L9+R9+X9 -> 0 | AA9: =M9+S9+Y9 -> 0 | AB9: =Z9+AA9 -> 0
A10: PERSNL-PS | B10: 70000 (Personnel)/ 81000 (Consultant) | C10: MEX | D10: MEX | E10: A.1.2 Program Specialist (50%) | F10: 1 | G10: Month | H10: 10 | I10: 0.5 | M10: 0 | N10: =F10 -> 1 | O10: 12 | P10: =J10*1.035 -> 0 | Q10: =N10*P10*O10*I10 -> 0 | R10: =Q10 -> 0 | S10: 0 | T10: =N10 -> 1 | U10: 4 | V10: =P10*1.035 -> 0 | W10: =T10*V10*U10*I10 -> 0 | X10: =W10 -> 0 | Y10: 0 | Z10: =L10+R10+X10 -> 0 | AA10: =M10+S10+Y10 -> 0 | AB10: =Z10+AA10 -> 0
A11: PERSNL-PA | B11: 70000 (Personnel)/ 81000 (Consultant) | C11: MEX | D11: MEX | E11: A.1.3 Program Assistant (50%) | F11: 1 | G11: Month | H11: 10 | I11: 0.5 | M11: 0 | N11: =F11 -> 1 | O11: 12 | P11: =J11*1.035 -> 0 | Q11: =N11*P11*O11*I11 -> 0 | R11: =Q11 -> 0 | S11: 0 | T11: =N11 -> 1 | U11: 4 | V11: =P11*1.035 -> 0 | W11: =T11*V11*U11*I11 -> 0 | X11: =W11 -> 0 | Y11: 0 | Z11: =L11+R11+X11 -> 0 | AA11: =M11+S11+Y11 -> 0 | AB11: =Z11+AA11 -> 0
A12: PERSNL-F&A | B12: 70000 (Personnel)/ 81000 (Consultant) | C12: MEX | D12: MEX | E12: A.1.4 Administration and Finance Officer (50%) | F12: 1 | G12: Month | H12: 10 | I12: 0.5 | M12: =K12-L12 -> 0 | N12: =F12 -> 1 | O12: 12 | P12: =J12*1.035 -> 0 | Q12: =N12*P12*O12*I12 -> 0 | R12: =Q12 -> 0 | S12: =Q12-R12 -> 0 | T12: =N12 -> 1 | U12: 4 | V12: =P12*1.035 -> 0 | W12: =T12*V12*U12*I12 -> 0 | X12: =W12 -> 0 | Y12: =W12-X12 -> 0 | Z12: =L12+R12+X12 -> 0 | AA12: =M12+S12+Y12 -> 0 | AB12: =Z12+AA12 -> 0
E13: A.2 HQ Staff Salaries
A14: PERSNL | B14: Timesheets | C14: 0 | D14: 0 | E14: A.2.1 Program Manager (HQ) (20%) | F14: 1 | G14: Month | H14: 12 | I14: 0.2 | M14: =K14-L14 -> 0 | N14: 1 | O14: =H14 -> 12 | P14: =J14*1.035 -> 0 | Q14: =N14*P14*O14*I14 -> 0 | R14: =Q14 -> 0 | S14: =Q14-R14 -> 0 | T14: 1 | U14: 6 | V14: =P14*1.035 -> 0 | W14: =T14*V14*U14*I14 -> 0 | X14: =W14 -> 0 | Y14: =W14-X14 -> 0 | Z14: =L14+R14+X14 -> 0 | AA14: =M14+S14+Y14 -> 0 | AB14: =Z14+AA14 -> 0
E15: Subtotal Personnel | K15: 54250 | L15: 54250 | M15: 0 | Q15: 59926.5 | R15: 59926.5 | S15: 0 | W15: 27101.992 | X15: 27101.992 | Y15: 0 | Z15: 141278.49 | AA15: 0 | AB15: 141278.49
E16: B. Fringe Benefits
E17: B.1 HQ Fringe Benefits
A18: FRINGE | B18: Timesheets | C18: 0 | D18: 0 | E18: B.1.1 U.S.-Based Personnel Fringe Benefits | G18: %/ Month | H18: 12 | I18: 0.2181 | J18: =J14 -> 0 | K18: =K14*I18 -> 0 | L18: =K18 -> 0 | M18: 0 | O18: =H18 -> 12 | P18: =P14 -> 0 | Q18: =Q14*I18 -> 0 | R18: =Q18 -> 0 | S18: =Q18-R18 -> 0 | U18: 6 | V18: =V14 -> 0 | W18: =W14*I18 -> 0 | X18: =W18 -> 0 | Y18: =W18-X18 -> 0 | Z18: =L18+R18+X18 -> 0 | AA18: =M18+S18+Y18 -> 0 | AB18: =Z18+AA18 -> 0
E19: B.2 Field Fringe Benefits
A20: FRINGE-MX | B20: 70015 | C20: MEX | D20: MEX | E20: B.2.1 Program Coordinator (100%) | G20: %/ Month | H20: =H9 -> 12 | I20: 0.5084 | J20: =J9 -> 0 | K20: =K9*I20 -> 0 | L20: =K20 -> 0 | M20: 0 | O20: 12 | P20: =P9 -> 0 | Q20: =Q9*I20 -> 0 | R20: =Q20 -> 0 | S20: =Q20-R20 -> 0 | U20: 4 | V20: =V9 -> 0 | W20: =W9*I20 -> 0 | X20: =W20 -> 0 | Y20: =W20-X20 -> 0 | Z20: =L20+R20+X20 -> 0 | AA20: =M20+S20+Y20 -> 0 | AB20: =Z20+AA20 -> 0
A21: FRINGE-MX | B21: 70015 | C21: MEX | D21: MEX | E21: B.2.2 Program Specialist (50%) | G21: %/ Month | H21: =H10 -> 10 | I21: 0.5084 | J21: =J10 -> 0 | K21: =K10*I21 -> 0 | L21: =K21 -> 0 | M21: 0 | O21: 12 | P21: =P10 -> 0 | Q21: =Q10*I21 -> 0 | R21: =Q21 -> 0 | S21: =Q21-R21 -> 0 | U21: 4 | V21: =V10 -> 0 | W21: =W10*I21 -> 0 | X21: =W21 -> 0 | Y21: =W21-X21 -> 0 | Z21: =L21+R21+X21 -> 0 | AA21: =M21+S21+Y21 -> 0 | AB21: =Z21+AA21 -> 0
A22: FRINGE-MX | B22: 70015 | C22: MEX | D22: MEX | E22: B.2.3 Program Assistant (50%) | G22: %/ Month | H22: =H11 -> 10 | I22: 0.5084 | J22: =J11 -> 0 | K22: =K11*I22 -> 0 | L22: =K22 -> 0 | M22: 0 | O22: 12 | P22: =P11 -> 0 | Q22: =Q11*I22 -> 0 | R22: =Q22 -> 0 | S22: =Q22-R22 -> 0 | U22: 4 | V22: =V11 -> 0 | W22: =W11*I22 -> 0 | X22: =W22 -> 0 | Y22: =W22-X22 -> 0 | Z22: =L22+R22+X22 -> 0 | AA22: =M22+S22+Y22 -> 0 | AB22: =Z22+AA22 -> 0
A23: FRINGE-MX | B23: 70015 | C23: MEX | D23: MEX | E23: B.2.4 Administration and Finance Officer (50%) | G23: %/ Month | H23: =H12 -> 10 | I23: 0.5084 | J23: =J12 -> 0 | K23: =K12*I23 -> 0 | L23: =K23 -> 0 | M23: 0 | O23: 12 | P23: =P12 -> 0 | Q23: =Q12*I23 -> 0 | R23: =Q23 -> 0 | S23: =Q23-R23 -> 0 | U23: 6 | V23: =V12 -> 0 | W23: =W12*I23 -> 0 | X23: =W23 -> 0 | Y23: =W23-X23 -> 0 | Z23: =L23+R23+X23 -> 0 | AA23: =M23+S23+Y23 -> 0 | AB23: =Z23+AA23 -> 0
E24: Subtotal Fringe Benefits | K24: 24793.82 | L24: 24793.82 | M24: 0 | Q24: 27582.212 | R24: 27582.212 | S24: 0 | W24: 12285.965 | X24: 12285.965 | Y24: 0 | Z24: 64661.997 | AA24: 0 | AB24: 64661.997
E25: C. Travel
E26: C.1 HQ Staff International Travel
A27: STFTRAVEL | B27: 86040 | C27: 0 | D27: 0 | E27: C.1.1 International Airfare (DC-MX) | F27: 1 | G27: Flight | H27: 1 | I27: 1 | J27: 450 | K27: =F27*J27*H27 -> 450 | L27: =K27 -> 450 | M27: =K27-L27 -> 0 | N27: 1 | O27: 1 | P27: =J27*1.02 -> 459 | Q27: =N27*P27*O27*I27 -> 459 | R27: =Q27 -> 459 | S27: =Q27-R27 -> 0 | T27: 1 | U27: 1 | V27: =P27*1.02 -> 468.18 | W27: =T27*V27*U27*I27 -> 468.18 | X27: =W27 -> 468.18 | Y27: =W27-X27 -> 0 | Z27: =L27+R27+X27 -> 1377.18 | AA27: =M27+S27+Y27 -> 0 | AB27: =Z27+AA27 -> 1377.18
A28: GROUNDTRAN | B28: 86000 | C28: 0 | D28: 0 | E28: C.1.2 Ground Transportation | F28: 1 | G28: Trip | H28: 1 | I28: 1 | J28: 100 | K28: =F28*J28*H28 -> 100 | L28: =K28 -> 100 | M28: =K28-L28 -> 0 | N28: 1 | O28: 1 | P28: =J28*1.02 -> 102 | Q28: =N28*P28*O28*I28 -> 102 | R28: =Q28 -> 102 | S28: =Q28-R28 -> 0 | T28: 1 | U28: 1 | V28: =P28*1.02 -> 104.04 | W28: =T28*V28*U28*I28 -> 104.04 | X28: =W28 -> 104.04 | Y28: =W28-X28 -> 0 | Z28: =L28+R28+X28 -> 306.04 | AA28: =M28+S28+Y28 -> 0 | AB28: =Z28+AA28 -> 306.04
A29: LODGING | B29: 86030 | C29: 0 | D29: 0 | E29: C.1.3 Lodging | F29: 1 | G29: Night | H29: 5 | I29: 1 | J29: 150 | K29: =F29*J29*H29 -> 750 | L29: =K29 -> 750 | M29: =K29-L29 -> 0 | N29: 1 | O29: 5 | P29: =J29*1.02 -> 153 | Q29: =N29*P29*O29*I29 -> 765 | R29: =Q29 -> 765 | S29: =Q29-R29 -> 0 | T29: 1 | U29: 5 | V29: =P29*1.02 -> 156.06 | W29: =T29*V29*U29*I29 -> 780.3 | X29: =W29 -> 780.3 | Y29: =W29-X29 -> 0 | Z29: =L29+R29+X29 -> 2295.3 | AA29: =M29+S29+Y29 -> 0 | AB29: =Z29+AA29 -> 2295.3
A30: STFCN DIEM | B30: 86050 | C30: 0 | D30: 0 | E30: C.1.4 M&IE | F30: 1 | G30: Day | H30: 5 | I30: 1 | J30: 106.2 | K30: =F30*J30*H30 -> 531 | L30: =K30 -> 531 | M30: =K30-L30 -> 0 | N30: 1 | O30: 5 | P30: =J30*1.02 -> 108.324 | Q30: =N30*P30*O30*I30 -> 541.62 | R30: =Q30 -> 541.62 | S30: =Q30-R30 -> 0 | T30: 1 | U30: 5 | V30: =P30*1.02 -> 110.49048 | W30: =T30*V30*U30*I30 -> 552.4524 | X30: =W30 -> 552.4524 | Y30: =W30-X30 -> 0 | Z30: =L30+R30+X30 -> 1625.0724 | AA30: =M30+S30+Y30 -> 0 | AB30: =Z30+AA30 -> 1625.0724
E31: C.2 Local Staff In-Country Travel
A32: LSLODGING | B32: 86030 | C32: MEX | D32: MEX | E32: C.2.1 Lodging | F32: 3 | G32: Night | H32: 8 | I32: 1 | J32: 100 | K32: =F32*J32*H32 -> 2400 | L32: =K32 -> 2400 | M32: =K32-L32 -> 0 | N32: 3 | O32: 8 | P32: =J32*1.02 -> 102 | Q32: =N32*P32*O32*I32 -> 2448 | R32: =Q32 -> 2448 | S32: =Q32-R32 -> 0 | T32: 3 | U32: 2 | V32: =P32*1.02 -> 104.04 | W32: =T32*V32*U32*I32 -> 624.24 | X32: =W32 -> 624.24 | Y32: =W32-X32 -> 0 | Z32: =L32+R32+X32 -> 5472.24 | AA32: =M32+S32+Y32 -> 0 | AB32: =Z32+AA32 -> 5472.24
A33: LSM&IE | B33: 86050 | C33: MEX | D33: MEX | E33: C.2.2 M&IE | F33: 3 | G33: Day | H33: 8 | I33: 1 | J33: 45.75 | K33: =F33*J33*H33 -> 1098 | L33: =K33 -> 1098 | M33: =K33-L33 -> 0 | N33: 3 | O33: 8 | P33: =J33*1.02 -> 46.665 | Q33: =N33*P33*O33*I33 -> 1119.96 | R33: =Q33 -> 1119.96 | S33: =Q33-R33 -> 0 | T33: 3 | U33: 2 | V33: =P33*1.02 -> 47.5983 | W33: =T33*V33*U33*I33 -> 285.5898 | X33: =W33 -> 285.5898 | Y33: =W33-X33 -> 0 | Z33: =L33+R33+X33 -> 2503.5498 | AA33: =M33+S33+Y33 -> 0 | AB33: =Z33+AA33 -> 2503.5498
A34: LSTRANS | B34: 86000 | C34: MEX | D34: MEX | E34: C.2.3 Ground Transportation | F34: 1 | G34: Month | H34: 10 | I34: 1 | J34: 150 | K34: =F34*J34*H34 -> 1500 | L34: =K34 -> 1500 | M34: =K34-L34 -> 0 | N34: 1 | O34: 12 | P34: =J34*1.02 -> 153 | Q34: =N34*P34*O34*I34 -> 1836 | R34: =Q34 -> 1836 | S34: =Q34-R34 -> 0 | T34: 1 | U34: 3 | V34: =P34*1.02 -> 156.06 | W34: =T34*V34*U34*I34 -> 468.18 | X34: =W34 -> 468.18 | Y34: =W34-X34 -> 0 | Z34: =L34+R34+X34 -> 3804.18 | AA34: =M34+S34+Y34 -> 0 | AB34: =Z34+AA34 -> 3804.18
A35: LSDOMAIR | B35: 86040 | C35: MEX | D35: MEX | E35: C.2.4 Domestic Airfare | F35: 1 | G35: Year | H35: 4 | I35: 1 | J35: 150 | K35: =F35*J35*H35 -> 600 | L35: =K35 -> 600 | M35: =K35-L35 -> 0 | N35: 1 | O35: 4 | P35: =J35*1.02 -> 153 | Q35: =N35*P35*O35*I35 -> 612 | R35: =Q35 -> 612 | S35: =Q35-R35 -> 0 | T35: 1 | U35: 2 | V35: =P35*1.02 -> 156.06 | W35: =T35*V35*U35*I35 -> 312.12 | X35: =W35 -> 312.12 | Y35: =W35-X35 -> 0 | Z35: =L35+R35+X35 -> 1524.12 | AA35: =M35+S35+Y35 -> 0 | AB35: =Z35+AA35 -> 1524.12
E36: C.3 Local Staff International Travel
A37: LOCAL TRVL | B37: 86000 | C37: MEX | D37: MEX | E37: C.3.1 DRL Labor Implementer Workshop Trip | F37: 1 | G37: Trip | H37: 1 | I37: 1 | J37: 5000 | K37: =F37*J37*H37 -> 5000 | L37: =K37 -> 5000 | M37: =K37-L37 -> 0 | N37: 1 | O37: 0 | P37: =J37*1.02 -> 5100 | Q37: =N37*P37*O37*I37 -> 0 | R37: =Q37 -> 0 | S37: =Q37-R37 -> 0 | T37: 1 | U37: 0 | V37: =P37*1.02 -> 5202 | W37: =T37*V37*U37*I37 -> 0 | X37: =W37 -> 0 | Y37: =W37-X37 -> 0 | Z37: =L37+R37+X37 -> 5000 | AA37: =M37+S37+Y37 -> 0 | AB37: =Z37+AA37 -> 5000
E38: Subtotal Travel | K38: =SUM(K27:K37) -> 12429 | L38: =SUM(L27:L37) -> 12429 | M38: =SUM(M27:M37) -> 0 | Q38: =SUM(Q27:Q37) -> 7883.58 | R38: =SUM(R27:R37) -> 7883.58 | S38: =SUM(S27:S37) -> 0 | W38: =SUM(W27:W37) -> 3595.1022 | X38: =SUM(X27:X37) -> 3595.1022 | Y38: =SUM(Y27:Y37) -> 0 | Z38: =SUM(Z27:Z37) -> 23907.682 | AA38: =SUM(AA27:AA37) -> 0 | AB38: =SUM(AB27:AB37) -> 23907.682
E39: D. Equipment
E40: E. Supplies
...

Sheet Cereal
C1: SUBGRANTEE: CEREAL
C2: Budget Line Items | D2: Description | E2: No. | F2: Rate | G2: Unit Type | H2: Frequency | I2: % | J2: YEAR 1 | M2: YEAR 2 | P2: YEAR 3 | S2: Total
J3: Total | K3: Grant | L3: Cost Share | M3: Total | N3: Grant | O3: Cost Share | P3: Total | Q3: Grant | R3: Cost Share | S3: Total | T3: Grant | U3: Cost Share
A4: Activity | B4: Object Code | C4: A. Personnel
A6: SUBCEREAL | B6: 7370 | C6: A.1 Project Coordinator (60%) | E6: 1 | F6: 1100 | G6: Month | H6: 8 | I6: 0.6 | J6: =(E6*F6*H6*I6) -> 5280 | K6: =J6 -> 5280 | L6: =J6-K6 -> 0 | M6: =(E6*F6*12*I6)*1.025 -> 8118 | N6: =M6 -> 8118 | O6: =M6-N6 -> 0 | P6: =((F6*1.025)*1.025)*I6*3 -> 2080.2375 | Q6: =P6 -> 2080.2375 | R6: =P6-Q6 -> 0 | S6: =J6+M6+P6 -> 15478.237 | T6: =K6+N6+Q6 -> 15478.237 | U6: =L6+O6+R6 -> 0
A7: SUBCEREAL | B7: 7370 | C7: A.1 Project Administrator (20%) | E7: 1 | F7: 1000 | G7: Month | H7: 8 | I7: 0.2 | J7: =(E7*F7*H7*I7) -> 1600 | K7: =J7 -> 1600 | L7: =J7-K7 -> 0 | M7: =(E7*F7*12*I7)*1.025 -> 2460 | N7: =M7 -> 2460 | O7: =M7-N7 -> 0 | P7: =((F7*1.025)*1.025)*I7*3 -> 630.375 | Q7: =P7 -> 630.375 | R7: =P7-Q7 -> 0 | S7: =J7+M7+P7 -> 4690.375 | T7: =K7+N7+Q7 -> 4690.375 | U7: =L7+O7+R7 -> 0
C8: Subtotal Personnel | J8: =SUM(J5:J7) -> 6880 | K8: =SUM(K5:K7) -> 6880 | L8: =SUM(L5:L7) -> 0 | M8: =SUM(M5:M7) -> 10578 | N8: =SUM(N5:N7) -> 10578 | O8: =SUM(O5:O7) -> 0 | P8: =SUM(P5:P7) -> 2710.6125 | Q8: =SUM(Q5:Q7) -> 2710.6125 | ... U8: =SUM(U5:U7) -> 0
C9: B. Fringe Benefits
A10: SUBCEREAL | B10: 7370 | C10: B.1 Project Coordinator (60%) | E10: 1 | F10: 1100 | G10: %/ Month | H10: 8 | I10: 0.3 | J10: =(J6*I10) -> 1584 | K10: =J10 -> 1584 | L10: =J10-K10 -> 0 | M10: =(I10*M6) -> 2435.4 | N10: =M10 -> 2435.4 | O10: =M10-N10 -> 0 | P10: =(I10*P6) -> 624.07125 | Q10: =P10 -> 624.07125 | R10: =P10-Q10 -> 0 | S10: =J10+M10+P10 -> 4643.4712 | T10: =K10+N10+Q10 -> 4643.4712 | U10: =L10+O10+R10 -> 0
A11: SUBCEREAL | B11: 7370 | C11: B.2 Project Administrator (20%) | E11: 1 | F11: 1000 | G11: %/ Month | H11: 8 | I11: 0.3 | J11: =(J7*I11) -> 480 | K11: =J11 -> 480 | L11: =J11-K11 -> 0 | M11: =(I11*M7) -> 738 | N11: =M11 -> 738 | O11: =M11-N11 -> 0 | P11: =(I11*P7) -> 189.1125 | Q11: =P11 -> 189.1125 | R11: =P11-Q11 -> 0 | S11: =J11+M11+P11 -> 1407.1125 | T11: =K11+N11+Q11 -> 1407.1125 | U11: =L11+O11+R11 -> 0
C12: Subtotal Fringe Benefits | J12: =SUM(J10:J11) -> 2064 | K12: =SUM(K10:K11) -> 2064 | L12: =SUM(L10:L11) -> 0 | M12: =SUM(M10:M11) -> 3173.4 | N12: =SUM(N10:N11) -> 3173.4 | O12: =SUM(O10:O11) -> 0 | P12: =SUM(P10:P11) -> 813.18375 | Q12: =SUM(Q10:Q11) -> 813.18375 | ... U12: =SUM(U10:U11) -> 0
C13: C. Travel
A14: SUBCEREAL | B14: 7370 | C14: C.1 Ground Transportation | E14: 1 | F14: 150 | G14: Monthly | H14: 5 | I14: 1 | J14: =(E14*F14*H14*I14) -> 750 | K14: =J14 -> 750 | L14: =J14-K14 -> 0 | M14: =(E14*F14*8*I14)*1.025 -> 1230 | N14: =M14 -> 1230 | O14: =M14-N14 -> 0 | P14: =(E14*(F14*1.025)*2*I14)*1.025 -> 315.1875 | Q14: =P14 -> 315.1875 | R14: =P14-Q14 -> 0 | S14: =J14+M14+P14 -> 2295.1875 | T14: =K14+N14+Q14 -> 2295.1875 | U14: =L14+O14+R14 -> 0
A15: SUBCEREAL | B15: 7370 | C15: C.2 Lodging | E15: =E7 -> 1 | F15: 300 | G15: Monthly | H15: 5 | I15: 1 | J15: =(E15*F15*H15*I15) -> 1500 | K15: =J15 -> 1500 | L15: =J15-K15 -> 0 | M15: =(E15*F15*8*I15)*1.025 -> 2460 | N15: =M15 -> 2460 | O15: =M15-N15 -> 0 | P15: =(E15*(F15*1.025)*2*I15)*1.025 -> 630.375 | Q15: =P15 -> 630.375 | R15: =P15-Q15 -> 0 | S15: =J15+M15+P15 -> 4590.375 | T15: =K15+N15+Q15 -> 4590.375 | U15: =L15+O15+R15 -> 0
A16: SUBCEREAL | B16: 7370 | C16: C.3 M&IE | E16: 1 | F16: 300 | G16: Monthly | H16: 5 | I16: 1 | J16: =(E16*F16*H16*I16) -> 1500 | K16: =J16 -> 1500 | L16: =J16-K16 -> 0 | M16: =(E16*F16*8*I16)*1.025 -> 2460 | N16: =M16 -> 2460 | O16: =M16-N16 -> 0 | P16: =(E16*(F16*1.025)*2*I16)*1.025 -> 630.375 | Q16: =P16 -> 630.375 | R16: =P16-Q16 -> 0 | S16: =J16+M16+P16 -> 4590.375 | T16: =K16+N16+Q16 -> 4590.375 | U16: =L16+O16+R16 -> 0
C17: Subtotal Travel | J17: =SUM(J14:J16) -> 3750 | K17: =SUM(K14:K16) -> 3750 | L17: =SUM(L14:L16) -> 0 | M17: =SUM(M14:M16) -> 6150 | N17: =SUM(N14:N16) -> 6150 | O17: =SUM(O14:O16) -> 0 | P17: =SUM(P14:P16) -> 1575.9375 | Q17: =SUM(Q14:Q16) -> 1575.9375 | ... U17: =SUM(U14:U16) -> 0
C18: D. Equipment
C19: E. Supplies
C20: F. Contractual and Subaward
C21: G. Construction
C22: H. Other Direct Costs
C23: Objectives and Activities
C24: O1: Increase workers’ knowledge of labor law, and ability to understand the applicability of labor regulations and international labor standards relevant to the United 2026 games.
C25: H.1: Activity 1: Expand educational programs led by labor rights organizations in Mexico with experience in popular education methods, to train workers on protections under Mexican labor law, international labor standards, business and human rights frameworks relevant to the United 2026 games, and the risks of the games for Mexican workers.
A26: SUBCEREAL | B26: 7370 | C26: H.1.1 Labor rights trainings for workers on labor law | E26: 1 | F26: 150 | G26: Workshop | H26: 4 | I26: 1 | J26: =E26*F26*H26*I26 -> 600 | K26: =J26 -> 600 | L26: =J26-K26 -> 0 | M26: =E26*F26*H26*I26 -> 600 | N26: =M26 -> 600 | O26: =M26-N26 -> 0 | P26: =E26*F26*0*I26 -> 0 | Q26: =P26 -> 0 | R26: =P26-Q26 -> 0 | S26: =J26+M26+P26 -> 1200 | T26: =K26+N26+Q26 -> 1200 | U26: =S26-T26 -> 0
A27: SUBCEREAL | B27: 7370 | C27: H.1.2 Printing of materials for labor rights trainings | E27: 1 | F27: 60 | G27: Workshop | H27: 4 | I27: 1 | J27: =F27*H27*I27 -> 240 | K27: =J27 -> 240 | L27: =J27-K27 -> 0 | M27: =F27*H27*I27 -> 240 | N27: =M27 -> 240 | O27: =M27-N27 -> 0 | P27: =E27*F27*0*I27 -> 0 | Q27: =P27 -> 0 | R27: =P27-Q27 -> 0 | S27: =J27+M27+P27 -> 480 | T27: =K27+N27+Q27 -> 480 | U27: =S27-T27 -> 0
A28: SUBCEREAL | B28: 7370 | C28: H.1.3 Lodging for participants | E28: 1 | F28: 300 | G28: Workshop | H28: 4 | I28: 1 | J28: =F28*H28*I28 -> 1200 | K28: =J28 -> 1200 | L28: =J28-K28 -> 0 | M28: =F28*H28*I28 -> 1200 | N28: =M28 -> 1200 | O28: =M28-N28 -> 0 | P28: =E28*F28*0*I28 -> 0 | Q28: =P28 -> 0 | R28: =P28-Q28 -> 0 | S28: =J28+M28+P28 -> 2400 | T28: =K28+N28+Q28 -> 2400 | U28: =S28-T28 -> 0
A29: SUBCEREAL | B29: 7370 | C29: H.1.4 Transportation for participants | E29: 1 | F29: 80 | G29: Workshop | H29: 4 | I29: 1 | J29: =F29*H29*I29 -> 320 | K29: =J29 -> 320 | L29: =J29-K29 -> 0 | M29: =F29*H29*I29 -> 320 | N29: =M29 -> 320 | O29: =M29-N29 -> 0 | P29: =E29*F29*0*I29 -> 0 | Q29: =P29 -> 0 | R29: =P29-Q29 -> 0 | S29: =J29+M29+P29 -> 640 | T29: =K29+N29+Q29 -> 640 | U29: =S29-T29 -> 0
A30: SUBCEREAL | B30: 7370 | C30: H.1.5 Worker outreach campaign | E30: 1 | F30: 300 | G30: Campaign | H30: 2 | I30: 1 | J30: =E30*F30*H30*I30 -> 600 | K30: =J30 -> 600 | L30: 0 | M30: =E30*F30*H30*I30 -> 600 | N30: =M30 -> 600 | O30: =M30-N30 -> 0 | P30: =E30*F30*0*I30 -> 0 | Q30: =P30 -> 0 | R30: =P30-Q30 -> 0 | S30: =J30+M30+P30 -> 1200 | T30: =K30+N30+Q30 -> 1200 | U30: =S30-T30 -> 0
C31: O2: Increase engagement and coordination between labor rights organizations, the private sector, and democratic, independent unions on the UHRS and around pre-games planning of United 2026 events, including the implementation of the human rights strategy in each host city, and ways that the Government of Mexico, FIFA and the Mexican National Soccer Federation will address and mitigate labor rights risks associated with the games.
C32: H.2 Activity 2: Establish and facilitate a civil society labor advisory network in Mexico.
A33: SUBCEREAL | B33: 7370 | C33: H.2.1 Coordination Meetings | E33: 1 | F33: 100 | G33: Meeting | H33: 3 | I33: 1 | J33: =E33*F33*H33*I33 -> 300 | K33: =J33 -> 300 | L33: =J33-K33 -> 0 | M33: =E33*F33*H33*I33 -> 300 | N33: =M33 -> 300 | O33: =M33-N33 -> 0 | P33: =E33*F33*2*I33 -> 200 | Q33: =P33 -> 200 | R33: =P33-Q33 -> 0 | S33: =J33+M33+P33 -> 800 | T33: =K33+N33+Q33 -> 800 | U33: =S33-T33 -> 0
C34: O4: Increase awareness among the general public of Mexico’s commitments to human rights in regard to the United 2026 games.
C35: H.3 Activity 5 - Provide technical assistance to civil society to develop a media campaign to socialize information of labor rights risks in preparation for the United 2026 games.
A36: SUBCEREAL | B36: 7370 | C36: H.3.1 United 2026 media campaign | E36: 1 | F36: 650 | G36: Campaign | H36: 1 | I36: 1 | J36: =E36*F36*H36*I36 -> 650 | K36: =J36 -> 650 | L36: 0 | M36: =E36*F36*H36*I36 -> 650 | N36: =M36 -> 650 | O36: =M36-N36 -> 0 | P36: =E36*F36*H36*I36 -> 650 | Q36: =P36 -> 650 | R36: =P36-Q36 -> 0 | S36: =J36+M36+P36 -> 1950 | T36: =K36+N36+Q36 -> 1950 | U36: =S36-T36 -> 0
C37: Subtotal Other Direct Costs | J37: =SUM(J26:J36) -> 3910 | K37: =SUM(K26:K36) -> 3910 | L37: =SUM(L24:L36) -> 0 | M37: =SUM(M26:M36) -> 3910 | N37: =SUM(N26:N36) -> 3910 | O37: =SUM(O24:O36) -> 0 | P37: =SUM(P26:P36) -> 850 | Q37: =SUM(Q26:Q36) -> 850 | R37: =SUM(R24:R36) -> 0 | S37: =SUM(S26:S36) -> 8670 | T37: =SUM(T26:T36) -> 8670 | U37: =SUM(U26:U36) -> 0
C38: I. Total Direct Costs | J38: =J8+J12+J17+J37 -> 16604 | K38: =J38 -> 16604 | L38: =J38-K38 -> 0 | M38: =M8+M12+M17+M37 -> 23811.4 | N38: =M38 -> 23811.4 | O38: =M38-N38 -> 0 | P38: =P8+P12+P17+P37 -> 5949.7338 | Q38: =P38 -> 5949.7338 | R38: =P38-Q38 -> 0 | S38: =S8+S12+S17+S37 -> 46365.134 | T38: =S38 -> 46365.134 | U38: =SUM(U8+U17+U37) -> 0
C39: J. Indirect Cost
A40: SUBCEREAL | B40: 7370 | C40: J.1 Administrative Cost (8%) | F40: 0.08 | I40: 1 | J40: =J38*F40*I40 -> 1328.32 | K40: =J40 -> 1328.32 | L40: =SUM(L38:L39) -> 0 | M40: =M38*F40*I40 -> 1904.912 | N40: =M40 -> 1904.912 | O40: =SUM(O38:O39) -> 0 | P40: =P38*F40*I40 -> 475.9787 | Q40: =P40 -> 475.9787 | R40: =SUM(R38:R39) -> 0 | S40: =J40+M40+P40 -> 3709.2107 | T40: =S40 -> 3709.2107 | U40: =S40-T40 -> 0
C41: J.2 Total Indirect Cost | J41: =J40 -> 1328.32 | K41: =K40 -> 1328.32 | L41: =L40 -> 0 | M41: =M40 -> 1904.912 | N41: =N40 -> 1904.912 | O41: =O40 -> 0 | P41: =P40 -> 475.9787 | Q41: =Q40 -> 475.9787 | ... U41: =U40 -> 0
...

Sheet CDM
C1: SUBGRANTEE: CENTRO DE LOS DERECHOS DEL MIGRANTE
A2: Activity Code | B2: Object Code | C2: Budget Line Items | D2: Description | E2: No. | F2: Rate | G2: Unit Type | H2: Frequency | I2: % | J2: YEAR 1 | M2: YEAR 2 | P2: YEAR 3 | S2: Total
J3: Total | K3: Grant | L3: Cost Share | M3: Total | N3: Grant | O3: Cost Share | P3: Total | Q3: Grant | R3: Cost Share | S3: Total | T3: Grant | U3: Cost Share
C4: A. Personnel
A6: SUBCDM | B6: 7370 | C6: A.1 Project Coordinator (60%) | E6: 1 | F6: 1100 | G6: Month | H6: 8 | I6: 0.6 | J6: =(E6*F6*H6*I6) -> 5280 | K6: =J6 -> 5280 | L6: =J6-K6 -> 0 | M6: =(E6*F6*12*I6)*1.025 -> 8118 | N6: =M6 -> 8118 | O6: =M6-N6 -> 0 | P6: =((F6*1.025)*1.025)*I6*3 -> 2080.2375 | Q6: =P6 -> 2080.2375 | R6: =P6-Q6 -> 0 | S6: =J6+M6+P6 -> 15478.237 | T6: =K6+N6+Q6 -> 15478.237 | U6: =L6+O6+R6 -> 0
A7: SUBCDM | B7: 7370 | C7: A.2 Project Administrator (20%) | E7: 1 | F7: 1000 | G7: Month | H7: 8 | I7: 0.2 | J7: =(E7*F7*H7*I7) -> 1600 | K7: =J7 -> 1600 | L7: =J7-K7 -> 0 | M7: =(E7*F7*12*I7)*1.025 -> 2460 | N7: =M7 -> 2460 | O7: =M7-N7 -> 0 | P7: =((F7*1.025)*1.025)*I7*3 -> 630.375 | Q7: =P7 -> 630.375 | R7: =P7-Q7 -> 0 | S7: =J7+M7+P7 -> 4690.375 | T7: =K7+N7+Q7 -> 4690.375 | U7: =L7+O7+R7 -> 0
C8: Subtotal Personnel | J8: =SUM(J5:J7) -> 6880 | K8: =SUM(K5:K7) -> 6880 | L8: =SUM(L5:L7) -> 0 | M8: =SUM(M5:M7) -> 10578 | N8: =SUM(N5:N7) -> 10578 | O8: =SUM(O5:O7) -> 0 | P8: =SUM(P5:P7) -> 2710.6125 | Q8: =SUM(Q5:Q7) -> 2710.6125 | ... U8: =SUM(U5:U7) -> 0
C9: B. Fringe Benefits
A10: SUBCDM | B10: 7370 | C10: B.1 Project Coordinator (60%) | E10: 1 | F10: 1100 | G10: %/ Month | H10: 8 | I10: 0.3 | J10: =(J6*I10) -> 1584 | K10: =J10 -> 1584 | L10: =J10-K10 -> 0 | M10: =(I10*M6) -> 2435.4 | N10: =M10 -> 2435.4 | O10: =M10-N10 -> 0 | P10: =(I10*P6) -> 624.07125 | Q10: =P10 -> 624.07125 | R10: =P10-Q10 -> 0 | S10: =J10+M10+P10 -> 4643.4712 | T10: =K10+N10+Q10 -> 4643.4712 | U10: =L10+O10+R10 -> 0
A11: SUBCDM | B11: 7370 | C11: B.2 Project Administrator (20%) | E11: 1 | F11: 1000 | G11: %/ Month | H11: 8 | I11: 0.3 | J11: =(J7*I11) -> 480 | K11: =J11 -> 480 | L11: =J11-K11 -> 0 | M11: =(I11*M7) -> 738 | N11: =M11 -> 738 | O11: =M11-N11 -> 0 | P11: =(I11*P7) -> 189.1125 | Q11: =P11 -> 189.1125 | R11: =P11-Q11 -> 0 | S11: =J11+M11+P11 -> 1407.1125 | T11: =K11+N11+Q11 -> 1407.1125 | U11: =L11+O11+R11 -> 0
C12: Subtotal Fringe Benefits | J12: =SUM(J10:J11) -> 2064 | K12: =SUM(K10:K11) -> 2064 | L12: =SUM(L10:L11) -> 0 | M12: =SUM(M10:M11) -> 3173.4 | N12: =SUM(N10:N11) -> 3173.4 | O12: =SUM(O10:O11) -> 0 | P12: =SUM(P10:P11) -> 813.18375 | Q12: =SUM(Q10:Q11) -> 813.18375 | ... U12: =SUM(U10:U11) -> 0
C13: C. Travel
A14: SUBCDM | B14: 7370 | C14: C.1 Ground Transportation | E14: 1 | F14: 150 | G14: Monthly | H14: 6 | I14: 1 | J14: =(E14*F14*H14*I14) -> 900 | K14: =J14 -> 900 | L14: =J14-K14 -> 0 | M14: =(E14*F14*8*I14)*1.025 -> 1230 | N14: =M14 -> 1230 | O14: =M14-N14 -> 0 | P14: =(E14*(F14*1.025)*2*I14)*1.025 -> 315.1875 | Q14: =P14 -> 315.1875 | R14: =P14-Q14 -> 0 | S14: =J14+M14+P14 -> 2445.1875 | T14: =K14+N14+Q14 -> 2445.1875 | U14: =L14+O14+R14 -> 0
A15: SUBCDM | B15: 7370 | C15: C.2 Lodging | E15: =E7 -> 1 | F15: 300 | G15: Monthly | H15: 6 | I15: 1 | J15: =(E15*F15*H15*I15) -> 1800 | K15: =J15 -> 1800 | L15: =J15-K15 -> 0 | M15: =(E15*F15*8*I15)*1.025 -> 2460 | N15: =M15 -> 2460 | O15: =M15-N15 -> 0 | P15: =(E15*(F15*1.025)*2*I15)*1.025 -> 630.375 | Q15: =P15 -> 630.375 | R15: =P15-Q15 -> 0 | S15: =J15+M15+P15 -> 4890.375 | T15: =K15+N15+Q15 -> 4890.375 | U15: =L15+O15+R15 -> 0
A16: SUBCDM | B16: 7370 | C16: C.3 M&IE | E16: 1 | F16: 300 | G16: Monthly | H16: 6 | I16: 1 | J16: =(E16*F16*H16*I16) -> 1800 | K16: =J16 -> 1800 | L16: =J16-K16 -> 0 | M16: =(E16*F16*8*I16)*1.025 -> 2460 | N16: =M16 -> 2460 | O16: =M16-N16 -> 0 | P16: =(E16*(F16*1.025)*2*I16)*1.025 -> 630.375 | Q16: =P16 -> 630.375 | R16: =P16-Q16 -> 0 | S16: =J16+M16+P16 -> 4890.375 | T16: =K16+N16+Q16 -> 4890.375 | U16: =L16+O16+R16 -> 0
C17: Subtotal Travel | J17: =SUM(J14:J16) -> 4500 | K17: =SUM(K14:K16) -> 4500 | L17: =SUM(L14:L16) -> 0 | M17: =SUM(M14:M16) -> 6150 | N17: =SUM(N14:N16) -> 6150 | O17: =SUM(O14:O16) -> 0 | P17: =SUM(P14:P16) -> 1575.9375 | Q17: =SUM(Q14:Q16) -> 1575.9375 | ... U17: =SUM(U14:U16) -> 0
C18: D. Equipment
C19: E. Supplies
C20: F. Contractual and Subaward
C21: G. Construction
C22: H. Other Direct Costs
C23: Objectives and Activities
C24: O1: Increase workers’ knowledge of labor law, and ability to understand the applicability of labor regulations and international labor standards relevant to the United 2026 games.
C25: H.1: Activity 1: Expand educational programs led by labor rights organizations in Mexico with experience in popular education methods, to train workers on protections under Mexican labor law, international labor standards, business and human rights frameworks relevant to the United 2026 games, and the risks of the games for Mexican workers.
A26: SUBCDM | B26: 7370 | C26: H.1.1 Labor rights trainings for workers on labor law | E26: 1 | F26: 150 | G26: Workshop | H26: 4 | I26: 1 | J26: =E26*F26*H26*I26 -> 600 | K26: =J26 -> 600 | L26: =J26-K26 -> 0 | M26: =E26*F26*H26*I26 -> 600 | N26: =M26 -> 600 | O26: =M26-N26 -> 0 | P26: =E26*F26*0*I26 -> 0 | Q26: =P26 -> 0 | R26: =P26-Q26 -> 0 | S26: =J26+M26+P26 -> 1200 | T26: =K26+N26+Q26 -> 1200 | U26: =S26-T26 -> 0
A27: SUBCDM | B27: 7370 | C27: H.1.2 Printing of materials for labor rights trainings | E27: 1 | F27: 60 | G27: Workshop | H27: 4 | I27: 1 | J27: =F27*H27*I27 -> 240 | K27: =J27 -> 240 | L27: =J27-K27 -> 0 | M27: =F27*H27*I27 -> 240 | N27: =M27 -> 240 | O27: =M27-N27 -> 0 | P27: =E27*F27*0*I27 -> 0 | Q27: =P27 -> 0 | R27: =P27-Q27 -> 0 | S27: =J27+M27+P27 -> 480 | T27: =K27+N27+Q27 -> 480 | U27: =S27-T27 -> 0
A28: SUBCDM | B28: 7370 | C28: H.1.3 Lodging for participants | E28: 1 | F28: 300 | G28: Workshop | H28: 4 | I28: 1 | J28: =F28*H28*I28 -> 1200 | K28: =J28 -> 1200 | L28: =J28-K28 -> 0 | M28: =F28*H28*I28 -> 1200 | N28: =M28 -> 1200 | O28: =M28-N28 -> 0 | P28: =E28*F28*0*I28 -> 0 | Q28: =P28 -> 0 | R28: =P28-Q28 -> 0 | S28: =J28+M28+P28 -> 2400 | T28: =K28+N28+Q28 -> 2400 | U28: =S28-T28 -> 0
A29: SUBCDM | B29: 7370 | C29: H.1.4 Transportation for participants | E29: 1 | F29: 80 | G29: Workshop | H29: 4 | I29: 1 | J29: =F29*H29*I29 -> 320 | K29: =J29 -> 320 | L29: =J29-K29 -> 0 | M29: =F29*H29*I29 -> 320 | N29: =M29 -> 320 | O29: =M29-N29 -> 0 | P29: =E29*F29*0*I29 -> 0 | Q29: =P29 -> 0 | R29: =P29-Q29 -> 0 | S29: =J29+M29+P29 -> 640 | T29: =K29+N29+Q29 -> 640 | U29: =S29-T29 -> 0
A30: SUBCDM | B30: 7370 | C30: H.1.5 Worker outreach campaign | E30: 1 | F30: 300 | G30: Campaign | H30: 2 | I30: 1 | J30: =E30*F30*H30*I30 -> 600 | K30: =J30 -> 600 | L30: 0 | M30: =E30*F30*H30*I30 -> 600 | N30: =M30 -> 600 | O30: =M30-N30 -> 0 | P30: =E30*F30*0*I30 -> 0 | Q30: =P30 -> 0 | R30: =P30-Q30 -> 0 | S30: =J30+M30+P30 -> 1200 | T30: =K30+N30+Q30 -> 1200 | U30: =S30-T30 -> 0
C31: O2: Increase engagement and coordination between labor rights organizations, the private sector, and democratic, independent unions on the UHRS and around pre-games planning of United 2026 events, including the implementation of the human rights strategy in each host city, and ways that the Government of Mexico, FIFA and the Mexican National Soccer Federation will address and mitigate labor rights risks associated with the games.
C32: H.2 Activity 2: Establish and facilitate a civil society labor advisory network in Mexico.
A33: SUBCDM | B33: 7370 | C33: H.2.1 Coordination Meetings | E33: 1 | F33: 100 | G33: Meeting | H33: 3 | I33: 1 | J33: =E33*F33*H33*I33 -> 300 | K33: =J33 -> 300 | L33: =J33-K33 -> 0 | M33: =E33*F33*H33*I33 -> 300 | N33: =M33 -> 300 | O33: =M33-N33 -> 0 | P33: =E33*F33*2*I33 -> 200 | Q33: =P33 -> 200 | R33: =P33-Q33 -> 0 | S33: =J33+M33+P33 -> 800 | T33: =K33+N33+Q33 -> 800 | U33: =S33-T33 -> 0
C34: O4: Increase awareness among the general public of Mexico’s commitments to human rights in regard to the United 2026 games.
C35: H.3: Activity 5 - Provide technical assistance to civil society to develop a media campaign to socialize information of labor rights risks in preparation for the United 2026 games
A36: SUBCDM | B36: 7370 | C36: H.3.1 Website for labor rights violations | E36: 1 | F36: 1500 | G36: Website | H36: 1 | I36: 1 | J36: =E36*F36*0*I36 -> 0 | K36: =J36 -> 0 | L36: 0 | M36: =E36*F36*H36*I36 -> 1500 | N36: =M36 -> 1500 | O36: =M36-N36 -> 0 | P36: =E36*F36*0*I36 -> 0 | Q36: =P36 -> 0 | R36: =P36-Q36 -> 0 | S36: =J36+M36+P36 -> 1500 | T36: =K36+N36+Q36 -> 1500 | U36: =S36-T36 -> 0
A37: SUBCDM | B37: 7370 | C37: H.3.2 United 2026 media campaign | E37: 1 | F37: 500 | G37: Campaign | H37: 1 | I37: 1 | J37: =E37*F37*H37*I37 -> 500 | K37: =J37 -> 500 | L37: 0 | M37: =E37*F37*H37*I37 -> 500 | N37: =M37 -> 500 | O37: =M37-N37 -> 0 | P37: =E37*F37*H37*I37 -> 500 | Q37: =P37 -> 500 | R37: =P37-Q37 -> 0 | S37: =J37+M37+P37 -> 1500 | T37: =K37+N37+Q37 -> 1500 | U37: =S37-T37 -> 0
A38: SUBCDM | B38: 7370 | C38: H.3.2 Information sessions for the general public | E38: 1 | F38: 300 | G38: Event | H38: 2 | I38: 1 | J38: =E38*F38*H38*I38 -> 600 | K38: =J38 -> 600 | L38: 0 | M38: =E38*F38*H38*I38 -> 600 | N38: =M38 -> 600 | O38: =M38-N38 -> 0 | P38: =E38*F38*H38*I38 -> 600 | Q38: =P38 -> 600 | R38: =P38-Q38 -> 0 | S38: =J38+M38+P38 -> 1800 | T38: =K38+N38+Q38 -> 1800 | U38: =S38-T38 -> 0
A39: SUBCDM | B39: 7370 | C39: H.3.4 Development/Printing of materials for information sessions | E39: 1 | F39: 100 | G39: Event | H39: 2 | I39: 1 | J39: =E39*F39*H39*I39 -> 200 | K39: =J39 -> 200 | L39: 0 | M39: =E39*F39*H39*I39 -> 200 | N39: =M39 -> 200 | O39: =M39-N39 -> 0 | P39: =E39*F39*H39*I39 -> 200 | Q39: =P39 -> 200 | R39: =P39-Q39 -> 0 | S39: =J39+M39+P39 -> 600 | T39: =K39+N39+Q39 -> 600 | U39: =S39-T39 -> 0
C40: Subtotal Other Direct Costs | J40: =SUM(J26:J39) -> 4560 | K40: =SUM(K26:K39) -> 4560 | L40: =SUM(L26:L39) -> 0 | M40: =SUM(M26:M39) -> 6060 | N40: =SUM(N26:N39) -> 6060 | O40: =SUM(O26:O39) -> 0 | P40: =SUM(P26:P39) -> 1500 | Q40: =SUM(Q26:Q39) -> 1500 | ... U40: =SUM(U26:U39) -> 0
C41: I. Total Direct Costs | J41: =J8+J12+J17+J40 -> 18004 | K41: =J41 -> 18004 | L41: =J41-K41 -> 0 | M41: =M8+M12+M17+M40 -> 25961.4 | N41: =M41 -> 25961.4 | O41: =M41-N41 -> 0 | P41: =P8+P12+P17+P40 -> 6599.7338 | Q41: =P41 -> 6599.7338 | R41: =P41-Q41 -> 0 | S41: =S8+S12+S17+S40 -> 50565.134 | T41: =S41 -> 50565.134 | U41: =SUM(U8+U17+U40) -> 0
...

Sheet RMS
C1: SUBGRANTEE: RED DE MUJERES SINDICALISTAS
A2: Activity Code | B2: Object Code | C2: Budget Line Items | D2: Description | E2: No. | F2: Rate | G2: Unit Type | H2: Frequency | I2: % | J2: YEAR 1 | M2: YEAR 2 | P2: YEAR 3 | S2: Total
J3: Total | K3: Grant | L3: Cost Share | M3: Total | N3: Grant | O3: Cost Share | P3: Total | Q3: Grant | R3: Cost Share | S3: Total | T3: Grant | U3: Cost Share
C4: A. Personnel
A5: SUBRMS | B5: 7370 | C5: A.1 Project Coordinator (60%) | E5: 1 | F5: 1100 | G5: Month | H5: 8 | I5: 0.6 | J5: =(E5*F5*H5*I5) -> 5280 | K5: =J5 -> 5280 | L5: =J5-K5 -> 0 | M5: =(E5*F5*12*I5)*1.025 -> 8118 | N5: =M5 -> 8118 | O5: =M5-N5 -> 0 | P5: =((F5*1.025)*1.025)*I5*3 -> 2080.2375 | Q5: =P5 -> 2080.2375 | R5: =P5-Q5 -> 0 | S5: =J5+M5+P5 -> 15478.237 | T5: =K5+N5+Q5 -> 15478.237 | U5: =L5+O5+R5 -> 0
A6: SUBRMS | B6: 7370 | C6: A.2 Project Administrator (20%) | E6: 1 | F6: 1000 | G6: Month | H6: 8 | I6: 0.2 | J6: =(E6*F6*H6*I6) -> 1600 | K6: =J6 -> 1600 | L6: =J6-K6 -> 0 | M6: =(E6*F6*12*I6)*1.025 -> 2460 | N6: =M6 -> 2460 | O6: =M6-N6 -> 0 | P6: =((F6*1.025)*1.025)*I6*3 -> 630.375 | Q6: =P6 -> 630.375 | R6: =P6-Q6 -> 0 | S6: =J6+M6+P6 -> 4690.375 | T6: =K6+N6+Q6 -> 4690.375 | U6: =L6+O6+R6 -> 0
C7: Subtotal Personnel | J7: =SUM(J5:J6) -> 6880 | K7: =SUM(K5:K6) -> 6880 | L7: =SUM(L5:L6) -> 0 | M7: =SUM(M5:M6) -> 10578 | N7: =SUM(N5:N6) -> 10578 | O7: =SUM(O5:O6) -> 0 | P7: =SUM(P5:P6) -> 2710.6125 | Q7: =SUM(Q5:Q6) -> 2710.6125 | ... U7: =SUM(U5:U6) -> 0
C8: B. Fringe Benefits
A9: SUBRMS | B9: 7370 | C9: B.1 Project Coordinator (60%) | E9: 1 | F9: 1100 | G9: %/ Month | H9: 8 | I9: 0.3 | J9: =(J5*I9) -> 1584 | K9: =J9 -> 1584 | L9: =J9-K9 -> 0 | M9: =(I9*M5) -> 2435.4 | N9: =M9 -> 2435.4 | O9: =M9-N9 -> 0 | P9: =(I9*P5) -> 624.07125 | Q9: =P9 -> 624.07125 | R9: =P9-Q9 -> 0 | S9: =J9+M9+P9 -> 4643.4712 | T9: =K9+N9+Q9 -> 4643.4712 | U9: =L9+O9+R9 -> 0
A10: SUBRMS | B10: 7370 | C10: B.2 Project Administrator (20%) | E10: 1 | F10: 1000 | G10: %/ Month | H10: 8 | I10: 0.3 | J10: =(J6*I10) -> 480 | K10: =J10 -> 480 | L10: =J10-K10 -> 0 | M10: =(I10*M6) -> 738 | N10: =M10 -> 738 | O10: =M10-N10 -> 0 | P10: =(I10*P6) -> 189.1125 | Q10: =P10 -> 189.1125 | R10: =P10-Q10 -> 0 | S10: =J10+M10+P10 -> 1407.1125 | T10: =K10+N10+Q10 -> 1407.1125 | U10: =L10+O10+R10 -> 0
C11: Subtotal Fringe Benefits | J11: =SUM(J9:J10) -> 2064 | K11: =SUM(K9:K10) -> 2064 | L11: =SUM(L9:L10) -> 0 | M11: =SUM(M9:M10) -> 3173.4 | N11: =SUM(N9:N10) -> 3173.4 | O11: =SUM(O9:O10) -> 0 | P11: =SUM(P9:P10) -> 813.18375 | Q11: =SUM(Q9:Q10) -> 813.18375 | ... U11: =SUM(U9:U10) -> 0
C12: C. Travel
A13: SUBRMS | B13: 7370 | C13: C.1 Ground Transportation | E13: 1 | F13: 150 | G13: Monthly | H13: 6 | I13: 1 | J13: =(E13*F13*H13*I13) -> 900 | K13: =J13 -> 900 | L13: =J13-K13 -> 0 | M13: =(E13*F13*8*I13)*1.025 -> 1230 | N13: =M13 -> 1230 | O13: =M13-N13 -> 0 | P13: =(E13*(F13*1.025)*2*I13)*1.025 -> 315.1875 | Q13: =P13 -> 315.1875 | R13: =P13-Q13 -> 0 | S13: =J13+M13+P13 -> 2445.1875 | T13: =K13+N13+Q13 -> 2445.1875 | U13: =L13+O13+R13 -> 0
A14: SUBRMS | B14: 7370 | C14: C.2 Lodging | E14: =E6 -> 1 | F14: 300 | G14: Monthly | H14: 6 | I14: 1 | J14: =(E14*F14*H14*I14) -> 1800 | K14: =J14 -> 1800 | L14: =J14-K14 -> 0 | M14: =(E14*F14*8*I14)*1.025 -> 2460 | N14: =M14 -> 2460 | O14: =M14-N14 -> 0 | P14: =(E14*(F14*1.025)*2*I14)*1.025 -> 630.375 | Q14: =P14 -> 630.375 | R14: =P14-Q14 -> 0 | S14: =J14+M14+P14 -> 4890.375 | T14: =K14+N14+Q14 -> 4890.375 | U14: =L14+O14+R14 -> 0
A15: SUBRMS | B15: 7370 | C15: C.3 M&IE | E15: 1 | F15: 300 | G15: Monthly | H15: 6 | I15: 1 | J15: =(E15*F15*H15*I15) -> 1800 | K15: =J15 -> 1800 | L15: =J15-K15 -> 0 | M15: =(E15*F15*8*I15)*1.025 -> 2460 | N15: =M15 -> 2460 | O15: =M15-N15 -> 0 | P15: =(E15*(F15*1.025)*2*I15)*1.025 -> 630.375 | Q15: =P15 -> 630.375 | R15: =P15-Q15 -> 0 | S15: =J15+M15+P15 -> 4890.375 | T15: =K15+N15+Q15 -> 4890.375 | U15: =L15+O15+R15 -> 0
C16: Subtotal Travel | J16: =SUM(J13:J15) -> 4500 | K16: =SUM(K13:K15) -> 4500 | L16: =SUM(L13:L15) -> 0 | M16: =SUM(M13:M15) -> 6150 | N16: =SUM(N13:N15) -> 6150 | O16: =SUM(O13:O15) -> 0 | P16: =SUM(P13:P15) -> 1575.9375 | Q16: =SUM(Q13:Q15) -> 1575.9375 | ... U16: =SUM(U13:U15) -> 0
C17: D. Equipment
C18: E. Supplies
C19: F. Contractual and Subaward
C20: G. Construction
C21: H. Other Direct Costs
C22: Objectives and Activities
C23: O1: Increase workers’ knowledge of labor law, and ability to understand the applicability of labor regulations and international labor standards relevant to the United 2026 games.
C24: H.1: Activity 1: Expand educational programs led by labor rights organizations in Mexico with experience in popular education methods, to train workers on protections under Mexican labor law, international labor standards, business and human rights frameworks relevant to the United 2026 games, and the risks of the games for Mexican workers.
A25: SUBRMS | B25: 7370 | C25: H.1.1 Labor rights trainings for workers on labor law (including venue and materials) | E25: 1 | F25: 150 | G25: Workshop | H25: 4 | I25: 1 | J25: =E25*F25*H25*I25 -> 600 | K25: =J25 -> 600 | L25: =J25-K25 -> 0 | M25: =E25*F25*H25*I25 -> 600 | N25: =M25 -> 600 | O25: =M25-N25 -> 0 | P25: =E25*F25*0*I25 -> 0 | Q25: =P25 -> 0 | R25: =P25-Q25 -> 0 | S25: =J25+M25+P25 -> 1200 | T25: =K25+N25+Q25 -> 1200 | U25: =S25-T25 -> 0
A26: SUBRMS | B26: 7370 | C26: H.1.2 Printing of materials for labor rights trainings | E26: 1 | F26: 60 | G26: Workshop | H26: 4 | I26: 1 | J26: =F26*H26*I26 -> 240 | K26: =J26 -> 240 | L26: =J26-K26 -> 0 | M26: =F26*H26*I26 -> 240 | N26: =M26 -> 240 | O26: =M26-N26 -> 0 | P26: =E26*F26*0*I26 -> 0 | Q26: =P26 -> 0 | R26: =P26-Q26 -> 0 | S26: =J26+M26+P26 -> 480 | T26: =K26+N26+Q26 -> 480 | U26: =S26-T26 -> 0
A27: SUBRMS | B27: 7370 | C27: H.1.3 Lodging for participants | E27: 1 | F27: 300 | G27: Workshop | H27: 4 | I27: 1 | J27: =F27*H27*I27 -> 1200 | K27: =J27 -> 1200 | L27: =J27-K27 -> 0 | M27: =F27*H27*I27 -> 1200 | N27: =M27 -> 1200 | O27: =M27-N27 -> 0 | P27: =E27*F27*0*I27 -> 0 | Q27: =P27 -> 0 | R27: =P27-Q27 -> 0 | S27: =J27+M27+P27 -> 2400 | T27: =K27+N27+Q27 -> 2400 | U27: =S27-T27 -> 0
A28: SUBRMS | B28: 7370 | C28: H.1.4 Transportation for participants | E28: 1 | F28: 80 | G28: Workshop | H28: 4 | I28: 1 | J28: =F28*H28*I28 -> 320 | K28: =J28 -> 320 | L28: =J28-K28 -> 0 | M28: =F28*H28*I28 -> 320 | N28: =M28 -> 320 | O28: =M28-N28 -> 0 | P28: =E28*F28*0*I28 -> 0 | Q28: =P28 -> 0 | R28: =P28-Q28 -> 0 | S28: =J28+M28+P28 -> 640 | T28: =K28+N28+Q28 -> 640 | U28: =S28-T28 -> 0
A29: SUBRMS | B29: 7370 | C29: H.1.5 Worker outreach campaign | E29: 1 | F29: 300 | G29: Campaign | H29: 2 | I29: 1 | J29: =E29*F29*H29*I29 -> 600 | K29: =J29 -> 600 | L29: 0 | M29: =E29*F29*H29*I29 -> 600 | N29: =M29 -> 600 | O29: =M29-N29 -> 0 | P29: =E29*F29*0*I29 -> 0 | Q29: =P29 -> 0 | R29: =P29-Q29 -> 0 | S29: =J29+M29+P29 -> 1200 | T29: =K29+N29+Q29 -> 1200 | U29: =S29-T29 -> 0
C30: O2: Increase engagement and coordination between labor rights organizations, the private sector, and democratic, independent unions on the UHRS and around pre-games planning of United 2026 events, including the implementation of the human rights strategy in each host city, and ways that the Government of Mexico, FIFA and the Mexican National Soccer Federation will address and mitigate labor rights risks associated with the games.
C31: H.2 Activity 2- Establish and facilitate a civil society labor advisory network in Mexico
A32: SUBRMS | B32: 7370 | C32: H.2.1 Coordination meetings (including materials) | E32: 1 | F32: 120 | G32: Meeting | H32: 3 | I32: 1 | J32: =E32*H32*F32*I32 -> 360 | K32: =J32 -> 360 | L32: 0 | M32: =E32*F32*H32*I32 -> 360 | N32: =M32 -> 360 | O32: =M32-N32 -> 0 | P32: =0*F32*H32*I32 -> 0 | Q32: =P32 -> 0 | R32: =P32-Q32 -> 0 | S32: =J32+M32+P32 -> 720 | T32: =K32+N32+Q32 -> 720 | U32: =S32-T32 -> 0
C33: O4: Increase awareness among the general public of Mexico’s commitments to human rights in regard to the United 2026 games.
C34: H.3: Activity 5 - Provide technical assistance to civil society to develop a media campaign to socialize information of labor rights risks in preparation for the United 2026 games.
A35: SUBRMS | B35: 7370 | C35: H.3.1 United 2026 media campaign | E35: 1 | F35: 600 | G35: Campaign | H35: 1 | I35: 1 | J35: =E35*F35*H35*I35 -> 600 | K35: =J35 -> 600 | L35: 0 | M35: =E35*F35*H35*I35 -> 600 | N35: =M35 -> 600 | O35: =M35-N35 -> 0 | P35: =E35*F35*H35*I35 -> 600 | Q35: =P35 -> 600 | R35: =P35-Q35 -> 0 | S35: =J35+M35+P35 -> 1800 | T35: =K35+N35+Q35 -> 1800 | U35: =S35-T35 -> 0
A36: SUBRMS | B36: 7370 | C36: H.3.2 Information sessions for the general public | E36: 1 | F36: 300 | G36: Event | H36: 2 | I36: 1 | J36: =E36*F36*H36*I36 -> 600 | K36: =J36 -> 600 | L36: 0 | M36: =E36*F36*H36*I36 -> 600 | N36: =M36 -> 600 | O36: =M36-N36 -> 0 | P36: =E36*F36*H36*I36 -> 600 | Q36: =P36 -> 600 | R36: =P36-Q36 -> 0 | S36: =J36+M36+P36 -> 1800 | T36: =K36+N36+Q36 -> 1800 | U36: =S36-T36 -> 0
A37: SUBRMS | B37: 7370 | C37: H.3.3 Development/Printing of materials for information sessions | E37: 1 | F37: 100 | G37: Event | H37: 2 | I37: 1 | J37: =E37*F37*H37*I37 -> 200 | K37: =J37 -> 200 | L37: 0 | M37: =E37*F37*H37*I37 -> 200 | N37: =M37 -> 200 | O37: =M37-N37 -> 0 | P37: =E37*F37*H37*I37 -> 200 | Q37: =P37 -> 200 | R37: =P37-Q37 -> 0 | S37: =J37+M37+P37 -> 600 | T37: =K37+N37+Q37 -> 600 | U37: =S37-T37 -> 0
C38: Subtotal Other Direct Costs | J38: =SUM(J25:J37) -> 4720 | K38: =SUM(K25:K37) -> 4720 | L38: =SUM(L25:L37) -> 0 | M38: =SUM(M25:M37) -> 4720 | N38: =SUM(N25:N37) -> 4720 | O38: =SUM(O25:O35) -> 0 | P38: =SUM(P25:P37) -> 1400 | Q38: =SUM(Q25:Q37) -> 1400 | R38: =SUM(R25:R37) -> 0 | S38: =SUM(S25:S37) -> 10840 | T38: =SUM(T25:T37) -> 10840 | U38: =SUM(U25:U37) -> 0
C39: I. Total Direct Costs | J39: =J7+J11+J16+J38 -> 18164 | K39: =J39 -> 18164 | L39: =J39-K39 -> 0 | M39: =M7+M11+M16+M38 -> 24621.4 | N39: =M39 -> 24621.4 | O39: =M39-N39 -> 0 | P39: =P7+P11+P16+P38 -> 6499.7338 | Q39: =P39 -> 6499.7338 | R39: =P39-Q39 -> 0 | S39: =S7+S11+S16+S38 -> 49285.134 | T39: =S39 -> 49285.134 | U39: =SUM(U7+U16+U38) -> 0
C40: J. Indirect Cost
...

Sheet Consultants
A1: CONSULTANTS
A2: Budget Line Items | B2: No. | C2: Rate | D2: Unit Type | E2: Frequency | F2: % | G2: YEAR 1 | J2: YEAR 2 | M2: YEAR 3 | P2: Total
G3: Total | H3: Grant | I3: Cost Share | J3: Total | K3: Grant | L3: Cost Share | M3: Total | N3: Grant | O3: Cost Share | P3: Total | Q3: Grant | R3: Cost Share
A4: Consultants
A5: Consultant (Activity 1) | B5: 1 | C5: 120 | D5: Days | E5: 20 | F5: 1 | G5: =B5*C5*E5*F5 -> 2400 | H5: =G5 -> 2400 | I5: =G5-H5 -> 0 | J5: 0 | K5: =J5 -> 0 | L5: =J5-K5 -> 0 | M5: 0 | N5: =M5 -> 0 | O5: =M5-N5 -> 0 | P5: =G5+J5+M5 -> 2400 | Q5: =P5 -> 2400 | R5: =P5-Q5 -> 0
A6: Communications Specialist | B6: 1 | C6: 120 | D6: Days | E6: 25 | F6: 1 | G6: =B6*C6*E6*F6 -> 3000 | H6: =G6 -> 3000 | I6: =G6-H6 -> 0 | J6: =B6*C6*E6*F6 -> 3000 | K6: =J6 -> 3000 | L6: =J6-K6 -> 0 | M6: =B6*C6*E6*F6 -> 3000 | N6: =M6 -> 3000 | O6: =M6-N6 -> 0 | P6: =G6+J6+M6 -> 9000 | Q6: =P6 -> 9000 | R6: =P6-Q6 -> 0
A7: Subtotal Consultants | G7: =SUM(G5:G6) -> 5400 | H7: =SUM(H5:H6) -> 5400 | I7: =SUM(I5:I6) -> 0 | J7: =SUM(J5:J6) -> 3000 | K7: =SUM(K5:K6) -> 3000 | L7: =SUM(L5:L6) -> 0 | M7: =SUM(M5:M6) -> 3000 | N7: =SUM(N5:N6) -> 3000 | ... R7: =SUM(R5:R6) -> 0
A8: GRAND TOTAL | G8: =G7 -> 5400 | H8: =H7 -> 5400 | I8: =I7 -> 0 | J8: =J7 -> 3000 | K8: =K7 -> 3000 | L8: =L7 -> 0 | M8: =M7 -> 3000 | N8: =N7 -> 3000 | ... R8: =R7 -> 0

Sheet Detailed Budget (2)
A1: ='Budget Summary'!C4 -> Year 1 | C1: 2017 | K1: 2018 | Q1: 2019 | W1: Total
A2: Account Code | B2: All costs in US$ | C2: No. | D2: Unit Type | E2: No. of Units | F2: % | G2: Rate | H2: Total | I2: Grant | J2: CRS | K2: No. | L2: Freq. | M2: Rate | N2: Total | O2: Grant | P2: CRS | Q2: No. | R2: Freq. | S2: Rate | T2: Total | U2: Grant | V2: CRS | W2: Grant | X2: CRS | Y2: Grand Total
A3: 6052, 6069 | B3: Personnel | G3: 65 | I3: 0.85 | J3: =(100%-I3) -> 0.15 | M3: 1.36909 | O3: 1.2999 | P3: =(100%-O3) -> -0.2999 | S3: 1.36909 | U3: -0.04571 | V3: =(100%-U3) -> 1.04571
B4: Staff Salaries
B5: Head of Office | C5: 0.3 | D5: FTE | E5: 12 | F5: 1 | G5: =(1391532.0682/$G$3)/12 -> 1784.0155 | H5: =C5*G5*E5 -> 6422.4557 | I5: =H5 -> 6422.4557 | J5: =H5-I5 -> 0 | K5: =C5 -> 0.3 | L5: =E5 -> 12 | M5: =G5*1.05 -> 1873.2162 | N5: =K5*M5*L5 -> 6743.5785 | O5: =N5 -> 6743.5785 | P5: =N5-O5 -> 0 | Q5: =K5 -> 0.3 | R5: =L5 -> 12 | S5: =M5*1.05 -> 1966.8771 | T5: =Q5*S5*R5 -> 7080.7574 | U5: =T5 -> 7080.7574 | V5: =T5-U5 -> 0 | W5: =I5+O5+U5 -> 20246.792 | X5: =J5+P5+V5 -> 0 | Y5: =W5+X5 -> 20246.792 | Z5: =H5+N5+T5-Y5 -> 0 | AA5: =I5+O5+U5-W5 -> 0 | AB5: =J5+P5+V5-X5 -> 0
B6: Program Coordinator | C6: 0.8 | D6: FTE | E6: 12 | F6: 1 | G6: =(881322/$G$3)/12 -> 1129.9 | H6: =C6*G6*E6 -> 10847.04 | I6: =H6 -> 10847.04 | J6: 0 | K6: =C6 -> 0.8 | L6: =E6 -> 12 | M6: =G6*1.05 -> 1186.395 | N6: =K6*M6*L6 -> 11389.392 | O6: =N6 -> 11389.392 | P6: 0 | Q6: =K6 -> 0.8 | R6: =L6 -> 12 | S6: =M6*1.05 -> 1245.7148 | T6: =Q6*S6*R6 -> 11958.862 | U6: =T6 -> 11958.862 | V6: 0 | W6: =I6+O6+U6 -> 34195.294 | X6: =J6+P6+V6 -> 0 | Y6: =W6+X6 -> 34195.294 | Z6: =H6+N6+T6-Y6 -> 0 | AA6: =I6+O6+U6-W6 -> 0 | AB6: =J6+P6+V6-X6 -> 0
B7: Finance officer | C7: 0.2 | D7: FTE | E7: 12 | F7: 1 | G7: =(583144.65/$G$3)/12 -> 747.62135 | H7: =C7*G7*E7 -> 1794.2912 | I7: =H7 -> 1794.2912 | J7: =H7-I7 -> 0 | K7: =C7 -> 0.2 | L7: =E7 -> 12 | M7: =G7*1.05 -> 785.00241 | N7: =K7*M7*L7 -> 1884.0058 | O7: =N7 -> 1884.0058 | P7: =N7-O7 -> 0 | Q7: =K7 -> 0.2 | R7: =L7 -> 12 | S7: =M7*1.05 -> 824.25253 | T7: =Q7*S7*R7 -> 1978.2061 | U7: =T7 -> 1978.2061 | V7: =T7-U7 -> 0 | W7: =I7+O7+U7 -> 5656.5031 | X7: =J7+P7+V7 -> 0 | Y7: =W7+X7 -> 5656.5031 | Z7: =H7+N7+T7-Y7 -> 0 | AA7: =I7+O7+U7-W7 -> 0 | AB7: =J7+P7+V7-X7 -> 0
B8: Administrative Staff | C8: 0.6 | D8: FTE | E8: 12 | F8: 1 | G8: =(1126756.3725/$G$3)/4/12 -> 361.13986 | H8: =C8*G8*E8 -> 2600.207 | I8: =H8 -> 2600.207 | J8: =H8-I8 -> 0 | K8: =C8 -> 0.6 | L8: =E8 -> 12 | M8: =G8*1.05 -> 379.19686 | N8: =K8*M8*L8 -> 2730.2174 | O8: =N8 -> 2730.2174 | P8: =N8-O8 -> 0 | Q8: =K8 -> 0.6 | R8: =L8 -> 12 | S8: =M8*1.05 -> 398.1567 | T8: =Q8*S8*R8 -> 2866.7282 | U8: =T8 -> 2866.7282 | V8: =T8-U8 -> 0 | W8: =I8+O8+U8 -> 8197.1526 | X8: =J8+P8+V8 -> 0 | Y8: =W8+X8 -> 8197.1526 | Z8: =H8+N8+T8-Y8 -> 0 | AA8: =I8+O8+U8-W8 -> 0 | AB8: =J8+P8+V8-X8 -> 0
B9: MEAL Cordinator | C9: 0.4 | D9: FTE | E9: 12 | F9: 1 | G9: =(856059.4813/$G$3)/12 -> 1097.5122 | H9: =C9*G9*E9 -> 5268.0583 | I9: =H9 -> 5268.0583 | J9: =H9-I9 -> 0 | K9: =C9 -> 0.4 | L9: =E9 -> 12 | M9: =G9*1.05 -> 1152.3878 | N9: =K9*M9*L9 -> 5531.4613 | O9: =N9 -> 5531.4613 | P9: =N9-O9 -> 0 | Q9: =K9 -> 0.4 | R9: =L9 -> 12 | S9: =M9*1.05 -> 1210.0072 | T9: =Q9*S9*R9 -> 5808.0343 | U9: =T9 -> 5808.0343 | V9: =T9-U9 -> 0 | W9: =I9+O9+U9 -> 16607.554 | X9: =J9+P9+V9 -> 0 | Y9: =W9+X9 -> 16607.554 | Z9: =H9+N9+T9-Y9 -> 0 | AA9: =I9+O9+U9-W9 -> 0 | AB9: =J9+P9+V9-X9 -> 0
B10: Mang.& tech.advisors - Int’l Staff | C10: 0.04 | D10: FTE | E10: 12 | F10: 1 | G10: 2986.75 | H10: =C10*G10*E10 -> 1433.64 | I10: 1075.23 | J10: =H10-I10 -> 358.41 | K10: =C10 -> 0.04 | L10: =E10 -> 12 | M10: =G10*$M$3 -> 4089.1296 | N10: =K10*M10*L10 -> 1962.7822 | O10: =I10*$O$3 -> 1397.6915 | P10: =N10-O10 -> 565.09071 | Q10: =K10 -> 0.04 | R10: =L10 -> 12 | S10: =M10 -> 4089.1296 | T10: =Q10*S10*R10 -> 1962.7822 | U10: =O10+(O10*$U$3) -> 1333.803 | V10: =T10-U10 -> 628.97919 | W10: =I10+O10+U10 -> 3806.7245 | X10: =J10+P10+V10 -> 1552.4799 | Y10: =W10+X10 -> 5359.2044 | Z10: =H10+N10+T10-Y10 -> 0 | AA10: =I10+O10+U10-W10 -> 0 | AB10: =J10+P10+V10-X10 -> 0
B11: Mang.& tech.advisors - Nat.staff | C11: 0.65 | D11: FTE | E11: 12 | F11: 1 | G11: 1461 | H11: =C11*G11*E11 -> 11395.8 | I11: 8941.32 | J11: =H11-I11 -> 2454.48 | K11: =C11 -> 0.65 | L11: =E11 -> 12 | M11: =G11*$M$3 -> 2000.2405 | N11: =K11*M11*L11 -> 15601.876 | O11: =I11*$O$3 -> 11622.822 | P11: =N11-O11 -> 3979.054 | Q11: =K11 -> 0.65 | R11: =L11 -> 12 | S11: =M11 -> 2000.2405 | T11: =Q11*S11*R11 -> 15601.876 | U11: =O11+(O11*$U$3) -> 11091.543 | V11: =T11-U11 -> 4510.3331 | W11: =I11+O11+U11 -> 31655.685 | X11: =J11+P11+V11 -> 10943.867 | Y11: =W11+X11 -> 42599.552 | Z11: =H11+N11+T11-Y11 -> 0 | AA11: =I11+O11+U11-W11 -> 0 | AB11: =J11+P11+V11-X11 -> 0
B12: Sub Total Personnel | H12: =SUM(H5:H11) -> 39761.492 | I12: =SUM(I5:I11) -> 36948.602 | J12: =SUM(J5:J11) -> 2812.89 | N12: =SUM(N5:N11) -> 45843.313 | O12: =SUM(O5:O11) -> 41299.168 | P12: =SUM(P5:P11) -> 4544.1447 | T12: =SUM(T5:T11) -> 47257.246 | U12: =SUM(U5:U11) -> 42117.933 | V12: =SUM(V5:V11) -> 5139.3123 | W12: =SUM(W5:W11) -> 120365.7 | X12: =SUM(X5:X11) -> 12496.347 | Y12: =SUM(Y5:Y11) -> 132862.05 | Z12: =H12+N12+T12-Y12 -> 0 | AA12: =I12+O12+U12-W12 -> 0 | AB12: =J12+P12+V12-X12 -> 0
A13: 6061, 6063, 6071 | B13: Fringe Benefits | Z13: =H13+N13+T13-Y13 -> 0 | AA13: =I13+O13+U13-W13 -> 0 | AB13: =J13+P13+V13-X13 -> 0
B14: Fringe Benefits – National Staff | C14: =SUM(C5:C9) -> 2.3 | D14: Salary | E14: 12 | F14: 0.135 | G14: =SUM(H5:H9)/12 -> 2244.3377 | H14: =SUM(H5:H9)*$F$14 -> 3635.8271 | I14: =H14 -> 3635.8271 | J14: 0 | K14: =C14 -> 2.3 | L14: =E14 -> 12 | M14: =G14*1.05 -> 2356.5546 | N14: =SUM(N5:N9)*$F$14 -> 3817.6184 | O14: =N14 -> 3817.6184 | P14: =N14-O14 -> 0 | Q14: =K14 -> 2.3 | R14: =L14 -> 12 | S14: =M14*1.05001 -> 2474.4059 | T14: =SUM(T5:T9)*$F$14 -> 4008.4993 | U14: =T14 -> 4008.4993 | V14: =T14-U14 -> 0 | W14: =I14+O14+U14 -> 11461.945 | X14: =J14+P14+V14 -> 0 | Y14: =W14+X14 -> 11461.945 | Z14: =H14+N14+T14-Y14 -> 0 | AA14: =I14+O14+U14-W14 -> 0 | AB14: =J14+P14+V14-X14 -> 0
B15: Fringe Benefits – Int’l Staff | C15: =C10 -> 0.04 | D15: Salary | E15: 12 | F15: 0.29 | G15: 119.47 | H15: =G15*E15*F15 -> 415.7556 | I15: 311.8167 | J15: =H15-I15 -> 103.9389 | K15: =C15 -> 0.04 | L15: =E15 -> 12 | M15: =G15*$M$3 -> 163.56518 | N15: =M15*L15*F15 -> 569.20683 | O15: =I15*$O$3 -> 405.33053 | P15: =N15-O15 -> 163.87631 | Q15: =K15 -> 0.04 | R15: =L15 -> 12 | S15: =M15 -> 163.56518 | T15: =F15*S15*R15 -> 569.20683 | U15: =O15+(O15*$U$3) -> 386.80287 | V15: =T15-U15 -> 182.40396 | W15: =I15+O15+U15 -> 1103.9501 | X15: =J15+P15+V15 -> 450.21917 | Y15: =W15+X15 -> 1554.1693 | Z15: =H15+N15+T15-Y15 -> 0 | AA15: =I15+O15+U15-W15 -> 0 | AB15: =J15+P15+V15-X15 -> 0
B16: Overseas Allowances – Int’l Staff | C16: =C10 -> 0.04 | D16: FTE | E16: 12 | F16: 1 | G16: 2234.56 | H16: =C16*G16*E16 -> 1072.5888 | I16: 804.4416 | J16: =H16-I16 -> 268.1472 | K16: =K10 -> 0.04 | L16: =E16 -> 12 | M16: =G16*$M$3 -> 3059.3138 | N16: =K16*M16*L16 -> 1468.4706 | O16: =I16*$O$3 -> 1045.6936 | P16: =N16-O16 -> 422.77696 | Q16: =Q10 -> 0.04 | R16: =L16 -> 12 | S16: =M16 -> 3059.3138 | T16: =Q16*S16*R16 -> 1468.4706 | U16: =O16+(O16*$U$3) -> 997.89498 | V16: =T16-U16 -> 470.57562 | W16: =I16+O16+U16 -> 2848.0302 | X16: =J16+P16+V16 -> 1161.4998 | Y16: =W16+X16 -> 4009.53 | Z16: =H16+N16+T16-Y16 -> 0 | AA16: =I16+O16+U16-W16 -> 0 | AB16: =J16+P16+V16-X16 -> 0
