Workbook

Sheet POA Line Item Budget
D1: PARTNERS OF THE AMERICAS
D2: Project Name: 2024 TIP Office International Programs to Combat Human Trafficking
A3: Entity: | B3: P | D3: Funding Opportunity: DFOP0016706
A4: Program/Dept.: | B4: 20200 | D4: Budget Assumptions
A5: Funder-Grant: | B5: DOS454 | D5: Inflation - Locally Purchased Goods/Services - 4% | E5: 1.04
D6: Merit Based Increases for HQ & Field Staff - 5% | E6: 1.05
D8: All costs in US$ | E8: Year 1 | K8: Year 2 | O8: Year 3 | S8: Year 4 | W8: Year 5 | AA8: Total
A9: Budget Code | B9: Account Code | C9: County Code | D9: Budget Line Items | E9: No. | F9: Unit Type | G9: No. of Units | H9: % | I9: Rate | J9: JTIP Total | K9: No. | L9: No. of Units | M9: Rate | N9: JTIP Total | O9: No. | P9: No. of Units | Q9: Rate | R9: JTIP Total | S9: No. | T9: No. of Units | U9: Rate | V9: JTIP Total | W9: No. | X9: No. of Units | Y9: Rate | Z9: JTIP Total | AA9: Total Federal Funds Requested
D10: Personnel
A11: PERSNL-PC | B11: 70000 | C11: PRY | D11: Project Coordinator (50% LOE) - Macarena Jiménez | E11: 1 | F11: FTE/month | G11: 12 | H11: 0.5 | I11: 9680 | J11: =E11*I11*G11*H11 -> 58080 | K11: =E11 -> 1 | L11: 12 | M11: =I11*$E$6 -> 10164 | N11: =K11*M11*L11*H11 -> 60984 | O11: 1 | P11: 12 | Q11: =M11*$E$6 -> 10672.2 | R11: =H11*O11*P11*Q11 -> 64033.2 | S11: 1 | T11: 12 | U11: =Q11*$E$6 -> 11205.81 | V11: =H11*S11*T11*U11 -> 67234.86 | W11: 1 | X11: 12 | Y11: =U11*$E$6 -> 11766.101 | Z11: =H11*W11*X11*Y11 -> 70596.603 | AA11: =J11+N11+R11+V11+Z11 -> 320928.66
A12: PERSNL-TS | B12: 70000 | C12: PRY | D12: Technical Specialist (50% LOE) - Aurora Figueredo | E12: 1 | F12: FTE/month | G12: 9 | H12: 0.5 | I12: 4800 | J12: =E12*I12*G12*H12 -> 21600 | K12: =E12 -> 1 | L12: 12 | M12: =I12*$E$6 -> 5040 | N12: =K12*M12*L12*H12 -> 30240 | O12: 1 | P12: 12 | Q12: =M12*$E$6 -> 5292 | R12: =H12*O12*P12*Q12 -> 31752 | S12: 1 | T12: 12 | U12: =Q12*$E$6 -> 5556.6 | V12: =H12*S12*T12*U12 -> 33339.6 | W12: 1 | X12: 6 | Y12: =U12*$E$6 -> 5834.43 | Z12: =H12*W12*X12*Y12 -> 17503.29 | AA12: =J12+N12+R12+V12+Z12 -> 134434.89
A13: PERSNL-M&E | B13: 70000 | C13: PRY | D13: M&E Coordinator (100% LOE) | E13: 1 | F13: FTE/month | G13: 9 | H13: 1 | I13: 2000 | J13: =E13*G13*H13*I13 -> 18000 | K13: 1 | L13: 12 | M13: =I13*$E$6 -> 2100 | N13: =K13*M13*L13*H13 -> 25200 | O13: 1 | P13: 12 | Q13: =M13*$E$6 -> 2205 | R13: =O13*Q13*P13*H13 -> 26460 | S13: 1 | T13: 12 | U13: =Q13*$E$6 -> 2315.25 | V13: =S13*U13*T13*H13 -> 27783 | W13: 1 | X13: 8 | Y13: =U13*$E$6*H13 -> 2431.0125 | Z13: =W13*Y13*X13*H13 -> 19448.1 | AA13: =J13+N13+R13+V13+Z13 -> 116891.1
A14: PERSNL-F&A | B14: 70000 | C14: PRY | D14: Administration and Finance Officer (50% LOE) | E14: 1 | F14: FTE/month | G14: 9 | H14: 0.5 | I14: 2200 | J14: =E14*I14*G14*H14 -> 9900 | K14: =E14 -> 1 | L14: 12 | M14: =I14*$E$6 -> 2310 | N14: =K14*M14*L14*H14 -> 13860 | O14: 1 | P14: 12 | Q14: =M14*$E$6 -> 2425.5 | R14: =H14*O14*P14*Q14 -> 14553 | S14: 1 | T14: 12 | U14: =Q14*$E$6 -> 2546.775 | V14: =H14*S14*T14*U14 -> 15280.65 | W14: 1 | X14: 8 | Y14: =U14*$E$6 -> 2674.1137 | Z14: =H14*W14*X14*Y14 -> 10696.455 | AA14: =J14+N14+R14+V14+Z14 -> 64290.105
A15: PERSNL | B15: 50000 | C15: PRY | D15: Project Manager (HQ) (30% LOE) | E15: 1 | F15: FTE/month | G15: 12 | H15: 0.3 | I15: 5567 | J15: =E15*I15*G15*H15 -> 20041.2 | K15: =E15 -> 1 | L15: 12 | M15: =I15*$E$6 -> 5845.35 | N15: =K15*M15*L15*H15 -> 21043.26 | O15: 1 | P15: 12 | Q15: =M15*$E$6 -> 6137.6175 | R15: =H15*O15*P15*Q15 -> 22095.423 | S15: 1 | T15: 12 | U15: =Q15*$E$6 -> 6444.4984 | V15: =H15*S15*T15*U15 -> 23200.194 | W15: 1 | X15: 12 | Y15: =U15*$E$6 -> 6766.7233 | Z15: =H15*W15*X15*Y15 -> 24360.204 | AA15: =J15+N15+R15+V15+Z15 -> 110740.28
D16: Subtotal Personnel | J16: =SUM(J11:J15) -> 127621.2 | N16: =SUM(N11:N15) -> 151327.26 | R16: =SUM(R11:R15) -> 158893.62 | V16: =SUM(V11:V15) -> 166838.3 | Z16: =SUM(Z11:Z15) -> 142604.65 | AA16: =SUM(AA11:AA15) -> 747285.04
D17: Fringe Benefits
A18: FRINGE-PY | B18: 70015 | C18: PRY | D18: =D11 -> Project Coordinator (50% LOE) - Macarena Jiménez | E18: =E11 -> 1 | F18: % Salary | G18: 1 | H18: 0.3527 | I18: =J11 -> 58080 | J18: =E18*I18*G18*H18 -> 20484.816 | K18: =E18 -> 1 | L18: 1 | M18: =N11 -> 60984 | N18: =H18*M18*K18*L18 -> 21509.057 | O18: 1 | P18: 1 | Q18: =R11 -> 64033.2 | R18: =H18*O18*P18*Q18 -> 22584.51 | S18: 1 | T18: 1 | U18: =V11 -> 67234.86 | V18: =H18*S18*T18*U18 -> 23713.735 | W18: 1 | X18: 1 | Y18: =Z11 -> 70596.603 | Z18: =H18*W18*X18*Y18 -> 24899.422 | AA18: =J18+N18+R18+V18+Z18 -> 113191.54
A19: FRINGE-PY | B19: 70015 | C19: PRY | D19: =D12 -> Technical Specialist (50% LOE) - Aurora Figueredo | E19: =E12 -> 1 | F19: % Salary | G19: 1 | H19: 0.3527 | I19: =J12 -> 21600 | J19: =E19*I19*G19*H19 -> 7618.32 | K19: =E19 -> 1 | L19: 1 | M19: =N12 -> 30240 | N19: =H19*M19*K19*L19 -> 10665.648 | O19: 1 | P19: 1 | Q19: =R12 -> 31752 | R19: =H19*O19*P19*Q19 -> 11198.93 | S19: 1 | T19: 1 | U19: =V12 -> 33339.6 | V19: =H19*S19*T19*U19 -> 11758.877 | W19: 1 | X19: 1 | Y19: =Z12 -> 17503.29 | Z19: =H19*W19*X19*Y19 -> 6173.4104 | AA19: =J19+N19+R19+V19+Z19 -> 47415.186
A20: FRINGE-PY | B20: 70015 | C20: PRY | D20: M&E Coordinator (100% LOE) | E20: =E13 -> 1 | F20: % Salary | G20: 1 | H20: 0.3527 | I20: =J13 -> 18000 | J20: =E20*I20*G20*H20 -> 6348.6 | K20: 1 | L20: 1 | M20: =N13 -> 25200 | N20: =H20*M20*K20*L20 -> 8888.04 | O20: 1 | P20: 1 | Q20: =R13 -> 26460 | R20: =H20*O20*P20*Q20 -> 9332.442 | S20: 1 | T20: 1 | U20: =V13 -> 27783 | V20: =H20*S20*T20*U20 -> 9799.0641 | W20: 1 | X20: 1 | Y20: =Z13 -> 19448.1 | Z20: =H20*W20*X20*Y20 -> 6859.3449 | AA20: =J20+N20+R20+V20+Z20 -> 41227.491
A21: FRINGE-PY | B21: 70015 | C21: PRY | D21: =D14 -> Administration and Finance Officer (50% LOE) | E21: =E14 -> 1 | F21: % Salary | G21: 1 | H21: 0.3527 | I21: =J14 -> 9900 | J21: =E21*I21*G21*H21 -> 3491.73 | K21: =E21 -> 1 | L21: 1 | M21: =N14 -> 13860 | N21: =H21*M21*K21*L21 -> 4888.422 | O21: 1 | P21: 1 | Q21: =R14 -> 14553 | R21: =H21*O21*P21*Q21 -> 5132.8431 | S21: 1 | T21: 1 | U21: =V14 -> 15280.65 | V21: =H21*S21*T21*U21 -> 5389.4853 | W21: 1 | X21: 1 | Y21: =Z14 -> 10696.455 | Z21: =H21*W21*X21*Y21 -> 3772.6397 | AA21: =J21+N21+R21+V21+Z21 -> 22675.12
A22: FRINGE | B22: 50900 | C22: PRY | D22: =D15 -> Project Manager (HQ) (30% LOE) | E22: =E15 -> 1 | F22: % Salary | G22: 1 | H22: 0.2347 | I22: =J15 -> 20041.2 | J22: =E22*I22*G22*H22 -> 4703.6696 | K22: =E22 -> 1 | L22: 1 | M22: =N15 -> 21043.26 | N22: =H22*M22*K22*L22 -> 4938.8531 | O22: 1 | P22: 1 | Q22: =R15 -> 22095.423 | R22: =H22*O22*P22*Q22 -> 5185.7958 | S22: 1 | T22: 1 | U22: =V15 -> 23200.194 | V22: =H22*S22*T22*U22 -> 5445.0856 | W22: 1 | X22: 1 | Y22: =Z15 -> 24360.204 | Z22: =H22*W22*X22*Y22 -> 5717.3398 | AA22: =J22+N22+R22+V22+Z22 -> 25990.744
D23: Subtotal Fringe Benefits | J23: =SUM(J18:J22) -> 42647.136 | N23: =SUM(N18:N22) -> 50890.02 | R23: =SUM(R18:R22) -> 53434.521 | V23: =SUM(V18:V22) -> 56106.247 | Z23: =SUM(Z18:Z22) -> 47422.157 | AA23: =J23+N23+R23+V23+Z23 -> 250500.08
D24: Travel
D25: HQ Staff International Travel
A26: STFTRAVEL | B26: 86040 | C26: USA | D26: International Airfare (Washington, DC- Asuncion, Paraguay) | E26: 1 | F26: Trip | G26: 1 | H26: 1 | I26: 2000 | J26: =E26*I26*G26 -> 2000 | K26: 1 | L26: 1 | M26: =I26*$E$5 -> 2080 | N26: =K26*M26*L26*H26 -> 2080 | O26: 1 | P26: 1 | Q26: =M26*$E$5 -> 2163.2 | R26: =O26*Q26*P26*L26 -> 2163.2 | S26: 1 | T26: 1 | U26: =Q26*$E$5 -> 2249.728 | V26: =S26*U26*T26*P26 -> 2249.728 | W26: 1 | X26: 1 | Y26: =U26*$E$5 -> 2339.7171 | Z26: =W26*Y26*X26*T26 -> 2339.7171 | AA26: =J26+N26+R26+V26+Z26 -> 10832.645
A27: GROUNDTRAN | B27: 86000 | C27: USA | D27: Ground Transportation | E27: 1 | F27: Day | G27: 7 | H27: 1 | I27: 50 | J27: =E27*I27*G27 -> 350 | K27: 1 | L27: 7 | M27: =I27*$E$5 -> 52 | N27: =K27*M27*L27*H27 -> 364 | O27: 1 | P27: 7 | Q27: =M27*$E$5 -> 54.08 | R27: =O27*Q27*P27 -> 378.56 | S27: 1 | T27: 7 | U27: =Q27*$E$5 -> 56.2432 | V27: =S27*U27*T27 -> 393.7024 | W27: 1 | X27: 7 | Y27: =U27*$E$5 -> 58.492928 | Z27: =W27*Y27*X27 -> 409.4505 | AA27: =J27+N27+R27+V27+Z27 -> 1895.7129
A28: LODGING | B28: 86030 | C28: USA | D28: Lodging in Asuncion | E28: 1 | F28: Night | G28: =G26*7 -> 7 | H28: 1 | I28: 95 | J28: =E28*I28*G28 -> 665 | K28: 1 | L28: =L26*7 -> 7 | M28: =I28*$E$5 -> 98.8 | N28: =K28*M28*L28*H28 -> 691.6 | O28: 1 | P28: =P26*7 -> 7 | Q28: =M28*$E$5 -> 102.752 | R28: =O28*Q28*P28 -> 719.264 | S28: 1 | T28: =T26*7 -> 7 | U28: =Q28*$E$5 -> 106.86208 | V28: =S28*U28*T28 -> 748.03456 | W28: 1 | X28: =X26*7 -> 7 | Y28: =U28*$E$5 -> 111.13656 | Z28: =W28*Y28*X28 -> 777.95594 | AA28: =J28+N28+R28+V28+Z28 -> 3601.8545
A29: STFCN DIEM | B29: 86050 | C29: USA | D29: M&IE in Asuncion | E29: 1 | F29: Day | G29: =G26*7 -> 7 | H29: 1 | I29: 81 | J29: =E29*I29*G29 -> 567 | K29: 1 | L29: =L26*7 -> 7 | M29: =I29*$E$5 -> 84.24 | N29: =K29*M29*L29*H29 -> 589.68 | O29: 1 | P29: =P26*7 -> 7 | Q29: =M29*$E$5 -> 87.6096 | R29: =O29*Q29*P29 -> 613.2672 | S29: 1 | T29: =T26*7 -> 7 | U29: =Q29*$E$5 -> 91.113984 | V29: =S29*U29*T29 -> 637.79789 | W29: 1 | X29: =X26*7 -> 7 | Y29: =U29*$E$5 -> 94.758543 | Z29: =W29*Y29*X29 -> 663.3098 | AA29: =J29+N29+R29+V29+Z29 -> 3071.0549
D30: Local Staff In-Country Travel | AA30: =J30+N30+R30+V30+Z30 -> 0
A31: LSLODGING | B31: 86030 | C31: PRY | D31: Lodging in Chaco, Ciudad del Este, Caaguazú, and Alto Paraná | E31: 3 | F31: Night | G31: 3 | H31: 1 | I31: 85 | J31: =E31*I31*G31 -> 765 | K31: 6 | L31: 3 | M31: =I31*$E$5 -> 88.4 | N31: =K31*M31*L31*H31 -> 1591.2 | O31: 6 | P31: 3 | Q31: =M31*$E$5 -> 91.936 | R31: =O31*Q31*P31 -> 1654.848 | S31: 6 | T31: 3 | U31: =Q31*$E$5 -> 95.61344 | V31: =S31*U31*T31 -> 1721.0419 | W31: 6 | X31: 3 | Y31: =U31*$E$5 -> 99.437978 | Z31: =W31*Y31*X31 -> 1789.8836 | AA31: =J31+N31+R31+V31+Z31 -> 7521.9735
A32: LSM&IE | B32: 86050 | C32: PRY | D32: M&IE in Chaco, Ciudad del Este, Caaguazú, and Alto Paraná | E32: 3 | F32: Day | G32: 3 | H32: 1 | I32: =60 * 0.9 -> 54 | J32: =E32*I32*G32 -> 486 | K32: 6 | L32: 3 | M32: =I32*$E$5 -> 56.16 | N32: =K32*M32*L32*H32 -> 1010.88 | O32: 6 | P32: 3 | Q32: =M32*$E$5 -> 58.4064 | R32: =O32*Q32*P32 -> 1051.3152 | S32: 6 | T32: 3 | U32: =Q32*$E$5 -> 60.742656 | V32: =S32*U32*T32 -> 1093.3678 | W32: 6 | X32: 3 | Y32: =U32*$E$5 -> 63.172362 | Z32: =W32*Y32*X32 -> 1137.1025 | AA32: =J32+N32+R32+V32+Z32 -> 4778.6655
A33: LSTRANS | B33: 86000 | C33: PRY | D33: Ground Transportation in Chaco, Ciudad del Este, Caaguazú, and Alto Paraná | E33: 3 | F33: Trip | G33: 1 | H33: 1 | I33: 750 | J33: =E33*I33*G33 -> 2250 | K33: 6 | L33: 1 | M33: =I33*$E$5 -> 780 | N33: =K33*M33*L33*H33 -> 4680 | O33: 6 | P33: 1 | Q33: =M33*$E$5 -> 811.2 | R33: =O33*Q33*P33 -> 4867.2 | S33: 6 | T33: 1 | U33: =Q33*$E$5 -> 843.648 | V33: =S33*U33*T33 -> 5061.888 | W33: 6 | X33: 1 | Y33: =U33*$E$5 -> 877.39392 | Z33: =W33*Y33*X33 -> 5264.3635 | AA33: =J33+N33+R33+V33+Z33 -> 22123.452
D34: International Travel - Participants Exchange of Experience on Best Practices for Managing Shelters (Activity 2.1)
A35: TRVL.2.1.A | B35: 86040 | C35: PRY | D35: International Airfare (Asuncion, Paraguay to Chile/Argentina) | E35: 0 | F35: Trip | G35: 0 | H35: 1 | I35: 350 | J35: =E35*I35*G35 -> 0 | K35: 3 | L35: 1 | M35: =I35*$E$5 -> 364 | N35: =K35*M35*L35*H35 -> 1092 | O35: 3 | P35: 1 | Q35: =M35*$E$5 -> 378.56 | R35: =O35*Q35*P35*L35 -> 1135.68 | S35: 0 | T35: 0 | U35: 0 | V35: =S35*U35*T35*P35 -> 0 | W35: 0 | X35: 0 | Y35: 0 | Z35: 0 | AA35: =J35+N35+R35+V35+Z35 -> 2227.68
A36: TRVL.2.1.B | B36: 86000 | C36: PRY | D36: Ground Transportation | E36: 0 | F36: Trip | G36: 0 | H36: 1 | I36: 50 | J36: =E36*I36*G36 -> 0 | K36: 3 | L36: 1 | M36: =I36*$E$5 -> 52 | N36: =K36*M36*L36*H36 -> 156 | O36: 3 | P36: 1 | Q36: =M36*$E$5 -> 54.08 | R36: =O36*Q36*P36*L36 -> 162.24 | S36: 0 | T36: 0 | U36: 0 | V36: =S36*U36*T36*P36 -> 0 | W36: 0 | X36: 0 | Y36: 0 | Z36: 0 | AA36: =J36+N36+R36+V36+Z36 -> 318.24
A37: TRVL.2.1.C | B37: 86030 | C37: PRY | D37: Lodging in Chile/Argentina | E37: 0 | F37: Night | G37: =G36*2 -> 0 | H37: 1 | I37: 110 | J37: =E37*I37*G37 -> 0 | K37: 3 | L37: 4 | M37: =I37*$E$5 -> 114.4 | N37: =K37*M37*L37*H37 -> 1372.8 | O37: 3 | P37: 4 | Q37: =M37*$E$5 -> 118.976 | R37: =O37*Q37*P37 -> 1427.712 | S37: 0 | T37: 0 | U37: 0 | V37: =S37*U37*T37*P37 -> 0 | W37: 0 | X37: 0 | Y37: 0 | Z37: 0 | AA37: =J37+N37+R37+V37+Z37 -> 2800.512
A38: TRVL.2.1.D | B38: 86050 | C38: PRY | D38: M&IE in Chile/Argentina | E38: 0 | F38: Day | G38: =G36*2 -> 0 | H38: 1 | I38: 100 | J38: =E38*I38*G38 -> 0 | K38: 3 | L38: 4 | M38: =I38*$E$5 -> 104 | N38: =K38*M38*L38*H38 -> 1248 | O38: 3 | P38: 4 | Q38: =M38*$E$5 -> 108.16 | R38: =O38*Q38*P38 -> 1297.92 | S38: 0 | T38: 0 | U38: 0 | V38: =S38*U38*T38*P38 -> 0 | W38: 0 | X38: 0 | Y38: 0 | Z38: 0 | AA38: =J38+N38+R38+V38+Z38 -> 2545.92
D39: Domestic Travel - Participants of Coordination Meetings to Develop a Network of Alternative Shelters (Activity 3.4)
A40: TRVL.3.4.A | B40: 86000 | C40: PRY | D40: Ground Transportation to/from Asuncion | E40: 1 | F40: Participant | G40: 10 | H40: 1 | I40: 250 | J40: =E40*I40*G40 -> 2500 | K40: 2 | L40: 10 | M40: =I40*$E$5 -> 260 | N40: =K40*M40*L40*H40 -> 5200 | O40: 2 | P40: 10 | Q40: =M40*$E$5 -> 270.4 | R40: =H40*O40*P40*Q40 -> 5408 | S40: 2 | T40: 10 | U40: =Q40*$E$5 -> 281.216 | V40: =S40*T40*U40*H40 -> 5624.32 | W40: 0 | X40: 0 | Y40: 0 | Z40: 0 | AA40: =J40+N40+R40+V40+Z40 -> 18732.32
A41: TRVL.3.4.B | B41: 86030 | C41: PRY | D41: Lodging in Asuncion | E41: 1 | F41: Night | G41: 10 | H41: 1 | I41: 95 | J41: =E41*I41*G41 -> 950 | K41: 2 | L41: =L40*1 -> 10 | M41: =I41*$E$5 -> 98.8 | N41: =K41*M41*L41*H41 -> 1976 | O41: 2 | P41: =P40*1 -> 10 | Q41: =M41*$E$5 -> 102.752 | R41: =H41*O41*P41*Q41 -> 2055.04 | S41: 2 | T41: 10 | U41: =Q41*$E$5 -> 106.86208 | V41: =H41*S41*T41*U41 -> 2137.2416 | W41: 0 | X41: 0 | Y41: 0 | Z41: 0 | AA41: =J41+N41+R41+V41+Z41 -> 7118.2816
...

Sheet M&E Budget
A1: M&E Budget
A2: Personnel Costs - M&E Coordinator (100% LOE) | B2: ='POA Line Item Budget'!AA13 -> 116891.1
A3: Fringe Benefits - M&E Coordinator (100% LOE) | B3: ='POA Line Item Budget'!AA20 -> 41227.491
A4: ='POA Line Item Budget'!D124 -> Customize M&E Database for Project | B4: ='POA Line Item Budget'!AA124 -> 4468.32
A5: ='POA Line Item Budget'!D125 -> M&E Materials | B5: ='POA Line Item Budget'!AA125 -> 4603.8742
A6: ='POA Line Item Budget'!D126 -> M&E Training and Coordination Meetings | B6: ='POA Line Item Budget'!AA126 -> 2708.1613
A7: Mid-term Evaluation | B7: ='POA Line Item Budget'!AA63 -> 27040
A8: Final Evaluation | B8: ='POA Line Item Budget'!AA64 -> 29246.464
A9: Total M&E Budget | B9: =SUM(B2:B8) -> 226185.41
A10: Percentage of M&E Budget | B10: =B9/2500000 -> 0.090474164

Sheet Summary by Year
A1: PARTNERS OF THE AMERICAS
A2: Project Name: 2024 TIP Office International Programs to Combat Human Trafficking
A3: Funding Opportunity: DFOP0016706 and Assistance Number: 19.019
A4: SUMMARY BUDGET
B5: Year 1 | C5: Year 2 | D5: Year 3 | E5: Year 4 | F5: Year 5 | G5: Total
A6: BUDGET SUMMARY CATEGORIES | B6: JTIP | C6: JTIP | D6: JTIP | E6: JTIP | F6: JTIP | G6: Cost Share | H6: Total Federal Funds Requested
A7: 1. Personnel | B7: ='POA Line Item Budget'!J16 -> 127621.2 | C7: ='POA Line Item Budget'!N16 -> 151327.26 | D7: ='POA Line Item Budget'!R16 -> 158893.62 | E7: ='POA Line Item Budget'!V16 -> 166838.3 | F7: ='POA Line Item Budget'!Z16 -> 142604.65 | G7: 0 | H7: =B7+C7+D7+E7+F7 -> 747285.04
A8: 2. Fringe Benefits | B8: ='POA Line Item Budget'!J23 -> 42647.136 | C8: ='POA Line Item Budget'!N23 -> 50890.02 | D8: ='POA Line Item Budget'!R23 -> 53434.521 | E8: ='POA Line Item Budget'!V23 -> 56106.247 | F8: ='POA Line Item Budget'!Z23 -> 47422.157 | G8: 0 | H8: =B8+C8+D8+E8+F8 -> 250500.08
A9: 3. Travel | B9: ='POA Line Item Budget'!J43 -> 11343 | C9: ='POA Line Item Budget'!N43 -> 23736.96 | D9: ='POA Line Item Budget'!R43 -> 24686.438 | E9: ='POA Line Item Budget'!V43 -> 21489.402 | F9: ='POA Line Item Budget'!Z43 -> 12381.783 | G9: 0 | H9: =B9+C9+D9+E9+F9 -> 93637.583
A10: 4. Equipment | H10: =B10+C10+D10+E10+F10 -> 0
A11: 5. Supplies | B11: ='POA Line Item Budget'!J47 -> 6900 | C11: ='POA Line Item Budget'!N47 -> 1123.2 | D11: ='POA Line Item Budget'!R47 -> 1168.128 | E11: ='POA Line Item Budget'!V47 -> 1214.8531 | F11: ='POA Line Item Budget'!Z47 -> 1263.4472 | G11: 0 | H11: =B11+C11+D11+E11+F11 -> 11669.628
A12: 6. Contractual | B12: ='POA Line Item Budget'!J65 -> 36930 | C12: ='POA Line Item Budget'!N65 -> 90729.6 | D12: ='POA Line Item Budget'!R65 -> 121398.78 | E12: ='POA Line Item Budget'!V65 -> 98133.135 | F12: ='POA Line Item Budget'!Z65 -> 37669.446 | G12: 0 | H12: =B12+C12+D12+E12+F12 -> 384860.96
A13: 7. Construction | H13: =B13+C13+D13+E13+F13 -> 0
A14: 8. Other Direct Costs | B14: ='POA Line Item Budget'!J127 -> 107833.32 | C14: ='POA Line Item Budget'!N127 -> 150347.6 | D14: ='POA Line Item Budget'!R127 -> 145891.62 | E14: ='POA Line Item Budget'!V127 -> 153538.31 | F14: ='POA Line Item Budget'!Z127 -> 37768.884 | G14: 0 | H14: =B14+C14+D14+E14+F14 -> 595379.73
A15: 9. Total Direct Costs | B15: =SUM(B7:B14) -> 333274.66 | C15: =SUM(C7:C14) -> 468154.64 | D15: =SUM(D7:D14) -> 505473.11 | E15: =SUM(E7:E14) -> 497320.25 | F15: =SUM(F7:F14) -> 279110.37 | G15: =SUM(G7:G14) -> 0 | H15: =B15+C15+D15+E15+F15 -> 2083333
A16: 10. Indirect Costs | B16: ='POA Line Item Budget'!J129 -> 66654.931 | C16: ='POA Line Item Budget'!N129 -> 93630.928 | D16: ='POA Line Item Budget'!R129 -> 101094.62 | E16: ='POA Line Item Budget'!V129 -> 99464.051 | F16: ='POA Line Item Budget'!Z129 -> 55822.074 | G16: 0 | H16: =B16+C16+D16+E16+F16 -> 416666.61
A17: 11. Total Costs | B17: =B15+B16 -> 399929.59 | C17: =C15+C16 -> 561785.57 | D17: =D15+D16 -> 606567.73 | E17: =E15+E16 -> 596784.3 | F17: =F15+F16 -> 334932.44 | G17: =G15+G16 -> 0 | H17: =H15+H16 -> 2499999.6
