Workbook

Sheet DOL415
C1: Partners of the Americas - #415 DOL Educafuturo
C2: Monthly Cash Disbursements Journal
E3: Month ending | F3: 41399
E4: Country | F4: Panama
A6: * Choose from drop down list
A7: Date | B7: Ref or | C7: Payee | D7: *Budget Description | E7: *Activity | F7: Amount | G7: *Object | H7: Country | I7: Office | J7: *Subcontract | O7: Session Description
B8: CK# | E8: Code | F8: (USD) | G8: Code | J8: ID
D9: Select from drop down | E9: =VLOOKUP(D9,'PN-Coding'!$A$2:$C$36,2,FALSE) -> 0 | G9: =VLOOKUP(D9,'PN-Coding'!$A$2:$C$36,3,FALSE) -> 0 | H9: PN | I9: PN | J9: 0
D10: 1.5 EpC Translation to Indigenous Languages | E10: =VLOOKUP(D10,'PN-Coding'!$A$2:$C$36,2,FALSE) -> D.1.5 | G10: =VLOOKUP(D10,'PN-Coding'!$A$2:$C$36,3,FALSE) -> 7740
D11: 1.5 Material Design and Printing | E11: =VLOOKUP(D11,'PN-Coding'!$A$2:$C$36,2,FALSE) -> D.1.5 | G11: =VLOOKUP(D11,'PN-Coding'!$A$2:$C$36,3,FALSE) -> 7710
D12: 10.7 Lodging and per diem - Program Management Trip | E12: =VLOOKUP(D12,'PN-Coding'!$A$2:$C$36,2,FALSE) -> D.10.7 | G12: =VLOOKUP(D12,'PN-Coding'!$A$2:$C$36,3,FALSE) -> 7015
D13: 10.7 Airfare - Panama-Ecuador - Program Management Trip | E13: =VLOOKUP(D13,'PN-Coding'!$A$2:$C$36,2,FALSE) -> D.10.7 | G13: =VLOOKUP(D13,'PN-Coding'!$A$2:$C$36,3,FALSE) -> 7010
D14: Select from drop down | E14: =VLOOKUP(D14,'PN-Coding'!$A$2:$C$36,2,FALSE) -> 0 | G14: =VLOOKUP(D14,'PN-Coding'!$A$2:$C$36,3,FALSE) -> 0
D15: Select from drop down | E15: =VLOOKUP(D15,'PN-Coding'!$A$2:$C$36,2,FALSE) -> 0 | G15: =VLOOKUP(D15,'PN-Coding'!$A$2:$C$36,3,FALSE) -> 0
D16: Select from drop down | E16: =VLOOKUP(D16,'PN-Coding'!$A$2:$C$36,2,FALSE) -> 0 | G16: =VLOOKUP(D16,'PN-Coding'!$A$2:$C$36,3,FALSE) -> 0
D17: Select from drop down | E17: =VLOOKUP(D17,'PN-Coding'!$A$2:$C$36,2,FALSE) -> 0 | G17: =VLOOKUP(D17,'PN-Coding'!$A$2:$C$36,3,FALSE) -> 0
D18: Select from drop down | E18: =VLOOKUP(D18,'PN-Coding'!$A$2:$C$36,2,FALSE) -> 0 | G18: =VLOOKUP(D18,'PN-Coding'!$A$2:$C$36,3,FALSE) -> 0
D19: Select from drop down | E19: =VLOOKUP(D19,'PN-Coding'!$A$2:$C$36,2,FALSE) -> 0 | G19: =VLOOKUP(D19,'PN-Coding'!$A$2:$C$36,3,FALSE) -> 0
D20: Select from drop down | E20: =VLOOKUP(D20,'PN-Coding'!$A$2:$C$36,2,FALSE) -> 0 | G20: =VLOOKUP(D20,'PN-Coding'!$A$2:$C$36,3,FALSE) -> 0
D21: Select from drop down | E21: =VLOOKUP(D21,'PN-Coding'!$A$2:$C$36,2,FALSE) -> 0 | G21: =VLOOKUP(D21,'PN-Coding'!$A$2:$C$36,3,FALSE) -> 0
... D46: Select from drop down | E46: =VLOOKUP(D46,'PN-Coding'!$A$2:$C$36,2,FALSE) -> 0 | G46: =VLOOKUP(D46,'PN-Coding'!$A$2:$C$36,3,FALSE) -> 0
E200: Total Disbursements | F200: =SUM(F30:F35) -> 0

Sheet PN-Coding
A1: BUDGET ITEM/Description | B1: Activity Code | C1: Object Codes | D1: Subcontract ID | E1: Country
A2: Select from drop down
A3: Panama Personnel | B3: Personnel | C3: 7410 | D3: Fe y Alegria | E3: PN
A4: Fringe Benefits - Panama (31%) | B4: Fringe | C4: 7420 | D4: 0
A5: Equipment | B5: Equipment | C5: 7440
A6: Audit Costs | B6: Audit | C6: 7465
A7: Bank Fees | B7: Bank fees | C7: 7460
A8: Panama & Ecuador Communications (includes courier, phones etc.) | B8: Communications | C8: 7450
A9: Equipment Repair (all) | B9: Equip. Maint & Repair | C9: 7445
A10: Insurance | B10: Insurance | C10: 8170
A11: Legal Fees | B11: Legal | C11: 7470
A12: Office & Computer Supplies | B12: Supplies | C12: 7455
A13: Rent & Utilities | B13: Rent & Utilities | C13: 7435
A14: 1.4 Lodging & Per Diem Staff | B14: D.1.4 | C14: 7015
A15: 1.5 EpC Translation to Indigenous Languages | B15: D.1.5 | C15: 7740
A16: 1.5 Material Design and Printing | B16: D.1.5 | C16: 7710
... A43: 8.7 3Subcontract: ORGANIZATION TO BE DETERMINED | B43: D.8.7 | C43: 7370

Sheet PARTNERS - ACCIDENTE
C1: Partners of the Americas
C2: Monthly Cash Disbursements Journal
F3: 42490
F4: Panama
A6: * Choose from drop down list
A7: Date | B7: Ref or | C7: Payee | D7: *Budget Description | E7: *Activity | F7: Amount | G7: *Object | H7: Description of Expense | I7: Country | J7: Office | K7: *Subcontract | P7: Session Description
B8: CK# | E8: Code | F8: (USD) | G8: Code | K8: ID
A9: 42282 | B9: 203383 | C9: Enoc Molina | F9: 300 | H9: CARGO PARTNERS: Reconocimiento por Perdidas sufridas en accidente de Nuevo Vigia (24/sept/15) | I9: PN | J9: PN | K9: Fe y Alegria | P9: Reporte Financiero - Abril 2016
A10: 42282 | B10: 203384 | C10: Eugenio Rodriguez | F10: 300 | H10: CARGO PARTNERS: Reconocimiento por Perdidas sufridas en accidente de Nuevo Vigia (24/sept/15) | I10: PN | J10: PN | K10: Fe y Alegria | P10: Reporte Financiero - Abril 2016
A11: 42282 | B11: 203385 | C11: Alida Sierra de Victoria | F11: 300 | H11: CARGO PARTNERS: Reconocimiento por Perdidas sufridas en accidente de Nuevo Vigia (24/sept/15) | I11: PN | J11: PN | K11: Fe y Alegria | P11: Reporte Financiero - Abril 2016
F13: =SUM(F9:F11) -> 900
F131: =SUM(#REF!) -> #REF!

Sheet PARTNERS - LIBROS
C1: Partners of the Americas
C2: Monthly Cash Disbursements Journal
F3: 42490
F4: Panama
A6: * Choose from drop down list
A7: Date | B7: Ref or | C7: Payee | D7: *Budget Description | E7: *Activity | F7: Amount | G7: *Object | H7: Description of Expense | I7: Country | J7: Office | K7: *Subcontract | P7: Session Description
B8: CK# | E8: Code | F8: (USD) | G8: Code | K8: ID
A9: 42426 | B9: 203635 | C9: Daphnee Ferguson | F9: 190 | H9: PARTNERS - Donacion de Libros: Honorarios Logistica Donacion de Libros (pago 1/5) | I9: PN | J9: PN | K9: Fe y Alegria | P9: Reporte Financiero - Abril 2016
A10: 42444 | B10: 203661 | C10: Daphnee Ferguson | F10: 380 | H10: PARTNERS - Donacion de Libros: Honorarios Logistica Donacion de Libros (pago 2/5) | I10: PN | J10: PN | K10: Fe y Alegria | P10: Reporte Financiero - Abril 2016
A11: 42451 | B11: 203668 | C11: Daphnee Ferguson | F11: 620 | H11: PARTNERS - Donacion de Libros: Viaticos a Darien | I11: PN | J11: PN | K11: Fe y Alegria | P11: Reporte Financiero - Abril 2016
A12: 42451 | B12: 203677 | C12: Daphnee Ferguson | F12: 700 | H12: PARTNERS - Donacion de Libros: Viaticos a C.Ngabe y Changuinola | I12: PN | J12: PN | K12: Fe y Alegria | P12: Reporte Financiero - Abril 2016
A13: 42451 | B13: 203678 | C13: Daphnee Ferguson | F13: 380 | H13: PARTNERS - Donacion de Libros: Honorarios Logistica Donacion de Libros (3/5) | I13: PN | J13: PN | K13: Fe y Alegria | P13: Reporte Financiero - Abril 2016
A14: 42464 | B14: S/R | C14: BAC Panama | F14: =22.45+35 -> 57.45 | H14: PARTNERS - Donacion de Libros: Cargos Bancarios: Comision por transferencia Internacional | I14: PN | J14: PN | K14: Fe y Alegria | P14: Reporte Financiero - Abril 2016
A15: 42464 | B15: 203695 | C15: Daphnee Ferguson | F15: 475 | H15: PARTNERS - Donacion de Libros: Honorarios Logistica Donacion de Libros (4/5) | I15: PN | J15: PN | K15: Fe y Alegria | P15: Reporte Financiero - Abril 2016
A16: 42464 | B16: 203701 | C16: Ana Lorena Jovane | F16: 1000 | H16: PARTNERS - Donacion de Libros: Entrega de donacion en comunidades (logistica) | I16: PN | J16: PN | K16: Fe y Alegria | P16: Reporte Financiero - Abril 2016
A17: 42478 | B17: 203720 | C17: Daphnee Ferguson | F17: 1505 | H17: PARTNERS - Donacion de Libros: Distribucion / Coordinacion | I17: PN | J17: PN | K17: Fe y Alegria | P17: Reporte Financiero - Abril 2016
A18: 42478 | B18: 203722 | C18: Ana Lorena Jovane | F18: 1700 | H18: PARTNERS - Donacion de Libros: Distribucion (viaticos) | I18: PN | J18: PN | K18: Fe y Alegria | P18: Reporte Financiero - Abril 2016
A19: 18 abrl 16 | C19: BAC Panama | F19: =22.45+35 -> 57.45 | H19: PARTNERS - Donacion de Libros: Cargos Bancarios: Comision por transferencia Internacional | I19: PN | J19: PN | K19: Fe y Alegria | P19: Reporte Financiero - Abril 2016
A20: 42485 | B20: 203726 | C20: Daphnee Ferguson | F20: 475 | H20: PARTNERS - Donacion de Libros: Honorarios Logistica Donacion de Libros (5/5) | I20: PN | J20: PN | K20: Fe y Alegria | P20: Reporte Financiero - Abril 2016
F22: =SUM(F9:F21) -> 7539.9
F140: =SUM(#REF!) -> #REF!

Sheet codes
A1: Activity Title | B1: Activity Code | C1: G/L Code
A2: Personnel | B2: PERSNL | C2: 7410
A3: Fringe Benefits | B3: FRINGE | C3: 7420
A4: Equipment | B4: EQUIP | C4: 7440
A5: Audit | B5: AUDIT | C5: 8230
A6: Bank Fees | B6: BANK FEES | C6: 7460
A7: Communications | B7: COMM | C7: 7450
A8: Equipment & Maint. Repair | B8: EQ.MNT REP | C8: 7445
A9: Insurance | B9: INSURANCE | C9: 8170
A10: Legal Fees | B10: LEGAL | C10: 7470
A11: Supplies | B11: SUPPLIES | C11: 7455
A12: Rent & Utilities | B12: RENT & UT | C12: 7435
A13: EPC Translations to Indigenous Languages & Matl Design Print | B13: D.1.5.A | C13: 7740
... A51: Final Evaluation | B51: D.10.10 | C51: 8221
A52: HQ Mgmt travel | B52: D.10.7.D | C52: 7510/7520
A53: Mid-term Evaluation | B53: D.10.9 | C53: 8221
A54: Subcontract: ExpoFlores - Education | B54: D.1.8.F | C54: 7370
A55: Subcontract: Comunidec - Zonal Coordinators | B55: D.10.11.D | C55: 7370
A56: Subcontract: FUDELA - Zonal Coordinators | B56: D.10.11.E | C56: 7370
A57: Subcontract: ExpoFlores - Zonal Coordinators | B57: D.10.11.F | C57: 7370
A58: Social Protection Svs. In Targated Communities | B58: D.3.1 | C58: 7120
A60: WASHINGTON
A61: Personnel | B61: PERSNL
A62: Fringe Benefits | B62: FRINGE
A63: Communications | B63: COMM
A64: Entrena Quantum Learning Teachers | B64: D.1.1
A65: Entrena Epc Facilitators Training | B65: D.1.2
A66: EpC Adaptation & Implementation | B66: D.1.3
A67: Entrena EPC Material Adaptation | B67: D.1.4
A68: Aganar Quality Control | B68: D.4.1
A69: Task Mapping Risk Assessment | B69: D.5.1
A70: CSR Technical Review | B70: D.5.2
A71: DevTech: M&E Specialist | B71: D.10.1
A72: Indirect Costs | B72: IDC
... A88: Software for Data Collection & Mgmt | B88: D.10.4
A91: PANAMA
A92: Personnel | B92: PERSNL | C92: 7410
A93: Fringe Benefits | B93: FRINGE | C93: 7420
A94: Equipment | B94: EQUIP | C94: 7440
A95: Audit | B95: AUDIT | C95: 8230
...

Sheet CODES NEWS
A1: Personnel | B1: PERSNL | C1: 7410 | D1: 657695.3
A2: Fringe Benefits | B2: FRINGE | C2: 7420 | D2: 228456
A3: Equipment | B3: EQUIP | C3: 7440 | D3: 11655
A4: Audit | B4: AUDIT | C4: 8230 | D4: 20000
A5: Bank Fees | B5: BANK FEES | C5: 7460 | D5: 4800
A6: Communications | B6: COMM | C6: 7450 | D6: 6200
A7: Equipment & Maint. Repair | B7: EQ.MNT REP | C7: 7445 | D7: 7000
A8: Insurance | B8: INSURANCE | C8: 8170 | D8: 4000
A9: Legal Fees | B9: LEGAL | C9: 7470 | D9: 1000
A10: Supplies | B10: SUPPLIES | C10: 7455 | D10: 3600
A11: Rent & Utilities | B11: RENT & UT | C11: 7435 | D11: 67200
A12: EPC Translations to Indigenous Languages & Matl Design Print | B12: D.1.5.A | C12: 7740 | D12: 57971.5
... A17: Subcontract: APROTENGB - Education | B17: D.1.8.C | C17: 7370 | D17: 84000
A18: EducaFuturo Darien | B18: D.1.8.G | C18: ???? | D18: 50228
A19: Final Evaluation | B19: D.10.10 | C19: 8221 | D19: 17500
A20: Subcontract: Fe y Alegria - Zonal Coordinators | B20: D.10.11.A | C20: 7370 | D20: 29188
A21: Subcontract: APRODISO - Zonal Coordinators | B21: D.10.11.B | C21: 7370 | D21: 12485
A22: Subcontract: APROTENGB - Zonal Coordinators | B22: D.10.11.C | C22: 7370 | D22: 39296
A23: Data Base Technician Equipment | B23: D.10.12 | C23: 7440 | D23: 1000
A24: DevTech Baseline Survey | B24: D.10.2 | C24: 8221 | D24: 36743
A25: DevTech Follow-up Survey | B25: D.10.3 | C25: 8221 | D25: 34500
A26: Research Survey, Analysis and Report | B26: D.10.5 | C26: ???? | D26: 10000
A27: CMEP Workshops | B27: D.10.6 | C27: 7120 | D27: 3638.24
A28: Establish M&E System- Airfare & Lodging and Per diem | B28: D.10.7.A | C28: 7010/7015 | D28: 2200
A29: Program Mgmt.- Airfare & Lodging and Per diem | B29: D.10.7.B | C29: 7510/7520 | D29: 6600
A30: Field Verification Trip Airfare, Local Transp & Lodging and per diem - Field Verification Visits | B30: D.10.7.C | C30: 7010/7015 | D30: 22500
A31: HQ Mgmt travel | B31: D.10.7.D | C31: 7510/7520 | D31: 500
A32: Annual Visits DOL | B32: D.10.8 | C32: 7431 | D32: 3000
A33: Mid-term Evaluation | B33: D.10.9 | C33: 8221 | D33: 17500
A34: Stakeholders Presentation of Program Evaluation | B34: D.11.1 | C34: 8221 | D34: 1175
A35: Closing Ceremony & Presentation of Program Results | B35: D.11.2 | C35: 7391 | D35: 2250
A36: Value Chain Analysis | B36: D.2.1 | C36: 7499 | D36: 4000
A37: Linking Households to Livelihood Programs | B37: D.2.2 | C37: 7499 | D37: 3525
A38: Tech Assist.to Develop Links to Business Activities | B38: D.2.3 | C38: 7120 | D38: 7500
A39: Subcontract: Fe y Alegria | B39: D.2.5.A | C39: 7370 | D39: 35000
A40: Subcontract: APROTENGB - Livelihoods | B40: D.2.5.C | C40: 7370 | D40: 14000
A41: EducaFuturo Darien - Livelihoods | B41: D.2.5.G | C41: ???? | D41: 30000
A42: Social Protection Svs. In Targated Communities | B42: D.3.1 | C42: 7120 | D42: 2500
A43: Subcontract: Fe y Alegria - Social Protection | B43: D.3.2.A | C43: 7370 | D43: 4688
A44: Subcontract: APROTENGB - Social Protection | B44: D.3.2.C | C44: 7370 | D44: 1875
...

Sheet Bank Recon
A2: DOL423 - Mexico
A3: Bank Reconciliation
A4: Bank Account: 22-00079459-3 Banco Santander
A5: Month and Year: | C5: 45108
A6: Exchange Rate for the Month MXN to USD | C6: 16.9203
A7: According to the Bank
A8: Balance as end of: | B8: 45108 | F8: 890791.97
A9: Plus:
A10: Deposits in Transit | F10: 0
A11: Less:
A12: Check in Transit | F12: =SUM(D14:D19) -> 0
A13: Number of Check | B13: Details of Expense | C13: Date | D13: Amount
D14: 0
D15: 0
D16: 0
D17: 0
D18: 0
D19: 0
B21: Balance According to the Bank: | C21: =C5 -> 45108 | F21: =F8+F10-F12 -> 890791.97
B22: Exchange Rate Applied MXN to USD | F22: =C6 -> 16.9203
B24: USD Balance According to the Bank end of: | C24: =C21 -> 45108 | F24: =F21/F22 -> 52646.346
A26: According to the Books
A27: Balance as Beginning of: | B27: =B8 -> 45108 | F27: 826863.71
A28: Plus:
A29: Deposits for the Month | F29: 426579.38
A30: Less:
A31: Check Written in Current Month | F31: 362651.12
B33: MXN Balance According to the Books end of: | C33: =C21 -> 45108 | F33: =F27+F29-F31 -> 890791.97
B34: Exchange Rate Applied MXN to USD | F34: =C6 -> 16.9203
B36: USD Balance According to the Books end of: | C36: =C33 -> 45108 | F36: =F33/F34 -> 52646.346
B38: Difference of Bank and Book Balance as end of: | C38: =C36 -> 45108 | F38: =F24-F36 -> 0
A40: By signing this report, I certify that the expenses contained in the present report for month of July 2023 equivalent to US dollars $13,309.59 were incurred by the entity, and are related to activities carried out by the project. I certify to the best of my knowledge and belief that the report is true, complete, and accurate, and that the expenditures and disbursements are for the purposes and objectives set forth in the terms and conditions of the Department of Labor (DOL) Award. I am aware that any false, fictitious, or fraudulent information, or the omission of any material fact, may subject me to criminal, civil or administrative penalties for fraud, false statements, false claims or otherwise. I understand that if the expenses contained herein are questioned or not approved by Partners CFO or by DOL, I will provide full cooperation to all the involved parties to complete such review, audit or investigation. | H40: Completar con el total de expensas del mes
A44: Prepared By:
B45: Finance-Administrative Director | D45: Date
A47: Approved By:
B48: Project Director | D48: Date

Sheet ACUMULADO
A1: Financial Summary | CE1: Financial Summary
B2: TOTAL BUDGET PANAMA - JULIO 2016 | C2: Budget Yr 1 | D2: First Quarter Expenditures | H2: Second Quarter Expenditures | L2: Third Quarter Expenditures | P2: Fourth Quarter Expenditures | T2: TOTAL | V2: Budget Yr1 | W2: Budget Yr 2 | X2: First Quarter Expenditures | AB2: Second Quarter Expenditures | AF2: Third Quarter Expenditures | AJ2: Fourth Quarter Expenditures | AN2: TOTAL | AP2: Budget Yr2 | AQ2: Budget Yr 3 | AR2: First Quarter Expenditures | AV2: Second Quarter Expenditures | AZ2: Third Quarter Expenditures | BD2: Fourth Quarter Expenditures | BH2: TOTAL | BJ2: Budget Yr3 | BK2: Budget Yr 4 | BL2: First Quarter Expenditures | BP2: Second Quarter Expenditures | BT2: Third Quarter Expenditures | BX2: Fourth Quarter Expenditures | CB2: TOTAL | CD2: Remaining
A3: Budget Description | D3: 41275 | E3: 41306 | F3: 41334 | G3: TOTAL | H3: 41365 | I3: 41395 | J3: 41426 | K3: TOTAL | L3: 41456 | M3: 41487 | N3: 41518 | O3: TOTAL | P3: 41548 | Q3: 41579 | R3: 41609 | S3: TOTAL | T3: EXPENDITURES 2013 | U3: % Implemetation | V3: Remaining | X3: 41640 | Y3: 41671 | Z3: 41699 | AA3: TOTAL | AB3: 41730 | AC3: 41760 | AD3: 41791 | AE3: TOTAL | AF3: 41821 | AG3: 41852 | AH3: 41883 | AI3: TOTAL | AJ3: 41913 | AK3: 41944 | AL3: 41974 | AM3: TOTAL | AN3: EXPENDITURES 2014 | AO3: % Implemetation | AP3: Remaining | AR3: 42005 | AS3: 42036 | AT3: 42064 | AU3: TOTAL | AV3: 42095 | AW3: 42125 | AX3: 42156 | AY3: TOTAL | AZ3: 42186 | BA3: 42217 | BB3: 42248 | BC3: TOTAL | BD3: 42278 | BE3: 42309 | BF3: 42339 | BG3: TOTAL | BH3: EXPENDITURES 2015 | BI3: % Implemetation | BJ3: Remaining | BL3: 42370 | BM3: 42401 | BN3: 42430 | BO3: TOTAL | BP3: 42461 | BQ3: 42491 | BR3: 42522 | BS3: TOTAL | BT3: 42552 | BU3: 42583 | BV3: 42614 | BW3: TOTAL | BX3: 42644 | BY3: 42675 | BZ3: 42705 | CA3: TOTAL | CB3: EXPENDITURES 2016 | CC3: % Implemetation | CE3: Budget Description
A4: Panama Personnel | B4: 702235.8 | C4: ='budget anual'!C6 -> #REF! | E4: 10962.24 | F4: 12340.35 | G4: =SUM(D4:F4) -> 23302.59 | H4: 15931.56 | I4: 15080.15 | J4: 15080.15 | K4: =SUM(H4:J4) -> 46091.86 | L4: 15080.15 | M4: 15080.15 | N4: 15095.39 | O4: =SUM(L4:N4) -> 45255.69 | P4: 15135.15 | Q4: 14159.89 | R4: 14080.15 | S4: =SUM(P4:R4) -> 43375.19 | T4: =G4+K4+O4+S4 -> 158025.33 | U4: =T4/C4 -> #REF! | V4: =C4-T4 -> #REF! | W4: ='budget anual'!D6 -> #REF! | X4: 14938.64 | Y4: 15030.16 | Z4: 15030.16 | AA4: =SUM(X4:Z4) -> 44998.96 | AB4: 15030.17 | AC4: 15030.15 | AD4: 15030.15 | AE4: =SUM(AB4:AD4) -> 45090.47 | AF4: 15030.15 | AG4: 15030.17 | AH4: 14934.7 | AI4: =SUM(AF4:AH4) -> 44995.02 | AJ4: =14969.3+13.12 -> 14982.42 | AK4: 15030.16 | AL4: 13180.16 | AM4: =SUM(AJ4:AL4) -> 43192.74 | AN4: =AA4+AE4+AI4+AM4 -> 178277.19 | AO4: =AN4/W4 -> #REF! | AP4: =(V4+W4)-AN4 -> #REF! | AQ4: ='budget anual'!E6 -> 131000 | AR4: 12123.73 | AS4: 14085.16 | AT4: 8056.65 | AU4: =SUM(AR4:AT4) -> 34265.54 | AV4: 7926.66 | AW4: 8843.31 | AX4: 8109.97 | AY4: =SUM(AV4:AX4) -> 24879.94 | AZ4: 8344.25 | BA4: 8859.98 | BB4: 9609.98 | BC4: =SUM(AZ4:BB4) -> 26814.21 | BD4: 10019.03 | BE4: 10359.96 | BF4: 10133.25 | BG4: =SUM(BD4:BF4) -> 30512.24 | BH4: =AU4+AY4+BC4+BG4 -> 116471.93 | BI4: =BH4/AQ4 -> 0.8890987 | BJ4: =(AP4+AQ4)-BH4 -> #REF! | BK4: =B4-T4-AN4-BH4 -> 249461.35 | BL4: 10412.99 | BM4: 9959.98 | BN4: 10309.97 | BO4: =SUM(BL4:BN4) -> 30682.94 | BP4: 10683.84 | BQ4: 10909.99 | BR4: 10809.98 | BS4: =SUM(BP4:BR4) -> 32403.81 | BT4: 10309.98 | BU4: =11059.12-500 -> 10559.12 | BV4: 10309.97 | BW4: =SUM(BT4:BV4) -> 31179.07 | BX4: 10809.97 | BY4: 8574.89 | BZ4: 6392.57 | CA4: =SUM(BX4:BZ4) -> 25777.43 | CB4: =BO4+BS4+BW4+CA4 -> 120043.25 | CC4: =CB4/BK4 -> 0.48120981 | CD4: =BK4-CB4 -> 129418.1 | CE4: Panama Personnel
A5: Fringe Benefits | B5: 228456 | C5: ='budget anual'!C8 -> #REF! | F5: 2080.88 | G5: =SUM(D5:F5) -> 2080.88 | H5: 6533.09 | I5: 2179.68 | J5: 2168.53 | K5: =SUM(H5:J5) -> 10881.3 | L5: 2168.53 | M5: 7739.87 | N5: 2188.44 | O5: =SUM(L5:N5) -> 12096.84 | P5: 4983.75 | Q5: 2130.33 | R5: 7222.66 | S5: =SUM(P5:R5) -> 14336.74 | T5: =G5+K5+O5+S5 -> 39395.76 | U5: =T5/C5 -> #REF! | V5: =C5-T5 -> #REF! | W5: ='budget anual'!D8 -> #REF! | X5: 2148.18 | Y5: 2161.33 | Z5: 2161.33 | AA5: =SUM(X5:Z5) -> 6470.84 | AB5: 7657.68 | AC5: 2161.34 | AD5: 2161.34 | AE5: =SUM(AB5:AD5) -> 11980.36 | AF5: 2161.34 | AG5: 7709.95 | AH5: 2147.61 | AI5: =SUM(AF5:AH5) -> 12018.9 | AJ5: 4037.12 | AK5: 2161.33 | AL5: 13254.69 | AM5: =SUM(AJ5:AL5) -> 19453.14 | AN5: =AA5+AE5+AI5+AM5 -> 49923.24 | AO5: =AN5/W5 -> #REF! | AP5: =(V5+W5)-AN5 -> #REF! | AQ5: ='budget anual'!E8 -> #REF! | AR5: 3006.2 | AS5: 9015.93 | AT5: 1067.96 | AU5: =SUM(AR5:AT5) -> 13090.09 | AV5: 3350.84 | AW5: 1271.67 | AX5: 1166.22 | AY5: =SUM(AV5:AX5) -> 5788.73 | AZ5: 1395.5 | BA5: 4327.25 | BB5: 1381.92 | BC5: =SUM(AZ5:BB5) -> 7104.67 | BD5: 1440.75 | BE5: 1489.77 | BF5: 5379.12 | BG5: =SUM(BD5:BF5) -> 8309.64 | BH5: =AU5+AY5+BC5+BG5 -> 34293.13 | BI5: =BH5/AQ5 -> #REF! | BJ5: =(AP5+AQ5)-BH5 -> #REF! | BK5: =B5-T5-AN5-BH5 -> 104843.87 | BL5: 1479.92 | BM5: 1432.25 | BN5: 1482.58 | BO5: =SUM(BL5:BN5) -> 4394.75 | BP5: 4917.38 | BQ5: 1518.53 | BR5: 1482.58 | BS5: =SUM(BP5:BR5) -> 7918.49 | BT5: 1482.59 | BU5: 5039.54 | BV5: 1482.58 | BW5: =SUM(BT5:BV5) -> 8004.71 | BX5: 11333.51 | BY5: 5076.61 | BZ5: 25835.2 | CA5: =SUM(BX5:BZ5) -> 42245.32 | CB5: =BO5+BS5+BW5+CA5 -> 62563.27 | CC5: =CB5/BK5 -> 0.59672797 | CD5: =BK5-CB5 -> 42280.6 | CE5: Fringe Benefits
A6: Equipment | B6: 11655 | C6: ='budget anual'!C17 -> 11655 | G6: =SUM(D6:F6) -> 0 | H6: =208.97+4862.08 -> 5071.05 | I6: 2843.77 | J6: 3431.87 | K6: =SUM(H6:J6) -> 11346.69 | L6: 74.9 | O6: =SUM(L6:N6) -> 74.9 | Q6: 475.08 | S6: =SUM(P6:R6) -> 475.08 | T6: =G6+K6+O6+S6 -> 11896.67 | U6: =T6/C6 -> 1.0207353 | V6: =C6-T6 -> -241.67 | W6: 0 | AA6: =SUM(X6:Z6) -> 0 | AD6: 93.09 | AE6: =SUM(AB6:AD6) -> 93.09 | AI6: =SUM(AF6:AH6) -> 0 | AM6: =SUM(AJ6:AL6) -> 0 | AN6: =AA6+AE6+AI6+AM6 -> 93.09 | AP6: =(V6+W6)-AN6 -> -334.76 | AQ6: 0 | AU6: =SUM(AR6:AT6) -> 0 | AV6: 972.63 | AY6: =SUM(AV6:AX6) -> 972.63 | BC6: =SUM(AZ6:BB6) -> 0 | BG6: =SUM(BD6:BF6) -> 0 | BH6: =AU6+AY6+BC6+BG6 -> 972.63 | BJ6: =(AP6+AQ6)-BH6 -> -1307.39 | BK6: =B6-T6-AN6-BH6 -> -1307.39 | BO6: =SUM(BL6:BN6) -> 0 | BS6: =SUM(BP6:BR6) -> 0 | BW6: =SUM(BT6:BV6) -> 0 | CA6: =SUM(BX6:BZ6) -> 0 | CB6: =BO6+BS6+BW6+CA6 -> 0 | CD6: =BK6-CB6 -> -1307.39 | CE6: Equipment
A7: Audit | B7: 20000 | C7: ='budget anual'!C30 -> 5000 | G7: =SUM(D7:F7) -> 0 | K7: =SUM(H7:J7) -> 0 | O7: =SUM(L7:N7) -> 0 | R7: 1350 | S7: =SUM(P7:R7) -> 1350 | T7: =G7+K7+O7+S7 -> 1350 | U7: =T7/C7 -> 0.27 | V7: =C7-T7 -> 3650 | W7: ='budget anual'!D30 -> 5000 | X7: 3150 | AA7: =SUM(X7:Z7) -> 3150 | AE7: =SUM(AB7:AD7) -> 0 | AI7: =SUM(AF7:AH7) -> 0 | AM7: =SUM(AJ7:AL7) -> 0 | AN7: =AA7+AE7+AI7+AM7 -> 3150 | AO7: =AN7/W7 -> 0.63 | AP7: =(V7+W7)-AN7 -> 5500 | AQ7: ='budget anual'!E30 -> 5000 | AR7: 2325 | AS7: 2325 | AU7: =SUM(AR7:AT7) -> 4650 | AY7: =SUM(AV7:AX7) -> 0 | BC7: =SUM(AZ7:BB7) -> 0 | BG7: =SUM(BD7:BF7) -> 0 | BH7: =AU7+AY7+BC7+BG7 -> 4650 | BI7: =BH7/AQ7 -> 0.93 | BJ7: =(AP7+AQ7)-BH7 -> 5850 | BK7: =B7-T7-AN7-BH7 -> 10850 | BL7: 1395 | BM7: 1040 | BN7: 3050.43 | BO7: =SUM(BL7:BN7) -> 5485.43 | BS7: =SUM(BP7:BR7) -> 0 | BW7: =SUM(BT7:BV7) -> 0 | CA7: =SUM(BX7:BZ7) -> 0 | CB7: =BO7+BS7+BW7+CA7 -> 5485.43 | CC7: =CB7/BK7 -> 0.50556959 | CD7: =BK7-CB7 -> 5364.57 | CE7: Audit
A8: Bank Fees | B8: 4800 | C8: ='budget anual'!C28 -> 1200 | E8: 21.4 | F8: 6.85 | G8: =SUM(D8:F8) -> 28.25 | H8: =5.35+21.4+1.5 -> 28.25 | I8: 35.4 | J8: 28.85 | K8: =SUM(H8:J8) -> 92.5 | L8: 463.6 | M8: 49.95 | N8: 7.65 | O8: =SUM(L8:N8) -> 521.2 | P8: 8.95 | Q8: 28.95 | R8: 33.9 | S8: =SUM(P8:R8) -> 71.8 | T8: =G8+K8+O8+S8 -> 713.75 | U8: =T8/C8 -> 0.59479167 | V8: =C8-T8 -> 486.25 | W8: ='budget anual'!D28 -> 1200 | X8: 40.05 | Y8: 8.95 | Z8: 50.55 | AA8: =SUM(X8:Z8) -> 99.55 | AB8: 44.5 | AC8: 7.35 | AD8: 111.04 | AE8: =SUM(AB8:AD8) -> 162.89 | AF8: 16.44 | AG8: 66.64 | AH8: 68.44 | AI8: =SUM(AF8:AH8) -> 151.52 | AJ8: 10.49 | AK8: 67.94 | AL8: 67.54 | AM8: =SUM(AJ8:AL8) -> 145.97 | AN8: =AA8+AE8+AI8+AM8 -> 559.93 | AO8: =AN8/W8 -> 0.46660833 | AP8: =(V8+W8)-AN8 -> 1126.32 | AQ8: ='budget anual'!E28 -> 1200 | AR8: 94.49 | AS8: 10.49 | AT8: 70.08 | AU8: =SUM(AR8:AT8) -> 175.06 | AV8: 70.08 | AW8: 76.71 | AX8: 77.21 | AY8: =SUM(AV8:AX8) -> 224 | AZ8: 70.38 | BA8: 68.48 | BB8: 70.18 | BC8: =SUM(AZ8:BB8) -> 209.04 | BD8: 69.48 | BE8: 78.31 | BF8: 79.01 | BG8: =SUM(BD8:BF8) -> 226.8 | BH8: =AU8+AY8+BC8+BG8 -> 834.9 | BI8: =BH8/AQ8 -> 0.69575 | BJ8: =(AP8+AQ8)-BH8 -> 1491.42 | BK8: =B8-T8-AN8-BH8 -> 2691.42 | BL8: 69.78 | BM8: 128.63 | BN8: 69.78 | BO8: =SUM(BL8:BN8) -> 268.19 | BP8: 449.33 | BQ8: 22.96 | BR8: 79.71 | BS8: =SUM(BP8:BR8) -> 552 | BT8: 72.48 | BU8: 74.28 | BV8: 41.92 | BW8: =SUM(BT8:BV8) -> 188.68 | BX8: 72.38 | BY8: 69.58 | BZ8: 19.56 | CA8: =SUM(BX8:BZ8) -> 161.52 | CB8: =BO8+BS8+BW8+CA8 -> 1170.39 | CC8: =CB8/BK8 -> 0.43485967 | CD8: =BK8-CB8 -> 1521.03 | CE8: Bank Fees
A9: Communications (courier, phones etc.) | B9: 6200 | C9: ='budget anual'!C19+'budget anual'!C20+'budget anual'!C21 -> 1550 | F9: 87.74 | G9: =SUM(D9:F9) -> 87.74 | I9: 107 | J9: 113.42 | K9: =SUM(H9:J9) -> 220.42 | O9: =SUM(L9:N9) -> 0 | P9: 163.07 | Q9: 88.25 | R9: 56.05 | S9: =SUM(P9:R9) -> 307.37 | T9: =G9+K9+O9+S9 -> 615.53 | U9: =T9/C9 -> 0.39711613 | V9: =C9-T9 -> 934.47 | W9: ='budget anual'!D19+'budget anual'!D20+'budget anual'!D21 -> 1550 | X9: 56.05 | Y9: 61.02 | Z9: 56.05 | AA9: =SUM(X9:Z9) -> 173.12 | AB9: 56.05 | AC9: 127.64 | AD9: 100.51 | AE9: =SUM(AB9:AD9) -> 284.2 | AF9: 100.21 | AG9: 100.51 | AH9: 158.01 | AI9: =SUM(AF9:AH9) -> 358.73 | AJ9: 395.83 | AK9: 100.19 | AL9: 123.96 | AM9: =SUM(AJ9:AL9) -> 619.98 | AN9: =AA9+AE9+AI9+AM9 -> 1436.03 | AO9: =AN9/W9 -> 0.92647097 | AP9: =(V9+W9)-AN9 -> 1048.44 | AQ9: ='budget anual'!E19+'budget anual'!E20+'budget anual'!E21 -> 1550 | AR9: 100.51 | AS9: 699.71 | AT9: 158.43 | AU9: =SUM(AR9:AT9) -> 958.65 | AV9: 170.51 | AW9: 143.31 | AX9: 167.51 | AY9: =SUM(AV9:AX9) -> 481.33 | AZ9: 116.61 | BA9: 164.21 | BB9: 600.69 | BC9: =SUM(AZ9:BB9) -> 881.51 | BD9: 143.31 | BE9: 153.72 | BF9: 104.93 | BG9: =SUM(BD9:BF9) -> 401.96 | BH9: =AU9+AY9+BC9+BG9 -> 2723.45 | BI9: =BH9/AQ9 -> 1.7570645 | BJ9: =(AP9+AQ9)-BH9 -> -125.01 | BK9: =B9-T9-AN9-BH9 -> 1424.99 | BL9: 146.63 | BM9: 160.64 | BN9: 121.51 | BO9: =SUM(BL9:BN9) -> 428.78 | BP9: 156.5 | BQ9: 183.58 | BR9: 114.29 | BS9: =SUM(BP9:BR9) -> 454.37 | BT9: 203.99 | BU9: 173.92 | BV9: 308.18 | BW9: =SUM(BT9:BV9) -> 686.09 | BX9: 143.31 | BY9: 159.38 | BZ9: 220.19 | CA9: =SUM(BX9:BZ9) -> 522.88 | CB9: =BO9+BS9+BW9+CA9 -> 2092.12 | CC9: =CB9/BK9 -> 1.4681647 | CD9: =BK9-CB9 -> -667.13 | CE9: Communications (courier, phones etc.)
A10: Equpment (all) maintenance & Repairs | B10: 11800 | C10: ='budget anual'!C26+'budget anual'!C27+'budget anual'!C29 -> 2950 | G10: =SUM(D10:F10) -> 0 | H10: =50+7.5 -> 57.5 | I10: 80.2 | J10: 72.87 | K10: =SUM(H10:J10) -> 210.57 | M10: 251.26 | N10: 491.13 | O10: =SUM(L10:N10) -> 742.39 | P10: 10 | Q10: 115 | S10: =SUM(P10:R10) -> 125 | T10: =G10+K10+O10+S10 -> 1077.96 | U10: =T10/C10 -> 0.36541017 | V10: =C10-T10 -> 1872.04 | W10: ='budget anual'!D26+'budget anual'!D27+'budget anual'!D29 -> 2950 | Y10: 19.73 | Z10: 115.5 | AA10: =SUM(X10:Z10) -> 135.23 | AB10: 70 | AC10: 137.8 | AD10: 80 | AE10: =SUM(AB10:AD10) -> 287.8 | AF10: 34.5 | AG10: 147.13 | AH10: 146.4 | AI10: =SUM(AF10:AH10) -> 328.03 | AJ10: 72.07 | AL10: 12.16 | AM10: =SUM(AJ10:AL10) -> 84.23 | AN10: =AA10+AE10+AI10+AM10 -> 835.29 | AO10: =AN10/W10 -> 0.28314915 | AP10: =(V10+W10)-AN10 -> 3986.75 | AQ10: ='budget anual'!E26+'budget anual'!E27+'budget anual'!E29 -> 2950 | AR10: 248.85 | AS10: 196.38 | AT10: 508.84 | AU10: =SUM(AR10:AT10) -> 954.07 | AV10: 432.97 | AW10: 292.83 | AX10: 277.96 | AY10: =SUM(AV10:AX10) -> 1003.76 | AZ10: 283.64 | BA10: 179.59 | BB10: 402.01 | BC10: =SUM(AZ10:BB10) -> 865.24 | BD10: 240.4 | BE10: 233 | BG10: =SUM(BD10:BF10) -> 473.4 | BH10: =AU10+AY10+BC10+BG10 -> 3296.47 | BI10: =BH10/AQ10 -> 1.1174475 | BJ10: =(AP10+AQ10)-BH10 -> 3640.28 | BK10: =B10-T10-AN10-BH10 -> 6590.28 | BL10: 332.95 | BM10: 159.06 | BN10: 1495.27 | BO10: =SUM(BL10:BN10) -> 1987.28 | BP10: 86 | BQ10: 579.94 | BR10: 578.88 | BS10: =SUM(BP10:BR10) -> 1244.82 | BT10: =450+44.9 -> 494.9 | BU10: =232.06-5-20 -> 207.06 | BV10: 770.7 | BW10: =SUM(BT10:BV10) -> 1472.66 | BX10: 502.69 | BY10: 68.26 | BZ10: 1044.82 | CA10: =SUM(BX10:BZ10) -> 1615.77 | CB10: =BO10+BS10+BW10+CA10 -> 6320.53 | CC10: =CB10/BK10 -> 0.95906851 | CD10: =BK10-CB10 -> 269.75 | CE10: Equpment (all) maintenance & Repairs
A11: Insurance | B11: 4000 | C11: ='budget anual'!C31 -> 1000 | G11: =SUM(D11:F11) -> 0 | K11: =SUM(H11:J11) -> 0 | O11: =SUM(L11:N11) -> 0 | S11: =SUM(P11:R11) -> 0 | T11: =G11+K11+O11+S11 -> 0 | U11: =T11/C11 -> 0 | V11: =C11-T11 -> 1000 | W11: ='budget anual'!D31 -> 1000 | AA11: =SUM(X11:Z11) -> 0 | AE11: =SUM(AB11:AD11) -> 0 | AH11: 77 | AI11: =SUM(AF11:AH11) -> 77 | AM11: =SUM(AJ11:AL11) -> 0 | AN11: =AA11+AE11+AI11+AM11 -> 77 | AO11: =AN11/W11 -> 0.077 | AP11: =(V11+W11)-AN11 -> 1923 | AQ11: ='budget anual'!E31 -> 1000 | AU11: =SUM(AR11:AT11) -> 0 | AY11: =SUM(AV11:AX11) -> 0 | BC11: =SUM(AZ11:BB11) -> 0 | BG11: =SUM(BD11:BF11) -> 0 | BH11: =AU11+AY11+BC11+BG11 -> 0 | BI11: =BH11/AQ11 -> 0 | BJ11: =(AP11+AQ11)-BH11 -> 2923 | BK11: =B11-T11-AN11-BH11 -> 3923 | BO11: =SUM(BL11:BN11) -> 0 | BS11: =SUM(BP11:BR11) -> 0 | BW11: =SUM(BT11:BV11) -> 0 | CA11: =SUM(BX11:BZ11) -> 0 | CB11: =BO11+BS11+BW11+CA11 -> 0 | CC11: =CB11/BK11 -> 0 | CD11: =BK11-CB11 -> 3923 | CE11: Insurance
A12: Legal | B12: 1000 | C12: ='budget anual'!C32 -> 0 | G12: =SUM(D12:F12) -> 0 | K12: =SUM(H12:J12) -> 0 | O12: =SUM(L12:N12) -> 0 | S12: =SUM(P12:R12) -> 0 | T12: =G12+K12+O12+S12 -> 0 | U12: =T12/C12 -> #DIV/0! | V12: =C12-T12 -> 0 | W12: ='budget anual'!D32 -> 250 | AA12: =SUM(X12:Z12) -> 0 | AE12: =SUM(AB12:AD12) -> 0 | AI12: =SUM(AF12:AH12) -> 0 | AK12: 214 | AM12: =SUM(AJ12:AL12) -> 214 | AN12: =AA12+AE12+AI12+AM12 -> 214 | AO12: =AN12/W12 -> 0.856 | AP12: =(V12+W12)-AN12 -> 36 | AQ12: ='budget anual'!E32 -> 500 | AU12: =SUM(AR12:AT12) -> 0 | AW12: 214 | AY12: =SUM(AV12:AX12) -> 214 | BA12: 1760 | BC12: =SUM(AZ12:BB12) -> 1760 | BF12: 350 | BG12: =SUM(BD12:BF12) -> 350 | BH12: =AU12+AY12+BC12+BG12 -> 2324 | BI12: =BH12/AQ12 -> 4.648 | BJ12: =(AP12+AQ12)-BH12 -> -1788 | BK12: =B12-T12-AN12-BH12 -> -1538 | BO12: =SUM(BL12:BN12) -> 0 | BQ12: 550 | BS12: =SUM(BP12:BR12) -> 550 | BW12: =SUM(BT12:BV12) -> 0 | BX12: 450 | CA12: =SUM(BX12:BZ12) -> 450 | CB12: =BO12+BS12+BW12+CA12 -> 1000 | CC12: =CB12/BK12 -> -0.65019506 | CD12: =BK12-CB12 -> -2538 | CE12: Legal
A13: Office & Computer Supplies | B13: 3600 | C13: ='budget anual'!C22+'budget anual'!C23 -> 900 | G13: =SUM(D13:F13) -> 0 | H13: =218.66+169.32+200+0.8+83.88+277.82 -> 950.48 | I13: 11.7 | J13: 211.05 | K13: =SUM(H13:J13) -> 1173.23 | L13: 72.16 | M13: 12.84 | O13: =SUM(L13:N13) -> 85 | P13: 29.62 | Q13: 53.61 | S13: =SUM(P13:R13) -> 83.23 | T13: =G13+K13+O13+S13 -> 1341.46 | U13: =T13/C13 -> 1.4905111 | V13: =C13-T13 -> -441.46 | W13: ='budget anual'!D22+'budget anual'!D23 -> 900 | X13: 199.02 | Y13: 105.93 | Z13: 88.54 | AA13: =SUM(X13:Z13) -> 393.49 | AB13: 133.72 | AC13: 125.71 | AD13: 116.14 | AE13: =SUM(AB13:AD13) -> 375.57 | AF13: 84.6 | AG13: 168.02 | AH13: 181.72 | AI13: =SUM(AF13:AH13) -> 434.34 | AJ13: 151.02 | AK13: 20.38 | AL13: 118.33 | AM13: =SUM(AJ13:AL13) -> 289.73 | AN13: =AA13+AE13+AI13+AM13 -> 1493.13 | AO13: =AN13/W13 -> 1.6590333 | AP13: =(V13+W13)-AN13 -> -1034.59 | AQ13: ='budget anual'!E22+'budget anual'!E23 -> 900 | AT13: 48.77 | AU13: =SUM(AR13:AT13) -> 48.77 | AV13: 196.81 | AW13: 217.06 | AX13: 283.4 | AY13: =SUM(AV13:AX13) -> 697.27 | AZ13: 315.98 | BA13: 176.23 | BB13: 301.41 | BC13: =SUM(AZ13:BB13) -> 793.62 | BD13: 178.2 | BE13: 191.31 | BG13: =SUM(BD13:BF13) -> 369.51 | BH13: =AU13+AY13+BC13+BG13 -> 1909.17 | BI13: =BH13/AQ13 -> 2.1213 | BJ13: =(AP13+AQ13)-BH13 -> -2043.76 | BK13: =B13-T13-AN13-BH13 -> -1143.76 | BL13: 279.73 | BM13: 307.5 | BN13: 212.28 | BO13: =SUM(BL13:BN13) -> 799.51 | BP13: 216.79 | BQ13: 262.09 | BR13: 117.34 | BS13: =SUM(BP13:BR13) -> 596.22 | BT13: 354.06 | BU13: 535.03 | BV13: 207.94 | BW13: =SUM(BT13:BV13) -> 1097.03 | BX13: 370.5 | BY13: 4.28 | BZ13: 87.44 | CA13: =SUM(BX13:BZ13) -> 462.22 | CB13: =BO13+BS13+BW13+CA13 -> 2954.98 | CC13: =CB13/BK13 -> -2.5835665 | CD13: =BK13-CB13 -> -4098.74 | CE13: Office & Computer Supplies
A14: Rent & Utilities | B14: 62400 | C14: ='budget anual'!C25 -> 15600 | G14: =SUM(D14:F14) -> 0 | H14: 3600 | I14: 1200 | J14: 11000 | K14: =SUM(H14:J14) -> 15800 | O14: =SUM(L14:N14) -> 0 | S14: =SUM(P14:R14) -> 0 | T14: =G14+K14+O14+S14 -> 15800 | U14: =T14/C14 -> 1.0128205 | V14: =C14-T14 -> -200 | W14: ='budget anual'!D25 -> 15600 | Y14: 1400 | Z14: 1400 | AA14: =SUM(X14:Z14) -> 2800 | AB14: 1400 | AC14: 1400 | AD14: 1400 | AE14: =SUM(AB14:AD14) -> 4200 | AF14: 1400 | AG14: 1400 | AH14: 1400 | AI14: =SUM(AF14:AH14) -> 4200 | AJ14: 1400 | AK14: 1400 | AL14: 1400 | AM14: =SUM(AJ14:AL14) -> 4200 | AN14: =AA14+AE14+AI14+AM14 -> 15400 | AO14: =AN14/W14 -> 0.98717949 | AP14: =(V14+W14)-AN14 -> 0 | AQ14: ='budget anual'!E25 -> 15600 | AR14: 1400 | AS14: 1400 | AT14: 1400 | AU14: =SUM(AR14:AT14) -> 4200 | AV14: =1400+2343 -> 3743 | AW14: =49.21+1400 -> 1449.21 | AX14: 1400 | AY14: =SUM(AV14:AX14) -> 6592.21 | AZ14: 1400 | BA14: 1400 | BB14: 1400 | BC14: =SUM(AZ14:BB14) -> 4200 | BD14: 1400 | BE14: 1400 | BF14: 1400 | BG14: =SUM(BD14:BF14) -> 4200 | BH14: =AU14+AY14+BC14+BG14 -> 19192.21 | BI14: =BH14/AQ14 -> 1.2302699 | BJ14: =(AP14+AQ14)-BH14 -> -3592.21 | BK14: =B14-T14-AN14-BH14 -> 12007.79 | BL14: 1400 | BM14: 1400 | BN14: 1400 | BO14: =SUM(BL14:BN14) -> 4200 | BP14: 1400 | BQ14: 1400 | BR14: 1400 | BS14: =SUM(BP14:BR14) -> 4200 | BT14: 1400 | BU14: 1400 | BV14: 1400 | BW14: =SUM(BT14:BV14) -> 4200 | BX14: 1400 | BY14: 1400 | BZ14: 1400 | CA14: =SUM(BX14:BZ14) -> 4200 | CB14: =BO14+BS14+BW14+CA14 -> 16800 | CC14: =CB14/BK14 -> 1.3990918 | CD14: =BK14-CB14 -> -4792.21 | CE14: Rent & Utilities
B15: =SUM(B4:B14) -> 1056146.8 | C15: =SUM(C4:C14) -> #REF! | D15: =SUM(D4:D14) -> 0 | E15: =SUM(E4:E14) -> 10983.64 | F15: =SUM(F4:F14) -> 14515.82 | G15: =SUM(G4:G14) -> 25499.46 | H15: =SUM(H4:H14) -> 32171.93 | I15: =SUM(I4:I14) -> 21537.9 | ... T15: =SUM(T4:T14) -> 230216.46 | U15: =T15/C15 -> #REF! | V15: =SUM(V4:V14) -> #REF! | W15: =SUM(W4:W14) -> #REF! | X15: =SUM(X4:X14) -> 20531.94 | Y15: =SUM(Y4:Y14) -> 18787.12 | Z15: =SUM(Z4:Z14) -> 18902.13 | AA15: =SUM(AA4:AA14) -> 58221.19 | AB15: =SUM(AB4:AB14) -> 24392.12 | AC15: =SUM(AC4:AC14) -> 18989.99 | ... AN15: =SUM(AN4:AN14) -> 251458.9 | AO15: =AN15/W15 -> #REF! | AP15: =SUM(AP4:AP14) -> #REF! | AQ15: =SUM(AQ4:AQ14) -> #REF! | AR15: =SUM(AR4:AR14) -> 19298.78 | AS15: =SUM(AS4:AS14) -> 27732.67 | AT15: =SUM(AT4:AT14) -> 11310.73 | AU15: =SUM(AU4:AU14) -> 58342.18 | AV15: =SUM(AV4:AV14) -> 16863.5 | AW15: =SUM(AW4:AW14) -> 12508.1 | ... BH15: =SUM(BH4:BH14) -> 186667.89 | BI15: =BH15/AQ15 -> #REF! | BJ15: =SUM(BJ4:BJ14) -> #REF! | BK15: =SUM(BK4:BK14) -> 387803.55 | BL15: =SUM(BL4:BL14) -> 15517 | BM15: =SUM(BM4:BM14) -> 14588.06 | BN15: =SUM(BN4:BN14) -> 18141.82 | BO15: =SUM(BO4:BO14) -> 48246.88 | BP15: =SUM(BP4:BP14) -> 17909.84 | BQ15: =SUM(BQ4:BQ14) -> 15427.09 | ... CB15: =SUM(CB4:CB14) -> 218429.97 | CC15: =CB15/BK15 -> 0.56324902 | CD15: =SUM(CD4:CD14) -> 169373.58
A16: Output 1: Education | CE16: Output 1: Education
A17: Translation to Indigenous Languages | B17: 0 | C17: 0 | G17: =SUM(D17:F17) -> 0 | K17: =SUM(H17:J17) -> 0 | O17: =SUM(L17:N17) -> 0 | S17: =SUM(P17:R17) -> 0 | T17: =G17+K17+O17+S17 -> 0 | U17: =T17/C17 -> #DIV/0! | V17: =C17-T17 -> 0 | W17: 0 | AA17: =SUM(X17:Z17) -> 0 | AE17: =SUM(AB17:AD17) -> 0 | AI17: =SUM(AF17:AH17) -> 0 | AM17: =SUM(AJ17:AL17) -> 0 | AN17: =AA17+AE17+AI17+AM17 -> 0 | AP17: =(V17+W17)-AN17 -> 0 | AQ17: 0 | AU17: =SUM(AR17:AT17) -> 0 | AY17: =SUM(AV17:AX17) -> 0 | BC17: =SUM(AZ17:BB17) -> 0 | BG17: =SUM(BD17:BF17) -> 0 | BH17: =AU17+AY17+BC17+BG17 -> 0 | BJ17: =(AP17+AQ17)-BH17 -> 0 | BK17: =B17-T17-AN17-BH17 -> 0 | BO17: =SUM(BL17:BN17) -> 0 | BS17: =SUM(BP17:BR17) -> 0 | BW17: =SUM(BT17:BV17) -> 0 | CA17: =SUM(BX17:BZ17) -> 0 | CB17: =BO17+BS17+BW17+CA17 -> 0 | CD17: =BK17-CB17 -> 0 | CE17: Translation to Indigenous Languages
A18: Materials, Design & Printing | B18: 57972.12 | C18: ='budget anual'!C48 -> #REF! | F18: 137.3 | G18: =SUM(D18:F18) -> 137.3 | K18: =SUM(H18:J18) -> 0 | L18: 214.72 | O18: =SUM(L18:N18) -> 214.72 | Q18: 20.33 | R18: 1000 | S18: =SUM(P18:R18) -> 1020.33 | T18: =G18+K18+O18+S18 -> 1372.35 | U18: =T18/C18 -> #REF! | V18: =C18-T18 -> #REF! | W18: ='budget anual'!D48 -> #REF! | Z18: 527.3 | AA18: =SUM(X18:Z18) -> 527.3 | AD18: 11208.25 | AE18: =SUM(AB18:AD18) -> 11208.25 | AF18: 14692.25 | AG18: 4.99 | AI18: =SUM(AF18:AH18) -> 14697.24 | AJ18: 400 | AL18: 10539.5 | AM18: =SUM(AJ18:AL18) -> 10939.5 | AN18: =AA18+AE18+AI18+AM18 -> 37372.29 | AP18: =(V18+W18)-AN18 -> #REF! | AQ18: ='budget anual'!E48 -> 19226.86 | AT18: 10539.5 | AU18: =SUM(AR18:AT18) -> 10539.5 | AW18: 489.53 | AY18: =SUM(AV18:AX18) -> 489.53 | AZ18: 3849.33 | BA18: 4338.85 | BB18: 262.15 | BC18: =SUM(AZ18:BB18) -> 8450.33 | BG18: =SUM(BD18:BF18) -> 0 | BH18: =AU18+AY18+BC18+BG18 -> 19479.36 | BJ18: =(AP18+AQ18)-BH18 -> #REF! | BK18: =B18-T18-AN18-BH18 -> -251.88 | BO18: =SUM(BL18:BN18) -> 0 | BS18: =SUM(BP18:BR18) -> 0 | BW18: =SUM(BT18:BV18) -> 0 | CA18: =SUM(BX18:BZ18) -> 0 | CB18: =BO18+BS18+BW18+CA18 -> 0 | CD18: =BK18-CB18 -> -251.88 | CE18: Materials, Design & Printing
A19: 1.6 Local Workshops venue and logistics | B19: 64000 | C19: ='budget anual'!C52 -> #REF! | G19: =SUM(D19:F19) -> 0 | K19: =SUM(H19:J19) -> 0 | N19: 1500 | O19: =SUM(L19:N19) -> 1500 | P19: 10472.89 | Q19: -287.15 | R19: 6365 | S19: =SUM(P19:R19) -> 16550.74 | T19: =G19+K19+O19+S19 -> 18050.74 | U19: =T19/C19 -> #REF! | V19: =C19-T19 -> #REF! | W19: ='budget anual'!D52 -> #REF! | X19: 12085.61 | AA19: =SUM(X19:Z19) -> 12085.61 | AE19: =SUM(AB19:AD19) -> 0 | AH19: 15896.29 | AI19: =SUM(AF19:AH19) -> 15896.29 | AJ19: -277.02 | AM19: =SUM(AJ19:AL19) -> -277.02 | AN19: =AA19+AE19+AI19+AM19 -> 27704.88 | AO19: =AN19/W19 -> #REF! | AP19: =(V19+W19)-AN19 -> #REF! | AQ19: ='budget anual'!E52 -> 18244.38 | AR19: 24098.08 | AS19: 5688.42 | AT19: 630.46 | AU19: =SUM(AR19:AT19) -> 30416.96 | AY19: =SUM(AV19:AX19) -> 0 | AZ19: 130 | BB19: 147.17 | BC19: =SUM(AZ19:BB19) -> 277.17 | BD19: 1584.65 | BG19: =SUM(BD19:BF19) -> 1584.65 | BH19: =AU19+AY19+BC19+BG19 -> 32278.78 | BJ19: =(AP19+AQ19)-BH19 -> #REF! | BK19: =B19-T19-AN19-BH19 -> -14034.4 | BL19: -482.73 | BO19: =SUM(BL19:BN19) -> -482.73 | BQ19: 1000 | BR19: 2491.98 | BS19: =SUM(BP19:BR19) -> 3491.98 | BW19: =SUM(BT19:BV19) -> 0 | CA19: =SUM(BX19:BZ19) -> 0 | CB19: =BO19+BS19+BW19+CA19 -> 3009.25 | CD19: =BK19-CB19 -> -17043.65 | CE19: 1.6 Local Workshops venue and logistics
A20: 1.7 Short Term Education Consultant Support | B20: 18200 | C20: ='budget anual'!C53 -> 0 | V20: 0 | W20: ='budget anual'!D53 -> 15500 | AF20: 3100 | AG20: 3875 | AI20: =SUM(AF20:AH20) -> 6975 | AJ20: 8525 | AM20: =SUM(AJ20:AL20) -> 8525 | AN20: =AA20+AE20+AI20+AM20 -> 15500 | AP20: =(V20+W20)-AN20 -> 0 | AQ20: ='budget anual'!E53 -> 2700 | AZ20: 600 | BA20: 800 | BB20: 900 | BC20: =SUM(AZ20:BB20) -> 2300 | BD20: 400 | BG20: =SUM(BD20:BF20) -> 400 | BH20: =AU20+AY20+BC20+BG20 -> 2700 | BJ20: =(AP20+AQ20)-BH20 -> 0 | BK20: =B20-T20-AN20-BH20 -> 0 | BO20: =SUM(BL20:BN20) -> 0 | BS20: =SUM(BP20:BR20) -> 0 | BW20: =SUM(BT20:BV20) -> 0 | CA20: =SUM(BX20:BZ20) -> 0 | CB20: =BO20+BS20+BW20+CA20 -> 0 | CD20: =BK20-CB20 -> 0 | CE20: 1.7 Short Term Education Consultant Support
A21: Implementation of EpC Activities: | AM21: =SUM(AJ21:AL21) -> 0 | AN21: =AA21+AE21+AI21+AM21 -> 0 | BG21: =SUM(BD21:BF21) -> 0 | BH21: =AU21+AY21+BC21+BG21 -> 0 | BJ21: =(AP21+AQ21)-BH21 -> 0 | BK21: =B21-T21-AN21-BH21 -> 0 | BO21: =SUM(BL21:BN21) -> 0 | BS21: =SUM(BP21:BR21) -> 0 | BW21: =SUM(BT21:BV21) -> 0 | CA21: =SUM(BX21:BZ21) -> 0 | CB21: =BO21+BS21+BW21+CA21 -> 0 | CD21: =BK21-CB21 -> 0 | CE21: Implementation of EpC Activities:
A22: Fey Alegria Direct Activities | B22: 210250 | C22: ='budget anual'!C56 -> #REF! | G22: =SUM(D22:F22) -> 0 | K22: =SUM(H22:J22) -> 0 | O22: =SUM(L22:N22) -> 0 | Q22: 97853.85 | S22: =SUM(P22:R22) -> 97853.85 | T22: =G22+K22+O22+S22 -> 97853.85 | U22: =T22/C22 -> #REF! | V22: =C22-T22 -> #REF! | W22: ='budget anual'!D56 -> #REF! | AA22: =SUM(X22:Z22) -> 0 | AE22: =SUM(AB22:AD22) -> 0 | AI22: =SUM(AF22:AH22) -> 0 | AK22: 33094.07 | AL22: 1643.02 | AM22: =SUM(AJ22:AL22) -> 34737.09 | AN22: =AA22+AE22+AI22+AM22 -> 34737.09 | AO22: =AN22/W22 -> #REF! | AP22: =(V22+W22)-AN22 -> #REF! | AQ22: ='budget anual'!E56 -> #REF! | AR22: 1995.56 | AS22: 1273.02 | AT22: 2097.46 | AU22: =SUM(AR22:AT22) -> 5366.04 | AV22: 882.67 | AW22: 932.67 | AX22: 1024.33 | AY22: =SUM(AV22:AX22) -> 2839.67 | AZ22: 951 | BA22: 24080.55 | BB22: 1176 | BC22: =SUM(AZ22:BB22) -> 26207.55 | BD22: 1223.73 | BE22: 1244.18 | BF22: =1326+15000 -> 16326 | BG22: =SUM(BD22:BF22) -> 18793.91 | BH22: =AU22+AY22+BC22+BG22 -> 53207.17 | BI22: =BH22/AQ22 -> #REF! | BJ22: =(AP22+AQ22)-BH22 -> #REF! | BK22: =B22-T22-AN22-BH22 -> 24451.89 | BL22: 1322.71 | BM22: =25300+1275.98 -> 26575.98 | BN22: 1286 | BO22: =SUM(BL22:BN22) -> 29184.69 | BP22: 1321 | BQ22: 6334.46 | BR22: =1371+16694.76 -> 18065.76 | BS22: =SUM(BP22:BR22) -> 25721.22 | BT22: 1371 | BU22: 1371 | BV22: 1372.57 | BW22: =SUM(BT22:BV22) -> 4114.57 | BX22: =1321+4400+1315.03 -> 7036.03 | BY22: 1583.52 | BZ22: 2314.85 | CA22: =SUM(BX22:BZ22) -> 10934.4 | CB22: =BO22+BS22+BW22+CA22 -> 69954.88 | CC22: =CB22/BK22 -> 2.8609191 | CD22: =BK22-CB22 -> -45502.99 | CE22: Fey Alegria Direct Activities
A23: Subcontract: APRODISO (Darién y Comarca Emberá) | B23: 21282.5 | C23: ='budget anual'!C57 -> 0 | G23: =SUM(D23:F23) -> 0 | K23: =SUM(H23:J23) -> 0 | O23: =SUM(L23:N23) -> 0 | S23: =SUM(P23:R23) -> 0 | T23: =G23+K23+O23+S23 -> 0 | U23: 0 | V23: =C23-T23 -> 0 | W23: ='budget anual'!D57 -> 21282.5 | X23: 18360 | AA23: =SUM(X23:Z23) -> 18360 | AE23: =SUM(AB23:AD23) -> 0 | AI23: =SUM(AF23:AH23) -> 0 | AK23: 2940 | AL23: -17.5 | AM23: =SUM(AJ23:AL23) -> 2922.5 | AN23: =AA23+AE23+AI23+AM23 -> 21282.5 | AO23: 0 | AP23: =(V23+W23)-AN23 -> 0 | AQ23: ='budget anual'!E57 -> 0 | AU23: =SUM(AR23:AT23) -> 0 | AY23: =SUM(AV23:AX23) -> 0 | BC23: =SUM(AZ23:BB23) -> 0 | BG23: =SUM(BD23:BF23) -> 0 | BH23: =AU23+AY23+BC23+BG23 -> 0 | BI23: 0 | BJ23: =(AP23+AQ23)-BH23 -> 0 | BK23: =B23-T23-AN23-BH23 -> 0 | BO23: =SUM(BL23:BN23) -> 0 | BS23: =SUM(BP23:BR23) -> 0 | BW23: =SUM(BT23:BV23) -> 0 | CA23: =SUM(BX23:BZ23) -> 0 | CB23: =BO23+BS23+BW23+CA23 -> 0 | CC23: 0 | CD23: =BK23-CB23 -> 0 | CE23: Subcontract: APRODISO (Darién y Comarca Emberá)
A24: Subcontract: APROTENG (Bocas del Toro) | B24: 84000 | C24: ='budget anual'!C58 -> #REF! | G24: =SUM(D24:F24) -> 0 | K24: =SUM(H24:J24) -> 0 | O24: =SUM(L24:N24) -> 0 | S24: =SUM(P24:R24) -> 0 | T24: =G24+K24+O24+S24 -> 0 | U24: 0 | V24: =C24-T24 -> #REF! | W24: ='budget anual'!D58 -> #REF! | X24: 13917 | AA24: =SUM(X24:Z24) -> 13917 | AE24: =SUM(AB24:AD24) -> 0 | AH24: 10000 | AI24: =SUM(AF24:AH24) -> 10000 | AM24: =SUM(AJ24:AL24) -> 0 | AN24: =AA24+AE24+AI24+AM24 -> 23917 | AO24: 0 | AP24: =(V24+W24)-AN24 -> #REF! | AQ24: ='budget anual'!E58 -> #REF! | AT24: 12000 | AU24: =SUM(AR24:AT24) -> 12000 | AX24: 7500 | AY24: =SUM(AV24:AX24) -> 7500 | BA24: 12000 | BC24: =SUM(AZ24:BB24) -> 12000 | BD24: 8500 | BF24: 12550 | BG24: =SUM(BD24:BF24) -> 21050 | BH24: =AU24+AY24+BC24+BG24 -> 52550 | BI24: 0 | BJ24: =(AP24+AQ24)-BH24 -> #REF! | BK24: =B24-T24-AN24-BH24 -> 7533 | BO24: =SUM(BL24:BN24) -> 0 | BP24: 1350 | BQ24: =5170.5-300 -> 4870.5 | BR24: 2488.17 | BS24: =SUM(BP24:BR24) -> 8708.67 | BT24: 6138.38 | BU24: 5071.88 | BV24: 3418.9 | BW24: =SUM(BT24:BV24) -> 14629.16 | BX24: 2480.46 | CA24: =SUM(BX24:BZ24) -> 2480.46 | CB24: =BO24+BS24+BW24+CA24 -> 25818.29 | CC24: 0 | CD24: =BK24-CB24 -> -18285.29 | CE24: Subcontract: APROTENG (Bocas del Toro)
A25: EducaFuturo - Darién y Comarca Emberá | B25: 99200 | AP25: =(V25+W25)-AN25 -> 0 | AQ25: ='budget anual'!E62 -> 28110.13 | AT25: =2699.54-86.89+1000 -> 3612.65 | AU25: =SUM(AR25:AT25) -> 3612.65 | AV25: =1461.47+2252.11 -> 3713.58 | AW25: =1972.88+4894.71 -> 6867.59 | AX25: =2319.38+1400.89 -> 3720.27 | AY25: =SUM(AV25:AX25) -> 14301.44 | AZ25: =3412.5+1959.02 -> 5371.52 | BA25: =2754.17+2545.89 -> 5300.06 | BB25: =3866.67+1970.04 -> 5836.71 | BC25: =SUM(AZ25:BB25) -> 16508.29 | BD25: =3077.08+1169.8 -> 4246.88 | BE25: =3650+2318.7 -> 5968.7 | BF25: =2983.33+2769.45 -> 5752.78 | BG25: =SUM(BD25:BF25) -> 15968.36 | BH25: =AU25+AY25+BC25+BG25 -> 50390.74 | BJ25: =(AP25+AQ25)-BH25 -> -22280.61 | BK25: =B25-T25-AN25-BH25 -> 48809.26 | BL25: 2415.7 | BM25: 2475.2 | BN25: 2314.45 | BO25: =SUM(BL25:BN25) -> 7205.35 | BP25: =1570.56+3626.69 -> 5197.25 | BQ25: =2941.67+2365.7 -> 5307.37 | BR25: 4813.63 | BS25: =SUM(BP25:BR25) -> 15318.25 | BT25: 3953.03 | BU25: =4936+500 -> 5436 | BV25: 5465.71 | BW25: =SUM(BT25:BV25) -> 14854.74 | BX25: 3704.06 | BY25: 2539.11 | BZ25: -0.01 | CA25: =SUM(BX25:BZ25) -> 6243.16 | CB25: =BO25+BS25+BW25+CA25 -> 43621.5 | CD25: =BK25-CB25 -> 5187.76 | CE25: EducaFuturo - Darién y Comarca Emberá
B26: =SUM(B16:B25) -> 554904.62 | C26: =SUM(C16:C25) -> #REF! | D26: =SUM(D16:D25) -> 0 | E26: =SUM(E16:E25) -> 0 | F26: =SUM(F16:F25) -> 137.3 | G26: =SUM(G16:G25) -> 137.3 | H26: =SUM(H16:H25) -> 0 | I26: =SUM(I16:I25) -> 0 | ... T26: =SUM(T16:T25) -> 117276.94 | U26: =T26/C26 -> #REF! | V26: =SUM(V16:V25) -> #REF! | W26: =SUM(W16:W25) -> #REF! | X26: =SUM(X16:X25) -> 44362.61 | Y26: =SUM(Y16:Y25) -> 0 | Z26: =SUM(Z16:Z25) -> 527.3 | AA26: =SUM(AA16:AA25) -> 44889.91 | AB26: =SUM(AB16:AB25) -> 0 | AC26: =SUM(AC16:AC25) -> 0 | ... AN26: =SUM(AN16:AN25) -> 160513.76 | AO26: =AN26/W26 -> #REF! | AP26: =SUM(AP16:AP25) -> #REF! | AQ26: =SUM(AQ16:AQ25) -> #REF! | AR26: =SUM(AR16:AR25) -> 26093.64 | AS26: =SUM(AS16:AS25) -> 6961.44 | AT26: =SUM(AT16:AT25) -> 28880.07 | AU26: =SUM(AU16:AU25) -> 61935.15 | AV26: =SUM(AV16:AV25) -> 4596.25 | AW26: =SUM(AW16:AW25) -> 8289.79 | ... BH26: =SUM(BH16:BH25) -> 210606.05 | BI26: =BH26/AQ26 -> #REF! | BJ26: =SUM(BJ16:BJ25) -> #REF! | BK26: =SUM(BK16:BK25) -> 66507.87 | BL26: =SUM(BL16:BL25) -> 3255.68 | BM26: =SUM(BM16:BM25) -> 29051.18 | BN26: =SUM(BN16:BN25) -> 3600.45 | BO26: =SUM(BO16:BO25) -> 35907.31 | BP26: =SUM(BP16:BP25) -> 7868.25 | BQ26: =SUM(BQ16:BQ25) -> 17512.33 | ... CB26: =SUM(CB16:CB25) -> 142403.92 | CC26: =CB26/BK26 -> 2.1411589 | CD26: =SUM(CD16:CD25) -> -75896.05
A27: Output 2: Livelihoods | CE27: Output 2: Livelihoods
A28: 2.1 Value Chain Analysis | B28: 4000 | C28: ='budget anual'!C72 -> 0 | G28: =SUM(D28:F28) -> 0 | K28: =SUM(H28:J28) -> 0 | O28: =SUM(L28:N28) -> 0 | S28: =SUM(P28:R28) -> 0 | T28: =G28+K28+O28+S28 -> 0 | U28: =T28/C28 -> #DIV/0! | V28: =C28-T28 -> 0 | W28: ='budget anual'!D72 -> 0 | AA28: =SUM(X28:Z28) -> 0 | AE28: =SUM(AB28:AD28) -> 0 | AI28: =SUM(AF28:AH28) -> 0 | AM28: =SUM(AJ28:AL28) -> 0 | AN28: =AA28+AE28+AI28+AM28 -> 0 | AP28: =(V28+W28)-AN28 -> 0 | AQ28: ='budget anual'!E72 -> 0 | AU28: =SUM(AR28:AT28) -> 0 | AY28: =SUM(AV28:AX28) -> 0 | BC28: =SUM(AZ28:BB28) -> 0 | BG28: =SUM(BD28:BF28) -> 0 | BH28: =AU28+AY28+BC28+BG28 -> 0 | BJ28: =(AP28+AQ28)-BH28 -> 0 | BK28: =B28-T28-AN28-BH28 -> 4000 | BO28: =SUM(BL28:BN28) -> 0 | BQ28: 500 | BR28: 541.06 | BS28: =SUM(BP28:BR28) -> 1041.06 | BT28: 348.11 | BW28: =SUM(BT28:BV28) -> 348.11 | BX28: -240.25 | CA28: =SUM(BX28:BZ28) -> -240.25 | CB28: =BO28+BS28+BW28+CA28 -> 1148.92 | CD28: =BK28-CB28 -> 2851.08 | CE28: 2.1 Value Chain Analysis
A29: 2.2 Linking Households to Livelihood Programs | B29: 3525 | C29: ='budget anual'!C73 -> #REF! | G29: =SUM(D29:F29) -> 0 | K29: =SUM(H29:J29) -> 0 | O29: =SUM(L29:N29) -> 0 | S29: =SUM(P29:R29) -> 0 | T29: =G29+K29+O29+S29 -> 0 | U29: =T29/C29 -> #REF! | V29: =C29-T29 -> #REF! | W29: ='budget anual'!D73 -> #REF! | AA29: =SUM(X29:Z29) -> 0 | AE29: =SUM(AB29:AD29) -> 0 | AI29: =SUM(AF29:AH29) -> 0 | AM29: =SUM(AJ29:AL29) -> 0 | AN29: =AA29+AE29+AI29+AM29 -> 0 | AO29: =AN29/W29 -> #REF! | AP29: =(V29+W29)-AN29 -> #REF! | AQ29: ='budget anual'!E73 -> #REF! | AU29: =SUM(AR29:AT29) -> 0 | AX29: 360 | AY29: =SUM(AV29:AX29) -> 360 | BA29: 213.29 | BC29: =SUM(AZ29:BB29) -> 213.29 | BG29: =SUM(BD29:BF29) -> 0 | BH29: =AU29+AY29+BC29+BG29 -> 573.29 | BI29: =BH29/AQ29 -> #REF! | BJ29: =(AP29+AQ29)-BH29 -> #REF! | BK29: =B29-T29-AN29-BH29 -> 2951.71 | BL29: -108.5 | BO29: =SUM(BL29:BN29) -> -108.5 | BS29: =SUM(BP29:BR29) -> 0 | BW29: =SUM(BT29:BV29) -> 0 | CA29: =SUM(BX29:BZ29) -> 0 | CB29: =BO29+BS29+BW29+CA29 -> -108.5 | CC29: =CB29/BK29 -> -0.036758354 | CD29: =BK29-CB29 -> 3060.21 | CE29: 2.2 Linking Households to Livelihood Programs
A30: 2.3 Technical Assistance to Develop Links to Business Activities | B30: 7500 | C30: ='budget anual'!C74 -> #REF! | T30: =G30+K30+O30+S30 -> 0 | V30: =C30-T30 -> #REF! | W30: ='budget anual'!D74 -> #REF! | AN30: =AA30+AE30+AI30+AM30 -> 0 | AP30: =(V30+W30)-AN30 -> #REF! | AQ30: ='budget anual'!E74 -> #REF! | AS30: 500 | AT30: 1400 | AU30: =SUM(AR30:AT30) -> 1900 | AY30: =SUM(AV30:AX30) -> 0 | BC30: =SUM(AZ30:BB30) -> 0 | BD30: 1000 | BF30: 1650 | BG30: =SUM(BD30:BF30) -> 2650 | BH30: =AU30+AY30+BC30+BG30 -> 4550 | BI30: =BH30/AQ30 -> #REF! | BJ30: =(AP30+AQ30)-BH30 -> #REF! | BK30: =B30-T30-AN30-BH30 -> 2950 | BL30: 2226.28 | BM30: 30 | BO30: =SUM(BL30:BN30) -> 2256.28 | BS30: =SUM(BP30:BR30) -> 0 | BW30: =SUM(BT30:BV30) -> 0 | BX30: -1171.43 | CA30: =SUM(BX30:BZ30) -> -1171.43 | CB30: =BO30+BS30+BW30+CA30 -> 1084.85 | CC30: =CB30/BK30 -> 0.36774576 | CD30: =BK30-CB30 -> 1865.15 | CE30: 2.3 Technical Assistance to Develop Links to Business Activities
A31: Literacy fund | B31: 1000 | BK31: =B31-T31-AN31-BH31 -> 1000 | BU31: 124.68 | BV31: 106.78 | BW31: =SUM(BT31:BV31) -> 231.46 | BX31: 1500 | CA31: =SUM(BX31:BZ31) -> 1500 | CB31: =BO31+BS31+BW31+CA31 -> 1731.46 | CD31: =BK31-CB31 -> -731.46 | CE31: Literacy fund
A32: Subcontract: Fe y Alegría (Comarca Ngäbe y Colón) | B32: 35000 | C32: ='budget anual'!C79 -> 0 | T32: =G32+K32+O32+S32 -> 0 | V32: =C32-T32 -> 0 | W32: ='budget anual'!D79 -> 0 | AN32: =AA32+AE32+AI32+AM32 -> 0 | AP32: =(V32+W32)-AN32 -> 0 | AQ32: ='budget anual'!E79 -> 0 | AU32: =SUM(AR32:AT32) -> 0 | AY32: =SUM(AV32:AX32) -> 0 | BC32: =SUM(AZ32:BB32) -> 0 | BG32: =SUM(BD32:BF32) -> 0 | BH32: =AU32+AY32+BC32+BG32 -> 0 | BJ32: =(AP32+AQ32)-BH32 -> 0 | BK32: =B32-T32-AN32-BH32 -> 35000 | BO32: =SUM(BL32:BN32) -> 0 | BR32: 25000 | BS32: =SUM(BP32:BR32) -> 25000 | BW32: =SUM(BT32:BV32) -> 0 | CA32: =SUM(BX32:BZ32) -> 0 | CB32: =BO32+BS32+BW32+CA32 -> 25000 | CD32: =BK32-CB32 -> 10000 | CE32: Subcontract: Fe y Alegría (Comarca Ngäbe y Colón)
A33: Subcontract: APRODISO (Darién y Comarca Emberá) | B33: 0 | C33: ='budget anual'!C80 -> 0 | T33: =G33+K33+O33+S33 -> 0 | V33: =C33-T33 -> 0 | W33: ='budget anual'!D80 -> 0 | AN33: =AA33+AE33+AI33+AM33 -> 0 | AP33: =(V33+W33)-AN33 -> 0 | AQ33: ='budget anual'!E80 -> 0 | AU33: =SUM(AR33:AT33) -> 0 | AY33: =SUM(AV33:AX33) -> 0 | BC33: =SUM(AZ33:BB33) -> 0 | BG33: =SUM(BD33:BF33) -> 0 | BH33: =AU33+AY33+BC33+BG33 -> 0 | BJ33: =(AP33+AQ33)-BH33 -> 0 | BK33: =B33-T33-AN33-BH33 -> 0 | BO33: =SUM(BL33:BN33) -> 0 | BS33: =SUM(BP33:BR33) -> 0 | BW33: =SUM(BT33:BV33) -> 0 | CA33: =SUM(BX33:BZ33) -> 0 | CB33: =BO33+BS33+BW33+CA33 -> 0 | CD33: =BK33-CB33 -> 0 | CE33: Subcontract: APRODISO (Darién y Comarca Emberá)
A34: Subcontract: APROTENG (Bocas del Toro) | B34: 12050 | C34: ='budget anual'!C81 -> 0 | G34: =SUM(D34:F34) -> 0 | K34: =SUM(H34:J34) -> 0 | O34: =SUM(L34:N34) -> 0 | S34: =SUM(P34:R34) -> 0 | T34: =G34+K34+O34+S34 -> 0 | U34: =T34/C34 -> #DIV/0! | V34: =C34-T34 -> 0 | W34: ='budget anual'!D81 -> 0 | AA34: =SUM(X34:Z34) -> 0 | AE34: =SUM(AB34:AD34) -> 0 | AI34: =SUM(AF34:AH34) -> 0 | AM34: =SUM(AJ34:AL34) -> 0 | AN34: =AA34+AE34+AI34+AM34 -> 0 | AO34: =AN34/W34 -> #DIV/0! | AP34: =(V34+W34)-AN34 -> 0 | AQ34: ='budget anual'!E81 -> 1500 | AU34: =SUM(AR34:AT34) -> 0 | AY34: =SUM(AV34:AX34) -> 0 | BC34: =SUM(AZ34:BB34) -> 0 | BD34: 1500 | BG34: =SUM(BD34:BF34) -> 1500 | BH34: =AU34+AY34+BC34+BG34 -> 1500 | BI34: =BH34/AQ34 -> 1 | BJ34: =(AP34+AQ34)-BH34 -> 0 | BK34: =B34-T34-AN34-BH34 -> 10550 | BO34: =SUM(BL34:BN34) -> 0 | BR34: 853.25 | BS34: =SUM(BP34:BR34) -> 853.25 | BT34: 1033.95 | BU34: 1873.5 | BV34: =8168.4+283 -> 8451.4 | BW34: =SUM(BT34:BV34) -> 11358.85 | BX34: 1061 | BZ34: 80 | CA34: =SUM(BX34:BZ34) -> 1141 | CB34: =BO34+BS34+BW34+CA34 -> 13353.1 | CC34: =CB34/BK34 -> 1.2656967 | CD34: =BK34-CB34 -> -2803.1 | CE34: Subcontract: APROTENG (Bocas del Toro)
A35: D.2.5.G EducaFuturo Darién & Comarca Emberá | B35: 22050 | C35: 0 | W35: 0 | AQ35: ='budget anual'!E85 -> 40 | BC35: =SUM(AZ35:BB35) -> 0 | BE35: 40 | BG35: =SUM(BD35:BF35) -> 40 | BH35: =AU35+AY35+BC35+BG35 -> 40 | BJ35: =(AP35+AQ35)-BH35 -> 0 | BK35: =B35-T35-AN35-BH35 -> 22010 | BO35: =SUM(BL35:BN35) -> 0 | BS35: =SUM(BP35:BR35) -> 0 | BV35: 18098.62 | BW35: =SUM(BT35:BV35) -> 18098.62 | BX35: -207.31 | BY35: 924.75 | CA35: =SUM(BX35:BZ35) -> 717.44 | CB35: =BO35+BS35+BW35+CA35 -> 18816.06 | CD35: =BK35-CB35 -> 3193.94 | CE35: D.2.5.G EducaFuturo Darién & Comarca Emberá
B36: =SUM(B27:B35) -> 85125 | C36: =SUM(C27:C34) -> #REF! | D36: =SUM(D27:D34) -> 0 | E36: =SUM(E27:E34) -> 0 | F36: =SUM(F27:F34) -> 0 | G36: =SUM(G27:G34) -> 0 | H36: =SUM(H27:H34) -> 0 | I36: =SUM(I27:I34) -> 0 | J36: =SUM(J27:J34) -> 0 | ... T36: =SUM(T27:T34) -> 0 | U36: =T36/C36 -> #REF! | V36: =SUM(V27:V34) -> #REF! | W36: =SUM(W27:W34) -> #REF! | X36: =SUM(X27:X34) -> 0 | Y36: =SUM(Y27:Y34) -> 0 | Z36: =SUM(Z27:Z34) -> 0 | AA36: =SUM(AA27:AA34) -> 0 | AB36: =SUM(AB27:AB34) -> 0 | AC36: =SUM(AC27:AC34) -> 0 | ... AN36: =SUM(AN27:AN34) -> 0 | AO36: =AN36/W36 -> #REF! | AP36: =SUM(AP27:AP34) -> #REF! | AQ36: =SUM(AQ27:AQ35) -> #REF! | AR36: =SUM(AR27:AR34) -> 0 | AS36: =SUM(AS27:AS34) -> 500 | AT36: =SUM(AT27:AT34) -> 1400 | AU36: =SUM(AU27:AU34) -> 1900 | AV36: =SUM(AV27:AV34) -> 0 | AW36: =SUM(AW27:AW34) -> 0 | AX36: =SUM(AX27:AX34) -> 360 | AY36: =SUM(AY27:AY34) -> 360 | ... BA36: =SUM(BA27:BA34) -> 213.29 | BB36: =SUM(BB27:BB35) -> 0 | BC36: =SUM(BC27:BC35) -> 213.29 | BD36: =SUM(BD27:BD35) -> 2500 | BE36: =SUM(BE27:BE35) -> 40 | BF36: =SUM(BF27:BF35) -> 1650 | BG36: =SUM(BG27:BG35) -> 4190 | BH36: =SUM(BH27:BH35) -> 6663.29 | BI36: =BH36/AQ36 -> #REF! | BJ36: =SUM(BJ27:BJ35) -> #REF! | BK36: =SUM(BK27:BK35) -> 78461.71 | BL36: =SUM(BL27:BL35) -> 2117.78 | BM36: =SUM(BM27:BM35) -> 30 | BN36: =SUM(BN27:BN35) -> 0 | BO36: =SUM(BO27:BO35) -> 2147.78 | BP36: =SUM(BP27:BP35) -> 0 | BQ36: =SUM(BQ27:BQ35) -> 500 | ... CB36: =SUM(CB27:CB35) -> 61025.89 | CC36: =CB36/BK36 -> 0.77777925 | CD36: =SUM(CD27:CD35) -> 17435.82
A37: Output 3: Social Protection | CE37: Output 3: Social Protection
A38: Social Protecion Services in Targeted Communities | B38: 250 | C38: ='budget anual'!C88 -> 0 | G38: =SUM(D38:F38) -> 0 | K38: =SUM(H38:J38) -> 0 | O38: =SUM(L38:N38) -> 0 | S38: =SUM(P38:R38) -> 0 | T38: =G38+K38+O38+S38 -> 0 | U38: =T38/C38 -> #DIV/0! | V38: =C38-T38 -> 0 | W38: ='budget anual'!D88 -> 0 | AA38: =SUM(X38:Z38) -> 0 | AE38: =SUM(AB38:AD38) -> 0 | AI38: =SUM(AF38:AH38) -> 0 | AM38: =SUM(AJ38:AL38) -> 0 | AN38: =AA38+AE38+AI38+AM38 -> 0 | AO38: =AN38/W38 -> #DIV/0! | AP38: =(V38+W38)-AN38 -> 0 | AQ38: ='budget anual'!E88 -> 0 | AU38: =SUM(AR38:AT38) -> 0 | AY38: =SUM(AV38:AX38) -> 0 | BC38: =SUM(AZ38:BB38) -> 0 | BG38: =SUM(BD38:BF38) -> 0 | BH38: =AU38+AY38+BC38+BG38 -> 0 | BI38: =BH38/AQ38 -> #DIV/0! | BJ38: =(AP38+AQ38)-BH38 -> 0 | BK38: =B38-T38-AN38-BH38 -> 250 | BO38: =SUM(BL38:BN38) -> 0 | BS38: =SUM(BP38:BR38) -> 0 | BW38: =SUM(BT38:BV38) -> 0 | CA38: =SUM(BX38:BZ38) -> 0 | CB38: =BO38+BS38+BW38+CA38 -> 0 | CC38: =CB38/BK38 -> 0 | CD38: =BK38-CB38 -> 250 | CE38: Social Protecion Services in Targeted Communities
A39: Subcontract: Fe y Alegría (Comarca Ngäbe y Colón) | B39: 4687.5 | C39: ='budget anual'!C89 -> 0 | T39: =G39+K39+O39+S39 -> 0 | V39: =C39-T39 -> 0 | W39: ='budget anual'!D89 -> 0 | AN39: =AA39+AE39+AI39+AM39 -> 0 | AP39: =(V39+W39)-AN39 -> 0 | AQ39: ='budget anual'!E89 -> 0 | BG39: =SUM(BD39:BF39) -> 0 | BH39: =AU39+AY39+BC39+BG39 -> 0 | BJ39: =(AP39+AQ39)-BH39 -> 0 | BK39: =B39-T39-AN39-BH39 -> 4687.5 | BO39: =SUM(BL39:BN39) -> 0 | BR39: 4687.5 | BS39: =SUM(BP39:BR39) -> 4687.5 | BW39: =SUM(BT39:BV39) -> 0 | CA39: =SUM(BX39:BZ39) -> 0 | CB39: =BO39+BS39+BW39+CA39 -> 4687.5 | CD39: =BK39-CB39 -> 0 | CE39: Subcontract: Fe y Alegría (Comarca Ngäbe y Colón)
A40: Subcontract: APRODISO (Darién y Comarca Emberá) | B40: 0 | C40: ='budget anual'!C90 -> 0 | T40: =G40+K40+O40+S40 -> 0 | V40: =C40-T40 -> 0 | W40: ='budget anual'!D90 -> 0 | AN40: =AA40+AE40+AI40+AM40 -> 0 | AP40: =(V40+W40)-AN40 -> 0 | AQ40: ='budget anual'!E90 -> 0 | BG40: =SUM(BD40:BF40) -> 0 | BH40: =AU40+AY40+BC40+BG40 -> 0 | BJ40: =(AP40+AQ40)-BH40 -> 0 | BK40: =B40-T40-AN40-BH40 -> 0 | BO40: =SUM(BL40:BN40) -> 0 | BS40: =SUM(BP40:BR40) -> 0 | BW40: =SUM(BT40:BV40) -> 0 | CA40: =SUM(BX40:BZ40) -> 0 | CB40: =BO40+BS40+BW40+CA40 -> 0 | CD40: =BK40-CB40 -> 0 | CE40: Subcontract: APRODISO (Darién y Comarca Emberá)
...

Sheet budget anual
A1: PRESUPUESTO EDUCAFUTURO - APROBADO EN DICIEMBRE 2015
A4: BUDGET ITEM | B4: PANAMA | C4: AÑO 2013 | D4: AÑO 2014 | E4: AÑO 2015 | F4: AÑO 2016 | G4: TOTAL
A6: Sub-Total Direct Labor | B6: 657695.3 | C6: =#REF! -> #REF! | D6: =#REF! -> #REF! | E6: 131000 | F6: 190392.78 | G6: =SUM(C6:F6) -> #REF!
A7: Fringe Benefits - Ecuador
A8: Fringe Benefits - Panama | B8: 228456 | C8: =#REF! -> #REF! | D8: =#REF! -> #REF! | E8: =#REF! -> #REF! | F8: 104843.87 | G8: =SUM(C8:F8) -> #REF!
A9: Fringe Benefits - Home Office (32.40%)
A11: Total Direct Labor | B11: =SUM(B6:B10) -> 886151.3 | C11: =SUM(C6:C10) -> #REF! | D11: =SUM(D6:D10) -> #REF! | E11: =SUM(E6:E10) -> #REF! | F11: =SUM(F6:F10) -> 295236.65 | G11: =SUM(G6:G10) -> #REF!
A12: Housing Allowance
A13: Living Expenses - Education Specialist | G13: =SUM(C13:F13) -> 0
A15: Total Housing | B15: =SUM(B13:B14) -> 0 | C15: =SUM(C13:C14) -> 0 | D15: =SUM(D13:D14) -> 0 | E15: =SUM(E13:E14) -> 0 | F15: =SUM(F13:F14) -> 0 | G15: =SUM(G13:G14) -> 0
A16: Equipment
A17: Total Equipment | B17: 11655 | C17: 11655 | D17: 0 | E17: 0 | F17: 0 | G17: =SUM(C17:F17) -> 11655
A18: Office Expenses
A19: Courier fees/services | B19: 1400 | C19: 350 | D19: 350 | E19: 350 | F19: 350 | G19: =SUM(C19:F19) -> 1400
A20: Email/Internet | B20: 1680 | C20: 420 | D20: 420 | E20: 420 | F20: 420 | G20: =SUM(C20:F20) -> 1680
A21: Telephone (cellular and land line) | B21: 3120 | C21: 780 | D21: 780 | E21: 780 | F21: 780 | G21: =SUM(C21:F21) -> 3120
A22: Computer Supplies | B22: 1200 | C22: 300 | D22: 300 | E22: 300 | F22: 300 | G22: =SUM(C22:F22) -> 1200
A23: Office Supplies | B23: 2400 | C23: 600 | D23: 600 | E23: 600 | F23: 600 | G23: =SUM(C23:F23) -> 2400
A24: Office rent (Ecuador @ 25%) | B24: 0 | C24: 0 | D24: 0 | E24: 0 | F24: 0 | G24: =SUM(C24:F24) -> 0
A25: Office rent (Panama @ 100%) | B25: 62400 | C25: 15600 | D25: 15600 | E25: 15600 | F25: 15600 | G25: =SUM(C25:F25) -> 62400
A26: Office Utilities | B26: 4800 | C26: 1200 | D26: 1200 | E26: 1200 | F26: 1200 | G26: =SUM(C26:F26) -> 4800
A27: Vehicle Maintenance/repairs/spare parts/gasoline | B27: 6000 | C27: 1500 | D27: 1500 | E27: 1500 | F27: 1500 | G27: =SUM(C27:F27) -> 6000
A28: Banking and Cash Handling Fees | B28: =9600/2 -> 4800 | C28: 1200 | D28: 1200 | E28: 1200 | F28: 1200 | G28: =SUM(C28:F28) -> 4800
A29: Equipment and Office Repairs and Maintenance | B29: 1000 | C29: 250 | D29: 250 | E29: 250 | F29: 250 | G29: =SUM(C29:F29) -> 1000
A30: Audit Costs (A-133) | B30: 20000 | C30: 5000 | D30: 5000 | E30: 5000 | F30: 5000 | G30: =SUM(C30:F30) -> 20000
A31: Property and Liability Insurance | B31: 4000 | C31: 1000 | D31: 1000 | E31: 1000 | F31: 1000 | G31: =SUM(C31:F31) -> 4000
A32: Legal Fees | B32: 1000 | C32: 0 | D32: 250 | E32: 500 | F32: 250 | G32: =SUM(C32:F32) -> 1000
A34: Total Office Expenses | B34: =SUM(B19:B33) -> 113800 | C34: =SUM(C19:C33) -> 28200 | D34: =SUM(D19:D33) -> 28450 | E34: =SUM(E19:E33) -> 28700 | F34: =SUM(F19:F33) -> 28450 | G34: =SUM(G19:G33) -> 113800
A35: Output 1: Education
A36: 1.1 Entrena: Quantum Learning for Teachers | G36: =SUM(C36:F36) -> 0
A37: Airfare DR-Panama-Ecuador | G37: =SUM(C37:F37) -> 0
A38: Lodging and per diem Trainer | G38: =SUM(C38:F38) -> 0
