Workbook
Name Category: #N/A
Name Category: Comparasion!#REF!
Name Category: RMS!$G$9:$G$113
Name Category: 'Project Budget'!$F$15:$F$221
Name DL_Country: #N/A
Name DL_Country: Comparasion!#REF!
Name DL_Country: RMS!#REF!
Name DL_Country: 'Project Budget'!#REF!
Name DL_TotalDOL: #N/A
Name DL_TotalDOL: Comparasion!$B$7:$B$35
Name DL_TotalDOL: RMS!$T$9:$T$27
Name DL_TotalDOL: 'Project Budget'!$S$14:$S$39
Name EQ_Country: #N/A
Name EQ_Country: Comparasion!#REF!
Name EQ_Country: RMS!#REF!
Name EQ_Country: 'Project Budget'!#REF!
Name EQ_TotalDOL: #N/A
Name EQ_TotalDOL: Comparasion!#REF!
Name EQ_TotalDOL: RMS!#REF!
Name EQ_TotalDOL: 'Project Budget'!#REF!
Name inf: #N/A
Name inf: Comparasion!#REF!
Name inf: #REF!
Name inf: #REF!
Name JEA_Country: #N/A
Name JEA_Country: Comparasion!#REF!
Name JEA_Country: #REF!
Name JEA_Country: #REF!
Name JEA_Year1: #N/A
Name JEA_Year1: Comparasion!#REF!
Name JEA_Year1: #REF!
Name JEA_Year1: #REF!
Name ME_Country: #N/A
Name ME_Country: Comparasion!#REF!
Name ME_Country: RMS!#REF!
Name ME_Country: 'Project Budget'!#REF!
Name ME_TotalDOL: #N/A
Name ME_TotalDOL: Comparasion!$B$260:$B$275
Name ME_TotalDOL: RMS!#REF!
Name ME_TotalDOL: 'Project Budget'!$S$189:$S$203
Name O1_Country: #N/A
Name O1_Country: Comparasion!#REF!
Name O1_Country: RMS!#REF!
Name O1_Country: 'Project Budget'!#REF!
Name O1_TotalDOL: #N/A
Name O1_TotalDOL: Comparasion!#REF!
Name O1_TotalDOL: RMS!$T$108:$T$109
Name O1_TotalDOL: 'Project Budget'!#REF!
Name O2_Country: #N/A
Name O2_Country: Comparasion!#REF!
Name O2_Country: RMS!#REF!
Name O2_Country: 'Project Budget'!#REF!
Name O2_TotalDOL: #N/A
Name O2_TotalDOL: Comparasion!#REF!
Name O2_TotalDOL: RMS!#REF!
Name O2_TotalDOL: 'Project Budget'!#REF!
Name SU_Country: #N/A
Name SU_Country: Comparasion!#REF!
Name SU_Country: RMS!#REF!
Name SU_Country: 'Project Budget'!#REF!

Sheet Budget Summary
A1: Improving Gender Equity in the Mexican Workplace
A2: FOA-ILAB-21-13
A3: CFDA 17.401
A4: Partners of the Americas
A6: BUDGET ITEM | B6: TOTAL DOL | C6: TOTAL COST SHARING | D6: PROJECT GRAND TOTAL | E6: ORIGINAL BUDGET | F6: DIFFERENCE
A7: Direct Labor (Personnel & Fringe) | B7: ='Project Budget'!S42 -> 3064473 | C7: ='Project Budget'!T42 -> 0 | D7: =SUM(B7:C7) -> 3064473 | E7: 2642048 | F7: =ROUND(D7-E7,0) -> 422425
A8: Travel | B8: ='Project Budget'!S62 -> 107797 | C8: ='Project Budget'!T62 -> 0 | D8: =SUM(B8:C8) -> 107797 | E8: 238355 | F8: =ROUND(D8-E8,0) -> -130558
A9: Equipment | B9: ='Project Budget'!S66 -> 0 | C9: ='Project Budget'!T66 -> 0 | D9: =SUM(B9:C9) -> 0 | E9: 45000 | F9: =ROUND(D9-E9,0) -> -45000
A10: Supplies and Office Expenses | B10: ='Project Budget'!S88 -> 474489 | C10: ='Project Budget'!T88 -> 0 | D10: =SUM(B10:C10) -> 474489 | E10: 331507 | F10: =ROUND(D10-E10,0) -> 142982
A11: Contractual (Subawards and Contracts) | B11: ='Project Budget'!S102 -> 3380737 | C11: ='Project Budget'!T102 -> 0 | D11: =SUM(B11:C11) -> 3380737 | E11: 3449920 | F11: =ROUND(D11-E11,0) -> -69183
A12: Other - Outcome 1 | B12: ='Project Budget'!S143 -> 187250 | C12: ='Project Budget'!T143 -> 0 | D12: =SUM(B12:C12) -> 187250 | E12: 318440 | F12: =ROUND(D12-E12,0) -> -131190
A13: Other - Outcome 2 | B13: ='Project Budget'!S184 -> 164740 | C13: ='Project Budget'!T184 -> 0 | D13: =SUM(B13:C13) -> 164740 | E13: 342320 | F13: =ROUND(D13-E13,0) -> -177580
A14: Monitoring, Evaluation, and Collection of Reliable Data | B14: ='Project Budget'!S217 -> 391126 | C14: ='Project Budget'!T217 -> 0 | D14: =SUM(B14:C14) -> 391126 | E14: 403022 | F14: =ROUND(D14-E14,0) -> -11896
A15: Total Direct Costs | B15: =SUM(B7:B14) -> 7770612 | C15: =SUM(C7:C14) -> 0 | D15: =SUM(D7:D14) -> 7770612 | E15: 7770611 | F15: =ROUND(D15-E15,-1) -> 0
A16: Indirect Costs (NICRA) | B16: ='Project Budget'!S221 -> 2229388 | C16: ='Project Budget'!T221 -> 0 | D16: =SUM(B16:C16) -> 2229388 | E16: 2229388 | F16: =ROUND(D16-E16,0) -> 0
A17: TOTAL COSTS | B17: =B16+B15 -> 10000000 | C17: =C16+C15 -> 0 | D17: =D16+D15 -> 10000000 | E17: 10000000 | F17: =ROUND(D17-E17,0) -> 0
A19: ADMINISTRATIVE COSTS | B19: =B16+B7 -> 5293861
A20: PROGRAM COSTS | B20: =B8+B12+B13+B14+B11+B10+B9 -> 4706139

Sheet Project Budget
E1: Equal Access to Quality Jobs for Women and Girls in Agriculture (EQUAL)
E2: FOA-ILAB-19-02
E3: Partners of the Americas
E4: Partners of the Americas
E5: NOFO: FOA-ILAB-21-13
E6: Project Name: Improving Gender Equity in the Mexican Workplace
E7: Country: Mexico
A8: Entity: | B8: P | E8: Budget Assumptions:
A9: Program-Dept.: | B9: 20200 | E9: Inflation - US Based Goods/Services | F9: 1.03
A10: Funder-Grant: | B10: DOL425 | E10: Inflation - Locally Purchased Goods/Services | F10: 1.04
E11: Merit Based Increases for HQ & Field Staff | F11: 1.035
A12: Activity Code | B12: Account Code | C12: Country Code | D12: Subcontract Code | E12: BUDGET ITEM | F12: CATEGORY | G12: UNIT | H12: # of Units | I12: RATE / UNIT | J12: YEAR 1 2022 | K12: # of Units | L12: YEAR 2 2023 | M12: # of Units | N12: YEAR 3 2024 | O12: # of Units | P12: YEAR 4 2025 | Q12: # of Units | R12: YEAR 5 2026 | S12: TOTAL DOL | T12: TOTAL COST SHARING | U12: PROJECT GRAND TOTAL
E13: Direct Labor (Personnel & Fringe Benefits)
E14: Key Personnel
A15: PERSNL-PD | B15: 70000 | C15: 0 | D15: 0 | E15: Project Director (100%) - Dr. Alma Rico | F15: Salaries | G15: Month | H15: 12 | I15: 8000 | J15: =H15*I15 -> 96000 | K15: 12 | L15: =K15*I15*$F$11 -> 99360 | M15: 12 | N15: =(M15*I15*$F$11*$F$11) -> 102838 | O15: 12 | P15: =O15*I15*$F$11*$F$11*$F$11 -> 106437 | Q15: 6 | R15: =I15*Q15*$F$11*$F$11*$F$11*$F$11 -> 55081 | S15: =SUM(J15+L15+N15+P15+R15) -> 459716 | T15: 0 | U15: =SUM(S15:T15) -> 459716
A16: PERSNL-M&E | B16: 70000 | C16: MEX | D16: 0 | E16: Monitoring and Evaluation (M&E) Officer (100%) - Ms. Ana Georgina Pulido-Carrillo / Azucena Aguirre Crespo | F16: Salaries | G16: Month | H16: 11 | I16: 4400 | J16: =I16*H16 -> 48400 | K16: 12 | L16: =K16*I16*$F$11 -> 54648 | M16: 12 | N16: =M16*I16*$F$11*$F$11 -> 56561 | O16: 12 | P16: =O16*I16*$F$11*$F$11*$F$11 -> 58540 | Q16: 6 | R16: =I16*Q16*$F$11*$F$11*$F$11*$F$11 -> 30295 | S16: =SUM(J16+L16+N16+P16+R16) -> 248444 | T16: 0 | U16: =SUM(S16:T16) -> 248444
E18: Other Professional Personnel
A19: PERSNL-GS | B19: 70000 | C19: MEX | D19: 0 | E19: Gender Specialist (100%) XIHH | F19: Salaries | G19: Month | H19: 9 | I19: 3000 | J19: =I19*H19 -> 27000 | K19: 12 | L19: =K19*I19*$F$11 -> 37260 | M19: 12 | N19: =M19*I19*$F$11*$F$11 -> 38564 | O19: 12 | P19: =O19*I19*$F$11*$F$11*$F$11 -> 39914 | Q19: 3 | R19: =I19*Q19*$F$11*$F$11*$F$11*$F$11 -> 10328 | S19: =SUM(J19+L19+N19+P19+R19) -> 153066 | T19: 0 | U19: =SUM(S19:T19) -> 153066
A20: PERSNL-WLO | B20: 70000 | C20: MEX | D20: 0 | E20: Work Labor Organizations Specialist (100%) GVG | F20: Salaries | G20: Month | H20: 6 | I20: 3500 | J20: =I20*H20 -> 21000 | K20: 12 | L20: =K20*I20*$F$11 -> 43470 | M20: 12 | N20: =M20*I20*$F$11*$F$11 -> 44991 | O20: 12 | P20: =O20*I20*$F$11*$F$11*$F$11 -> 46566 | Q20: 3 | R20: =I20*Q20*$F$11*$F$11*$F$11*$F$11 -> 12049 | S20: =SUM(J20+L20+N20+P20+R20) -> 168076 | T20: 0 | U20: =SUM(S20:T20) -> 168076
A21: PERSNL-COM | B21: 70000 | C21: MEX | D21: 0 | E21: Communication Specialist (100%) VRG | F21: Salaries | G21: Month | H21: 6 | I21: 2800 | J21: =H21*I21 -> 16800 | K21: 12 | L21: =K21*I21*$F$11 -> 34776 | M21: 12 | N21: =M21*I21*$F$11*$F$11 -> 35993 | O21: 12 | P21: =O21*I21*$F$11*$F$11*$F$11 -> 37253 | Q21: 3 | R21: =I21*Q21*$F$11*$F$11*$F$11*$F$11 -> 9639 | S21: =SUM(J21+L21+N21+P21+R21) -> 134461 | T21: 0 | U21: =SUM(S21:T21) -> 134461
A22: PERSNL-RCM | B22: 70000 | C22: MEX | D22: 0 | E22: Regional Coordinator CDMEX (100%) TBD | F22: Salaries | G22: Month | H22: 5 | I22: 2440 | J22: =H22*I22 -> 12200 | K22: 12 | L22: =K22*I22*$F$11 -> 30305 | M22: 12 | N22: =M22*I22*$F$11*$F$11 -> 31365 | O22: 12 | P22: =O22*I22*$F$11*$F$11*$F$11 -> 32463 | Q22: 3 | R22: =I22*Q22*$F$11*$F$11*$F$11*$F$11 -> 8400 | S22: =SUM(J22+L22+N22+P22+R22) -> 114733 | T22: 0 | U22: =SUM(S22:T22) -> 114733
A23: PERSNL-RCM | B23: 70000 | C23: MEX | D23: 0 | E23: Regional Coordinator Jalisco (100%) TBD | F23: Salaries | G23: Month | H23: 5 | I23: 2440 | J23: =H23*I23 -> 12200 | K23: 12 | L23: =K23*I23*$F$11 -> 30305 | M23: 12 | N23: =M23*I23*$F$11*$F$11 -> 31365 | O23: 12 | P23: =O23*I23*$F$11*$F$11*$F$11 -> 32463 | Q23: 3 | R23: =I23*Q23*$F$11*$F$11*$F$11*$F$11 -> 8400 | S23: =SUM(J23+L23+N23+P23+R23) -> 114733 | T23: 0 | U23: =SUM(S23:T23) -> 114733
A24: PERSNL-RCJ | B24: 70000 | C24: MEX | D24: 0 | E24: Regional Coordinator Chihuahua (100%) TBD | F24: Salaries | G24: Month | H24: 5 | I24: 2440 | J24: =H24*I24 -> 12200 | K24: 12 | L24: =K24*I24*$F$11 -> 30305 | M24: 12 | N24: =M24*I24*$F$11*$F$11 -> 31365 | O24: 12 | P24: =O24*I24*$F$11*$F$11*$F$11 -> 32463 | Q24: 3 | R24: =I24*Q24*$F$11*$F$11*$F$11*$F$11 -> 8400 | S24: =SUM(J24+L24+N24+P24+R24) -> 114733 | T24: 0 | U24: =SUM(S24:T24) -> 114733
A25: PERSNL-M&E | B25: 70000 | C25: MEX | D25: 0 | E25: Monitoring & Evaluation Specialist (100%) TBD | F25: Salaries | G25: Month | H25: 4 | I25: 2500 | J25: =H25*I25 -> 10000 | K25: 12 | L25: =K25*I25*$F$11 -> 31050 | M25: 12 | N25: =M25*I25*$F$11*$F$11 -> 32137 | O25: 12 | P25: =O25*I25*$F$11*$F$11*$F$11 -> 33262 | Q25: 3 | R25: =I25*Q25*$F$11*$F$11*$F$11*$F$11 -> 8606 | S25: =SUM(J25+L25+N25+P25+R25) -> 115055 | T25: 0 | U25: =SUM(S25:T25) -> 115055
A26: PERSNL-PA | B26: 70000 | C26: MEX | D26: 0 | E26: Project Assistant (100%) VILC | F26: Salaries | G26: Month | H26: 7 | I26: 2010 | J26: =H26*I26 -> 14070 | K26: 12 | L26: =K26*I26*$F$11 -> 24964 | M26: 12 | N26: =M26*I26*$F$11*$F$11 -> 25838 | O26: 12 | P26: =O26*I26*$F$11*$F$11*$F$11 -> 26742 | Q26: 6 | R26: =I26*Q26*$F$11*$F$11*$F$11*$F$11 -> 13839 | S26: =SUM(J26+L26+N26+P26+R26) -> 105453 | T26: 0 | U26: =SUM(S26:T26) -> 105453
A27: PERSNL-F&A | B27: 70000 | C27: MEX | D27: 0 | E27: Finance & Administration Director (45%) RARH | F27: Salaries | G27: Month | H27: 12 | I27: =6750*0.45 -> 3038 | J27: =H27*I27 -> 36456 | K27: 12 | L27: =K27*I27*$F$11 -> 37732 | M27: 12 | N27: =M27*I27*$F$11*$F$11 -> 39053 | O27: 12 | P27: =O27*I27*$F$11*$F$11*$F$11 -> 40419 | Q27: 6 | R27: =I27*Q27*$F$11*$F$11*$F$11*$F$11 -> 20917 | S27: =SUM(J27+L27+N27+P27+R27) -> 174577 | T27: 0 | U27: =SUM(S27:T27) -> 174577
A28: PERSNL-AST | B28: 70000 | C28: MEX | D28: 0 | E28: Administration Officer (50%) ASA | F28: Salaries | G28: Month | H28: 12 | I28: =2010*0.5 -> 1005 | J28: =H28*I28 -> 12060 | K28: 12 | L28: =K28*I28*$F$11 -> 12482 | M28: 12 | N28: =M28*I28*$F$11*$F$11 -> 12919 | O28: 12 | P28: =O28*I28*$F$11*$F$11*$F$11 -> 13371 | Q28: 6 | R28: =I28*Q28*$F$11*$F$11*$F$11*$F$11 -> 6920 | S28: =SUM(J28+L28+N28+P28+R28) -> 57752 | T28: 0 | U28: =SUM(S28:T28) -> 57752
A29: PERSNL-ACT | B29: 70000 | C29: MEX | D29: 0 | E29: Finance Officer (100%) LGA | F29: Salaries | G29: Month | H29: 8 | I29: 1900 | J29: =H29*I29 -> 15200 | K29: 12 | L29: =K29*I29*$F$11 -> 23598 | M29: 12 | N29: =M29*I29*$F$11*$F$11 -> 24424 | O29: 12 | P29: =O29*I29*$F$11*$F$11*$F$11 -> 25279 | Q29: 6 | R29: =I29*Q29*$F$11*$F$11*$F$11*$F$11 -> 13082 | S29: =SUM(J29+L29+N29+P29+R29) -> 101583 | T29: 0 | U29: =SUM(S29:T29) -> 101583
E31: Home Office Support
A32: PERSNL-PM | B32: Timesheets | C32: 0 | D32: 0 | E32: Project Manager (10%) | F32: Salaries | G32: Month | H32: 12 | I32: =13000*0.1 -> 1300 | J32: =H32*I32 -> 15600 | K32: 12 | L32: =K32*I32*$F$11 -> 16146 | M32: 12 | N32: =M32*I32*$F$11*$F$11 -> 16711 | O32: 12 | P32: =O32*I32*$F$11*$F$11*$F$11 -> 17296 | Q32: 6 | R32: =I32*Q32*$F$11*$F$11*$F$11*$F$11 -> 8951 | S32: =SUM(J32+L32+N32+P32+R32) -> 74704 | T32: 0 | U32: =SUM(S32:T32) -> 74704
A33: PERSNL-PO | B33: Timesheets | C33: 0 | D33: 0 | E33: Program Officer (40%) | F33: Salaries | G33: Month | H33: 12 | I33: =5500*0.4 -> 2200 | J33: =H33*I33 -> 26400 | K33: 12 | L33: =K33*I33*$F$11 -> 27324 | M33: 12 | N33: =M33*I33*$F$11*$F$11 -> 28280 | O33: 12 | P33: =O33*I33*$F$11*$F$11*$F$11 -> 29270 | Q33: 6 | R33: =I33*Q33*$F$11*$F$11*$F$11*$F$11 -> 15147 | S33: =SUM(J33+L33+N33+P33+R33) -> 126421 | T33: 0 | U33: =SUM(S33:T33) -> 126421
E35: Subtotal Personnel | J35: =SUM(J15:J33) -> 375586 | L35: =SUM(L15:L33) -> 533725 | N35: =SUM(N15:N33) -> 552404 | P35: =SUM(P15:P33) -> 571738 | R35: =SUM(R15:R33) -> 230054 | S35: =SUM(J35+L35+N35+P35+R35) -> 2263507 | T35: 0 | U35: =SUM(S35:T35) -> 2263507
E37: Fringe Benefits
A38: FRINGE-MX | B38: 70015 | C38: MEX | D38: 0 | E38: Fringe benefits - Mexico | F38: Fringe Benefits | G38: Month | I38: 0.3671 | J38: =SUM(J15:J29)*$I38 -> 122459 | L38: =SUM(L15:L29)*$I38 -> 179973 | N38: =SUM(N15:N29)*$I38 -> 186271 | P38: =SUM(P15:P29)*$I38 -> 192791 | R38: =SUM(R15:R29)*$I38 -> 75606 | S38: =SUM(J38+L38+N38+P38+R38) -> 757100 | T38: 0 | U38: =SUM(S38:T38) -> 757100
A39: FRINGE | B39: Timesheets | C39: 0 | D39: 0 | E39: Fringe benefits - Home Office Support | F39: Fringe Benefits | G39: Month | I39: 0.2181 | J39: =SUM(J32:J33)*$I$39 -> 9160 | L39: =SUM(L32:L33)*$I$39 -> 9481 | N39: =SUM(N32:N33)*$I$39 -> 9813 | P39: =SUM(P32:P33)*$I$39 -> 10156 | R39: =SUM(R32:R33)*$I$39 -> 5256 | S39: =SUM(J39+L39+N39+P39+R39) -> 43866 | T39: 0 | U39: =SUM(S39:T39) -> 43866
E41: Subtotal Fringe Benefits | J41: =SUM(J38:J40) -> 131619 | L41: =SUM(L38:L40) -> 189454 | N41: =SUM(N38:N40) -> 196084 | P41: =SUM(P38:P40) -> 202947 | R41: =SUM(R38:R40) -> 80862 | S41: =SUM(S38:S40) -> 800966 | T41: =SUM(T39:T39) -> 0 | U41: =SUM(U38:U40) -> 800966
E42: Subtotal Direct Labor (Personnel & Fringe Benefits) | J42: =J41+J35 -> 507205 | L42: =L41+L35 -> 723179 | N42: =N41+N35 -> 748488 | P42: =P41+P35 -> 774685 | R42: =R41+R35 -> 310916 | S42: =S41+S35 -> 3064473 | T42: =T41+T35 -> 0 | U42: =U41+U35 -> 3064473
E43: Travel
E44: T1: Post-award Meeting with ILAB
A45: GE.T1.A | B45: 86040 | C45: 0/MEX | D45: 0 | E45: Airfare - Mexico-DC | F45: Travel | G45: Trip | I45: 650 | J45: =H45*I45 -> 0 | K45: 2 | L45: =K45*I45*$F$10 -> 1352 | N45: =M45*I45*$F$10*$F$10 -> 0 | O45: 0 | P45: =O45*I45*$F$10*$F$10*$F$10 -> 0 | Q45: 0 | R45: =Q45*I45*$F$10*$F$10*$F$10*$F$10 -> 0 | S45: =J45+L45+N45+P45+R45 -> 1352 | T45: - | U45: =SUM(S45:T45) -> 1352
...

Sheet Comparasion
A1: Equal Access to Quality Jobs for Women and Girls in Agriculture (EQUAL)
A2: FOA-ILAB-19-02
A3: Partners of the Americas
A4: Project Name: Improving Gender Equity in the Mexican Workplace
A5: BUDGET ITEM | B5: Current approved allocation | C5: New proposed allocation | D5: New proposed allocation
A6: Direct Labor (Personnel & Fringe Benefits)
A7: Key Personnel
A8: Project Director (100%) - Dr. Alma Rico | B8: 453777 | C8: ='Project Budget'!S15 -> 459716 | D8: ='Project Budget'!U15 -> 459716
A9: Monitoring and Evaluation (M&E) Officer (100%) - Ms. Ana Georgina Pulido-Carrillo | B9: 253722 | C9: ='Project Budget'!S16 -> 248444 | D9: ='Project Budget'!U16 -> 248444
A11: Other Professional Personnel
A12: Gender Specialist (100%) | B12: 200619 | C12: ='Project Budget'!U19 -> 153066 | D12: =B12-C12 -> 47553
A13: Work Labor Organizations Specialist (100%) GVG | B13: 0 | C13: ='Project Budget'!U20 -> 168076 | D13: =B13-C13 -> -168076
A14: Communication Specialist (100%) VRG | B14: 0 | C14: ='Project Budget'!U21 -> 134461 | D14: =B14-C14 -> -134461
A15: Regional Coordinator CDMX (100%) | B15: 112871 | C15: ='Project Budget'!U22 -> 114733 | D15: =B15-C15 -> -1862
A16: Regional Coordinator Jalisco (100%) | B16: 112871 | C16: ='Project Budget'!U23 -> 114733 | D16: =B16-C16 -> -1862
A17: Regional Coordinator Chihuahua (100%) | B17: 112871 | C17: ='Project Budget'!U24 -> 114733 | D17: =B17-C17 -> -1862
A18: Communication Officer (100%) | B18: 146220 | C18: 0 | D18: =B18-C18 -> 146220
A19: Monitoring & Evaluation Specialist (100%) TBD | B19: 0 | C19: ='Project Budget'!S25 -> 115055 | D19: =B19-C19 -> -115055
A20: Project Assistant (100%) VILC | B20: 0 | C20: ='Project Budget'!S26 -> 105453 | D20: =B20-C20 -> -105453
A21: Finance & Administration Director (45%) RARH | B21: 169992 | C21: ='Project Budget'!S27 -> 174577 | D21: =B21-C21 -> -4585
A22: Administrative Assistant (100%) | B22: 94264 | C22: 0 | D22: =B22-C22 -> 94264
A23: Accountant (100%) | B23: 98130 | C23: 0 | D23: =B23-C23 -> 98130
A24: Administration Officer (50%) ASA | B24: 0 | C24: ='Project Budget'!U28 -> 57752 | D24: =B24-C24 -> -57752
A25: Finance Officer (100%) LGA | B25: 0 | C25: ='Project Budget'!U29 -> 101583 | D25: =B25-C25 -> -101583
A27: Home Office Support
A28: Project Manager (10%) | B28: 72078 | C28: ='Project Budget'!S32 -> 74704 | D28: =B28-C28 -> -2626
A29: Program Officer (40%) | B29: 126860 | C29: ='Project Budget'!S33 -> 126421 | D29: =B29-C29 -> 439
A31: Subtotal Personnel | B31: =SUM(B8:B29) -> 1954275 | C31: =SUM(C8:C29) -> 2263507 | D31: =B31-C31 -> -309232
A33: Fringe Benefits
A34: Fringe benefits - Mexico Staff | B34: 644385 | C34: ='Project Budget'!S38 -> 757100 | D34: =B34-C34 -> -112715
A35: Fringe benefits - Home Office Support | B35: 43388 | C35: ='Project Budget'!S39 -> 43866 | D35: =B35-C35 -> -478
A37: Subtotal Fringe Benefits | B37: =SUM(B33:B35) -> 687773 | C37: =SUM(C33:C35) -> 800966 | D37: =B37-C37 -> -113193
A38: Subtotal Direct Labor (Personnel & Fringe Benefits) | B38: =B37+B31 -> 2642048 | C38: =C37+C31 -> 3064473 | D38: =B38-C38 -> -422425
A39: Travel
A40: T1: Post-award Meeting with ILAB
A41: Airfare - Mexico-DC | B41: 1300 | C41: ='Project Budget'!U45 -> 1352 | D41: =B41-C41 -> -52
A42: Lodging and M&IE in DC | B42: 2184 | C42: ='Project Budget'!U46 -> 2267 | D42: =B42-C42 -> -83
A43: Local transportation in DC | B43: 600 | C43: ='Project Budget'!U47 -> 624 | D43: =B43-C43 -> -24
A44: U.S. Visa Fees | B44: 320 | C44: ='Project Budget'!U48 -> 333 | D44: =B44-C44 -> -13
A45: T2: Field Personnel Annual Visits with ILAB
...

Sheet RMS
F1: Name of Project: DOL425 Improving Gender Equity in the Mexican Workplace
F2: Name of Subawardee: Red de Mujeres Sindicalistas (RMS)
F3: Subaward Budget
A4: Entity: | B4: P | F4: Budget Assumptions:
A5: Program-Dept.: | B5: 20200 | F5: Inflation - Locally Purchased Goods/Services | G5: 1.04
A6: Funder-Grant: | B6: DOL425 | F6: Merit Based Increases for Staff | G6: 1.035
A7: Activity Code | B7: Account Code | C7: Country Code | D7: Subcontract Code | E7: Sub-budget Code | F7: BUDGET ITEM | G7: CATEGORY | H7: UNIT | I7: # of Units | J7: RATE/ UNIT | K7: YEAR 1 2022 | L7: # of Units | M7: YEAR 2 2023 | N7: # of Units | O7: YEAR 3 2024 | P7: # of Units | Q7: YEAR 4 2025 | R7: # of Units | S7: YEAR 5 2026 | T7: TOTAL PARTNERS OF THE AMERICAS | U7: TOTAL COST SHARING | V7: PROJECT GRAND TOTAL
F8: Direct Labor
A9: SUBRMS | B9: 89050 | C9: MEX | D9: RMS | E9: RMSPERPC | F9: General Project Coordinator (50%) | G9: Salaries | H9: Month | I9: 3 | J9: =4500*0.5 -> 2250 | K9: =I9*J9 -> 6750 | L9: 12 | M9: =L9*J9*$G$6 -> 27945 | N9: 12 | O9: =N9*J9*$G$6*$G$6 -> 28923 | P9: 12 | Q9: =P9*J9*$G$6*$G$6*$G$6 -> 29935 | R9: 2 | S9: =R9*J9*$G$6*$G$6*$G$6*$G$6 -> 5164 | T9: =SUM(K9+M9+O9+Q9+S9) -> 98717 | U9: 0 | V9: =SUM(T9:U9) -> 98717
A10: SUBRMS | B10: 89050 | C10: MEX | D10: RMS | E10: RMSPERTC | F10: Training Coordinator (50%) | G10: Salaries | H10: Month | I10: 3 | J10: =4500*0.5 -> 2250 | K10: =I10*J10 -> 6750 | L10: 12 | M10: =L10*J10*$G$6 -> 27945 | N10: 12 | O10: =N10*J10*$G$6*$G$6 -> 28923 | P10: 12 | Q10: =P10*J10*$G$6*$G$6*$G$6 -> 29935 | R10: 2 | S10: =R10*J10*$G$6*$G$6*$G$6*$G$6 -> 5164 | T10: =SUM(K10+M10+O10+Q10+S10) -> 98717 | U10: 0 | V10: =SUM(T10:U10) -> 98717
A11: SUBRMS | B11: 89050 | C11: MEX | D11: RMS | E11: RMSPERAC | F11: Administration Coordinator (50%) | G11: Salaries | H11: Month | I11: 3 | J11: =4500*0.5 -> 2250 | K11: =I11*J11 -> 6750 | L11: 12 | M11: =L11*J11*$G$6 -> 27945 | N11: 12 | O11: =N11*J11*$G$6*$G$6 -> 28923 | P11: 12 | Q11: =P11*J11*$G$6*$G$6*$G$6 -> 29935 | R11: 2 | S11: =R11*J11*$G$6*$G$6*$G$6*$G$6 -> 5164 | T11: =SUM(K11+M11+O11+Q11+S11) -> 98717 | U11: 0 | V11: =SUM(T11:U11) -> 98717
A12: SUBRMS | B12: 89050 | C12: MEX | D12: RMS | E12: RMSPERCOM | F12: Communication Coordinator (50%) | G12: Salaries | H12: Month | I12: 3 | J12: =2500*0.5 -> 1250 | K12: =I12*J12 -> 3750 | L12: 12 | M12: =L12*J12*$G$6 -> 15525 | N12: 12 | O12: =N12*J12*$G$6*$G$6 -> 16068 | P12: 12 | Q12: =P12*J12*$G$6*$G$6*$G$6 -> 16631 | R12: 2 | S12: =R12*J12*$G$6*$G$6*$G$6*$G$6 -> 2869 | T12: =SUM(K12+M12+O12+Q12+S12) -> 54843 | U12: 0 | V12: =SUM(T12:U12) -> 54843
A13: SUBRMS | B13: 89050 | C13: MEX | D13: RMS | E13: RMSPERM&E | F13: Monitoring & Evaluation Coordinator (100%) | G13: Salaries | H13: Month | I13: 2 | J13: 1752 | K13: =I13*J13 -> 3504 | L13: 12 | M13: =L13*J13*$G$6 -> 21760 | N13: 12 | O13: =N13*J13*$G$6*$G$6 -> 22521 | P13: 12 | Q13: =P13*J13*$G$6*$G$6*$G$6 -> 23310 | R13: 2 | S13: =R13*J13*$G$6*$G$6*$G$6*$G$6 -> 4021 | T13: =SUM(K13+M13+O13+Q13+S13) -> 75116 | U13: 0 | V13: =SUM(T13:U13) -> 75116
A14: SUBRMS | B14: 89050 | C14: MEX | D14: RMS | E14: RMSPERIMPC | F14: Follow-up and Implementation Coordinator (100%) | G14: Salaries | H14: Month | I14: 2 | J14: 1502 | K14: =I14*J14 -> 3004 | L14: 12 | M14: =L14*J14*$G$6 -> 18655 | N14: 12 | O14: =N14*J14*$G$6*$G$6 -> 19308 | P14: 12 | Q14: =P14*J14*$G$6*$G$6*$G$6 -> 19984 | R14: 2 | S14: =R14*J14*$G$6*$G$6*$G$6*$G$6 -> 3447 | T14: =SUM(K14+M14+O14+Q14+S14) -> 64398 | U14: 0 | V14: =SUM(T14:U14) -> 64398
A15: SUBRMS | B15: 89050 | C15: MEX | D15: RMS | E15: RMSPERADM | F15: Administration Assistant (50%) | G15: Salaries | H15: Month | I15: 2 | J15: =1001*0.5 -> 501 | K15: =I15*J15 -> 1002 | L15: 12 | M15: =L15*J15*$G$6 -> 6222 | N15: 12 | O15: =N15*J15*$G$6*$G$6 -> 6440 | P15: 12 | Q15: =P15*J15*$G$6*$G$6*$G$6 -> 6666 | R15: 2 | S15: =R15*J15*$G$6*$G$6*$G$6*$G$6 -> 1150 | T15: =SUM(K15+M15+O15+Q15+S15) -> 21480 | U15: 0 | V15: =SUM(T15:U15) -> 21480
A16: SUBRMS | B16: 89050 | C16: MEX | D16: RMS | E16: RMSPERORG | F16: Organization and Logistics Lead (100%) | G16: Salaries | H16: Month | I16: 2 | J16: 1001 | K16: =I16*J16 -> 2002 | L16: 12 | M16: =L16*J16*$G$6 -> 12432 | N16: 12 | O16: =N16*J16*$G$6*$G$6 -> 12868 | P16: 12 | Q16: =P16*J16*$G$6*$G$6*$G$6 -> 13318 | R16: 2 | S16: =R16*J16*$G$6*$G$6*$G$6*$G$6 -> 2297 | T16: =SUM(K16+M16+O16+Q16+S16) -> 42917 | U16: 0 | V16: =SUM(T16:U16) -> 42917
A17: SUBRMS | B17: 89050 | C17: MEX | D17: RMS | E17: RMSPEREVN | F17: Events Assistant (100%) | G17: Salaries | H17: Month | I17: 2 | J17: 1001 | K17: =I17*J17 -> 2002 | L17: 12 | M17: =L17*J17*$G$6 -> 12432 | N17: 12 | O17: =N17*J17*$G$6*$G$6 -> 12868 | P17: 12 | Q17: =P17*J17*$G$6*$G$6*$G$6 -> 13318 | R17: 2 | S17: =R17*J17*$G$6*$G$6*$G$6*$G$6 -> 2297 | T17: =SUM(K17+M17+O17+Q17+S17) -> 42917 | U17: 0 | V17: =SUM(T17:U17) -> 42917
A18: SUBRMS | B18: 89050 | C18: MEX | D18: RMS | E18: RMSPERACCT | F18: Accountant (100%) | G18: Salaries | H18: Month | I18: 3 | J18: 1001 | K18: =I18*J18 -> 3003 | L18: 12 | M18: =L18*J18*$G$6 -> 12432 | N18: 12 | O18: =N18*J18*$G$6*$G$6 -> 12868 | P18: 12 | Q18: =P18*J18*$G$6*$G$6*$G$6 -> 13318 | R18: 2 | S18: =R18*J18*$G$6*$G$6*$G$6*$G$6 -> 2297 | T18: =SUM(K18+M18+O18+Q18+S18) -> 43918 | U18: 0 | V18: =SUM(T18:U18) -> 43918
A19: SUBRMS | B19: 89050 | C19: MEX | D19: RMS | E19: RMSPERDES | F19: Designer (50%) | G19: Salaries | H19: Month | I19: 2 | J19: =1001*0.5 -> 501 | K19: =I19*J19 -> 1002 | L19: 12 | M19: =L19*J19*$G$6 -> 6222 | N19: 12 | O19: =N19*J19*$G$6*$G$6 -> 6440 | P19: 12 | Q19: =P19*J19*$G$6*$G$6*$G$6 -> 6666 | R19: 2 | S19: =R19*J19*$G$6*$G$6*$G$6*$G$6 -> 1150 | T19: =SUM(K19+M19+O19+Q19+S19) -> 21480 | U19: 0 | V19: =SUM(T19:U19) -> 21480
A20: SUBRMS | B20: 89050 | C20: MEX | D20: RMS | E20: RMSPERSOC | F20: Social Media and Campaigns Lead (50%) | G20: Salaries | H20: Month | I20: 2 | J20: =1001*0.5 -> 501 | K20: =I20*J20 -> 1002 | L20: 12 | M20: =L20*J20*$G$6 -> 6222 | N20: 12 | O20: =N20*J20*$G$6*$G$6 -> 6440 | P20: 12 | Q20: =P20*J20*$G$6*$G$6*$G$6 -> 6666 | R20: 2 | S20: =R20*J20*$G$6*$G$6*$G$6*$G$6 -> 1150 | T20: =SUM(K20+M20+O20+Q20+S20) -> 21480 | U20: 0 | V20: =SUM(T20:U20) -> 21480
A21: SUBRMS | B21: 89050 | C21: MEX | D21: RMS | E21: RMSPERCDJ | F21: Cd. Juarez Organizer (100%) | G21: Salaries | H21: Month | I21: 2 | J21: 1001 | K21: =I21*J21 -> 2002 | L21: 12 | M21: =L21*J21*$G$6 -> 12432 | N21: 12 | O21: =N21*J21*$G$6*$G$6 -> 12868 | P21: 12 | Q21: =P21*J21*$G$6*$G$6*$G$6 -> 13318 | R21: 2 | S21: =R21*J21*$G$6*$G$6*$G$6*$G$6 -> 2297 | T21: =SUM(K21+M21+O21+Q21+S21) -> 42917 | U21: 0 | V21: =SUM(T21:U21) -> 42917
A22: SUBRMS | B22: 89050 | C22: MEX | D22: RMS | E22: RMSPERGUAD | F22: Guadalajara Organizer (100%) | G22: Salaries | H22: Month | I22: 2 | J22: 851 | K22: =I22*J22 -> 1702 | L22: 12 | M22: =L22*J22*$G$6 -> 10569 | N22: 12 | O22: =N22*J22*$G$6*$G$6 -> 10939 | P22: 12 | Q22: =P22*J22*$G$6*$G$6*$G$6 -> 11322 | R22: 2 | S22: =R22*J22*$G$6*$G$6*$G$6*$G$6 -> 1953 | T22: =SUM(K22+M22+O22+Q22+S22) -> 36485 | U22: 0 | V22: =SUM(T22:U22) -> 36485
A23: SUBRMS | B23: 89050 | C23: MEX | D23: RMS | E23: RMSPERCDMX | F23: CDMX Organizer (100%) | G23: Salaries | H23: Month | I23: 2 | J23: 851 | K23: =I23*J23 -> 1702 | L23: 12 | M23: =L23*J23*$G$6 -> 10569 | N23: 12 | O23: =N23*J23*$G$6*$G$6 -> 10939 | P23: 12 | Q23: =P23*J23*$G$6*$G$6*$G$6 -> 11322 | R23: 2 | S23: =R23*J23*$G$6*$G$6*$G$6*$G$6 -> 1953 | T23: =SUM(K23+M23+O23+Q23+S23) -> 36485 | U23: 0 | V23: =SUM(T23:U23) -> 36485
F24: Subtotal | K24: =SUM(K9:K23) -> 45927 | M24: =SUM(M9:M23) -> 229307 | O24: =SUM(O9:O23) -> 237336 | Q24: =SUM(Q9:Q23) -> 245644 | S24: =SUM(S9:S23) -> 42373 | T24: =SUM(T9:T23) -> 800587 | U24: =SUM(U9:U23) -> 0 | V24: =SUM(V9:V23) -> 800587
F26: Fringe Benefits
A27: SUBRMS | B27: 89050 | C27: MEX | D27: RMS | E27: RMSFRINGE | F27: Fringe benefits - Field Office | G27: Fringe Benefits | J27: 0.2 | K27: =K24*$J$27 -> 9185 | M27: =M24*$J$27 -> 45861 | O27: =O24*$J$27 -> 47467 | Q27: =Q24*$J$27 -> 49129 | S27: =S24*$J$27 -> 8475 | T27: =SUM(K27+M27+O27+Q27+S27) -> 160117 | U27: 0 | V27: =SUM(T27:U27) -> 160117
F29: Subtotal Direct Labor | K29: =SUM(K24:K27) -> 55112 | M29: =SUM(M24:M27) -> 275168 | O29: =SUM(O24:O27) -> 284803 | Q29: =SUM(Q24:Q27) -> 294773 | S29: =SUM(S24:S27) -> 50848 | T29: =K29+M29+O29+Q29+S29 -> 960704 | U29: =SUM(U9:U27) -> 0 | V29: =SUM(T29:U29) -> 960704
F31: Travel
F32: T1: Cd. Juarez Chihuahua / Guadalajara/ CDMX
A33: SUBRMS | B33: 89050 | C33: MEX | D33: RMS | E33: RMSAIRFARE | F33: Airfare | G33: Travel | H33: Trip | I33: 9 | J33: 300 | K33: =I33*J33 -> 2700 | L33: 32 | M33: =L33*J33 -> 9600 | N33: 60 | O33: =N33*J33 -> 18000 | P33: 36 | Q33: =P33*J33 -> 10800 | R33: 4 | S33: =R33*J33 -> 1200 | T33: =K33+M33+O33+Q33+S33 -> 42300 | U33: 0 | V33: =SUM(T33:U33) -> 42300
A34: SUBRMS | B34: 89050 | C34: MEX | D34: RMS | E34: RMSLODGING | F34: Lodging | G34: Travel | H34: Day | I34: =9+9+6+3 -> 27 | J34: 75 | K34: =I34*J34 -> 2025 | L34: =20+18+14+12 -> 64 | M34: =L34*J34 -> 4800 | N34: =36+36+36+12 -> 120 | O34: =N34*J34 -> 9000 | P34: =28+22+22 -> 72 | Q34: =P34*J34 -> 5400 | R34: 16 | S34: =R34*J34 -> 1200 | T34: =K34+M34+O34+Q34+S34 -> 22425 | U34: 0 | V34: =SUM(T34:U34) -> 22425
A35: SUBRMS | B35: 89050 | C35: MEX | D35: RMS | E35: RMSM&IE | F35: M&IE | G35: Travel | H35: Day | I35: =9+9+6+1 -> 25 | J35: 40 | K35: =I35*J35 -> 1000 | L35: =20+18+14+6 -> 58 | M35: =L35*J35 -> 2320 | N35: =36+36+36+36+6 -> 150 | O35: =N35*J35 -> 6000 | P35: =28+22+22 -> 72 | Q35: =P35*J35 -> 2880 | R35: 16 | S35: =R35*J35 -> 640 | T35: =K35+M35+O35+Q35+S35 -> 12840 | U35: 0 | V35: =SUM(T35:U35) -> 12840
A36: SUBRMS | B36: 89050 | C36: MEX | D36: RMS | E36: RMSTRANS | F36: Ground Transportation | G36: Travel | H36: Day | I36: =9+9+6+3 -> 27 | J36: 35 | K36: =I36*J36 -> 945 | L36: =20+18+14+12 -> 64 | M36: =L36*J36 -> 2240 | N36: =36+36+36+12 -> 120 | O36: =N36*J36 -> 4200 | P36: =28+22+22 -> 72 | Q36: =P36*J36 -> 2520 | R36: 16 | S36: =R36*J36 -> 560 | T36: =K36+M36+O36+Q36+S36 -> 10465 | U36: 0 | V36: =SUM(T36:U36) -> 10465
A37: SUBRMS | B37: 89050 | C37: MEX | D37: RMS | E37: RMSMSTRE | F37: Misc. Staff Travel Related Expenses | G37: Travel | H37: Day | I37: =3+9 -> 12 | J37: 25 | K37: =I37*J37 -> 300 | L37: =10+18+14 -> 42 | M37: =L37*J37 -> 1050 | N37: =18+36 -> 54 | O37: =N37*J37 -> 1350 | P37: =14+22 -> 36 | Q37: =P37*J37 -> 900 | R37: 5 | S37: =R37*J37 -> 125 | T37: =K37+M37+O37+Q37+S37 -> 3725 | U37: 0 | V37: =SUM(T37:U37) -> 3725
F39: Subtotal Travel | K39: =SUM(K33:K37) -> 6970 | M39: =SUM(M33:M37) -> 20010 | O39: =SUM(O33:O37) -> 38550 | Q39: =SUM(Q33:Q37) -> 22500 | S39: =SUM(S33:S37) -> 3725 | T39: =K39+M39+O39+Q39+S39 -> 91755 | U39: =SUM(U33:U37) -> 0 | V39: =SUM(T39:U39) -> 91755
F40: Supplies - Under $5,000 USD
A41: SUBRMS | B41: 89050 | C41: MEX | D41: RMS | E41: RMSDESKTOP | F41: Desktop computers, laptops and software | G41: Supplies | H41: Unit | I41: 5 | J41: 751 | K41: =I41*J41 -> 3755 | L41: 5 | M41: =L41*J41 -> 3755 | N41: 0 | O41: =N41*J41 -> 0 | P41: 0 | Q41: =P41*J41 -> 0 | R41: 0 | S41: =R41*J41 -> 0 | T41: =K41+M41+O41+Q41+S41 -> 7510 | U41: 0 | V41: =SUM(T41:U41) -> 7510
A42: SUBRMS | B42: 89050 | C42: MEX | D42: RMS | E42: RMSMEET | F42: Meeting Expenses | G42: Supplies | H42: Unit | I42: 1 | J42: 100 | K42: =I42*J42 -> 100 | L42: 12 | M42: =L42*J42 -> 1200 | N42: 12 | O42: =N42*J42 -> 1200 | P42: 12 | Q42: =P42*J42 -> 1200 | R42: 3 | S42: =R42*J42 -> 300 | T42: =K42+M42+O42+Q42+S42 -> 4000 | U42: 0 | V42: =SUM(T42:U42) -> 4000
A43: SUBRMS | B43: 89050 | C43: MEX | D43: RMS | E43: RMSPHONE | F43: Phones | G43: Supplies | H43: Unit | I43: 7 | J43: 300 | K43: =I43*J43 -> 2100 | L43: 0 | M43: =L43*J43 -> 0 | N43: 2 | O43: =N43*J43 -> 600 | P43: 0 | Q43: =P43*J43 -> 0 | R43: 0 | S43: =R43*J43 -> 0 | T43: =K43+M43+O43+Q43+S43 -> 2700 | U43: 0 | V43: =SUM(T43:U43) -> 2700
A44: SUBRMS | B44: 89050 | C44: MEX | D44: RMS | E44: RMSSUPPLY | F44: Office Supplies | G44: Supplies | H44: Month | I44: 1 | J44: 75 | K44: =I44*J44 -> 75 | L44: 12 | M44: =L44*J44 -> 900 | N44: 12 | O44: =N44*J44 -> 900 | P44: 12 | Q44: =P44*J44 -> 900 | R44: 1 | S44: =R44*J44 -> 75 | T44: =K44+M44+O44+Q44+S44 -> 2850 | U44: 0 | V44: =SUM(T44:U44) -> 2850
...

Sheet CEREAL
F1: Name of Project: Improving Gender Equity in the Mexican Workplace
F2: Name of Subawardee: Center for Reflection and Action on Labor Rights (CEREAL)
F3: Subaward Budget
A4: Entity: | B4: P | F4: Budget Assumptions:
A5: Program-Dept.: | B5: 20200 | F5: Inflation - Locally Purchased Goods/Services | G5: 1.04
A6: Funder-Grant: | B6: DOL425 | F6: Merit Based Increases for Staff | G6: 1.035
A7: Activity Code | B7: Account Code | C7: Country Code | D7: Subcontract Code | E7: Sub-budget Code | F7: BUDGET ITEM | G7: CATEGORY | H7: UNIT | I7: # of Units | J7: RATE/ UNIT | K7: YEAR 1 2022 | L7: # of Units | M7: YEAR 2 2023 | N7: # of Units | O7: YEAR 3 2024 | P7: # of Units | Q7: YEAR 4 2025 | R7: # of Units | S7: YEAR 5 2026 | T7: TOTAL CEREAL | U7: TOTAL COST SHARING | V7: PROJECT GRAND TOTAL
F8: Direct Labor
A9: SUBCEREAL | B9: 89050 | C9: MEX | D9: CEREAL | E9: CERPERPC | F9: Project Coordinator 50% | G9: Salaries | H9: Month | I9: 3 | J9: 1586 | K9: =I9*J9 -> 4758 | L9: 12 | M9: =L9*J9*$G$6 -> 19698 | N9: 12 | O9: =N9*J9*$G$6*$G$6 -> 20388 | P9: 12 | Q9: =P9*J9*$G$6*$G$6*$G$6 -> 21101 | R9: 2 | S9: =R9*J9*$G$6*$G$6*$G$6*$G$6 -> 3640 | T9: =SUM(K9+M9+O9+Q9+S9) -> 69585 | U9: 0 | V9: =SUM(T9:U9) -> 69585
A10: SUBCEREAL | B10: 89050 | C10: MEX | D10: CEREAL | E10: CERPERADM | F10: Administration 50% | G10: Salaries | H10: Month | I10: 3 | J10: 1458 | K10: =I10*J10 -> 4374 | L10: 12 | M10: =L10*J10*$G$6 -> 18108 | N10: 12 | O10: =N10*J10*$G$6*$G$6 -> 18742 | P10: 12 | Q10: =P10*J10*$G$6*$G$6*$G$6 -> 19398 | R10: 2 | S10: =R10*J10*$G$6*$G$6*$G$6*$G$6 -> 3346 | T10: =SUM(K10+M10+O10+Q10+S10) -> 63968 | U10: 0 | V10: =SUM(T10:U10) -> 63968
A11: SUBCEREAL | B11: 89050 | C11: MEX | D11: CEREAL | E11: CERPERIDV | F11: Institutional Development 50% | G11: Salaries | H11: Month | I11: 3 | J11: 1458 | K11: =I11*J11 -> 4374 | L11: 12 | M11: =L11*J11*$G$6 -> 18108 | N11: 12 | O11: =N11*J11*$G$6*$G$6 -> 18742 | P11: 12 | Q11: =P11*J11*$G$6*$G$6*$G$6 -> 19398 | R11: 2 | S11: =R11*J11*$G$6*$G$6*$G$6*$G$6 -> 3346 | T11: =SUM(K11+M11+O11+Q11+S11) -> 63968 | U11: 0 | V11: =SUM(T11:U11) -> 63968
A12: SUBCEREAL | B12: 89050 | C12: MEX | D12: CEREAL | E12: CERPERLEG | F12: Legal Coordinator 50% | G12: Salaries | H12: Month | I12: 3 | J12: 1458 | K12: =I12*J12 -> 4374 | L12: 12 | M12: =L12*J12*$G$6 -> 18108 | N12: 12 | O12: =N12*J12*$G$6*$G$6 -> 18742 | P12: 12 | Q12: =P12*J12*$G$6*$G$6*$G$6 -> 19398 | R12: 2 | S12: =R12*J12*$G$6*$G$6*$G$6*$G$6 -> 3346 | T12: =SUM(K12+M12+O12+Q12+S12) -> 63968 | U12: 0 | V12: =SUM(T12:U12) -> 63968
A13: SUBCEREAL | B13: 89050 | C13: MEX | D13: CEREAL | E13: CERPEROPC | F13: Organizational Processes Coordinator 50% | G13: Salaries | H13: Month | I13: 3 | J13: 1458 | K13: =I13*J13 -> 4374 | L13: 12 | M13: =L13*J13*$G$6 -> 18108 | N13: 12 | O13: =N13*J13*$G$6*$G$6 -> 18742 | P13: 12 | Q13: =P13*J13*$G$6*$G$6*$G$6 -> 19398 | R13: 2 | S13: =R13*J13*$G$6*$G$6*$G$6*$G$6 -> 3346 | T13: =SUM(K13+M13+O13+Q13+S13) -> 63968 | U13: 0 | V13: =SUM(T13:U13) -> 63968
A14: SUBCEREAL | B14: 89050 | C14: MEX | D14: CEREAL | E14: CERPEREDU | F14: Education Coordinator 50% | G14: Salaries | H14: Month | I14: 3 | J14: 1458 | K14: =I14*J14 -> 4374 | L14: 12 | M14: =L14*J14*$G$6 -> 18108 | N14: 12 | O14: =N14*J14*$G$6*$G$6 -> 18742 | P14: 12 | Q14: =P14*J14*$G$6*$G$6*$G$6 -> 19398 | S14: =R14*J14*$G$6*$G$6*$G$6*$G$6 -> 0 | T14: =SUM(K14+M14+O14+Q14+S14) -> 60622 | U14: 0 | V14: =SUM(T14:U14) -> 60622
A15: SUBCEREAL | B15: 89050 | C15: MEX | D15: CEREAL | E15: CERPERPRO | F15: Promotor 1 50% | G15: Salaries | H15: Month | I15: 2 | J15: 125 | K15: =I15*J15 -> 250 | L15: 12 | M15: =L15*J15*$G$6 -> 1553 | N15: 12 | O15: =N15*J15*$G$6*$G$6 -> 1607 | P15: 12 | Q15: =P15*J15*$G$6*$G$6*$G$6 -> 1663 | S15: =R15*J15*$G$6*$G$6*$G$6*$G$6 -> 0 | T15: =SUM(K15+M15+O15+Q15+S15) -> 5073 | U15: 0 | V15: =SUM(T15:U15) -> 5073
A16: SUBCEREAL | B16: 89050 | C16: MEX | D16: CEREAL | E16: CERPERPRO | F16: Promotor 2 50% | G16: Salaries | H16: Month | I16: 2 | J16: 125 | K16: =I16*J16 -> 250 | L16: 12 | M16: =L16*J16*$G$6 -> 1553 | N16: 12 | O16: =N16*J16*$G$6*$G$6 -> 1607 | P16: 12 | Q16: =P16*J16*$G$6*$G$6*$G$6 -> 1663 | S16: =R16*J16*$G$6*$G$6*$G$6*$G$6 -> 0 | T16: =SUM(K16+M16+O16+Q16+S16) -> 5073 | U16: 0 | V16: =SUM(T16:U16) -> 5073
A17: SUBCEREAL | B17: 89050 | C17: MEX | D17: CEREAL | E17: CERPERPRO | F17: Promotor 3 50% | G17: Salaries | H17: Month | I17: 2 | J17: 125 | K17: =I17*J17 -> 250 | L17: 12 | M17: =L17*J17*$G$6 -> 1553 | N17: 12 | O17: =N17*J17*$G$6*$G$6 -> 1607 | P17: 12 | Q17: =P17*J17*$G$6*$G$6*$G$6 -> 1663 | S17: =R17*J17*$G$6*$G$6*$G$6*$G$6 -> 0 | T17: =SUM(K17+M17+O17+Q17+S17) -> 5073 | U17: 0 | V17: =SUM(T17:U17) -> 5073
A18: SUBCEREAL | B18: 89050 | C18: MEX | D18: CEREAL | E18: CERPERPRO | F18: Promotor 4 50% | G18: Salaries | H18: Month | I18: 2 | J18: 125 | K18: =I18*J18 -> 250 | L18: 12 | M18: =L18*J18*$G$6 -> 1553 | N18: 12 | O18: =N18*J18*$G$6*$G$6 -> 1607 | P18: 12 | Q18: =P18*J18*$G$6*$G$6*$G$6 -> 1663 | S18: =R18*J18*$G$6*$G$6*$G$6*$G$6 -> 0 | T18: =SUM(K18+M18+O18+Q18+S18) -> 5073 | U18: 0 | V18: =SUM(T18:U18) -> 5073
F20: Subtotal Direct Labor | K20: =SUM(K9:K19) -> 27628 | M20: =SUM(M9:M19) -> 116450 | O20: =SUM(O9:O19) -> 120526 | Q20: =SUM(Q9:Q19) -> 124743 | S20: =SUM(S9:S19) -> 17024 | T20: =SUM(T9:T19) -> 406371 | U20: =SUM(U9:U19) -> 0 | V20: =SUM(V9:V19) -> 406371
F22: Subtotal Travel | K22: =SUM(K21:K21) -> 0 | M22: =SUM(M21:M21) -> 0 | O22: =SUM(O21:O21) -> 0 | Q22: =SUM(Q21:Q21) -> 0 | S22: =SUM(S21:S21) -> 0 | T22: =SUM(T21:T21) -> 0 | U22: =SUM(U21:U21) -> 0 | V22: =SUM(V21:V21) -> 0
F23: Supplies & Office Expenses
A24: SUBCEREAL | B24: 89050 | C24: MEX | D24: CEREAL | E24: CERDESK | F24: Desktop computers, laptops and software | G24: Supplies | H24: Unit | I24: 4 | J24: 1000 | K24: =I24*J24 -> 4000 | L24: 0 | M24: =L24*J24*$G$5 -> 0 | N24: 0 | O24: =N24*J24*$G$5*$G$5 -> 0 | P24: 0 | Q24: =P24*J24*$G$5*$G$5*$G$5 -> 0 | R24: 0 | S24: =R24*J24*$G$5*$G$5*$G$5*$G$5 -> 0 | T24: =K24+M24+O24+Q24+S24 -> 4000 | U24: 0 | V24: =SUM(T24:U24) -> 4000
A25: SUBCEREAL | B25: 89050 | C25: MEX | D25: CEREAL | E25: CERMEET | F25: Meeting Expenses | G25: Supplies | H25: Year | I25: 1 | J25: 1000 | K25: =I25*J25 -> 1000 | L25: 1 | M25: =L25*J25*$G$5 -> 1040 | N25: 1 | O25: =N25*J25*$G$5*$G$5 -> 1082 | P25: 1 | Q25: =P25*J25*$G$5*$G$5*$G$5 -> 1125 | R25: 0.25 | S25: =R25*J25*$G$5*$G$5*$G$5*$G$5 -> 292 | T25: =K25+M25+O25+Q25+S25 -> 4539 | U25: 0 | V25: =SUM(T25:U25) -> 4539
A26: SUBCEREAL | B26: 89050 | C26: MEX | D26: CEREAL | E26: CERPHONE | F26: Phones | G26: Supplies | H26: Unit | I26: 4 | J26: 300 | K26: =I26*J26 -> 1200 | L26: 0 | M26: =L26*J26*$G$5 -> 0 | N26: 0 | O26: =N26*J26*$G$5*$G$5 -> 0 | P26: 0 | Q26: =P26*J26*$G$5*$G$5*$G$5 -> 0 | R26: 0 | S26: =R26*J26*$G$5*$G$5*$G$5*$G$5 -> 0 | T26: =K26+M26+O26+Q26+S26 -> 1200 | U26: 0 | V26: =SUM(T26:U26) -> 1200
A27: SUBCEREAL | B27: 89050 | C27: MEX | D27: CEREAL | E27: CERMATLS | F27: Stationary / Printing Materials | G27: Supplies | H27: Year | I27: 1 | J27: 900 | K27: =I27*J27 -> 900 | L27: 1 | M27: =L27*J27*$G$5 -> 936 | N27: 1 | O27: =N27*J27*$G$5*$G$5 -> 973 | P27: 1 | Q27: =P27*J27*$G$5*$G$5*$G$5 -> 1012 | R27: 0.25 | S27: =R27*J27*$G$5*$G$5*$G$5*$G$5 -> 263 | T27: =K27+M27+O27+Q27+S27 -> 4084 | U27: 0 | V27: =SUM(T27:U27) -> 4084
A28: SUBCEREAL | B28: 89050 | C28: MEX | D28: CEREAL | E28: CERCAMARA | F28: Camara Canon | G28: Supplies | H28: Set | I28: 1 | J28: 1000 | K28: =I28*J28 -> 1000 | L28: 0 | M28: =L28*J28*$G$5 -> 0 | N28: 0 | O28: =N28*J28*$G$5*$G$5 -> 0 | P28: 0 | Q28: =P28*J28*$G$5*$G$5*$G$5 -> 0 | R28: 0 | S28: =R28*J28*$G$5*$G$5*$G$5*$G$5 -> 0 | T28: =K28+M28+O28+Q28+S28 -> 1000 | U28: 0 | V28: =SUM(T28:U28) -> 1000
A29: SUBCEREAL | B29: 89050 | C29: MEX | D29: CEREAL | E29: CERPRINT | F29: Printer | G29: Supplies | H29: Set | I29: 1 | J29: 550 | K29: =I29*J29 -> 550 | L29: 0 | M29: =L29*J29*$G$5 -> 0 | N29: 0 | O29: =N29*J29*$G$5*$G$5 -> 0 | P29: 0 | Q29: =P29*J29*$G$5*$G$5*$G$5 -> 0 | R29: 0 | S29: =R29*J29*$G$5*$G$5*$G$5*$G$5 -> 0 | T29: =K29+M29+O29+Q29+S29 -> 550 | U29: 0 | V29: =SUM(T29:U29) -> 550
A30: SUBCEREAL | B30: 89050 | C30: MEX | D30: CEREAL | E30: CERSPEAKER | F30: Speaker System | G30: Supplies | H30: Set | I30: 1 | J30: 250 | K30: =I30*J30 -> 250 | L30: 0 | M30: =L30*J30*$G$5 -> 0 | N30: 0 | O30: =N30*J30*$G$5*$G$5 -> 0 | P30: 0 | Q30: =P30*J30*$G$5*$G$5*$G$5 -> 0 | R30: 0 | S30: =R30*J30*$G$5*$G$5*$G$5*$G$5 -> 0 | T30: =K30+M30+O30+Q30+S30 -> 250 | U30: 0 | V30: =SUM(T30:U30) -> 250
A31: SUBCEREAL | B31: 89050 | C31: MEX | D31: CEREAL | E31: CERBANK | F31: Banking and cash handling fees | G31: Office Expenses | H31: Month | I31: 3 | J31: 40 | K31: =I31*J31 -> 120 | L31: 12 | M31: =L31*J31*$G$5 -> 499 | N31: 12 | O31: =N31*J31*$G$5*$G$5 -> 519 | P31: 12 | Q31: =P31*J31*$G$5*$G$5*$G$5 -> 540 | R31: 2 | S31: =R31*J31*$G$5*$G$5*$G$5*$G$5 -> 94 | T31: =K31+M31+O31+Q31+S31 -> 1772 | U31: 0 | V31: =SUM(T31:U31) -> 1772
A32: SUBCEREAL | B32: 89050 | C32: MEX | D32: CEREAL | E32: CEREMAIL | F32: Email/Internet | G32: Office Expenses | H32: Month | I32: 3 | J32: 100 | K32: =I32*J32 -> 300 | L32: 12 | M32: =L32*J32*$G$5 -> 1248 | N32: 12 | O32: =N32*J32*$G$5*$G$5 -> 1298 | P32: 12 | Q32: =P32*J32*$G$5*$G$5*$G$5 -> 1350 | R32: 2 | S32: =R32*J32*$G$5*$G$5*$G$5*$G$5 -> 234 | T32: =K32+M32+O32+Q32+S32 -> 4430 | U32: 0 | V32: =SUM(T32:U32) -> 4430
A33: SUBCEREAL | B33: 89050 | C33: MEX | D33: CEREAL | E33: CERCOMMS | F33: Phones and Communication Costs | G33: Office Expenses | H33: Month | I33: 3 | J33: =(30*4) -> 120 | K33: =I33*J33 -> 360 | L33: 12 | M33: =L33*J33*$G$5 -> 1498 | N33: 12 | O33: =N33*J33*$G$5*$G$5 -> 1558 | P33: 12 | Q33: =P33*J33*$G$5*$G$5*$G$5 -> 1620 | R33: 2 | S33: =R33*J33*$G$5*$G$5*$G$5*$G$5 -> 281 | T33: =K33+M33+O33+Q33+S33 -> 5317 | U33: 0 | V33: =SUM(T33:U33) -> 5317
A34: SUBCEREAL | B34: 89050 | C34: MEX | D34: CEREAL | E34: CERRENT | F34: Office Rent | G34: Office Expenses | H34: Month | I34: 2 | J34: 1000 | K34: =I34*J34 -> 2000 | L34: 12 | M34: =L34*J34*$G$5 -> 12480 | N34: 12 | O34: =N34*J34*$G$5*$G$5 -> 12979 | P34: 12 | Q34: =P34*J34*$G$5*$G$5*$G$5 -> 13498 | R34: 2 | S34: =R34*J34*$G$5*$G$5*$G$5*$G$5 -> 2340 | T34: =K34+M34+O34+Q34+S34 -> 43297 | U34: 0 | V34: =SUM(T34:U34) -> 43297
A35: SUBCEREAL | B35: 89050 | C35: MEX | D35: CEREAL | E35: CEREQUIP | F35: Equipment and office repairs and maintenance | G35: Office Expenses | H35: Month | I35: 0 | J35: 250 | K35: =I35*J35 -> 0 | L35: 3 | M35: =L35*J35*$G$5 -> 780 | N35: 3 | O35: =N35*J35*$G$5*$G$5 -> 811 | P35: 3 | Q35: =P35*J35*$G$5*$G$5*$G$5 -> 844 | R35: 1 | S35: =R35*J35*$G$5*$G$5*$G$5*$G$5 -> 292 | T35: =K35+M35+O35+Q35+S35 -> 2727 | U35: 0 | V35: =SUM(T35:U35) -> 2727
A36: SUBCEREAL | B36: 89050 | C36: MEX | D36: CEREAL | E36: CERINSUR | F36: Insurance | G36: Office Expenses | H36: Year | I36: 1 | J36: 250 | K36: =I36*J36 -> 250 | L36: 1 | M36: =L36*J36*$G$5 -> 260 | N36: 1 | O36: =N36*J36*$G$5*$G$5 -> 270 | P36: 1 | Q36: =P36*J36*$G$5*$G$5*$G$5 -> 281 | R36: 0.25 | S36: =R36*J36*$G$5*$G$5*$G$5*$G$5 -> 73 | T36: =K36+M36+O36+Q36+S36 -> 1134 | U36: 0 | V36: =SUM(T36:U36) -> 1134
A37: SUBCEREAL | B37: 89050 | C37: MEX | D37: CEREAL | E37: CERSUPPLY | F37: Offices supplies | G37: Office Expenses | H37: Year | I37: 1 | J37: 250 | K37: =I37*J37 -> 250 | L37: 1 | M37: =L37*J37*$G$5 -> 260 | N37: 1 | O37: =N37*J37*$G$5*$G$5 -> 270 | P37: 1 | Q37: =P37*J37*$G$5*$G$5*$G$5 -> 281 | R37: 1 | S37: =R37*J37*$G$5*$G$5*$G$5*$G$5 -> 292 | T37: =K37+M37+O37+Q37+S37 -> 1353 | U37: 0 | V37: =SUM(T37:U37) -> 1353
F39: Subtotal Supplies & Office Expenses | K39: =SUM(K24:K37) -> 12180 | M39: =SUM(M24:M37) -> 19001 | O39: =SUM(O24:O37) -> 19760 | Q39: =SUM(Q24:Q37) -> 20551 | S39: =SUM(S24:S37) -> 4161 | T39: =SUM(T24:T37) -> 75653 | U39: =SUM(U24:U37) -> 0 | V39: =SUM(V24:V37) -> 75653
F40: The above is only for percentage calculations for the below outcomes
F41: Outcome 1: WO advance issues surrounding substantive equality, including gender proportionality in leadership and participation in key activities, within their institutions
F42: Activities/Costs
F43: Personnel & Fringe (40% of Direct Labor line item) | G43: Outcome1 | H43: Unit | I43: =$K$20 -> 27628 | J43: 0.4 | K43: =I43*J43 -> 11051 | L43: =$M$20 -> 116450 | M43: =L43*J43 -> 46580 | N43: =$O$20 -> 120526 | O43: =N43*J43 -> 48210 | P43: =$Q$20 -> 124743 | Q43: =P43*J43 -> 49897 | R43: =$S$20 -> 17024 | S43: =R43*J43 -> 6810 | T43: =K43+M43+O43+Q43+S43 -> 162548 | U43: 0 | V43: =SUM(T43:U43) -> 162548
...
