Workbook
Name \A: #REF!
Name \A: #REF!
Name \A: #REF!
Name \P: #REF!
Name \P: #REF!
Name \P: #REF!
Name \S: #REF!
Name \S: #REF!
Name \S: #REF!
Name _______sho1: '[3]Detailed Budget-SAVE'!#REF!
Name _______sho1: '[3]Detailed Budget-SAVE'!#REF!
Name _______sho1: '[3]Detailed Budget-SAVE'!#REF!
Name __2DAI_1: #N/A
Name __3FEE: #N/A
Name __AFP1: #N/A
Name __AFP2: #N/A
Name __AFP3: #N/A
Name __AFP4: #N/A
Name __AMP1: #N/A
Name __AMP2: #N/A
Name __AMP3: #N/A
Name __AMP4: #N/A
Name __DAI4: #N/A
Name __EES1: #N/A
Name __EES2: #N/A
Name __EES3: #N/A
Name __EES4: #N/A
Name __EXT1: #N/A
Name __EXT2: #N/A
Name __EXT3: #N/A
Name __EXT4: #N/A
Name __FCP1: #N/A
Name __FCP2: #N/A
Name __FCP3: #N/A
Name __FCP4: #N/A
Name __FRI1: #N/A
Name __FRI4: #N/A
Name __HRA1: #N/A
Name __HRA2: #N/A
Name __HRA3: #N/A
Name __HRA4: #N/A
Name __inf1: #REF!
Name __LT4: [4]Parameters!$B$40
Name __ODC1: #N/A
Name __ODC2: #N/A
Name __POL1: #N/A
Name __POL2: #N/A
Name __POL3: #N/A
Name __POL4: #N/A
Name __TOT1: #N/A
Name __TOT2: #N/A
Name __TRV1: #N/A
Name __TRV2: #N/A
Name _060: #REF!
Name _1_1: #REF!
Name _13th_and_14th_month: [5]Parameters!$D$62
Name _2_1034: #REF!
Name _2DAI_1: #N/A
Name _3_1440: #REF!
Name _3FEE: #N/A

Sheet USDA Budget Summary
A1: C-1
A2: Proposed Budget Summary
A4: Program (FFPr or MGD): | B4: FFPr
A5: Country of Operation: | B5: Nigeria (Non-priority country)
A6: Implementing Organization: | B6: Partners of the Americas Inc.
A7: Fiscal Year: | B7: 2025
A8: Agreement Number: | B8: USDA-FAS-10.606-0700-25(000)
A10: Total Amount of Federal Funds Requested
A11: Funding Source (FAS for MGD) (CCC for FFPr) | B11: Funding Year | C11: Commodity Cost | D11: Freight Cost | E11: Administrative Costs (cash portion) | F11: Total Federal Funding Obligated
B12: 2025 | C12: 20610000 | D12: 4750000 | E12: 1000000 | F12: =E12+D12+C12 -> 26360000
A14: Project Operating Budget
A15: Expense Type | B15: Monetization Proceeds (FFPr Only) | C15: FAS or CCC Funds (CCC is Admin Only) | D15: Cost Share | E15: Total w/out Cost Share | F15: Total w/Cost Share
A16: Administration
A17: Salaries/Personnel | B17: ='Program Budget'!V32-C17 -> 98891.649 | C17: 264655 | D17: ='Program Budget'!W32 -> 0 | E17: =B17+C17 -> 363546.65 | F17: =B17+C17+D17 -> 363546.65
A18: Benefits | B18: ='Program Budget'!V38-C18 -> 26906.721 | C18: 68781 | D18: ='Program Budget'!W38 -> 0 | E18: =B18+C18 -> 95687.721 | F18: =B18+C18+D18 -> 95687.721
A19: Travel | B19: ='Program Budget'!V58-C19 -> 180726.56 | C19: 60136 | D19: ='Program Budget'!W58 -> 0 | E19: =B19+C19 -> 240862.56 | F19: =B19+C19+D19 -> 240862.56
A20: Professional Services/Contractual | B20: ='Program Budget'!V84-C20 -> 641325.78 | C20: 351567.22 | D20: ='Program Budget'!W84 -> 0 | E20: =B20+C20 -> 992893 | F20: =B20+C20+D20 -> 992893
A21: Equipment | B21: ='Program Budget'!V89-C21 -> 0 | C21: 60000 | D21: ='Program Budget'!W89 -> 0 | E21: =B21+C21 -> 60000 | F21: =B21+C21+D21 -> 60000
A22: Office | B22: ='Program Budget'!V105-C22 -> 229220.93 | C22: 47105 | D22: ='Program Budget'!W105 -> 0 | E22: =B22+C22 -> 276325.93 | F22: =B22+C22+D22 -> 276325.93
A23: Supplies | B23: ='Program Budget'!V114-C23 -> 5323.0325 | C23: 10346 | D23: ='Program Budget'!W114 -> 0 | E23: =B23+C23 -> 15669.032 | F23: =B23+C23+D23 -> 15669.032
A24: Other | B24: ='Program Budget'!V126-C24 -> 64793.809 | C24: 6975 | D24: 0 | E24: =B24+C24 -> 71768.809 | F24: =B24+C24+D24 -> 71768.809
A25: Total Administration | B25: =SUM(B17:B24) -> 1247188.5 | C25: =SUM(C17:C24) -> 869565.22 | D25: =SUM(D17:D24) -> 0 | E25: =SUM(E17:E24) -> 2116753.7 | F25: =SUM(F17:F24) -> 2116753.7
A27: Activities
A28: Activity 1: Increase Agricultural Productivity & Trade through Livestock Production | B28: ='Program Budget'!V183 -> 3439474 | C28: 0 | D28: ='Program Budget'!W183 -> 40000 | E28: =B28+C28 -> 3439474 | F28: =B28+C28+D28 -> 3479474
A29: Activity 2: Improve Trade Finance Capacity to Increase US Exports to Nigeria | B29: ='Program Budget'!V263 -> 4282400.9 | C29: 0 | D29: ='Program Budget'!W263 -> 307715.54 | E29: =B29+C29 -> 4282400.9 | F29: =B29+C29+D29 -> 4590116.5
A30: Activity 3: Expand Trade by Reducing Non-Tariff Trade Barriers | B30: ='Program Budget'!V315 -> 1095119.7 | C30: 0 | D30: =ROUND('Program Budget'!W315,0) -> 0 | E30: =B30+C30 -> 1095119.7 | F30: =B30+C30+D30 -> 1095119.7
A31: Total Activities | B31: =SUM(B28:B30) -> 8816994.6 | C31: =SUM(C28:C30) -> 0 | D31: =SUM(D28:D30) -> 347715.54 | E31: =SUM(E28:E30) -> 8816994.6 | F31: =SUM(F28:F30) -> 9164710.1
A33: Commodity and Food Purchases (N/A to FFPr)
A34: Commodity Procurement | B34: 0 | C34: 0 | D34: 0 | E34: =B34+C34 -> 0 | F34: =B34+C34+D34 -> 0
A35: Food Vouchers (N/A to MGD)
A36: Cash Transfers (N/A to MGD)
A37: Total Commodity Procurement | B37: =SUM(B34:B36) -> 0 | C37: =SUM(C34:C36) -> 0 | D37: =SUM(D34:D36) -> 0 | E37: =SUM(E34:E36) -> 0 | F37: =SUM(F34:F36) -> 0
A39: ITSH (N/A to FFPr)
A40: Salaries | B40: 0 | C40: 0 | D40: 0 | E40: =B40+C40 -> 0 | F40: =B40+C40+D40 -> 0
A41: Benefits | B41: 0 | C41: 0 | D41: 0 | E41: =B41+C41 -> 0 | F41: =B41+C41+D41 -> 0
A42: Transportation | B42: 0 | C42: 0 | D42: 0 | E42: =B42+C42 -> 0 | F42: =B42+C42+D42 -> 0
A43: Professional Services | B43: 0 | C43: 0 | D43: =0 -> 0 | E43: =B43+C43 -> 0 | F43: =B43+C43+D43 -> 0
A44: Warehouse | B44: 0 | C44: 0 | D44: 0 | E44: =B44+C44 -> 0 | F44: =B44+C44+D44 -> 0
A45: Supplies | B45: 0 | C45: 0 | D45: 0 | E45: =B45+C45 -> 0 | F45: =B45+C45+D45 -> 0
A46: Other | B46: 0 | C46: 0 | D46: 0 | E46: =B46+C46 -> 0 | F46: =B46+C46+D46 -> 0
...

Sheet Detailed Budget
A2: Item | B2: Type of Unit | C2: Year 1 | G2: Year 2 | K2: Year 3 | O2: Year 4 | S2: Year 5 | W2: Total
C3: Cost | D3: Quantity | E3: Percent Allocated | F3: Total | G3: Cost | H3: Quantity | I3: Percent Allocated | J3: Total | K3: Cost | L3: Quantity | M3: Percent Allocated | N3: Total | O3: Cost | P3: Quantity | Q3: Percent Allocated | R3: Total | S3: Cost | T3: Quantity | U3: Percent Allocated | V3: Total
A4: Direct Costs
A5: Salaries
A6: USN/TCN Staff
A7: None | F7: =C7*D7*E7 -> 0 | J7: =G7*H7*I7 -> 0 | N7: =K7*L7*M7 -> 0 | R7: =O7*P7*Q7 -> 0 | V7: =S7*T7*U7 -> 0 | W7: =F7+J7+N7+R7+V7 -> 0
A8: Total: Expatriate Salaries & Wages | F8: =SUM(F7:F7) -> 0 | J8: =SUM(J7:J7) -> 0 | N8: =SUM(N7:N7) -> 0 | R8: =SUM(R7:R7) -> 0 | V8: =SUM(V7:V7) -> 0 | W8: =+F8+J8+N8+R8+V8 -> 0
A9: CNN Staff
A10: ='Program Budget'!D12 -> Key Personnel: Chief of Party | B10: ='Program Budget'!F12 -> Month | C10: ='Program Budget'!H12 -> 9583.3333 | D10: ='Program Budget'!G12 -> 11 | E10: ='Program Budget'!E12+'Activity 1'!E10+'Activity 2'!E10+'Activity 3'!E10 -> 1 | F10: =C10*D10*E10 -> 105416.67 | G10: =C10*1.05 -> 10062.5 | H10: ='Program Budget'!K12 -> 12 | I10: =Admin!I10+'Activity 1'!I10+'Activity 2'!I10+'Activity 3'!I10 -> 1 | J10: =G10*H10*I10 -> 120750 | K10: =G10*1.05 -> 10565.625 | L10: ='Program Budget'!N12 -> 12 | M10: =Admin!M10+'Activity 1'!M10+'Activity 2'!M10+'Activity 3'!M10 -> 1 | N10: =K10*L10*M10 -> 126787.5 | O10: =K10*1.05 -> 11093.906 | P10: ='Program Budget'!Q12 -> 12 | Q10: =Admin!Q10+'Activity 1'!Q10+'Activity 2'!Q10+'Activity 3'!Q10 -> 1 | R10: =O10*P10*Q10 -> 133126.88 | S10: =O10*1.05 -> 11648.602 | T10: ='Program Budget'!T12 -> 0 | U10: =Admin!U10+'Activity 1'!U10+'Activity 2'!U10+'Activity 3'!U10 -> 0 | V10: =S10*T10*U10 -> 0 | W10: =F10+J10+N10+R10+V10 -> 486081.04
A11: ='Program Budget'!D13 -> Technical Director | B11: ='Program Budget'!F13 -> Month | C11: ='Program Budget'!H13 -> 3500 | D11: ='Program Budget'!G13 -> 9 | E11: ='Program Budget'!E13+'Activity 1'!E11+'Activity 2'!E11+'Activity 3'!E11 -> 1 | F11: =C11*D11*E11 -> 31500 | G11: =C11*1.05 -> 3675 | H11: ='Program Budget'!K13 -> 12 | I11: =Admin!I11+'Activity 1'!I11+'Activity 2'!I11+'Activity 3'!I11 -> 1 | J11: =G11*H11*I11 -> 44100 | K11: =G11*1.05 -> 3858.75 | L11: ='Program Budget'!N13 -> 12 | M11: =Admin!M11+'Activity 1'!M11+'Activity 2'!M11+'Activity 3'!M11 -> 1 | N11: =K11*L11*M11 -> 46305 | O11: =K11*1.05 -> 4051.6875 | P11: ='Program Budget'!Q13 -> 12 | Q11: =Admin!Q11+'Activity 1'!Q11+'Activity 2'!Q11+'Activity 3'!Q11 -> 1 | R11: =O11*P11*Q11 -> 48620.25 | S11: =O11*1.05 -> 4254.2719 | T11: ='Program Budget'!T13 -> 0 | U11: =Admin!U11+'Activity 1'!U11+'Activity 2'!U11+'Activity 3'!U11 -> 0 | V11: =S11*T11*U11 -> 0 | W11: =F11+J11+N11+R11+V11 -> 170525.25
A12: ='Program Budget'!D14 -> Technical Lead - Activity 2 US Exports | B12: ='Program Budget'!F14 -> Month | C12: ='Program Budget'!H14 -> 2833.3333 | D12: ='Program Budget'!G14 -> 8 | E12: ='Program Budget'!E14+'Activity 1'!E12+'Activity 2'!E12+'Activity 3'!E12 -> 1 | F12: =C12*D12*E12 -> 22666.667 | G12: =C12*1.05 -> 2975 | H12: ='Program Budget'!K14 -> 12 | I12: =Admin!I12+'Activity 1'!I12+'Activity 2'!I12+'Activity 3'!I12 -> 1 | J12: =G12*H12*I12 -> 35700 | K12: =G12*1.05 -> 3123.75 | L12: ='Program Budget'!N14 -> 12 | M12: =Admin!M12+'Activity 1'!M12+'Activity 2'!M12+'Activity 3'!M12 -> 1 | N12: =K12*L12*M12 -> 37485 | O12: =K12*1.05 -> 3279.9375 | P12: ='Program Budget'!Q14 -> 12 | Q12: =Admin!Q12+'Activity 1'!Q12+'Activity 2'!Q12+'Activity 3'!Q12 -> 1 | R12: =O12*P12*Q12 -> 39359.25 | S12: =O12*1.05 -> 3443.9344 | T12: ='Program Budget'!T14 -> 0 | U12: =Admin!U12+'Activity 1'!U12+'Activity 2'!U12+'Activity 3'!U12 -> 0 | V12: =S12*T12*U12 -> 0 | W12: =F12+J12+N12+R12+V12 -> 135210.92
A13: ='Program Budget'!D15 -> Technical Lead - Activity 2 Access to Finance Specialist | B13: ='Program Budget'!F15 -> Month | C13: ='Program Budget'!H15 -> 2833.3333 | D13: ='Program Budget'!G15 -> 8 | E13: ='Program Budget'!E15+'Activity 1'!E13+'Activity 2'!E13+'Activity 3'!E13 -> 1 | F13: =C13*D13*E13 -> 22666.667 | G13: =C13*1.05 -> 2975 | H13: ='Program Budget'!K15 -> 12 | I13: =Admin!I13+'Activity 1'!I13+'Activity 2'!I13+'Activity 3'!I13 -> 1 | J13: =G13*H13*I13 -> 35700 | K13: =G13*1.05 -> 3123.75 | L13: ='Program Budget'!N15 -> 12 | M13: =Admin!M13+'Activity 1'!M13+'Activity 2'!M13+'Activity 3'!M13 -> 1 | N13: =K13*L13*M13 -> 37485 | O13: =K13*1.05 -> 3279.9375 | P13: ='Program Budget'!Q15 -> 12 | Q13: =Admin!Q13+'Activity 1'!Q13+'Activity 2'!Q13+'Activity 3'!Q13 -> 1 | R13: =O13*P13*Q13 -> 39359.25 | S13: =O13*1.05 -> 3443.9344 | T13: ='Program Budget'!T15 -> 0 | U13: =Admin!U13+'Activity 1'!U13+'Activity 2'!U13+'Activity 3'!U13 -> 0 | V13: =S13*T13*U13 -> 0 | W13: =F13+J13+N13+R13+V13 -> 135210.92
A14: ='Program Budget'!D16 -> Communications/Strategic Partnerships Manager | B14: ='Program Budget'!F16 -> Month | C14: ='Program Budget'!H16 -> 2666.6667 | D14: ='Program Budget'!G16 -> 8 | E14: ='Program Budget'!E16+'Activity 1'!E14+'Activity 2'!E14+'Activity 3'!E14 -> 1 | F14: =C14*D14*E14 -> 21333.333 | G14: =C14*1.05 -> 2800 | H14: ='Program Budget'!K16 -> 12 | I14: =Admin!I14+'Activity 1'!I14+'Activity 2'!I14+'Activity 3'!I14 -> 1 | J14: =G14*H14*I14 -> 33600 | K14: =G14*1.05 -> 2940 | L14: ='Program Budget'!N16 -> 12 | M14: =Admin!M14+'Activity 1'!M14+'Activity 2'!M14+'Activity 3'!M14 -> 1 | N14: =K14*L14*M14 -> 35280 | O14: =K14*1.05 -> 3087 | P14: ='Program Budget'!Q16 -> 12 | Q14: =Admin!Q14+'Activity 1'!Q14+'Activity 2'!Q14+'Activity 3'!Q14 -> 1 | R14: =O14*P14*Q14 -> 37044 | S14: =O14*1.05 -> 3241.35 | T14: ='Program Budget'!T16 -> 0 | U14: =Admin!U14+'Activity 1'!U14+'Activity 2'!U14+'Activity 3'!U14 -> 0 | V14: =S14*T14*U14 -> 0 | W14: =F14+J14+N14+R14+V14 -> 127257.33
A15: ='Program Budget'!D17 -> M&E Director | B15: ='Program Budget'!F17 -> Month | C15: ='Program Budget'!H17 -> 3500 | D15: ='Program Budget'!G17 -> 10 | E15: ='Program Budget'!E17+'Activity 1'!E15+'Activity 2'!E15+'Activity 3'!E15 -> 1 | F15: =C15*D15*E15 -> 35000 | G15: =C15*1.05 -> 3675 | H15: ='Program Budget'!K17 -> 12 | I15: =Admin!I15+'Activity 1'!I15+'Activity 2'!I15+'Activity 3'!I15 -> 1 | J15: =G15*H15*I15 -> 44100 | K15: =G15*1.05 -> 3858.75 | L15: ='Program Budget'!N17 -> 12 | M15: =Admin!M15+'Activity 1'!M15+'Activity 2'!M15+'Activity 3'!M15 -> 1 | N15: =K15*L15*M15 -> 46305 | O15: =K15*1.05 -> 4051.6875 | P15: ='Program Budget'!Q17 -> 12 | Q15: =Admin!Q15+'Activity 1'!Q15+'Activity 2'!Q15+'Activity 3'!Q15 -> 1 | R15: =O15*P15*Q15 -> 48620.25 | S15: =O15*1.05 -> 4254.2719 | T15: ='Program Budget'!T17 -> 0 | U15: =Admin!U15+'Activity 1'!U15+'Activity 2'!U15+'Activity 3'!U15 -> 0 | V15: =S15*T15*U15 -> 0 | W15: =F15+J15+N15+R15+V15 -> 174025.25
A16: ='Program Budget'!D18 -> M&E Specialist | B16: ='Program Budget'!F18 -> Month | C16: ='Program Budget'!H18 -> 2000 | D16: ='Program Budget'!G18 -> 8 | E16: ='Program Budget'!E18+'Activity 1'!E16+'Activity 2'!E16+'Activity 3'!E16 -> 1 | F16: =C16*D16*E16 -> 16000 | G16: =C16*1.05 -> 2100 | H16: ='Program Budget'!K18 -> 12 | I16: =Admin!I16+'Activity 1'!I16+'Activity 2'!I16+'Activity 3'!I16 -> 1 | J16: =G16*H16*I16 -> 25200 | K16: =G16*1.05 -> 2205 | L16: ='Program Budget'!N18 -> 12 | M16: =Admin!M16+'Activity 1'!M16+'Activity 2'!M16+'Activity 3'!M16 -> 1 | N16: =K16*L16*M16 -> 26460 | O16: =K16*1.05 -> 2315.25 | P16: ='Program Budget'!Q18 -> 12 | Q16: =Admin!Q16+'Activity 1'!Q16+'Activity 2'!Q16+'Activity 3'!Q16 -> 1 | R16: =O16*P16*Q16 -> 27783 | S16: =O16*1.05 -> 2431.0125 | T16: ='Program Budget'!T18 -> 0 | U16: =Admin!U16+'Activity 1'!U16+'Activity 2'!U16+'Activity 3'!U16 -> 0 | V16: =S16*T16*U16 -> 0 | W16: =F16+J16+N16+R16+V16 -> 95443
A17: ='Program Budget'!D19 -> Key Personnel: Finance & Administration (F&A) Director | B17: ='Program Budget'!F19 -> Month | C17: ='Program Budget'!H19 -> 3500 | D17: ='Program Budget'!G19 -> 10 | E17: ='Program Budget'!E19+'Activity 1'!E17+'Activity 2'!E17+'Activity 3'!E17 -> 1 | F17: =C17*D17*E17 -> 35000 | G17: =C17*1.05 -> 3675 | H17: ='Program Budget'!K19 -> 12 | I17: =Admin!I17+'Activity 1'!I17+'Activity 2'!I17+'Activity 3'!I17 -> 1 | J17: =G17*H17*I17 -> 44100 | K17: =G17*1.05 -> 3858.75 | L17: ='Program Budget'!N19 -> 12 | M17: =Admin!M17+'Activity 1'!M17+'Activity 2'!M17+'Activity 3'!M17 -> 1 | N17: =K17*L17*M17 -> 46305 | O17: =K17*1.05 -> 4051.6875 | P17: ='Program Budget'!Q19 -> 12 | Q17: =Admin!Q17+'Activity 1'!Q17+'Activity 2'!Q17+'Activity 3'!Q17 -> 1 | R17: =O17*P17*Q17 -> 48620.25 | S17: =O17*1.05 -> 4254.2719 | T17: ='Program Budget'!T19 -> 0 | U17: =Admin!U17+'Activity 1'!U17+'Activity 2'!U17+'Activity 3'!U17 -> 0 | V17: =S17*T17*U17 -> 0 | W17: =F17+J17+N17+R17+V17 -> 174025.25
A18: ='Program Budget'!D20 -> Accountant | B18: ='Program Budget'!F20 -> Month | C18: ='Program Budget'!H20 -> 2000 | D18: ='Program Budget'!G20 -> 8 | E18: ='Program Budget'!E20+'Activity 1'!E18+'Activity 2'!E18+'Activity 3'!E18 -> 1 | F18: =C18*D18*E18 -> 16000 | G18: =C18*1.05 -> 2100 | H18: ='Program Budget'!K20 -> 12 | I18: =Admin!I18+'Activity 1'!I18+'Activity 2'!I18+'Activity 3'!I18 -> 1 | J18: =G18*H18*I18 -> 25200 | K18: =G18*1.05 -> 2205 | L18: ='Program Budget'!N20 -> 12 | M18: =Admin!M18+'Activity 1'!M18+'Activity 2'!M18+'Activity 3'!M18 -> 1 | N18: =K18*L18*M18 -> 26460 | O18: =K18*1.05 -> 2315.25 | P18: ='Program Budget'!Q20 -> 12 | Q18: =Admin!Q18+'Activity 1'!Q18+'Activity 2'!Q18+'Activity 3'!Q18 -> 1 | R18: =O18*P18*Q18 -> 27783 | S18: =O18*1.05 -> 2431.0125 | T18: ='Program Budget'!T20 -> 0 | U18: =Admin!U18+'Activity 1'!U18+'Activity 2'!U18+'Activity 3'!U18 -> 0 | V18: =S18*T18*U18 -> 0 | W18: =F18+J18+N18+R18+V18 -> 95443
A19: ='Program Budget'!D21 -> Administration/ HR Manager | B19: ='Program Budget'!F21 -> Month | C19: ='Program Budget'!H21 -> 2666.6667 | D19: ='Program Budget'!G21 -> 10 | E19: ='Program Budget'!E21+'Activity 1'!E19+'Activity 2'!E19+'Activity 3'!E19 -> 1 | F19: =C19*D19*E19 -> 26666.667 | G19: =C19*1.05 -> 2800 | H19: ='Program Budget'!K21 -> 12 | I19: =Admin!I19+'Activity 1'!I19+'Activity 2'!I19+'Activity 3'!I19 -> 1 | J19: =G19*H19*I19 -> 33600 | K19: =G19*1.05 -> 2940 | L19: ='Program Budget'!N21 -> 12 | M19: =Admin!M19+'Activity 1'!M19+'Activity 2'!M19+'Activity 3'!M19 -> 1 | N19: =K19*L19*M19 -> 35280 | O19: =K19*1.05 -> 3087 | P19: ='Program Budget'!Q21 -> 12 | Q19: =Admin!Q19+'Activity 1'!Q19+'Activity 2'!Q19+'Activity 3'!Q19 -> 1 | R19: =O19*P19*Q19 -> 37044 | S19: =O19*1.05 -> 3241.35 | T19: ='Program Budget'!T21 -> 0 | U19: =Admin!U19+'Activity 1'!U19+'Activity 2'!U19+'Activity 3'!U19 -> 0 | V19: =S19*T19*U19 -> 0 | W19: =F19+J19+N19+R19+V19 -> 132590.67
A20: ='Program Budget'!D22 -> Grants & Contracts Manager | B20: ='Program Budget'!F22 -> Month | C20: ='Program Budget'!H22 -> 2666.6667 | D20: ='Program Budget'!G22 -> 9 | E20: ='Program Budget'!E22+'Activity 1'!E20+'Activity 2'!E20+'Activity 3'!E20 -> 1 | F20: =C20*D20*E20 -> 24000 | G20: =C20*1.05 -> 2800 | H20: ='Program Budget'!K22 -> 12 | I20: =Admin!I20+'Activity 1'!I20+'Activity 2'!I20+'Activity 3'!I20 -> 1 | J20: =G20*H20*I20 -> 33600 | K20: =G20*1.05 -> 2940 | L20: ='Program Budget'!N22 -> 12 | M20: =Admin!M20+'Activity 1'!M20+'Activity 2'!M20+'Activity 3'!M20 -> 1 | N20: =K20*L20*M20 -> 35280 | O20: =K20*1.05 -> 3087 | P20: ='Program Budget'!Q22 -> 12 | Q20: =Admin!Q20+'Activity 1'!Q20+'Activity 2'!Q20+'Activity 3'!Q20 -> 1 | R20: =O20*P20*Q20 -> 37044 | S20: =O20*1.05 -> 3241.35 | T20: ='Program Budget'!T22 -> 0 | U20: =Admin!U20+'Activity 1'!U20+'Activity 2'!U20+'Activity 3'!U20 -> 0 | V20: =S20*T20*U20 -> 0 | W20: =F20+J20+N20+R20+V20 -> 129924
A21: ='Program Budget'!D23 -> Compliance & Procurement Specialist | B21: ='Program Budget'!F23 -> Month | C21: ='Program Budget'!H23 -> 2000 | D21: ='Program Budget'!G23 -> 9 | E21: ='Program Budget'!E23+'Activity 1'!E21+'Activity 2'!E21+'Activity 3'!E21 -> 1 | F21: =C21*D21*E21 -> 18000 | G21: =C21*1.05 -> 2100 | H21: ='Program Budget'!K23 -> 12 | I21: =Admin!I21+'Activity 1'!I21+'Activity 2'!I21+'Activity 3'!I21 -> 1 | J21: =G21*H21*I21 -> 25200 | K21: =G21*1.05 -> 2205 | L21: ='Program Budget'!N23 -> 12 | M21: =Admin!M21+'Activity 1'!M21+'Activity 2'!M21+'Activity 3'!M21 -> 1 | N21: =K21*L21*M21 -> 26460 | O21: =K21*1.05 -> 2315.25 | P21: ='Program Budget'!Q23 -> 12 | Q21: =Admin!Q21+'Activity 1'!Q21+'Activity 2'!Q21+'Activity 3'!Q21 -> 1 | R21: =O21*P21*Q21 -> 27783 | S21: =O21*1.05 -> 2431.0125 | T21: ='Program Budget'!T23 -> 0 | U21: =Admin!U21+'Activity 1'!U21+'Activity 2'!U21+'Activity 3'!U21 -> 0 | V21: =S21*T21*U21 -> 0 | W21: =F21+J21+N21+R21+V21 -> 97443
A22: ='Program Budget'!D24 -> Driver | B22: ='Program Budget'!F24 -> Month | C22: ='Program Budget'!H24 -> 500 | D22: ='Program Budget'!G24 -> 7 | E22: ='Program Budget'!E24+'Activity 1'!E22+'Activity 2'!E22+'Activity 3'!E22 -> 1 | F22: =C22*D22*E22 -> 3500 | G22: =C22*1.05 -> 525 | H22: ='Program Budget'!K24 -> 12 | I22: =Admin!I22+'Activity 1'!I22+'Activity 2'!I22+'Activity 3'!I22 -> 1 | J22: =G22*H22*I22 -> 6300 | K22: =G22*1.05 -> 551.25 | L22: ='Program Budget'!N24 -> 12 | M22: =Admin!M22+'Activity 1'!M22+'Activity 2'!M22+'Activity 3'!M22 -> 1 | N22: =K22*L22*M22 -> 6615 | O22: =K22*1.05 -> 578.8125 | P22: ='Program Budget'!Q24 -> 12 | Q22: =Admin!Q22+'Activity 1'!Q22+'Activity 2'!Q22+'Activity 3'!Q22 -> 1 | R22: =O22*P22*Q22 -> 6945.75 | S22: =O22*1.05 -> 607.75313 | T22: ='Program Budget'!T24 -> 0 | U22: =Admin!U22+'Activity 1'!U22+'Activity 2'!U22+'Activity 3'!U22 -> 0 | V22: =S22*T22*U22 -> 0 | W22: =F22+J22+N22+R22+V22 -> 23360.75
A23: Total Local Salary Cost | F23: =SUM(F10:F22) -> 377750 | J23: =SUM(J10:J22) -> 507150 | N23: =SUM(N10:N22) -> 532507.5 | R23: =SUM(R10:R22) -> 559132.88 | V23: =SUM(V10:V22) -> 0 | W23: =SUM(W10:W22) -> 1976540.4 | Y23: =Admin!W23+'Activity 1'!W23+'Activity 2'!W23+'Activity 3'!W23 -> 1976540.4
A24: HQ Staff
A25: ='Program Budget'!D26 -> Senior Vice President of Programs | B25: ='Program Budget'!F26 -> Month | C25: ='Program Budget'!H26 -> 13500 | D25: ='Program Budget'!G26 -> 12 | E25: =Admin!E25+'Activity 1'!E25+'Activity 2'!E25+'Activity 3'!E25 -> 0.05 | F25: =C25*D25*E25 -> 8100 | G25: =C25*1.05 -> 14175 | H25: ='Program Budget'!K26 -> 12 | I25: =Admin!I25+'Activity 1'!I25+'Activity 2'!I25+'Activity 3'!I25 -> 0.05 | J25: =G25*H25*I25 -> 8505 | K25: =G25*1.05 -> 14883.75 | L25: ='Program Budget'!N26 -> 12 | M25: =Admin!M25+'Activity 1'!M25+'Activity 2'!M25+'Activity 3'!M25 -> 0.05 | N25: =K25*L25*M25 -> 8930.25 | O25: =K25*1.05 -> 15627.938 | P25: ='Program Budget'!Q26 -> 12 | Q25: =Admin!Q25+'Activity 1'!Q25+'Activity 2'!Q25+'Activity 3'!Q25 -> 0.05 | R25: =O25*P25*Q25 -> 9376.7625 | S25: =O25*1.05 -> 16409.334 | T25: ='Program Budget'!T26 -> 0 | U25: =Admin!U25+'Activity 1'!U25+'Activity 2'!U25+'Activity 3'!U25 -> 0 | V25: =S25*T25*U25 -> 0 | W25: =F25+J25+N25+R25+V25 -> 34912.012
A26: ='Program Budget'!D27 -> Senior Program Director | B26: ='Program Budget'!F27 -> Month | C26: ='Program Budget'!H27 -> 12500 | D26: ='Program Budget'!G27 -> 12 | E26: =Admin!E26+'Activity 1'!E26+'Activity 2'!E26+'Activity 3'!E26 -> 0.25 | F26: =C26*D26*E26 -> 37500 | G26: =C26*1.05 -> 13125 | H26: ='Program Budget'!K27 -> 12 | I26: =Admin!I26+'Activity 1'!I26+'Activity 2'!I26+'Activity 3'!I26 -> 0.25 | J26: =G26*H26*I26 -> 39375 | K26: =G26*1.05 -> 13781.25 | L26: ='Program Budget'!N27 -> 12 | M26: =Admin!M26+'Activity 1'!M26+'Activity 2'!M26+'Activity 3'!M26 -> 0.25 | N26: =K26*L26*M26 -> 41343.75 | O26: =K26*1.05 -> 14470.312 | P26: ='Program Budget'!Q27 -> 12 | Q26: =Admin!Q26+'Activity 1'!Q26+'Activity 2'!Q26+'Activity 3'!Q26 -> 0.25 | R26: =O26*P26*Q26 -> 43410.938 | S26: =O26*1.05 -> 15193.828 | T26: ='Program Budget'!T27 -> 0 | U26: =Admin!U26+'Activity 1'!U26+'Activity 2'!U26+'Activity 3'!U26 -> 0 | V26: =S26*T26*U26 -> 0 | W26: =F26+J26+N26+R26+V26 -> 161629.69
A27: ='Program Budget'!D28 -> Associate Director | B27: ='Program Budget'!F28 -> Month | C27: ='Program Budget'!H28 -> 7500 | D27: ='Program Budget'!G28 -> 12 | E27: =Admin!E27+'Activity 1'!E27+'Activity 2'!E27+'Activity 3'!E27 -> 1 | F27: =C27*D27*E27 -> 90000 | G27: =C27*1.05 -> 7875 | H27: ='Program Budget'!K28 -> 12 | I27: =Admin!I27+'Activity 1'!I27+'Activity 2'!I27+'Activity 3'!I27 -> 1 | J27: =G27*H27*I27 -> 94500 | K27: =G27*1.05 -> 8268.75 | L27: ='Program Budget'!N28 -> 12 | M27: =Admin!M27+'Activity 1'!M27+'Activity 2'!M27+'Activity 3'!M27 -> 1 | N27: =K27*L27*M27 -> 99225 | O27: =K27*1.05 -> 8682.1875 | P27: ='Program Budget'!Q28 -> 12 | Q27: =Admin!Q27+'Activity 1'!Q27+'Activity 2'!Q27+'Activity 3'!Q27 -> 1 | R27: =O27*P27*Q27 -> 104186.25 | S27: =O27*1.05 -> 9116.2969 | T27: ='Program Budget'!T28 -> 0 | U27: =Admin!U27+'Activity 1'!U27+'Activity 2'!U27+'Activity 3'!U27 -> 0 | V27: =S27*T27*U27 -> 0 | W27: =F27+J27+N27+R27+V27 -> 387911.25
A28: ='Program Budget'!D29 -> Compliance & Contracts Director | B28: ='Program Budget'!F29 -> Month | C28: ='Program Budget'!H29 -> 9166.6667 | D28: ='Program Budget'!G29 -> 12 | E28: =Admin!E28+'Activity 1'!E28+'Activity 2'!E28+'Activity 3'!E28 -> 0.25 | F28: =C28*D28*E28 -> 27500 | G28: =C28*1.05 -> 9625 | H28: ='Program Budget'!K29 -> 12 | I28: =Admin!I28+'Activity 1'!I28+'Activity 2'!I28+'Activity 3'!I28 -> 0.25 | J28: =G28*H28*I28 -> 28875 | K28: =G28*1.05 -> 10106.25 | L28: ='Program Budget'!N29 -> 12 | M28: =Admin!M28+'Activity 1'!M28+'Activity 2'!M28+'Activity 3'!M28 -> 0.25 | N28: =K28*L28*M28 -> 30318.75 | O28: =K28*1.05 -> 10611.562 | P28: ='Program Budget'!Q29 -> 12 | Q28: =Admin!Q28+'Activity 1'!Q28+'Activity 2'!Q28+'Activity 3'!Q28 -> 0.25 | R28: =O28*P28*Q28 -> 31834.688 | S28: =O28*1.05 -> 11142.141 | T28: ='Program Budget'!T29 -> 0 | U28: =Admin!U28+'Activity 1'!U28+'Activity 2'!U28+'Activity 3'!U28 -> 0 | V28: =S28*T28*U28 -> 0 | W28: =F28+J28+N28+R28+V28 -> 118528.44 | Y28: =W28+W29 -> 390066.31
A29: ='Program Budget'!D30 -> Finance, HR, & Administration Home Office Support | B29: ='Program Budget'!F30 -> Month | C29: ='Program Budget'!H30 -> 7500 | D29: ='Program Budget'!G30 -> 12 | E29: =Admin!E29+'Activity 1'!E29+'Activity 2'!E29+'Activity 3'!E29 -> 0.7 | F29: =C29*D29*E29 -> 63000 | G29: =C29*1.05 -> 7875 | H29: ='Program Budget'!K30 -> 12 | I29: =Admin!I29+'Activity 1'!I29+'Activity 2'!I29+'Activity 3'!I29 -> 0.7 | J29: =G29*H29*I29 -> 66150 | K29: =G29*1.05 -> 8268.75 | L29: ='Program Budget'!N30 -> 12 | M29: =Admin!M29+'Activity 1'!M29+'Activity 2'!M29+'Activity 3'!M29 -> 0.7 | N29: =K29*L29*M29 -> 69457.5 | O29: =K29*1.05 -> 8682.1875 | P29: ='Program Budget'!Q30 -> 12 | Q29: =Admin!Q29+'Activity 1'!Q29+'Activity 2'!Q29+'Activity 3'!Q29 -> 0.7 | R29: =O29*P29*Q29 -> 72930.375 | S29: =O29*1.05 -> 9116.2969 | T29: ='Program Budget'!T30 -> 0 | U29: =Admin!U29+'Activity 1'!U29+'Activity 2'!U29+'Activity 3'!U29 -> 0 | V29: =S29*T29*U29 -> 0 | W29: =F29+J29+N29+R29+V29 -> 271537.88
A30: Total HQ Staff | F30: =SUM(F24:F29) -> 226100 | J30: =SUM(J24:J29) -> 237405 | N30: =SUM(N24:N29) -> 249275.25 | R30: =SUM(R24:R29) -> 261739.01 | V30: =SUM(V24:V29) -> 0 | W30: =SUM(W24:W29) -> 974519.26 | Y30: =Admin!W30+'Activity 1'!W30+'Activity 2'!W30+'Activity 3'!W30 -> 974519.26
A32: Subtotal: Salaries & Wages | F32: =F30+F23+F8 -> 603850 | J32: =J30+J23+J8 -> 744555 | N32: =N30+N23+N8 -> 781782.75 | R32: =R30+R23+R8 -> 820871.89 | V32: =V30+V23+V8 -> 0 | W32: =+F32+J32+N32+R32+V32 -> 2951059.6
A33: Fringe
A34: USN/TCN Staff | B34: ='Program Budget'!F36 -> % | C34: =F8 -> 0 | D34: 1 | E34: 0 | F34: =C34*D34*E34 -> 0 | G34: =J8 -> 0 | H34: 1 | I34: =E34 -> 0 | J34: =G34*H34*I34 -> 0 | K34: =N8 -> 0 | L34: 1 | M34: =I34 -> 0 | N34: =K34*L34*M34 -> 0 | O34: =R8 -> 0 | P34: 1 | Q34: =M34 -> 0 | R34: =O34*P34*Q34 -> 0 | S34: =V8 -> 0 | T34: 1 | U34: 0 | V34: =S34*T34*U34 -> 0 | W34: =F34+J34+N34+R34+V34 -> 0
A35: ='Program Budget'!D35 -> Fringe Benefits CCN - Nigeria | B35: ='Program Budget'!F35 -> % | C35: =F23 -> 377750 | D35: 1 | E35: ='Program Budget'!H35 -> 0.296 | F35: =C35*D35*E35 -> 111814 | G35: =J23 -> 507150 | H35: 1 | I35: =E35 -> 0.296 | J35: =G35*H35*I35 -> 150116.4 | K35: =N23 -> 532507.5 | L35: 1 | M35: =E35 -> 0.296 | N35: =K35*L35*M35 -> 157622.22 | O35: =R23 -> 559132.88 | P35: 1 | Q35: =E35 -> 0.296 | R35: =O35*P35*Q35 -> 165503.33 | S35: =V23 -> 0 | T35: 1 | U35: 0 | V35: =S35*T35*U35 -> 0 | W35: =F35+J35+N35+R35+V35 -> 585055.95
A36: HQ Staff | B36: ='Program Budget'!F36 -> % | C36: =F30 -> 226100 | D36: 1 | E36: ='Program Budget'!H36 -> 0.2347 | F36: =C36*D36*E36 -> 53065.67 | G36: =J30 -> 237405 | H36: 1 | I36: =E36 -> 0.2347 | J36: =G36*H36*I36 -> 55718.953 | K36: =N30 -> 249275.25 | L36: 1 | M36: =I36 -> 0.2347 | N36: =K36*L36*M36 -> 58504.901 | O36: =R30 -> 261739.01 | P36: 1 | Q36: =M36 -> 0.2347 | R36: =O36*P36*Q36 -> 61430.146 | S36: =V30 -> 0 | T36: 1 | U36: 0 | V36: =S36*T36*U36 -> 0 | W36: =F36+J36+N36+R36+V36 -> 228719.67
A37: Total: Fringe Benefits | F37: =+SUM(F34:F36) -> 164879.67 | J37: =+SUM(J34:J36) -> 205835.35 | N37: =+SUM(N34:N36) -> 216127.12 | R37: =+SUM(R34:R36) -> 226933.48 | V37: =+SUM(V34:V36) -> 0 | W37: =+F37+J37+N37+R37+V37 -> 813775.62
A38: Allowances
A39: None | F39: =C39*D39*E39 -> 0 | J39: =G39*H39*I39 -> 0 | N39: =K39*L39*M39 -> 0 | R39: =O39*P39*Q39 -> 0 | V39: =S39*T39*U39 -> 0 | W39: =F39+J39+N39+R39+V39 -> 0
A40: Total: Allowances | F40: =SUM(F39:F39) -> 0 | J40: =SUM(J39:J39) -> 0 | N40: =SUM(N39:N39) -> 0 | R40: =SUM(R39:R39) -> 0 | V40: =SUM(V39:V39) -> 0 | W40: =SUM(W39:W39) -> 0
A42: Subtotal: Benefits | F42: =F40+F37 -> 164879.67 | J42: =J40+J37 -> 205835.35 | N42: =N40+N37 -> 216127.12 | R42: =R40+R37 -> 226933.48 | V42: =V40+V37 -> 0 | W42: =+F42+J42+N42+R42+V42 -> 813775.62
A43: International Travel
...

Sheet Admin
A2: Item | C2: Year 1 | G2: Year 2 | K2: Year 3 | O2: Year 4 | S2: Year 5 | W2: Total
C3: Cost | D3: Quantity | E3: Percent Allocated | F3: Total | G3: Cost | H3: Quantity | I3: Percent Allocated | J3: Total | K3: Cost | L3: Quantity | M3: Percent Allocated | N3: Total | O3: Cost | P3: Quantity | Q3: Percent Allocated | R3: Total | S3: Cost | T3: Quantity | U3: Percent Allocated | V3: Total
A4: Direct Costs
A5: Salaries
A6: USN/TCN Staff
A7: None | F7: =C7*D7*E7 -> 0 | J7: =G7*H7*I7 -> 0 | N7: =K7*L7*M7 -> 0 | R7: =O7*P7*Q7 -> 0 | V7: =S7*T7*U7 -> 0 | W7: =F7+J7+N7+R7+V7 -> 0
A8: Total: Expatriate Salaries & Wages | F8: =SUM(F7:F7) -> 0 | J8: =SUM(J7:J7) -> 0 | N8: =SUM(N7:N7) -> 0 | R8: =SUM(R7:R7) -> 0 | V8: =SUM(V7:V7) -> 0 | W8: =+F8+J8+N8+R8+V8 -> 0
A9: CNN Staff
A10: ='Program Budget'!D12 -> Key Personnel: Chief of Party | B10: ='Program Budget'!F12 -> Month | C10: ='Program Budget'!H12 -> 9583.3333 | D10: ='Program Budget'!G12 -> 11 | E10: ='Program Budget'!E12 -> 0.5 | F10: =C10*D10*E10 -> 52708.333 | G10: =C10*1.05 -> 10062.5 | H10: ='Program Budget'!K12 -> 12 | I10: ='Program Budget'!J12 -> 0.05 | J10: =G10*H10*I10 -> 6037.5 | K10: =G10*1.05 -> 10565.625 | L10: ='Program Budget'!N12 -> 12 | M10: ='Program Budget'!M12 -> 0.05 | N10: =K10*L10*M10 -> 6339.375 | O10: =K10*1.05 -> 11093.906 | P10: ='Program Budget'!Q12 -> 12 | Q10: ='Program Budget'!P12 -> 0.05 | R10: =O10*P10*Q10 -> 6656.3438 | S10: =O10*1.05 -> 11648.602 | T10: ='Program Budget'!T12 -> 0 | U10: ='Program Budget'!S12 -> 0 | V10: =S10*T10*U10 -> 0 | W10: =F10+J10+N10+R10+V10 -> 71741.552
A11: ='Program Budget'!D13 -> Technical Director | B11: ='Program Budget'!F13 -> Month | C11: ='Program Budget'!H13 -> 3500 | D11: ='Program Budget'!G13 -> 9 | E11: ='Program Budget'!E13 -> 0.28 | F11: =C11*D11*E11 -> 8820 | G11: =C11*1.05 -> 3675 | H11: ='Program Budget'!K13 -> 12 | I11: ='Program Budget'!J13 -> 0 | J11: =G11*H11*I11 -> 0 | K11: =G11*1.05 -> 3858.75 | L11: ='Program Budget'!N13 -> 12 | M11: ='Program Budget'!M13 -> 0 | N11: =K11*L11*M11 -> 0 | O11: =K11*1.05 -> 4051.6875 | P11: ='Program Budget'!Q13 -> 12 | Q11: ='Program Budget'!P13 -> 0 | R11: =O11*P11*Q11 -> 0 | S11: =O11*1.05 -> 4254.2719 | T11: ='Program Budget'!T13 -> 0 | U11: ='Program Budget'!S13 -> 0 | V11: =S11*T11*U11 -> 0 | W11: =F11+J11+N11+R11+V11 -> 8820
A12: ='Program Budget'!D14 -> Technical Lead - Activity 2 US Exports | B12: ='Program Budget'!F14 -> Month | C12: ='Program Budget'!H14 -> 2833.3333 | D12: ='Program Budget'!G14 -> 8 | E12: ='Program Budget'!E14 -> 0.2 | F12: =C12*D12*E12 -> 4533.3333 | G12: =C12*1.05 -> 2975 | H12: ='Program Budget'!K14 -> 12 | I12: ='Program Budget'!J14 -> 0 | J12: =G12*H12*I12 -> 0 | K12: =G12*1.05 -> 3123.75 | L12: ='Program Budget'!N14 -> 12 | M12: ='Program Budget'!M14 -> 0 | N12: =K12*L12*M12 -> 0 | O12: =K12*1.05 -> 3279.9375 | P12: ='Program Budget'!Q14 -> 12 | Q12: ='Program Budget'!P14 -> 0 | R12: =O12*P12*Q12 -> 0 | S12: =O12*1.05 -> 3443.9344 | T12: ='Program Budget'!T14 -> 0 | U12: ='Program Budget'!S14 -> 0 | V12: =S12*T12*U12 -> 0 | W12: =F12+J12+N12+R12+V12 -> 4533.3333
A13: ='Program Budget'!D15 -> Technical Lead - Activity 2 Access to Finance Specialist | B13: ='Program Budget'!F15 -> Month | C13: ='Program Budget'!H15 -> 2833.3333 | D13: ='Program Budget'!G15 -> 8 | E13: ='Program Budget'!E15 -> 0.2 | F13: =C13*D13*E13 -> 4533.3333 | G13: =C13*1.05 -> 2975 | H13: ='Program Budget'!K15 -> 12 | I13: ='Program Budget'!J15 -> 0 | J13: =G13*H13*I13 -> 0 | K13: =G13*1.05 -> 3123.75 | L13: ='Program Budget'!N15 -> 12 | M13: ='Program Budget'!M15 -> 0 | N13: =K13*L13*M13 -> 0 | O13: =K13*1.05 -> 3279.9375 | P13: ='Program Budget'!Q15 -> 12 | Q13: ='Program Budget'!P15 -> 0 | R13: =O13*P13*Q13 -> 0 | S13: =O13*1.05 -> 3443.9344 | T13: ='Program Budget'!T15 -> 0 | U13: ='Program Budget'!S15 -> 0 | V13: =S13*T13*U13 -> 0 | W13: =F13+J13+N13+R13+V13 -> 4533.3333
A14: ='Program Budget'!D16 -> Communications/Strategic Partnerships Manager | B14: ='Program Budget'!F16 -> Month | C14: ='Program Budget'!H16 -> 2666.6667 | D14: ='Program Budget'!G16 -> 8 | E14: ='Program Budget'!E16 -> 0.2 | F14: =C14*D14*E14 -> 4266.6667 | G14: =C14*1.05 -> 2800 | H14: ='Program Budget'!K16 -> 12 | I14: ='Program Budget'!J16 -> 0 | J14: =G14*H14*I14 -> 0 | K14: =G14*1.05 -> 2940 | L14: ='Program Budget'!N16 -> 12 | M14: ='Program Budget'!M16 -> 0 | N14: =K14*L14*M14 -> 0 | O14: =K14*1.05 -> 3087 | P14: ='Program Budget'!Q16 -> 12 | Q14: ='Program Budget'!P16 -> 0 | R14: =O14*P14*Q14 -> 0 | S14: =O14*1.05 -> 3241.35 | T14: ='Program Budget'!T16 -> 0 | U14: ='Program Budget'!S16 -> 0 | V14: =S14*T14*U14 -> 0 | W14: =F14+J14+N14+R14+V14 -> 4266.6667
A15: ='Program Budget'!D17 -> M&E Director | B15: ='Program Budget'!F17 -> Month | C15: ='Program Budget'!H17 -> 3500 | D15: ='Program Budget'!G17 -> 10 | E15: ='Program Budget'!E17 -> 0.35 | F15: =C15*D15*E15 -> 12250 | G15: =C15*1.05 -> 3675 | H15: ='Program Budget'!K17 -> 12 | I15: ='Program Budget'!J17 -> 0.05 | J15: =G15*H15*I15 -> 2205 | K15: =G15*1.05 -> 3858.75 | L15: ='Program Budget'!N17 -> 12 | M15: ='Program Budget'!M17 -> 0.05 | N15: =K15*L15*M15 -> 2315.25 | O15: =K15*1.05 -> 4051.6875 | P15: ='Program Budget'!Q17 -> 12 | Q15: ='Program Budget'!P17 -> 0.05 | R15: =O15*P15*Q15 -> 2431.0125 | S15: =O15*1.05 -> 4254.2719 | T15: ='Program Budget'!T17 -> 0 | U15: ='Program Budget'!S17 -> 0 | V15: =S15*T15*U15 -> 0 | W15: =F15+J15+N15+R15+V15 -> 19201.263
A16: ='Program Budget'!D18 -> M&E Specialist | B16: ='Program Budget'!F18 -> Month | C16: ='Program Budget'!H18 -> 2000 | D16: ='Program Budget'!G18 -> 8 | E16: ='Program Budget'!E18 -> 0.2 | F16: =C16*D16*E16 -> 3200 | G16: =C16*1.05 -> 2100 | H16: ='Program Budget'!K18 -> 12 | I16: ='Program Budget'!J18 -> 0.05 | J16: =G16*H16*I16 -> 1260 | K16: =G16*1.05 -> 2205 | L16: ='Program Budget'!N18 -> 12 | M16: ='Program Budget'!M18 -> 0.05 | N16: =K16*L16*M16 -> 1323 | O16: =K16*1.05 -> 2315.25 | P16: ='Program Budget'!Q18 -> 12 | Q16: ='Program Budget'!P18 -> 0.05 | R16: =O16*P16*Q16 -> 1389.15 | S16: =O16*1.05 -> 2431.0125 | T16: ='Program Budget'!T18 -> 0 | U16: ='Program Budget'!S18 -> 0 | V16: =S16*T16*U16 -> 0 | W16: =F16+J16+N16+R16+V16 -> 7172.15
A17: ='Program Budget'!D19 -> Key Personnel: Finance & Administration (F&A) Director | B17: ='Program Budget'!F19 -> Month | C17: ='Program Budget'!H19 -> 3500 | D17: ='Program Budget'!G19 -> 10 | E17: ='Program Budget'!E19 -> 0.35 | F17: =C17*D17*E17 -> 12250 | G17: =C17*1.05 -> 3675 | H17: ='Program Budget'!K19 -> 12 | I17: ='Program Budget'!J19 -> 0.05 | J17: =G17*H17*I17 -> 2205 | K17: =G17*1.05 -> 3858.75 | L17: ='Program Budget'!N19 -> 12 | M17: ='Program Budget'!M19 -> 0.05 | N17: =K17*L17*M17 -> 2315.25 | O17: =K17*1.05 -> 4051.6875 | P17: ='Program Budget'!Q19 -> 12 | Q17: ='Program Budget'!P19 -> 0.05 | R17: =O17*P17*Q17 -> 2431.0125 | S17: =O17*1.05 -> 4254.2719 | T17: ='Program Budget'!T19 -> 0 | U17: ='Program Budget'!S19 -> 0 | V17: =S17*T17*U17 -> 0 | W17: =F17+J17+N17+R17+V17 -> 19201.263
A18: ='Program Budget'!D20 -> Accountant | B18: ='Program Budget'!F20 -> Month | C18: ='Program Budget'!H20 -> 2000 | D18: ='Program Budget'!G20 -> 8 | E18: ='Program Budget'!E20 -> 0.2 | F18: =C18*D18*E18 -> 3200 | G18: =C18*1.05 -> 2100 | H18: ='Program Budget'!K20 -> 12 | I18: ='Program Budget'!J20 -> 0 | J18: =G18*H18*I18 -> 0 | K18: =G18*1.05 -> 2205 | L18: ='Program Budget'!N20 -> 12 | M18: ='Program Budget'!M20 -> 0 | N18: =K18*L18*M18 -> 0 | O18: =K18*1.05 -> 2315.25 | P18: ='Program Budget'!Q20 -> 12 | Q18: ='Program Budget'!P20 -> 0 | R18: =O18*P18*Q18 -> 0 | S18: =O18*1.05 -> 2431.0125 | T18: ='Program Budget'!T20 -> 0 | U18: ='Program Budget'!S20 -> 0 | V18: =S18*T18*U18 -> 0 | W18: =F18+J18+N18+R18+V18 -> 3200
A19: ='Program Budget'!D21 -> Administration/ HR Manager | B19: ='Program Budget'!F21 -> Month | C19: ='Program Budget'!H21 -> 2666.6667 | D19: ='Program Budget'!G21 -> 10 | E19: ='Program Budget'!E21 -> 0.35 | F19: =C19*D19*E19 -> 9333.3333 | G19: =C19*1.05 -> 2800 | H19: ='Program Budget'!K21 -> 12 | I19: ='Program Budget'!J21 -> 0.05 | J19: =G19*H19*I19 -> 1680 | K19: =G19*1.05 -> 2940 | L19: ='Program Budget'!N21 -> 12 | M19: ='Program Budget'!M21 -> 0.05 | N19: =K19*L19*M19 -> 1764 | O19: =K19*1.05 -> 3087 | P19: ='Program Budget'!Q21 -> 12 | Q19: ='Program Budget'!P21 -> 0.05 | R19: =O19*P19*Q19 -> 1852.2 | S19: =O19*1.05 -> 3241.35 | T19: ='Program Budget'!T21 -> 0 | U19: ='Program Budget'!S21 -> 0 | V19: =S19*T19*U19 -> 0 | W19: =F19+J19+N19+R19+V19 -> 14629.533
A20: ='Program Budget'!D22 -> Grants & Contracts Manager | B20: ='Program Budget'!F22 -> Month | C20: ='Program Budget'!H22 -> 2666.6667 | D20: ='Program Budget'!G22 -> 9 | E20: ='Program Budget'!E22 -> 0.28 | F20: =C20*D20*E20 -> 6720 | G20: =C20*1.05 -> 2800 | H20: ='Program Budget'!K22 -> 12 | I20: ='Program Budget'!J22 -> 0 | J20: =G20*H20*I20 -> 0 | K20: =G20*1.05 -> 2940 | L20: ='Program Budget'!N22 -> 12 | M20: ='Program Budget'!M22 -> 0 | N20: =K20*L20*M20 -> 0 | O20: =K20*1.05 -> 3087 | P20: ='Program Budget'!Q22 -> 12 | Q20: ='Program Budget'!P22 -> 0 | R20: =O20*P20*Q20 -> 0 | S20: =O20*1.05 -> 3241.35 | T20: ='Program Budget'!T22 -> 0 | U20: ='Program Budget'!S22 -> 0 | V20: =S20*T20*U20 -> 0 | W20: =F20+J20+N20+R20+V20 -> 6720
A21: ='Program Budget'!D23 -> Compliance & Procurement Specialist | B21: ='Program Budget'!F23 -> Month | C21: ='Program Budget'!H23 -> 2000 | D21: ='Program Budget'!G23 -> 9 | E21: ='Program Budget'!E23 -> 0.28 | F21: =C21*D21*E21 -> 5040 | G21: =C21*1.05 -> 2100 | H21: ='Program Budget'!K23 -> 12 | I21: ='Program Budget'!J23 -> 0 | J21: =G21*H21*I21 -> 0 | K21: =G21*1.05 -> 2205 | L21: ='Program Budget'!N23 -> 12 | M21: ='Program Budget'!M23 -> 0 | N21: =K21*L21*M21 -> 0 | O21: =K21*1.05 -> 2315.25 | P21: ='Program Budget'!Q23 -> 12 | Q21: ='Program Budget'!P23 -> 0 | R21: =O21*P21*Q21 -> 0 | S21: =O21*1.05 -> 2431.0125 | T21: ='Program Budget'!T23 -> 0 | U21: ='Program Budget'!S23 -> 0 | V21: =S21*T21*U21 -> 0 | W21: =F21+J21+N21+R21+V21 -> 5040
A22: ='Program Budget'!D24 -> Driver | B22: ='Program Budget'!F24 -> Month | C22: ='Program Budget'!H24 -> 500 | D22: ='Program Budget'!G24 -> 7 | E22: ='Program Budget'!E24 -> 0 | F22: =C22*D22*E22 -> 0 | G22: =C22*1.05 -> 525 | H22: ='Program Budget'!K24 -> 12 | I22: ='Program Budget'!J24 -> 0 | J22: =G22*H22*I22 -> 0 | K22: =G22*1.05 -> 551.25 | L22: ='Program Budget'!N24 -> 12 | M22: ='Program Budget'!M24 -> 0 | N22: =K22*L22*M22 -> 0 | O22: =K22*1.05 -> 578.8125 | P22: ='Program Budget'!Q24 -> 12 | Q22: ='Program Budget'!P24 -> 0 | R22: =O22*P22*Q22 -> 0 | S22: =O22*1.05 -> 607.75313 | T22: ='Program Budget'!T24 -> 0 | U22: ='Program Budget'!S24 -> 0 | V22: =S22*T22*U22 -> 0 | W22: =F22+J22+N22+R22+V22 -> 0
A23: Total Local Salary Cost | F23: =SUM(F9:F22) -> 126855 | J23: =SUM(J9:J22) -> 13387.5 | N23: =SUM(N9:N22) -> 14056.875 | R23: =SUM(R9:R22) -> 14759.719 | V23: =SUM(V9:V22) -> 0 | W23: =SUM(W9:W22) -> 169059.09
A24: HQ Staff
A25: ='Program Budget'!D26 -> Senior Vice President of Programs | B25: ='Program Budget'!F26 -> Month | C25: ='Program Budget'!H26 -> 13500 | D25: ='Program Budget'!G26 -> 12 | E25: ='Program Budget'!E26 -> 0.02 | F25: =C25*D25*E25 -> 3240 | G25: =C25*1.05 -> 14175 | H25: ='Program Budget'!K26 -> 12 | I25: ='Program Budget'!J26 -> 0.02 | J25: =G25*H25*I25 -> 3402 | K25: =G25*1.05 -> 14883.75 | L25: ='Program Budget'!N26 -> 12 | M25: ='Program Budget'!M26 -> 0.02 | N25: =K25*L25*M25 -> 3572.1 | O25: =K25*1.05 -> 15627.938 | P25: ='Program Budget'!Q26 -> 12 | Q25: ='Program Budget'!P26 -> 0.02 | R25: =O25*P25*Q25 -> 3750.705 | S25: =O25*1.05 -> 16409.334 | T25: ='Program Budget'!T26 -> 0 | U25: ='Program Budget'!S26 -> 0 | V25: =S25*T25*U25 -> 0 | W25: =F25+J25+N25+R25+V25 -> 13964.805
A26: ='Program Budget'!D27 -> Senior Program Director | B26: ='Program Budget'!F27 -> Month | C26: ='Program Budget'!H27 -> 12500 | D26: ='Program Budget'!G27 -> 12 | E26: ='Program Budget'!E27 -> 0.12 | F26: =C26*D26*E26 -> 18000 | G26: =C26*1.05 -> 13125 | H26: ='Program Budget'!K27 -> 12 | I26: ='Program Budget'!J27 -> 0.05 | J26: =G26*H26*I26 -> 7875 | K26: =G26*1.05 -> 13781.25 | L26: ='Program Budget'!N27 -> 12 | M26: ='Program Budget'!M27 -> 0.05 | N26: =K26*L26*M26 -> 8268.75 | O26: =K26*1.05 -> 14470.312 | P26: ='Program Budget'!Q27 -> 12 | Q26: ='Program Budget'!P27 -> 0.05 | R26: =O26*P26*Q26 -> 8682.1875 | S26: =O26*1.05 -> 15193.828 | T26: ='Program Budget'!T27 -> 0 | U26: ='Program Budget'!S27 -> 0 | V26: =S26*T26*U26 -> 0 | W26: =F26+J26+N26+R26+V26 -> 42825.938
A27: ='Program Budget'!D28 -> Associate Director | B27: ='Program Budget'!F28 -> Month | C27: ='Program Budget'!H28 -> 7500 | D27: ='Program Budget'!G28 -> 12 | E27: ='Program Budget'!E28 -> 0.5 | F27: =C27*D27*E27 -> 45000 | G27: =C27*1.05 -> 7875 | H27: ='Program Budget'!K28 -> 12 | I27: ='Program Budget'!J28 -> 0.05 | J27: =G27*H27*I27 -> 4725 | K27: =G27*1.05 -> 8268.75 | L27: ='Program Budget'!N28 -> 12 | M27: ='Program Budget'!M28 -> 0.05 | N27: =K27*L27*M27 -> 4961.25 | O27: =K27*1.05 -> 8682.1875 | P27: ='Program Budget'!Q28 -> 12 | Q27: ='Program Budget'!P28 -> 0.05 | R27: =O27*P27*Q27 -> 5209.3125 | S27: =O27*1.05 -> 9116.2969 | T27: ='Program Budget'!T28 -> 0 | U27: ='Program Budget'!S28 -> 0 | V27: =S27*T27*U27 -> 0 | W27: =F27+J27+N27+R27+V27 -> 59895.562
A28: ='Program Budget'!D29 -> Compliance & Contracts Director | B28: ='Program Budget'!F29 -> Month | C28: ='Program Budget'!H29 -> 9166.6667 | D28: ='Program Budget'!G29 -> 12 | E28: ='Program Budget'!E29 -> 0.12 | F28: =C28*D28*E28 -> 13200 | G28: =C28*1.05 -> 9625 | H28: ='Program Budget'!K29 -> 12 | I28: ='Program Budget'!J29 -> 0.05 | J28: =G28*H28*I28 -> 5775 | K28: =G28*1.05 -> 10106.25 | L28: ='Program Budget'!N29 -> 12 | M28: ='Program Budget'!M29 -> 0.05 | N28: =K28*L28*M28 -> 6063.75 | O28: =K28*1.05 -> 10611.562 | P28: ='Program Budget'!Q29 -> 12 | Q28: ='Program Budget'!P29 -> 0.05 | R28: =O28*P28*Q28 -> 6366.9375 | S28: =O28*1.05 -> 11142.141 | T28: ='Program Budget'!T29 -> 0 | U28: ='Program Budget'!S29 -> 0 | V28: =S28*T28*U28 -> 0 | W28: =F28+J28+N28+R28+V28 -> 31405.688
A29: ='Program Budget'!D30 -> Finance, HR, & Administration Home Office Support | B29: ='Program Budget'!F30 -> Month | C29: ='Program Budget'!H30 -> 7500 | D29: ='Program Budget'!G30 -> 12 | E29: ='Program Budget'!E30 -> 0.35 | F29: =C29*D29*E29 -> 31500 | G29: =C29*1.05 -> 7875 | H29: ='Program Budget'!K30 -> 12 | I29: ='Program Budget'!J30 -> 0.05 | J29: =G29*H29*I29 -> 4725 | K29: =G29*1.05 -> 8268.75 | L29: ='Program Budget'!N30 -> 12 | M29: ='Program Budget'!M30 -> 0.05 | N29: =K29*L29*M29 -> 4961.25 | O29: =K29*1.05 -> 8682.1875 | P29: ='Program Budget'!Q30 -> 12 | Q29: ='Program Budget'!P30 -> 0.05 | R29: =O29*P29*Q29 -> 5209.3125 | S29: =O29*1.05 -> 9116.2969 | T29: ='Program Budget'!T30 -> 0 | U29: ='Program Budget'!S30 -> 0 | V29: =S29*T29*U29 -> 0 | W29: =F29+J29+N29+R29+V29 -> 46395.562
A30: Total HQ Staff | F30: =SUM(F24:F29) -> 110940 | J30: =SUM(J24:J29) -> 26502 | N30: =SUM(N24:N29) -> 27827.1 | R30: =SUM(R24:R29) -> 29218.455 | V30: =SUM(V24:V29) -> 0 | W30: =SUM(W24:W29) -> 194487.55
A32: Subtotal: Salaries & Wages | F32: =F30+F23+F8 -> 237795 | J32: =J30+J23+J8 -> 39889.5 | N32: =N30+N23+N8 -> 41883.975 | R32: =R30+R23+R8 -> 43978.174 | V32: =V30+V23+V8 -> 0 | W32: =+F32+J32+N32+R32+V32 -> 363546.65
A33: Fringe
A34: USN/TCN Staff | B34: ='Program Budget'!F35 -> % | C34: =F8 -> 0 | D34: 1 | E34: 0 | F34: =C34*D34*E34 -> 0 | G34: =J8 -> 0 | H34: 1 | I34: =E34 -> 0 | J34: =G34*H34*I34 -> 0 | K34: =N8 -> 0 | L34: 1 | M34: =E34 -> 0 | N34: =K34*L34*M34 -> 0 | O34: =R8 -> 0 | P34: 1 | Q34: =E34 -> 0 | R34: =O34*P34*Q34 -> 0 | S34: =V8 -> 0 | T34: 1 | U34: =E34 -> 0 | V34: =S34*T34*U34 -> 0 | W34: =F34+J34+N34+R34+V34 -> 0
A35: ='Program Budget'!D35 -> Fringe Benefits CCN - Nigeria | B35: ='Program Budget'!F36 -> % | C35: =F23 -> 126855 | D35: 1 | E35: ='Program Budget'!H35 -> 0.296 | F35: =C35*D35*E35 -> 37549.08 | G35: =J23 -> 13387.5 | H35: 1 | I35: =E35 -> 0.296 | J35: =G35*H35*I35 -> 3962.7 | K35: =N23 -> 14056.875 | L35: 1 | M35: =E35 -> 0.296 | N35: =K35*L35*M35 -> 4160.835 | O35: =R23 -> 14759.719 | P35: 1 | Q35: =E35 -> 0.296 | R35: =O35*P35*Q35 -> 4368.8768 | S35: =V23 -> 0 | T35: 1 | U35: 0 | V35: =S35*T35*U35 -> 0 | W35: =F35+J35+N35+R35+V35 -> 50041.492
A36: HQ Staff | B36: ='Program Budget'!F36 -> % | C36: =F30 -> 110940 | D36: 1 | E36: ='Program Budget'!H36 -> 0.2347 | F36: =C36*D36*E36 -> 26037.618 | G36: =J30 -> 26502 | H36: 1 | I36: =E36 -> 0.2347 | J36: =G36*H36*I36 -> 6220.0194 | K36: =N30 -> 27827.1 | L36: 1 | M36: =E36 -> 0.2347 | N36: =K36*L36*M36 -> 6531.0204 | O36: =R30 -> 29218.455 | P36: 1 | Q36: =E36 -> 0.2347 | R36: =O36*P36*Q36 -> 6857.5714 | S36: =V30 -> 0 | T36: 1 | U36: 0 | V36: =S36*T36*U36 -> 0 | W36: =F36+J36+N36+R36+V36 -> 45646.229
A37: Total: Fringe Benefits | F37: =+SUM(F34:F36) -> 63586.698 | J37: =+SUM(J34:J36) -> 10182.719 | N37: =+SUM(N34:N36) -> 10691.855 | R37: =+SUM(R34:R36) -> 11226.448 | V37: =+SUM(V34:V36) -> 0 | W37: =+F37+J37+N37+R37+V37 -> 95687.721
A38: Allowances
A39: None | F39: =C39*D39*E39 -> 0 | J39: =G39*H39*I39 -> 0 | N39: =K39*L39*M39 -> 0 | R39: =O39*P39*Q39 -> 0 | V39: =S39*T39*U39 -> 0 | W39: =F39+J39+N39+R39+V39 -> 0
A40: Total: Allowances | F40: =SUM(F39:F39) -> 0 | J40: =SUM(J39:J39) -> 0 | N40: =SUM(N39:N39) -> 0 | R40: =SUM(R39:R39) -> 0 | V40: =SUM(V39:V39) -> 0 | W40: =SUM(W39:W39) -> 0
A42: Subtotal: Benefits | F42: =F40+F37 -> 63586.698 | J42: =J40+J37 -> 10182.719 | N42: =N40+N37 -> 10691.855 | R42: =R40+R37 -> 11226.448 | V42: =V40+V37 -> 0 | W42: =+F42+J42+N42+R42+V42 -> 95687.721
A43: International Travel
...

Sheet Activity 1
A2: Item | B2: Type of Unit | C2: Year 1 | G2: Year 2 | K2: Year 3 | O2: Year 4 | S2: Year 5 | W2: Total
C3: Cost | D3: Quantity | E3: Percent Allocated | F3: Total | G3: Cost | H3: Quantity | I3: Percent Allocated | J3: Total | K3: Cost | L3: Quantity | M3: Percent Allocated | N3: Total | O3: Cost | P3: Quantity | Q3: Percent Allocated | R3: Total | S3: Cost | T3: Quantity | U3: Percent Allocated | V3: Total
A4: Direct Costs
A5: Salaries/Personnel
A6: USN/TCN Staff
A7: None | F7: =C7*D7*E7 -> 0 | J7: =G7*H7*I7 -> 0 | N7: =K7*L7*M7 -> 0 | R7: =O7*P7*Q7 -> 0 | V7: =S7*T7*U7 -> 0 | W7: =F7+J7+N7+R7+V7 -> 0
A8: Total: Expatriate Salaries & Wages | F8: =SUM(F7:F7) -> 0 | J8: =SUM(J7:J7) -> 0 | N8: =SUM(N7:N7) -> 0 | R8: =SUM(R7:R7) -> 0 | V8: =SUM(V7:V7) -> 0 | W8: =+F8+J8+N8+R8+V8 -> 0
A9: CCN Staff
A10: ='Program Budget'!D12 -> Key Personnel: Chief of Party | B10: ='Program Budget'!F131 -> Month | C10: ='Program Budget'!H131 -> 9583.3333 | D10: ='Program Budget'!G131 -> 11 | E10: ='Program Budget'!E131 -> 0.2 | F10: =C10*D10*E10 -> 21083.333 | G10: =C10*1.05 -> 10062.5 | H10: ='Program Budget'!K131 -> 12 | I10: ='Program Budget'!J131 -> 0.2 | J10: =G10*H10*I10 -> 24150 | K10: =G10*1.05 -> 10565.625 | L10: ='Program Budget'!N131 -> 12 | M10: ='Program Budget'!M131 -> 0.2 | N10: =K10*L10*M10 -> 25357.5 | O10: =K10*1.05 -> 11093.906 | P10: ='Program Budget'!Q131 -> 12 | Q10: ='Program Budget'!P131 -> 0.3 | R10: =O10*P10*Q10 -> 39938.063 | S10: =O10*1.05 -> 11648.602 | T10: ='Program Budget'!T131 -> 0 | U10: ='Program Budget'!S131 -> 0 | V10: =S10*T10*U10 -> 0 | W10: =F10+J10+N10+R10+V10 -> 110528.9
A11: ='Program Budget'!D13 -> Technical Director | B11: ='Program Budget'!F132 -> Month | C11: ='Program Budget'!H132 -> 3500 | D11: ='Program Budget'!G132 -> 9 | E11: ='Program Budget'!E132 -> 0.22 | F11: =C11*D11*E11 -> 6930 | G11: =C11*1.05 -> 3675 | H11: ='Program Budget'!K132 -> 12 | I11: ='Program Budget'!J132 -> 0.2 | J11: =G11*H11*I11 -> 8820 | K11: =G11*1.05 -> 3858.75 | L11: ='Program Budget'!N132 -> 12 | M11: ='Program Budget'!M132 -> 0.2 | N11: =K11*L11*M11 -> 9261 | O11: =K11*1.05 -> 4051.6875 | P11: ='Program Budget'!Q132 -> 12 | Q11: ='Program Budget'!P132 -> 0.3 | R11: =O11*P11*Q11 -> 14586.075 | S11: =O11*1.05 -> 4254.2719 | T11: ='Program Budget'!T132 -> 0 | U11: ='Program Budget'!S132 -> 0 | V11: =S11*T11*U11 -> 0 | W11: =F11+J11+N11+R11+V11 -> 39597.075
A12: ='Program Budget'!D14 -> Technical Lead - Activity 2 US Exports | B12: ='Program Budget'!F133 -> Month | C12: ='Program Budget'!H133 -> 2833.3333 | D12: ='Program Budget'!G133 -> 8 | E12: ='Program Budget'!E133 -> 0 | F12: =C12*D12*E12 -> 0 | G12: =C12*1.05 -> 2975 | H12: ='Program Budget'!K133 -> 12 | I12: ='Program Budget'!J133 -> 0 | J12: =G12*H12*I12 -> 0 | K12: =G12*1.05 -> 3123.75 | L12: ='Program Budget'!N133 -> 12 | M12: ='Program Budget'!M133 -> 0 | N12: =K12*L12*M12 -> 0 | O12: =K12*1.05 -> 3279.9375 | P12: ='Program Budget'!Q133 -> 12 | Q12: ='Program Budget'!P133 -> 0 | R12: =O12*P12*Q12 -> 0 | S12: =O12*1.05 -> 3443.9344 | T12: ='Program Budget'!T133 -> 0 | U12: ='Program Budget'!S133 -> 0 | V12: =S12*T12*U12 -> 0 | W12: =F12+J12+N12+R12+V12 -> 0
A13: ='Program Budget'!D15 -> Technical Lead - Activity 2 Access to Finance Specialist | B13: ='Program Budget'!F134 -> Month | C13: ='Program Budget'!H134 -> 2833.3333 | D13: ='Program Budget'!G134 -> 8 | E13: ='Program Budget'!E134 -> 0 | F13: =C13*D13*E13 -> 0 | G13: =C13*1.05 -> 2975 | H13: ='Program Budget'!K134 -> 12 | I13: ='Program Budget'!J134 -> 0 | J13: =G13*H13*I13 -> 0 | K13: =G13*1.05 -> 3123.75 | L13: ='Program Budget'!N134 -> 12 | M13: ='Program Budget'!M134 -> 0 | N13: =K13*L13*M13 -> 0 | O13: =K13*1.05 -> 3279.9375 | P13: ='Program Budget'!Q134 -> 12 | Q13: ='Program Budget'!P134 -> 0 | R13: =O13*P13*Q13 -> 0 | S13: =O13*1.05 -> 3443.9344 | T13: ='Program Budget'!T134 -> 0 | U13: ='Program Budget'!S134 -> 0 | V13: =S13*T13*U13 -> 0 | W13: =F13+J13+N13+R13+V13 -> 0
A14: ='Program Budget'!D16 -> Communications/Strategic Partnerships Manager | B14: ='Program Budget'!F135 -> Month | C14: ='Program Budget'!H135 -> 2666.6667 | D14: ='Program Budget'!G135 -> 8 | E14: ='Program Budget'!E135 -> 0.3 | F14: =C14*D14*E14 -> 6400 | G14: =C14*1.05 -> 2800 | H14: ='Program Budget'!K135 -> 12 | I14: ='Program Budget'!J135 -> 0.4 | J14: =G14*H14*I14 -> 13440 | K14: =G14*1.05 -> 2940 | L14: ='Program Budget'!N135 -> 12 | M14: ='Program Budget'!M135 -> 0.4 | N14: =K14*L14*M14 -> 14112 | O14: =K14*1.05 -> 3087 | P14: ='Program Budget'!Q135 -> 12 | Q14: ='Program Budget'!P135 -> 0.5 | R14: =O14*P14*Q14 -> 18522 | S14: =O14*1.05 -> 3241.35 | T14: ='Program Budget'!T135 -> 0 | U14: ='Program Budget'!S135 -> 0 | V14: =S14*T14*U14 -> 0 | W14: =F14+J14+N14+R14+V14 -> 52474
A15: ='Program Budget'!D17 -> M&E Director | B15: ='Program Budget'!F136 -> Month | C15: ='Program Budget'!H136 -> 3500 | D15: ='Program Budget'!G136 -> 10 | E15: ='Program Budget'!E136 -> 0.2 | F15: =C15*D15*E15 -> 7000 | G15: =C15*1.05 -> 3675 | H15: ='Program Budget'!K136 -> 12 | I15: ='Program Budget'!J136 -> 0.25 | J15: =G15*H15*I15 -> 11025 | K15: =G15*1.05 -> 3858.75 | L15: ='Program Budget'!N136 -> 12 | M15: ='Program Budget'!M136 -> 0.25 | N15: =K15*L15*M15 -> 11576.25 | O15: =K15*1.05 -> 4051.6875 | P15: ='Program Budget'!Q136 -> 12 | Q15: ='Program Budget'!P136 -> 0.35 | R15: =O15*P15*Q15 -> 17017.087 | S15: =O15*1.05 -> 4254.2719 | T15: ='Program Budget'!T136 -> 0 | U15: ='Program Budget'!S136 -> 0 | V15: =S15*T15*U15 -> 0 | W15: =F15+J15+N15+R15+V15 -> 46618.337
A16: ='Program Budget'!D18 -> M&E Specialist | B16: ='Program Budget'!F137 -> Month | C16: ='Program Budget'!H137 -> 2000 | D16: ='Program Budget'!G137 -> 8 | E16: ='Program Budget'!E137 -> 0.25 | F16: =C16*D16*E16 -> 4000 | G16: =C16*1.05 -> 2100 | H16: ='Program Budget'!K137 -> 12 | I16: ='Program Budget'!J137 -> 0.25 | J16: =G16*H16*I16 -> 6300 | K16: =G16*1.05 -> 2205 | L16: ='Program Budget'!N137 -> 12 | M16: ='Program Budget'!M137 -> 0.25 | N16: =K16*L16*M16 -> 6615 | O16: =K16*1.05 -> 2315.25 | P16: ='Program Budget'!Q137 -> 12 | Q16: ='Program Budget'!P137 -> 0.35 | R16: =O16*P16*Q16 -> 9724.05 | S16: =O16*1.05 -> 2431.0125 | T16: ='Program Budget'!T137 -> 0 | U16: ='Program Budget'!S137 -> 0 | V16: =S16*T16*U16 -> 0 | W16: =F16+J16+N16+R16+V16 -> 26639.05
A17: ='Program Budget'!D19 -> Key Personnel: Finance & Administration (F&A) Director | B17: ='Program Budget'!F138 -> Month | C17: ='Program Budget'!H138 -> 3500 | D17: ='Program Budget'!G138 -> 10 | E17: ='Program Budget'!E138 -> 0.2 | F17: =C17*D17*E17 -> 7000 | G17: =C17*1.05 -> 3675 | H17: ='Program Budget'!K138 -> 12 | I17: ='Program Budget'!J138 -> 0.3 | J17: =G17*H17*I17 -> 13230 | K17: =G17*1.05 -> 3858.75 | L17: ='Program Budget'!N138 -> 12 | M17: ='Program Budget'!M138 -> 0.3 | N17: =K17*L17*M17 -> 13891.5 | O17: =K17*1.05 -> 4051.6875 | P17: ='Program Budget'!Q138 -> 12 | Q17: ='Program Budget'!P138 -> 0.4 | R17: =O17*P17*Q17 -> 19448.1 | S17: =O17*1.05 -> 4254.2719 | T17: ='Program Budget'!T138 -> 0 | U17: ='Program Budget'!S138 -> 0 | V17: =S17*T17*U17 -> 0 | W17: =F17+J17+N17+R17+V17 -> 53569.6
A18: ='Program Budget'!D20 -> Accountant | B18: ='Program Budget'!F139 -> Month | C18: ='Program Budget'!H139 -> 2000 | D18: ='Program Budget'!G139 -> 8 | E18: ='Program Budget'!E139 -> 0.25 | F18: =C18*D18*E18 -> 4000 | G18: =C18*1.05 -> 2100 | H18: ='Program Budget'!K139 -> 12 | I18: ='Program Budget'!J139 -> 0.25 | J18: =G18*H18*I18 -> 6300 | K18: =G18*1.05 -> 2205 | L18: ='Program Budget'!N139 -> 12 | M18: ='Program Budget'!M139 -> 0.25 | N18: =K18*L18*M18 -> 6615 | O18: =K18*1.05 -> 2315.25 | P18: ='Program Budget'!Q139 -> 12 | Q18: ='Program Budget'!P139 -> 0.4 | R18: =O18*P18*Q18 -> 11113.2 | S18: =O18*1.05 -> 2431.0125 | T18: ='Program Budget'!T139 -> 0 | U18: ='Program Budget'!S139 -> 0 | V18: =S18*T18*U18 -> 0 | W18: =F18+J18+N18+R18+V18 -> 28028.2
A19: ='Program Budget'!D21 -> Administration/ HR Manager | B19: ='Program Budget'!F140 -> Month | C19: ='Program Budget'!H140 -> 2666.6667 | D19: ='Program Budget'!G140 -> 10 | E19: ='Program Budget'!E140 -> 0.15 | F19: =C19*D19*E19 -> 4000 | G19: =C19*1.05 -> 2800 | H19: ='Program Budget'!K140 -> 12 | I19: ='Program Budget'!J140 -> 0.25 | J19: =G19*H19*I19 -> 8400 | K19: =G19*1.05 -> 2940 | L19: ='Program Budget'!N140 -> 12 | M19: ='Program Budget'!M140 -> 0.25 | N19: =K19*L19*M19 -> 8820 | O19: =K19*1.05 -> 3087 | P19: ='Program Budget'!Q140 -> 12 | Q19: ='Program Budget'!P140 -> 0.35 | R19: =O19*P19*Q19 -> 12965.4 | S19: =O19*1.05 -> 3241.35 | T19: ='Program Budget'!T140 -> 0 | U19: ='Program Budget'!S140 -> 0 | V19: =S19*T19*U19 -> 0 | W19: =F19+J19+N19+R19+V19 -> 34185.4
A20: ='Program Budget'!D22 -> Grants & Contracts Manager | B20: ='Program Budget'!F141 -> Month | C20: ='Program Budget'!H141 -> 2666.6667 | D20: ='Program Budget'!G141 -> 9 | E20: ='Program Budget'!E141 -> 0.21 | F20: =C20*D20*E20 -> 5040 | G20: =C20*1.05 -> 2800 | H20: ='Program Budget'!K141 -> 12 | I20: ='Program Budget'!J141 -> 0.3 | J20: =G20*H20*I20 -> 10080 | K20: =G20*1.05 -> 2940 | L20: ='Program Budget'!N141 -> 12 | M20: ='Program Budget'!M141 -> 0.3 | N20: =K20*L20*M20 -> 10584 | O20: =K20*1.05 -> 3087 | P20: ='Program Budget'!Q141 -> 12 | Q20: ='Program Budget'!P141 -> 0.4 | R20: =O20*P20*Q20 -> 14817.6 | S20: =O20*1.05 -> 3241.35 | T20: ='Program Budget'!T141 -> 0 | U20: ='Program Budget'!S141 -> 0 | V20: =S20*T20*U20 -> 0 | W20: =F20+J20+N20+R20+V20 -> 40521.6
A21: ='Program Budget'!D23 -> Compliance & Procurement Specialist | B21: ='Program Budget'!F142 -> Month | C21: ='Program Budget'!H142 -> 2000 | D21: ='Program Budget'!G142 -> 9 | E21: ='Program Budget'!E142 -> 0.21 | F21: =C21*D21*E21 -> 3780 | G21: =C21*1.05 -> 2100 | H21: ='Program Budget'!K142 -> 12 | I21: ='Program Budget'!J142 -> 0.3 | J21: =G21*H21*I21 -> 7560 | K21: =G21*1.05 -> 2205 | L21: ='Program Budget'!N142 -> 12 | M21: ='Program Budget'!M142 -> 0.3 | N21: =K21*L21*M21 -> 7938 | O21: =K21*1.05 -> 2315.25 | P21: ='Program Budget'!Q142 -> 12 | Q21: ='Program Budget'!P142 -> 0.4 | R21: =O21*P21*Q21 -> 11113.2 | S21: =O21*1.05 -> 2431.0125 | T21: ='Program Budget'!T142 -> 0 | U21: ='Program Budget'!S142 -> 0 | V21: =S21*T21*U21 -> 0 | W21: =F21+J21+N21+R21+V21 -> 30391.2
A22: ='Program Budget'!D24 -> Driver | B22: ='Program Budget'!F143 -> Month | C22: ='Program Budget'!H143 -> 500 | D22: ='Program Budget'!G143 -> 7 | E22: ='Program Budget'!E143 -> 0.25 | F22: =C22*D22*E22 -> 875 | G22: =C22*1.05 -> 525 | H22: ='Program Budget'!K143 -> 12 | I22: ='Program Budget'!J143 -> 0.25 | J22: =G22*H22*I22 -> 1575 | K22: =G22*1.05 -> 551.25 | L22: ='Program Budget'!N143 -> 12 | M22: ='Program Budget'!M143 -> 0.25 | N22: =K22*L22*M22 -> 1653.75 | O22: =K22*1.05 -> 578.8125 | P22: ='Program Budget'!Q143 -> 12 | Q22: ='Program Budget'!P143 -> 0.35 | R22: =O22*P22*Q22 -> 2431.0125 | S22: =O22*1.05 -> 607.75313 | T22: ='Program Budget'!T143 -> 0 | U22: ='Program Budget'!S143 -> 0 | V22: =S22*T22*U22 -> 0 | W22: =F22+J22+N22+R22+V22 -> 6534.7625
A23: Total Local Salary Cost | F23: =SUM(F10:F22) -> 70108.333 | J23: =SUM(J10:J22) -> 110880 | N23: =SUM(N10:N22) -> 116424 | R23: =SUM(R10:R22) -> 171675.79 | V23: =SUM(V10:V22) -> 0 | W23: =SUM(W10:W22) -> 469088.12
A24: HQ Staff
A25: ='Program Budget'!D26 -> Senior Vice President of Programs | B25: ='Program Budget'!F145 -> Month | C25: ='Program Budget'!H145 -> 13500 | D25: ='Program Budget'!G145 -> 12 | E25: ='Program Budget'!E145 -> 0.01 | F25: =C25*D25*E25 -> 1620 | G25: =C25*1.05 -> 14175 | H25: ='Program Budget'!K145 -> 12 | I25: ='Program Budget'!J145 -> 0.01 | J25: =G25*H25*I25 -> 1701 | K25: =G25*1.05 -> 14883.75 | L25: ='Program Budget'!N145 -> 12 | M25: ='Program Budget'!M145 -> 0.01 | N25: =K25*L25*M25 -> 1786.05 | O25: =K25*1.05 -> 15627.938 | P25: ='Program Budget'!Q145 -> 12 | Q25: ='Program Budget'!P145 -> 0.01 | R25: =O25*P25*Q25 -> 1875.3525 | S25: =O25*1.05 -> 16409.334 | T25: ='Program Budget'!T145 -> 0 | U25: ='Program Budget'!S145 -> 0 | V25: =S25*T25*U25 -> 0 | W25: =F25+J25+N25+R25+V25 -> 6982.4025
A26: ='Program Budget'!D27 -> Senior Program Director | B26: ='Program Budget'!F146 -> Month | C26: ='Program Budget'!H146 -> 12500 | D26: ='Program Budget'!G146 -> 12 | E26: ='Program Budget'!E146 -> 0.04 | F26: =C26*D26*E26 -> 6000 | G26: =C26*1.05 -> 13125 | H26: ='Program Budget'!K146 -> 12 | I26: ='Program Budget'!J146 -> 0.05 | J26: =G26*H26*I26 -> 7875 | K26: =G26*1.05 -> 13781.25 | L26: ='Program Budget'!N146 -> 12 | M26: ='Program Budget'!M146 -> 0.05 | N26: =K26*L26*M26 -> 8268.75 | O26: =K26*1.05 -> 14470.312 | P26: ='Program Budget'!Q146 -> 12 | Q26: ='Program Budget'!P146 -> 0.05 | R26: =O26*P26*Q26 -> 8682.1875 | S26: =O26*1.05 -> 15193.828 | T26: ='Program Budget'!T146 -> 0 | U26: ='Program Budget'!S146 -> 0 | V26: =S26*T26*U26 -> 0 | W26: =F26+J26+N26+R26+V26 -> 30825.938
A27: ='Program Budget'!D28 -> Associate Director | B27: ='Program Budget'!F147 -> Month | C27: ='Program Budget'!H147 -> 7500 | D27: ='Program Budget'!G147 -> 12 | E27: ='Program Budget'!E147 -> 0.05 | F27: =C27*D27*E27 -> 4500 | G27: =C27*1.05 -> 7875 | H27: ='Program Budget'!K147 -> 12 | I27: ='Program Budget'!J147 -> 0.2 | J27: =G27*H27*I27 -> 18900 | K27: =G27*1.05 -> 8268.75 | L27: ='Program Budget'!N147 -> 12 | M27: ='Program Budget'!M147 -> 0.2 | N27: =K27*L27*M27 -> 19845 | O27: =K27*1.05 -> 8682.1875 | P27: ='Program Budget'!Q147 -> 12 | Q27: ='Program Budget'!P147 -> 0.2 | R27: =O27*P27*Q27 -> 20837.25 | S27: =O27*1.05 -> 9116.2969 | T27: ='Program Budget'!T147 -> 0 | U27: ='Program Budget'!S147 -> 0 | V27: =S27*T27*U27 -> 0 | W27: =F27+J27+N27+R27+V27 -> 64082.25
A28: ='Program Budget'!D29 -> Compliance & Contracts Director | B28: ='Program Budget'!F148 -> Month | C28: ='Program Budget'!H148 -> 9166.6667 | D28: ='Program Budget'!G148 -> 12 | E28: ='Program Budget'!E148 -> 0.04 | F28: =C28*D28*E28 -> 4400 | G28: =C28*1.05 -> 9625 | H28: ='Program Budget'!K148 -> 12 | I28: ='Program Budget'!J148 -> 0.05 | J28: =G28*H28*I28 -> 5775 | K28: =G28*1.05 -> 10106.25 | L28: ='Program Budget'!N148 -> 12 | M28: ='Program Budget'!M148 -> 0.05 | N28: =K28*L28*M28 -> 6063.75 | O28: =K28*1.05 -> 10611.562 | P28: ='Program Budget'!Q148 -> 12 | Q28: ='Program Budget'!P148 -> 0.05 | R28: =O28*P28*Q28 -> 6366.9375 | S28: =O28*1.05 -> 11142.141 | T28: ='Program Budget'!T148 -> 0 | U28: ='Program Budget'!S148 -> 0 | V28: =S28*T28*U28 -> 0 | W28: =F28+J28+N28+R28+V28 -> 22605.688
