Workbook
Name Category: #N/A
Name Category: #N/A
Name Category: #N/A
Name Category: 'Project Budget'!$G$16:$G$208
Name DL_Country: #N/A
Name DL_Country: #N/A
Name DL_Country: #N/A
Name DL_Country: 'Project Budget'!#REF!
Name DL_TotalDOL: #N/A
Name DL_TotalDOL: #N/A
Name DL_TotalDOL: #N/A
Name DL_TotalDOL: 'Project Budget'!$R$15:$R$35
Name EQ_Country: #N/A
Name EQ_Country: #N/A
Name EQ_Country: #N/A
Name EQ_Country: 'Project Budget'!#REF!
Name EQ_TotalDOL: #N/A
Name EQ_TotalDOL: #N/A
Name EQ_TotalDOL: #N/A
Name EQ_TotalDOL: 'Project Budget'!#REF!
Name inf: #N/A
Name inf: #N/A
Name inf: #N/A
Name inf: #REF!
Name JEA_Country: #N/A
Name JEA_Country: #N/A
Name JEA_Country: #N/A
Name JEA_Country: #REF!
Name JEA_Year1: #N/A
Name JEA_Year1: #N/A
Name JEA_Year1: #N/A
Name JEA_Year1: #REF!
Name ME_Country: #N/A
Name ME_Country: #N/A
Name ME_Country: #N/A
Name ME_Country: 'Project Budget'!#REF!
Name ME_TotalDOL: #N/A
Name ME_TotalDOL: #N/A
Name ME_TotalDOL: #N/A
Name ME_TotalDOL: 'Project Budget'!$R$179:$R$192
Name O1_Country: #N/A
Name O1_Country: #N/A
Name O1_Country: #N/A
Name O1_Country: 'Project Budget'!#REF!
Name O1_TotalDOL: #N/A
Name O1_TotalDOL: #N/A
Name O1_TotalDOL: #N/A
Name O1_TotalDOL: 'Project Budget'!$R$85:$R$85
Name O2_Country: #N/A
Name O2_Country: #N/A
Name O2_Country: #N/A
Name O2_Country: 'Project Budget'!#REF!
Name O2_TotalDOL: #N/A
Name O2_TotalDOL: #N/A
Name O2_TotalDOL: #N/A
Name O2_TotalDOL: 'Project Budget'!#REF!
Name SU_Country: #N/A
Name SU_Country: #N/A
Name SU_Country: #N/A
Name SU_Country: 'Project Budget'!#REF!

Sheet Budget Summary
B1: Advancing Labor Compliance in Colombia’s Port Sector
B2: FOA-ILAB-20-09
B3: Partners of the Americas
B4: BUDGET ITEM | C4: TOTAL DOL | D4: TOTAL COST SHARING | E4: PROJECT GRAND TOTAL
B5: Direct Labor | C5: ='Project Budget'!R37 -> 1688340.4 | D5: ='Project Budget'!S37 -> 0 | E5: =SUM(C5:D5) -> 1688340.4
B6: Travel | C6: ='Project Budget'!R59 -> 71509.611 | D6: ='Project Budget'!S59 -> 0 | E6: =SUM(C6:D6) -> 71509.611
B7: Equipment | C7: ='Project Budget'!R62 -> 0 | D7: ='Project Budget'!S62 -> 0 | E7: =SUM(C7:D7) -> 0
B8: Supplies and Office Expenses | C8: ='Project Budget'!R81 -> 278250.22 | D8: ='Project Budget'!S81 -> 0 | E8: =SUM(C8:D8) -> 278250.22
B9: Outcome 1 | C9: ='Project Budget'!R98 -> 545426.32 | D9: ='Project Budget'!S98 -> 0 | E9: =SUM(C9:D9) -> 545426.32
B10: Outcome 2 | C10: ='Project Budget'!R123 -> 312200.36 | D10: ='Project Budget'!S142 -> 0 | E10: =SUM(C10:D10) -> 312200.36
B11: Outcome 3 | C11: ='Project Budget'!R142 -> 663288.23 | D11: ='Project Budget'!S142 -> 0 | E11: ='Project Budget'!T142 -> 663288.23
B12: Outcome 4 | C12: ='Project Budget'!R175 -> 131152.04 | D12: ='Project Budget'!S175 -> 0 | E12: ='Project Budget'!T175 -> 131152.04
B13: Monitoring, Evaluation, and Collection of Reliable Data | C13: ='Project Budget'!R204 -> 195138.32 | D13: ='Project Budget'!S204 -> 0 | E13: =SUM(C13:D13) -> 195138.32
B14: Total Direct Costs | C14: =SUM(C5:C13) -> 3885305.5 | D14: =SUM(D5:D13) -> 0 | E14: =SUM(E5:E13) -> 3885305.5
B15: Indirect Costs (NICRA) | C15: ='Project Budget'!R208 -> 1114694.1 | D15: ='Project Budget'!S208 -> 0 | E15: =SUM(C15:D15) -> 1114694.1
B16: TOTAL COSTS | C16: =C15+C14 -> 4999999.6 | D16: =D15+D14 -> 0 | E16: =E15+E14 -> 4999999.6
B18: ADMINISTRATIVE COSTS (Direct Labor, Equipment, Supplies, Indirect Costs) | C18: =C5+C7+C8+C15 -> 3081284.7
B19: PROGRAM COSTS (Travel, Contractual, Other Direct Costs) | C19: =C6+C9+C10+C11+C12+C13 -> 1918714.9

Sheet Project Budget
F1: Equal Access to Quality Jobs for Women and Girls in Agriculture (EQUAL)
F2: FOA-ILAB-19-02
G3: Advancing Labor Compliance in Colombia’s Port Sector
A4: Entity: | B4: P | F4: Partners of the Americas
A5: Program-Dept.: | B5: 20200 | F5: NOFO: FOA-ILAB-20-09
A6: Funder-Grant: | B6: DOL422 | F6: Duration: 4 Years
F7: Country: Colombia
F8: Budget Assumptions:
F9: Inflation - US Based Goods/Services | G9: 1.03
F10: Inflation - Locally Purchased Goods/Services | G10: 1.05
F11: Merit Based Increases for HQ & Field Staff | G11: 1.035
A13: Sage Activity | B13: Sage Object Code/ Line Item | C13: Country Code (DC=0 or CO) | D13: Office Code (DC=0 or CO) | E13: Subcontract Code | F13: BUDGET ITEM | G13: CATEGORY | H13: UNIT | I13: # of Units | J13: RATE / UNIT | K13: YEAR 1 | L13: # of Units | M13: YEAR 2 | N13: # of Units | O13: YEAR 3 | P13: # of Units | Q13: YEAR 4 | R13: TOTAL DOL | S13: TOTAL COST SHARING | T13: PROJECT GRAND TOTAL
F14: Direct Labor
F15: Key Personnel
A16: PERSNL-PD | B16: Timesheets | C16: USA | D16: USA | E16: 0 | F16: Project Director (90%) | G16: Salaries | H16: Month | I16: 12 | J16: =5630*0.9 -> 5067 | K16: =I16*J16 -> 60804 | L16: 12 | M16: =L16*J16*$G$11 -> 62932.14 | N16: 12 | O16: =N16*J16*$G$11*$G$11 -> 65134.765 | P16: 12 | Q16: =P16*J16*$G$11*$G$11*$G$11 -> 67414.482 | R16: =SUM(K16+M16+O16+Q16) -> 256285.39 | S16: 0 | T16: =SUM(R16:S16) -> 256285.39
A17: PERSNL-M&E | B17: 70000 | C17: COL2 | D17: COL2 | E17: 0 | F17: Monitoring and Evaluation (M&E) Officer (100%) | G17: Salaries | H17: Month | I17: 11 | J17: 3300 | K17: =I17*J17 -> 36300 | L17: 12 | M17: =L17*J17*$G$11 -> 40986 | N17: 12 | O17: =N17*J17*$G$11*$G$11 -> 42420.51 | P17: 12 | Q17: =P17*J17*$G$11*$G$11*$G$11 -> 43905.228 | R17: =SUM(K17+M17+O17+Q17) -> 163611.74 | S17: 0 | T17: =SUM(R17:S17) -> 163611.74
F19: Other Professional Personnel
A20: PERSNL-DPD | B20: 70000 | C20: COL2 | D20: COL2 | E20: 0 | F20: Deputy Project Director (100%) | G20: Salaries | H20: Month | I20: 10 | J20: 3500 | K20: =I20*J20 -> 35000 | L20: 12 | M20: =L20*J20*$G$11 -> 43470 | N20: 12 | O20: =N20*J20*$G$11*$G$11 -> 44991.45 | P20: 10 | Q20: =P20*J20*$G$11*$G$11*$G$11 -> 38805.126 | R20: =SUM(K20+M20+O20+Q20) -> 162266.58 | S20: 0 | T20: =SUM(R20:S20) -> 162266.58
A21: PERSNL-COM | B21: 70000 | C21: COL2 | D21: COL2 | E21: 0 | F21: Communications Officer (50%) | G21: Salaries | H21: Month | I21: 10 | J21: =2600*0.5 -> 1300 | K21: =I21*J21 -> 13000 | L21: 12 | M21: =L21*J21*$G$11 -> 16146 | N21: 12 | O21: =N21*J21*$G$11*$G$11 -> 16711.11 | P21: 9 | Q21: =P21*J21*$G$11*$G$11*$G$11 -> 12971.999 | R21: =SUM(K21+M21+O21+Q21) -> 58829.109 | S21: 0 | T21: =SUM(R21:S21) -> 58829.109
A22: PERSNL-POB | B22: 70000 | C22: COL2 | D22: COL2 | E22: 0 | F22: Stakeholder Engagement and Partnership Officer in Buenaventura/Cali (100%) | G22: Salaries | H22: Month | I22: 10 | J22: 3400 | K22: =I22*J22 -> 34000 | L22: 12 | M22: =L22*J22*$G$11 -> 42228 | N22: 12 | O22: =N22*J22*$G$11*$G$11 -> 43705.98 | P22: 9 | Q22: =P22*J22*$G$11*$G$11*$G$11 -> 33926.767 | R22: =SUM(K22+M22+O22+Q22) -> 153860.75 | S22: 0 | T22: =SUM(R22:S22) -> 153860.75
A23: PERSNL-POC | B23: 70000 | C23: COL2 | D23: COL2 | E23: 0 | F23: Stakeholder Engagement and Partnership Officer in Cartagena (100%) | G23: Salaries | H23: Month | I23: 0 | J23: 3000 | K23: =I23*J23 -> 0 | L23: 12 | M23: =L23*J23*$G$11 -> 37260 | N23: 12 | O23: =N23*J23*$G$11*$G$11 -> 38564.1 | P23: 9 | Q23: =P23*J23*$G$11*$G$11*$G$11 -> 29935.383 | R23: =SUM(K23+M23+O23+Q23) -> 105759.48 | S23: 0 | T23: =SUM(R23:S23) -> 105759.48
A24: PERSNL-F&A | B24: 70000 | C24: COL2 | D24: COL2 | E24: 0 | F24: Finance and Administration Manager (100%) | G24: Salaries | H24: Month | I24: 11 | J24: 2000 | K24: =I24*J24 -> 22000 | L24: 12 | M24: =L24*J24*$G$11 -> 24840 | N24: 12 | O24: =N24*J24*$G$11*$G$11 -> 25709.4 | P24: 12 | Q24: =P24*J24*$G$11*$G$11*$G$11 -> 26609.229 | R24: =SUM(K24+M24+O24+Q24) -> 99158.629 | S24: 0 | T24: =SUM(R24:S24) -> 99158.629
F26: Home Office Support
A27: PERSNL-PM | B27: Timesheets | C27: USA | D27: USA | E27: 0 | F27: Project Manager (10%) | G27: Salaries | H27: Month | I27: 12 | J27: =9334*0.1 -> 933.4 | K27: =I27*J27 -> 11200.8 | L27: 12 | M27: =L27*J27*$G$11 -> 11592.828 | N27: 12 | O27: =N27*J27*$G$11*$G$11 -> 11998.577 | P27: 12 | Q27: =P27*J27*$G$11*$G$11*$G$11 -> 12418.527 | R27: =SUM(K27+M27+O27+Q27) -> 47210.732 | S27: 0 | T27: =SUM(R27:S27) -> 47210.732
A28: PERSNL-PO | B28: Timesheets | C28: USA | D28: USA | E28: 0 | F28: Program Officer (40%) | G28: Salaries | H28: Month | I28: 12 | J28: =5200*0.4 -> 2080 | K28: =I28*J28 -> 24960 | L28: 12 | M28: =L28*J28*$G$11 -> 25833.6 | N28: 12 | O28: =N28*J28*$G$11*$G$11 -> 26737.776 | P28: 12 | Q28: =P28*J28*$G$11*$G$11*$G$11 -> 27673.598 | R28: =SUM(K28+M28+O28+Q28) -> 105204.97 | S28: 0 | T28: =SUM(R28:S28) -> 105204.97
F30: Subtotal | K30: =SUM(K16:K28) -> 237264.8 | M30: =SUM(M16:M28) -> 305288.57 | O30: =SUM(O16:O28) -> 315973.67 | Q30: =SUM(Q16:Q28) -> 293660.34 | R30: =SUM(K30+M30+O30+Q30) -> 1152187.4 | S30: 0 | T30: =SUM(R30:S30) -> 1152187.4
F32: Fringe Benefits
A33: FRINGE-CO | B33: 70015 | C33: COL2 | D33: COL2 | E33: 0 | F33: Fringe Benefits CCN - Colombia (above $3,204 monthly) | G33: Fringe Benefits | J33: 0.53864 | K33: =SUM(K16+K17+K20+K22)*$J$33 -> 89470.259 | M33: =SUM(M16+M17+M20+M22)*$J$33 -> 102134.84 | O33: =SUM(O16+O17+O20+O22)*$J$33 -> 105709.56 | Q33: =SUM(Q16+Q17+Q20+Q22)*$J$33 -> 99137.555 | R33: =SUM(K33+M33+O33+Q33) -> 396452.21 | S33: 0 | T33: =SUM(R33:S33) -> 396452.21
A34: FRINGE-CO | B34: 70015 | C34: COL2 | D34: COL2 | E34: 0 | F34: Fringe Benefits CCN - Colombia (below $3,204 monthly) | G34: Fringe Benefits | J34: 0.40364 | K34: =SUM(K21,K23,K24)*$J$34 -> 14127.4 | M34: =SUM(M21,M23,M24)*$J$34 -> 31583.215 | O34: =SUM(O21,O23,O24)*$J$34 -> 32688.628 | Q34: =SUM(Q21,Q23,Q24)*$J$34 -> 28059.685 | R34: =SUM(K34+M34+O34+Q34) -> 106458.93 | S34: 0 | T34: =SUM(R34:S34) -> 106458.93
A35: FRINGE | B35: 50900 | C35: USA | D35: USA | E35: 0 | F35: Fringe benefits - Home Office Support | G35: Fringe Benefits | J35: 0.2181 | K35: =SUM(K27:K28)*$J$35 -> 7886.6705 | M35: =SUM(M27:M28)*$J$35 -> 8162.7039 | O35: =SUM(O27:O28)*$J$35 -> 8448.3986 | Q35: =SUM(Q27:Q28)*$J$35 -> 8744.0925 | R35: =SUM(K35+M35+O35+Q35) -> 33241.866 | S35: 0 | T35: =SUM(R35:S35) -> 33241.866
F37: Subtotal Direct Labor | K37: =SUM(K30:K35) -> 348749.13 | M37: =SUM(M30:M35) -> 447169.33 | O37: =SUM(O30:O35) -> 462820.25 | Q37: =SUM(Q30:Q35) -> 429601.67 | R37: =K37+M37+O37+Q37 -> 1688340.4 | S37: =SUM(S30:S35) -> 0 | T37: =SUM(R37:S37) -> 1688340.4
F38: Travel
F39: T1: Post-award Meeting with ILAB
A40: CP.T1.A | B40: 86040 | C40: COL2 | D40: COL2 | E40: 0 | F40: Airfare - Colombia-DC | G40: Travel | H40: Trip | I40: 2 | J40: 750 | K40: =I40*J40 -> 1500 | L40: 0 | M40: =L40*J40*$G$9 -> 0 | N40: 0 | O40: =N40*J40*$G$9*$G$9 -> 0 | P40: 0 | Q40: =P40*J40*$G$9*$G$9*$G$9 -> 0 | R40: =K40+M40+O40+Q40 -> 1500 | S40: - | T40: =SUM(R40:S40) -> 1500
A41: CP.T1.B | B41: 86030 (Lodging)/ 86050 (M&IE) | C41: COL2 | D41: COL2 | E41: 0 | F41: Lodging and M&IE in DC | G41: Travel | H41: Day | I41: =5*2 -> 10 | J41: =68.4+210 -> 278.4 | K41: =I41*J41 -> 2784 | L41: 0 | M41: =L41*J41*$G$9 -> 0 | N41: 0 | O41: =N41*J41*$G$9*$G$9 -> 0 | P41: 0 | Q41: =P41*J41*$G$9*$G$9*$G$9 -> 0 | R41: =K41+M41+O41+Q41 -> 2784 | S41: - | T41: =SUM(R41:S41) -> 2784
A42: CP.T1.C | B42: 86000 | C42: COL2 | D42: COL2 | E42: 0 | F42: Local transportation in DC | G42: Travel | H42: Day | I42: 5 | J42: 25 | K42: =I42*J42 -> 125 | L42: 0 | M42: =L42*J42*$G$9 -> 0 | N42: 0 | O42: =N42*J42*$G$9*$G$9 -> 0 | P42: 0 | Q42: =P42*J42*$G$9*$G$9*$G$9 -> 0 | R42: =K42+M42+O42+Q42 -> 125 | S42: - | T42: =SUM(R42:S42) -> 125
A43: CP.T1.D | B43: 86050 | C43: COL2 | D43: COL2 | E43: 0 | F43: U.S. Visa Fees | G43: Travel | H43: Trip | I43: 2 | J43: 160 | K43: =I43*J43 -> 320 | L43: 0 | M43: =L43*J43*$G$9 -> 0 | N43: 0 | O43: =N43*J43*$G$9*$G$9 -> 0 | P43: 0 | Q43: =P43*J43*$G$9*$G$9*$G$9 -> 0 | R43: =K43+M43+O43+Q43 -> 320 | S43: - | T43: =SUM(R43:S43) -> 320
F44: T2: Field Personnel Annual Visits with ILAB
A45: CP.T2.A | B45: 86040 | C45: COL2 | D45: COL2 | E45: 0 | F45: Airfare - Colombia-DC | G45: Travel | H45: Trip | I45: 0 | J45: 750 | K45: =I45*J45 -> 0 | L45: 1 | M45: =L45*J45*$G$9 -> 772.5 | N45: 2 | O45: =N45*J45*$G$9*$G$9 -> 1591.35 | P45: 1 | Q45: =P45*J45*$G$9*$G$9*$G$9 -> 819.54525 | R45: =K45+M45+O45+Q45 -> 3183.3953 | S45: - | T45: =SUM(R45:S45) -> 3183.3953
A46: CP.T2.B | B46: 86030 (Lodging)/ 86050 (M&IE) | C46: COL2 | D46: COL2 | E46: 0 | F46: Lodging and M&IE in DC | G46: Travel | H46: Day | I46: 0 | J46: =68.4+210 -> 278.4 | K46: =I46*J46 -> 0 | L46: 7 | M46: =L46*J46*$G$9 -> 2007.264 | N46: 14 | O46: =N46*J46*$G$9*$G$9 -> 4134.9638 | P46: 7 | Q46: =P46*J46*$G$9*$G$9*$G$9 -> 2129.5064 | R46: =K46+M46+O46+Q46 -> 8271.7342 | S46: - | T46: =SUM(R46:S46) -> 8271.7342
...

Sheet SAI
A1: Name of Project: Advancing Labor Compliance in Colombia’s Port Sector
A2: Name of Subawardee: Social Accountability International (SAI)
A3: Subaward Budget
A4: Budget Assumptions:
A5: Inflation - US Based Goods/Services | B5: 1.03
A6: Inflation - Locally Purchased Goods/Services | B6: 1.05
A7: Merit Based Increases for HQ Staff | B7: 1.03
A8: Merit Based Increases for Field Staff | B8: 1.035
A10: BUDGET ITEM | B10: COUNTRY | C10: CATEGORY | D10: UNIT | E10: # of Units | F10: RATE/ UNIT | G10: YEAR 1 | H10: # of Units | I10: YEAR 2 | J10: # of Units | K10: YEAR 3 | L10: # of Units | M10: YEAR 4 | N10: TOTAL SAI | O10: TOTAL COST SHARING | P10: PROJECT GRAND TOTAL
A12: Direct Labor
A13: Field Personnel (include Level of Effort (LOE))
A14: Trainer & Facilitator 1 | B14: Colombia | C14: Salaries | D14: Day | E14: =5*6 -> 30 | F14: 300 | G14: =E14*F14 -> 9000 | H14: =10*12 -> 120 | I14: =H14*F14*$B$8 -> 37260 | J14: 120 | K14: =J14*F14*$B$8*$B$8 -> 38564.1 | L14: =11.5*12 -> 138 | M14: =L14*F14*$B$8*$B$8*$B$8 -> 45900.92 | N14: =SUM(G14+I14+K14+M14) -> 130725.02 | O14: 0 | P14: =SUM(N14:O14) -> 130725.02
A15: Trainer & Facilitator 2 | B15: Colombia | C15: Salaries | D15: Day | E15: =5*6 -> 30 | F15: 300 | G15: =E15*F15 -> 9000 | H15: =10*12 -> 120 | I15: =H15*F15*$B$8 -> 37260 | J15: 120 | K15: =J15*F15*$B$8*$B$8 -> 38564.1 | L15: =11.5*12 -> 138 | M15: =L15*F15*$B$8*$B$8*$B$8 -> 45900.92 | N15: =SUM(G15+I15+K15+M15) -> 130725.02 | O15: 0 | P15: =SUM(N15:O15) -> 130725.02
A16: Trainer & Facilitator 3 | B16: Costa Rica | C16: Salaries | D16: Day | E16: =5*3 -> 15 | F16: 350 | G16: =E16*F16 -> 5250 | H16: =5*3 -> 15 | I16: =H16*F16*$B$8 -> 5433.75 | J16: =5*3 -> 15 | K16: =J16*F16*$B$8*$B$8 -> 5623.9312 | L16: 0 | M16: =L16*F16*$B$8*$B$8*$B$8 -> 0 | N16: =SUM(G16+I16+K16+M16) -> 16307.681 | O16: 0 | P16: =SUM(N16:O16) -> 16307.681
A17: Trainer & Facilitator 4 | B17: Costa Rica | C17: Salaries | D17: Day | E17: =5*3 -> 15 | F17: 550 | G17: =E17*F17 -> 8250 | H17: =5*3 -> 15 | I17: =H17*F17*$B$8 -> 8538.75 | J17: =5*3 -> 15 | K17: =J17*F17*$B$8*$B$8 -> 8837.6062 | L17: 0 | M17: =L17*F17*$B$8*$B$8*$B$8 -> 0 | N17: =SUM(G17+I17+K17+M17) -> 25626.356 | O17: 0 | P17: =SUM(N17:O17) -> 25626.356
A18: HQ Personnel (include Level of Effort (LOE))
A19: Senior Director, Innovations and Capacity Building | B19: USA | C19: Salaries | D19: Day | E19: =2*12 -> 24 | F19: =125000/222 -> 563.06306 | G19: =E19*F19 -> 13513.514 | H19: =2*12 -> 24 | I19: =H19*F19*$B$7 -> 13918.919 | J19: =2*12 -> 24 | K19: =J19*F19*$B$7*$B$7 -> 14336.486 | L19: =2*12 -> 24 | M19: =L19*F19*$B$7*$B$7*$B$7 -> 14766.581 | N19: =SUM(G19+I19+K19+M19) -> 56535.5 | O19: 0 | P19: =SUM(N19:O19) -> 56535.5
A20: Associate Director, Innovations and Partnerships | B20: USA | C20: Salaries | D20: Day | E20: =4*10 -> 40 | F20: =100000/218 -> 458.7156 | G20: =E20*F20 -> 18348.624 | H20: =3*12 -> 36 | I20: =H20*F20*$B$7 -> 17009.174 | J20: =2*12 -> 24 | K20: =J20*F20*$B$7*$B$7 -> 11679.633 | L20: =2*12 -> 24 | M20: =L20*F20*$B$7*$B$7*$B$7 -> 12030.022 | N20: =SUM(G20+I20+K20+M20) -> 59067.453 | O20: 0 | P20: =SUM(N20:O20) -> 59067.453
A21: Manager, Innovations & Corporate Programs | B21: USA | C21: Salaries | D21: Day | E21: =1*12 -> 12 | F21: =70000/222 -> 315.31532 | G21: =E21*F21 -> 3783.7838 | H21: =1*12 -> 12 | I21: =H21*F21*$B$7 -> 3897.2973 | J21: =1*12 -> 12 | K21: =J21*F21*$B$7*$B$7 -> 4014.2162 | L21: =1*12 -> 12 | M21: =L21*F21*$B$7*$B$7*$B$7 -> 4134.6427 | N21: =SUM(G21+I21+K21+M21) -> 15829.94 | O21: 0 | P21: =SUM(N21:O21) -> 15829.94
A22: Manager, Stakeholder Relations | B22: USA | C22: Salaries | D22: Day | E22: =1*10 -> 10 | F22: =70000/222 -> 315.31532 | G22: =E22*F22 -> 3153.1532 | H22: =2*12 -> 24 | I22: =H22*F22*$B$7 -> 7794.5946 | J22: =1*12 -> 12 | K22: =J22*F22*$B$7*$B$7 -> 4014.2162 | L22: 10 | M22: =L22*F22*$B$7*$B$7*$B$7 -> 3445.5356 | N22: =SUM(G22+I22+K22+M22) -> 18407.5 | O22: 0 | P22: =SUM(N22:O22) -> 18407.5
A23: Manager, Operations | B23: USA | C23: Salaries | D23: Day | E23: =2*10 -> 20 | F23: =70000/222 -> 315.31532 | G23: =E23*F23 -> 6306.3063 | H23: =1*12 -> 12 | I23: =H23*F23*$B$7 -> 3897.2973 | J23: =1*12 -> 12 | K23: =J23*F23*$B$7*$B$7 -> 4014.2162 | L23: =1*12 -> 12 | M23: =L23*F23*$B$7*$B$7*$B$7 -> 4134.6427 | N23: =SUM(G23+I23+K23+M23) -> 18352.463 | O23: 0 | P23: =SUM(N23:O23) -> 18352.463
A25: Subtotal | G25: =SUM(G14:G23) -> 76605.381 | I25: =SUM(I14:I23) -> 135009.78 | K25: =SUM(K14:K23) -> 129648.51 | M25: =SUM(M14:M23) -> 130313.26 | N25: =SUM(G25+I25+K25+M25) -> 471576.93 | O25: 0 | P25: =SUM(N25:O25) -> 471576.93
A27: Fringe Benefits
A28: Fringe benefits HQ Support | C28: Fringe Benefits | F28: 0.29 | G28: =F28*SUM(G19:G23) -> 13080.56 | I28: =F28*SUM(I19:I23) -> 13490.012 | K28: =F28*SUM(K19:K23) -> 11037.043 | M28: =F28*SUM(M19:M23) -> 11168.313 | N28: =SUM(G28+I28+K28+M28) -> 48775.928 | O28: 0 | P28: =SUM(N28:O28) -> 48775.928
E29: 5
A30: Subtotal Direct Labor | G30: =SUM(G25:G28) -> 89685.941 | I30: =SUM(I25:I28) -> 148499.79 | K30: =SUM(K25:K28) -> 140685.55 | M30: =SUM(M25:M28) -> 141481.58 | N30: =G30+I30+K30+M30 -> 520352.86 | O30: =SUM(O13:O28) -> 0 | P30: =SUM(N30:O30) -> 520352.86
A32: Travel
A33: HQ Trips to Colombia
A34: Airfare NYC-Colombia (Bogota/Buenaventura/Cartagena) | C34: Travel | D34: Trip | E34: 1 | F34: 400 | G34: =E34*F34 -> 400 | H34: 1 | I34: =H34*F34*$B$6 -> 420 | J34: 1 | K34: =J34*F34*$B$6*$B$6 -> 441 | L34: 1 | M34: =L34*F34*$B$6*$B$6*$B$6 -> 463.05 | N34: =G34+I34+K34+M34 -> 1724.05 | O34: - | P34: =SUM(N34:O34) -> 1724.05
A35: Airfare Cartagena-Buenaventura | C35: Travel | D35: Trip | E35: 1 | F35: 60 | G35: =E35*F35 -> 60 | H35: 1 | I35: =H35*F35*$B$6 -> 63 | J35: 1 | K35: =J35*F35*$B$6*$B$6 -> 66.15 | L35: 1 | M35: =L35*F35*$B$6*$B$6*$B$6 -> 69.4575 | N35: =G35+I35+K35+M35 -> 258.6075 | O35: - | P35: =SUM(N35:O35) -> 258.6075
A36: Lodging and M&IE - Colombia (Bogota/Buenaventura/Cartagena) | C36: Travel | D36: Day | E36: 7 | F36: =200+99 -> 299 | G36: =E36*F36 -> 2093 | H36: 7 | I36: =H36*F36*$B$6 -> 2197.65 | J36: 7 | K36: =J36*F36*$B$6*$B$6 -> 2307.5325 | L36: 7 | M36: =L36*F36*$B$6*$B$6*$B$6 -> 2422.9091 | N36: =G36+I36+K36+M36 -> 9021.0916 | O36: - | P36: =SUM(N36:O36) -> 9021.0916
A37: Ground Transportation | C37: Travel | D37: Day | E37: 7 | F37: 25 | G37: =E37*F37 -> 175 | H37: 7 | I37: =H37*F37*$B$6 -> 183.75 | J37: 7 | K37: =J37*F37*$B$6*$B$6 -> 192.9375 | L37: 7 | M37: =L37*F37*$B$6*$B$6*$B$6 -> 202.58438 | N37: =G37+I37+K37+M37 -> 754.27188 | O37: - | P37: =SUM(N37:O37) -> 754.27188
A38: Field Personnel Trips in Colombia (field personnel based in Bogota)
A39: Airfare Bogota-Buenaventura | C39: Travel | D39: Trip | E39: 5 | F39: 70 | G39: =E39*F39 -> 350 | H39: 6 | I39: =H39*F39*$B$6 -> 441 | J39: 4 | K39: =J39*F39*$B$6*$B$6 -> 308.7 | L39: 2 | M39: =L39*F39*$B$6*$B$6*$B$6 -> 162.0675 | N39: =G39+I39+K39+M39 -> 1261.7675 | O39: - | P39: =SUM(N39:O39) -> 1261.7675
A40: Airfare Bogota-Cartagena | C40: Travel | D40: Trip | E40: 5 | F40: 60 | G40: =E40*F40 -> 300 | H40: 6 | I40: =H40*F40*$B$6 -> 378 | J40: 4 | K40: =J40*F40*$B$6*$B$6 -> 264.6 | L40: 2 | M40: =L40*F40*$B$6*$B$6*$B$6 -> 138.915 | N40: =G40+I40+K40+M40 -> 1081.515 | O40: - | P40: =SUM(N40:O40) -> 1081.515
A41: Lodging and M&IE - Buenaventura | C41: Travel | D41: Day | E41: =5*5 -> 25 | F41: =96+55 -> 151 | G41: =E41*F41 -> 3775 | H41: =6*5 -> 30 | I41: =H41*F41*$B$6 -> 4756.5 | J41: =4*5 -> 20 | K41: =J41*F41*$B$6*$B$6 -> 3329.55 | L41: =2*5 -> 10 | M41: =L41*F41*$B$6*$B$6*$B$6 -> 1748.0138 | N41: =G41+I41+K41+M41 -> 13609.064 | O41: - | P41: =SUM(N41:O41) -> 13609.064
A42: Lodging and M&IE - Cartagena | C42: Travel | D42: Day | E42: =5*5 -> 25 | F42: =200+99 -> 299 | G42: =E42*F42 -> 7475 | H42: =6*5 -> 30 | I42: =H42*F42*$B$6 -> 9418.5 | J42: =4*5 -> 20 | K42: =J42*F42*$B$6*$B$6 -> 6592.95 | L42: =2*5 -> 10 | M42: =L42*F42*$B$6*$B$6*$B$6 -> 3461.2988 | N42: =G42+I42+K42+M42 -> 26947.749 | O42: - | P42: =SUM(N42:O42) -> 26947.749
A43: Ground Transportation | C43: Travel | D43: Day | E43: 50 | F43: 25 | G43: =E43*F43 -> 1250 | H43: 60 | I43: =H43*F43*$B$6 -> 1575 | J43: 40 | K43: =J43*F43*$B$6*$B$6 -> 1102.5 | L43: 20 | M43: =L43*F43*$B$6*$B$6*$B$6 -> 578.8125 | N43: =G43+I43+K43+M43 -> 4506.3125 | O43: - | P43: =SUM(N43:O43) -> 4506.3125
A45: Subtotal Travel | G45: =SUM(G33:G43) -> 15878 | I45: =SUM(I33:I43) -> 19433.4 | K45: =SUM(K33:K43) -> 14605.92 | M45: =SUM(M33:M43) -> 9247.1085 | N45: =G45+I45+K45+M45 -> 59164.429 | O45: =SUM(O33:O43) -> 0 | P45: =SUM(N45:O45) -> 59164.429
A46: Supplies - Under $5,000 USD
...

Sheet Fundación Carvajal
A1: Name of Project: Advancing Labor Compliance in Colombia’s Port Sector
A2: Name of Subawardee: Fundación Carvajal
A3: Budget Assumptions:
A5: Inflation - Locally Purchased Goods/Services | B5: 1.05
A7: Merit Based Increases for Field Staff | B7: 1.035
A9: BUDGET ITEM | B9: CATEGORY | C9: UNIT | D9: # of Units | E9: RATE/ UNIT | F9: YEAR 1 | G9: # of Units | H9: YEAR 2 | I9: # of Units | J9: YEAR 3 | K9: # of Units | L9: YEAR 4 | M9: TOTAL FUNDACIÓN CARVAJAL | N9: TOTAL COST SHARING | O9: PROJECT GRAND TOTAL
A11: Direct Labor
A12: Field Personnel
A13: Civil Society Engagement Coordinator (30%) | B13: Salaries | C13: Month | D13: 0 | E13: 615 | F13: =D13*E13 -> 0 | G13: 12 | H13: =G13*E13*$B$7 -> 7638.3 | I13: 12 | J13: =I13*E13 -> 7380 | K13: 0 | L13: =K13*E13 -> 0 | M13: =SUM(F13+H13+J13+L13) -> 15018.3 | N13: 0 | O13: =SUM(M13:N13) -> 15018.3
A14: Social Adviser (100%) | B14: Salaries | C14: Month | D14: 0 | E14: 762 | F14: =D14*E14 -> 0 | G14: 12 | H14: =G14*E14*$B$7 -> 9464.04 | I14: 12 | J14: =I14*E14 -> 9144 | K14: 0 | L14: =K14*E14 -> 0 | M14: =SUM(F14+H14+J14+L14) -> 18608.04 | N14: 0 | O14: =SUM(M14:N14) -> 18608.04
A15: HQ Personnel
A16: Methodological Leader (10%) | B16: Salaries | C16: Month | D16: 0 | E16: 307 | F16: =D16*E16 -> 0 | G16: 10 | H16: =G16*E16*$B$7 -> 3177.45 | I16: 12 | J16: =I16*E16 -> 3684 | K16: 0 | L16: =K16*E16 -> 0 | M16: =SUM(F16+H16+J16+L16) -> 6861.45 | N16: 0 | O16: =SUM(M16:N16) -> 6861.45
A17: Civil Society Mapping Leader (10%) | B17: Salaries | C17: Month | D17: 0 | E17: 108 | F17: =D17*E17 -> 0 | G17: 10 | H17: =G17*E17*$B$7 -> 1117.8 | I17: 12 | J17: =I17*E17 -> 1296 | K17: 0 | L17: =K17*E17 -> 0 | M17: =SUM(F17+H17+J17+L17) -> 2413.8 | N17: 0 | O17: =SUM(M17:N17) -> 2413.8
A19: Subtotal | F19: =SUM(F13:F17) -> 0 | H19: =SUM(H13:H17) -> 21397.59 | J19: =SUM(J13:J17) -> 21504 | L19: =SUM(L13:L17) -> 0 | M19: =SUM(F19+H19+J19+L19) -> 42901.59 | N19: 0 | O19: =SUM(M19:N19) -> 42901.59
A21: Fringe Benefits
A22: Fringe benefits | B22: Fringe Benefits | C22: Month | D22: 0 | E22: 0.53766 | F22: =F19*E22 -> 0 | H22: =H19*E22 -> 11504.628 | J22: =E22*J19 -> 11561.841 | L22: =L19*E22 -> 0 | M22: =SUM(F22+H22+J22+L22) -> 23066.469 | N22: 0 | O22: =SUM(M22:N22) -> 23066.469
A24: Subtotal Direct Labor | F24: =SUM(F19:F22) -> 0 | H24: =SUM(H19:H22) -> 32902.218 | J24: =SUM(J19:J22) -> 33065.841 | L24: =SUM(L19:L22) -> 0 | M24: =F24+H24+J24+L24 -> 65968.059 | N24: =SUM(N12:N22) -> 0 | O24: =SUM(M24:N24) -> 65968.059
A26: Travel
A28: Subtotal Travel | F28: =F2 -> 0 | H28: =H27 -> 0 | J28: =J27 -> 0 | L28: =L27 -> 0 | M28: =F28+H28+J28+L28 -> 0 | N28: =N27 -> 0 | O28: =SUM(M28:N28) -> 0
A29: Supplies and Office Expenses
A30: Laptop computers | B30: Supplies | C30: Unit | D30: 0 | E30: 750 | F30: =D30*E30 -> 0 | G30: 3 | H30: =G30*E30*$B$5 -> 2362.5 | I30: 0 | J30: =(I30*E30)*$B$5*$B$5 -> 0 | K30: 0 | L30: =(K30*E30)*$B$5*$B$5*$B$5 -> 0 | M30: =F30+H30+J30+L30 -> 2362.5 | N30: 0 | O30: =SUM(M30:N30) -> 2362.5
A31: Zoom License | B31: Supplies | C31: Month | D31: 0 | E31: 19 | F31: =D31*E31 -> 0 | G31: 12 | H31: =G31*E31*$B$5 -> 239.4 | I31: 12 | J31: =(I31*E31)*$B$5*$B$5 -> 251.37 | K31: 0 | L31: =(K31*E31)*$B$5*$B$5*$B$5 -> 0 | M31: =F31+H31+J31+L31 -> 490.77 | N31: 0 | O31: =SUM(M31:N31) -> 490.77
A32: Project cellphone | B32: Supplies | C32: Unit | D32: 0 | E32: 500 | F32: =D32*E32 -> 0 | G32: 1 | H32: =G32*E32*$B$5 -> 525 | I32: 0 | J32: =(I32*E32)*$B$5*$B$5 -> 0 | L32: =(K32*E32)*$B$5*$B$5*$B$5 -> 0 | M32: =F32+H32+J32+L32 -> 525 | N32: 0 | O32: =SUM(M32:N32) -> 525
A33: Project cellphone plan | B33: Supplies | C33: Month | D33: 0 | E33: 25 | F33: =D33*E33 -> 0 | G33: 12 | H33: =G33*E33*$B$5 -> 315 | I33: 12 | J33: =(I33*E33)*$B$5*$B$5 -> 330.75 | K33: 0 | L33: =(K33*E33)*$B$5*$B$5*$B$5 -> 0 | M33: =F33+H33+J33+L33 -> 645.75 | N33: 0 | O33: =SUM(M33:N33) -> 645.75
A34: Banking and cash handling fees | B34: Supplies | C34: Month | D34: 0 | E34: 30 | F34: =D34*E34 -> 0 | G34: 12 | H34: =G34*E34*$B$5 -> 378 | I34: 12 | J34: =(I34*E34)*$B$5*$B$5 -> 396.9 | K34: 0 | L34: =(K34*E34)*$B$5*$B$5*$B$5 -> 0 | M34: =F34+H34+J34+L34 -> 774.9 | N34: 0 | O34: =SUM(M34:N34) -> 774.9
A35: Courier fees/services/postage | B35: Supplies | C35: Year | D35: 0 | E35: 100 | F35: =D35*E35 -> 0 | G35: 1 | H35: =G35*E35*$B$5 -> 105 | I35: 1 | J35: =(I35*E35)*$B$5*$B$5 -> 110.25 | K35: 0 | L35: =(K35*E35)*$B$5*$B$5*$B$5 -> 0 | M35: =F35+H35+J35+L35 -> 215.25 | N35: 0 | O35: =SUM(M35:N35) -> 215.25
A36: Recruitment/Procurement Advertising | B36: Supplies | C36: Year | D36: 0 | E36: 81 | F36: =D36*E36 -> 0 | G36: 3 | H36: =G36*E36*$B$5 -> 255.15 | I36: 0 | J36: =(I36*E36)*$B$5*$B$5 -> 0 | K36: 0 | L36: =(K36*E36)*$B$5*$B$5*$B$5 -> 0 | M36: =F36+H36+J36+L36 -> 255.15 | N36: 0 | O36: =SUM(M36:N36) -> 255.15
A37: Project emails and internet | B37: Supplies | C37: Month | D37: 0 | E37: 43 | F37: =D37*E37 -> 0 | G37: 12 | H37: =G37*E37*$B$5 -> 541.8 | I37: 12 | J37: =(I37*E37)*$B$5*$B$5 -> 568.89 | K37: 0 | L37: =(K37*E37)*$B$5*$B$5*$B$5 -> 0 | M37: =F37+H37+J37+L37 -> 1110.69 | N37: 0 | O37: =SUM(M37:N37) -> 1110.69
A38: Project office rent | B38: Supplies | C38: Month | D38: 0 | E38: 111 | F38: =D38*E38 -> 0 | G38: 12 | H38: =G38*E38*$B$5 -> 1398.6 | I38: 12 | J38: =(I38*E38)*$B$5*$B$5 -> 1468.53 | K38: 0 | L38: =(K38*E38)*$B$5*$B$5*$B$5 -> 0 | M38: =F38+H38+J38+L38 -> 2867.13 | N38: 0 | O38: =SUM(M38:N38) -> 2867.13
A39: Security Plan expenses | B39: Supplies | C39: Month | D39: 0 | E39: 1000 | F39: =D39*E39 -> 0 | G39: 12 | H39: =G39*E39*$B$5 -> 12600 | I39: 12 | J39: =(I39*E39)*$B$5*$B$5 -> 13230 | K39: 0 | L39: =(K39*E39)*$B$5*$B$5*$B$5 -> 0 | M39: =F39+H39+J39+L39 -> 25830 | N39: 0 | O39: =SUM(M39:N39) -> 25830
A40: Biosecurity kits for project staff | B40: Supplies | C40: Month | D40: 0 | E40: 42 | F40: =D40*E40 -> 0 | G40: 12 | H40: =G40*E40*$B$5 -> 529.2 | I40: 12 | J40: =(I40*E40)*$B$5*$B$5 -> 555.66 | K40: 0 | L40: =(K40*E40)*$B$5*$B$5*$B$5 -> 0 | M40: =F40+H40+J40+L40 -> 1084.86 | N40: 0 | O40: =SUM(M40:N40) -> 1084.86
A42: Subtotal Supplies and Office Expenses | F42: =SUM(F30:F40) -> 0 | H42: =SUM(H30:H40) -> 19249.65 | J42: =SUM(J30:J40) -> 16912.35 | L42: =SUM(L30:L40) -> 0 | M42: =F42+H42+J42+L42 -> 36162 | N42: =SUM(N30:N40) -> 0 | O42: =SUM(M42:N42) -> 36162
A43: The above is only for percentage calculations for the below outcomes
A44: Outcome 2: Development of approaches to support compliance with internationally recognized labor standards in Colombia’s port sector
A45: Activities/Costs
A46: Personnel & Fringe (20% of Direct Labor line item) | B46: Personnel | C46: Unit | D46: =$F$24 -> 0 | E46: 0.25 | F46: =D46*E46 -> 0 | G46: =H24 -> 32902.218 | H46: =G46*E46 -> 8225.5546 | I46: =$J$24 -> 33065.841 | J46: =I46*E46 -> 8266.4602 | K46: =$L$24 -> 0 | L46: =K46*E46 -> 0 | M46: =F46+H46+J46+L46 -> 16492.015 | N46: 0 | O46: =SUM(M46:N46) -> 16492.015
A47: Supplies and Office Expenses 20% | B47: Supplies | C47: Unit | D47: =$F$42 -> 0 | E47: 0.25 | F47: =D47*E47 -> 0 | G47: =H42 -> 19249.65 | H47: =G47*E47 -> 4812.4125 | I47: =$J$42 -> 16912.35 | J47: =I47*E47 -> 4228.0875 | K47: =$L$42 -> 0 | L47: =K47*E47 -> 0 | M47: =F47+H47+J47+L47 -> 9040.5 | N47: 0 | O47: =SUM(M47:N47) -> 9040.5
A48: 2.1.3.1 Socialization of scope of the project with civil society organizations
A49: Initial engagement meetings with civil society organizations | B49: Other | C49: Meeting | D49: 0 | E49: 125 | F49: =D49*E49 -> 0 | G49: 8 | H49: =(G49*E49)*$B$5 -> 1050 | I49: 4 | J49: =(I49*E49)*$B$5*$B$5 -> 551.25 | K49: 0 | L49: =(K49*E49)*$B$5*$B$5*$B$5 -> 0 | M49: =F49+H49+J49+L49 -> 1601.25 | N49: 0 | O49: =SUM(M49:N49) -> 1601.25
A50: 2.1.3.2 Strengthen civil society and worker organizations
...

Sheet Universidad Javeriana
A1: Name of Project: Advancing Labor Compliance in Colombia’s Port Sector
A2: Name of Subawardee: Universidad Javeriana
A3: Subaward Budget
A4: Budget Assumptions:
A5: Inflation - US Based Goods/Services | B5: 1.03
A6: Inflation - Locally Purchased Goods/Services | B6: 1.05
A7: Merit Based Increases for HQ Staff | B7: 1.03
A10: BUDGET ITEM | B10: COUNTRY | C10: CATEGORY | D10: UNIT | E10: # of Units | F10: RATE/ UNIT | G10: YEAR 1 | H10: # of Units | I10: YEAR 2 | J10: # of Units | K10: YEAR 3 | L10: # of Units | M10: YEAR 4 | N10: TOTAL UNIVERSIDAD JAVERIANA | O10: TOTAL COST SHARING | P10: PROJECT GRAND TOTAL
A12: Direct Labor
A13: HQ Personnel (include Level of Effort (LOE))
A14: Project Manager (100%) | C14: Salaries | D14: Month | E14: 10 | F14: 2500 | G14: =E14*F14 -> 25000 | H14: 12 | I14: =((H14*F14)*50%)*$B$7 -> 15450 | J14: 12 | K14: =((J14*F14)*50%)*$B$7*$B$7 -> 15913.5 | L14: 10 | M14: =((L14*F14)*40%)*$B$7*$B$7*$B$7 -> 10927.27 | N14: =SUM(G14+I14+K14+M14) -> 67290.77 | O14: 0 | P14: =SUM(N14:O14) -> 67290.77
A15: Project Academic Coordinator (100%) | C15: Salaries | D15: Month | E15: 10 | F15: 1800 | G15: =E15*F15 -> 18000 | H15: 12 | I15: =((H15*F15)*50%)*$B$7 -> 11124 | J15: 12 | K15: =((J15*F15)*50%)*$B$7*$B$7 -> 11457.72 | L15: 10 | M15: =((L15*F15)*40%)*$B$7*$B$7*$B$7 -> 7867.6344 | N15: =SUM(G15+I15+K15+M15) -> 48449.354 | O15: 0 | P15: =SUM(N15:O15) -> 48449.354
A16: Research Logistic Coordinator (100%) | C16: Salaries | D16: Month | E16: 10 | F16: 1000 | G16: =E16*F16 -> 10000 | H16: 3 | I16: =((H16*F16)*50%)*$B$7 -> 1545 | J16: 0 | K16: =((J16*F16)*50%)*$B$7*$B$7 -> 0 | L16: 0 | M16: =((L16*F16)*40%)*$B$7*$B$7*$B$7 -> 0 | N16: =SUM(G16+I16+K16+M16) -> 11545 | O16: 0 | P16: =SUM(N16:O16) -> 11545
A18: Subtotal | G18: =SUM(G13:G16) -> 53000 | I18: =SUM(I13:I16) -> 28119 | K18: =SUM(K13:K16) -> 27371.22 | M18: =SUM(M13:M16) -> 18794.904 | N18: =SUM(G18+I18+K18+M18) -> 127285.12 | O18: 0 | P18: =SUM(N18:O18) -> 127285.12
A20: Fringe Benefits
A21: Fringe benefits | C21: Fringe Benefits | F21: 0.3164 | G21: =G18*F21 -> 16769.2 | I21: =I18*F21 -> 8896.8516 | K21: =K18*F21 -> 8660.254 | M21: =M18*F21 -> 5946.7078 | N21: =SUM(G21+I21+K21+M21) -> 40273.013 | O21: 0 | P21: =SUM(N21:O21) -> 40273.013
A23: Subtotal Direct Labor | G23: =SUM(G18:G21) -> 69769.2 | I23: =SUM(I18:I21) -> 37015.852 | K23: =SUM(K18:K21) -> 36031.474 | M23: =SUM(M18:M21) -> 24741.612 | N23: =G23+I23+K23+M23 -> 167558.14 | O23: =SUM(O13:O21) -> 0 | P23: =SUM(N23:O23) -> 167558.14
A25: Travel
A27: Subtotal Travel | G27: =G26 -> 0 | I27: =I26 -> 0 | K27: =K26 -> 0 | M27: =M26 -> 0 | N27: =G27+I27+K27+M27 -> 0 | O27: =O26 -> 0 | P27: =SUM(N27:O27) -> 0
A28: Supplies - Under $5,000 USD
A30: Subtotal Supplies | G30: =G29 -> 0 | I30: =I29 -> 0 | K30: =K29 -> 0 | M30: =M29 -> 0 | N30: =G30+I30+K30+M30 -> 0 | O30: =O29 -> 0 | P30: =SUM(N30:O30) -> 0
A31: Office Expenses
A32: Banking and cash handling fees | C32: Office Expenses | D32: Month | E32: 10 | F32: 30 | G32: =E32*F32 -> 300 | H32: 12 | I32: =((H32*F32)*50%)*$B$6 -> 189 | J32: 12 | K32: =((J32*F32)*50%)*$B$6*$B$6 -> 198.45 | L32: 10 | M32: =((L32*F32)*40%)*$B$6*$B$6*$B$6 -> 138.915 | N32: =G32+I32+K32+M32 -> 826.365 | O32: 0 | P32: =SUM(N32:O32) -> 826.365
A33: Office supplies | C33: Office Expenses | D33: Month | E33: 10 | F33: 150 | G33: =E33*F33 -> 1500 | H33: 12 | I33: =((H33*F33)*50%)*$B$6 -> 945 | J33: 12 | K33: =((J33*F33)*50%)*$B$6*$B$6 -> 992.25 | L33: 10 | M33: =((L33*F33)*40%)*$B$6*$B$6*$B$6 -> 694.575 | N33: =G33+I33+K33+M33 -> 4131.825 | O33: 0 | P33: =SUM(N33:O33) -> 4131.825
A34: Security Plan expenses | C34: Office Expenses | D34: Month | E34: 10 | F34: 1000 | G34: =E34*F34 -> 10000 | H34: 12 | I34: =((H34*F34)*50%)*$B$6 -> 6300 | J34: 12 | K34: =((J34*F34)*50%)*$B$6*$B$6 -> 6615 | L34: 10 | M34: =((L34*F34)*40%)*$B$6*$B$6*$B$6 -> 4630.5 | N34: =G34+I34+K34+M34 -> 27545.5 | O34: 0 | P34: =SUM(N34:O34) -> 27545.5
A35: Biosecurity skits for staff | C35: Office Expenses | D35: Month | E35: 10 | F35: 40 | G35: =E35*F35 -> 400 | H35: 12 | I35: =((H35*F35)*50%)*$B$6 -> 252 | J35: 12 | K35: =((J35*F35)*50%)*$B$6*$B$6 -> 264.6 | L35: 10 | M35: =((L35*F35)*40%)*$B$6*$B$6*$B$6 -> 185.22 | N35: =G35+I35+K35+M35 -> 1101.82 | O35: 0 | P35: =SUM(N35:O35) -> 1101.82
A37: Subtotal Office Expenses | G37: =SUM(G32:G35) -> 12200 | I37: =SUM(I32:I35) -> 7686 | K37: =SUM(K32:K35) -> 8070.3 | M37: =SUM(M32:M35) -> 5649.21 | N37: =G37+I37+K37+M37 -> 33605.51 | O37: =SUM(O32:O35) -> 0 | P37: =SUM(N37:O37) -> 33605.51
A38: The above is only for percentage calculations for the below outcomes
A39: Outcome 1: Increased understanding of barriers to compliance with national laws related to internationally recognized labor rights in Colombia’s port sector
A40: Activities/Costs
A41: Personnel and Fringe (25% of Direct Labor line item) | C41: Salaries | D41: Month | E41: =G23 -> 69769.2 | F41: 0.25 | G41: =E41*F41 -> 17442.3 | H41: =I23 -> 37015.852 | I41: =H41*F41 -> 9253.9629 | J41: =K23 -> 36031.474 | K41: =J41*F41 -> 9007.8685 | L41: =M23 -> 24741.612 | M41: =L41*F41 -> 6185.403 | N41: =G41+I41+K41+M41 -> 41889.534 | O41: - | P41: =SUM(N41:O41) -> 41889.534
A42: Office Expenses 25% | C42: Supplies | D42: Month | E42: =G37 -> 12200 | F42: 0.25 | G42: =E42*F42 -> 3050 | H42: =I37 -> 7686 | I42: =H42*F42 -> 1921.5 | J42: =K37 -> 8070.3 | K42: =J42*F42 -> 2017.575 | L42: =M37 -> 5649.21 | M42: =L42*F42 -> 1412.3025 | N42: =G42+I42+K42+M42 -> 8401.3775 | O42: - | P42: =SUM(N42:O42) -> 8401.3775
A43: Labor Research Coordinator | C43: Salaries | D43: Month | E43: 10 | F43: 1800 | G43: =E43*F43 -> 18000 | H43: 0 | I43: =((H43*F43)*50%)*$B$8 -> 0 | J43: 0 | K43: =((J43*F43)*50%)*$B$8*$B$8 -> 0 | L43: 0 | M43: =((L43*F43)*40%)*$B$8*$B$8*$B$8 -> 0 | N43: =G43+I43+K43+M43 -> 18000 | O43: 0 | P43: =SUM(N43:O43) -> 18000
A44: Quantitative Investigator | C44: Salaries | D44: Month | E44: 10 | F44: 1500 | G44: =E44*F44 -> 15000 | H44: 0 | I44: =((H44*F44)*50%)*$B$8 -> 0 | J44: 0 | K44: =((J44*F44)*50%)*$B$8*$B$8 -> 0 | L44: 0 | M44: =((L44*F44)*40%)*$B$8*$B$8*$B$8 -> 0 | N44: =G44+I44+K44+M44 -> 15000 | O44: 0 | P44: =SUM(N44:O44) -> 15000
A45: Field Investigator 1 | C45: Salaries | D45: Month | E45: 10 | F45: 1000 | G45: =E45*F45 -> 10000 | H45: 0 | I45: =((H45*F45)*50%)*$B$8 -> 0 | J45: 0 | K45: =((J45*F45)*50%)*$B$8*$B$8 -> 0 | L45: 0 | M45: =((L45*F45)*40%)*$B$8*$B$8*$B$8 -> 0 | N45: =G45+I45+K45+M45 -> 10000 | O45: 0 | P45: =SUM(N45:O45) -> 10000
A46: Field Investigator 2 | C46: Salaries | D46: Month | E46: 10 | F46: 1000 | G46: =E46*F46 -> 10000 | H46: 0 | I46: =((H46*F46)*50%)*$B$8 -> 0 | J46: 0 | K46: =((J46*F46)*50%)*$B$8*$B$8 -> 0 | L46: 0 | M46: =((L46*F46)*40%)*$B$8*$B$8*$B$8 -> 0 | N46: =G46+I46+K46+M46 -> 10000 | O46: 0 | P46: =SUM(N46:O46) -> 10000
A47: Field Investigator 3 | C47: Salaries | D47: Month | E47: 10 | F47: 1000 | G47: =E47*F47 -> 10000 | H47: 0 | I47: =((H47*F47)*50%)*$B$8 -> 0 | J47: 0 | K47: =((J47*F47)*50%)*$B$8*$B$8 -> 0 | L47: 0 | M47: =((L47*F47)*40%)*$B$8*$B$8*$B$8 -> 0 | N47: =G47+I47+K47+M47 -> 10000 | O47: 0 | P47: =SUM(N47:O47) -> 10000
A48: Fringe benefits - Outcome 1 | C48: Fringe Benefits | F48: 0.3164 | G48: =SUM(G43:G47)*F48 -> 19933.2 | I48: =SUM(I43:I47)*F48 -> 0 | K48: =((J48*F48)*50%)*$B$8*$B$8 -> 0 | M48: =((L48*F48)*40%)*$B$8*$B$8*$B$8 -> 0 | N48: =G48+I48+K48+M48 -> 19933.2 | O48: 0 | P48: =SUM(N48:O48) -> 19933.2
A49: 1.1.1.1 Interviews with port stakeholders for the development of port assessment | P49: =SUM(N49:O49) -> 0
A50: Field personnel - Airfare | C50: Travel | D50: Trip | E50: 6 | F50: 100 | G50: =E50*F50 -> 600 | H50: 0 | I50: =(H50*F50)*$B$6 -> 0 | J50: 0 | K50: =(J50*F50)*$B$6*$B$6 -> 0 | L50: 0 | M50: =(L50*F50)*$B$6*$B$6*$B$6 -> 0 | N50: =G50+I50+K50+M50 -> 600 | O50: - | P50: =SUM(N50:O50) -> 600
...

Sheet SF-424 Cost Categories
B2: Category | C2: TOTAL USDOL
B3: Salaries | C3: =SUMIF(Category,B3,TotalDOL) -> 1152187.4
B4: Fringe Benefits | C4: =SUMIF(Category,"Fringe Benefits",TotalDOL) -> 536153
B5: Travel | C5: =SUMIF(Category,"Travel",TotalDOL) -> 105008.56
B6: Equipment | C6: =SUMIF(Category,"Equipment",TotalDOL) -> 0
B7: Supplies | C7: =SUMIF(Category,"Supplies",TotalDOL) -> 278250.22
B8: Contractual | C8: =SUMIF(Category,"Contractual",TotalDOL) -> 1472575.7
B9: Other Direct Charges | C9: =SUMIF(Category,"Other",TotalDOL) -> 315985.65
B10: Indirect Charges | C10: =SUMIF(Category,"Indirect Charges",TotalDOL) -> 1114694.1
B12: TOTAL | C12: =SUM(C3:C10) -> 4974854.7
