Workbook

Sheet Budget Summary
A1: Partners of the Americas
A2: Education and Culture Program 2021
A3: CFDA 19.415
A4: Budget Summary | B4: Educational and Cultural Affairs | C4: Cost Sharing | D4: Total
A5: Program Costs | B5: ='Budget Details'!G23+'Budget Details'!G47 -> 167772 | C5: ='Budget Details'!H23+'Budget Details'!H47 -> 112276.8 | D5: =B5+C5 -> 280048.8
A6: Program costs per participant | B6: =B5/30 -> 5592.4 | C6: =C5/30 -> 3742.56 | D6: =B6+C6 -> 9334.96
A7: Administrative Costs | B7: ='Budget Details'!G9+'Budget Details'!G12+'Budget Details'!G50 -> 199338.06 | C7: ='Budget Details'!H9+'Budget Details'!H12 -> 0 | D7: =B7+C7 -> 199338.06
A8: Administrative costs per participant | B8: =B7/30 -> 6644.602 | C8: =C7/30 -> 0 | D8: =B8+C8 -> 6644.602
A9: Total Costs | B9: =B5+B7 -> 367110.06 | C9: =C5+C7 -> 112276.8 | D9: =B9+C9 -> 479386.86
A10: Total costs per participant Number of Participants: 30 | B10: =B6+B8 -> 12237.002 | C10: =C6+C8 -> 3742.56 | D10: =B10+C10 -> 15979.562
A14: Budget Categories | B14: Amount
A15: 1. Personnel* | B15: ='Budget Details'!G9 -> 96457.57
A16: 2. Fringe Benefits* | B16: ='Budget Details'!G12 -> 21037.396
A17: 3. Travel | B17: ='Budget Details'!G23 -> 65750
A18: 4. Equipment | B18: ='Budget Details'!G24 -> 0
A19: 5. Supplies* | B19: ='Budget Details'!G25 -> 0
A20: 6. Contractual | B20: ='Budget Details'!G26 -> 0
A21: 7. Construction | B21: ='Budget Details'!G27 -> 0
A22: 8. Other Direct Costs | B22: ='Budget Details'!G47 -> 102022
A23: 9. Total Direct Costs (lines 1-8) | B23: =SUM(B15:B22) -> 285266.97
A24: 10. Indirect Costs* | B24: ='Budget Details'!G50 -> 81843.093
A25: 11. Total Costs (lines 9-10) | B25: =B24+B23 -> 367110.06
A26: 12. Cost-Sharing | B26: ='Budget Details'!H51 -> 112276.8
A27: Program Costs Total | B27: =B17+B22 -> 167772
A28: Administrative Costs Total | B28: =B15+B16+B24 -> 199338.06
A29: *Administrative Costs

Sheet Budget Details
A1: Entity: P | C1: Partners of the Americas
A2: Program-Dept: EC | C2: Education and Culture Program 2021
A3: Funder-Grant: DOS285 | C3: CFDA 19.415
A4: Activity Code | B4: Object Code | C4: Budget Category | D4: 2020 Original ECA Funds Requested | E4: 2020 ECA Revised Funds Requested** | F4: 2020 Actual Expenses | G4: 2021 ECA Funds Requested | H4: 2021 Cost Sharing | I4: 2021 Total Budget | J4: % Change
C5: I. Salaries*
A6: PERSNL | B6: Timesheets | C6: 1. Program Director - $10,070/Month (March 2021 - June 2021 at 5% LOE, and July 2021 - Feb. 2022 at 10% LOE) | D6: 12941 | E6: =(9730*0.05*3)+(9730*0.1*7)+((9730*1.035)*0.1*6) -> 14312.83 | F6: 0 | G6: =(10070*0.05*4)+(10070*0.1*6)+((10070*1.035)*0.1*2) -> 10140.49 | H6: 0 | I6: =SUM(G6:H6) -> 10140.49 | J6: =(G6-E6)/E6 -> -0.29151048
C7: 2. Senior Program Officer - $6,276/Month (March - June 2021 at 50% LOE, and July 2021 - Feb. 2022 at 100% LOE) | D7: 83886 | E7: =(6064*0.2*3)+(6064*0.85*7)+((6064*1.035)*1*4)+((6064*1.035)*0.5*2) -> 71100.4 | F7: 11615.6 | G7: =(6276*0.5*4)+(6276*6)+((6276*1.035)*2) -> 63199.32 | H7: 0 | I7: =SUM(G7:H7) -> 63199.32 | J7: =(G7-E7)/E7 -> -0.11112568
C8: 3. Program Assistant - $4,416/Month (March 2021 - June 2021 at 30% LOE, and July 2021 - Feb. 2022 at 50% LOE) | D8: 5882 | E8: =4313*0.2*6 -> 5175.6 | F8: 974.63 | G8: =(4416*0.3*4)+(4416*0.5*6)+((4416*1.035)*0.5*2) -> 23117.76 | H8: 0 | I8: =SUM(G8:H8) -> 23117.76 | J8: =(G8-E8)/E8 -> 3.4666821
C9: Total Salaries | D9: =SUM(D6:D8) -> 102709 | E9: =SUM(E6:E8) -> 90588.83 | F9: =SUM(F6:F8) -> 12590.23 | G9: =SUM(G6:G8) -> 96457.57 | H9: =SUM(H6:H8) -> 0 | I9: =SUM(G9:H9) -> 96457.57 | J9: =(G9-E9)/E9 -> 0.064784367
C10: II. Fringe Benefits*
A11: FRINGE | B11: Timesheets | C11: 0.2181 | D11: =D9*0.2647 -> 27187.072 | E11: =E9*C11 -> 19757.424 | F11: 3587.09 | G11: =G9*C11 -> 21037.396 | H11: =H9*0.2647 -> 0 | I11: =SUM(G11:H11) -> 21037.396 | J11: =(G11-E11)/E11 -> 0.064784367
C12: Total Fringe Benefits | D12: =SUM(D11) -> 27187.072 | E12: =SUM(E11) -> 19757.424 | F12: =SUM(F11) -> 3587.09 | G12: =SUM(G11) -> 21037.396 | H12: =SUM(H11) -> 0 | I12: =SUM(G12:H12) -> 21037.396 | J12: =(G12-E12)/E12 -> 0.064784367
C13: III. Travel
C14: 1. Staff Travel
A15: STFTRAVEL | B15: 7510 | C15: a. Domestic Round Trip Airfare ($500 x 2) | D15: 0 | E15: 0 | F15: 0 | G15: =500*2 -> 1000 | H15: 0 | I15: =SUM(E15:H15) -> 1000 | J15: 1
A16: STFCN DIEM | B16: 7520 | C16: b. Domestic Per Diem ($180 x 5 x 2) | D16: 0 | E16: 0 | F16: 0 | G16: =180*5*2 -> 1800 | H16: 0 | I16: =SUM(E16:H16) -> 1800 | J16: 1
A17: STFTRAVEL | B17: 7510 | C17: c. International Round Trip Airfare ($1,400 x 2 trip) | D17: =1200*2 -> 2400 | E17: =1400*2 -> 2800 | F17: 0 | G17: =1400*2 -> 2800 | H17: 0 | I17: =SUM(G17:H17) -> 2800 | J17: =(G17-E17)/E17 -> 0
A18: STFCN DIEM | B18: 7520 Per Diem/ (7320 Lodging | C18: d. International Lodging & Per Diem ($225 x 7 days x 2 trips) | D18: =225*5*2 -> 2250 | E18: =225*7*2 -> 3150 | F18: 0 | G18: =225*7*2 -> 3150 | H18: 0 | I18: =SUM(G18:H18) -> 3150 | J18: =(G18-E18)/E18 -> 0
C19: 2. Participant Travel
A20: PARTTRAVEL | B20: 7010 | C20: a. Round Trip Airfare ($1,800 x 30 trips) | D20: =1600*55 -> 88000 | E20: =1800*35 -> 63000 | F20: 0 | G20: =1800*30 -> 54000 | H20: 0 | I20: =SUM(G20:H20) -> 54000 | J20: =(G20-E20)/E20 -> -0.14285714
A21: PARTPERDIE | B21: 7015 | C21: b. International/Domestic Per Diem ($100 x 30 trips) | D21: =100*55 -> 5500 | E21: =100*35 -> 3500 | F21: 0 | G21: =100*30 -> 3000 | H21: 0 | I21: =SUM(G21:H21) -> 3000 | J21: =(G21-E21)/E21 -> -0.14285714
C22: c. Visa Fees ($180 x 2 participants) | D22: =180*5 -> 900 | E22: =180*2 -> 360 | F22: 0 | G22: 0 | H22: 0 | I22: =SUM(G22:H22) -> 0 | J22: =(G22-E22)/E22 -> -1
C23: Total Travel | D23: =SUM(D15:D22) -> 99050 | E23: =SUM(E15:E22) -> 72810 | F23: =SUM(F15:F21) -> 0 | G23: =SUM(G15:G22) -> 65750 | H23: =SUM(H15:H22) -> 0 | I23: =SUM(I15:I22) -> 65750 | J23: =(G23-E23)/E23 -> -0.096964703
C24: IV. Equipment
C25: V. Supplies*
C26: VI. Contractual
C27: VII. Construction
C28: VIII. Other Direct Costs
C29: 1. Honoraria
A30: EVENT | B30: 7610 | C30: a. Event Coordinator ($320/day x 96 days) (8 Days/Month) | D30: =320*32 -> 10240 | E30: =320*88 -> 28160 | F30: 0 | G30: =320*96 -> 30720 | H30: 0 | I30: =SUM(G30:H30) -> 30720 | J30: =(G30-E30)/E30 -> 0.090909091
C31: 2. Allowances
A32: TEACHERAST | B32: 7015 | C32: a. Teacher Allowance ($400 x 2 trips) | D32: =400*4 -> 1600 | E32: =400*2 -> 800 | F32: 0 | G32: =400*2 -> 800 | H32: 0 | I32: =SUM(G32:H32) -> 800 | J32: =(G32-E32)/E32 -> 0
C33: 3. Fees
A34: MONEVAL | B34: 8221 | C34: a. Monitoring and Evaluation ($250 x 20 days) | D34: =250*4 -> 1000 | E34: =250*20 -> 5000 | F34: 0 | G34: =250*20 -> 5000 | H34: 0 | I34: =SUM(G34:H34) -> 5000 | J34: =(G34-E34)/E34 -> 0
C35: 4. Events
A36: MEETING | B36: 7390 | C36: a. Event Costs - What Works Peer Learning Event | D36: 5000 | E36: 5000 | F36: 0 | G36: 5000 | H36: 0 | I36: =SUM(G36:H36) -> 5000 | J36: =(G36-E36)/E36 -> 0
C37: 5. Communications
A38: CONSULT | B38: 7610 | C38: a. Consultant for Promotion & Program Communications ($250/month x 12 months) | D38: 0 | E38: =225*16 -> 3600 | F38: 0 | G38: =250*12 -> 3000 | H38: 0 | I38: 0 | J38: =(G38-E38)/E38 -> -0.16666667
A39: SUBSCRIPT | B39: 8110 | C39: b. Platform Subscriptions ($75/month x 12 months) | D39: 0 | E39: =75*16 -> 1200 | F39: 0 | G39: =75*12 -> 900 | H39: 0 | I39: 0 | J39: =(G39-E39)/E39 -> -0.25
A40: COMM | B40: 8110 | C40: c. Online Platform for E-Trainings ($2000/year) | D40: 0 | E40: =2000*2 -> 4000 | F40: 0 | G40: =2000 -> 2000 | H40: 0 | I40: 0 | J40: =(G40-E40)/E40 -> -0.5
...

Sheet Volunteer Time Cost Share
A1: U.S. and LAC Volunteer Time
A2: Item | B2: # Vol-days | C2: Daily Rate | D2: Travel/project grants | E2: Total Cost Share
A4: Non-US Volunteers
A5: Participant selection/planning and preparation | B5: 2 | C5: =5*8 -> 40 | D5: 15 | E5: =B5*C5*D5 -> 1200
A6: Orientation | B6: 2 | C6: =5*8 -> 40 | D6: 15 | E6: =B6*C6*D6 -> 1200
A7: Follow-on engagement | B7: 5 | C7: =5*8 -> 40 | D7: 15 | E7: =B7*C7*D7 -> 3000
A8: Sub total | E8: =SUM(E5:E7) -> 5400
A9: U.S. Volunteers
A10: Participant selection/planning and preparation | B10: 2 | C10: =48.96*8 -> 391.68 | D10: 15 | E10: =B10*C10*D10 -> 11750.4
A11: Orientation | B11: 2 | C11: =48.96*8 -> 391.68 | D11: 15 | E11: =B11*C11*D11 -> 11750.4
A12: Follow-on engagement | B12: 5 | C12: =48.96*8 -> 391.68 | D12: 15 | E12: =B12*C12*D12 -> 29376
A13: Sub total | E13: =SUM(E10:E12) -> 52876.8
A14: Total volunteer time match | E14: =E13+E8 -> 58276.8
