Workbook

Sheet Budget Summary
A1: Partners of the Americas
A2: FY 2022 Traditional Public-Private Partnership Program (Education and Culture Program)
A3: CFDA 19.415 / Funding Opportunity #SFOP0008415
A4: Budget Summary | B4: Educational and Cultural Affairs | C4: Cost Sharing | D4: Total
A5: Program Costs | B5: ='Budget Details'!F25+'Budget Details'!F50+'Budget Details'!F31 -> 163965.6 | C5: ='Budget Details'!G25+'Budget Details'!G50+'Budget Details'!G31 -> 57603.2 | D5: =B5+C5 -> 221568.8
A6: Program costs per participant | B6: =B5/30 -> 5465.52 | C6: =C5/30 -> 1920.1067 | D6: =B6+C6 -> 7385.6267
A7: Administrative Costs | B7: ='Budget Details'!F11+'Budget Details'!F14+'Budget Details'!F54 -> 203144.29 | C7: ='Budget Details'!G11+'Budget Details'!G14+'Budget Details'!G54 -> 38668.8 | D7: =B7+C7 -> 241813.09
A8: Administrative costs per participant | B8: =B7/30 -> 6771.4762 | C8: =C7/30 -> 1288.96 | D8: =B8+C8 -> 8060.4362
A9: Total Costs | B9: =B5+B7 -> 367109.89 | C9: =C5+C7 -> 96272 | D9: =B9+C9 -> 463381.89
A10: Total costs per participant Number of Participants: 30 | B10: =B6+B8 -> 12236.996 | C10: =C6+C8 -> 3209.0667 | D10: =B10+C10 -> 15446.063
A14: Budget Categories | B14: Amount
A15: 1. Personnel* | B15: ='Budget Details'!F11 -> 99582.326
A16: 2. Fringe Benefits* | B16: ='Budget Details'!F14 -> 21718.905
A17: 3. Travel | B17: ='Budget Details'!F25 -> 73835
A18: 4. Equipment | B18: ='Budget Details'!F26 -> 0
A19: 5. Supplies* | B19: ='Budget Details'!F27 -> 0
A20: 6. Contractual | B20: ='Budget Details'!F31 -> 42000
A21: 7. Construction | B21: ='Budget Details'!F32 -> 0
A22: 8. Other Direct Costs | B22: ='Budget Details'!F50 -> 48130.6
A23: 9. Total Direct Costs (lines 1-8) | B23: =SUM(B15:B22) -> 285266.83
A24: 10. Indirect Costs* | B24: ='Budget Details'!F54 -> 81843.054
A25: 11. Total Costs (lines 9-10) | B25: =B24+B23 -> 367109.89
A26: 12. Cost-Sharing | B26: ='Budget Details'!G55 -> 96272
A27: Program Costs Total | B27: =B17+B22+B20 -> 163965.6
A28: Administrative Costs Total | B28: =B15+B16+B24 -> 203144.29
A29: *Administrative Costs

Sheet Budget Details
C1: Partners of the Americas
A2: Program/Dept.: | B2: 40300 | C2: FY 2022 Traditional Public-Private Partnership Program (Education and Culture Program)
A3: Funder-Grant: | B3: DOS286 | C3: CFDA 19.415 / Funding Opportunity #SFOP0008415
C4: March 1, 2022 - September 30, 2023
A5: Budget (Activity) Code | B5: Account Code | C5: Budget Category | D5: Approved FY 2021 ECA Funding Level | E5: FY 2021 Actual Budget | F5: FY 2022 ECA Funds Request | G5: FY 2022 Cost Sharing | H5: FY 2022 Total Budget | I5: % Change
C6: I. Salaries*
A7: PERSNL | B7: 50000 (Timesheets) | C7: 1. Program Director - $12,938/Month March 2022 - Sept. 2022 at 10% LOE Oct. 2022 - Sept. 2023 at 5% LOE | D7: =(10070*0.05*4)+(10070*0.1*6)+((10070*1.035)*0.1*2) -> 10140.49 | E7: =(10070*0.05*7)+((10070*1.035)*0.1*6)+((10070*1.035)*0.05*3) -> 11341.337 | F7: =(12938*0.1*7)+(12938*0.05*3)+((12938*1.035)*0.05*9) -> 17023.174 | G7: 0 | H7: =SUM(F7:G7) -> 17023.174 | I7: =(F7-D7)/D7 -> 0.67873283
A8: PERSNL | B8: 50000 (Timesheets) | C8: 2. Senior Program Officer - $6,416/Month March 2022 - June 2022 at 10% LOE July 2022 - April 2023 at 50% LOE May 2023 - Sept. 2023 at 20% LOE | D8: =(6276*0.5*4)+(6276*6)+((6276*1.035)*2) -> 63199.32 | E8: =(6185*0.5*7)+((6185*1.035)*6)+(((6185*1.035)*0.5)*3) -> 69658.562 | F8: =((6416*0.1)*4)+((6416*0.5)*6)+(((6416*1.035)*0.5)*4)+(((6416*1.035)*0.2)*5) -> 41736.08 | G8: 0 | H8: =SUM(F8:G8) -> 41736.08 | I8: =(F8-D8)/D8 -> -0.33961188
A9: PERSNL | B9: 50000 (Timesheets) | C9: 3. Program Assistant - $4,583/Month March 2022 - May 2022 at 25% LOE June 2022 - Sept. 2023 at 50% LOE | D9: =(4416*0.3*4)+(4416*0.5*6)+((4416*1.035)*0.5*2) -> 23117.76 | E9: =(4200*0.25*7)+((4200*1.035)*0.25*9) -> 17130.75 | F9: =(4583*0.25*3)+(4583*0.5*7)+((4583*1.035)*0.5*9) -> 40823.072 | G9: 0 | H9: =SUM(F9:G9) -> 40823.072 | I9: =(F9-D9)/D9 -> 0.76587492
C10: 4. Program Support | D10: 0 | E10: 0 | F10: 0 | G10: =(21.2*8)*3*76 -> 38668.8 | H10: =SUM(F10:G10) -> 38668.8 | I10: 1
C11: Total Salaries | D11: =SUM(D7:D10) -> 96457.57 | E11: =SUM(E7:E10) -> 98130.65 | F11: =SUM(F7:F10) -> 99582.326 | G11: =SUM(G7:G10) -> 38668.8 | H11: =G11+F11 -> 138251.13 | I11: =(F11-D11)/D11 -> 0.032395135
C12: II. Fringe Benefits*
A13: FRINGE | B13: 50900 (Timesheets) | C13: 0.2181 | D13: =D11*C13 -> 21037.396 | E13: =E11*C13 -> 21402.295 | F13: =F11*C13 -> 21718.905 | G13: 0 | H13: =SUM(F13:G13) -> 21718.905 | I13: =(F13-D13)/D13 -> 0.032395135
C14: Total Fringe Benefits | D14: =SUM(D13) -> 21037.396 | E14: =SUM(E13) -> 21402.295 | F14: =SUM(F13) -> 21718.905 | G14: =SUM(G13) -> 0 | H14: =G14+F14 -> 21718.905 | I14: =(F14-D14)/D14 -> 0.032395135
C15: III. Travel
C16: 1. Staff Travel
A17: STFTRAVEL | B17: 86040 | C17: a. Domestic Round Trip Airfare ($600 x 1 trip) | D17: =500*2 -> 1000 | E17: 0 | F17: =600*1 -> 600 | G17: 0 | H17: =SUM(F17:G17) -> 600 | I17: =(F17-D17)/D17 -> -0.4
A18: STFCN DIEM | B18: 86030 (Lodging) & 86050 (M&IE) | C18: b. Domestic Lodging & Per Diem ($180 x 5 days x 1 trip) | D18: =180*5*2 -> 1800 | E18: 0 | F18: =180*5*1 -> 900 | G18: 0 | H18: =SUM(F18:G18) -> 900 | I18: =(F18-D18)/D18 -> -0.5
A19: STFTRAVEL | B19: 86040 | C19: c. International Round Trip Airfare ($1,400 x 1 trip) | D19: =1400*2 -> 2800 | E19: 0 | F19: =1400 -> 1400 | G19: 0 | H19: =SUM(F19:G19) -> 1400 | I19: =(F19-D19)/D19 -> -0.5
A20: STFCN DIEM | B20: 86030 (Lodging) & 86050 (M&IE) | C20: d. International Lodging & Per Diem ($225 x 7 days x 1 trip) | D20: =225*7*2 -> 3150 | E20: 0 | F20: =225*7 -> 1575 | G20: 0 | H20: =SUM(F20:G20) -> 1575 | I20: =(F20-D20)/D20 -> -0.5
C21: 2. Participant Travel
A22: PARTTRAVEL | B22: 86040 | C22: a. Round Trip Airfare ($1,800 x 30 trips) | D22: =1800*30 -> 54000 | E22: =1800*15 -> 27000 | F22: =1800*30 -> 54000 | G22: 0 | H22: =SUM(F22:G22) -> 54000 | I22: =(F22-D22)/D22 -> 0
A23: PARTPERDIE | B23: 86050 | C23: b. International/Domestic Per Diem ($50/day x 10 days x 30 trips) | D23: =100*30 -> 3000 | E23: =(53*10)*15 -> 7950 | F23: =50*10*30 -> 15000 | G23: 0 | H23: =SUM(F23:G23) -> 15000 | I23: =(F23-D23)/D23 -> 4
A24: PARTPERDIE | B24: 86050 | C24: c. Visa Fees ($180 x 2 participants) | D24: 0 | E24: 0 | F24: =180*2 -> 360 | G24: 0 | H24: =SUM(F24:G24) -> 360 | I24: 0
C25: Total Travel | D25: =SUM(D17:D24) -> 65750 | E25: =SUM(E17:E24) -> 34950 | F25: =SUM(F17:F24) -> 73835 | G25: =SUM(G17:G24) -> 0 | H25: =G25+F25 -> 73835 | I25: =(F25-D25)/D25 -> 0.12296578
C26: IV. Equipment
C27: V. Supplies*
C28: VI. Contractual
A29: GRANTS | B29: 89000 | C29: a. Large Subawards (2 subawards x $16,500) | D29: 0 | E29: =10000*3 -> 30000 | F29: =16500*2 -> 33000 | G29: =5500*2 -> 11000 | H29: =SUM(F29:G29) -> 44000 | I29: 1
A30: GRANTS | B30: 89000 | C30: b. Small Subawards (3 subawards x $3,000) | D30: =3000*18 -> 54000 | E30: =4000*6 -> 24000 | F30: =3000*3 -> 9000 | G30: =1000*3 -> 3000 | H30: =SUM(F30:G30) -> 12000 | I30: =(F30-D30)/D30 -> -0.83333333
C31: Total Contractual | D31: =SUM(D29:D30) -> 54000 | E31: =SUM(E29:E30) -> 54000 | F31: =SUM(F29:F30) -> 42000 | G31: =SUM(G29:G30) -> 14000 | H31: =G31+F31 -> 56000 | I31: =(F31-D31)/D31 -> -0.22222222
C32: VII. Construction
C33: VIII. Other Direct Costs
C34: 1. Honoraria
A35: CONSULT | B35: 81000 | C35: a. Logistics Consultant ($325/day x 96 days) (5 Days/Month) | D35: =320*96 -> 30720 | E35: =320*96 -> 30720 | F35: =325*96 -> 31200 | G35: 0 | H35: =SUM(F35:G35) -> 31200 | I35: =(F35-D35)/D35 -> 0.015625
C36: 2. Allowances
A37: TEACHERAST | B37: 81015 | C37: a. Teacher Allowance ($400 x 2 trips) | D37: =400*2 -> 800 | E37: 0 | F37: 0 | G37: 0 | H37: =SUM(F37:G37) -> 0 | I37: =(F37-D37)/D37 -> -1
C38: 3. Fees
A39: MONEVAL | B39: 81010 | C39: a. Monitoring and Evaluation ($255 x 20 days) | D39: =250*20 -> 5000 | E39: =250*40 -> 10000 | F39: =255*20 -> 5100 | G39: 0 | H39: =SUM(F39:G39) -> 5100 | I39: =(F39-D39)/D39 -> 0.02
C40: 4. Events
...

Sheet Volunteer Time Cost Share
A1: U.S. and LAC Volunteer Time
A2: Item | B2: # Vol-days | C2: Daily Rate | D2: Travel/project grants | E2: Total Cost Share
A4: Non-US Volunteers
A5: Participant selection/planning and preparation | B5: 2 | C5: =5*8 -> 40 | D5: 20 | E5: =B5*C5*D5 -> 1600
A6: Orientation | B6: 2 | C6: =5*8 -> 40 | D6: 20 | E6: =B6*C6*D6 -> 1600
A7: Follow-on engagement | B7: 5 | C7: =5*8 -> 40 | D7: 20 | E7: =B7*C7*D7 -> 4000
A8: Sub total | E8: =SUM(E5:E7) -> 7200
A9: U.S. Volunteers
A10: Participant selection/planning and preparation | B10: 2 | C10: =50.56*8 -> 404.48 | D10: 10 | E10: =B10*C10*D10 -> 8089.6
A11: Orientation | B11: 2 | C11: =50.56*8 -> 404.48 | D11: 10 | E11: =B11*C11*D11 -> 8089.6
A12: Follow-on engagement | B12: 5 | C12: =50.56*8 -> 404.48 | D12: 10 | E12: =B12*C12*D12 -> 20224
A13: Sub total | E13: =SUM(E10:E12) -> 36403.2
A14: Total volunteer time match | E14: =E13+E8 -> 43603.2
