Workbook
Name agentfee: #REF!
Name agentfee: Assumptions!$D$55
Name avrent: [1]Assumptions!$D$111
Name avrent: #REF!
Name avrent: Assumptions!$D$98
Name Category: #REF!
Name Check25: 'SF424'!$A$5
Name Check26: 'SF424'!$A$6
Name Check27: 'SF424'!$A$7
Name Check28: 'SF424'!$D$5
Name Check29: 'SF424'!$D$6
Name Check30: 'SF424'!$D$7
Name Check32: 'SF424'!$A$126
Name Check33: 'SF424'!$A$127
Name Check35: 'SF424'!$A$129
Name Check36: 'SF424'!$A$131
Name coffee: [1]Assumptions!$D$108
Name coffee: #REF!
Name coffee: Assumptions!$D$95
Name consairfare: #REF!
Name consairfare: Assumptions!$D$80
Name consground: #REF!
Name consground: Assumptions!$D$81
Name conslodg: #REF!
Name conslodg: Assumptions!$D$82
Name consmeals: #REF!
Name consmeals: Assumptions!$D$83
Name consmisc: #REF!
Name consmisc: Assumptions!$D$84
Name DL_Country: '[2]Line-Item Budget'!#REF!
Name DL_Country: #REF!
Name DL_TotalDOL: #REF!
Name Dropdown1: 'SF424'!$G$5
Name Dropdown2: 'SF424'!#REF!
Name EQ_Country: '[2]Line-Item Budget'!#REF!
Name EQ_Country: #REF!
Name EQ_TotalDOL: '[2]Line-Item Budget'!#REF!
Name EQ_TotalDOL: #REF!
Name er: #REF!
Name er: Assumptions!$B$17
Name ground: #REF!
Name ground: Assumptions!$D$59
Name guideprint: Assumptions!$D$103
Name inmuniz: #REF!
Name inmuniz: Assumptions!$D$57
Name intairfare: #REF!
Name intairfare: Assumptions!$D$52
Name intcalls: #REF!
Name intcalls: Assumptions!#REF!
Name intcons: #REF!
Name intcons: Assumptions!$D$77
Name intmisc: #REF!
Name intmisc: Assumptions!$D$60
Name livingq: #REF!
Name livingq: Assumptions!#REF!
Name Local_transport_part: [2]Assumptions!$B$10:$D$10
Name localairfare: #REF!
Name localairfare: Assumptions!$D$73
Name localcons: #REF!
Name localcons: Assumptions!$D$79

Sheet AgroJusto Budget
C1: Project Line-Item Budget
C2: Partners of the Americas
C3: Project to Improve Adherence to International Labor Standards in the Agricultural Sector in Ecuador Improve Adherence to International Labor Standards in the Agricultural Sector in Ecuador
C4: 48 Months
C5: Cost Assumptions
C6: Inflation - US Based Goods/Services | D6: 1.03
C7: Inflation - Locally Purchased Goods/Services | D7: 1.04
C8: Merit Based Increases for HO & Field Staff | D8: 1.05
A10: Activity Code | B10: Account Code | C10: BUDGET ITEM | D10: CATEGORY | E10: LOE | F10: UNIT | G10: # of Units | H10: RATE / UNIT | I10: Year 1 | J10: # of Units | K10: Year 2 | L10: # of Units | M10: Year 3 | N10: # of Units | O10: Year 4 | P10: TOTAL DOL | Q10: TOTAL COST SHARING | R10: PROJECT GRAND TOTAL
C11: Personnel
C12: Key Personnel
A13: PERSNL-PD | B13: 70000 | C13: Project Director (100%) - Alexis Naranjo | D13: Salaries | E13: 1 | F13: Month | G13: 11 | H13: 6000 | I13: =G13*H13*E13 -> 66000 | J13: 12 | K13: =J13*H13*$D$8 -> 75600 | L13: 12 | M13: =(L13*H13*$D$8*$D$8) -> 79380 | N13: 12 | O13: =N13*H13*$D$8*$D$8*$D$8 -> 83349 | P13: =SUM(I13+K13+M13+O13) -> 304329 | Q13: 0 | R13: =SUM(P13:Q13) -> 304329
A14: PERSNL-M&E | B14: 70000 | C14: Monitoring and Evaluation (M&E) Officer (100%) - Mónica Rentería | D14: Salaries | E14: 1 | F14: Month | G14: 11 | H14: =40000/12 -> 3333.3333 | I14: =G14*H14*E14 -> 36666.667 | J14: 12 | K14: =J14*H14*$D$8 -> 42000 | L14: 12 | M14: =(L14*H14*$D$8*$D$8) -> 44100 | N14: 12 | O14: =N14*H14*$D$8*$D$8*$D$8 -> 46305 | P14: =SUM(I14+K14+M14+O14) -> 169071.67 | Q14: 0 | R14: =SUM(P14:Q14) -> 169071.67
C15: Other Professional Personnel
A16: PERSNL-PSL | B16: 70000 | C16: Public Sector Liaison (100%)- Luis Almagor | D16: Salaries | E16: 1 | F16: Month | G16: 11 | H16: 2400 | I16: =G16*H16*E16 -> 26400 | J16: 12 | K16: =J16*H16*$D$8 -> 30240 | L16: 12 | M16: =(L16*H16*$D$8*$D$8) -> 31752 | N16: 8 | O16: =N16*H16*$D$8*$D$8*$D$8 -> 22226.4 | P16: =SUM(I16+K16+M16+O16) -> 110618.4 | Q16: 0 | R16: =SUM(P16:Q16) -> 110618.4
A17: PERSNL-COM | B17: 70000 | C17: Communications Specialist (100%) - Emilia Bayas | D17: Salaries | E17: 1 | F17: Month | G17: 11 | H17: 1800 | I17: =G17*H17*E17 -> 19800 | J17: 12 | K17: =J17*H17*$D$8 -> 22680 | L17: 12 | M17: =(L17*H17*$D$8*$D$8) -> 23814 | N17: 8 | O17: =N17*H17*$D$8*$D$8*$D$8 -> 16669.8 | P17: =SUM(I17+K17+M17+O17) -> 82963.8 | Q17: 0 | R17: =SUM(P17:Q17) -> 82963.8
A18: PERSNL-SAF | B18: 70000 | C18: Occupational Safety and Health Specialist (100%) - César Ávila | D18: Salaries | E18: 1 | F18: Month | G18: 11 | H18: 2400 | I18: =G18*H18*E18 -> 26400 | J18: 12 | K18: =J18*H18*$D$8 -> 30240 | L18: 12 | M18: =(L18*H18*$D$8*$D$8) -> 31752 | N18: 8 | O18: =N18*H18*$D$8*$D$8*$D$8 -> 22226.4 | P18: =SUM(I18+K18+M18+O18) -> 110618.4 | Q18: 0 | R18: =SUM(P18:Q18) -> 110618.4
A19: PERSNL-F&A | B19: 70000 | C19: Finance & Administration Director (100%) | D19: Salaries | E19: 1 | F19: Month | G19: 5 | H19: 3400 | I19: =G19*H19*E19 -> 17000 | J19: 12 | K19: =J19*H19*$D$8 -> 42840 | L19: 12 | M19: =(L19*H19*$D$8*$D$8) -> 44982 | N19: 12 | O19: =N19*H19*$D$8*$D$8*$D$8 -> 47231.1 | P19: =SUM(I19+K19+M19+O19) -> 152053.1 | Q19: 0 | R19: =SUM(P19:Q19) -> 152053.1
A20: PERSNL-OPS | B20: 70000 | C20: Operations Coordinator (100%) | D20: Salaries | E20: 1 | F20: Month | G20: 3 | H20: 2000 | I20: =G20*H20*E20 -> 6000 | J20: 12 | K20: =J20*H20*$D$8 -> 25200 | L20: 12 | M20: =(L20*H20*$D$8*$D$8) -> 26460 | N20: 8 | O20: =N20*H20*$D$8*$D$8*$D$8 -> 18522 | P20: =SUM(I20+K20+M20+O20) -> 76182 | Q20: 0 | R20: =SUM(P20:Q20) -> 76182
A21: PERSNL-RCC | B21: 70000 | C21: Regional Coordinator 1, Cotopaxi (100%) | D21: Salaries | E21: 1 | F21: Month | G21: 3 | H21: =15000/12-62 -> 1188 | I21: =G21*H21*E21 -> 3564 | J21: 12 | K21: =J21*H21*$D$8 -> 14968.8 | L21: 12 | M21: =(L21*H21*$D$8*$D$8) -> 15717.24 | N21: 8 | O21: =N21*H21*$D$8*$D$8*$D$8 -> 11002.068 | P21: =SUM(I21+K21+M21+O21) -> 45252.108 | Q21: 0 | R21: =SUM(P21:Q21) -> 45252.108
A22: PERSNL-RCO | B22: 70000 | C22: Regional Coordinator 2, El Oro (100%) | D22: Salaries | E22: 1 | F22: Month | G22: 3 | H22: =15000/12-62 -> 1188 | I22: =G22*H22*E22 -> 3564 | J22: 12 | K22: =J22*H22*$D$8 -> 14968.8 | L22: 12 | M22: =(L22*H22*$D$8*$D$8) -> 15717.24 | N22: 8 | O22: =N22*H22*$D$8*$D$8*$D$8 -> 11002.068 | P22: =SUM(I22+K22+M22+O22) -> 45252.108 | Q22: 0 | R22: =SUM(P22:Q22) -> 45252.108
C23: Home Office Support | M23: =(L23*H23*$D$6*$D$7) -> 0 | O23: =N23*H23*$D$6*$D$7*$D$8 -> 0
A24: PERSNL-PM | B24: 50000 | C24: Project Manager (30%) | D24: Salaries | E24: 0.3 | F24: Month | G24: 11 | H24: 10729 | I24: =G24*H24*E24 -> 35405.7 | J24: 12 | K24: =J24*H24*$D$8*E24 -> 40555.62 | L24: 12 | M24: =(L24*H24*$D$8*$D$8)*E24 -> 42583.401 | N24: 12 | O24: =(N24*H24*$D$8*$D$8*$D$8)*E24 -> 44712.571 | P24: =SUM(I24+K24+M24+O24) -> 163257.29 | Q24: 0 | R24: =SUM(P24:Q24) -> 163257.29
A25: PERSNL-PO | B25: 50000 | C25: 2 Program Officers (20%) | D25: Salaries | E25: 0.2 | F25: Month | G25: 11 | H25: 10105 | I25: =G25*H25*E25 -> 22231 | J25: 12 | K25: =J25*H25*$D$8*E25 -> 25464.6 | L25: 12 | M25: =(L25*H25*$D$8*$D$8)*E25 -> 26737.83 | N25: 12 | O25: =(N25*H25*$D$8*$D$8*$D$8)*E25 -> 28074.722 | P25: =SUM(I25+K25+M25+O25) -> 102508.15 | Q25: 0 | R25: =SUM(P25:Q25) -> 102508.15
C26: Total Personnel | I26: =SUM(I13:I25) -> 263031.37 | K26: =SUM(K13:K25) -> 364757.82 | M26: =SUM(M13:M25) -> 382995.71 | O26: =SUM(O13:O25) -> 351321.13 | P26: =SUM(P13:P25) -> 1362106 | Q26: =SUM(Q13:Q25) -> 0 | R26: =SUM(P26:Q26) -> 1362106
C27: Fringe Benefits
C29: Fringe Benefits
A30: FRINGE-EC | B30: 70015 | C30: Fringe benefits - Ecuador | D30: Fringe Benefits | F30: Month | H30: 0.4333 | I30: =SUM(I13:I22)*$H30 -> 88997.509 | K30: =SUM(K13:K22)*$H30 -> 129443 | M30: =SUM(M13:M22)*$H30 -> 135915.15 | O30: =SUM(O13:O22)*$H30 -> 120688.71 | P30: =SUM(I30+K30+M30+O30) -> 475044.37 | Q30: 0 | R30: =SUM(P30:Q30) -> 475044.37
A31: FRINGE | B31: 50900 | C31: Fringe benefits - Home Office Support | D31: Fringe Benefits | F31: Month | H31: 0.2347 | I31: =SUM(I24:I25)*$H$31 -> 13527.333 | K31: =SUM(K24:K25)*$H$31 -> 15494.946 | M31: =SUM(M24:M25)*$H$31 -> 16269.693 | O31: =SUM(O24:O25)*$H$31 -> 17083.178 | P31: =SUM(I31+K31+M31+O31) -> 62375.15 | Q31: 0 | R31: =SUM(P31:Q31) -> 62375.15
C33: Total Fringe Benefits | I33: =SUM(I30:I32) -> 102524.84 | K33: =SUM(K30:K32) -> 144937.95 | M33: =SUM(M30:M32) -> 152184.85 | O33: =SUM(O30:O32) -> 137771.89 | P33: =SUM(P30:P32) -> 537419.52 | Q33: =SUM(Q31:Q31) -> 0 | R33: =SUM(R30:R32) -> 537419.52
C34: Travel
C35: T1: Post-award Meeting with ILAB
A36: EC.T1.A | B36: 86040 | C36: Airfare - Ecuador-DC | D36: Travel | F36: Trip | H36: 650 | I36: =G36*H36 -> 0 | J36: 2 | K36: =J36*H36*$D$7 -> 1352 | L36: 0 | M36: =L36*H36*$D$7*$D$7 -> 0 | N36: 0 | O36: =N36*H36*$D$7*$D$7*$D$7 -> 0 | P36: =SUM(I36+K36+M36+O36) -> 1352 | Q36: - | R36: =SUM(P36:Q36) -> 1352
A37: EC.T1.B | B37: 86030 (Lodging)/ 86050 (M&IE) | C37: Lodging and M&IE in DC | D37: Travel | F37: Day | H37: =(258+79)*90% -> 303.3 | I37: =G37*H37 -> 0 | J37: 10 | K37: =J37*H37*$D$7 -> 3154.32 | L37: 0 | M37: =L37*H37*$D$7*$D$7 -> 0 | N37: 0 | O37: =N37*H37*$D$7*$D$7*$D$7 -> 0 | P37: =SUM(I37+K37+M37+O37) -> 3154.32 | Q37: - | R37: =SUM(P37:Q37) -> 3154.32
A38: EC.T1.C | B38: 86000 | C38: Local transportation in DC | D38: Travel | F38: Day | H38: 60 | I38: =G38*H38 -> 0 | J38: 10 | K38: =J38*H38*$D$7 -> 624 | L38: 0 | M38: =L38*H38*$D$7*$D$7 -> 0 | N38: 0 | O38: =N38*H38*$D$7*$D$7*$D$7 -> 0 | P38: =SUM(I38+K38+M38+O38) -> 624 | Q38: - | R38: =SUM(P38:Q38) -> 624
A39: EC.T1.D | B39: 86050 | C39: U.S. Visa Fees | D39: Travel | F39: Trip | H39: 160 | I39: =G39*H39 -> 0 | J39: 2 | K39: =J39*H39*$D$7 -> 332.8 | L39: 0 | M39: =L39*H39*$D$7*$D$7 -> 0 | N39: 0 | O39: =N39*H39*$D$7*$D$7*$D$7 -> 0 | P39: =SUM(I39+K39+M39+O39) -> 332.8 | Q39: - | R39: =SUM(P39:Q39) -> 332.8
C40: T2: Field Personnel Annual Visits with ILAB
A41: EC.T2.A | B41: 86040 | C41: Airfare - Ecuador-DC | D41: Travel | F41: Trip | G41: 2 | H41: 650 | I41: =G41*H41 -> 1300 | J41: 2 | K41: =J41*H41*$D$7 -> 1352 | L41: 2 | M41: =L41*H41*$D$7*$D$7 -> 1406.08 | N41: 2 | O41: =N41*H41*$D$7*$D$7*$D$7 -> 1462.3232 | P41: =SUM(I41+K41+M41+O41) -> 5520.4032 | Q41: - | R41: =SUM(P41:Q41) -> 5520.4032
A42: EC.T2.B | B42: 86030 (Lodging)/ 86050 (M&IE) | C42: Lodging and M&IE in DC | D42: Travel | F42: Day | G42: 5 | H42: =(258+79)*90% -> 303.3 | I42: =G42*H42 -> 1516.5 | J42: 10 | K42: =J42*H42*$D$7 -> 3154.32 | L42: 10 | M42: =L42*H42*$D$7*$D$7 -> 3280.4928 | N42: 10 | O42: =N42*H42*$D$7*$D$7*$D$7 -> 3411.7125 | P42: =SUM(I42+K42+M42+O42) -> 11363.025 | Q42: - | R42: =SUM(P42:Q42) -> 11363.025
A43: EC.T2.C | B43: 86000 | C43: Local transportation in DC | D43: Travel | F43: Day | G43: 5 | H43: 60 | I43: =G43*H43 -> 300 | J43: 10 | K43: =J43*H43*$D$7 -> 624 | L43: 10 | M43: =L43*H43*$D$7*$D$7 -> 648.96 | N43: 10 | O43: =N43*H43*$D$7*$D$7*$D$7 -> 674.9184 | P43: =SUM(I43+K43+M43+O43) -> 2247.8784 | Q43: - | R43: =SUM(P43:Q43) -> 2247.8784
...

Sheet  Activities Detail
C5: Partners of the Americas
C6: DONOR: | D6: =Assumptions!C9 -> USDOL
C7: Country: | D7: =Assumptions!C10 -> Ecuador
C8: Program Name: | D8: =Assumptions!C11 -> Project to Improve Adherence to International Labor Standards in the Agricultural Sector in Ecuador
C9: Grant Number: | D9: =Assumptions!C12 -> FOA-ILAB-23-28
C10: Period of Performance: | D10: =Assumptions!C13 -> 48 months
C14: ACTIVITY DESCRIPTION | D14: Units | F14: Cost | G14: Base | H14: # of days | J14: ='AgroJusto Budget'!I10 -> Year 1 | M14: ='AgroJusto Budget'!K10 -> Year 2 | P14: ='AgroJusto Budget'!M10 -> Year 3 | S14: ='AgroJusto Budget'!O10 -> Year 4 | V14: Total
J15: # Activities | L15: Amount | M15: # Activities | O15: Amount | P15: # Activities | R15: Amount | S15: # Activities | U15: Amount
C16: ODC Escalation Factor | D16: 0.04 | L16: 1 | O16: =$L$16*SUM(1+$D$16) -> 1.04 | R16: =$O$16*SUM(1+$D$16) -> 1.0816 | U16: =$R$16*SUM(1+$D$16) -> 1.124864
C17: MEETINGS
C20: Activity 1.2. Strengthen intersectoral coordination by re-invigorating referral mechanisms and strengthening Consejos and Juntas: | H20: 1 | J20: 0 | L20: =SUM(K22:K46) -> 0 | M20: 4 | O20: =SUM(N22:N26) -> 1435.2 | P20: 0 | R20: =SUM(Q22:Q26) -> 0 | S20: 0 | U20: =SUM(T22:T26) -> 0 | V20: =SUM(L20,O20,R20,U20,) -> 1435.2
C21: Workshop activities costs
A22: EC.1.4.A | B22: 86000 | C22: Local transportation (training site) | D22: 15 | E22: Individual | F22: =parttransp -> 4 | G22: /day | H22: =IF(D22=0,0,H20) -> 1 | I22: =D22*F22*H22 -> 60 | K22: =$I22*J20*L$16 -> 0 | N22: =$I22*M20*O$16 -> 249.6 | Q22: =$I22*P20*R$16 -> 0 | T22: =$I22*S20*U$16 -> 0 | V22: =T22+Q22+N22+K22 -> 249.6
A23: EC.1.4.B | B23: 87000 | C23: Lunch/coffee breaks | D23: 15 | E23: Individual | F23: =coffee+lunch -> 16 | G23: /day | H23: =IF(D23=0,0,H20) -> 1 | I23: =D23*F23*H23 -> 240 | K23: =$I23*J20*L$16 -> 0 | N23: =$I23*M20*O$16 -> 998.4 | Q23: =$I23*P20*R$16 -> 0 | T23: =$I23*S20*U$16 -> 0 | V23: =T23+Q23+N23+K23 -> 998.4
A24: EC.1.7.C | B24: 82420 | C24: Materials & Supplies | D24: 15 | E24: workshop | F24: =mats -> 3 | G24: =E24 -> workshop | H24: =IF(D24=0,0,1) -> 1 | I24: =D24*F24*H24 -> 45 | K24: =$I24*J20*L$16 -> 0 | N24: =$I24*M20*O$16 -> 187.2 | Q24: =$I24*P20*R$16 -> 0 | T24: =$I24*S20*U$16 -> 0 | V24: =T24+Q24+N24+K24 -> 187.2
A25: EC.1.2.A | B25: 85300 | C25: Printing (Guide) | D25: 0 | E25: canton | F25: =guideprint -> 200 | G25: =E25 -> canton | H25: =IF(D25=0,0,1) -> 0 | I25: =D25*F25*H25 -> 0 | K25: =$I25*L$16 -> 0 | Q25: =$I25*P20*R$16 -> 0 | T25: =$I25*S20*U$16 -> 0 | V25: =T25+Q25+N25+K25 -> 0
A26: EC.1.1.A | B26: 81000 | C26: Local Consultant (Guide Development) | D26: 0 | E26: Individual | F26: =localcons -> 300 | G26: /day | H26: 1 | I26: =D26*F26*H26 -> 0 | K26: =$I26*J20*L$16 -> 0 | N26: =$I26*M20*O$16 -> 0 | Q26: =$I26*P20*R$16 -> 0 | T26: =$I26*S20*U$16 -> 0 | V26: =T26+Q26+N26+K26 -> 0
C27: Staff from outside training site | V27: =T27+Q27+N27+K27 -> 0
C28: Transportation (El Oro) | D28: 3 | E28: Individual | F28: =Assumptions!D73 -> 195 | G28: /trip | H28: 1 | I28: =D28*F28*H28 -> 585 | K28: =$I28*K$20*L$16 -> 0 | N28: =$I28*M20*O$16 -> 2433.6 | V28: 0
C29: Ground transportation (El Oro) | D29: 3 | E29: Individual | F29: =partground -> 9 | G29: /day | H29: 4 | I29: =D29*F29*H29 -> 108 | K29: =$I29*K$20*L$16 -> 0 | N29: =$I29*M20*O$16 -> 449.28 | V29: 0
C30: Lodging | D30: 3 | E30: Individual | F30: =Assumptions!D70 -> 122 | G30: /day | H30: 4 | I30: =D30*F30*H30 -> 1464 | K30: =$I30*K$20*L$16 -> 0 | N30: =$I30*M20*O$16 -> 6090.24 | V30: 0
C31: M&IE | D31: 3 | E31: Individual | F31: =partmeals -> 47 | G31: /day | H31: 4 | I31: =D31*F31*H31 -> 564 | K31: =$I31*K$20*L$16 -> 0 | N31: =$I31*M20*O$16 -> 2346.24 | V31: 0
C32: Staff from outside training site | V32: =T32+Q32+N32+K32 -> 0
C33: Transportation (Cotopaxi) | D33: 3 | E33: Individual | F33: =partground -> 9 | G33: /trip | H33: 2 | I33: =D33*F33*H33 -> 54 | K33: =$I33*J$20*L$16 -> 0 | N33: =$I33*M20*O$16 -> 224.64 | V33: 0
C34: Ground transportation (Cotopaxi) | D34: 3 | E34: Individual | F34: =partground -> 9 | G34: /day | H34: 4 | I34: =D34*F34*H34 -> 108 | K34: =$I34*J$20*L$16 -> 0 | N34: =$I34*M20*O$16 -> 449.28 | V34: 0
C35: M&IE | D35: 3 | E35: Individual | F35: =partmeals -> 47 | G35: /day | H35: 4 | I35: =D35*F35*H35 -> 564 | K35: =$I35*J$20*L$16 -> 0 | N35: =$I35*M20*O$16 -> 2346.24 | V35: 0
C37: Staff from outside training site - Asistencia Técnica (coordinar mesas)
C38: Transportation (El Oro) | D38: 2 | E38: Individual | F38: =Assumptions!D73 -> 195 | G38: /trip | H38: 1 | I38: =D38*F38*H38 -> 390 | K38: =$I38*K$20*L$16 -> 0 | N38: =$I38*M20*O$16 -> 1622.4
C39: Ground transportation (El Oro) | D39: 2 | E39: Individual | F39: =partground -> 9 | G39: /day | H39: 4 | I39: =D39*F39*H39 -> 72 | K39: =$I39*K$20*L$16 -> 0 | N39: =$I39*M20*O$16 -> 299.52
C40: Lodging | D40: 2 | E40: Individual | F40: =Assumptions!D70 -> 122 | G40: /day | H40: 4 | I40: =D40*F40*H40 -> 976 | K40: =$I40*K$20*L$16 -> 0 | N40: =$I40*M20*O$16 -> 4060.16
C41: M&IE | D41: 2 | E41: Individual | F41: =partmeals -> 47 | G41: /day | H41: 4 | I41: =D41*F41*H41 -> 376 | K41: =$I41*K$20*L$16 -> 0 | N41: =$I41*M20*O$16 -> 1564.16
C42: Staff from outside training site
C43: Transportation (Cotopaxi) | D43: 2 | E43: Individual | F43: =partground -> 9 | G43: /trip | H43: 2 | I43: =D43*F43*H43 -> 36 | K43: =$I43*J$20*L$16 -> 0 | N43: =$I43*M20*O$16 -> 149.76
C44: Ground transportation (Cotopaxi) | D44: 2 | E44: Individual | F44: =partground -> 9 | G44: /day | H44: 4 | I44: =D44*F44*H44 -> 72 | K44: =$I44*J$20*L$16 -> 0 | N44: =$I44*M20*O$16 -> 299.52
C45: M&IE | D45: 2 | E45: Individual | F45: =partmeals -> 47 | G45: /day | H45: 4 | I45: =D45*F45*H45 -> 376 | K45: =$I45*J$20*L$16 -> 0 | N45: =$I45*M20*O$16 -> 1564.16
V46: =T46+Q46+N46+K46 -> 0
C47: ACTIVITY TOTAL | G47: =SUM(N21:N46) -> 25334.4
C49: Activity 1.3. Develop government capacity building strategy applying assessment results | H49: 1 | L49: =SUM(K51:K61) -> 0 | M49: 1 | O49: =SUM(N51:N51) -> 10400 | P49: 0 | R49: =SUM(Q51:Q61) -> 0 | S49: 0 | U49: =SUM(T51:T61) -> 0 | V49: =SUM(L49,O49,R49,U49,) -> 10400
C50: Project activities costs
C51: Application of MIRTI | D51: 1 | E51: each | F51: 10000 | G51: MIRTI | H51: 1 | I51: =D51*F51*H51 -> 10000 | N51: =$I51*M49*O$16 -> 10400 | V51: =T51+Q51+N51+K51 -> 10400
...

Sheet US & Local Summaries
A1: =Assumptions!B8 -> Partners of America
A2: =Assumptions!B9 -> DONOR: | F2: =Assumptions!C9 -> USDOL
A3: =Assumptions!B10 -> Country: | F3: =Assumptions!C10 -> Ecuador
A4: =Assumptions!B11 -> Program Name: | F4: =Assumptions!C11 -> Project to Improve Adherence to International Labor Standards in the Agricultural Sector in Ecuador
A5: =Assumptions!B12 -> Grant Number: | F5: =Assumptions!C12 -> FOA-ILAB-23-28
A6: =Assumptions!B13 -> Period of Performance: | F6: =Assumptions!C13 -> 48 months | I6: =Assumptions!G13 -> 0
A8: US COSTS
A10: Line Item | F10: =#REF! -> #REF! | I10: =#REF! -> #REF! | L10: =#REF! -> #REF! | O10: =#REF! -> #REF! | R10: =#REF! -> #REF! | U10: Total
A12: Salaries | F12: =#REF! -> #REF! | I12: =#REF! -> #REF! | L12: =#REF! -> #REF! | O12: =#REF! -> #REF! | R12: =#REF! -> #REF! | U12: =SUM(F12,I12,L12,O12,R12) -> #REF!
A13: Fringe Benefits | F13: =#REF! -> #REF! | I13: =#REF! -> #REF! | L13: =#REF! -> #REF! | O13: =#REF! -> #REF! | R13: =#REF! -> #REF! | U13: =SUM(F13,I13,L13,O13,R13) -> #REF!
A14: Travel | F14: =#REF! -> #REF! | I14: =#REF! -> #REF! | L14: =#REF! -> #REF! | O14: =#REF! -> #REF! | R14: =#REF! -> #REF! | U14: =SUM(F14,I14,L14,O14,R14) -> #REF!
A15: Equipment | F15: =#REF! -> #REF! | I15: =#REF! -> #REF! | L15: =#REF! -> #REF! | O15: =#REF! -> #REF! | R15: =#REF! -> #REF! | U15: =SUM(F15,I15,L15,O15,R15) -> #REF!
A16: Materials and Supplies | F16: =#REF! -> #REF! | I16: =#REF! -> #REF! | L16: =#REF! -> #REF! | O16: =#REF! -> #REF! | R16: =#REF! -> #REF! | U16: =SUM(F16,I16,L16,O16,R16) -> #REF!
A17: Consultants | F17: =#REF! -> #REF! | I17: =#REF! -> #REF! | L17: =#REF! -> #REF! | O17: =#REF! -> #REF! | R17: =#REF! -> #REF! | U17: =SUM(F17,I17,L17,O17,R17) -> #REF!
A18: Contractual | F18: =#REF! -> #REF! | I18: =#REF! -> #REF! | L18: =#REF! -> #REF! | O18: =#REF! -> #REF! | R18: =#REF! -> #REF! | U18: =SUM(F18,I18,L18,O18,R18) -> #REF!
A19: Other Direct Costs | F19: =#REF! -> #REF! | I19: =#REF! -> #REF! | L19: =#REF! -> #REF! | O19: =#REF! -> #REF! | R19: =#REF! -> #REF! | U19: =SUM(F19,I19,L19,O19,R19) -> #REF!
A20: Subtotal | F20: =#REF! -> #REF! | I20: =#REF! -> #REF! | L20: =#REF! -> #REF! | O20: =#REF! -> #REF! | R20: =#REF! -> #REF! | U20: =SUM(F20,I20,L20,O20,R20) -> #REF!
A22: Service Center (excluding subcontractors) | F22: =#REF! -> #REF! | I22: =#REF! -> #REF! | L22: =#REF! -> #REF! | O22: =#REF! -> #REF! | R22: =#REF! -> #REF! | U22: =SUM(F22,I22,L22,O22,R22) -> #REF!
A23: Service Center on Subcontractors | F23: =#REF! -> #REF! | I23: =#REF! -> #REF! | L23: =#REF! -> #REF! | O23: =#REF! -> #REF! | R23: =#REF! -> #REF! | U23: =SUM(F23,I23,L23,O23,R23) -> #REF!
A25: F&A Costs | F25: =#REF! -> #REF! | I25: =#REF! -> #REF! | L25: =#REF! -> #REF! | O25: =#REF! -> #REF! | R25: =#REF! -> #REF! | U25: =SUM(F25,I25,L25,O25,R25) -> #REF!
A26: F&A Costs (Applied to Subcontracts) | F26: =#REF! -> #REF! | I26: =#REF! -> #REF! | L26: =#REF! -> #REF! | O26: =#REF! -> #REF! | R26: =#REF! -> #REF! | U26: =SUM(F26,I26,L26,O26,R26) -> #REF!
A28: Total per year | F28: =SUM(F20:F27) -> #REF! | I28: =SUM(I20:I27) -> #REF! | L28: =SUM(L20:L27) -> #REF! | O28: =SUM(O20:O27) -> #REF! | R28: =SUM(R20:R27) -> #REF! | U28: =SUM(E28:T28) -> #REF!
A30: IN-COUNTRY COSTS
A32: Line Item | F32: =F10 -> #REF! | I32: =I10 -> #REF! | L32: =L10 -> #REF! | O32: =O10 -> #REF! | R32: =R10 -> #REF! | U32: =U10 -> Total
A34: Salaries | F34: =#REF! -> #REF! | I34: =#REF! -> #REF! | L34: =#REF! -> #REF! | O34: =#REF! -> #REF! | R34: =#REF! -> #REF! | U34: =SUM(F34,I34,L34,O34,R34) -> #REF!
A35: Fringe Benefits | F35: =#REF! -> #REF! | I35: =#REF! -> #REF! | L35: =#REF! -> #REF! | O35: =#REF! -> #REF! | R35: =#REF! -> #REF! | U35: =SUM(F35,I35,L35,O35,R35) -> #REF!
A36: Travel | F36: =#REF! -> #REF! | I36: =#REF! -> #REF! | L36: =#REF! -> #REF! | O36: =#REF! -> #REF! | R36: =#REF! -> #REF! | U36: =SUM(F36,I36,L36,O36,R36) -> #REF!
A37: Equipment | F37: =#REF! -> #REF! | I37: =#REF! -> #REF! | L37: =#REF! -> #REF! | O37: =#REF! -> #REF! | R37: =#REF! -> #REF! | U37: =SUM(F37,I37,L37,O37,R37) -> #REF!
A38: Materials and Supplies | F38: =#REF! -> #REF! | I38: =#REF! -> #REF! | L38: =#REF! -> #REF! | O38: =#REF! -> #REF! | R38: =#REF! -> #REF! | U38: =SUM(F38,I38,L38,O38,R38) -> #REF!
A39: Consultants | F39: =#REF! -> #REF! | I39: =#REF! -> #REF! | L39: =#REF! -> #REF! | O39: =#REF! -> #REF! | R39: =#REF! -> #REF! | U39: =SUM(F39,I39,L39,O39,R39) -> #REF!
A40: Contractual | F40: =#REF! -> #REF! | I40: =#REF! -> #REF! | L40: =#REF! -> #REF! | O40: =#REF! -> #REF! | R40: =#REF! -> #REF! | U40: =SUM(F40,I40,L40,O40,R40) -> #REF!
A41: Other Direct Costs | F41: =#REF! -> #REF! | I41: =#REF! -> #REF! | L41: =#REF! -> #REF! | O41: =#REF! -> #REF! | R41: =#REF! -> #REF! | U41: =SUM(F41,I41,L41,O41,R41) -> #REF!
A42: Subtotal | F42: =#REF! -> #REF! | I42: =#REF! -> #REF! | L42: =#REF! -> #REF! | O42: =#REF! -> #REF! | R42: =#REF! -> #REF! | U42: =SUM(F42,I42,L42,O42,R42) -> #REF!
A44: Service Center (excluding subcontractors) | F44: =#REF! -> #REF! | I44: =#REF! -> #REF! | L44: =#REF! -> #REF! | O44: =#REF! -> #REF! | R44: =#REF! -> #REF! | U44: =SUM(F44,I44,L44,O44,R44) -> #REF!
A45: Service Center on Subcontractors | F45: =#REF! -> #REF! | I45: =#REF! -> #REF! | L45: =#REF! -> #REF! | O45: =#REF! -> #REF! | R45: =#REF! -> #REF! | U45: =SUM(F45,I45,L45,O45,R45) -> #REF!
A47: F&A Costs | F47: =#REF! -> #REF! | I47: =#REF! -> #REF! | L47: =#REF! -> #REF! | O47: =#REF! -> #REF! | R47: =#REF! -> #REF! | U47: =SUM(F47,I47,L47,O47,R47) -> #REF!
A48: F&A Costs (Applied to Subcontracts) | F48: =#REF! -> #REF! | I48: =#REF! -> #REF! | L48: =#REF! -> #REF! | O48: =#REF! -> #REF! | R48: =#REF! -> #REF! | U48: =SUM(F48,I48,L48,O48,R48) -> #REF!
A50: Total per year | F50: =SUM(F42:F49) -> #REF! | I50: =SUM(I42:I49) -> #REF! | L50: =SUM(L42:L49) -> #REF! | O50: =SUM(O42:O49) -> #REF! | R50: =SUM(R42:R49) -> #REF! | U50: =SUM(F50,I50,L50,O50,R50) -> #REF!
A52: Grand Total | F52: =SUM(F50,F28) -> #REF! | I52: =SUM(I50,I28) -> #REF! | L52: =SUM(L50,L28) -> #REF! | O52: =SUM(O50,O28) -> #REF! | R52: =SUM(R50,R28) -> #REF! | U52: =SUM(F52,I52,L52,O52,R52) -> #REF!

Sheet TA Summary
B1: =Assumptions!$B$8 -> Partners of America
B2: =CONCATENATE(Assumptions!$B9," ",Assumptions!$C9) -> DONOR: USDOL
B3: =CONCATENATE(Assumptions!$B10," ",Assumptions!$C10) -> Country: Ecuador
B4: =CONCATENATE(Assumptions!$B11," ",Assumptions!$C11) -> Program Name: Project to Improve Adherence to International Labor Standards in the Agricultural Sector in Ecuador
B5: =CONCATENATE(Assumptions!$B12," ",Assumptions!$C12) -> Grant Number: FOA-ILAB-23-28
B7: TOTAL FUNDING FOR EXPATRIATE AND IN-COUNTRY TECHNICAL ASSISTANCE
B9: Line Item | C9: =#REF! -> #REF! | F9: =#REF! -> #REF! | I9: =#REF! -> #REF! | L9: =#REF! -> #REF! | O9: =#REF! -> #REF! | S9: Total
A11: 6.a | B11: Expatriate Technical Assistance
B12: Program and Technical Staff - US Hires | C12: =SUM(#REF!,#REF!) -> #REF! | F12: =SUM(#REF!,#REF!) -> #REF! | I12: =SUM(#REF!,#REF!) -> #REF! | L12: =SUM(#REF!,#REF!) -> #REF! | O12: =SUM(#REF!,#REF!) -> #REF! | S12: =SUM(C12:O12) -> #REF!
B13: STA US Hires | C13: =SUM(#REF!) -> #REF! | F13: =SUM(#REF!) -> #REF! | I13: =SUM(#REF!) -> #REF! | L13: =SUM(#REF!) -> #REF! | O13: =SUM(#REF!) -> #REF! | S13: =SUM(C13:O13) -> #REF!
B14: Regional Hires | C14: =SUM(#REF!,#REF!) -> #REF! | F14: =SUM(#REF!,#REF!) -> #REF! | I14: =SUM(#REF!,#REF!) -> #REF! | L14: =SUM(#REF!,#REF!) -> #REF! | O14: =SUM(#REF!,#REF!) -> #REF! | S14: =SUM(C14:O14) -> #REF!
B15: International Consultants | C15: =SUM(#REF!) -> #REF! | F15: =SUM(#REF!) -> #REF! | I15: =SUM(#REF!) -> #REF! | L15: =SUM(#REF!) -> #REF! | O15: =SUM(#REF!) -> #REF! | S15: =SUM(C15:O15) -> #REF!
B16: Fringe Benefits US Hires | C16: =SUM(#REF!,#REF!,#REF!) -> #REF! | F16: =SUM(#REF!,#REF!,#REF!) -> #REF! | I16: =SUM(#REF!,#REF!,#REF!) -> #REF! | L16: =SUM(#REF!,#REF!,#REF!) -> #REF! | O16: =SUM(#REF!,#REF!,#REF!) -> #REF! | S16: =SUM(C16:O16) -> #REF!
B17: Fringe Benefits Regional Hires | C17: =SUM(#REF!) -> #REF! | F17: =SUM(#REF!) -> #REF! | I17: =SUM(#REF!) -> #REF! | L17: =SUM(#REF!) -> #REF! | O17: =SUM(#REF!) -> #REF! | S17: =SUM(C17:O17) -> #REF!
B18: Allowances | C18: =SUM(#REF!) -> #REF! | F18: =SUM(#REF!) -> #REF! | I18: =SUM(#REF!) -> #REF! | L18: =SUM(#REF!) -> #REF! | O18: =SUM(#REF!) -> #REF! | S18: =SUM(C18:O18) -> #REF!
B19: International Travel | C19: =#REF! -> #REF! | F19: =#REF! -> #REF! | I19: =#REF! -> #REF! | L19: =#REF! -> #REF! | O19: =#REF! -> #REF! | S19: =SUM(C19:O19) -> #REF!
B20: International Consultants Travel | C20: =SUM(#REF!) -> #REF! | F20: =SUM(#REF!) -> #REF! | I20: =SUM(#REF!) -> #REF! | L20: =SUM(#REF!) -> #REF! | O20: =SUM(#REF!) -> #REF! | S20: =SUM(C20:O20) -> #REF!
B21: Total Expatriate TA | C21: =SUM(C12:C20) -> #REF! | F21: =SUM(F12:F20) -> #REF! | I21: =SUM(I12:I20) -> #REF! | L21: =SUM(L12:L20) -> #REF! | O21: =SUM(O12:O20) -> #REF! | S21: =SUM(C21:O21) -> #REF!
B23: Country Offices
B24: Program and Technical Staff - Local Hires | C24: =#REF! -> #REF! | F24: =#REF! -> #REF! | I24: =#REF! -> #REF! | L24: =#REF! -> #REF! | O24: =#REF! -> #REF! | S24: =SUM(O24,C24,F24,I24,L24) -> #REF!
B25: Support Staff - Local Hires | C25: =#REF! -> #REF! | F25: =#REF! -> #REF! | I25: =#REF! -> #REF! | L25: =#REF! -> #REF! | O25: =#REF! -> #REF! | S25: =SUM(O25,C25,F25,I25,L25) -> #REF!
B26: Local Consultants Labor | C26: =SUM(#REF!) -> #REF! | F26: =SUM(#REF!) -> #REF! | I26: =SUM(#REF!) -> #REF! | L26: =SUM(#REF!) -> #REF! | O26: =SUM(#REF!) -> #REF! | S26: =SUM(O26,C26,F26,I26,L26) -> #REF!
B27: Fringe Benefits - Local Hires | C27: =#REF! -> #REF! | F27: =#REF! -> #REF! | I27: =#REF! -> #REF! | L27: =#REF! -> #REF! | O27: =#REF! -> #REF! | S27: =SUM(O27,C27,F27,I27,L27) -> #REF!
B28: Domestic Travel | C28: =#REF! -> #REF! | F28: =#REF! -> #REF! | I28: =#REF! -> #REF! | L28: =#REF! -> #REF! | O28: =#REF! -> #REF! | S28: =SUM(O28,C28,F28,I28,L28) -> #REF!
B29: Local Consultants Travel | C29: =SUM(#REF!) -> #REF! | F29: =SUM(#REF!) -> #REF! | I29: =SUM(#REF!) -> #REF! | L29: =SUM(#REF!) -> #REF! | O29: =SUM(#REF!) -> #REF! | S29: =SUM(O29,C29,F29,I29,L29) -> #REF!
B30: Total Cooperating Country Nationals TA | C30: =SUM(C23:C29) -> #REF! | F30: =SUM(F23:F29) -> #REF! | I30: =SUM(I23:I29) -> #REF! | L30: =SUM(L23:L29) -> #REF! | O30: =SUM(O23:O29) -> #REF! | S30: =SUM(C30:O30) -> #REF!
B32: Total Technical Assistance Costs | C32: =SUM(C30,C21) -> #REF! | F32: =SUM(F30,F21) -> #REF! | I32: =SUM(I30,I21) -> #REF! | L32: =SUM(L30,L21) -> #REF! | O32: =SUM(O30,O21) -> #REF! | S32: =SUM(C32:O32) -> #REF!

Sheet Funding By Partner
A1: =Assumptions!$B$8 -> Partners of America
A2: =CONCATENATE(Assumptions!$B9," ",Assumptions!$C9) -> DONOR: USDOL
A3: =CONCATENATE(Assumptions!$B10," ",Assumptions!$C10) -> Country: Ecuador
A4: =CONCATENATE(Assumptions!$B11," ",Assumptions!$C11) -> Program Name: Project to Improve Adherence to International Labor Standards in the Agricultural Sector in Ecuador
A5: =CONCATENATE(Assumptions!$B12," ",Assumptions!$C12) -> Grant Number: FOA-ILAB-23-28
A7: TOTAL FUNDING BY PARTNER
A9: Partner | B9: =Assumptions!G24 -> Year 1 | E9: =Assumptions!J24 -> Year 2 | H9: =Assumptions!M24 -> Year 3 | K9: =Assumptions!P24 -> Year 4 | N9: =Assumptions!S24 -> Year 5 | Q9: Total
B10: Federal Funding | C10: Non-Federal Funding | E10: Federal Funding | F10: Non-Federal Funding | H10: Federal Funding | I10: Non-Federal Funding | K10: Federal Funding | L10: Non-Federal Funding | N10: Federal Funding | O10: Non-Federal Funding | Q10: Federal Funding | R10: Non-Federal Funding | T10: If RFA requests for Cost Share - Unhide columns "C", "F", "I", "L", "O" and "Q"
T11: Double-checks
A12: Jhpiego Corporation | B12: =B35-SUM(B13:B33) -> #REF! | E12: =E35-SUM(E13:E33) -> #REF! | H12: =H35-SUM(H13:H33) -> #REF! | K12: =K35-SUM(K13:K33) -> #REF! | N12: =N35-SUM(N13:N33) -> #REF! | Q12: =SUM(B12,E12,H12,K12,N12) -> #REF! | R12: =SUM(C12,F12,I12,L12,O12,#REF!,#REF!,#REF!,#REF!,#REF!) -> #REF! | T12: =SUM(B12:P12) -> #REF!
A14: =#REF! -> #REF! | B14: =#REF! -> #REF! | E14: =#REF! -> #REF! | H14: =#REF! -> #REF! | K14: =#REF! -> #REF! | N14: =#REF! -> #REF! | Q14: =SUM(B14,E14,H14,K14,N14) -> #REF! | R14: =SUM(O14,L14,I14,F14,C14) -> 0 | T14: =SUM(B14:P14) -> #REF!
A16: =#REF! -> #REF! | B16: =#REF! -> #REF! | E16: =#REF! -> #REF! | H16: =#REF! -> #REF! | K16: =#REF! -> #REF! | N16: =#REF! -> #REF! | Q16: =SUM(B16,E16,H16,K16,N16) -> #REF! | R16: =SUM(O16,L16,I16,F16,C16) -> 0 | T16: =SUM(B16:P16) -> #REF!
A18: =#REF! -> #REF! | B18: =#REF! -> #REF! | E18: =#REF! -> #REF! | H18: =#REF! -> #REF! | K18: =#REF! -> #REF! | N18: =#REF! -> #REF! | Q18: =SUM(B18,E18,H18,K18,N18) -> #REF! | R18: =SUM(O18,L18,I18,F18,C18) -> 0 | T18: =SUM(B18:P18) -> #REF!
A20: =#REF! -> #REF! | B20: =#REF! -> #REF! | E20: =#REF! -> #REF! | H20: =#REF! -> #REF! | K20: =#REF! -> #REF! | N20: =#REF! -> #REF! | Q20: =SUM(B20,E20,H20,K20,N20) -> #REF! | R20: =SUM(O20,L20,I20,F20,C20) -> 0 | T20: =SUM(B20:P20) -> #REF!
A22: =#REF! -> #REF! | B22: =#REF! -> #REF! | E22: =#REF! -> #REF! | H22: =#REF! -> #REF! | K22: =#REF! -> #REF! | N22: =#REF! -> #REF! | Q22: =SUM(B22,E22,H22,K22,N22) -> #REF! | R22: =SUM(O22,L22,I22,F22,C22) -> 0 | T22: =SUM(B22:P22) -> #REF!
A24: =#REF! -> #REF! | B24: =#REF! -> #REF! | E24: =#REF! -> #REF! | H24: =#REF! -> #REF! | K24: =#REF! -> #REF! | N24: =#REF! -> #REF! | Q24: =SUM(B24,E24,H24,K24,N24) -> #REF! | R24: =SUM(O24,L24,I24,F24,C24) -> 0 | T24: =SUM(B24:P24) -> #REF!
A26: =#REF! -> #REF! | B26: =#REF! -> #REF! | E26: =#REF! -> #REF! | H26: =#REF! -> #REF! | K26: =#REF! -> #REF! | N26: =#REF! -> #REF! | Q26: =SUM(B26,E26,H26,K26,N26) -> #REF! | R26: =SUM(O26,L26,I26,F26,C26) -> 0 | T26: =SUM(B26:P26) -> #REF!
A28: =#REF! -> #REF! | B28: =#REF! -> #REF! | E28: =#REF! -> #REF! | H28: =#REF! -> #REF! | K28: =#REF! -> #REF! | N28: =#REF! -> #REF! | Q28: =SUM(B28,E28,H28,K28,N28) -> #REF! | R28: =SUM(O28,L28,I28,F28,C28) -> 0 | T28: =SUM(B28:P28) -> #REF!
A30: =#REF! -> #REF! | B30: =#REF! -> #REF! | E30: =#REF! -> #REF! | H30: =#REF! -> #REF! | K30: =#REF! -> #REF! | N30: =#REF! -> #REF! | Q30: =SUM(B30,E30,H30,K30,N30) -> #REF! | R30: =SUM(O30,L30,I30,F30,C30) -> 0 | T30: =SUM(B30:P30) -> #REF!
Q32: =SUM(N32,K32,H32,E32,B32) -> 0 | R32: =SUM(O32,L32,I32,F32,C32) -> 0 | T32: =SUM(B32:P32) -> 0
A35: TOTAL COSTS | B35: =#REF! -> #REF! | C35: =SUM(C11:C34) -> 0 | E35: =#REF! -> #REF! | F35: =SUM(F11:F34) -> 0 | H35: =#REF! -> #REF! | I35: =SUM(I11:I34) -> 0 | K35: =#REF! -> #REF! | L35: =SUM(L11:L34) -> 0 | N35: =#REF! -> #REF! | O35: =SUM(O11:O34) -> 0 | Q35: =SUM(B35,E35,H35,K35,N35) -> #REF! | R35: =SUM(O35,L35,I35,F35,C35) -> 0 | T35: =SUM(B35:P35) -> #REF!

Sheet LOE Table
A1: =Assumptions!$B$8 -> Partners of America
A2: =CONCATENATE(Assumptions!$B9," ",Assumptions!$C9) -> DONOR: USDOL | Q2: Escalation Factor:
A3: =CONCATENATE(Assumptions!$B10," ",Assumptions!$C10) -> Country: Ecuador | Q3: Inflation Rate:
A4: =CONCATENATE(Assumptions!$B11," ",Assumptions!$C11) -> Program Name: Project to Improve Adherence to International Labor Standards in the Agricultural Sector in Ecuador
A5: =CONCATENATE(Assumptions!$B12," ",Assumptions!$C12) -> Grant Number: FOA-ILAB-23-28
A7: LEVEL OF EFFORT TABLE
A9: PERSONNEL | C9: =#REF! -> #REF! | F9: =#REF! -> #REF! | I9: =Assumptions!M24 -> Year 3 | L9: =#REF! -> #REF! | O9: =#REF! -> #REF! | R9: Total | T9: Calculation
A10: Position Description | B10: Unit | C10: Units | F10: Units | I10: Units | L10: Units | O10: Units | R10: % | S10: US$ | T10: Check: | V10: show
V11: =IF(SUM(S12:S190)=0,"hide","show") -> #REF!
A12: =#REF! -> #REF! | V12: =IF(SUM(S20:S190)=0,"hide","show") -> #REF!
A13: =#REF! -> #REF! | V13: =IF(SUM(S14:S18)=0,"hide","show") -> #REF!
A14: =#REF! -> #REF! | B14: % | C14: =#REF! -> #REF! | F14: =#REF! -> #REF! | I14: =#REF! -> #REF! | L14: =#REF! -> #REF! | O14: =#REF! -> #REF! | R14: =C14+F14+I14+L14+O14 -> #REF! | S14: =#REF! -> #REF! | V14: =IF(S14=0,"hide","show") -> #REF!
A15: =#REF! -> #REF! | B15: % | C15: =#REF! -> #REF! | F15: =#REF! -> #REF! | I15: =#REF! -> #REF! | L15: =#REF! -> #REF! | O15: =#REF! -> #REF! | R15: =C15+F15+I15+L15+O15 -> #REF! | S15: =#REF! -> #REF! | V15: =IF(S15=0,"hide","show") -> #REF!
A16: =#REF! -> #REF! | B16: % | C16: =#REF! -> #REF! | F16: =#REF! -> #REF! | I16: =#REF! -> #REF! | L16: =#REF! -> #REF! | O16: =#REF! -> #REF! | R16: =C16+F16+I16+L16+O16 -> #REF! | S16: =#REF! -> #REF! | V16: =IF(S16=0,"hide","show") -> #REF!
A17: =#REF! -> #REF! | B17: % | C17: =#REF! -> #REF! | F17: =#REF! -> #REF! | I17: =#REF! -> #REF! | L17: =#REF! -> #REF! | O17: =#REF! -> #REF! | R17: =C17+F17+I17+L17+O17 -> #REF! | S17: =#REF! -> #REF! | V17: =IF(S17=0,"hide","show") -> #REF!
A18: =#REF! -> #REF! | B18: % | C18: =#REF! -> #REF! | F18: =#REF! -> #REF! | I18: =#REF! -> #REF! | L18: =#REF! -> #REF! | O18: =#REF! -> #REF! | R18: =C18+F18+I18+L18+O18 -> #REF! | S18: =#REF! -> #REF! | V18: =IF(S18=0,"hide","show") -> #REF!
V19: =IF(SUM(S20:S110)=0,"hide","show") -> #REF!
A20: =#REF! -> #REF! | V20: =IF(SUM(S21:S25)=0,"hide","show") -> #REF!
A21: =#REF! -> #REF! | B21: % | C21: =#REF! -> #REF! | F21: =#REF! -> #REF! | I21: =#REF! -> #REF! | L21: =#REF! -> #REF! | O21: =#REF! -> #REF! | R21: =C21+F21+I21+L21+O21 -> #REF! | S21: =#REF! -> #REF! | V21: =IF(S21=0,"hide","show") -> #REF!
A22: =#REF! -> #REF! | B22: % | C22: =#REF! -> #REF! | F22: =#REF! -> #REF! | I22: =#REF! -> #REF! | L22: =#REF! -> #REF! | O22: =#REF! -> #REF! | R22: =C22+F22+I22+L22+O22 -> #REF! | S22: =#REF! -> #REF! | V22: =IF(S22=0,"hide","show") -> #REF!
A23: =#REF! -> #REF! | B23: % | C23: =#REF! -> #REF! | F23: =#REF! -> #REF! | I23: =#REF! -> #REF! | L23: =#REF! -> #REF! | O23: =#REF! -> #REF! | R23: =C23+F23+I23+L23+O23 -> #REF! | S23: =#REF! -> #REF! | V23: =IF(S23=0,"hide","show") -> #REF!
A24: =#REF! -> #REF! | B24: % | C24: =#REF! -> #REF! | F24: =#REF! -> #REF! | I24: =#REF! -> #REF! | L24: =#REF! -> #REF! | O24: =#REF! -> #REF! | R24: =C24+F24+I24+L24+O24 -> #REF! | S24: =#REF! -> #REF! | V24: =IF(S24=0,"hide","show") -> #REF!
A25: =#REF! -> #REF! | B25: % | C25: =#REF! -> #REF! | F25: =#REF! -> #REF! | I25: =#REF! -> #REF! | L25: =#REF! -> #REF! | O25: =#REF! -> #REF! | R25: =C25+F25+I25+L25+O25 -> #REF! | S25: =#REF! -> #REF! | V25: =IF(S25=0,"hide","show") -> #REF!
V26: =IF(SUM(S27:S190)=0,"hide","show") -> #REF!
A27: =#REF! -> #REF! | V27: =IF(SUM(S28:S190)=0,"hide","show") -> #REF!
A28: =#REF! -> #REF! | V28: =IF(SUM(S29:S110)=0,"hide","show") -> #REF!
A29: =#REF! -> #REF! | B29: % | C29: =#REF! -> #REF! | F29: =#REF! -> #REF! | I29: =#REF! -> #REF! | L29: =#REF! -> #REF! | O29: =#REF! -> #REF! | R29: =C29+F29+I29+L29+O29 -> #REF! | S29: =#REF! -> #REF! | V29: =IF(S29=0,"hide","show") -> #REF!
A30: =#REF! -> #REF! | B30: % | C30: =#REF! -> #REF! | F30: =#REF! -> #REF! | I30: =#REF! -> #REF! | L30: =#REF! -> #REF! | O30: =#REF! -> #REF! | R30: =C30+F30+I30+L30+O30 -> #REF! | S30: =#REF! -> #REF! | V30: =IF(S30=0,"hide","show") -> #REF!
A31: =#REF! -> #REF! | B31: % | C31: =#REF! -> #REF! | F31: =#REF! -> #REF! | I31: =#REF! -> #REF! | L31: =#REF! -> #REF! | O31: =#REF! -> #REF! | R31: =C31+F31+I31+L31+O31 -> #REF! | S31: =#REF! -> #REF! | V31: =IF(S31=0,"hide","show") -> #REF!
A32: =#REF! -> #REF! | B32: % | C32: =#REF! -> #REF! | F32: =#REF! -> #REF! | I32: =#REF! -> #REF! | L32: =#REF! -> #REF! | O32: =#REF! -> #REF! | R32: =C32+F32+I32+L32+O32 -> #REF! | S32: =#REF! -> #REF! | V32: =IF(S32=0,"hide","show") -> #REF!
A33: =#REF! -> #REF! | B33: % | C33: =#REF! -> #REF! | F33: =#REF! -> #REF! | I33: =#REF! -> #REF! | L33: =#REF! -> #REF! | O33: =#REF! -> #REF! | R33: =C33+F33+I33+L33+O33 -> #REF! | S33: =#REF! -> #REF! | V33: =IF(S33=0,"hide","show") -> #REF!
A34: =#REF! -> #REF! | B34: % | C34: =#REF! -> #REF! | F34: =#REF! -> #REF! | I34: =#REF! -> #REF! | L34: =#REF! -> #REF! | O34: =#REF! -> #REF! | R34: =C34+F34+I34+L34+O34 -> #REF! | S34: =#REF! -> #REF! | V34: =IF(S34=0,"hide","show") -> #REF!
A35: =#REF! -> #REF! | B35: % | C35: =#REF! -> #REF! | F35: =#REF! -> #REF! | I35: =#REF! -> #REF! | L35: =#REF! -> #REF! | O35: =#REF! -> #REF! | R35: =C35+F35+I35+L35+O35 -> #REF! | S35: =#REF! -> #REF! | V35: =IF(S35=0,"hide","show") -> #REF!
A36: =#REF! -> #REF! | B36: % | C36: =#REF! -> #REF! | F36: =#REF! -> #REF! | I36: =#REF! -> #REF! | L36: =#REF! -> #REF! | O36: =#REF! -> #REF! | R36: =C36+F36+I36+L36+O36 -> #REF! | S36: =#REF! -> #REF! | V36: =IF(S36=0,"hide","show") -> #REF!
A37: =#REF! -> #REF! | B37: % | C37: =#REF! -> #REF! | F37: =#REF! -> #REF! | I37: =#REF! -> #REF! | L37: =#REF! -> #REF! | O37: =#REF! -> #REF! | R37: =C37+F37+I37+L37+O37 -> #REF! | S37: =#REF! -> #REF! | V37: =IF(S37=0,"hide","show") -> #REF!
A38: =#REF! -> #REF! | B38: % | C38: =#REF! -> #REF! | F38: =#REF! -> #REF! | I38: =#REF! -> #REF! | L38: =#REF! -> #REF! | O38: =#REF! -> #REF! | R38: =C38+F38+I38+L38+O38 -> #REF! | S38: =#REF! -> #REF! | V38: =IF(S38=0,"hide","show") -> #REF!
A39: =#REF! -> #REF! | B39: % | C39: =#REF! -> #REF! | F39: =#REF! -> #REF! | I39: =#REF! -> #REF! | L39: =#REF! -> #REF! | O39: =#REF! -> #REF! | R39: =C39+F39+I39+L39+O39 -> #REF! | S39: =#REF! -> #REF! | V39: =IF(S39=0,"hide","show") -> #REF!
A40: =#REF! -> #REF! | B40: % | C40: =#REF! -> #REF! | F40: =#REF! -> #REF! | I40: =#REF! -> #REF! | L40: =#REF! -> #REF! | O40: =#REF! -> #REF! | R40: =C40+F40+I40+L40+O40 -> #REF! | S40: =#REF! -> #REF! | V40: =IF(S40=0,"hide","show") -> #REF!
... A114: =#REF! -> #REF! | B114: % | C114: =#REF! -> #REF! | F114: =#REF! -> #REF! | I114: =#REF! -> #REF! | L114: =#REF! -> #REF! | O114: =#REF! -> #REF! | R114: =C114+F114+I114+L114+O114 -> #REF! | S114: =#REF! -> #REF! | V114: =IF(S114=0,"hide","show") -> #REF!
V115: =IF(SUM(S117:S190)=0,"hide","show") -> #REF!
...

Sheet Total Budget by Sponsored Class
B1: =Assumptions!B8 -> Partners of America
B2: =Assumptions!B9 -> DONOR: | C2: =Assumptions!C9 -> USDOL
B3: =Assumptions!B10 -> Country: | C3: =Assumptions!C10 -> Ecuador
B4: =Assumptions!B11 -> Program Name: | C4: =Assumptions!C11 -> Project to Improve Adherence to International Labor Standards in the Agricultural Sector in Ecuador
B5: =Assumptions!B12 -> Grant Number: | C5: =Assumptions!C12 -> FOA-ILAB-23-28
B6: =Assumptions!B13 -> Period of Performance: | C6: =Assumptions!C13 -> 48 months | H6: =Assumptions!G13 -> 0
B8: TOTAL BUDGET SUMMARY BY SPONSORED CLASS
H10: US COSTS for ION | I10: 78 - 12345678
A12: SF424a | B12: Sponsored Class | C12: Description | D12: G/L | E12: Description | H12: Total | I12: =#REF! -> #REF! | L12: =#REF! -> #REF! | O12: =#REF! -> #REF! | R12: =#REF! -> #REF! | U12: =#REF! -> #REF!
A14: Personnel | B14: 610000 | C14: Salaries & Wages: Faculty and Senior Staff | H14: =SUM(I14,L14,O14,R14,U14) -> #REF! | I14: =SUM('US Costs by Sponsored Class'!I14,'Incountry Costs by GL USD'!I15) -> #REF! | L14: =SUM('US Costs by Sponsored Class'!L14,'Incountry Costs by GL USD'!L15) -> #REF! | O14: =SUM('US Costs by Sponsored Class'!O14,'Incountry Costs by GL USD'!O15) -> #REF! | R14: =SUM('US Costs by Sponsored Class'!R14,'Incountry Costs by GL USD'!R15) -> #REF! | U14: =SUM('US Costs by Sponsored Class'!U14,'Incountry Costs by GL USD'!U15) -> #REF!
B15: 612000 | C15: Salaries & Wages: Administrative Staff | H15: =SUM(I15,L15,O15,R15,U15) -> #REF! | I15: ='US Costs by Sponsored Class'!I15 -> #REF! | L15: ='US Costs by Sponsored Class'!L15 -> #REF! | O15: ='US Costs by Sponsored Class'!O15 -> #REF! | R15: ='US Costs by Sponsored Class'!R15 -> #REF! | U15: ='US Costs by Sponsored Class'!U15 -> #REF!
A17: Fringe Benefits | B17: 620000 | C17: Fringe Benefits | H17: =SUM(I17,L17,O17,R17,U17) -> #REF! | I17: =SUM('US Costs by Sponsored Class'!I16,'Incountry Costs by GL USD'!I16) -> #REF! | L17: =SUM('US Costs by Sponsored Class'!L16,'Incountry Costs by GL USD'!L16) -> #REF! | O17: =SUM('US Costs by Sponsored Class'!O16,'Incountry Costs by GL USD'!O16) -> #REF! | R17: =SUM('US Costs by Sponsored Class'!R16,'Incountry Costs by GL USD'!R16) -> #REF! | U17: =SUM('US Costs by Sponsored Class'!U16,'Incountry Costs by GL USD'!U16) -> #REF!
A19: Travel | B19: 652000 | C19: Travel Domestic | H19: =SUM(I19,L19,O19,R19,U19) -> #REF! | I19: =SUM('US Costs by Sponsored Class'!I18,'Incountry Costs by GL USD'!I17) -> #REF! | L19: =SUM('US Costs by Sponsored Class'!L18,'Incountry Costs by GL USD'!L17) -> #REF! | O19: =SUM('US Costs by Sponsored Class'!O18,'Incountry Costs by GL USD'!O17) -> #REF! | R19: =SUM('US Costs by Sponsored Class'!R18,'Incountry Costs by GL USD'!R17) -> #REF! | U19: =SUM('US Costs by Sponsored Class'!U18,'Incountry Costs by GL USD'!U17) -> #REF!
B20: 652100 | C20: Travel Foreign | H20: =SUM(I20,L20,O20,R20,U20) -> #REF! | I20: =SUM('US Costs by Sponsored Class'!H19,'Incountry Costs by GL USD'!I18:I19) -> #REF! | L20: =SUM('US Costs by Sponsored Class'!K19,'Incountry Costs by GL USD'!L18:L19) -> #REF! | O20: =SUM('US Costs by Sponsored Class'!N19,'Incountry Costs by GL USD'!O18:O19) -> #REF! | R20: =SUM('US Costs by Sponsored Class'!Q19,'Incountry Costs by GL USD'!R18:R19) -> #REF! | U20: =SUM('US Costs by Sponsored Class'!T19,'Incountry Costs by GL USD'!U18:U19) -> #REF!
A22: Supplies | B22: 630000 | C22: Supplies & Materials | H22: =SUM(I22,L22,O22,R22,U22) -> #REF! | I22: =SUM('US Costs by Sponsored Class'!I21:I22,'Incountry Costs by GL USD'!I20:I29) -> #REF! | L22: =SUM('US Costs by Sponsored Class'!L21:L22,'Incountry Costs by GL USD'!L20:L29) -> #REF! | O22: =SUM('US Costs by Sponsored Class'!O21:O22,'Incountry Costs by GL USD'!O20:O29) -> #REF! | R22: =SUM('US Costs by Sponsored Class'!R21:R22,'Incountry Costs by GL USD'!R20:R29) -> #REF! | U22: =SUM('US Costs by Sponsored Class'!U21:U22,'Incountry Costs by GL USD'!U20:U29) -> #REF!
D24: 633032 | E24: Office Supplies
D25: 633037 | E25: Publications/Journals/Subscriptions
D26: 635001 | E26: Electricity
D27: 635010 | E27: Utilities: Water
D28: 640282 | E28: Delivery/Courier Service
A30: Equipment | B30: 653400 | C30: Equipment | H30: =SUM(I30,L30,O30,R30,U30) -> #REF! | I30: =SUM('US Costs by Sponsored Class'!I29,'Incountry Costs by GL USD'!I30) -> #REF! | L30: =SUM('US Costs by Sponsored Class'!L29,'Incountry Costs by GL USD'!L30) -> #REF! | O30: =SUM('US Costs by Sponsored Class'!O29,'Incountry Costs by GL USD'!O30) -> #REF! | R30: =SUM('US Costs by Sponsored Class'!R29,'Incountry Costs by GL USD'!R30) -> #REF! | U30: =SUM('US Costs by Sponsored Class'!U29,'Incountry Costs by GL USD'!U30) -> #REF!
A32: Contractual | B32: 640300 | C32: Contractual Services | H32: =SUM(I32,L32,O32,R32,U32) -> #REF! | I32: =SUM('US Costs by Sponsored Class'!I31,'Incountry Costs by GL USD'!I32:I44) -> #REF! | L32: =SUM('US Costs by Sponsored Class'!L31,'Incountry Costs by GL USD'!L32:L44) -> #REF! | O32: =SUM('US Costs by Sponsored Class'!O31,'Incountry Costs by GL USD'!O32:O44) -> #REF! | R32: =SUM('US Costs by Sponsored Class'!R31,'Incountry Costs by GL USD'!R32:R44) -> #REF! | U32: =SUM('US Costs by Sponsored Class'!U31,'Incountry Costs by GL USD'!U32:U44) -> #REF!
B33: 640500 | C33: Consultant | H33: =SUM(I33,L33,O33,R33,U33) -> #REF! | I33: =SUM('US Costs by Sponsored Class'!I32,'Incountry Costs by GL USD'!I45) -> #REF! | L33: =SUM('US Costs by Sponsored Class'!L32,'Incountry Costs by GL USD'!L45) -> #REF! | O33: =SUM('US Costs by Sponsored Class'!O32,'Incountry Costs by GL USD'!O45) -> #REF! | R33: =SUM('US Costs by Sponsored Class'!R32,'Incountry Costs by GL USD'!R45) -> #REF! | U33: =SUM('US Costs by Sponsored Class'!U32,'Incountry Costs by GL USD'!U45) -> #REF!
B34: 642400 | C34: Subaward | H34: =SUM(I34,L34,O34,R34,U34) -> #REF! | I34: =SUM('US Costs by Sponsored Class'!I33,'Incountry Costs by GL USD'!I46) -> #REF! | L34: =SUM('US Costs by Sponsored Class'!L33,'Incountry Costs by GL USD'!L46) -> #REF! | O34: =SUM('US Costs by Sponsored Class'!O33,'Incountry Costs by GL USD'!O46) -> #REF! | R34: =SUM('US Costs by Sponsored Class'!R33,'Incountry Costs by GL USD'!R46) -> #REF! | U34: =SUM('US Costs by Sponsored Class'!U33,'Incountry Costs by GL USD'!U46) -> #REF!
B35: 637000 | C35: Repairs & Maintenance | H35: =SUM(I35,L35,O35,R35,U35) -> #REF! | I35: =SUM('US Costs by Sponsored Class'!I34,'Incountry Costs by GL USD'!I31) -> #REF! | L35: =SUM('US Costs by Sponsored Class'!L34,'Incountry Costs by GL USD'!L31) -> #REF! | O35: =SUM('US Costs by Sponsored Class'!O34,'Incountry Costs by GL USD'!O31) -> #REF! | R35: =SUM('US Costs by Sponsored Class'!R34,'Incountry Costs by GL USD'!R31) -> #REF! | U35: =SUM('US Costs by Sponsored Class'!U34,'Incountry Costs by GL USD'!U31) -> #REF!
A37: Other | B37: 640102 | C37: Leased Facilities External | H37: =SUM(I37,L37,O37,R37,U37) -> #REF! | I37: =SUM('US Costs by Sponsored Class'!I36,'Incountry Costs by GL USD'!I47) -> #REF! | L37: =SUM('US Costs by Sponsored Class'!L36,'Incountry Costs by GL USD'!L47) -> #REF! | O37: =SUM('US Costs by Sponsored Class'!O36,'Incountry Costs by GL USD'!O47) -> #REF! | R37: =SUM('US Costs by Sponsored Class'!R36,'Incountry Costs by GL USD'!R47) -> #REF! | U37: =SUM('US Costs by Sponsored Class'!U36,'Incountry Costs by GL USD'!U47) -> #REF!
B38: 641400 | C38: Telecommunications | H38: =SUM(I38,L38,O38,R38,U38) -> #REF! | I38: =SUM('US Costs by Sponsored Class'!I37,'Incountry Costs by GL USD'!I48) -> #REF! | L38: =SUM('US Costs by Sponsored Class'!L37,'Incountry Costs by GL USD'!L48) -> #REF! | O38: =SUM('US Costs by Sponsored Class'!O37,'Incountry Costs by GL USD'!O48) -> #REF! | R38: =SUM('US Costs by Sponsored Class'!R37,'Incountry Costs by GL USD'!R48) -> #REF! | U38: =SUM('US Costs by Sponsored Class'!U37,'Incountry Costs by GL USD'!U48) -> #REF!
B39: 642500 | C39: Other Expenses | H39: =SUM(I39,L39,O39,R39,U39) -> #REF! | I39: =SUM('US Costs by Sponsored Class'!I38,'Incountry Costs by GL USD'!I49:I54) -> #REF! | L39: =SUM('US Costs by Sponsored Class'!L38,'Incountry Costs by GL USD'!L49:L54) -> #REF! | O39: =SUM('US Costs by Sponsored Class'!O38,'Incountry Costs by GL USD'!O49:O54) -> #REF! | R39: =SUM('US Costs by Sponsored Class'!R38,'Incountry Costs by GL USD'!R49:R54) -> #REF! | U39: =SUM('US Costs by Sponsored Class'!U38,'Incountry Costs by GL USD'!U49:U54) -> #REF!
B40: 643000 | C40: Other Expenses (Excluded from F&A) | H40: =SUM(I40,L40,O40,R40,U40) -> #REF! | I40: =SUM('US Costs by Sponsored Class'!I39,'Incountry Costs by GL USD'!I55:I56) -> #REF! | L40: =SUM('US Costs by Sponsored Class'!L39,'Incountry Costs by GL USD'!L55:L56) -> #REF! | O40: =SUM('US Costs by Sponsored Class'!O39,'Incountry Costs by GL USD'!O55:O56) -> #REF! | R40: =SUM('US Costs by Sponsored Class'!R39,'Incountry Costs by GL USD'!R55:R56) -> #REF! | U40: =SUM('US Costs by Sponsored Class'!U39,'Incountry Costs by GL USD'!U55:U56) -> #REF!
B42: Subtotal | H42: =SUM(I42,L42,O42,R42,U42) -> #REF! | I42: =SUM(I13:I41) -> #REF! | L42: =SUM(L13:L41) -> #REF! | O42: =SUM(O13:O41) -> #REF! | R42: =SUM(R13:R41) -> #REF! | U42: =SUM(U13:U41) -> #REF!
B44: 690007 | C44: Service Center | H44: =SUM(I44,L44,O44,R44,U44) -> #REF! | I44: ='US Costs by Sponsored Class'!I43 -> #REF! | L44: ='US Costs by Sponsored Class'!L43 -> #REF! | O44: ='US Costs by Sponsored Class'!O43 -> #REF! | R44: ='US Costs by Sponsored Class'!R43 -> #REF! | U44: ='US Costs by Sponsored Class'!U43 -> #REF!
B46: 699999 | C46: F&A | H46: =SUM(I46,L46,O46,R46,U46) -> #REF! | I46: ='US Costs by Sponsored Class'!I45 -> #REF! | L46: ='US Costs by Sponsored Class'!L45 -> #REF! | O46: ='US Costs by Sponsored Class'!O45 -> #REF! | R46: ='US Costs by Sponsored Class'!R45 -> #REF! | U46: ='US Costs by Sponsored Class'!U45 -> #REF!
B48: Total per year | H48: =SUM(I48,L48,O48,R48,U48) -> #REF! | I48: =SUM(I42:I47) -> #REF! | L48: =SUM(L42:L47) -> #REF! | O48: =SUM(O42:O47) -> #REF! | R48: =SUM(R42:R47) -> #REF! | U48: =SUM(U42:U47) -> #REF!
B50: Calculation check

Sheet US Costs by Sponsored Class
B1: =Assumptions!B8 -> Partners of America
B2: =Assumptions!B9 -> DONOR: | C2: =Assumptions!C9 -> USDOL
B3: =Assumptions!B10 -> Country: | C3: =Assumptions!C10 -> Ecuador
B4: =Assumptions!B11 -> Program Name: | C4: =Assumptions!C11 -> Project to Improve Adherence to International Labor Standards in the Agricultural Sector in Ecuador
B5: =Assumptions!B12 -> Grant Number: | C5: =Assumptions!C12 -> FOA-ILAB-23-28
B6: =Assumptions!B13 -> Period of Performance: | C6: =Assumptions!C13 -> 48 months | E6: =Assumptions!G13 -> 0
B8: BUDGET SUMMARY BY G/L
D10: US COSTS for ION | E10: 78 - 12345678
A12: SF424a | B12: Sponsored Class | C12: Description | D12: G/L | E12: Description | H12: Workplan Year Budget | I12: =#REF! -> #REF! | L12: =#REF! -> #REF! | O12: =#REF! -> #REF! | R12: =#REF! -> #REF! | U12: =#REF! -> #REF!
A14: Personnel | B14: 610000 | C14: Salaries & Wages: Faculty and Senior Staff | D14: 613001 | E14: Salary: Non-Administrative Staff | H14: =SUM(I14,L14,O14,R14,U14) -> #REF! | I14: =SUMIF(#REF!,$B$14,#REF!) -> #REF! | L14: =SUMIF(#REF!,$B$14,#REF!) -> #REF! | O14: =SUMIF(#REF!,$B$14,#REF!) -> #REF! | R14: =SUMIF(#REF!,$B$14,#REF!) -> #REF! | U14: =SUMIF(#REF!,$B$14,#REF!) -> #REF!
B15: 612000 | C15: Salaries & Wages: Administrative Staff | D15: 612001 | E15: Salary: Administrative Staff | H15: =SUM(I15,L15,O15,R15,U15) -> #REF! | I15: =SUMIF(#REF!,$B$15,#REF!) -> #REF! | L15: =SUMIF(#REF!,$B$15,#REF!) -> #REF! | O15: =SUMIF(#REF!,$B$15,#REF!) -> #REF! | R15: =SUMIF(#REF!,$B$15,#REF!) -> #REF! | U15: =SUMIF(#REF!,$B$15,#REF!) -> #REF!
A16: Fringe Benefits | B16: 620000 | C16: Fringe Benefits | D16: 620001 | E16: Fringe Benefits: Staff | H16: =SUM(I16,L16,O16,R16,U16) -> #REF! | I16: =SUMIF(#REF!,$B$16,#REF!) -> #REF! | L16: =SUMIF(#REF!,$B$16,#REF!) -> #REF! | O16: =SUMIF(#REF!,$B$16,#REF!) -> #REF! | R16: =SUMIF(#REF!,$B$16,#REF!) -> #REF! | U16: =SUMIF(#REF!,$B$16,#REF!) -> #REF!
D17: 620002 | E17: Fringe Benefits: Allowances
A18: Travel | B18: 652000 | C18: Travel Domestic | H18: =SUM(I18,L18,O18,R18,U18) -> #REF! | I18: =SUMIF(#REF!,$B$18,#REF!) -> #REF! | L18: =SUMIF(#REF!,$B$18,#REF!) -> #REF! | O18: =SUMIF(#REF!,$B$18,#REF!) -> #REF! | R18: =SUMIF(#REF!,$B$18,#REF!) -> #REF! | U18: =SUMIF(#REF!,$B$18,#REF!) -> #REF!
B19: 652100 | C19: Travel Foreign | H19: =SUM(I19,L19,O19,R19,U19) -> #REF! | I19: =SUMIF(#REF!,$B$19,#REF!) -> #REF! | L19: =SUMIF(#REF!,$B$19,#REF!) -> #REF! | O19: =SUMIF(#REF!,$B$19,#REF!) -> #REF! | R19: =SUMIF(#REF!,$B$19,#REF!) -> #REF! | U19: =SUMIF(#REF!,$B$19,#REF!) -> #REF!
A21: Supplies | B21: 630000 | C21: Supplies & Materials | D21: 631001 | E21: Furniture | H21: =SUM(I21,L21,O21,R21,U21) -> #REF! | I21: =SUMIF(#REF!,$B$21,#REF!) -> #REF! | L21: =SUMIF(#REF!,$B$21,#REF!) -> #REF! | O21: =SUMIF(#REF!,$B$21,#REF!) -> #REF! | R21: =SUMIF(#REF!,$B$21,#REF!) -> #REF! | U21: =SUMIF(#REF!,$B$21,#REF!) -> #REF!
D22: 631003 | E22: Non-capital PC purchases | H22: =SUM(I22,L22,O22,R22,U22) -> #REF! | I22: =SUMIF(#REF!,$B$21,#REF!) -> #REF! | L22: =SUMIF(#REF!,$B$21,#REF!) -> #REF! | O22: =SUMIF(#REF!,$B$21,#REF!) -> #REF! | R22: =SUMIF(#REF!,$B$21,#REF!) -> #REF! | U22: =SUMIF(#REF!,$B$21,#REF!) -> #REF!
D23: 633032 | E23: Office Supplies | H23: =SUM(I23,L23,O23,R23,U23,#REF!,#REF!,#REF!,#REF!,#REF!) -> #REF!
D24: 633037 | E24: Publications/Journals/Subscriptions | H24: =SUM(I24,L24,O24,R24,U24,#REF!,#REF!,#REF!,#REF!,#REF!) -> #REF!
D25: 635001 | E25: Electricity | H25: =SUM(I25,L25,O25,R25,U25,#REF!,#REF!,#REF!,#REF!,#REF!) -> #REF!
D26: 635010 | E26: Utilities: Water | H26: =SUM(I26,L26,O26,R26,U26,#REF!,#REF!,#REF!,#REF!,#REF!) -> #REF!
D27: 640282 | E27: Delivery/Courier Service | H27: =SUM(I27,L27,O27,R27,U27,#REF!,#REF!,#REF!,#REF!,#REF!) -> #REF!
A29: Equipment | B29: 653400 | C29: Equipment | H29: =SUM(I29,L29,O29,R29,U29) -> #REF! | I29: =SUMIF(#REF!,$B$29,#REF!) -> #REF! | L29: =SUMIF(#REF!,$B$29,#REF!) -> #REF! | O29: =SUMIF(#REF!,$B$29,#REF!) -> #REF! | R29: =SUMIF(#REF!,$B$29,#REF!) -> #REF! | U29: =SUMIF(#REF!,$B$29,#REF!) -> #REF!
A31: Contractual | B31: 640300 | C31: Contractual Services | H31: =SUM(I31,L31,O31,R31,U31) -> #REF! | I31: =SUMIF(#REF!,$B$31,#REF!) -> #REF! | L31: =SUMIF(#REF!,$B$31,#REF!) -> #REF! | O31: =SUMIF(#REF!,$B$31,#REF!) -> #REF! | R31: =SUMIF(#REF!,$B$31,#REF!) -> #REF! | U31: =SUMIF(#REF!,$B$31,#REF!) -> #REF!
B32: 640500 | C32: Consultant | H32: =SUM(I32,L32,O32,R32,U32) -> #REF! | I32: =SUMIF(#REF!,$B$32,#REF!) -> #REF! | L32: =SUMIF(#REF!,$B$32,#REF!) -> #REF! | O32: =SUMIF(#REF!,$B$32,#REF!) -> #REF! | R32: =SUMIF(#REF!,$B$32,#REF!) -> #REF! | U32: =SUMIF(#REF!,$B$32,#REF!) -> #REF!
B33: 642400 | C33: Subaward | H33: =SUM(I33,L33,O33,R33,U33) -> #REF! | I33: =SUMIF(#REF!,$B$33,#REF!) -> #REF! | L33: =SUMIF(#REF!,$B$33,#REF!) -> #REF! | O33: =SUMIF(#REF!,$B$33,#REF!) -> #REF! | R33: =SUMIF(#REF!,$B$33,#REF!) -> #REF! | U33: =SUMIF(#REF!,$B$33,#REF!) -> #REF!
B34: 637000 | C34: Repairs & Maintenance | H34: =SUM(I34,L34,O34,R34,U34) -> #REF! | I34: =SUMIF(#REF!,$B$34,#REF!) -> #REF! | L34: =SUMIF(#REF!,$B$34,#REF!) -> #REF! | O34: =SUMIF(#REF!,$B$34,#REF!) -> #REF! | R34: =SUMIF(#REF!,$B$34,#REF!) -> #REF! | U34: =SUMIF(#REF!,$B$34,#REF!) -> #REF!
A36: Other | B36: 640102 | C36: Leased Facilities External | H36: =SUM(I36,L36,O36,R36,U36) -> #REF! | I36: =SUMIF(#REF!,$B$36,#REF!) -> #REF! | L36: =SUMIF(#REF!,$B$36,#REF!) -> #REF! | O36: =SUMIF(#REF!,$B$36,#REF!) -> #REF! | R36: =SUMIF(#REF!,$B$36,#REF!) -> #REF! | U36: =SUMIF(#REF!,$B$36,#REF!) -> #REF!
B37: 641400 | C37: Telecommunications | H37: =SUM(I37,L37,O37,R37,U37) -> #REF! | I37: =SUMIF(#REF!,$B$37,#REF!) -> #REF! | L37: =SUMIF(#REF!,$B$37,#REF!) -> #REF! | O37: =SUMIF(#REF!,$B$37,#REF!) -> #REF! | R37: =SUMIF(#REF!,$B$37,#REF!) -> #REF! | U37: =SUMIF(#REF!,$B$37,#REF!) -> #REF!
B38: 642500 | C38: Other Expenses | H38: =SUM(I38,L38,O38,R38,U38) -> #REF! | I38: =SUMIF(#REF!,$B$38,#REF!) -> #REF! | L38: =SUMIF(#REF!,$B$38,#REF!) -> #REF! | O38: =SUMIF(#REF!,$B$38,#REF!) -> #REF! | R38: =SUMIF(#REF!,$B$38,#REF!) -> #REF! | U38: =SUMIF(#REF!,$B$38,#REF!) -> #REF!
B39: 643000 | C39: Other Expenses (Excluded from F&A) | H39: =SUM(I39,L39,O39,R39,U39) -> #REF! | I39: =SUMIF(#REF!,$B$39,#REF!) -> #REF! | L39: =SUMIF(#REF!,$B$39,#REF!) -> #REF! | O39: =SUMIF(#REF!,$B$39,#REF!) -> #REF! | R39: =SUMIF(#REF!,$B$39,#REF!) -> #REF! | U39: =SUMIF(#REF!,$B$39,#REF!) -> #REF!
B41: Subtotal | H41: =SUM(I41,L41,O41,R41,U41) -> #REF! | I41: =SUM(L13:L40) -> #REF! | L41: =SUM(O13:O40) -> #REF! | O41: =SUM(R13:R40) -> #REF! | R41: =SUM(U13:U40) -> #REF! | U41: =SUM(X13:X40) -> 0
B43: 690007 | C43: Service Center | H43: =SUM(I43,L43,O43,R43,U43) -> #REF! | I43: =SUMIF(#REF!,$B$43,#REF!) -> #REF! | L43: =SUMIF(#REF!,$B$43,#REF!) -> #REF! | O43: =SUMIF(#REF!,$B$43,#REF!) -> #REF! | R43: =SUMIF(#REF!,$B$43,#REF!) -> #REF! | U43: =SUMIF(#REF!,$B$43,#REF!) -> #REF!
B45: 699999 | C45: F&A | H45: =SUM(I45,L45,O45,R45,U45) -> #REF! | I45: =SUMIF(#REF!,$B$45,#REF!) -> #REF! | L45: =SUMIF(#REF!,$B$45,#REF!) -> #REF! | O45: =SUMIF(#REF!,$B$45,#REF!) -> #REF! | R45: =SUMIF(#REF!,$B$45,#REF!) -> #REF! | U45: =SUMIF(#REF!,$B$45,#REF!) -> #REF!
B47: Total per year | H47: =SUM(H41:H46) -> #REF! | I47: =SUM(I41:I46) -> #REF! | L47: =SUM(L41:L46) -> #REF! | O47: =SUM(O41:O46) -> #REF! | R47: =SUM(R41:R46) -> #REF! | U47: =SUM(U41:U46) -> #REF!
B49: Calculation check | I49: =SUM(#REF!,#REF!,#REF!) -> #REF! | L49: =SUM(#REF!,#REF!,#REF!) -> #REF! | O49: =SUM(#REF!,#REF!,#REF!) -> #REF! | R49: =SUM(#REF!,#REF!,#REF!) -> #REF! | U49: =SUM(#REF!,#REF!,#REF!) -> #REF!

Sheet Incountry Costs by GL USD
D1: Jhpiego Corporation
D2: =Assumptions!B9 -> DONOR: | E2: =Assumptions!C9 -> USDOL
D3: =Assumptions!B10 -> Country: | E3: =Assumptions!C10 -> Ecuador
D4: =Assumptions!B11 -> Program Name: | E4: =Assumptions!C11 -> Project to Improve Adherence to International Labor Standards in the Agricultural Sector in Ecuador
D5: =Assumptions!B12 -> Grant Number: | E5: =Assumptions!C12 -> FOA-ILAB-23-28
D6: =Assumptions!B13 -> Period of Performance: | E6: =Assumptions!C13 -> 48 months | H6: =Assumptions!G13 -> 0
D8: BUDGET SUMMARY BY G/L in USD
D10: IN-COUNTRY COSTS by Jhpiego FISCAL YEAR
E11: IN-COUNTRY ION: | I11: 21 - 987654321 | L11: 22 - 987654322 | O11: 23 - 987654323 | R11: 24 - 987654324 | U11: 25 - 987654325
A13: SF424a | B13: Sponsored Class | C13: Description | D13: G/L | E13: Description | H13: Workplan Year Budget | I13: =#REF! -> #REF! | L13: =#REF! -> #REF! | O13: =#REF! -> #REF! | R13: =#REF! -> #REF! | U13: =#REF! -> #REF!
A15: Personnel | B15: 610000 | C15: Salaries & Wages | D15: 616112 | E15: In-country Salaries | H15: =SUM(I15,L15,O15,R15,U15) -> #REF! | I15: =SUMIF(#REF!,$D$15,#REF!) -> #REF! | L15: =SUMIF(#REF!,$D$15,#REF!) -> #REF! | O15: =SUMIF(#REF!,$D$15,#REF!) -> #REF! | R15: =SUMIF(#REF!,$D$15,#REF!) -> #REF! | U15: =SUMIF(#REF!,$D$15,#REF!) -> #REF!
A16: Fringe Benefits | B16: 620000 | C16: Fringe Benefits | D16: 620112 | E16: In-country Fringe | H16: =SUM(I16,L16,O16,R16,U16) -> #REF! | I16: =SUMIF(#REF!,$D$16,#REF!) -> #REF! | L16: =SUMIF(#REF!,$D$16,#REF!) -> #REF! | O16: =SUMIF(#REF!,$D$16,#REF!) -> #REF! | R16: =SUMIF(#REF!,$D$16,#REF!) -> #REF! | U16: =SUMIF(#REF!,$D$16,#REF!) -> #REF!
A17: Travel | B17: 652000 | C17: Travel Domestic | D17: 652201 | E17: Trainee Travel | H17: =SUM(I17,L17,O17,R17,U17) -> #REF! | I17: =SUMIF(#REF!,$D$17,#REF!) -> #REF! | L17: =SUMIF(#REF!,$D$17,#REF!) -> #REF! | O17: =SUMIF(#REF!,$D$17,#REF!) -> #REF! | R17: =SUMIF(#REF!,$D$17,#REF!) -> #REF! | U17: =SUMIF(#REF!,$D$17,#REF!) -> #REF!
B18: 652100 | C18: Travel Foreign | D18: 652101 | E18: Travel Foreign | H18: =SUM(I18,L18,O18,R18,U18) -> #REF! | I18: =SUMIF(#REF!,$D$18,#REF!) -> #REF! | L18: =SUMIF(#REF!,$D$18,#REF!) -> #REF! | O18: =SUMIF(#REF!,$D$18,#REF!) -> #REF! | R18: =SUMIF(#REF!,$D$18,#REF!) -> #REF! | U18: =SUMIF(#REF!,$D$18,#REF!) -> #REF!
D19: 652102 | E19: Travel Overseas Local | H19: =SUM(I19,L19,O19,R19,U19) -> #REF! | I19: =SUMIF(#REF!,$D$19,#REF!) -> #REF! | L19: =SUMIF(#REF!,$D$19,#REF!) -> #REF! | O19: =SUMIF(#REF!,$D$19,#REF!) -> #REF! | R19: =SUMIF(#REF!,$D$19,#REF!) -> #REF! | U19: =SUMIF(#REF!,$D$19,#REF!) -> #REF!
A20: Supplies | B20: 630000 | C20: Supplies & Materials | D20: 631001 | E20: Furniture | H20: =SUM(I20,L20,O20,R20,U20) -> #REF! | I20: =SUMIF(#REF!,$D$20,#REF!) -> #REF! | L20: =SUMIF(#REF!,$D$20,#REF!) -> #REF! | O20: =SUMIF(#REF!,$D$20,#REF!) -> #REF! | R20: =SUMIF(#REF!,$D$20,#REF!) -> #REF! | U20: =SUMIF(#REF!,$D$20,#REF!) -> #REF!
B21: 630000 | C21: Supplies & Materials | D21: 631003 | E21: Non-capital PC purchases | H21: =SUM(I21,L21,O21,R21,U21) -> #REF! | I21: =SUMIF(#REF!,$D$21,#REF!) -> #REF! | L21: =SUMIF(#REF!,$D$21,#REF!) -> #REF! | O21: =SUMIF(#REF!,$D$21,#REF!) -> #REF! | R21: =SUMIF(#REF!,$D$21,#REF!) -> #REF! | U21: =SUMIF(#REF!,$D$21,#REF!) -> #REF!
