Workbook
Name __pd1: [1]Rates!$J$24
Name __pd6: [1]Rates!$J$30
Name __tix1: [1]Rates!$J$40
Name __tix2: [1]Rates!$J$41
Name __tix6: [1]Rates!$J$47
Name ANPDH: '[2]Salary & PR Tax'!#REF!
Name Board: '[3]Schedule E - Other'!$F$102
Name CEE_Consult: #REF!
Name CENIDH: #REF!
Name Consultants: #REF!
Name Equipment: '[4]Schedule D - Equipment'!$E$26
Name fg: #REF!
Name Housing: '[2]Salary & PR Tax'!#REF!
Name inf: [5]Assumptions!$C$75
Name Inflation: '[6]Detail-1'!$J$2
Name Interns: #REF!
Name jenn: #REF!
Name Local_Hire: #REF!
Name Local_Hires: #REF!
Name Merit: '[6]Detail-1'!$J$1
Name padf01: '[7]Level of Effort'!$C$14
Name padf02: '[7]Level of Effort'!$C$15
Name padf03: '[7]Level of Effort'!$C$16
Name padf04: '[7]Level of Effort'!$C$17
Name padf05: [7]Rates!$J$23
Name postdif01: [7]Rates!$J$34
Name postdif02: [7]Rates!$J$65
Name Print_Titles_MI: #REF!
Name sdf: #REF!
Name Travel_Regional: #REF!
Name Travel_WDC: #REF!

Sheet Budget Summary
A1: Partners of the Americas for Venezuela's Farmer-to-Farmer Program Budget
A2: USAID NFO #7200AA19B00002
A4: Line Items | B4: Year 1 | E4: Year 2 | H4: Year 3 | K4: Year 4 | N4: Year 5 | Q4: Total | R4: Total | S4: Grand
B5: USAID | C5: Leverage | D5: Total | E5: USAID | F5: Leverage | G5: Total | H5: USAID | I5: Leverage | J5: Total | K5: USAID | L5: Leverage | M5: Total | N5: USAID | O5: Leverage | P5: Total | Q5: USAID | R5: Leverage | S5: Total
A7: Salaries & Wages | B7: =Budget!I32 -> 622538 | C7: =Budget!J32 -> 343260 | D7: =SUM(B7:C7) -> 965798 | E7: =Budget!O32 -> 884068.02 | F7: =Budget!P32 -> 1162192.5 | G7: =SUM(E7:F7) -> 2046260.5 | H7: =Budget!U32 -> 703799.11 | I7: =Budget!V32 -> 834592.5 | J7: =SUM(H7:I7) -> 1538391.6 | K7: =Budget!AA32 -> 667412.68 | L7: =Budget!AB32 -> 506992.5 | M7: =SUM(K7:L7) -> 1174405.2 | N7: =Budget!AG32 -> 547922.72 | O7: =Budget!AH32 -> 166387.5 | P7: =SUM(N7:O7) -> 714310.22 | Q7: =Budget!AJ32 -> 3425740.5 | R7: =Budget!AK32 -> 3013425 | S7: =Budget!AL32 -> 6439165.5
A9: Fringe Benefits | B9: =Budget!I43 -> 252030.92 | C9: =Budget!J43 -> 0 | D9: =Budget!K43 -> 252030.92 | E9: =Budget!O43 -> 360022.86 | F9: =Budget!P43 -> 0 | G9: =Budget!Q43 -> 360022.86 | H9: =Budget!U43 -> 214720.86 | I9: =Budget!V43 -> 0 | J9: =Budget!W43 -> 214720.86 | K9: =Budget!AA43 -> 182513.76 | L9: =Budget!AB43 -> 0 | M9: =Budget!AC43 -> 182513.76 | N9: =Budget!AG43 -> 146046.92 | O9: =Budget!AH43 -> 0 | P9: =Budget!AI43 -> 146046.92 | Q9: =Budget!AJ43 -> 1155335.3 | R9: =Budget!AK43 -> 0 | S9: =Budget!AL43 -> 1155335.3
A11: Travel & Transportation | B11: =Budget!I97 -> 63646 | C11: =Budget!J97 -> 0 | D11: =Budget!K97 -> 63646 | E11: =Budget!O97 -> 275195.72 | F11: =Budget!P97 -> 0 | G11: =Budget!Q97 -> 275195.72 | H11: =Budget!U97 -> 232008.91 | I11: =Budget!V97 -> 0 | J11: =Budget!W97 -> 232008.91 | K11: =Budget!AA97 -> 236649.09 | L11: =Budget!AB97 -> 0 | M11: =Budget!AC97 -> 236649.09 | N11: =Budget!AG97 -> 93020.951 | O11: =Budget!AH97 -> 0 | P11: =Budget!AI97 -> 93020.951 | Q11: =Budget!AJ97 -> 900520.68 | R11: =Budget!AK97 -> 0 | S11: =Budget!AL97 -> 900520.68
A13: Equipment | B13: =Budget!I104 -> 165700 | C13: =Budget!J104 -> 0 | D13: =Budget!K104 -> 165700 | E13: =Budget!O104 -> 0 | F13: =Budget!P104 -> 0 | G13: =Budget!Q104 -> 0 | H13: =Budget!U104 -> 0 | I13: =Budget!V104 -> 0 | J13: =Budget!W104 -> 0 | K13: =Budget!AA104 -> 0 | L13: =Budget!AB104 -> 0 | M13: =Budget!AC104 -> 0 | N13: =Budget!AG104 -> 0 | O13: =Budget!AH104 -> 0 | P13: =Budget!AI104 -> 0 | Q13: =Budget!AJ104 -> 165700 | R13: =Budget!AK104 -> 0 | S13: =Budget!AL104 -> 165700
A15: Supplies | B15: =Budget!I131 -> 108796.19 | C15: =Budget!J131 -> 0 | D15: =Budget!K131 -> 108796.19 | E15: =Budget!O131 -> 131200 | F15: =Budget!P131 -> 0 | G15: =Budget!Q131 -> 131200 | H15: =Budget!U131 -> 71200 | I15: =Budget!V131 -> 0 | J15: =Budget!W131 -> 71200 | K15: =Budget!AA131 -> 11200 | L15: =Budget!AB131 -> 0 | M15: =Budget!AC131 -> 11200 | N15: =Budget!AG131 -> 8025 | O15: =Budget!AH131 -> 0 | P15: =Budget!AI131 -> 8025 | Q15: =Budget!AJ131 -> 330421.19 | R15: =Budget!AK131 -> 0 | S15: =Budget!AL131 -> 330421.19
A17: Contractual | B17: =Budget!I166 -> 2100186 | C17: =Budget!J166 -> 0 | D17: =Budget!K166 -> 2100186 | E17: =Budget!O166 -> 1963800 | F17: =Budget!P166 -> 0 | G17: =Budget!Q166 -> 1963800 | H17: =Budget!U166 -> 1519200 | I17: =Budget!V166 -> 0 | J17: =Budget!W166 -> 1519200 | K17: =Budget!AA166 -> 944200 | L17: =Budget!AB166 -> 0 | M17: =Budget!AC166 -> 944200 | N17: =Budget!AG166 -> 848000 | O17: =Budget!AH166 -> 0 | P17: =Budget!AI166 -> 848000 | Q17: =Budget!AJ166 -> 7375386 | R17: =Budget!AK166 -> 0 | S17: =Budget!AL166 -> 7375386
A19: Other Direct Costs | B19: =Budget!I200 -> 78710 | C19: =Budget!J200 -> 0 | D19: =Budget!K200 -> 78710 | E19: =Budget!O200 -> 146308.8 | F19: =Budget!P200 -> 0 | G19: =Budget!Q200 -> 146308.8 | H19: =Budget!U200 -> 149234.98 | I19: =Budget!V200 -> 0 | J19: =Budget!W200 -> 149234.98 | K19: =Budget!AA200 -> 152219.68 | L19: =Budget!AB200 -> 0 | M19: =Budget!AC200 -> 152219.68 | N19: =Budget!AG200 -> 107523.4 | O19: =Budget!AH200 -> 0 | P19: =Budget!AI200 -> 107523.4 | Q19: =Budget!AJ200 -> 633996.85 | R19: =Budget!AK200 -> 0 | S19: =Budget!AL200 -> 633996.85
A21: Total Direct Costs | B21: =Budget!I202 -> 3391607.1 | C21: =Budget!J202 -> 343260 | D21: =Budget!K202 -> 3734867.1 | E21: =Budget!O202 -> 3760595.4 | F21: =Budget!P202 -> 1162192.5 | G21: =Budget!Q202 -> 4922787.9 | H21: =Budget!U202 -> 2890163.9 | I21: =Budget!V202 -> 834592.5 | J21: =Budget!W202 -> 3724756.4 | K21: =Budget!AA202 -> 2194195.2 | L21: =Budget!AB202 -> 506992.5 | M21: =Budget!AC202 -> 2701187.7 | N21: =Budget!AG202 -> 1750539 | O21: =Budget!AH202 -> 166387.5 | P21: =Budget!AI202 -> 1916926.5 | Q21: =Budget!AJ202 -> 13987101 | R21: =Budget!AK202 -> 3013425 | S21: =Budget!AL202 -> 17000526
A22: Indirect Costs | B22: =Budget!I203 -> 973052.08 | C22: =Budget!J203 -> 0 | D22: =Budget!K203 -> 973052.08 | E22: =Budget!O203 -> 1078914.8 | F22: =Budget!P203 -> 0 | G22: =Budget!Q203 -> 1078914.8 | H22: =Budget!U203 -> 829188.01 | I22: =Budget!V203 -> 0 | J22: =Budget!W203 -> 829188.01 | K22: =Budget!AA203 -> 629514.6 | L22: =Budget!AB203 -> 0 | M22: =Budget!AC203 -> 629514.6 | N22: =Budget!AG203 -> 502229.64 | O22: =Budget!AH203 -> 0 | P22: =Budget!AI203 -> 502229.64 | Q22: =Budget!AJ203 -> 4012899.2 | R22: =Budget!AK203 -> 0 | S22: =Budget!AL203 -> 4012899.2
A23: Total | B23: =Budget!I204 -> 4364659.2 | C23: =Budget!J204 -> 343260 | D23: =Budget!K204 -> 4707919.2 | E23: =Budget!O204 -> 4839510.2 | F23: =Budget!P204 -> 1162192.5 | G23: =Budget!Q204 -> 6001702.7 | H23: =Budget!U204 -> 3719351.9 | I23: =Budget!V204 -> 834592.5 | J23: =Budget!W204 -> 4553944.4 | K23: =Budget!AA204 -> 2823709.8 | L23: =Budget!AB204 -> 506992.5 | M23: =Budget!AC204 -> 3330702.3 | N23: =Budget!AG204 -> 2252768.6 | O23: =Budget!AH204 -> 166387.5 | P23: =Budget!AI204 -> 2419156.1 | Q23: =Budget!AJ204 -> 18000000 | R23: =Budget!AK204 -> 3013425 | S23: =Budget!AL204 -> 21013425

Sheet Budget
A1: Entity: | B1: P | D1: Partners of the Americas 7200AA19B00002 for Venezuela's Farmer-to-Farmer Program Budget
A2: Program/Dept.: | B2: FTF
A3: Funder-Grant: | B3: USAID671
A5: Actvity | B5: Object | C5: Country | D5: Line Items | I5: Year 1 | O5: Year 2 | R5: Year 3 | AA5: Year 4 | AG5: Year 5 | AJ5: Total | AK5: Total | AL5: Grand
A6: Code | B6: Code | C6: Code | E6: Unit | F6: Cost | G6: Duration | H6: Type | I6: USAID | J6: Leverage | K6: Total | L6: Unit | M6: Cost | N6: Duration | O6: USAID | P6: Leverage | Q6: Total | R6: Unit | S6: Cost | T6: Duration | U6: USAID | V6: Leverage | W6: Total | X6: Unit | Y6: Cost | Z6: Duration | AA6: USAID | AB6: Leverage | AC6: Total | AD6: Unit | AE6: Cost | AF6: Duration | AG6: USAID | AH6: Leverage | AI6: Total | AJ6: USAID | AK6: Leverage | AL6: Total
C7: 0 is DC, VZ is Venezuela
D8: Salary & Wages
D9: Headquarters | E9: LOE
A10: PERSNL | B10: Timesheets | C10: 0 | D10: Program Director | E10: 0.3 | F10: 9730 | G10: 12 | H10: /months | I10: =G10*F10*E10 -> 35028 | J10: 0 | K10: =SUM(I10:J10) -> 35028 | L10: =E10 -> 0.3 | M10: =F10*1.035 -> 10070.55 | N10: 12 | O10: =L10*M10*N10 -> 36253.98 | P10: 0 | Q10: =SUM(O10:P10) -> 36253.98 | R10: =E10 -> 0.3 | S10: =M10*1.035 -> 10423.019 | T10: 12 | U10: =R10*S10*T10 -> 37522.869 | V10: 0 | W10: =SUM(U10:V10) -> 37522.869 | X10: =R10 -> 0.3 | Y10: =S10*1.035 -> 10787.825 | Z10: 12 | AA10: =X10*Y10*Z10 -> 38836.17 | AB10: 0 | AC10: =SUM(AA10:AB10) -> 38836.17 | AD10: =X10 -> 0.3 | AE10: =Y10*1.035 -> 11165.399 | AF10: 12 | AG10: =AD10*AE10*AF10 -> 40195.436 | AH10: 0 | AI10: =SUM(AG10:AH10) -> 40195.436 | AJ10: =I10+O10+U10+AA10+AG10 -> 187836.45 | AK10: =J10+P10+V10+AB10+AH10 -> 0 | AL10: =SUM(AJ10:AK10) -> 187836.45
A11: PERSNL | B11: Timesheets | C11: 0 | D11: Associate Director | E11: 1 | F11: 7500 | G11: 12 | H11: /months | I11: =G11*F11*E11 -> 90000 | J11: 0 | K11: =SUM(I11:J11) -> 90000 | L11: =E11 -> 1 | M11: =F11*1.035 -> 7762.5 | N11: 12 | O11: =L11*M11*N11 -> 93150 | P11: 0 | Q11: =SUM(O11:P11) -> 93150 | R11: =L11 -> 1 | S11: =M11*1.035 -> 8034.1875 | T11: 12 | U11: =R11*S11*T11 -> 96410.25 | V11: 0 | W11: =SUM(U11:V11) -> 96410.25 | X11: =R11 -> 1 | Y11: =S11*1.035 -> 8315.3841 | Z11: 12 | AA11: =X11*Y11*Z11 -> 99784.609 | AB11: 0 | AC11: =SUM(AA11:AB11) -> 99784.609 | AD11: =X11 -> 1 | AE11: =Y11*1.035 -> 8606.4225 | AF11: 12 | AG11: =AD11*AE11*AF11 -> 103277.07 | AH11: 0 | AI11: =SUM(AG11:AH11) -> 103277.07 | AJ11: =I11+O11+U11+AA11+AG11 -> 482621.93 | AK11: =J11+P11+V11+AB11+AH11 -> 0 | AL11: =SUM(AJ11:AK11) -> 482621.93
A12: PERSNL | B12: Timesheets | C12: 0 | D12: Senior Program Officer | E12: 1 | F12: 5834 | G12: 12 | H12: /months | I12: =G12*F12*E12 -> 70008 | J12: 0 | K12: =SUM(I12:J12) -> 70008 | L12: =E12 -> 1 | M12: =F12*1.035 -> 6038.19 | N12: 12 | O12: =L12*M12*N12 -> 72458.28 | P12: 0 | Q12: =SUM(O12:P12) -> 72458.28 | R12: =L12 -> 1 | S12: =M12*1.035 -> 6249.5266 | T12: 12 | U12: =R12*S12*T12 -> 74994.32 | V12: 0 | W12: =SUM(U12:V12) -> 74994.32 | X12: =R12 -> 1 | Y12: =S12*1.035 -> 6468.2601 | Z12: 12 | AA12: =X12*Y12*Z12 -> 77619.121 | AB12: 0 | AC12: =SUM(AA12:AB12) -> 77619.121 | AD12: =X12 -> 1 | AE12: =Y12*1.035 -> 6694.6492 | AF12: 12 | AG12: =AD12*AE12*AF12 -> 80335.79 | AH12: 0 | AI12: =SUM(AG12:AH12) -> 80335.79 | AJ12: =I12+O12+U12+AA12+AG12 -> 375415.51 | AK12: =J12+P12+V12+AB12+AH12 -> 0 | AL12: =SUM(AJ12:AK12) -> 375415.51
D13: Subtotal HQ Salaries | I13: =SUM(I10:I12) -> 195036 | J13: =SUM(J10:J12) -> 0 | K13: =SUM(K10:K12) -> 195036 | O13: =SUM(O10:O12) -> 201862.26 | P13: =SUM(P10:P12) -> 0 | Q13: =SUM(Q10:Q12) -> 201862.26 | U13: =SUM(U10:U12) -> 208927.44 | V13: =SUM(V10:V12) -> 0 | W13: =SUM(W10:W12) -> 208927.44 | AA13: =SUM(AA10:AA12) -> 216239.9 | AB13: =SUM(AB10:AB12) -> 0 | AC13: =SUM(AC10:AC12) -> 216239.9 | AG13: =SUM(AG10:AG12) -> 223808.3 | AH13: =SUM(AH10:AH12) -> 0 | AI13: =SUM(AI10:AI12) -> 223808.3 | AJ13: =SUM(AJ10:AJ12) -> 1045873.9 | AK13: =SUM(AK10:AK12) -> 0 | AL13: =SUM(AL10:AL12) -> 1045873.9
D14: *Key Personnel
D15: Field Salaries | E15: LOE
A16: PERSNL | B16: 7410 Personnel/ 7610 Consultant | C16: VZ | D16: Country Director - Expatriate* | E16: 1 | F16: 14516 | G16: 10 | H16: /months | I16: =E16*F16*G16 -> 145160 | J16: 0 | K16: =SUM(I16:J16) -> 145160 | L16: 1 | M16: =F16*1.035 -> 15024.06 | N16: 12 | O16: =M16*N16*L16 -> 180288.72 | P16: 0 | Q16: =SUM(O16:P16) -> 180288.72 | R16: 1 | S16: =M16*1.035 -> 15549.902 | T16: 2 | U16: =T16*S16*R16 -> 31099.804 | V16: 0 | W16: =SUM(U16:V16) -> 31099.804 | X16: 1 | Y16: =S16*1.035 -> 16094.149 | Z16: 0 | AA16: =Z16*Y16*X16 -> 0 | AB16: 0 | AC16: =SUM(AA16:AB16) -> 0 | AD16: 1 | AE16: =Y16*1.035 -> 16657.444 | AF16: 0 | AG16: =AF16*AE16*AD16 -> 0 | AH16: 0 | AI16: =SUM(AG16:AH16) -> 0 | AJ16: =I16+O16+U16+AA16+AG16 -> 356548.52 | AK16: =J16+P16+V16+AB16+AH16 -> 0 | AL16: =SUM(AJ16:AK16) -> 356548.52
A17: PERSNL | B17: 7410 Personnel/ 7610 Consultant | C17: VZ | D17: Deputy Country Director* | E17: 1 | F17: 6717 | G17: 10 | H17: /months | I17: =E17*F17*G17 -> 67170 | J17: 0 | K17: =SUM(I17:J17) -> 67170 | L17: 1 | M17: =F17*1.035 -> 6952.095 | N17: 12 | O17: =M17*N17*L17 -> 83425.14 | P17: 0 | Q17: =SUM(O17:P17) -> 83425.14 | R17: 1 | S17: =M17*1.035 -> 7195.4183 | T17: 12 | U17: =T17*S17*R17 -> 86345.02 | V17: 0 | W17: =SUM(U17:V17) -> 86345.02 | X17: 1 | Y17: =S17*1.035 -> 7447.258 | Z17: 12 | AA17: =Z17*Y17*X17 -> 89367.096 | AB17: 0 | AC17: =SUM(AA17:AB17) -> 89367.096 | AD17: 1 | AE17: =Y17*1.035 -> 7707.912 | AF17: 12 | AG17: =AF17*AE17*AD17 -> 92494.944 | AH17: 0 | AI17: =SUM(AG17:AH17) -> 92494.944 | AJ17: =I17+O17+U17+AA17+AG17 -> 418802.2 | AK17: =J17+P17+V17+AB17+AH17 -> 0 | AL17: =SUM(AJ17:AK17) -> 418802.2
A18: PERSNL | B18: 7410 Personnel/ 7610 Consultant | C18: VZ | D18: Finance Director | E18: 1 | F18: 4334 | G18: 9 | H18: /months | I18: =E18*F18*G18 -> 39006 | J18: 0 | K18: =SUM(I18:J18) -> 39006 | L18: 1 | M18: =F18*1.035 -> 4485.69 | N18: 12 | O18: =M18*N18*L18 -> 53828.28 | P18: 0 | Q18: =SUM(O18:P18) -> 53828.28 | R18: 1 | S18: =M18*1.035 -> 4642.6891 | T18: 12 | U18: =T18*S18*R18 -> 55712.27 | V18: 0 | W18: =SUM(U18:V18) -> 55712.27 | X18: 1 | Y18: =S18*1.035 -> 4805.1833 | Z18: 12 | AA18: =Z18*Y18*X18 -> 57662.199 | AB18: 0 | AC18: =SUM(AA18:AB18) -> 57662.199 | AD18: 1 | AE18: =Y18*1.035 -> 4973.3647 | AF18: 12 | AG18: =AF18*AE18*AD18 -> 59680.376 | AH18: 0 | AI18: =SUM(AG18:AH18) -> 59680.376 | AJ18: =I18+O18+U18+AA18+AG18 -> 265889.13 | AK18: =J18+P18+V18+AB18+AH18 -> 0 | AL18: =SUM(AJ18:AK18) -> 265889.13
A19: PERSNL | B19: 7410 Personnel/ 7610 Consultant | C19: VZ | D19: Safety & Security Director | E19: 1 | F19: 4334 | G19: 6 | H19: /months | I19: =E19*F19*G19 -> 26004 | J19: 0 | K19: =SUM(I19:J19) -> 26004 | L19: 1 | M19: =F19*1.035 -> 4485.69 | N19: 12 | O19: =M19*N19*L19 -> 53828.28 | P19: 0 | Q19: =SUM(O19:P19) -> 53828.28 | R19: 1 | S19: =M19*1.035 -> 4642.6891 | T19: 12 | U19: =T19*S19*R19 -> 55712.27 | V19: 0 | W19: =SUM(U19:V19) -> 55712.27 | X19: 1 | Y19: =S19*1.035 -> 4805.1833 | Z19: 12 | AA19: =Z19*Y19*X19 -> 57662.199 | AB19: 0 | AC19: =SUM(AA19:AB19) -> 57662.199 | AD19: 1 | AE19: =Y19*1.035 -> 4973.3647 | AF19: 7 | AG19: =AF19*AE19*AD19 -> 34813.553 | AH19: 0 | AI19: =SUM(AG19:AH19) -> 34813.553 | AJ19: =I19+O19+U19+AA19+AG19 -> 228020.3 | AK19: =J19+P19+V19+AB19+AH19 -> 0 | AL19: =SUM(AJ19:AK19) -> 228020.3
A20: PERSNL | B20: 7410 Personnel/ 7610 Consultant | C20: VZ | D20: Compliance Specialist | E20: 1 | F20: 2492 | G20: 6 | H20: /months | I20: =E20*F20*G20 -> 14952 | J20: 0 | K20: =SUM(I20:J20) -> 14952 | L20: 1 | M20: =F20*1.035 -> 2579.22 | N20: 12 | O20: =M20*N20*L20 -> 30950.64 | P20: 0 | Q20: =SUM(O20:P20) -> 30950.64 | R20: 1 | S20: =M20*1.035 -> 2669.4927 | T20: 12 | U20: =T20*S20*R20 -> 32033.912 | V20: 0 | W20: =SUM(U20:V20) -> 32033.912 | X20: 1 | Y20: =S20*1.035 -> 2762.9249 | Z20: 12 | AA20: =Z20*Y20*X20 -> 33155.099 | AB20: 0 | AC20: =SUM(AA20:AB20) -> 33155.099 | AD20: 1 | AE20: =Y20*1.035 -> 2859.6273 | AF20: 7 | AG20: =AF20*AE20*AD20 -> 20017.391 | AH20: 0 | AI20: =SUM(AG20:AH20) -> 20017.391 | AJ20: =I20+O20+U20+AA20+AG20 -> 131109.04 | AK20: =J20+P20+V20+AB20+AH20 -> 0 | AL20: =SUM(AJ20:AK20) -> 131109.04
A21: PERSNL | B21: 7410 Personnel/ 7610 Consultant | C21: VZ | D21: Accountant | E21: 1 | F21: 2492 | G21: 6 | H21: /months | I21: =E21*F21*G21 -> 14952 | J21: 0 | K21: =SUM(I21:J21) -> 14952 | L21: 1 | M21: =F21*1.035 -> 2579.22 | N21: 12 | O21: =M21*N21*L21 -> 30950.64 | P21: 0 | Q21: =SUM(O21:P21) -> 30950.64 | R21: 1 | S21: =M21*1.035 -> 2669.4927 | T21: 12 | U21: =T21*S21*R21 -> 32033.912 | V21: 0 | W21: =SUM(U21:V21) -> 32033.912 | X21: 1 | Y21: =S21*1.035 -> 2762.9249 | Z21: 12 | AA21: =Z21*Y21*X21 -> 33155.099 | AB21: 0 | AC21: =SUM(AA21:AB21) -> 33155.099 | AD21: 1 | AE21: =Y21*1.035 -> 2859.6273 | AF21: 7 | AG21: =AF21*AE21*AD21 -> 20017.391 | AH21: 0 | AI21: =SUM(AG21:AH21) -> 20017.391 | AJ21: =I21+O21+U21+AA21+AG21 -> 131109.04 | AK21: =J21+P21+V21+AB21+AH21 -> 0 | AL21: =SUM(AJ21:AK21) -> 131109.04
A22: PERSNL | B22: 7410 Personnel/ 7610 Consultant | C22: VZ | D22: Administrative Assistant | E22: 1 | F22: 2167 | G22: 6 | H22: /months | I22: =E22*F22*G22 -> 13002 | J22: 0 | K22: =SUM(I22:J22) -> 13002 | L22: 1 | M22: =F22*1.035 -> 2242.845 | N22: 12 | O22: =M22*N22*L22 -> 26914.14 | P22: 0 | Q22: =SUM(O22:P22) -> 26914.14 | R22: 1 | S22: =M22*1.035 -> 2321.3446 | T22: 12 | U22: =T22*S22*R22 -> 27856.135 | V22: 0 | W22: =SUM(U22:V22) -> 27856.135 | X22: 1 | Y22: =S22*1.035 -> 2402.5916 | Z22: 12 | AA22: =Z22*Y22*X22 -> 28831.1 | AB22: 0 | AC22: =SUM(AA22:AB22) -> 28831.1 | AD22: 1 | AE22: =Y22*1.035 -> 2486.6823 | AF22: 7 | AG22: =AF22*AE22*AD22 -> 17406.776 | AH22: 0 | AI22: =SUM(AG22:AH22) -> 17406.776 | AJ22: =I22+O22+U22+AA22+AG22 -> 114010.15 | AK22: =J22+P22+V22+AB22+AH22 -> 0 | AL22: =SUM(AJ22:AK22) -> 114010.15
A23: PERSNL | B23: 7410 Personnel/ 7610 Consultant | C23: VZ | D23: M&E Specialist | E23: 1 | F23: 2492 | G23: 6 | H23: /months | I23: =E23*F23*G23 -> 14952 | J23: 0 | K23: =SUM(I23:J23) -> 14952 | L23: 1 | M23: =F23*1.035 -> 2579.22 | N23: 12 | O23: =M23*N23*L23 -> 30950.64 | P23: 0 | Q23: =SUM(O23:P23) -> 30950.64 | R23: 1 | S23: =M23*1.035 -> 2669.4927 | T23: 12 | U23: =T23*S23*R23 -> 32033.912 | V23: 0 | W23: =SUM(U23:V23) -> 32033.912 | X23: 1 | Y23: =S23*1.035 -> 2762.9249 | Z23: 12 | AA23: =Z23*Y23*X23 -> 33155.099 | AB23: 0 | AC23: =SUM(AA23:AB23) -> 33155.099 | AD23: 1 | AE23: =Y23*1.035 -> 2859.6273 | AF23: 9 | AG23: =AF23*AE23*AD23 -> 25736.646 | AH23: 0 | AI23: =SUM(AG23:AH23) -> 25736.646 | AJ23: =I23+O23+U23+AA23+AG23 -> 136828.3 | AK23: =J23+P23+V23+AB23+AH23 -> 0 | AL23: =SUM(AJ23:AK23) -> 136828.3
A24: PERSNL | B24: 7410 Personnel/ 7610 Consultant | C24: VZ | D24: Community Development Coordinators (CDC) (4 CDCs in Year 1 & 2, 2 CDCs in Year 3-4) | E24: 1 | F24: 2167 | G24: 6 | H24: /months | I24: =E24*F24*G24*4 -> 52008 | J24: 0 | K24: =SUM(I24:J24) -> 52008 | L24: 1 | M24: =F24*1.035 -> 2242.845 | N24: 12 | O24: =M24*N24*L24*4 -> 107656.56 | P24: 0 | Q24: =SUM(O24:P24) -> 107656.56 | R24: 1 | S24: =M24*1.035 -> 2321.3446 | T24: 12 | U24: =T24*S24*R24*2 -> 55712.27 | V24: 0 | W24: =SUM(U24:V24) -> 55712.27 | X24: 1 | Y24: =S24*1.035 -> 2402.5916 | Z24: 6 | AA24: =Z24*Y24*X24*2 -> 28831.1 | AB24: 0 | AC24: =SUM(AA24:AB24) -> 28831.1 | AD24: 1 | AE24: =Y24*1.035 -> 2486.6823 | AF24: 0 | AG24: =AF24*AE24*AD24 -> 0 | AH24: 0 | AI24: =SUM(AG24:AH24) -> 0 | AJ24: =I24+O24+U24+AA24+AG24 -> 244207.93 | AK24: 0 | AL24: =SUM(AJ24:AK24) -> 244207.93
A25: PERSNL | B25: 7410 Personnel/ 7610 Consultant | C25: VZ | D25: Nutrition and Food Safety Specialist | E25: 1 | F25: 3358 | G25: 6 | H25: /months | I25: =E25*F25*G25 -> 20148 | J25: 0 | K25: =SUM(I25:J25) -> 20148 | L25: 1 | M25: =F25*1.035 -> 3475.53 | N25: 12 | O25: =M25*N25*L25 -> 41706.36 | P25: 0 | Q25: =SUM(O25:P25) -> 41706.36 | R25: 1 | S25: =M25*1.035 -> 3597.1735 | T25: 12 | U25: =T25*S25*R25 -> 43166.083 | V25: 0 | W25: =SUM(U25:V25) -> 43166.083 | X25: 1 | Y25: =S25*1.035 -> 3723.0746 | Z25: 12 | AA25: =Z25*Y25*X25 -> 44676.895 | AB25: 0 | AC25: =SUM(AA25:AB25) -> 44676.895 | AD25: 1 | AE25: =Y25*1.035 -> 3853.3822 | AF25: 7 | AG25: =AF25*AE25*AD25 -> 26973.676 | AH25: 0 | AI25: =SUM(AG25:AH25) -> 26973.676 | AJ25: =I25+O25+U25+AA25+AG25 -> 176671.01 | AK25: =J25+P25+V25+AB25+AH25 -> 0 | AL25: =SUM(AJ25:AK25) -> 176671.01
A26: PERSNL | B26: 7410 Personnel/ 7610 Consultant | C26: VZ | D26: Agricultural & Private Sector Specialist* | E26: 1 | F26: 3358 | G26: 6 | H26: /months | I26: =E26*F26*G26 -> 20148 | J26: 0 | K26: =SUM(I26:J26) -> 20148 | L26: 1 | M26: =F26*1.035 -> 3475.53 | N26: 12 | O26: =M26*N26*L26 -> 41706.36 | P26: 0 | Q26: =SUM(O26:P26) -> 41706.36 | R26: 1 | S26: =M26*1.035 -> 3597.1735 | T26: 12 | U26: =T26*S26*R26 -> 43166.083 | V26: 0 | W26: =SUM(U26:V26) -> 43166.083 | X26: 1 | Y26: =S26*1.035 -> 3723.0746 | Z26: 12 | AA26: =Z26*Y26*X26 -> 44676.895 | AB26: 0 | AC26: =SUM(AA26:AB26) -> 44676.895 | AD26: 1 | AE26: =Y26*1.035 -> 3853.3822 | AF26: 7 | AG26: =AF26*AE26*AD26 -> 26973.676 | AH26: 0 | AI26: =SUM(AG26:AH26) -> 26973.676 | AJ26: =I26+O26+U26+AA26+AG26 -> 176671.01 | AK26: =J26+P26+V26+AB26+AH26 -> 0 | AL26: =SUM(AJ26:AK26) -> 176671.01
D27: Subtotal Field Salaries | I27: =SUM(I16:I26) -> 427502 | J27: =SUM(J16:J26) -> 0 | K27: =SUM(K16:K26) -> 427502 | O27: =SUM(O16:O26) -> 682205.76 | P27: =SUM(P16:P26) -> 0 | Q27: =SUM(Q16:Q26) -> 682205.76 | U27: =SUM(U16:U26) -> 494871.67 | V27: =SUM(V16:V26) -> 0 | W27: =SUM(W16:W26) -> 494871.67 | AA27: =SUM(AA16:AA26) -> 451172.78 | AB27: =SUM(AB16:AB26) -> 0 | AC27: =SUM(AC16:AC26) -> 451172.78 | AG27: =SUM(AG16:AG26) -> 324114.43 | AH27: =SUM(AH16:AH26) -> 0 | AI27: =SUM(AI16:AI26) -> 324114.43 | AJ27: =I27+O27+U27+AA27+AG27 -> 2379866.6 | AK27: =J27+P27+V27+AB27+AH27 -> 0 | AL27: =SUM(AJ27:AK27) -> 2379866.6
D29: Local MTC Volunteers | E29: ='Volunteer Numbers'!B9 -> 75 | F29: =Leverage!C3 -> 0 | H29: /day | I29: 0 | J29: =Leverage!B23*Leverage!C23*52*Budget!E29 -> 327600 | K29: =SUM(I29:J29) -> 327600 | L29: ='Volunteer Numbers'!C9 -> 150 | M29: =Leverage!C3 -> 0 | O29: 0 | P29: =Leverage!B23*Leverage!C23*52*Budget!L29 -> 655200 | Q29: =SUM(O29:P29) -> 655200 | R29: ='Volunteer Numbers'!D9 -> 75 | S29: =Leverage!C3 -> 0 | U29: 0 | V29: =Leverage!B23*Leverage!C23*52*Budget!R29 -> 327600 | W29: =SUM(U29:V29) -> 327600 | X29: 0 | Y29: =Leverage!C3 -> 0 | AA29: 0 | AB29: 0 | AC29: =SUM(AA29:AB29) -> 0 | AD29: 0 | AE29: =Leverage!C3 -> 0 | AG29: 0 | AH29: 0 | AI29: =SUM(AG29:AH29) -> 0 | AJ29: =I29+O29+U29+AA29+AG29 -> 0 | AK29: =J29+P29+V29+AB29+AH29 -> 1310400 | AL29: =SUM(AJ29:AK29) -> 1310400
D30: F2F Volunteers | E30: ='Volunteer Numbers'!B5 -> 2 | F30: =Leverage!C4 -> 522 | H30: /day | I30: 0 | J30: =Leverage!B17+Leverage!B18 -> 15660 | K30: =SUM(I30:J30) -> 15660 | L30: ='Volunteer Numbers'!C5 -> 13 | M30: =Leverage!C4 -> 522 | O30: 0 | P30: =Leverage!C17+Leverage!C18 -> 506992.5 | Q30: =SUM(O30:P30) -> 506992.5 | R30: ='Volunteer Numbers'!D5 -> 13 | S30: =Leverage!C4 -> 522 | U30: 0 | V30: =Leverage!D17+Leverage!D18 -> 506992.5 | W30: =SUM(U30:V30) -> 506992.5 | X30: ='Volunteer Numbers'!E5 -> 13 | Y30: =Leverage!C4 -> 522 | AA30: 0 | AB30: =Leverage!E17+Leverage!E18 -> 506992.5 | AC30: =SUM(AA30:AB30) -> 506992.5 | AD30: ='Volunteer Numbers'!F5 -> 4 | AE30: =Leverage!C4 -> 522 | AG30: 0 | AH30: =Leverage!F17+Leverage!F18 -> 166387.5 | AI30: =SUM(AG30:AH30) -> 166387.5 | AJ30: =I30+O30+U30+AA30+AG30 -> 0 | AK30: =J30+P30+V30+AB30+AH30 -> 1703025 | AL30: =SUM(AJ30:AK30) -> 1703025
D32: Salaries & Wages Total | I32: =I29+I27+I13+I30 -> 622538 | J32: =SUM(J29:J30) -> 343260 | K32: =K27+K13+K30+K29 -> 965798 | O32: =O29+O27+O13+O30 -> 884068.02 | P32: =SUM(P29:P30) -> 1162192.5 | Q32: =Q27+Q13+Q30+Q29 -> 2046260.5 | U32: =U29+U27+U13+U30 -> 703799.11 | V32: =SUM(V29:V30) -> 834592.5 | W32: =W27+W13+W30+W29 -> 1538391.6 | AA32: =AA29+AA27+AA13+AA30 -> 667412.68 | AB32: =SUM(AB29:AB30) -> 506992.5 | AC32: =AC27+AC13+AC30+AC29 -> 1174405.2 | AG32: =AG29+AG27+AG13+AG30 -> 547922.72 | AH32: =SUM(AH29:AH30) -> 166387.5 | AI32: =AI27+AI13+AI30+AI29 -> 714310.22 | AJ32: =AJ29+AJ27+AJ13+AJ30 -> 3425740.5 | AK32: =SUM(AK29:AK30) -> 3013425 | AL32: =AL29+AL27+AL13+AL30 -> 6439165.5
D34: Fringe Benefits
A35: FRINGE | B35: 6950 | C35: 0 | D35: Fringe Benefits - Headquarters | E35: 0.2181 | I35: =I13*E35 -> 42537.352 | J35: 0 | K35: =SUM(I35:J35) -> 42537.352 | O35: =O13*$E$35 -> 44026.159 | P35: 0 | Q35: =SUM(O35:P35) -> 44026.159 | U35: =U13*$E$35 -> 45567.074 | V35: 0 | W35: =SUM(U35:V35) -> 45567.074 | AA35: =AA13*$E$35 -> 47161.922 | AB35: 0 | AC35: =SUM(AA35:AB35) -> 47161.922 | AG35: =AG13*$E$35 -> 48812.589 | AH35: 0 | AI35: =SUM(AG35:AH35) -> 48812.589 | AJ35: =I35+O35+U35+AA35+AG35 -> 228105.1 | AK35: =J35+P35+V35+AB35+AH35 -> 0 | AL35: =SUM(AJ35:AK35) -> 228105.1
A36: FRINGE | B36: 7420 | C36: VZ | D36: Fringe Benefits - Field (Excluding Country Director) | E36: 0.3 | I36: =(SUM(I17:I26)*$E$36) -> 84702.6 | J36: 0 | K36: =SUM(I36:J36) -> 84702.6 | O36: =(SUM(O17:O26)*$E$36) -> 150575.11 | P36: 0 | Q36: =SUM(O36:P36) -> 150575.11 | U36: =(SUM(U17:U26)*$E$36) -> 139131.56 | V36: 0 | W36: =SUM(U36:V36) -> 139131.56 | AA36: =(SUM(AA17:AA26)*$E$36) -> 135351.83 | AB36: 0 | AC36: =SUM(AA36:AB36) -> 135351.83 | AG36: =(SUM(AG17:AG26)*$E$36) -> 97234.329 | AH36: 0 | AI36: =SUM(AG36:AH36) -> 97234.329 | AJ36: =I36+O36+U36+AA36+AG36 -> 606995.44 | AK36: =J36+P36+V36+AB36+AH36 -> 0 | AL36: =SUM(AJ36:AK36) -> 606995.44
A37: FRINGE | B37: 6950 | C37: VZ | D37: Expatriate Fringe Benefit Package | E37: 0.1967 | I37: =$E$37*I16 -> 28552.972 | J37: 0 | K37: =SUM(I37:J37) -> 28552.972 | O37: =$E$37*O16 -> 35462.791 | P37: 0 | Q37: =SUM(O37:P37) -> 35462.791 | U37: =$E$37*U16 -> 6117.3315 | V37: 0 | W37: =SUM(U37:V37) -> 6117.3315 | AA37: =$E$37*AA16 -> 0 | AB37: 0 | AC37: =SUM(AA37:AB37) -> 0 | AG37: =$E$37*AG16 -> 0 | AH37: 0 | AI37: =SUM(AG37:AH37) -> 0 | AJ37: =I37+O37+U37+AA37+AG37 -> 70133.095 | AK37: =J37+P37+V37+AB37+AH37 -> 0 | AL37: =SUM(AJ37:AK37) -> 70133.095
A38: COLA | B38: 7481 | C38: VZ | D38: Cost of Living Adjustment (COLA) for Expatriate Country Director | E38: 0.3 | I38: =$E$38*I16 -> 43548 | J38: 0 | K38: =SUM(I38:J38) -> 43548 | O38: =$E$38*O16 -> 54086.616 | P38: 0 | Q38: =SUM(O38:P38) -> 54086.616 | U38: =$E$38*U16 -> 9329.9413 | V38: 0 | W38: =SUM(U38:V38) -> 9329.9413 | AA38: =$E$38*AA16 -> 0 | AB38: 0 | AC38: =SUM(AA38:AB38) -> 0 | AG38: =$E$38*AG16 -> 0 | AH38: 0 | AI38: =SUM(AG38:AH38) -> 0 | AJ38: =I38+O38+U38+AA38+AG38 -> 106964.56 | AK38: =J38+P38+V38+AB38+AH38 -> 0 | AL38: =SUM(AJ38:AK38) -> 106964.56
A39: POST DIFF | B39: 7021 | C39: VZ | D39: Post (Hardship) Differential for Expatriate Country Director | E39: 0.25 | I39: =$E$39*I16 -> 36290 | J39: 0 | K39: =SUM(I39:J39) -> 36290 | O39: =$E$39*O16 -> 45072.18 | P39: 0 | Q39: =SUM(O39:P39) -> 45072.18 | U39: =$E$39*U16 -> 7774.951 | V39: 0 | W39: =SUM(U39:V39) -> 7774.951 | AA39: =$E$39*AA16 -> 0 | AB39: 0 | AC39: =SUM(AA39:AB39) -> 0 | AG39: =$E$39*AG16 -> 0 | AH39: 0 | AI39: =SUM(AG39:AH39) -> 0 | AJ39: =I39+O39+U39+AA39+AG39 -> 89137.131 | AK39: =J39+P39+V39+AB39+AH39 -> 0 | AL39: =SUM(AJ39:AK39) -> 89137.131
A40: HOUSE. ALL | B40: 7485 | C40: VZ | D40: Housing Allowance for Expatriate Country Director | E40: 1 | F40: 2400 | G40: 6 | H40: /month | I40: =G40*F40*E40 -> 14400 | J40: 0 | K40: =SUM(I40:J40) -> 14400 | L40: 1 | M40: =F40 -> 2400 | N40: =N16 -> 12 | O40: =N40*M40*L40 -> 28800 | P40: 0 | Q40: =SUM(O40:P40) -> 28800 | R40: 1 | S40: =F40 -> 2400 | T40: =T16 -> 2 | U40: =T40*S40*R40 -> 4800 | V40: 0 | W40: =SUM(U40:V40) -> 4800 | X40: 0 | Y40: =F40 -> 2400 | Z40: =Z16 -> 0 | AA40: =Z40*Y40*X40 -> 0 | AB40: 0 | AC40: =SUM(AA40:AB40) -> 0 | AD40: 0 | AE40: =F40 -> 2400 | AF40: =AF16 -> 0 | AG40: =AF40*AE40*AD40 -> 0 | AH40: 0 | AI40: =SUM(AG40:AH40) -> 0 | AJ40: =I40+O40+U40+AA40+AG40 -> 48000 | AK40: =J40+P40+V40+AB40+AH40 -> 0 | AL40: =SUM(AJ40:AK40) -> 48000
A41: ANNAIRFAR | B41: 7510 | C41: VZ | D41: Annual Home of Record | E41: 1 | F41: 2000 | G41: 1 | H41: /yearly | I41: =G41*F41*E41 -> 2000 | J41: 0 | K41: =SUM(I41:J41) -> 2000 | L41: 1 | M41: =F41 -> 2000 | N41: 1 | O41: =N41*M41*L41 -> 2000 | P41: 0 | Q41: =SUM(O41:P41) -> 2000 | R41: 1 | S41: =F41 -> 2000 | T41: 1 | U41: =T41*S41*R41 -> 2000 | V41: 0 | W41: =SUM(U41:V41) -> 2000 | X41: 0 | Y41: =F41 -> 2000 | Z41: 0 | AA41: =Z41*Y41*X41 -> 0 | AB41: 0 | AC41: =SUM(AA41:AB41) -> 0 | AD41: 0 | AE41: =F41 -> 2000 | AF41: 0 | AG41: =AF41*AE41*AD41 -> 0 | AH41: 0 | AI41: =SUM(AG41:AH41) -> 0 | AJ41: =I41+O41+U41+AA41+AG41 -> 6000 | AK41: =J41+P41+V41+AB41+AH41 -> 0 | AL41: =SUM(AJ41:AK41) -> 6000
D43: Fringe Benefits Total | I43: =SUM(I35:I42) -> 252030.92 | J43: =SUM(J35:J42) -> 0 | K43: =SUM(K35:K42) -> 252030.92 | O43: =SUM(O35:O42) -> 360022.86 | P43: =SUM(P35:P42) -> 0 | Q43: =SUM(Q35:Q42) -> 360022.86 | U43: =SUM(U35:U42) -> 214720.86 | V43: =SUM(V35:V42) -> 0 | W43: =SUM(W35:W42) -> 214720.86 | AA43: =SUM(AA35:AA42) -> 182513.76 | AB43: =SUM(AB35:AB42) -> 0 | AC43: =SUM(AC35:AC42) -> 182513.76 | AG43: =SUM(AG35:AG42) -> 146046.92 | AH43: =SUM(AH35:AH42) -> 0 | AI43: =SUM(AI35:AI42) -> 146046.92 | AJ43: =SUM(AJ35:AJ42) -> 1155335.3 | AK43: =SUM(AK35:AK42) -> 0 | AL43: =SUM(AL35:AL42) -> 1155335.3
D45: Travel & Transportation
D47: Volunteer Travel - International Airfare
...

Sheet Supplies
A1: Supplies
B2: Rate | C2: Unit | D2: Total
A4: Headquarters
A5: Laptop, Bag, Accessories, Shipping and Handling | B5: =B30 -> 1114.97 | C5: 3 | D5: =B5*C5 -> 3344.91
A6: Camera, Accessories, Memory Card, S&H | B6: =B38 -> 488.95 | C6: 1 | D6: =B6*C6 -> 488.95
A7: LCD Projector | B7: =B44 -> 738 | C7: 1 | D7: =B7*C7 -> 738
A8: Office Furniture (Includes Desk, Chairs, Table, Shelves, & Filing Cabinet) | B8: =B68 -> 2791 | C8: 3 | D8: =B8*C8 -> 8373
A9: Total HQ | D9: =SUM(D5:D8) -> 12944.86
A11: Field Office
A12: Venezuela
A13: Laptop | B13: =B30 -> 1114.97 | C13: 11 | D13: =B13*C13 -> 12264.67
A14: Printer | B14: =B50 -> 860 | C14: 2 | D14: =B14*C14 -> 1720
A15: Camera and Accessories | B15: =B38 -> 488.95 | C15: 3 | D15: =B15*C15 -> 1466.85
A16: Video Camera | B16: =B58 -> 337.95 | C16: 2 | D16: =B16*C16 -> 675.9
A17: LCD projector | B17: =B44 -> 738 | C17: 2 | D17: =B17*C17 -> 1476
A18: Total Field | D18: =SUM(D13:D17) -> 17603.42
A20: Total: | D20: =D18+D9 -> 30548.28
A23: Detailed Quotes for Supplies
A24: Item Detail | B24: Price
A26: Laptop
A27: Dell XPS 15 | B27: 1049.99
A28: Laptop Bag, Accessories | B28: 44.99
A29: Mouse | B29: 19.99
B30: =SUM(B27:B29) -> 1114.97
A32: Digital Camera
A33: Canon - PowerShot SX730 HS 20.3-Megapixel Digital Camera | B33: 380
A34: Camera Bag | B34: 21.95
A35: SanDisk 256GB Ultra microSDXC UHS-I Memory Card | B35: 35
A36: Dynex All in One Memory Card Reader | B36: 32
A37: Shipping and Handling | B37: 20
B38: =SUM(B33:B37) -> 488.95
A40: LCD Projector
A41: BenQ MH535FHD 1080P Projector with Ceiling Mount | B41: 583
A42: Extra Bulb, stand and accessories | B42: 135
A43: Shipping and Handling | B43: 20
B44: =SUM(B41:B43) -> 738
A46: Color Laser Printer
A47: Dell Color Smart Multifunction Printer S2825cdn Color Laser | B47: 390
A48: Toners & Accessories | B48: 450
A49: Shipping and Handling | B49: 20
...

Sheet Leverage
A2: Leverage Formula Summaries | B2: Per Day | C2: Per Volunteer - Long Term | D2: Per Volunteer - Short Term
A4: Estimated value of F2F volunteer professional time | B4: 522 | C4: 522 | D4: 522
A5: Total Volunteers: | B5: ='Volunteer Numbers'!G5 -> 45 | C5: =G11 -> 10 | D5: =G12 -> 35
A6: Total Days | B6: =SUM(C6:D6) -> 3262.5 | C6: =C5*((365/12)*9) -> 2737.5 | D6: =D5*15 -> 525 | E6: Assuming 9 months average per long term volunteer.
A7: Total LOP Program: | B7: =SUM(C7:D7) -> 1703025 | C7: =C6*C4 -> 1428975 | D7: =D6*D4 -> 274050
A9: Leverage Breakdown By Volunteer Type
A10: Volunteers | B10: FY20 | C10: FY21 | D10: FY22 | E10: FY23 | F10: FY24 | G10: Totals
A11: Long Term | B11: =Budget!E53 -> 0 | C11: =Budget!L53 -> 3 | D11: =Budget!R53 -> 3 | E11: =Budget!X53 -> 3 | F11: =Budget!AD53 -> 1 | G11: =SUM(B11:F11) -> 10
A12: Short Term | B12: =Budget!E57 -> 2 | C12: =Budget!L57 -> 10 | D12: =Budget!R57 -> 10 | E12: =Budget!X57 -> 10 | F12: =Budget!AD57 -> 3 | G12: =SUM(B12:F12) -> 35
A13: Total | B13: =SUM(B11:B12) -> 2 | C13: =SUM(C11:C12) -> 13 | D13: =SUM(D11:D12) -> 13 | E13: =SUM(E11:E12) -> 13 | F13: =SUM(F11:F12) -> 4 | G13: =SUM(G11:G12) -> 45
A15: Value Breakdown By Volunteer Type
A16: Volunteers | B16: FY20 | C16: FY21 | D16: FY22 | E16: FY23 | F16: FY24 | G16: Totals
A17: Long Term | B17: =B11*$C$4*((365/12)*9) -> 0 | C17: =C11*$C$4*((365/12)*9) -> 428692.5 | D17: =D11*$C$4*((365/12)*9) -> 428692.5 | E17: =E11*$C$4*((365/12)*9) -> 428692.5 | F17: =F11*$C$4*((365/12)*9) -> 142897.5 | G17: =SUM(B17:F17) -> 1428975
A18: Short Term | B18: =B12*$D$4*15 -> 15660 | C18: =C12*$D$4*15 -> 78300 | D18: =D12*$D$4*15 -> 78300 | E18: =E12*$D$4*15 -> 78300 | F18: =F12*$D$4*15 -> 23490 | G18: =SUM(B18:F18) -> 274050
A19: Total | B19: =SUM(B17:B18) -> 15660 | C19: =SUM(C17:C18) -> 506992.5 | D19: =SUM(D17:D18) -> 506992.5 | E19: =SUM(E17:E18) -> 506992.5 | F19: =SUM(F17:F18) -> 166387.5 | G19: =SUM(G17:G18) -> 1703025
A21: Leverage Formula Summaries | B21: Per Hour | C21: Average # of Hours/Week
A23: Local MTC Volunteer | B23: 7 | C23: =3*4 -> 12
A24: Total 300 Local MTC Volunteers (3/per MTC) for 1 Year | B24: =300*B23*C23*52 -> 1310400 | C24: =300*C23 -> 3600
A26: Leverage Grand Total
A27: 3013425

Sheet Volunteer Numbers
A2: Recruited and Fielded By Partners Only
A3: Volunteers | B3: FY20 | C3: FY21 | D3: FY22 | E3: FY23 | F3: FY24 | G3: Totals
A4: F2F Venezuela | B4: 2 | C4: 13 | D4: 13 | E4: 13 | F4: 4 | G4: =SUM(B4:F4) -> 45
A5: Total | B5: =SUM(B4:B4) -> 2 | C5: =SUM(C4:C4) -> 13 | D5: =SUM(D4:D4) -> 13 | E5: =SUM(E4:E4) -> 13 | F5: =SUM(F4:F4) -> 4 | G5: =SUM(G4:G4) -> 45
A7: Recruited and Fielded By Partners & Local Implementing Partners
A8: Volunteers | B8: FY20 | C8: FY21 | D8: FY22 | E8: FY23 | F8: FY24 | G8: Totals
A9: Local MTC Volunteers | B9: 75 | C9: 150 | D9: 75 | E9: 0 | F9: 0 | G9: =SUM(B9:F9) -> 300
A10: Total | B10: =SUM(B9:B9) -> 75 | C10: =SUM(C9:C9) -> 150 | D10: =SUM(D9:D9) -> 75 | E10: =SUM(E9:E9) -> 0 | F10: =SUM(F9:F9) -> 0 | G10: =SUM(G9:G9) -> 300
