Workbook
Name \a: '[1]CUADRO No 4'!#REF!
Name \c: #REF!
Name \i: #REF!
Name \P: #REF!
Name \r: #REF!
Name __pd1: [2]Rates!$J$24
Name __pd6: [2]Rates!$J$30
Name __tix1: [2]Rates!$J$40
Name __tix2: [2]Rates!$J$41
Name __tix6: [2]Rates!$J$47
Name _1: #REF!
Name _1998: #REF!
Name _1999: #REF!
Name _2: #REF!
Name _2000: #REF!
Name _2001: #REF!
Name _2002: #REF!
Name _3: #REF!
Name _4: #REF!
Name _5: #REF!
Name _6: #REF!
Name _7: #REF!
Name _8: #REF!
Name _fmi1: [3]PAGOFMI!$A$1:$L$51
Name _fmi2: [3]PAGOFMI!$P$1:$AA$51
Name _fmi3: [3]PAGORES!$AC$1:$AN$43
Name _fmi4: [3]PAGORES!$AP$1:$BA$44
Name _PIB01: [4]SUPUESTOS!#REF!
Name _PIB02: [5]SUPUESTOS!#REF!
Name _PIB95: [4]SUPUESTOS!$J$47
Name _PIB96: [4]SUPUESTOS!$K$47
Name _PIB97: [6]SUPUESTOS!$L$47
Name _PIB98: [6]SUPUESTOS!$M$47
Name _PIB99: [6]SUPUESTOS!$N$47
Name _RES9397: #REF!
Name _rez2: '[3]PAGOS VIGENCIA t'!$A$57:$AH$108
Name _rez3: [3]PAGORES!$A$1:$M$37
Name _rez4: [3]PAGORES!$O$1:$AN$43
Name a: #REF!
Name A_2002: #REF!
Name A_CAPITAL: [9]Hoja4!$B$3:$O$34
Name A_DEPTOS: [9]Hoja4!$B$76:$N$108
Name A_impresión_IM: #REF!
Name A_MUNPIOS: [9]Hoja4!$B$39:$N$71
Name AAA: [10]proyecINGRESOS99!$L$1:$T$97
Name AEFormar: [11]Variables!$C$5
Name Ajustado: #REF!
Name almuerzo: [11]Variables!$C$18
Name alquilertableta: [11]Variables!$C$21
Name ANEXO_No.: #REF!
Name ANEXO_No._5: #REF!
Name ANPDH: '[12]Salary & PR Tax'!#REF!
Name aprnac: [13]GASTOS!#REF!
Name APROPIACIONES_PAC_Y_REZAGO_1999___2000: #REF!
Name aprprp: [13]GASTOS!#REF!
Name asigbas: #REF!
Name asigbasempu: #REF!
Name asigbasisten: #REF!
Name asigmen: #REF!
Name auxalm: #REF!

Sheet Budget Summary Partners
B1: Partners of the Americas Juntos Aprendemos Budget 2020
B2: USAID RFA No. 7200AA21RFA00001
A4: Line Items | B4: Year 1 | E4: Year 2 | H4: Year 3 | K4: Year 4 | N4: Year 5 | Q4: Total | R4: Total | S4: Grand
B5: USAID | C5: Leverage | D5: Total | E5: USAID | F5: Leverage | G5: Total | H5: USAID | I5: Leverage | J5: Total | K5: USAID | L5: Leverage | M5: Total | N5: USAID | O5: Leverage | P5: Total | Q5: USAID | R5: Leverage | S5: Total
A7: Personnel | B7: ='Budget Partners'!K39 -> 757570.27 | C7: ='Budget Partners'!L39 -> 0 | D7: =SUM(B7:C7) -> 757570.27 | E7: ='Budget Partners'!Q39 -> 869469.74 | F7: ='Budget Partners'!R39 -> 0 | G7: =SUM(E7:F7) -> 869469.74 | H7: ='Budget Partners'!W39 -> 904248.53 | I7: ='Budget Partners'!X39 -> 0 | J7: =SUM(H7:I7) -> 904248.53 | K7: ='Budget Partners'!AC39 -> 940418.48 | L7: ='Budget Partners'!AD39 -> 0 | M7: =SUM(K7:L7) -> 940418.48 | N7: ='Budget Partners'!AI39 -> 919932.24 | O7: ='Budget Partners'!AJ39 -> 0 | P7: =SUM(N7:O7) -> 919932.24 | Q7: ='Budget Partners'!AL39 -> 4391639.3 | R7: ='Budget Partners'!AM39 -> 0 | S7: ='Budget Partners'!AN39 -> 4391639.3
A9: Fringe Benefits | B9: ='Budget Partners'!K57 -> 387758.33 | C9: ='Budget Partners'!L57 -> 0 | D9: ='Budget Partners'!M57 -> 387758.33 | E9: ='Budget Partners'!Q57 -> 421082.64 | F9: ='Budget Partners'!R57 -> 0 | G9: ='Budget Partners'!S57 -> 421082.64 | H9: ='Budget Partners'!W57 -> 435904.26 | I9: ='Budget Partners'!X57 -> 0 | J9: ='Budget Partners'!Y57 -> 435904.26 | K9: ='Budget Partners'!AC57 -> 454244.23 | L9: ='Budget Partners'!AD57 -> 0 | M9: ='Budget Partners'!AE57 -> 454244.23 | N9: ='Budget Partners'!AI57 -> 463361.04 | O9: ='Budget Partners'!AJ57 -> 0 | P9: ='Budget Partners'!AK57 -> 463361.04 | Q9: ='Budget Partners'!AL57 -> 2162350.5 | R9: ='Budget Partners'!AM57 -> 0 | S9: ='Budget Partners'!AN57 -> 2162350.5
A11: Travel | B11: ='Budget Partners'!K106 -> 55845 | C11: ='Budget Partners'!L106 -> 0 | D11: ='Budget Partners'!M106 -> 55845 | E11: ='Budget Partners'!Q106 -> 110986.5 | F11: ='Budget Partners'!R106 -> 0 | G11: ='Budget Partners'!S106 -> 110986.5 | H11: ='Budget Partners'!W106 -> 116653.85 | I11: ='Budget Partners'!X106 -> 0 | J11: ='Budget Partners'!Y106 -> 116653.85 | K11: ='Budget Partners'!AC106 -> 118091.68 | L11: ='Budget Partners'!AD106 -> 0 | M11: ='Budget Partners'!AE106 -> 118091.68 | N11: ='Budget Partners'!AI106 -> 70200.655 | O11: ='Budget Partners'!AJ106 -> 0 | P11: ='Budget Partners'!AK106 -> 70200.655 | Q11: ='Budget Partners'!AL106 -> 471777.68 | R11: ='Budget Partners'!AM106 -> 0 | S11: ='Budget Partners'!AN106 -> 471777.68
A13: Equipment | B13: ='Budget Partners'!K112 -> 150000 | C13: ='Budget Partners'!L112 -> 0 | D13: ='Budget Partners'!M112 -> 150000 | E13: ='Budget Partners'!Q112 -> 0 | F13: ='Budget Partners'!R112 -> 0 | G13: ='Budget Partners'!S112 -> 0 | H13: ='Budget Partners'!W112 -> 0 | I13: ='Budget Partners'!X112 -> 0 | J13: ='Budget Partners'!Y112 -> 0 | K13: ='Budget Partners'!AC112 -> 0 | L13: ='Budget Partners'!AD112 -> 0 | M13: ='Budget Partners'!AE112 -> 0 | N13: ='Budget Partners'!AI112 -> 0 | O13: ='Budget Partners'!AJ112 -> 0 | P13: ='Budget Partners'!AK112 -> 0 | Q13: ='Budget Partners'!AL112 -> 150000 | R13: ='Budget Partners'!AM112 -> 0 | S13: ='Budget Partners'!AN112 -> 150000
A15: Supplies | B15: ='Budget Partners'!K137 -> 86398.18 | C15: ='Budget Partners'!L137 -> 0 | D15: ='Budget Partners'!M137 -> 86398.18 | E15: ='Budget Partners'!Q137 -> 40125 | F15: ='Budget Partners'!R137 -> 0 | G15: ='Budget Partners'!S137 -> 40125 | H15: ='Budget Partners'!W137 -> 41283.075 | I15: ='Budget Partners'!X137 -> 0 | J15: ='Budget Partners'!Y137 -> 41283.075 | K15: ='Budget Partners'!AC137 -> 27723.393 | L15: ='Budget Partners'!AD137 -> 0 | M15: ='Budget Partners'!AE137 -> 27723.393 | N15: ='Budget Partners'!AI137 -> 22177.052 | O15: ='Budget Partners'!AJ137 -> 0 | P15: ='Budget Partners'!AK137 -> 22177.052 | Q15: ='Budget Partners'!AL137 -> 217706.7 | R15: ='Budget Partners'!AM137 -> 0 | S15: ='Budget Partners'!AN137 -> 217706.7
A17: Contractual | B17: ='Budget Partners'!K168 -> 3318069.5 | C17: ='Budget Partners'!L168 -> 245351.82 | D17: ='Budget Partners'!M168 -> 3563421.3 | E17: ='Budget Partners'!Q168 -> 3997677.1 | F17: ='Budget Partners'!R168 -> 200067.84 | G17: ='Budget Partners'!S168 -> 4197744.9 | H17: ='Budget Partners'!W168 -> 4340006.7 | I17: ='Budget Partners'!X168 -> 198207.17 | J17: ='Budget Partners'!Y168 -> 4538213.9 | K17: ='Budget Partners'!AC168 -> 4317470.6 | L17: ='Budget Partners'!AD168 -> 205687.48 | M17: ='Budget Partners'!AE168 -> 4523158 | N17: ='Budget Partners'!AI168 -> 2761408.6 | O17: ='Budget Partners'!AJ168 -> 209691.71 | P17: ='Budget Partners'!AK168 -> 2971100.3 | Q17: ='Budget Partners'!AL168 -> 18734632 | R17: ='Budget Partners'!AM168 -> 1059006 | S17: ='Budget Partners'!AN168 -> 19793638
A19: Other Direct Costs | B19: ='Budget Partners'!K220 -> 316251 | C19: ='Budget Partners'!L220 -> 0 | D19: ='Budget Partners'!M220 -> 316251 | E19: ='Budget Partners'!Q220 -> 192761.42 | F19: ='Budget Partners'!R220 -> 0 | G19: ='Budget Partners'!S220 -> 192761.42 | H19: ='Budget Partners'!W220 -> 197225 | I19: ='Budget Partners'!X220 -> 0 | J19: ='Budget Partners'!Y220 -> 197225 | K19: ='Budget Partners'!AC220 -> 199315.36 | L19: ='Budget Partners'!AD220 -> 0 | M19: ='Budget Partners'!AE220 -> 199315.36 | N19: ='Budget Partners'!AI220 -> 163481.31 | O19: ='Budget Partners'!AJ220 -> 0 | P19: ='Budget Partners'!AK220 -> 163481.31 | Q19: ='Budget Partners'!AL220 -> 1069034.1 | R19: ='Budget Partners'!AM220 -> 0 | S19: ='Budget Partners'!AN220 -> 1069034.1
A21: Total Direct Costs | B21: ='Budget Partners'!K222 -> 5071892.3 | C21: ='Budget Partners'!L222 -> 245351.82 | D21: ='Budget Partners'!M222 -> 5317244.1 | E21: ='Budget Partners'!Q222 -> 5632102.4 | F21: ='Budget Partners'!R222 -> 200067.84 | G21: ='Budget Partners'!S222 -> 5832170.2 | H21: ='Budget Partners'!W222 -> 6035321.4 | I21: ='Budget Partners'!X222 -> 198207.17 | J21: ='Budget Partners'!Y222 -> 6233528.6 | K21: ='Budget Partners'!AC222 -> 6057263.7 | L21: ='Budget Partners'!AD222 -> 205687.48 | M21: ='Budget Partners'!AE222 -> 6262951.2 | N21: ='Budget Partners'!AI222 -> 4400560.9 | O21: ='Budget Partners'!AJ222 -> 209691.71 | P21: ='Budget Partners'!AK222 -> 4610252.6 | Q21: ='Budget Partners'!AL222 -> 27197141 | R21: ='Budget Partners'!AM222 -> 1059006 | S21: ='Budget Partners'!AN222 -> 28256147
A22: Indirect Costs | B22: ='Budget Partners'!K223 -> 1455125.9 | C22: ='Budget Partners'!L223 -> 0 | D22: ='Budget Partners'!M223 -> 1455125.9 | E22: ='Budget Partners'!Q223 -> 1615850.2 | F22: ='Budget Partners'!R223 -> 0 | G22: ='Budget Partners'!S223 -> 1615850.2 | H22: ='Budget Partners'!W223 -> 1731533.7 | I22: ='Budget Partners'!X223 -> 0 | J22: ='Budget Partners'!Y223 -> 1731533.7 | K22: ='Budget Partners'!AC223 -> 1737829 | L22: ='Budget Partners'!AD223 -> 0 | M22: ='Budget Partners'!AE223 -> 1737829 | N22: ='Budget Partners'!AI223 -> 1262520.9 | O22: ='Budget Partners'!AJ223 -> 0 | P22: ='Budget Partners'!AK223 -> 1262520.9 | Q22: ='Budget Partners'!AL223 -> 7802859.7 | R22: ='Budget Partners'!AM223 -> 0 | S22: ='Budget Partners'!AN223 -> 7802859.7
A23: Total | B23: ='Budget Partners'!K224 -> 6527018.2 | C23: ='Budget Partners'!L224 -> 245351.82 | D23: ='Budget Partners'!M224 -> 6772370 | E23: ='Budget Partners'!Q224 -> 7247952.6 | F23: ='Budget Partners'!R224 -> 200067.84 | G23: ='Budget Partners'!S224 -> 7448020.4 | H23: ='Budget Partners'!W224 -> 7766855.1 | I23: ='Budget Partners'!X224 -> 198207.17 | J23: ='Budget Partners'!Y224 -> 7965062.3 | K23: ='Budget Partners'!AC224 -> 7795092.7 | L23: ='Budget Partners'!AD224 -> 205687.48 | M23: ='Budget Partners'!AE224 -> 8000780.1 | N23: ='Budget Partners'!AI224 -> 5663081.8 | O23: ='Budget Partners'!AJ224 -> 209691.71 | P23: ='Budget Partners'!AK224 -> 5872773.5 | Q23: ='Budget Partners'!AL224 -> 35000000 | R23: ='Budget Partners'!AM224 -> 1059006 | S23: ='Budget Partners'!AN224 -> 36059006
B25: New Partnership Initiative Eligibility
B26: Sub-awards to new or underutilized partners via prime awardees that serve in a limited mentorship role
B28: Modality 3a: Local Entity Sub-Awardees That Move to Direct Awards: Prime awardees must pass a minimum of 50 percent of the total funding of their awards to local sub-awardees, with a goal of moving them to qualify for direct awards. In appropriate cases, USAID might pursue prime / mentor awards with a provision for transition awards to some local entities during the life of the award.
B29: Total Award: | E29: =Q23 -> 35000000
B30: 50% of Total Award: | E30: =E29*0.5 -> 17500000
B31: Subaward Parque Explora: | E31: ='Budget Summary Parque Explora'!Q23 -> 6818381.4
B32: Subaward ProAntioquia: | E32: ='Budget Summary ProAntioquia'!Q23 -> 2133978.7
B33: Subaward Fundación Carvajal: | E33: ='Budget Summary Fund. Carvajal'!Q23 -> 8686266.3
B34: Total Subawards: | E34: =SUM(E31:E33) -> 17638626

Sheet Budget Partners
G1: Partners of the Americas Juntos Aprendemos Budget 2020
G2: USAID RFA No. 7200AA21RFA00001
G3: Duration: 5 Years
G4: Country: Colombia
A5: Entity: | B5: P | F5: Budget Assumptions
A6: Program-Dept.: | B6: 20300 | F6: Inflation - US Based Goods/Services - 1.5% | G6: 1.015
A7: Funder-Grant: | B7: USAID800 | F7: Inflation - Locally Purchased Goods/Services - 3%** | G7: 1.03
F8: Merit Based Increases for HQ & Field Staff - 4% | G8: 1.04
F9: **Based on Banco de la Republica Colombia Expected Inflation Rate
F11: *Key Personnel
A12: Sage Activity | B12: Sage Object Code/ Line Item | C12: Country Code (DC=0 or CO) | D12: Office Code (DC=0 or CO) | E12: Subcontract Code | F12: Line Items | K12: Year 1 | Q12: Year 2 | T12: Year 3 | AC12: Year 4 | AI12: Year 5 | AL12: Total | AM12: Total | AN12: Grand
G13: Unit | H13: Cost | I13: Duration | J13: Type | K13: USAID | L13: Leverage | M13: Total | N13: Unit | O13: Cost | P13: Duration | Q13: USAID | R13: Leverage | S13: Total | T13: Unit | U13: Cost | V13: Duration | W13: USAID | X13: Leverage | Y13: Total | Z13: Unit | AA13: Cost | AB13: Duration | AC13: USAID | AD13: Leverage | AE13: Total | AF13: Unit | AG13: Cost | AH13: Duration | AI13: USAID | AJ13: Leverage | AK13: Total | AL13: USAID | AM13: Leverage | AN13: Total
F15: Personnel
F16: Headquarters Personnel | G16: LOE
A17: PERSNL | B17: Timesheets | C17: USA | D17: USA | E17: 0 | F17: Program Director | G17: 0.3 | H17: =116762/12 -> 9730.1667 | I17: 12 | J17: /months | K17: =I17*H17*G17 -> 35028.6 | L17: 0 | M17: =SUM(K17:L17) -> 35028.6 | N17: =G17 -> 0.3 | O17: =H17*$G$8 -> 10119.373 | P17: 12 | Q17: =N17*O17*P17 -> 36429.744 | R17: 0 | S17: =SUM(Q17:R17) -> 36429.744 | T17: =G17 -> 0.3 | U17: =H17*$G$8*$G$8 -> 10524.148 | V17: 12 | W17: =T17*U17*V17 -> 37886.934 | X17: 0 | Y17: =SUM(W17:X17) -> 37886.934 | Z17: =T17 -> 0.3 | AA17: =H17*$G$8*$G$8*$G$8 -> 10945.114 | AB17: 12 | AC17: =Z17*AA17*AB17 -> 39402.411 | AD17: 0 | AE17: =SUM(AC17:AD17) -> 39402.411 | AF17: =Z17 -> 0.3 | AG17: =H17*$G$8*$G$8*$G$8*$G$8 -> 11382.919 | AH17: 12 | AI17: =AF17*AG17*AH17 -> 40978.508 | AJ17: 0 | AK17: =SUM(AI17:AJ17) -> 40978.508 | AL17: =K17+Q17+W17+AC17+AI17 -> 189726.2 | AM17: =L17+R17+X17+AD17+AJ17 -> 0 | AN17: =SUM(AL17:AM17) -> 189726.2
A18: PERSNL | B18: Timesheets | C18: USA | D18: USA | E18: 0 | F18: Associate Director | G18: 1 | H18: =85000/12 -> 7083.3333 | I18: 12 | J18: /months | K18: =I18*H18*G18 -> 85000 | L18: 0 | M18: =SUM(K18:L18) -> 85000 | N18: =G18 -> 1 | O18: =H18*$G$8 -> 7366.6667 | P18: 12 | Q18: =N18*O18*P18 -> 88400 | R18: 0 | S18: =SUM(Q18:R18) -> 88400 | T18: =N18 -> 1 | U18: =H18*$G$8*$G$8 -> 7661.3333 | V18: 12 | W18: =T18*U18*V18 -> 91936 | X18: 0 | Y18: =SUM(W18:X18) -> 91936 | Z18: =T18 -> 1 | AA18: =H18*$G$8*$G$8*$G$8 -> 7967.7867 | AB18: 12 | AC18: =Z18*AA18*AB18 -> 95613.44 | AD18: 0 | AE18: =SUM(AC18:AD18) -> 95613.44 | AF18: =Z18 -> 1 | AG18: =H18*$G$8*$G$8*$G$8*$G$8 -> 8286.4981 | AH18: 12 | AI18: =AF18*AG18*AH18 -> 99437.978 | AJ18: 0 | AK18: =SUM(AI18:AJ18) -> 99437.978 | AL18: =K18+Q18+W18+AC18+AI18 -> 460387.42 | AM18: =L18+R18+X18+AD18+AJ18 -> 0 | AN18: =SUM(AL18:AM18) -> 460387.42
A19: PERSNL | B19: Timesheets | C19: USA | D19: USA | E19: 0 | F19: Senior Program Officer | G19: 1 | H19: =52000/12 -> 4333.3333 | I19: 12 | J19: /months | K19: =I19*H19*G19 -> 52000 | L19: 0 | M19: =SUM(K19:L19) -> 52000 | N19: =G19 -> 1 | O19: =H19*$G$8 -> 4506.6667 | P19: 12 | Q19: =N19*O19*P19 -> 54080 | R19: 0 | S19: =SUM(Q19:R19) -> 54080 | T19: =N19 -> 1 | U19: =H19*$G$8*$G$8 -> 4686.9333 | V19: 12 | W19: =T19*U19*V19 -> 56243.2 | X19: 0 | Y19: =SUM(W19:X19) -> 56243.2 | Z19: =T19 -> 1 | AA19: =H19*$G$8*$G$8*$G$8 -> 4874.4107 | AB19: 12 | AC19: =Z19*AA19*AB19 -> 58492.928 | AD19: 0 | AE19: =SUM(AC19:AD19) -> 58492.928 | AF19: =Z19 -> 1 | AG19: =H19*$G$8*$G$8*$G$8*$G$8 -> 5069.3871 | AH19: 12 | AI19: =AF19*AG19*AH19 -> 60832.645 | AJ19: 0 | AK19: =SUM(AI19:AJ19) -> 60832.645 | AL19: =K19+Q19+W19+AC19+AI19 -> 281648.77 | AM19: =L19+R19+X19+AD19+AJ19 -> 0 | AN19: =SUM(AL19:AM19) -> 281648.77
F20: Subtotal HQ Personnel | K20: =SUM(K17:K19) -> 172028.6 | L20: =SUM(L17:L19) -> 0 | M20: =SUM(M17:M19) -> 172028.6 | Q20: =SUM(Q17:Q19) -> 178909.74 | R20: =SUM(R17:R19) -> 0 | S20: =SUM(S17:S19) -> 178909.74 | W20: =SUM(W17:W19) -> 186066.13 | X20: =SUM(X17:X19) -> 0 | Y20: =SUM(Y17:Y19) -> 186066.13 | AC20: =SUM(AC17:AC19) -> 193508.78 | AD20: =SUM(AD17:AD19) -> 0 | AE20: =SUM(AE17:AE19) -> 193508.78 | AI20: =SUM(AI17:AI19) -> 201249.13 | AJ20: =SUM(AJ17:AJ19) -> 0 | AK20: =SUM(AK17:AK19) -> 201249.13 | AL20: =SUM(AL17:AL19) -> 931762.39 | AM20: =SUM(AM17:AM19) -> 0 | AN20: =SUM(AN17:AN19) -> 931762.39
F22: Field Personnel | G22: LOE
A23: PERSNL-COP | B23: Timesheets | C23: COL2 | D23: COL2 | E23: 0 | F23: Chief of Party* | G23: 1 | H23: =135000/12 -> 11250 | I23: 12 | J23: /months | K23: =I23*H23*G23 -> 135000 | L23: 0 | M23: =SUM(K23:L23) -> 135000 | N23: 1 | O23: =H23*$G$8 -> 11700 | P23: 12 | Q23: =O23*P23*N23 -> 140400 | R23: 0 | S23: =SUM(Q23:R23) -> 140400 | T23: 1 | U23: =(H23*$G$8*$G$8) -> 12168 | V23: 12 | W23: =V23*U23*T23 -> 146016 | X23: 0 | Y23: =SUM(W23:X23) -> 146016 | Z23: 1 | AA23: =H23*$G$8*$G$8*$G$8 -> 12654.72 | AB23: 12 | AC23: =AB23*AA23*Z23 -> 151856.64 | AD23: 0 | AE23: =SUM(AC23:AD23) -> 151856.64 | AF23: 1 | AG23: =H23*$G$8*$G$8*$G$8*$G$8 -> 13160.909 | AH23: 12 | AI23: =AH23*AG23*AF23 -> 157930.91 | AJ23: 0 | AK23: =SUM(AI23:AJ23) -> 157930.91 | AL23: =K23+Q23+W23+AC23+AI23 -> 731203.55 | AM23: =L23+R23+X23+AD23+AJ23 -> 0 | AN23: =SUM(AL23:AM23) -> 731203.55
A24: PERSNL-DCP | B24: 70000 | C24: COL2 | D24: COL2 | E24: 0 | F24: Deputy Chief of Party* | G24: 1 | H24: =100000/12 -> 8333.3333 | I24: 12 | J24: /months | K24: =I24*H24*G24 -> 100000 | L24: 0 | M24: =SUM(K24:L24) -> 100000 | N24: 1 | O24: =H24*$G$8 -> 8666.6667 | P24: 12 | Q24: =O24*P24*N24 -> 104000 | R24: 0 | S24: =SUM(Q24:R24) -> 104000 | T24: 1 | U24: =H24*$G$8*$G$8 -> 9013.3333 | V24: 12 | W24: =V24*U24*T24 -> 108160 | X24: 0 | Y24: =SUM(W24:X24) -> 108160 | Z24: 1 | AA24: =H24*$G$8*$G$8*$G$8 -> 9373.8667 | AB24: 12 | AC24: =AB24*AA24*Z24 -> 112486.4 | AD24: 0 | AE24: =SUM(AC24:AD24) -> 112486.4 | AF24: 1 | AG24: =H24*$G$8*$G$8*$G$8*$G$8 -> 9748.8213 | AH24: 12 | AI24: =AH24*AG24*AF24 -> 116985.86 | AJ24: 0 | AK24: =SUM(AI24:AJ24) -> 116985.86 | AL24: =K24+Q24+W24+AC24+AI24 -> 541632.26 | AM24: =L24+R24+X24+AD24+AJ24 -> 0 | AN24: =SUM(AL24:AM24) -> 541632.26
A25: PERSNL-F&A | B25: 70000 | C25: COL2 | D25: COL2 | E25: 0 | F25: Finance & Admin Director | G25: 1 | H25: =52500/12 -> 4375 | I25: 12 | J25: /months | K25: =I25*H25*G25 -> 52500 | L25: 0 | M25: =SUM(K25:L25) -> 52500 | N25: 1 | O25: =H25*$G$8 -> 4550 | P25: 12 | Q25: =O25*P25*N25 -> 54600 | R25: 0 | S25: =SUM(Q25:R25) -> 54600 | T25: 1 | U25: =H25*$G$8*$G$8 -> 4732 | V25: 12 | W25: =V25*U25*T25 -> 56784 | X25: 0 | Y25: =SUM(W25:X25) -> 56784 | Z25: 1 | AA25: =H25*$G$8*$G$8*$G$8 -> 4921.28 | AB25: 12 | AC25: =AB25*AA25*Z25 -> 59055.36 | AD25: 0 | AE25: =SUM(AC25:AD25) -> 59055.36 | AF25: 1 | AG25: =H25*$G$8*$G$8*$G$8*$G$8 -> 5118.1312 | AH25: 12 | AI25: =AH25*AG25*AF25 -> 61417.574 | AJ25: 0 | AK25: =SUM(AI25:AJ25) -> 61417.574 | AL25: =K25+Q25+W25+AC25+AI25 -> 284356.93 | AM25: =L25+R25+X25+AD25+AJ25 -> 0 | AN25: =SUM(AL25:AM25) -> 284356.93
A26: PERSNL-GD | B26: 70000 | C26: COL2 | D26: COL2 | E26: 0 | F26: Grants Director | G26: 1 | H26: =52500/12 -> 4375 | I26: 10 | J26: /months | K26: =I26*H26*G26 -> 43750 | L26: 0 | M26: =SUM(K26:L26) -> 43750 | N26: 1 | O26: =H26*$G$8 -> 4550 | P26: 12 | Q26: =O26*P26*N26 -> 54600 | R26: 0 | S26: =SUM(Q26:R26) -> 54600 | T26: 1 | U26: =H26*$G$8*$G$8 -> 4732 | V26: 12 | W26: =V26*U26*T26 -> 56784 | X26: 0 | Y26: =SUM(W26:X26) -> 56784 | Z26: 1 | AA26: =H26*$G$8*$G$8*$G$8 -> 4921.28 | AB26: 12 | AC26: =AB26*AA26*Z26 -> 59055.36 | AD26: 0 | AE26: =SUM(AC26:AD26) -> 59055.36 | AF26: 1 | AG26: =H26*$G$8*$G$8*$G$8*$G$8 -> 5118.1312 | AH26: 12 | AI26: =AH26*AG26*AF26 -> 61417.574 | AJ26: 0 | AK26: =SUM(AI26:AJ26) -> 61417.574 | AL26: =K26+Q26+W26+AC26+AI26 -> 275606.93 | AM26: =L26+R26+X26+AD26+AJ26 -> 0 | AN26: =SUM(AL26:AM26) -> 275606.93
A27: PERSNL-HRM | B27: 70000 | C27: COL2 | D27: COL2 | E27: 0 | F27: Human Resource Manager | G27: 1 | H27: =38000/12 -> 3166.6667 | I27: 10 | J27: /months | K27: =I27*H27*G27 -> 31666.667 | L27: 0 | M27: =SUM(K27:L27) -> 31666.667 | N27: 1 | O27: =H27*$G$8 -> 3293.3333 | P27: 12 | Q27: =O27*P27*N27 -> 39520 | R27: 0 | S27: =SUM(Q27:R27) -> 39520 | T27: 1 | U27: =H27*$G$8*$G$8 -> 3425.0667 | V27: 12 | W27: =V27*U27*T27 -> 41100.8 | X27: 0 | Y27: =SUM(W27:X27) -> 41100.8 | Z27: 1 | AA27: =H27*$G$8*$G$8*$G$8 -> 3562.0693 | AB27: 12 | AC27: =AB27*AA27*Z27 -> 42744.832 | AD27: 0 | AE27: =SUM(AC27:AD27) -> 42744.832 | AF27: 1 | AG27: =H27*$G$8*$G$8*$G$8*$G$8 -> 3704.5521 | AH27: 11 | AI27: =AH27*AG27*AF27 -> 40750.073 | AJ27: 0 | AK27: =SUM(AI27:AJ27) -> 40750.073 | AL27: =K27+Q27+W27+AC27+AI27 -> 195782.37 | AM27: =L27+R27+X27+AD27+AJ27 -> 0 | AN27: =SUM(AL27:AM27) -> 195782.37
A28: PERSNL-ACT | B28: 70000 | C28: COL2 | D28: COL2 | E28: 0 | F28: Accountant | G28: 1 | H28: =22500/12 -> 1875 | I28: 9 | J28: /months | K28: =I28*H28*G28 -> 16875 | L28: 0 | M28: =SUM(K28:L28) -> 16875 | N28: 1 | O28: =H28*$G$8 -> 1950 | P28: 12 | Q28: =O28*P28*N28 -> 23400 | R28: 0 | S28: =SUM(Q28:R28) -> 23400 | T28: 1 | U28: =H28*$G$8*$G$8 -> 2028 | V28: 12 | W28: =V28*U28*T28 -> 24336 | X28: 0 | Y28: =SUM(W28:X28) -> 24336 | Z28: 1 | AA28: =H28*$G$8*$G$8*$G$8 -> 2109.12 | AB28: 12 | AC28: =AB28*AA28*Z28 -> 25309.44 | AD28: 0 | AE28: =SUM(AC28:AD28) -> 25309.44 | AF28: 1 | AG28: =H28*$G$8*$G$8*$G$8*$G$8 -> 2193.4848 | AH28: 9 | AI28: =AH28*AG28*AF28 -> 19741.363 | AJ28: 0 | AK28: =SUM(AI28:AJ28) -> 19741.363 | AL28: =K28+Q28+W28+AC28+AI28 -> 109661.8 | AM28: =L28+R28+X28+AD28+AJ28 -> 0 | AN28: =SUM(AL28:AM28) -> 109661.8
A29: PERSNL-ADM | B29: 70000 | C29: COL2 | D29: COL2 | E29: 0 | F29: Administrative Assistant | G29: 1 | H29: =15000/12 -> 1250 | I29: 8 | J29: /months | K29: =I29*H29*G29 -> 10000 | L29: 0 | M29: =SUM(K29:L29) -> 10000 | N29: 1 | O29: =H29*$G$8 -> 1300 | P29: 12 | Q29: =O29*P29*N29 -> 15600 | R29: 0 | S29: =SUM(Q29:R29) -> 15600 | T29: 1 | U29: =H29*$G$8*$G$8 -> 1352 | V29: 12 | W29: =V29*U29*T29 -> 16224 | X29: 0 | Y29: =SUM(W29:X29) -> 16224 | Z29: 1 | AA29: =H29*$G$8*$G$8*$G$8 -> 1406.08 | AB29: 12 | AC29: =AB29*AA29*Z29 -> 16872.96 | AD29: 0 | AE29: =SUM(AC29:AD29) -> 16872.96 | AF29: 1 | AG29: =H29*$G$8*$G$8*$G$8*$G$8 -> 1462.3232 | AH29: 8 | AI29: =AH29*AG29*AF29 -> 11698.586 | AJ29: 0 | AK29: =SUM(AI29:AJ29) -> 11698.586 | AL29: =K29+Q29+W29+AC29+AI29 -> 70395.546 | AM29: =L29+R29+X29+AD29+AJ29 -> 0 | AN29: =SUM(AL29:AM29) -> 70395.546
A30: PERSNL-MED | B30: 70000 | C30: COL2 | D30: COL2 | E30: 0 | F30: M&E Director | G30: 1 | H30: =52500/12 -> 4375 | I30: 12 | J30: /months | K30: =I30*H30*G30 -> 52500 | L30: 0 | M30: =SUM(K30:L30) -> 52500 | N30: 1 | O30: =H30*$G$8 -> 4550 | P30: 12 | Q30: =O30*P30*N30 -> 54600 | R30: 0 | S30: =SUM(Q30:R30) -> 54600 | T30: 1 | U30: =H30*$G$8*$G$8 -> 4732 | V30: 12 | W30: =V30*U30*T30 -> 56784 | X30: 0 | Y30: =SUM(W30:X30) -> 56784 | Z30: 1 | AA30: =H30*$G$8*$G$8*$G$8 -> 4921.28 | AB30: 12 | AC30: =AB30*AA30*Z30 -> 59055.36 | AD30: 0 | AE30: =SUM(AC30:AD30) -> 59055.36 | AF30: 1 | AG30: =H30*$G$8*$G$8*$G$8*$G$8 -> 5118.1312 | AH30: 12 | AI30: =AH30*AG30*AF30 -> 61417.574 | AJ30: 0 | AK30: =SUM(AI30:AJ30) -> 61417.574 | AL30: =K30+Q30+W30+AC30+AI30 -> 284356.93 | AM30: =L30+R30+X30+AD30+AJ30 -> 0 | AN30: =SUM(AL30:AM30) -> 284356.93
A31: PERSNL-M&E | B31: 70000 | C31: COL2 | D31: COL2 | E31: 0 | F31: M&E Manager | G31: 1 | H31: =38000/12 -> 3166.6667 | I31: 9 | J31: /months | K31: =I31*H31*G31 -> 28500 | L31: 0 | M31: =SUM(K31:L31) -> 28500 | N31: 1 | O31: =H31*$G$8 -> 3293.3333 | P31: 12 | Q31: =O31*P31*N31 -> 39520 | R31: 0 | S31: =SUM(Q31:R31) -> 39520 | T31: 1 | U31: =H31*$G$8*$G$8 -> 3425.0667 | V31: 12 | W31: =V31*U31*T31 -> 41100.8 | X31: 0 | Y31: =SUM(W31:X31) -> 41100.8 | Z31: 1 | AA31: =H31*$G$8*$G$8*$G$8 -> 3562.0693 | AB31: 12 | AC31: =AB31*AA31*Z31 -> 42744.832 | AD31: 0 | AE31: =SUM(AC31:AD31) -> 42744.832 | AF31: 1 | AG31: =H31*$G$8*$G$8*$G$8*$G$8 -> 3704.5521 | AH31: 9 | AI31: =AH31*AG31*AF31 -> 33340.969 | AJ31: 0 | AK31: =SUM(AI31:AJ31) -> 33340.969 | AL31: =K31+Q31+W31+AC31+AI31 -> 185206.6 | AM31: =L31+R31+X31+AD31+AJ31 -> 0 | AN31: =SUM(AL31:AM31) -> 185206.6
A32: PERSNL-CDD | B32: 70000 | C32: COL2 | D32: COL2 | E32: 0 | F32: Capacity Development Director* | G32: 1 | H32: =52500/12 -> 4375 | I32: 12 | J32: /months | K32: =I32*H32*G32 -> 52500 | L32: 0 | M32: =SUM(K32:L32) -> 52500 | N32: 1 | O32: =H32*$G$8 -> 4550 | P32: 12 | Q32: =O32*P32*N32 -> 54600 | R32: 0 | S32: =SUM(Q32:R32) -> 54600 | T32: 1 | U32: =H32*$G$8*$G$8 -> 4732 | V32: 12 | W32: =V32*U32*T32 -> 56784 | X32: 0 | Y32: =SUM(W32:X32) -> 56784 | Z32: 1 | AA32: =H32*$G$8*$G$8*$G$8 -> 4921.28 | AB32: 12 | AC32: =AB32*AA32*Z32 -> 59055.36 | AD32: 0 | AE32: =SUM(AC32:AD32) -> 59055.36 | AF32: 1 | AG32: =H32*$G$8*$G$8*$G$8*$G$8 -> 5118.1312 | AH32: 12 | AI32: =AH32*AG32*AF32 -> 61417.574 | AJ32: 0 | AK32: =SUM(AI32:AJ32) -> 61417.574 | AL32: =K32+Q32+W32+AC32+AI32 -> 284356.93 | AM32: =L32+R32+X32+AD32+AJ32 -> 0 | AN32: =SUM(AL32:AM32) -> 284356.93
A33: PERSNL-CDM | B33: 70000 | C33: COL2 | D33: COL2 | E33: 0 | F33: Capacity Development Manager | G33: 1 | H33: =38000/12 -> 3166.6667 | I33: 9 | J33: /months | K33: =I33*H33*G33 -> 28500 | L33: 0 | M33: =SUM(K33:L33) -> 28500 | N33: 1 | O33: =H33*$G$8 -> 3293.3333 | P33: 12 | Q33: =O33*P33*N33 -> 39520 | R33: 0 | S33: =SUM(Q33:R33) -> 39520 | T33: 1 | U33: =H33*$G$8*$G$8 -> 3425.0667 | V33: 12 | W33: =V33*U33*T33 -> 41100.8 | X33: 0 | Y33: =SUM(W33:X33) -> 41100.8 | Z33: 1 | AA33: =H33*$G$8*$G$8*$G$8 -> 3562.0693 | AB33: 12 | AC33: =AB33*AA33*Z33 -> 42744.832 | AD33: 0 | AE33: =SUM(AC33:AD33) -> 42744.832 | AF33: 1 | AG33: =H33*$G$8*$G$8*$G$8*$G$8 -> 3704.5521 | AH33: 9 | AI33: =AH33*AG33*AF33 -> 33340.969 | AJ33: 0 | AK33: =SUM(AI33:AJ33) -> 33340.969 | AL33: =K33+Q33+W33+AC33+AI33 -> 185206.6 | AM33: =L33+R33+X33+AD33+AJ33 -> 0 | AN33: =SUM(AL33:AM33) -> 185206.6
A34: PERSNL-RCN | B34: 70000 | C34: COL2 | D34: COL2 | E34: 0 | F34: Regional Coordinator Northern Coast | G34: 1 | H34: =22500/12 -> 1875 | I34: 6 | J34: /months | K34: =I34*H34*G34 -> 11250 | L34: 0 | M34: =SUM(K34:L34) -> 11250 | N34: 1 | O34: =H34*$G$8 -> 1950 | P34: 12 | Q34: =O34*P34*N34 -> 23400 | R34: 0 | S34: =SUM(Q34:R34) -> 23400 | T34: 1 | U34: =H34*$G$8*$G$8 -> 2028 | V34: 12 | W34: =V34*U34*T34 -> 24336 | X34: 0 | Y34: =SUM(W34:X34) -> 24336 | Z34: 1 | AA34: =H34*$G$8*$G$8*$G$8 -> 2109.12 | AB34: 12 | AC34: =AB34*AA34*Z34 -> 25309.44 | AD34: 0 | AE34: =SUM(AC34:AD34) -> 25309.44 | AF34: 1 | AG34: =H34*$G$8*$G$8*$G$8*$G$8 -> 2193.4848 | AH34: 9 | AI34: =AH34*AG34*AF34 -> 19741.363 | AJ34: 0 | AK34: =SUM(AI34:AJ34) -> 19741.363 | AL34: =K34+Q34+W34+AC34+AI34 -> 104036.8 | AM34: =L34+R34+X34+AD34+AJ34 -> 0 | AN34: =SUM(AL34:AM34) -> 104036.8
A35: PERSNL-RCC | B35: 70000 | C35: COL2 | D35: COL2 | E35: 0 | F35: Regional Coordinator Central Region | G35: 1 | H35: =22500/12 -> 1875 | I35: 6 | J35: /months | K35: =I35*H35*G35 -> 11250 | L35: 0 | M35: =SUM(K35:L35) -> 11250 | N35: 1 | O35: =H35*$G$8 -> 1950 | P35: 12 | Q35: =O35*P35*N35 -> 23400 | R35: 0 | S35: =SUM(Q35:R35) -> 23400 | T35: 1 | U35: =H35*$G$8*$G$8 -> 2028 | V35: 12 | W35: =V35*U35*T35 -> 24336 | X35: 0 | Y35: =SUM(W35:X35) -> 24336 | Z35: 1 | AA35: =H35*$G$8*$G$8*$G$8 -> 2109.12 | AB35: 12 | AC35: =AB35*AA35*Z35 -> 25309.44 | AD35: 0 | AE35: =SUM(AC35:AD35) -> 25309.44 | AF35: 1 | AG35: =H35*$G$8*$G$8*$G$8*$G$8 -> 2193.4848 | AH35: 9 | AI35: =AH35*AG35*AF35 -> 19741.363 | AJ35: 0 | AK35: =SUM(AI35:AJ35) -> 19741.363 | AL35: =K35+Q35+W35+AC35+AI35 -> 104036.8 | AM35: =L35+R35+X35+AD35+AJ35 -> 0 | AN35: =SUM(AL35:AM35) -> 104036.8
A36: PERSNL-RCW | B36: 70000 | C36: COL2 | D36: COL2 | E36: 0 | F36: Regional Coordinator Northwestern Region | G36: 1 | H36: =22500/12 -> 1875 | I36: 6 | J36: /months | K36: =I36*H36*G36 -> 11250 | L36: 0 | M36: =SUM(K36:L36) -> 11250 | N36: 1 | O36: =H36*$G$8 -> 1950 | P36: 12 | Q36: =O36*P36*N36 -> 23400 | R36: 0 | S36: =SUM(Q36:R36) -> 23400 | T36: 1 | U36: =H36*$G$8*$G$8 -> 2028 | V36: 12 | W36: =V36*U36*T36 -> 24336 | X36: 0 | Y36: =SUM(W36:X36) -> 24336 | Z36: 1 | AA36: =H36*$G$8*$G$8*$G$8 -> 2109.12 | AB36: 12 | AC36: =AB36*AA36*Z36 -> 25309.44 | AD36: 0 | AE36: =SUM(AC36:AD36) -> 25309.44 | AF36: 1 | AG36: =H36*$G$8*$G$8*$G$8*$G$8 -> 2193.4848 | AH36: 9 | AI36: =AH36*AG36*AF36 -> 19741.363 | AJ36: 0 | AK36: =SUM(AI36:AJ36) -> 19741.363 | AL36: =K36+Q36+W36+AC36+AI36 -> 104036.8 | AM36: =L36+R36+X36+AD36+AJ36 -> 0 | AN36: =SUM(AL36:AM36) -> 104036.8
F37: Subtotal Field Personnel | K37: =SUM(K23:K36) -> 585541.67 | L37: =SUM(L23:L36) -> 0 | M37: =SUM(M23:M36) -> 585541.67 | Q37: =SUM(Q23:Q36) -> 690560 | R37: =SUM(R23:R36) -> 0 | S37: =SUM(S23:S36) -> 690560 | W37: =SUM(W23:W36) -> 718182.4 | X37: =SUM(X23:X36) -> 0 | Y37: =SUM(Y23:Y36) -> 718182.4 | AC37: =SUM(AC23:AC36) -> 746909.7 | AD37: =SUM(AD23:AD36) -> 0 | AE37: =SUM(AE23:AE36) -> 746909.7 | AI37: =SUM(AI23:AI36) -> 718683.11 | AJ37: =SUM(AJ23:AJ36) -> 0 | AK37: =SUM(AK23:AK36) -> 718683.11 | AL37: =K37+Q37+W37+AC37+AI37 -> 3459876.9 | AM37: =L37+R37+X37+AD37+AJ37 -> 0 | AN37: =SUM(AL37:AM37) -> 3459876.9
F39: Personnel Total | K39: =K37+K20 -> 757570.27 | L39: =L37+L20 -> 0 | M39: =M37+M20 -> 757570.27 | Q39: =Q37+Q20 -> 869469.74 | R39: =R37+R20 -> 0 | S39: =S37+S20 -> 869469.74 | W39: =W37+W20 -> 904248.53 | X39: =X37+X20 -> 0 | Y39: =Y37+Y20 -> 904248.53 | AC39: =AC37+AC20 -> 940418.48 | AD39: =AD37+AD20 -> 0 | AE39: =AE37+AE20 -> 940418.48 | AI39: =AI37+AI20 -> 919932.24 | AJ39: =AJ37+AJ20 -> 0 | AK39: =AK37+AK20 -> 919932.24 | AL39: =AL37+AL20 -> 4391639.3 | AM39: =AM37+AM20 -> 0 | AN39: =AN37+AN20 -> 4391639.3
F41: Fringe Benefits
F42: HQ Fringe Benefits | G42: LOE
A43: FRINGE | B43: 50900 | C43: USA | D43: USA | E43: 0 | F43: Fringe Benefits - Headquarters | G43: 0.2181 | K43: =(K20+K23)*$G$43 -> 66962.938 | L43: 0 | M43: =SUM(K43:L43) -> 66962.938 | Q43: =(Q20+Q23)*$G$43 -> 69641.455 | R43: 0 | S43: =SUM(Q43:R43) -> 69641.455 | W43: =(W20+W23)*$G$43 -> 72427.113 | X43: 0 | Y43: =SUM(W43:X43) -> 72427.113 | AC43: =(AC20+AC23)*$G$43 -> 75324.198 | AD43: 0 | AE43: =SUM(AC43:AD43) -> 75324.198 | AI43: =(AI20+AI23)*$G$43 -> 78337.166 | AJ43: 0 | AK43: =SUM(AI43:AJ43) -> 78337.166 | AL43: =K43+Q43+W43+AC43+AI43 -> 362692.87 | AM43: =L43+R43+X43+AD43+AJ43 -> 0 | AN43: =SUM(AL43:AM43) -> 362692.87
F44: Subtotal HQ Fringe Benefits | K44: =SUM(K43) -> 66962.938 | L44: =SUM(L43) -> 0 | M44: =SUM(M43) -> 66962.938 | Q44: =SUM(Q43) -> 69641.455 | R44: =SUM(R43) -> 0 | S44: =SUM(S43) -> 69641.455 | W44: =SUM(W43) -> 72427.113 | X44: =SUM(X43) -> 0 | Y44: =SUM(Y43) -> 72427.113 | AC44: =SUM(AC43) -> 75324.198 | AD44: =SUM(AD43) -> 0 | AE44: =SUM(AE43) -> 75324.198 | AI44: =SUM(AI43) -> 78337.166 | AJ44: =SUM(AJ43) -> 0 | AK44: =SUM(AK43) -> 78337.166 | AL44: =SUM(AL43) -> 362692.87 | AM44: =SUM(AM43) -> 0 | AN44: =SUM(AN43) -> 362692.87
F46: Field Fringe Benefits
...

Sheet Budget Summary Parque Explora
B1: Name of Subawardee: Parque Explora
B2: USAID RFA No. 7200AA21RFA00001
B4: Year 1 | E4: Year 2 | H4: Year 3 | K4: Year 4 | N4: Year 5 | Q4: Total | R4: Total | S4: Grand
B5: USAID | C5: Leverage | D5: Total | E5: USAID | F5: Leverage | G5: Total | H5: USAID | I5: Leverage | J5: Total | K5: USAID | L5: Leverage | M5: Total | N5: USAID | O5: Leverage | P5: Total | Q5: USAID | R5: Leverage | S5: Total
A7: Personnel | B7: ='Budget Parque Explora'!L51 -> 290716.67 | C7: ='Budget Parque Explora'!M51 -> 67092.083 | D7: ='Budget Parque Explora'!N51 -> 357808.75 | E7: ='Budget Parque Explora'!R51 -> 560248 | F7: ='Budget Parque Explora'!S51 -> 48302.8 | G7: ='Budget Parque Explora'!T51 -> 608550.8 | H7: ='Budget Parque Explora'!X51 -> 582657.92 | I7: ='Budget Parque Explora'!Y51 -> 50234.912 | J7: ='Budget Parque Explora'!Z51 -> 632892.83 | K7: ='Budget Parque Explora'!AD51 -> 605964.24 | L7: ='Budget Parque Explora'!AE51 -> 52244.308 | M7: ='Budget Parque Explora'!AF51 -> 658208.55 | N7: ='Budget Parque Explora'!AJ51 -> 325522.89 | O7: ='Budget Parque Explora'!AK51 -> 54457.403 | P7: ='Budget Parque Explora'!AL51 -> 379980.3 | Q7: ='Budget Parque Explora'!AM51 -> 2365109.7 | R7: ='Budget Parque Explora'!AN51 -> 272331.51 | S7: ='Budget Parque Explora'!AO51 -> 2637441.2
A9: Fringe Benefits | B9: ='Budget Parque Explora'!L56 -> 130924.75 | C9: ='Budget Parque Explora'!M56 -> 32796.049 | D9: ='Budget Parque Explora'!N56 -> 163720.8 | E9: ='Budget Parque Explora'!R56 -> 243225.18 | F9: ='Budget Parque Explora'!S56 -> 22641.902 | G9: ='Budget Parque Explora'!T56 -> 265867.08 | H9: ='Budget Parque Explora'!X56 -> 252954.19 | I9: ='Budget Parque Explora'!Y56 -> 23547.578 | J9: ='Budget Parque Explora'!Z56 -> 276501.77 | K9: ='Budget Parque Explora'!AD56 -> 263072.36 | L9: ='Budget Parque Explora'!AE56 -> 24489.481 | M9: ='Budget Parque Explora'!AF56 -> 287561.84 | N9: ='Budget Parque Explora'!AJ56 -> 146280.36 | O9: ='Budget Parque Explora'!AK56 -> 26224.263 | P9: ='Budget Parque Explora'!AL56 -> 172504.63 | Q9: ='Budget Parque Explora'!AM56 -> 1036456.8 | R9: ='Budget Parque Explora'!AN56 -> 129699.27 | S9: ='Budget Parque Explora'!AO56 -> 1166156.1
A11: Travel | B11: ='Budget Parque Explora'!L121 -> 61740 | C11: ='Budget Parque Explora'!M121 -> 0 | D11: ='Budget Parque Explora'!N121 -> 61740 | E11: ='Budget Parque Explora'!R121 -> 122765.4 | F11: ='Budget Parque Explora'!S121 -> 0 | G11: ='Budget Parque Explora'!T121 -> 122765.4 | H11: ='Budget Parque Explora'!X121 -> 216148.93 | I11: ='Budget Parque Explora'!Y121 -> 0 | J11: ='Budget Parque Explora'!Z121 -> 216148.93 | K11: ='Budget Parque Explora'!AD121 -> 190494.37 | L11: ='Budget Parque Explora'!AE121 -> 0 | M11: ='Budget Parque Explora'!AF121 -> 190494.37 | N11: ='Budget Parque Explora'!AJ121 -> 68821.057 | O11: ='Budget Parque Explora'!AK121 -> 0 | P11: ='Budget Parque Explora'!AL121 -> 68821.057 | Q11: ='Budget Parque Explora'!AM121 -> 659969.76 | R11: ='Budget Parque Explora'!AN121 -> 0 | S11: ='Budget Parque Explora'!AO121 -> 659969.76
A13: Equipment | B13: ='Budget Parque Explora'!L127 -> 50000 | C13: ='Budget Parque Explora'!M127 -> 0 | D13: ='Budget Parque Explora'!N127 -> 50000 | E13: ='Budget Parque Explora'!R127 -> 0 | F13: ='Budget Parque Explora'!S127 -> 0 | G13: ='Budget Parque Explora'!T127 -> 0 | H13: ='Budget Parque Explora'!X127 -> 0 | I13: ='Budget Parque Explora'!Y127 -> 0 | J13: ='Budget Parque Explora'!Z127 -> 0 | K13: ='Budget Parque Explora'!AD127 -> 0 | L13: ='Budget Parque Explora'!AE127 -> 0 | M13: ='Budget Parque Explora'!AF127 -> 0 | N13: ='Budget Parque Explora'!AJ127 -> 0 | O13: ='Budget Parque Explora'!AK127 -> 0 | P13: ='Budget Parque Explora'!AL127 -> 0 | Q13: ='Budget Parque Explora'!AM127 -> 50000 | R13: ='Budget Parque Explora'!AN127 -> 0 | S13: ='Budget Parque Explora'!AO127 -> 50000
A15: Supplies | B15: ='Budget Parque Explora'!L142 -> 18439.9 | C15: ='Budget Parque Explora'!M142 -> 0 | D15: ='Budget Parque Explora'!N142 -> 18439.9 | E15: ='Budget Parque Explora'!R142 -> 21423.918 | F15: ='Budget Parque Explora'!S142 -> 0 | G15: ='Budget Parque Explora'!T142 -> 21423.918 | H15: ='Budget Parque Explora'!X142 -> 9548.1 | I15: ='Budget Parque Explora'!Y142 -> 0 | J15: ='Budget Parque Explora'!Z142 -> 9548.1 | K15: ='Budget Parque Explora'!AD142 -> 4917.2715 | L15: ='Budget Parque Explora'!AE142 -> 0 | M15: ='Budget Parque Explora'!AF142 -> 4917.2715 | N15: ='Budget Parque Explora'!AJ142 -> 3798.5922 | O15: ='Budget Parque Explora'!AK142 -> 0 | P15: ='Budget Parque Explora'!AL142 -> 3798.5922 | Q15: ='Budget Parque Explora'!AM142 -> 58127.781 | R15: ='Budget Parque Explora'!AN142 -> 0 | S15: ='Budget Parque Explora'!AO142 -> 58127.781
A17: Contractual | B17: ='Budget Parque Explora'!L154 -> 204200 | C17: ='Budget Parque Explora'!M154 -> 0 | D17: ='Budget Parque Explora'!N154 -> 204200 | E17: ='Budget Parque Explora'!R154 -> 208400 | F17: ='Budget Parque Explora'!S154 -> 0 | G17: ='Budget Parque Explora'!T154 -> 208400 | H17: ='Budget Parque Explora'!X154 -> 208400 | I17: ='Budget Parque Explora'!Y154 -> 0 | J17: ='Budget Parque Explora'!Z154 -> 208400 | K17: ='Budget Parque Explora'!AD154 -> 208400 | L17: ='Budget Parque Explora'!AE154 -> 0 | M17: ='Budget Parque Explora'!AF154 -> 208400 | N17: ='Budget Parque Explora'!AJ154 -> 206300 | O17: ='Budget Parque Explora'!AK154 -> 0 | P17: ='Budget Parque Explora'!AL154 -> 206300 | Q17: ='Budget Parque Explora'!AM154 -> 1035700 | R17: ='Budget Parque Explora'!AN154 -> 0 | S17: ='Budget Parque Explora'!AO154 -> 1035700
A19: Other Direct Costs | B19: ='Budget Parque Explora'!L203 -> 122135.9 | C19: ='Budget Parque Explora'!M203 -> 0 | D19: ='Budget Parque Explora'!N203 -> 122135.9 | E19: ='Budget Parque Explora'!R203 -> 76503.2 | F19: ='Budget Parque Explora'!S203 -> 0 | G19: ='Budget Parque Explora'!T203 -> 76503.2 | H19: ='Budget Parque Explora'!X203 -> 406653.84 | I19: ='Budget Parque Explora'!Y203 -> 0 | J19: ='Budget Parque Explora'!Z203 -> 406653.84 | K19: ='Budget Parque Explora'!AD203 -> 419001.66 | L19: ='Budget Parque Explora'!AE203 -> 0 | M19: ='Budget Parque Explora'!AF203 -> 419001.66 | N19: ='Budget Parque Explora'!AJ203 -> 64324.394 | O19: ='Budget Parque Explora'!AK203 -> 0 | P19: ='Budget Parque Explora'!AL203 -> 64324.394 | Q19: ='Budget Parque Explora'!AM203 -> 1088619 | R19: ='Budget Parque Explora'!AN203 -> 0 | S19: ='Budget Parque Explora'!AO203 -> 1088619
A21: Total Direct Costs | B21: =SUM(B7:B20) -> 878157.22 | C21: =SUM(C7:C20) -> 99888.132 | D21: =SUM(D7:D20) -> 978045.35 | E21: =SUM(E7:E20) -> 1232565.7 | F21: =SUM(F7:F20) -> 70944.702 | G21: =SUM(G7:G20) -> 1303510.4 | H21: =SUM(H7:H20) -> 1676363 | I21: =SUM(I7:I20) -> 73782.49 | ... S21: =SUM(S7:S20) -> 6696013.9
A22: Indirect Costs | B22: ='Budget Parque Explora'!L206 -> 62815.722 | C22: ='Budget Parque Explora'!M206 -> 9988.8132 | D22: ='Budget Parque Explora'!N206 -> 72804.535 | E22: ='Budget Parque Explora'!R206 -> 103256.57 | F22: ='Budget Parque Explora'!S206 -> 7094.4702 | G22: ='Budget Parque Explora'!T206 -> 110351.04 | H22: ='Budget Parque Explora'!X206 -> 147636.3 | I22: ='Budget Parque Explora'!Y206 -> 7378.249 | J22: ='Budget Parque Explora'!Z206 -> 155014.55 | K22: ='Budget Parque Explora'!AD206 -> 149184.99 | L22: ='Budget Parque Explora'!AE206 -> 7673.379 | M22: ='Budget Parque Explora'!AF206 -> 156858.37 | N22: ='Budget Parque Explora'!AJ206 -> 61504.73 | O22: ='Budget Parque Explora'!AK206 -> 8068.1667 | P22: ='Budget Parque Explora'!AL206 -> 69572.897 | Q22: ='Budget Parque Explora'!AM206 -> 524398.31 | R22: ='Budget Parque Explora'!AN206 -> 40203.078 | S22: ='Budget Parque Explora'!AO206 -> 564601.39
A23: Total | B23: =B22+B21 -> 940972.94 | C23: =C22+C21 -> 109876.95 | D23: =D22+D21 -> 1050849.9 | E23: =E22+E21 -> 1335822.3 | F23: =F22+F21 -> 78039.172 | G23: =G22+G21 -> 1413861.4 | H23: =H22+H21 -> 1823999.3 | I23: =I22+I21 -> 81160.739 | ... S23: =S22+S21 -> 7260615.3

Sheet Budget Parque Explora
H1: USAID Juntos Aprendemos
H2: Parque Explora
H3: Subaward Budget
A4: Entity: | B4: P | H4: Country: Colombia
A5: Program-Dept.: | B5: 20300 | G5: Budget Assumptions
A6: Funder-Grant: | B6: USAID800 | G6: Inflation - Locally Purchased Goods/Services - 3% | H6: 1.03
G7: Merit Based Increases for HQ & Field Staff - 4% | H7: 1.04
G9: *Key Personnel
A10: Sage Activity | B10: Sage Object Code/ Line Item | C10: Country Code (DC=0 or CO) | D10: Office Code (DC=0 or CO) | E10: Subcontract Code | F10: Open 1 Code | L10: Year 1 | R10: Year 2 | U10: Year 3 | AD10: Year 4 | AJ10: Year 5 | AM10: Total | AN10: Total | AO10: Grand
H11: Unit | I11: Cost | J11: Duration | K11: Type | L11: USAID | M11: Leverage | N11: Total | O11: Unit | P11: Cost | Q11: Duration | R11: USAID | S11: Leverage | T11: Total | U11: Unit | V11: Cost | W11: Duration | X11: USAID | Y11: Leverage | Z11: Total | AA11: Unit | AB11: Cost | AC11: Duration | AD11: USAID | AE11: Leverage | AF11: Total | AG11: Unit | AH11: Cost | AI11: Duration | AJ11: USAID | AK11: Leverage | AL11: Total | AM11: USAID | AN11: Leverage | AO11: Total
G13: Personnel
G14: Headquarters Personnel | H14: LOE
G15: Project Office (Bogota)
A16: SUBEXPLORA | B16: 89050 | C16: COL2 | D16: COL2 | E16: EXPLORA | F16: EXPPERSNL | G16: Community Engagement and Outreach Director* | H16: 1 | I16: =52500/12 -> 4375 | J16: 11 | K16: /months | L16: =J16*I16*H16 -> 48125 | M16: 0 | N16: =SUM(L16:M16) -> 48125 | O16: =H16 -> 1 | P16: =I16*$H$7 -> 4550 | Q16: 12 | R16: =O16*P16*Q16 -> 54600 | S16: 0 | T16: =SUM(R16:S16) -> 54600 | U16: =H16 -> 1 | V16: =I16*$H$7*$H$7 -> 4732 | W16: 12 | X16: =U16*V16*W16 -> 56784 | Y16: 0 | Z16: =SUM(X16:Y16) -> 56784 | AA16: =U16 -> 1 | AB16: =I16*$H$7*$H$7*$H$7 -> 4921.28 | AC16: 12 | AD16: =AA16*AB16*AC16 -> 59055.36 | AE16: 0 | AF16: =SUM(AD16:AE16) -> 59055.36 | AG16: =AA16 -> 1 | AH16: =I16*$H$7*$H$7*$H$7*$H$7 -> 5118.1312 | AI16: 11 | AJ16: =AG16*AH16*AI16 -> 56299.443 | AK16: 0 | AL16: =SUM(AJ16:AK16) -> 56299.443 | AM16: =L16+R16+X16+AD16+AJ16 -> 274863.8 | AN16: =M16+S16+Y16+AE16+AK16 -> 0 | AO16: =SUM(AM16:AN16) -> 274863.8
A17: SUBEXPLORA | B17: 89050 | C17: COL2 | D17: COL2 | E17: EXPLORA | F17: EXPPERSNL | G17: Community Engagement and Outreach Manager | H17: 1 | I17: =38000/12 -> 3166.6667 | J17: 10 | K17: /months | L17: =J17*I17*H17 -> 31666.667 | M17: 0 | N17: =SUM(L17:M17) -> 31666.667 | O17: 1 | P17: =I17*$H$7 -> 3293.3333 | Q17: 12 | R17: =P17*Q17*O17 -> 39520 | S17: 0 | T17: =SUM(R17:S17) -> 39520 | U17: 1 | V17: =I17*$H$7*$H$7 -> 3425.0667 | W17: 12 | X17: =W17*V17*U17 -> 41100.8 | Y17: 0 | Z17: =SUM(X17:Y17) -> 41100.8 | AA17: 1 | AB17: =I17*$H$7*$H$7*$H$7 -> 3562.0693 | AC17: 12 | AD17: =AC17*AB17*AA17 -> 42744.832 | AE17: 0 | AF17: =SUM(AD17:AE17) -> 42744.832 | AG17: 1 | AH17: =I17*$H$7*$H$7*$H$7*$H$7 -> 3704.5521 | AI17: 8 | AJ17: =AI17*AH17*AG17 -> 29636.417 | AK17: 0 | AL17: =SUM(AJ17:AK17) -> 29636.417 | AM17: =L17+R17+X17+AD17+AJ17 -> 184668.72 | AN17: =M17+S17+Y17+AE17+AK17 -> 0 | AO17: =SUM(AM17:AN17) -> 184668.72
G18: Parque Explora Office (Medellin)
A19: SUBEXPLORA | B19: 89050 | C19: COL2 | D19: COL2 | E19: EXPLORA | F19: EXPPERSNL | G19: School Research Coordinator | H19: 1 | I19: =22500/12 -> 1875 | J19: 10 | K19: /months | L19: =J19*I19*H19 -> 18750 | M19: 0 | N19: =SUM(L19:M19) -> 18750 | O19: 1 | P19: =I19*$H$7 -> 1950 | Q19: 12 | R19: =P19*Q19*O19 -> 23400 | S19: 0 | T19: =SUM(R19:S19) -> 23400 | U19: 1 | V19: =I19*$H$7*$H$7 -> 2028 | W19: 12 | X19: =W19*V19*U19 -> 24336 | Y19: 0 | Z19: =SUM(X19:Y19) -> 24336 | AA19: 1 | AB19: =I19*$H$7*$H$7*$H$7 -> 2109.12 | AC19: 12 | AD19: =AC19*AB19*AA19 -> 25309.44 | AE19: 0 | AF19: =SUM(AD19:AE19) -> 25309.44 | AG19: 1 | AH19: =I19*$H$7*$H$7*$H$7*$H$7 -> 2193.4848 | AI19: 8 | AJ19: =AI19*AH19*AG19 -> 17547.878 | AK19: 0 | AL19: =SUM(AJ19:AK19) -> 17547.878 | AM19: =L19+R19+X19+AD19+AJ19 -> 109343.32 | AN19: =M19+S19+Y19+AE19+AK19 -> 0 | AO19: =SUM(AM19:AN19) -> 109343.32
A20: SUBEXPLORA | B20: 89050 | C20: COL2 | D20: COL2 | E20: EXPLORA | F20: EXPPERSNL | G20: Pedagogical Coordinator | H20: 1 | I20: =22500/12 -> 1875 | J20: 10 | K20: /months | L20: =J20*I20*H20 -> 18750 | M20: 0 | N20: =SUM(L20:M20) -> 18750 | O20: 1 | P20: =I20*$H$7 -> 1950 | Q20: 12 | R20: =P20*Q20*O20 -> 23400 | S20: 0 | T20: =SUM(R20:S20) -> 23400 | U20: 1 | V20: =I20*$H$7*$H$7 -> 2028 | W20: 12 | X20: =W20*V20*U20 -> 24336 | Y20: 0 | Z20: =SUM(X20:Y20) -> 24336 | AA20: 1 | AB20: =I20*$H$7*$H$7*$H$7 -> 2109.12 | AC20: 12 | AD20: =AC20*AB20*AA20 -> 25309.44 | AE20: 0 | AF20: =SUM(AD20:AE20) -> 25309.44 | AG20: 1 | AH20: =I20*$H$7*$H$7*$H$7*$H$7 -> 2193.4848 | AI20: 8 | AJ20: =AI20*AH20*AG20 -> 17547.878 | AK20: 0 | AL20: =SUM(AJ20:AK20) -> 17547.878 | AM20: =L20+R20+X20+AD20+AJ20 -> 109343.32 | AN20: =M20+S20+Y20+AE20+AK20 -> 0 | AO20: =SUM(AM20:AN20) -> 109343.32
A21: SUBEXPLORA | B21: 89050 | C21: COL2 | D21: COL2 | E21: EXPLORA | F21: EXPPERSNL | G21: Clubes Explora Coordinator | H21: 1 | I21: =22500/12 -> 1875 | J21: 10 | K21: /months | L21: =J21*I21*H21 -> 18750 | M21: 0 | N21: =SUM(L21:M21) -> 18750 | O21: 1 | P21: =I21*$H$7 -> 1950 | Q21: 12 | R21: =P21*Q21*O21 -> 23400 | S21: 0 | T21: =SUM(R21:S21) -> 23400 | U21: 1 | V21: =I21*$H$7*$H$7 -> 2028 | W21: 12 | X21: =W21*V21*U21 -> 24336 | Y21: 0 | Z21: =SUM(X21:Y21) -> 24336 | AA21: 1 | AB21: =I21*$H$7*$H$7*$H$7 -> 2109.12 | AC21: 12 | AD21: =AC21*AB21*AA21 -> 25309.44 | AE21: 0 | AF21: =SUM(AD21:AE21) -> 25309.44 | AG21: 1 | AH21: =I21*$H$7*$H$7*$H$7*$H$7 -> 2193.4848 | AI21: 8 | AJ21: =AI21*AH21*AG21 -> 17547.878 | AK21: 0 | AL21: =SUM(AJ21:AK21) -> 17547.878 | AM21: =L21+R21+X21+AD21+AJ21 -> 109343.32 | AN21: =M21+S21+Y21+AE21+AK21 -> 0 | AO21: =SUM(AM21:AN21) -> 109343.32
A22: SUBEXPLORA | B22: 89050 | C22: COL2 | D22: COL2 | E22: EXPLORA | F22: EXPPERSNL | G22: Clubes Explora Content Professional | H22: 1 | I22: =15000/12 -> 1250 | J22: 10 | K22: /months | L22: =J22*I22*H22 -> 12500 | M22: 0 | N22: =SUM(L22:M22) -> 12500 | O22: 1 | P22: =I22*$H$7 -> 1300 | Q22: 12 | R22: =P22*Q22*O22 -> 15600 | S22: 0 | T22: =SUM(R22:S22) -> 15600 | U22: 1 | V22: =I22*$H$7*$H$7 -> 1352 | W22: 12 | X22: =W22*V22*U22 -> 16224 | Y22: 0 | Z22: =SUM(X22:Y22) -> 16224 | AA22: 1 | AB22: =I22*$H$7*$H$7*$H$7 -> 1406.08 | AC22: 12 | AD22: =AC22*AB22*AA22 -> 16872.96 | AE22: 0 | AF22: =SUM(AD22:AE22) -> 16872.96 | AG22: 1 | AH22: =I22*$H$7*$H$7*$H$7*$H$7 -> 1462.3232 | AI22: 8 | AJ22: =AI22*AH22*AG22 -> 11698.586 | AK22: 0 | AL22: =SUM(AJ22:AK22) -> 11698.586 | AM22: =L22+R22+X22+AD22+AJ22 -> 72895.546 | AN22: =M22+S22+Y22+AE22+AK22 -> 0 | AO22: =SUM(AM22:AN22) -> 72895.546
A23: SUBEXPLORA | B23: 89050 | C23: COL2 | D23: COL2 | E23: EXPLORA | F23: EXPPERSNL | G23: School Research Professional | H23: 1 | I23: =15000/12 -> 1250 | J23: 10 | K23: /months | L23: =J23*I23*H23 -> 12500 | M23: 0 | N23: =SUM(L23:M23) -> 12500 | O23: 1 | P23: =I23*$H$7 -> 1300 | Q23: 12 | R23: =P23*Q23*O23 -> 15600 | S23: 0 | T23: =SUM(R23:S23) -> 15600 | U23: 1 | V23: =I23*$H$7*$H$7 -> 1352 | W23: 12 | X23: =W23*V23*U23 -> 16224 | Y23: 0 | Z23: =SUM(X23:Y23) -> 16224 | AA23: 1 | AB23: =I23*$H$7*$H$7*$H$7 -> 1406.08 | AC23: 12 | AD23: =AC23*AB23*AA23 -> 16872.96 | AE23: 0 | AF23: =SUM(AD23:AE23) -> 16872.96 | AG23: 1 | AH23: =I23*$H$7*$H$7*$H$7*$H$7 -> 1462.3232 | AI23: 8 | AJ23: =AI23*AH23*AG23 -> 11698.586 | AK23: 0 | AL23: =SUM(AJ23:AK23) -> 11698.586 | AM23: =L23+R23+X23+AD23+AJ23 -> 72895.546 | AN23: =M23+S23+Y23+AE23+AK23 -> 0 | AO23: =SUM(AM23:AN23) -> 72895.546
A24: SUBEXPLORA | B24: 89050 | C24: COL2 | D24: COL2 | E24: EXPLORA | F24: EXPPERSNL | G24: Monitoring and Evaluation Specialist | H24: 1 | I24: =31200/12 -> 2600 | J24: 8 | K24: /months | L24: =J24*I24*H24 -> 20800 | M24: 0 | N24: =SUM(L24:M24) -> 20800 | O24: 1 | P24: =I24*$H$7 -> 2704 | Q24: 12 | R24: =P24*Q24*O24 -> 32448 | S24: 0 | T24: =SUM(R24:S24) -> 32448 | U24: 1 | V24: =I24*$H$7*$H$7 -> 2812.16 | W24: 12 | X24: =W24*V24*U24 -> 33745.92 | Y24: 0 | Z24: =SUM(X24:Y24) -> 33745.92 | AA24: 1 | AB24: =I24*$H$7*$H$7*$H$7 -> 2924.6464 | AC24: 12 | AD24: =AC24*AB24*AA24 -> 35095.757 | AE24: 0 | AF24: =SUM(AD24:AE24) -> 35095.757 | AG24: 1 | AH24: =I24*$H$7*$H$7*$H$7*$H$7 -> 3041.6323 | AI24: 8 | AJ24: =AI24*AH24*AG24 -> 24333.058 | AK24: 0 | AL24: =SUM(AJ24:AK24) -> 24333.058 | AM24: =L24+R24+X24+AD24+AJ24 -> 146422.73 | AN24: =M24+S24+Y24+AE24+AK24 -> 0 | AO24: =SUM(AM24:AN24) -> 146422.73
A25: SUBEXPLORA | B25: 89050 | C25: COL2 | D25: COL2 | E25: EXPLORA | F25: EXPPERSNL | G25: Communication and Graphic Design Professional | H25: 1 | I25: =15000/12 -> 1250 | J25: 6 | K25: /months | L25: =J25*I25*H25 -> 7500 | M25: 0 | N25: =SUM(L25:M25) -> 7500 | O25: 1 | P25: =I25*$H$7 -> 1300 | Q25: 12 | R25: =P25*Q25*O25 -> 15600 | S25: 0 | T25: =SUM(R25:S25) -> 15600 | U25: 1 | V25: =I25*$H$7*$H$7 -> 1352 | W25: 12 | X25: =W25*V25*U25 -> 16224 | Y25: 0 | Z25: =SUM(X25:Y25) -> 16224 | AA25: 1 | AB25: =I25*$H$7*$H$7*$H$7 -> 1406.08 | AC25: 12 | AD25: =AC25*AB25*AA25 -> 16872.96 | AE25: 0 | AF25: =SUM(AD25:AE25) -> 16872.96 | AG25: 1 | AH25: =I25*$H$7*$H$7*$H$7*$H$7 -> 1462.3232 | AI25: 8 | AJ25: =AI25*AH25*AG25 -> 11698.586 | AK25: 0 | AL25: =SUM(AJ25:AK25) -> 11698.586 | AM25: =L25+R25+X25+AD25+AJ25 -> 67895.546 | AN25: =M25+S25+Y25+AE25+AK25 -> 0 | AO25: =SUM(AM25:AN25) -> 67895.546
A26: SUBEXPLORA | B26: 89050 | C26: COL2 | D26: COL2 | E26: EXPLORA | F26: EXPPERSNL | G26: Grants & Compliance Coordinator | H26: 1 | I26: =22500/12 -> 1875 | J26: 3 | K26: /months | L26: =J26*I26*H26 -> 5625 | M26: 0 | N26: =SUM(L26:M26) -> 5625 | O26: 1 | P26: =I26*$H$7 -> 1950 | Q26: 12 | R26: =P26*Q26*O26 -> 23400 | S26: 0 | T26: =SUM(R26:S26) -> 23400 | U26: 1 | V26: =I26*$H$7*$H$7 -> 2028 | W26: 12 | X26: =W26*V26*U26 -> 24336 | Y26: 0 | Z26: =SUM(X26:Y26) -> 24336 | AA26: 1 | AB26: =I26*$H$7*$H$7*$H$7 -> 2109.12 | AC26: 12 | AD26: =AC26*AB26*AA26 -> 25309.44 | AE26: 0 | AF26: =SUM(AD26:AE26) -> 25309.44 | AG26: 1 | AH26: =I26*$H$7*$H$7*$H$7*$H$7 -> 2193.4848 | AI26: 8 | AJ26: =AI26*AH26*AG26 -> 17547.878 | AK26: 0 | AL26: =SUM(AJ26:AK26) -> 17547.878 | AM26: =L26+R26+X26+AD26+AJ26 -> 96218.318 | AN26: =M26+S26+Y26+AE26+AK26 -> 0 | AO26: =SUM(AM26:AN26) -> 96218.318
A27: SUBEXPLORA | B27: 89050 | C27: COL2 | D27: COL2 | E27: EXPLORA | F27: EXPPERSNL | G27: Finance & Admin Coordinator (2) | H27: 1 | I27: =(22500/12)*2 -> 3750 | J27: 9 | K27: /months | L27: =J27*I27*H27 -> 33750 | M27: 0 | N27: =SUM(L27:M27) -> 33750 | O27: 1 | P27: =I27*$H$7 -> 3900 | Q27: 12 | R27: =P27*Q27*O27 -> 46800 | S27: 0 | T27: =SUM(R27:S27) -> 46800 | U27: 1 | V27: =I27*$H$7*$H$7 -> 4056 | W27: 12 | X27: =W27*V27*U27 -> 48672 | Y27: 0 | Z27: =SUM(X27:Y27) -> 48672 | AA27: 1 | AB27: =I27*$H$7*$H$7*$H$7 -> 4218.24 | AC27: 12 | AD27: =AC27*AB27*AA27 -> 50618.88 | AE27: 0 | AF27: =SUM(AD27:AE27) -> 50618.88 | AG27: 1 | AH27: =I27*$H$7*$H$7*$H$7*$H$7 -> 4386.9696 | AI27: 8 | AJ27: =AI27*AH27*AG27 -> 35095.757 | AK27: 0 | AL27: =SUM(AJ27:AK27) -> 35095.757 | AM27: =L27+R27+X27+AD27+AJ27 -> 214936.64 | AN27: =M27+S27+Y27+AE27+AK27 -> 0 | AO27: =SUM(AM27:AN27) -> 214936.64
A28: SUBEXPLORA | B28: 89050 | C28: COL2 | D28: COL2 | E28: EXPLORA | F28: EXPERSNLEV | G28: Executive Director | H28: 0.05 | I28: =64000/12 -> 5333.3333 | J28: 11 | K28: /months | L28: 0 | M28: =J28*I28*H28 -> 2933.3333 | N28: =SUM(L28:M28) -> 2933.3333 | O28: 0.05 | P28: =I28*$H$7 -> 5546.6667 | Q28: 12 | R28: 0 | S28: =P28*O28*Q28 -> 3328 | T28: =SUM(R28:S28) -> 3328 | U28: 0.05 | V28: =I28*$H$7*$H$7 -> 5768.5333 | W28: 12 | X28: 0 | Y28: =V28*U28*W28 -> 3461.12 | Z28: =SUM(X28:Y28) -> 3461.12 | AA28: 0.05 | AB28: =I28*$H$7*$H$7*$H$7 -> 5999.2747 | AC28: 12 | AD28: 0 | AE28: =AB28*AA28*AC28 -> 3599.5648 | AF28: =SUM(AD28:AE28) -> 3599.5648 | AG28: 0.05 | AH28: =I28*$H$7*$H$7*$H$7*$H$7 -> 6239.2457 | AI28: 10 | AJ28: 0 | AK28: =AH28*AG28*AI28 -> 3119.6228 | AL28: =SUM(AJ28:AK28) -> 3119.6228 | AM28: =L28+R28+X28+AD28+AJ28 -> 0 | AN28: =M28+S28+Y28+AE28+AK28 -> 16441.641 | AO28: =SUM(AM28:AN28) -> 16441.641
A29: SUBEXPLORA | B29: 89050 | C29: COL2 | D29: COL2 | E29: EXPLORA | F29: EXPERSNLEV | G29: Financial Director | H29: 0.2 | I29: =48000/12 -> 4000 | J29: 11 | K29: /months | L29: 0 | M29: =J29*I29*H29 -> 8800 | N29: =SUM(L29:M29) -> 8800 | O29: 0.1 | P29: =I29*$H$7 -> 4160 | Q29: 12 | R29: 0 | S29: =P29*O29*Q29 -> 4992 | T29: =SUM(R29:S29) -> 4992 | U29: 0.1 | V29: =I29*$H$7*$H$7 -> 4326.4 | W29: 12 | X29: 0 | Y29: =V29*U29*W29 -> 5191.68 | Z29: =SUM(X29:Y29) -> 5191.68 | AA29: 0.1 | AB29: =I29*$H$7*$H$7*$H$7 -> 4499.456 | AC29: 12 | AD29: 0 | AE29: =AB29*AA29*AC29 -> 5399.3472 | AF29: =SUM(AD29:AE29) -> 5399.3472 | AG29: 0.2 | AH29: =I29*$H$7*$H$7*$H$7*$H$7 -> 4679.4342 | AI29: 12 | AJ29: 0 | AK29: =AH29*AG29*AI29 -> 11230.642 | AL29: =SUM(AJ29:AK29) -> 11230.642 | AM29: =L29+R29+X29+AD29+AJ29 -> 0 | AN29: =M29+S29+Y29+AE29+AK29 -> 35613.669 | AO29: =SUM(AM29:AN29) -> 35613.669
A30: SUBEXPLORA | B30: 89050 | C30: COL2 | D30: COL2 | E30: EXPLORA | F30: EXPERSNLEV | G30: Content Director | H30: 0.2 | I30: =48000/12 -> 4000 | J30: 9 | K30: /months | L30: 0 | M30: =J30*I30*H30 -> 7200 | N30: =SUM(L30:M30) -> 7200 | O30: 0.05 | P30: =I30*$H$7 -> 4160 | Q30: 12 | R30: 0 | S30: =P30*O30*Q30 -> 2496 | T30: =SUM(R30:S30) -> 2496 | U30: 0.05 | V30: =I30*$H$7*$H$7 -> 4326.4 | W30: 12 | X30: 0 | Y30: =V30*U30*W30 -> 2595.84 | Z30: =SUM(X30:Y30) -> 2595.84 | AA30: 0.05 | AB30: =I30*$H$7*$H$7*$H$7 -> 4499.456 | AC30: 12 | AD30: 0 | AE30: =AB30*AA30*AC30 -> 2699.6736 | AF30: =SUM(AD30:AE30) -> 2699.6736 | AG30: 0.1 | AH30: =I30*$H$7*$H$7*$H$7*$H$7 -> 4679.4342 | AI30: 8 | AJ30: 0 | AK30: =AH30*AG30*AI30 -> 3743.5474 | AL30: =SUM(AJ30:AK30) -> 3743.5474 | AM30: =L30+R30+X30+AD30+AJ30 -> 0 | AN30: =M30+S30+Y30+AE30+AK30 -> 18735.061 | AO30: =SUM(AM30:AN30) -> 18735.061
A31: SUBEXPLORA | B31: 89050 | C31: COL2 | D31: COL2 | E31: EXPLORA | F31: EXPERSNLEV | G31: Head of Content | H31: 0.2 | I31: 2000 | J31: 9 | K31: /months | L31: 0 | M31: =J31*I31*H31 -> 3600 | N31: =SUM(L31:M31) -> 3600 | O31: 0.05 | P31: =I31*$H$7 -> 2080 | Q31: 12 | R31: 0 | S31: =P31*O31*Q31 -> 1248 | T31: =SUM(R31:S31) -> 1248 | U31: 0.05 | V31: =I31*$H$7*$H$7 -> 2163.2 | W31: 12 | X31: 0 | Y31: =V31*U31*W31 -> 1297.92 | Z31: =SUM(X31:Y31) -> 1297.92 | AA31: 0.05 | AB31: =I31*$H$7*$H$7*$H$7 -> 2249.728 | AC31: 12 | AD31: 0 | AE31: =AB31*AA31*AC31 -> 1349.8368 | AF31: =SUM(AD31:AE31) -> 1349.8368 | AG31: 0.1 | AH31: =I31*$H$7*$H$7*$H$7*$H$7 -> 2339.7171 | AI31: 8 | AJ31: 0 | AK31: =AH31*AG31*AI31 -> 1871.7737 | AL31: =SUM(AJ31:AK31) -> 1871.7737 | AM31: =L31+R31+X31+AD31+AJ31 -> 0 | AN31: =M31+S31+Y31+AE31+AK31 -> 9367.5305 | AO31: =SUM(AM31:AN31) -> 9367.5305
A32: SUBEXPLORA | B32: 89050 | C32: COL2 | D32: COL2 | E32: EXPLORA | F32: EXPERSNLEV | G32: Director of Communications | H32: 0.2 | I32: =48000/12 -> 4000 | J32: 9 | K32: /months | L32: 0 | M32: =J32*I32*H32 -> 7200 | N32: =SUM(L32:M32) -> 7200 | O32: 0.05 | P32: =I32*$H$7 -> 4160 | Q32: 12 | R32: 0 | S32: =P32*O32*Q32 -> 2496 | T32: =SUM(R32:S32) -> 2496 | U32: 0.05 | V32: =I32*$H$7*$H$7 -> 4326.4 | W32: 12 | X32: 0 | Y32: =V32*U32*W32 -> 2595.84 | Z32: =SUM(X32:Y32) -> 2595.84 | AA32: 0.05 | AB32: =I32*$H$7*$H$7*$H$7 -> 4499.456 | AC32: 12 | AD32: 0 | AE32: =AB32*AA32*AC32 -> 2699.6736 | AF32: =SUM(AD32:AE32) -> 2699.6736 | AG32: 0.05 | AH32: =I32*$H$7*$H$7*$H$7*$H$7 -> 4679.4342 | AI32: 8 | AJ32: 0 | AK32: =AH32*AG32*AI32 -> 1871.7737 | AL32: =SUM(AJ32:AK32) -> 1871.7737 | AM32: =L32+R32+X32+AD32+AJ32 -> 0 | AN32: =M32+S32+Y32+AE32+AK32 -> 16863.287 | AO32: =SUM(AM32:AN32) -> 16863.287
A33: SUBEXPLORA | B33: 89050 | C33: COL2 | D33: COL2 | E33: EXPLORA | F33: EXPERSNLEV | G33: Director of Education | H33: 0.2 | I33: =48000/12 -> 4000 | J33: 10 | K33: /months | L33: 0 | M33: =J33*I33*H33 -> 8000 | N33: =SUM(L33:M33) -> 8000 | O33: 0.1 | P33: =I33*$H$7 -> 4160 | Q33: 12 | R33: 0 | S33: =P33*O33*Q33 -> 4992 | T33: =SUM(R33:S33) -> 4992 | U33: 0.1 | V33: =I33*$H$7*$H$7 -> 4326.4 | W33: 12 | X33: 0 | Y33: =V33*U33*W33 -> 5191.68 | Z33: =SUM(X33:Y33) -> 5191.68 | AA33: 0.1 | AB33: =I33*$H$7*$H$7*$H$7 -> 4499.456 | AC33: 12 | AD33: 0 | AE33: =AB33*AA33*AC33 -> 5399.3472 | AF33: =SUM(AD33:AE33) -> 5399.3472 | AG33: 0.2 | AH33: =I33*$H$7*$H$7*$H$7*$H$7 -> 4679.4342 | AI33: 8 | AJ33: 0 | AK33: =AH33*AG33*AI33 -> 7487.0948 | AL33: =SUM(AJ33:AK33) -> 7487.0948 | AM33: =L33+R33+X33+AD33+AJ33 -> 0 | AN33: =M33+S33+Y33+AE33+AK33 -> 31070.122 | AO33: =SUM(AM33:AN33) -> 31070.122
A34: SUBEXPLORA | B34: 89050 | C34: COL2 | D34: COL2 | E34: EXPLORA | F34: EXPERSNLEV | G34: Head of Education | H34: 0.3 | I34: 2000 | J34: 10 | K34: /months | L34: 0 | M34: =J34*I34*H34 -> 6000 | N34: =SUM(L34:M34) -> 6000 | O34: 0.15 | P34: =I34*$H$7 -> 2080 | Q34: 12 | R34: 0 | S34: =P34*O34*Q34 -> 3744 | T34: =SUM(R34:S34) -> 3744 | U34: 0.15 | V34: =I34*$H$7*$H$7 -> 2163.2 | W34: 12 | X34: 0 | Y34: =V34*U34*W34 -> 3893.76 | Z34: =SUM(X34:Y34) -> 3893.76 | AA34: 0.15 | AB34: =I34*$H$7*$H$7*$H$7 -> 2249.728 | AC34: 12 | AD34: 0 | AE34: =AB34*AA34*AC34 -> 4049.5104 | AF34: =SUM(AD34:AE34) -> 4049.5104 | AG34: 0.2 | AH34: =I34*$H$7*$H$7*$H$7*$H$7 -> 2339.7171 | AI34: 9 | AJ34: 0 | AK34: =AH34*AG34*AI34 -> 4211.4908 | AL34: =SUM(AJ34:AK34) -> 4211.4908 | AM34: =L34+R34+X34+AD34+AJ34 -> 0 | AN34: =M34+S34+Y34+AE34+AK34 -> 21898.761 | AO34: =SUM(AM34:AN34) -> 21898.761
A35: SUBEXPLORA | B35: 89050 | C35: COL2 | D35: COL2 | E35: EXPLORA | F35: EXPERSNLEV | G35: Director of Design | H35: 0.2 | I35: =48000/12 -> 4000 | J35: 8 | K35: /months | L35: 0 | M35: =J35*I35*H35 -> 6400 | N35: =SUM(L35:M35) -> 6400 | O35: 0.05 | P35: =I35*$H$7 -> 4160 | Q35: 12 | R35: 0 | S35: =P35*O35*Q35 -> 2496 | T35: =SUM(R35:S35) -> 2496 | U35: 0.05 | V35: =I35*$H$7*$H$7 -> 4326.4 | W35: 12 | X35: 0 | Y35: =V35*U35*W35 -> 2595.84 | Z35: =SUM(X35:Y35) -> 2595.84 | AA35: 0.05 | AB35: =I35*$H$7*$H$7*$H$7 -> 4499.456 | AC35: 12 | AD35: 0 | AE35: =AB35*AA35*AC35 -> 2699.6736 | AF35: =SUM(AD35:AE35) -> 2699.6736 | AG35: 0.05 | AH35: =I35*$H$7*$H$7*$H$7*$H$7 -> 4679.4342 | AI35: 8 | AJ35: 0 | AK35: =AH35*AG35*AI35 -> 1871.7737 | AL35: =SUM(AJ35:AK35) -> 1871.7737 | AM35: =L35+R35+X35+AD35+AJ35 -> 0 | AN35: =M35+S35+Y35+AE35+AK35 -> 16063.287 | AO35: =SUM(AM35:AN35) -> 16063.287
A36: SUBEXPLORA | B36: 89050 | C36: COL2 | D36: COL2 | E36: EXPLORA | F36: EXPERSNLEV | G36: Head of Design | H36: 0.2 | I36: 2000 | J36: 8 | K36: /months | L36: 0 | M36: =J36*I36*H36 -> 3200 | N36: =SUM(L36:M36) -> 3200 | O36: 0.1 | P36: =I36*$H$7 -> 2080 | Q36: 12 | R36: 0 | S36: =P36*O36*Q36 -> 2496 | T36: =SUM(R36:S36) -> 2496 | U36: 0.1 | V36: =I36*$H$7*$H$7 -> 2163.2 | W36: 12 | X36: 0 | Y36: =V36*U36*W36 -> 2595.84 | Z36: =SUM(X36:Y36) -> 2595.84 | AA36: 0.1 | AB36: =I36*$H$7*$H$7*$H$7 -> 2249.728 | AC36: 12 | AD36: 0 | AE36: =AB36*AA36*AC36 -> 2699.6736 | AF36: =SUM(AD36:AE36) -> 2699.6736 | AG36: 0.1 | AH36: =I36*$H$7*$H$7*$H$7*$H$7 -> 2339.7171 | AI36: 8 | AJ36: 0 | AK36: =AH36*AG36*AI36 -> 1871.7737 | AL36: =SUM(AJ36:AK36) -> 1871.7737 | AM36: =L36+R36+X36+AD36+AJ36 -> 0 | AN36: =M36+S36+Y36+AE36+AK36 -> 12863.287 | AO36: =SUM(AM36:AN36) -> 12863.287
A37: SUBEXPLORA | B37: 89050 | C37: COL2 | D37: COL2 | E37: EXPLORA | F37: EXPERSNLEV | G37: Purchasing Coordinator | H37: 0.1 | I37: 2000 | J37: 9 | K37: /months | L37: 0 | M37: =J37*I37*H37 -> 1800 | N37: =SUM(L37:M37) -> 1800 | O37: 0.1 | P37: =I37*$H$7 -> 2080 | Q37: 12 | R37: 0 | S37: =P37*O37*Q37 -> 2496 | T37: =SUM(R37:S37) -> 2496 | U37: 0.1 | V37: =I37*$H$7*$H$7 -> 2163.2 | W37: 12 | X37: 0 | Y37: =V37*U37*W37 -> 2595.84 | Z37: =SUM(X37:Y37) -> 2595.84 | AA37: 0.1 | AB37: =I37*$H$7*$H$7*$H$7 -> 2249.728 | AC37: 12 | AD37: 0 | AE37: =AB37*AA37*AC37 -> 2699.6736 | AF37: =SUM(AD37:AE37) -> 2699.6736 | AG37: 0.1 | AH37: =I37*$H$7*$H$7*$H$7*$H$7 -> 2339.7171 | AI37: 8 | AJ37: 0 | AK37: =AH37*AG37*AI37 -> 1871.7737 | AL37: =SUM(AJ37:AK37) -> 1871.7737 | AM37: =L37+R37+X37+AD37+AJ37 -> 0 | AN37: =M37+S37+Y37+AE37+AK37 -> 11463.287 | AO37: =SUM(AM37:AN37) -> 11463.287
A38: SUBEXPLORA | B38: 89050 | C38: COL2 | D38: COL2 | E38: EXPLORA | F38: EXPERSNLEV | G38: Accounting Coordinator | H38: 0.3 | I38: 1250 | J38: 8 | K38: /months | L38: 0 | M38: =J38*I38*H38 -> 3000 | N38: =SUM(L38:M38) -> 3000 | O38: 0.3 | P38: =I38*$H$7 -> 1300 | Q38: 12 | R38: 0 | S38: =P38*O38*Q38 -> 4680 | T38: =SUM(R38:S38) -> 4680 | U38: 0.3 | V38: =I38*$H$7*$H$7 -> 1352 | W38: 12 | X38: 0 | Y38: =V38*U38*W38 -> 4867.2 | Z38: =SUM(X38:Y38) -> 4867.2 | AA38: 0.3 | AB38: =I38*$H$7*$H$7*$H$7 -> 1406.08 | AC38: 12 | AD38: 0 | AE38: =AB38*AA38*AC38 -> 5061.888 | AF38: =SUM(AD38:AE38) -> 5061.888 | AG38: 0.3 | AH38: =I38*$H$7*$H$7*$H$7*$H$7 -> 1462.3232 | AI38: 10 | AJ38: 0 | AK38: =AH38*AG38*AI38 -> 4386.9696 | AL38: =SUM(AJ38:AK38) -> 4386.9696 | AM38: =L38+R38+X38+AD38+AJ38 -> 0 | AN38: =M38+S38+Y38+AE38+AK38 -> 21996.058 | AO38: =SUM(AM38:AN38) -> 21996.058
A39: SUBEXPLORA | B39: 89050 | C39: COL2 | D39: COL2 | E39: EXPLORA | F39: EXPERSNLEV | G39: Accounting Analyst | H39: 0.3 | I39: 1000 | J39: 8 | K39: /months | L39: 0 | M39: =J39*I39*H39 -> 2400 | N39: =SUM(L39:M39) -> 2400 | O39: 0.3 | P39: =I39*$H$7 -> 1040 | Q39: 12 | R39: 0 | S39: =P39*O39*Q39 -> 3744 | T39: =SUM(R39:S39) -> 3744 | U39: 0.3 | V39: =I39*$H$7*$H$7 -> 1081.6 | W39: 12 | X39: 0 | Y39: =V39*U39*W39 -> 3893.76 | Z39: =SUM(X39:Y39) -> 3893.76 | AA39: 0.3 | AB39: =I39*$H$7*$H$7*$H$7 -> 1124.864 | AC39: 12 | AD39: 0 | AE39: =AB39*AA39*AC39 -> 4049.5104 | AF39: =SUM(AD39:AE39) -> 4049.5104 | AG39: 0.3 | AH39: =I39*$H$7*$H$7*$H$7*$H$7 -> 1169.8586 | AI39: 8 | AJ39: 0 | AK39: =AH39*AG39*AI39 -> 2807.6605 | AL39: =SUM(AJ39:AK39) -> 2807.6605 | AM39: =L39+R39+X39+AD39+AJ39 -> 0 | AN39: =M39+S39+Y39+AE39+AK39 -> 16894.931 | AO39: =SUM(AM39:AN39) -> 16894.931
