Workbook

Sheet Summary Budget
A1: Entity: | B1: P
A2: Program-Dept.: | B2: FTF
A3: Funder-Grant: | B3: USDA700
A4: Country Code: | B4: COL2
A5: Subcontract Code: | B5: ICFUNDACION | E5: Item | F5: Unit | G5: # of Units | H5: Unit Value COP | I5: Unit Value USD | J5: Total Value COP | K5: Total Value USD | L5: C4D Contribution COP | M5: Contribution C4D USD | N5: % Contribution C4D | O5: Cotribution IC Cost - Share / COP | P5: Cotribution IC Cost - Share / USD | Q5: % Contribution IC Cost - Share/ | R5: Level of Effort (LOE) | S5: Detail
A6: Sage Activity | B6: Sage Object Code/ Line Item | C6: Sub Name Code | D6: Subcontract Activity Code | E6: 1.Personal (Laboral) | J6: =+SUM(J7:J24) -> 1606446288 | K6: =SUM(K7:K24) -> 364956.28 | L6: =+SUM(L7:L24) -> 1418576688 | M6: =SUM(M7:M24) -> 322275.61 | O6: =+SUM(O7:O24) -> 187869600 | P6: =SUM(P7:P24) -> 42680.661
A7: SUBPRODORG | B7: 89050 | C7: ICFUNDCION | D7: ICFPERPCO | E7: 1.1. Program Coordinator | F7: month | G7: =+'Detailed Budget'!AO4 -> 28 | H7: =+(('Detailed Budget'!D4*'Detailed Budget'!C4)+('Detailed Budget'!Q4*'Detailed Budget'!P4)+('Detailed Budget'!AD4*'Detailed Budget'!AC4))/G7 -> 2139428.6 | I7: =+H7/$E$73 -> 486.04045 | J7: =+H7*G7 -> 59904000 | K7: =+J7/$E$73 -> 13609.133 | L7: =+J7*N7 -> 0 | M7: =+L7/$E$73 -> 0 | N7: =+'Detailed Budget'!F4 -> 0 | O7: =+J7*Q7 -> 59904000 | P7: =+O7/$E$73 -> 13609.133 | Q7: =+'Detailed Budget'!I4 -> 1 | R7: =+'Detailed Budget'!AV4 -> 0.2 | S7: Laura Rivera
A8: SUBPRODORG | B8: 89050 | C8: ICFUNDCION | D8: ICFPERBSC | E8: 1.2. Business Strengthening Coordinator | F8: month | G8: =+'Detailed Budget'!AO5 -> 28 | H8: =+(('Detailed Budget'!D5*'Detailed Budget'!C5)+('Detailed Budget'!Q5*'Detailed Budget'!P5)+('Detailed Budget'!AD5*'Detailed Budget'!AC5))/G8 -> 4409362.3 | I8: =+H8/$E$73 -> 1001.7294 | J8: =+H8*G8 -> 123462144 | K8: =+J8/$E$73 -> 28048.423 | L8: =+J8*N8 -> 123462144 | M8: =+L8/$E$73 -> 28048.423 | N8: =+'Detailed Budget'!F5 -> 1 | O8: =+J8*Q8 -> 0 | P8: =+O8/$E$73 -> 0 | Q8: =+'Detailed Budget'!I5 -> 0 | R8: =+'Detailed Budget'!AV5 -> 1 | S8: Yineth Henao
A9: SUBPRODORG | B9: 89050 | C9: ICFUNDCION | D9: ICFPERCTS | E9: 1.3. Cacao technical specialist | F9: month | G9: =+'Detailed Budget'!AO6 -> 28 | H9: =+(('Detailed Budget'!D6*'Detailed Budget'!C6)+('Detailed Budget'!Q6*'Detailed Budget'!P6)+('Detailed Budget'!AD6*'Detailed Budget'!AC6))/G9 -> 4409362.3 | I9: =+H9/$E$73 -> 1001.7294 | J9: =+H9*G9 -> 123462144 | K9: =+J9/$E$73 -> 28048.423 | L9: =+J9*N9 -> 123462144 | M9: =+L9/$E$73 -> 28048.423 | N9: =+'Detailed Budget'!F6 -> 1 | O9: =+J9*Q9 -> 0 | P9: =+O9/$E$73 -> 0 | Q9: =+'Detailed Budget'!I6 -> 0 | R9: =+'Detailed Budget'!AV6 -> 1 | S9: Juan Gabriel Vargas
A10: SUBPRODORG | B10: 89050 | C10: ICFUNDCION | D10: ICFPERORG | E10: 1.4. Organizational Professional | F10: month | G10: =+'Detailed Budget'!AO7 -> 28 | H10: =+(('Detailed Budget'!D7*'Detailed Budget'!C7)+('Detailed Budget'!Q7*'Detailed Budget'!P7)+('Detailed Budget'!AD7*'Detailed Budget'!AC7))/G10 -> 3423085.7 | I10: =+H10/$E$73 -> 777.66473 | J10: =+H10*G10 -> 95846400 | K10: =+J10/$E$73 -> 21774.612 | L10: =+J10*N10 -> 71884800 | M10: =+L10/$E$73 -> 16330.959 | N10: =+'Detailed Budget'!F7 -> 0.75 | O10: =+J10*Q10 -> 23961600 | P10: =+O10/$E$73 -> 5443.6531 | Q10: =+'Detailed Budget'!I7 -> 0.25 | R10: =+'Detailed Budget'!AV7 -> 0.8 | S10: Por contratar
A11: SUBPRODORG | B11: 89050 | C11: ICFUNDCION | D11: ICFPERF&A | E11: 1.5. F&A Specialist | F11: month | G11: =+'Detailed Budget'!AO8 -> 28 | H11: =+(('Detailed Budget'!D8*'Detailed Budget'!C8)+('Detailed Budget'!Q8*'Detailed Budget'!P8)+('Detailed Budget'!AD8*'Detailed Budget'!AC8))/G11 -> 2032457.1 | I11: =+H11/$E$73 -> 461.73843 | J11: =+H11*G11 -> 56908800 | K11: =+J11/$E$73 -> 12928.676 | L11: =+J11*N11 -> 56908800 | M11: =+L11/$E$73 -> 12928.676 | N11: =+'Detailed Budget'!F8 -> 1 | O11: =+J11*Q11 -> 0 | P11: =+O11/$E$73 -> 0 | Q11: =+'Detailed Budget'!I8 -> 0 | R11: =+'Detailed Budget'!AV8 -> 0.5 | S11: Yuliana Murillo
A12: SUBPRODORG | B12: 89050 | C12: ICFUNDCION | D12: ICFPERBPP | E12: 1.6. Business Partner Professional Antioquia, Córdoba 1 | F12: month | G12: =+'Detailed Budget'!AO9 -> 27 | H12: =+(('Detailed Budget'!D9*'Detailed Budget'!C9)+('Detailed Budget'!Q9*'Detailed Budget'!P9)+('Detailed Budget'!AD9*'Detailed Budget'!AC9))/G12 -> 3728666.7 | I12: =+H12/$E$73 -> 847.08733 | J12: =+H12*G12 -> 100674000 | K12: =+J12/$E$73 -> 22871.358 | L12: =+J12*N12 -> 100674000 | M12: =+L12/$E$73 -> 22871.358 | N12: =+'Detailed Budget'!F9 -> 1 | O12: =+J12*Q12 -> 0 | P12: =+O12/$E$73 -> 0 | Q12: =+'Detailed Budget'!I9 -> 0 | R12: =+'Detailed Budget'!AV9 -> 1 | S12: Business Partner Professional
A13: SUBPRODORG | B13: 89050 | C13: ICFUNDCION | D13: ICFPERBPP | E13: 1.7. Business Partner Professional Antioquia, Córdoba 2 | F13: month | G13: =+'Detailed Budget'!AO10 -> 24 | H13: =+(('Detailed Budget'!D10*'Detailed Budget'!C10)+('Detailed Budget'!Q10*'Detailed Budget'!P10)+('Detailed Budget'!AD10*'Detailed Budget'!AC10))/G13 -> 3675000 | I13: =+H13/$E$73 -> 834.89521 | J13: =+H13*G13 -> 88200000 | K13: =+J13/$E$73 -> 20037.485 | L13: =+J13*N13 -> 88200000 | M13: =+L13/$E$73 -> 20037.485 | N13: =+'Detailed Budget'!F10 -> 1 | O13: =+J13*Q13 -> 0 | P13: =+O13/$E$73 -> 0 | Q13: =+'Detailed Budget'!I10 -> 0 | R13: =+'Detailed Budget'!AV10 -> 1 | S13: Business Partner Professional
A14: SUBPRODORG | B14: 89050 | C14: ICFUNDCION | D14: ICFPERBPP | E14: 1.8. Business Partner Professional Caldas | F14: month | G14: =+'Detailed Budget'!AO11 -> 27 | H14: =+(('Detailed Budget'!D11*'Detailed Budget'!C11)+('Detailed Budget'!Q11*'Detailed Budget'!P11)+('Detailed Budget'!AD11*'Detailed Budget'!AC11))/G14 -> 3728666.7 | I14: =+H14/$E$73 -> 847.08733 | J14: =+H14*G14 -> 100674000 | K14: =+J14/$E$73 -> 22871.358 | L14: =+J14*N14 -> 100674000 | M14: =+L14/$E$73 -> 22871.358 | N14: =+'Detailed Budget'!F11 -> 1 | O14: =+J14*Q14 -> 0 | P14: =+O14/$E$73 -> 0 | Q14: =+'Detailed Budget'!I11 -> 0 | R14: =+'Detailed Budget'!AV11 -> 1 | S14: Business Partner Professional
A15: SUBPRODORG | B15: 89050 | C15: ICFUNDCION | D15: ICFPERBPP | E15: 1.9. Business Partner Professional Guajira, Cesar, Magdalena | F15: month | G15: =+'Detailed Budget'!AO12 -> 27 | H15: =+(('Detailed Budget'!D12*'Detailed Budget'!C12)+('Detailed Budget'!Q12*'Detailed Budget'!P12)+('Detailed Budget'!AD12*'Detailed Budget'!AC12))/G15 -> 3728666.7 | I15: =+H15/$E$73 -> 847.08733 | J15: =+H15*G15 -> 100674000 | K15: =+J15/$E$73 -> 22871.358 | L15: =+J15*N15 -> 100674000 | M15: =+L15/$E$73 -> 22871.358 | N15: =+'Detailed Budget'!F12 -> 1 | O15: =+J15*Q15 -> 0 | P15: =+O15/$E$73 -> 0 | Q15: =+'Detailed Budget'!I12 -> 0 | R15: =+'Detailed Budget'!AV12 -> 1 | S15: Business Partner Professional
A16: SUBPRODORG | B16: 89050 | C16: ICFUNDCION | D16: ICFPERBPP | E16: 1.10. Business Partner Professional Huila | F16: month | G16: =+'Detailed Budget'!AO13 -> 27 | H16: =+(('Detailed Budget'!D13*'Detailed Budget'!C13)+('Detailed Budget'!Q13*'Detailed Budget'!P13)+('Detailed Budget'!AD13*'Detailed Budget'!AC13))/G16 -> 3728666.7 | I16: =+H16/$E$73 -> 847.08733 | J16: =+H16*G16 -> 100674000 | K16: =+J16/$E$73 -> 22871.358 | L16: =+J16*N16 -> 100674000 | M16: =+L16/$E$73 -> 22871.358 | N16: =+'Detailed Budget'!F13 -> 1 | O16: =+J16*Q16 -> 0 | P16: =+O16/$E$73 -> 0 | Q16: =+'Detailed Budget'!I13 -> 0 | R16: =+'Detailed Budget'!AV13 -> 1 | S16: Business Partner Professional
A17: SUBPRODORG | B17: 89050 | C17: ICFUNDCION | D17: ICFPERBPP | E17: 1.11. Business Partner Professional Santander and Bolivar | F17: month | G17: =+'Detailed Budget'!AO14 -> 24 | H17: =+(('Detailed Budget'!D14*'Detailed Budget'!C14)+('Detailed Budget'!Q14*'Detailed Budget'!P14)+('Detailed Budget'!AD14*'Detailed Budget'!AC14))/G17 -> 3675000 | I17: =+H17/$E$73 -> 834.89521 | J17: =+H17*G17 -> 88200000 | K17: =+J17/$E$73 -> 20037.485 | L17: =+J17*N17 -> 88200000 | M17: =+L17/$E$73 -> 20037.485 | N17: =+'Detailed Budget'!F14 -> 1 | O17: =+J17*Q17 -> 0 | P17: =+O17/$E$73 -> 0 | Q17: =+'Detailed Budget'!I14 -> 0 | R17: =+'Detailed Budget'!AV14 -> 1 | S17: Business Partner Professional
A18: SUBPRODORG | B18: 89050 | C18: ICFUNDCION | D18: ICFPERBPP | E18: 1.12. Business Partner Professional Cauca | F18: month | G18: =+'Detailed Budget'!AO15 -> 27 | H18: =+(('Detailed Budget'!D15*'Detailed Budget'!C15)+('Detailed Budget'!Q15*'Detailed Budget'!P15)+('Detailed Budget'!AD15*'Detailed Budget'!AC15))/G18 -> 3728666.7 | I18: =+H18/$E$73 -> 847.08733 | J18: =+H18*G18 -> 100674000 | K18: =+J18/$E$73 -> 22871.358 | L18: =+J18*N18 -> 100674000 | M18: =+L18/$E$73 -> 22871.358 | N18: =+'Detailed Budget'!F15 -> 1 | O18: =+J18*Q18 -> 0 | P18: =+O18/$E$73 -> 0 | Q18: =+'Detailed Budget'!I15 -> 0 | R18: =+'Detailed Budget'!AV15 -> 1 | S18: Business Partner Professional
... A24: SUBPRODORG | B24: 89050 | C24: ICFUNDCION | D24: ICFPERADA | E24: 1.18. Administrative Assistant | F24: month | G24: =+'Detailed Budget'!AO21 -> 28 | H24: =+(('Detailed Budget'!D21*'Detailed Budget'!C21)+('Detailed Budget'!Q21*'Detailed Budget'!P21)+('Detailed Budget'!AD21*'Detailed Budget'!AC21))/G24 -> 2567314.3 | I24: =+H24/$E$73 -> 583.24855 | J24: =+H24*G24 -> 71884800 | K24: =+J24/$E$73 -> 16330.959 | L24: =+J24*N24 -> 71884800 | M24: =+L24/$E$73 -> 16330.959 | N24: =+'Detailed Budget'!F21 -> 1 | O24: =+J24*Q24 -> 0 | P24: =+O24/$E$73 -> 0 | Q24: =+'Detailed Budget'!I21 -> 0 | R24: =+'Detailed Budget'!AV21 -> 1 | S24: Administrative Professiona
E25: 2. Fringe benefits | G25: 0.5829 | J25: =+SUM(J26:J43) -> 9.2212362e+08 | K25: =SUM(K26:K43) -> 209490.23 | L25: =+SUM(L26:L43) -> 8.1647224e+08 | M25: =SUM(M26:M43) -> 185488.1 | O25: =+SUM(O26:O43) -> 1.0565137e+08 | P25: =SUM(P26:P43) -> 24002.129
A26: SUBPRODORG | B26: 89050 | C26: ICFUNDCION | D26: ICFRINPCO | E26: =+E7 -> 1.1. Program Coordinator | F26: Month | G26: =+'Detailed Budget'!AO23 -> 28 | H26: =+(('Detailed Budget'!D23*'Detailed Budget'!C23)+('Detailed Budget'!Q23*'Detailed Budget'!P23)+('Detailed Budget'!AC23*'Detailed Budget'!AD23))/G26 -> 1247072.9 | I26: =+H26/$E$73 -> 283.31298 | J26: =+H26*G26 -> 34918042 | K26: =+J26/$E$73 -> 7932.7635 | L26: =+J26*N26 -> 0 | M26: =+L26/$E$73 -> 0 | N26: =+N7 -> 0 | O26: =+J26*Q26 -> 34918042 | P26: =+O26/$E$73 -> 7932.7635 | Q26: 1 | R26: =+R7 -> 0.2 | S26: By law, social benefits are calculated at 58.29% for personnel affiliated to risk 5, and 51.85% for administrative personnel at risk 1.
A27: SUBPRODORG | B27: 89050 | C27: ICFUNDCION | D27: ICFRINBSC | E27: =+E8 -> 1.2. Business Strengthening Coordinator | F27: Month | G27: =+'Detailed Budget'!AO24 -> 28 | H27: =+(('Detailed Budget'!D24*'Detailed Budget'!C24)+('Detailed Budget'!Q24*'Detailed Budget'!P24)+('Detailed Budget'!AC24*'Detailed Budget'!AD24))/G27 -> 2570217.3 | I27: =+H27/$E$73 -> 583.90805 | J27: =+H27*G27 -> 71966084 | K27: =+J27/$E$73 -> 16349.426 | L27: =+J27*N27 -> 71966084 | M27: =+L27/$E$73 -> 16349.426 | N27: =+N8 -> 1 | O27: =+J27*Q27 -> 0 | P27: =+O27/$E$73 -> 0 | Q27: 0 | R27: =+R8 -> 1
A28: SUBPRODORG | B28: 89050 | C28: ICFUNDCION | D28: ICFRINCTS | E28: =+E9 -> 1.3. Cacao technical specialist | F28: Month | G28: =+'Detailed Budget'!AO25 -> 28 | H28: =+(('Detailed Budget'!D25*'Detailed Budget'!C25)+('Detailed Budget'!Q25*'Detailed Budget'!P25)+('Detailed Budget'!AC25*'Detailed Budget'!AD25))/G28 -> 2570217.3 | I28: =+H28/$E$73 -> 583.90805 | J28: =+H28*G28 -> 71966084 | K28: =+J28/$E$73 -> 16349.426 | L28: =+J28*N28 -> 71966084 | M28: =+L28/$E$73 -> 16349.426 | N28: =+N9 -> 1 | O28: =+J28*Q28 -> 0 | P28: =+O28/$E$73 -> 0 | Q28: 0 | R28: =+R9 -> 1
A29: SUBPRODORG | B29: 89050 | C29: ICFUNDCION | D29: ICFRINORG | E29: =+E10 -> 1.4. Organizational Professional | F29: Month | G29: =+'Detailed Budget'!AO26 -> 28 | H29: =+(('Detailed Budget'!D26*'Detailed Budget'!C26)+('Detailed Budget'!Q26*'Detailed Budget'!P26)+('Detailed Budget'!AC26*'Detailed Budget'!AD26))/G29 -> 1995316.7 | I29: =+H29/$E$73 -> 453.30077 | J29: =+H29*G29 -> 55868867 | K29: =+J29/$E$73 -> 12692.422 | L29: =+J29*N29 -> 41901650 | M29: =+L29/$E$73 -> 9519.3162 | N29: =+N10 -> 0.75 | O29: =+J29*Q29 -> 13967217 | P29: =+O29/$E$73 -> 3173.1054 | Q29: 0.25 | R29: =+R10 -> 0.8
A30: SUBPRODORG | B30: 89050 | C30: ICFUNDCION | D30: ICFRINF&A | E30: =+E11 -> 1.5. F&A Specialist | F30: Month | G30: =+'Detailed Budget'!AO27 -> 28 | H30: =+(('Detailed Budget'!D27*'Detailed Budget'!C27)+('Detailed Budget'!Q27*'Detailed Budget'!P27)+('Detailed Budget'!AC27*'Detailed Budget'!AD27))/G30 -> 1184719.3 | I30: =+H30/$E$73 -> 269.14733 | J30: =+H30*G30 -> 33172140 | K30: =+J30/$E$73 -> 7536.1253 | L30: =+J30*N30 -> 33172140 | M30: =+L30/$E$73 -> 7536.1253 | N30: =+N11 -> 1 | O30: =+J30*Q30 -> 0 | P30: =+O30/$E$73 -> 0 | Q30: 0 | R30: =+R11 -> 0.5
A31: SUBPRODORG | B31: 89050 | C31: ICFUNDCION | D31: ICFRINBPP | E31: =+E12 -> 1.6. Business Partner Professional Antioquia, Córdoba 1 | F31: Month | G31: =+'Detailed Budget'!AO28 -> 27 | H31: =+(('Detailed Budget'!D28*'Detailed Budget'!C28)+('Detailed Budget'!Q28*'Detailed Budget'!P28)+('Detailed Budget'!AC28*'Detailed Budget'!AD28))/G31 -> 2173439.8 | I31: =+H31/$E$73 -> 493.76721 | J31: =+H31*G31 -> 58682875 | K31: =+J31/$E$73 -> 13331.715 | L31: =+J31*N31 -> 58682875 | M31: =+L31/$E$73 -> 13331.715 | N31: =+N12 -> 1 | O31: =+J31*Q31 -> 0 | P31: =+O31/$E$73 -> 0 | Q31: 0 | R31: =+R12 -> 1
A32: SUBPRODORG | B32: 89050 | C32: ICFUNDCION | D32: ICFRINBPP | E32: =+E13 -> 1.7. Business Partner Professional Antioquia, Córdoba 2 | F32: Month | G32: =+'Detailed Budget'!AO29 -> 24 | H32: =+(('Detailed Budget'!D29*'Detailed Budget'!C29)+('Detailed Budget'!Q29*'Detailed Budget'!P29)+('Detailed Budget'!AC29*'Detailed Budget'!AD29))/G32 -> 2142157.5 | I32: =+H32/$E$73 -> 486.66042 | J32: =+H32*G32 -> 51411780 | K32: =+J32/$E$73 -> 11679.85 | L32: =+J32*N32 -> 51411780 | M32: =+L32/$E$73 -> 11679.85 | N32: =+N13 -> 1 | O32: =+J32*Q32 -> 0 | P32: =+O32/$E$73 -> 0 | Q32: 0 | R32: =+R13 -> 1
A33: SUBPRODORG | B33: 89050 | C33: ICFUNDCION | D33: ICFRINBPP | E33: =+E14 -> 1.8. Business Partner Professional Caldas | F33: Month | G33: =+'Detailed Budget'!AO30 -> 27 | H33: =+(('Detailed Budget'!D30*'Detailed Budget'!C30)+('Detailed Budget'!Q30*'Detailed Budget'!P30)+('Detailed Budget'!AC30*'Detailed Budget'!AD30))/G33 -> 2173439.8 | I33: =+H33/$E$73 -> 493.76721 | J33: =+H33*G33 -> 58682875 | K33: =+J33/$E$73 -> 13331.715 | L33: =+J33*N33 -> 58682875 | M33: =+L33/$E$73 -> 13331.715 | N33: =+N14 -> 1 | O33: =+J33*Q33 -> 0 | P33: =+O33/$E$73 -> 0 | Q33: 0 | R33: =+R14 -> 1
A34: SUBPRODORG | B34: 89050 | C34: ICFUNDCION | D34: ICFRINBPP | E34: =+E15 -> 1.9. Business Partner Professional Guajira, Cesar, Magdalena | F34: Month | G34: =+'Detailed Budget'!AO31 -> 27 | H34: =+(('Detailed Budget'!D31*'Detailed Budget'!C31)+('Detailed Budget'!Q31*'Detailed Budget'!P31)+('Detailed Budget'!AC31*'Detailed Budget'!AD31))/G34 -> 2173439.8 | I34: =+H34/$E$73 -> 493.76721 | J34: =+H34*G34 -> 58682875 | K34: =+J34/$E$73 -> 13331.715 | L34: =+J34*N34 -> 58682875 | M34: =+L34/$E$73 -> 13331.715 | N34: =+N15 -> 1 | O34: =+J34*Q34 -> 0 | P34: =+O34/$E$73 -> 0 | Q34: 0 | R34: =+R15 -> 1
A35: SUBPRODORG | B35: 89050 | C35: ICFUNDCION | D35: ICFRINBPP | E35: =+E16 -> 1.10. Business Partner Professional Huila | F35: Month | G35: =+'Detailed Budget'!AO32 -> 27 | H35: =+(('Detailed Budget'!D32*'Detailed Budget'!C32)+('Detailed Budget'!Q32*'Detailed Budget'!P32)+('Detailed Budget'!AC32*'Detailed Budget'!AD32))/G35 -> 2173439.8 | I35: =+H35/$E$73 -> 493.76721 | J35: =+H35*G35 -> 58682875 | K35: =+J35/$E$73 -> 13331.715 | L35: =+J35*N35 -> 58682875 | M35: =+L35/$E$73 -> 13331.715 | N35: =+N16 -> 1 | O35: =+J35*Q35 -> 0 | P35: =+O35/$E$73 -> 0 | Q35: 0 | R35: =+R16 -> 1
A36: SUBPRODORG | B36: 89050 | C36: ICFUNDCION | D36: ICFRINBPP | E36: =+E17 -> 1.11. Business Partner Professional Santander and Bolivar | F36: Month | G36: =+'Detailed Budget'!AO33 -> 24 | H36: =+(('Detailed Budget'!D33*'Detailed Budget'!C33)+('Detailed Budget'!Q33*'Detailed Budget'!P33)+('Detailed Budget'!AC33*'Detailed Budget'!AD33))/G36 -> 2142157.5 | I36: =+H36/$E$73 -> 486.66042 | J36: =+H36*G36 -> 51411780 | K36: =+J36/$E$73 -> 11679.85 | L36: =+J36*N36 -> 51411780 | M36: =+L36/$E$73 -> 11679.85 | N36: =+N17 -> 1 | O36: =+J36*Q36 -> 0 | P36: =+O36/$E$73 -> 0 | Q36: 0 | R36: =+R17 -> 1
A37: SUBPRODORG | B37: 89050 | C37: ICFUNDCION | D37: ICFRINBPP | E37: =+E18 -> 1.12. Business Partner Professional Cauca | F37: Month | G37: =+'Detailed Budget'!AO34 -> 27 | H37: =+(('Detailed Budget'!D34*'Detailed Budget'!C34)+('Detailed Budget'!Q34*'Detailed Budget'!P34)+('Detailed Budget'!AC34*'Detailed Budget'!AD34))/G37 -> 2173439.8 | I37: =+H37/$E$73 -> 493.76721 | J37: =+H37*G37 -> 58682875 | K37: =+J37/$E$73 -> 13331.715 | L37: =+J37*N37 -> 58682875 | M37: =+L37/$E$73 -> 13331.715 | N37: =+N18 -> 1 | O37: =+J37*Q37 -> 0 | P37: =+O37/$E$73 -> 0 | Q37: 0 | R37: =+R18 -> 1
A38: SUBPRODORG | B38: 89050 | C38: ICFUNDCION | D38: ICFRINBPP | E38: =+E19 -> 1.13. Business Partner Professional Tolima 1 | F38: Month | G38: =+'Detailed Budget'!AO35 -> 27 | H38: =+(('Detailed Budget'!D35*'Detailed Budget'!C35)+('Detailed Budget'!Q35*'Detailed Budget'!P35)+('Detailed Budget'!AC35*'Detailed Budget'!AD35))/G38 -> 2173439.8 | I38: =+H38/$E$73 -> 493.76721 | J38: =+H38*G38 -> 58682875 | K38: =+J38/$E$73 -> 13331.715 | L38: =+J38*N38 -> 58682875 | M38: =+L38/$E$73 -> 13331.715 | N38: =+N19 -> 1 | O38: =+J38*Q38 -> 0 | P38: =+O38/$E$73 -> 0 | Q38: 0 | R38: =+R19 -> 1
... A43: SUBPRODORG | B43: 89050 | C43: ICFUNDCION | D43: ICFRINADA | E43: =+E24 -> 1.18. Administrative Assistant | F43: Month | G43: =+'Detailed Budget'!AO40 -> 28 | H43: =+(('Detailed Budget'!D40*'Detailed Budget'!C40)+('Detailed Budget'!Q40*'Detailed Budget'!P40)+('Detailed Budget'!AC40*'Detailed Budget'!AD40))/G43 -> 1331152.5 | I43: =+H43/$E$73 -> 302.41437 | J43: =+H43*G43 -> 37272269 | K43: =+J43/$E$73 -> 8467.6024 | L43: =+J43*N43 -> 37272269 | M43: =+L43/$E$73 -> 8467.6024 | N43: =+N24 -> 1 | O43: =+J43*Q43 -> 0 | P43: =+O43/$E$73 -> 0 | Q43: 0 | R43: =+R24 -> 1
E44: 3. Travel costs | J44: =+SUM(J45:J48) -> 288300000 | K44: =SUM(K45:K48) -> 65496.677 | L44: =+SUM(L45:L48) -> 288300000 | M44: =SUM(M45:M48) -> 65496.677 | O44: =+SUM(O45:O48) -> 0 | P44: =SUM(P45:P48) -> 0
A45: SUBPRODORG | B45: 89050 | C45: ICFUNDCION | D45: ICFAIR | E45: 3.1. Air transportation | F45: round trip | G45: =('Detailed Budget'!C42+'Detailed Budget'!P42+'Detailed Budget'!AC42) -> 51 | H45: ='Detailed Budget'!D42 -> 1000000 | I45: =+H45/$E$73 -> 227.18237 | J45: =+G45*H45 -> 51000000 | K45: =+J45/$E$73 -> 11586.301 | L45: =+J45*N45 -> 51000000 | M45: =+L45/$E$73 -> 11586.301 | N45: 1 | O45: =+J45*Q45 -> 0 | P45: =+O45/$E$73 -> 0 | Q45: 0 | S45: Average cost of travel for the project coordinator, strengthening coordinator, cocoa specialist, organizational specialist and A&F professional. For more details on travel, see the "Workshops and Travel" sheet.
A46: SUBPRODORG | B46: 89050 | C46: ICFUNDCION | D46: ICFTRANS | E46: 3.2. Land transportation | F46: trip | G46: =('Detailed Budget'!C43+'Detailed Budget'!P43+'Detailed Budget'!AC43) -> 375 | H46: ='Detailed Budget'!D43 -> 150000 | I46: =+H46/$E$73 -> 34.077356 | J46: =+G46*H46 -> 56250000 | K46: =+J46/$E$73 -> 12779.008 | L46: =+J46*N46 -> 56250000 | M46: =+L46/$E$73 -> 12779.008 | N46: 1 | O46: =+J46*Q46 -> 0 | P46: =+O46/$E$73 -> 0 | Q46: 0 | S46: Average cost of ground transportation to carry out project activities, this cost was calculated for project personnel. For more details on travel, see the "Workshops and Travel" sheet.
A47: SUBPRODORG | B47: 89050 | C47: ICFUNDCION | D47: IFCLODGING | E47: 3.3. Lodging | F47: ninghts lodging | G47: =('Detailed Budget'!C44+'Detailed Budget'!P44+'Detailed Budget'!AC44) -> 852 | H47: ='Detailed Budget'!D44 -> 100000 | I47: =+H47/$E$73 -> 22.718237 | J47: =+G47*H47 -> 85200000 | K47: =+J47/$E$73 -> 19355.938 | L47: =+J47*N47 -> 85200000 | M47: =+L47/$E$73 -> 19355.938 | N47: 1 | O47: =+J47*Q47 -> 0 | P47: =+O47/$E$73 -> 0 | Q47: 0 | S47: Average cost of lodging to carry out project activities, this cost was calculated for project staff. For more details on travel, see the "Workshops and Travel" sheet.
A48: SUBPRODORG | B48: 89050 | C48: ICFUNDCION | D48: IFCPERDIEM | E48: 3.4. Perdiem | F48: day | G48: =('Detailed Budget'!C45+'Detailed Budget'!P45+'Detailed Budget'!AC45) -> 1065 | H48: ='Detailed Budget'!D45 -> 90000 | I48: =+H48/$E$73 -> 20.446413 | J48: =+G48*H48 -> 95850000 | K48: =+J48/$E$73 -> 21775.43 | L48: =+J48*N48 -> 95850000 | M48: =+L48/$E$73 -> 21775.43 | N48: 1 | O48: =+J48*Q48 -> 0 | P48: =+O48/$E$73 -> 0 | Q48: 0 | S48: Average cost of food to carry out project activities, this cost was calculated for project staff. For more details on travel, see the "Workshops and Travel" sheet.
E49: 4. Professional services (consultants) | J49: =+SUM(J50:J52) -> 662000000 | K49: =SUM(K50:K52) -> 150394.73 | L49: =+SUM(L50:L52) -> 599000000 | M49: =SUM(M50:M52) -> 136082.24 | O49: =+SUM(O50:O51) -> 63000000 | P49: =SUM(P50:P52) -> 14312.489
...

Sheet NM
D3: Initial C4D COP | E3: Initial C4D USD | F3: Cost Share Initial COP | G3: Cost Share Initial USD | H3: Final C4D COP | I3: Final C4D USD | J3: Cost Share Final COP | K3: Cost Share Final USD
C4: 1.Personnel | D4: 1398311640 | E4: =+D4/$C$13 -> 317671.75 | F4: 26529600 | G4: =+F4/$C$13 -> 6027.0574 | H4: ='Summary Budget'!L6 -> 1418576688 | I4: =+H4/$C$13 -> 322275.61 | J4: =+'Summary Budget'!O6 -> 187869600 | K4: =+J4/$C$13 -> 42680.661
C5: 2. Fringe benefits | D5: 6.2630378e+08 | E5: =+D5/$C$13 -> 142285.18 | F5: 11882608 | G5: =+F5/$C$13 -> 2699.519 | H5: ='Summary Budget'!L25 -> 8.1647224e+08 | I5: =+H5/$C$13 -> 185488.1 | J5: =+'Summary Budget'!O25 -> 1.0565137e+08 | K5: =+J5/$C$13 -> 24002.129
C6: 3. Trips | D6: 307650000 | E6: =+D6/$C$13 -> 69892.656 | G6: =+F6/$C$13 -> 0 | H6: ='Summary Budget'!L44 -> 288300000 | I6: =+H6/$C$13 -> 65496.677 | J6: =+'Summary Budget'!O44 -> 0 | K6: =+J6/$C$13 -> 0
C7: 4. Professional services (consultants) | D7: 630000000 | E7: =+D7/$C$13 -> 143124.89 | F7: 63000000 | G7: =+F7/$C$13 -> 14312.489 | H7: ='Summary Budget'!L49 -> 599000000 | I7: =+H7/$C$13 -> 136082.24 | J7: =+'Summary Budget'!O49 -> 63000000 | K7: =+J7/$C$13 -> 14312.489
C8: 5. Materials | D8: 106930000 | E8: =+D8/$C$13 -> 24292.611 | G8: =+F8/$C$13 -> 0 | H8: ='Summary Budget'!L53 -> 73148400 | I8: =+H8/$C$13 -> 16618.027 | J8: =+'Summary Budget'!O53 -> 0 | K8: =+J8/$C$13 -> 0
C9: 6. Direct operating costs | D9: 2.9846531e+08 | E9: =+D9/$C$13 -> 67806.057 | F9: 1.7284191e+09 | G9: =+F9/$C$13 -> 392666.35 | H9: =+'Summary Budget'!L55 -> 106930000 | I9: =+H9/$C$13 -> 24292.611 | J9: =+'Summary Budget'!O55 -> 1244000000 | K9: =+J9/$C$13 -> 282614.87
C10: Administrative expenses | D10: 1.7833871e+08 | E10: =+D10/$C$13 -> 40515.411 | F10: 66877016 | G10: =+F10/$C$13 -> 15193.279 | H10: ='Summary Budget'!L68 -> 1.6755743e+08 | I10: =+H10/$C$13 -> 38066.094 | J10: =+'Summary Budget'!O68 -> 80026049 | K10: =+J10/$C$13 -> 18180.507
D11: =SUM(D4:D10) -> 3.5459994e+09 | E11: =SUM(E4:E10) -> 805588.56 | F11: =SUM(F4:F10) -> 1.8967083e+09 | G11: =SUM(G4:G10) -> 430898.69 | H11: =SUM(H4:H10) -> 3.4699848e+09 | I11: =SUM(I4:I10) -> 788319.36 | J11: =SUM(J4:J10) -> 1.680547e+09 | K11: =SUM(K4:K10) -> 381790.66
C12: Tasa Oanda
C13: 4401.75

Sheet Detailed Budget
A1: 4401.75 | B1: Year 1 | O1: Year 2 | AB1: Year 3
A2: Item | B2: Unit | C2: # of units | D2: Unit Value COP | E2: Unit Value USD | F2: % C4D | G2: C4D Contribution COP | H2: Contribution C4D USD | I2: % IC Cost - Share | J2: Cotribution IC Cost - Share / COP | K2: Cotribution IC Cost - Share / USD | L2: Total Value COP | M2: Total Value USD | O2: Unit | P2: # of units | Q2: Unit Value COP | R2: Unit Value USD | S2: % C4D | T2: C4D Contribution COP | U2: Contribution C4D USD | V2: % IC Cost - Share | W2: Cotribution IC Cost - Share / COP | X2: Cotribution IC Cost - Share / USD | Y2: Total Value COP | Z2: Total Value USD | AB2: Unit | AC2: # of units | AD2: Unit Value COP | AE2: Unit Value USD | AF2: % C4D | AG2: C4D Contribution COP | AH2: Contribution C4D USD | AI2: % IC Cost - Share | AJ2: Cotribution IC Cost - Share / COP | AK2: Cotribution IC Cost - Share / USD | AL2: Total Value COP | AM2: Total Value USD | AO2: Totals Qts. | AP2: Total budget COP | AQ2: Total budget USD | AR2: Total C4D COP | AS2: Total C4D USD | AT2: Total contribution IC Cost - Share / COP | AU2: Total contribution IC Cost - Share / USD | AV2: Level of Effort (LOE) | AW2: Value of base salary COP | AX2: Value of base salary USD
A3: =+'Summary Budget'!E6 -> 1.Personal (Laboral) | G3: =SUM(G4:G21) -> 593328000 | H3: =SUM(H4:H21) -> 134793.66 | J3: =SUM(J4:J21) -> 78600000 | K3: =SUM(K4:K21) -> 17856.534 | L3: =+SUM(L4:L21) -> 671928000 | M3: =SUM(M4:M21) -> 152650.2 | T3: =+SUM(T4:T21) -> 652660800 | U3: =SUM(U4:U21) -> 148273.03 | W3: =+SUM(W4:W21) -> 86460000 | X3: =SUM(X4:X21) -> 19642.188 | Y3: =+SUM(Y4:Y21) -> 739120800 | Z3: =SUM(Z4:Z21) -> 167915.22 | AG3: =SUM(AG4:AG21) -> 172587888 | AH3: =SUM(AH4:AH21) -> 39208.926 | AJ3: =SUM(AJ4:AJ21) -> 22809600 | AK3: =SUM(AK4:AK21) -> 5181.939 | AL3: =+SUM(AL4:AL21) -> 195397488 | AM3: =SUM(AM4:AM21) -> 44390.865 | AP3: =+SUM(AP4:AP21) -> 1606446288 | AQ3: =SUM(AQ4:AQ21) -> 364956.28 | AR3: =+SUM(AR4:AR21) -> 1418576688 | AS3: =SUM(AS4:AS21) -> 322275.61 | AT3: =+SUM(AT4:AT21) -> 187869600 | AU3: =SUM(AU4:AU21) -> 42680.661
A4: =+'Summary Budget'!E7 -> 1.1. Program Coordinator | B4: month | C4: 12 | D4: =+AW4*AV4 -> 2000000 | E4: =+D4/$A$1 -> 454.36474 | F4: 0 | G4: =L4*F4 -> 0 | H4: =+G4/$A$1 -> 0 | I4: 1 | J4: =L4*I4 -> 24000000 | K4: =+J4/$A$1 -> 5452.3769 | L4: =+D4*C4 -> 24000000 | M4: =+L4/$A$1 -> 5452.3769 | O4: mes | P4: 12 | Q4: =+D4*(1+10%) -> 2200000 | R4: =+Q4/$A$1 -> 499.80122 | S4: 0 | T4: =+S4*Y4 -> 0 | U4: =+T4/$A$1 -> 0 | V4: 1 | W4: =+V4*Y4 -> 26400000 | X4: =+W4/$A$1 -> 5997.6146 | Y4: =+Q4*P4 -> 26400000 | Z4: =+Y4/$A$1 -> 5997.6146 | AB4: mes | AC4: 4 | AD4: =+Q4*(1+8%) -> 2376000 | AE4: =+AD4/$A$1 -> 539.78531 | AF4: 0 | AG4: =+AF4*AL4 -> 0 | AH4: =+AG4/$A$1 -> 0 | AI4: 1 | AJ4: =+AI4*AL4 -> 9504000 | AK4: =+AJ4/$A$1 -> 2159.1413 | AL4: =+AD4*AC4 -> 9504000 | AM4: =+AL4/$A$1 -> 2159.1413 | AO4: =+SUM(AC4+P4+C4) -> 28 | AP4: =+L4+Y4+AL4 -> 59904000 | AQ4: =+AP4/$A$1 -> 13609.133 | AR4: =+AP4*F4 -> 0 | AS4: =+AR4/$A$1 -> 0 | AT4: =+AP4*I4 -> 59904000 | AU4: =+AT4/$A$1 -> 13609.133 | AV4: 0.2 | AW4: 10000000 | AX4: =+AW4/$A$1 -> 2271.8237 | BA4: =+L4 -> 24000000 | BB4: =+Y4 -> 26400000 | BC4: =+AL4 -> 9504000 | BH4: =+AR4+AT4-AP4 -> 0
A5: =+'Summary Budget'!E8 -> 1.2. Business Strengthening Coordinator | B5: month | C5: 12 | D5: =+AW5*AV5 -> 4122000 | E5: =+D5/$A$1 -> 936.44573 | F5: 1 | G5: =L5*F5 -> 49464000 | H5: =+G5/$A$1 -> 11237.349 | I5: 0 | J5: =L5*I5 -> 0 | K5: =+J5/$A$1 -> 0 | L5: =+D5*C5*AV5 -> 49464000 | M5: =+L5/$A$1 -> 11237.349 | O5: mes | P5: 12 | Q5: =+D5*(1+10%) -> 4534200 | R5: =+Q5/$A$1 -> 1030.0903 | S5: 1 | T5: =+S5*Y5 -> 54410400 | U5: =+T5/$A$1 -> 12361.084 | V5: 0 | W5: =+V5*Y5 -> 0 | X5: =+W5/$A$1 -> 0 | Y5: =+Q5*P5 -> 54410400 | Z5: =+Y5/$A$1 -> 12361.084 | AB5: mes | AC5: 4 | AD5: =+Q5*(1+8%) -> 4896936 | AE5: =+AD5/$A$1 -> 1112.4975 | AF5: 1 | AG5: =+AF5*AL5 -> 19587744 | AH5: =+AG5/$A$1 -> 4449.9901 | AI5: 0 | AJ5: =+AI5*AL5 -> 0 | AK5: =+AJ5/$A$1 -> 0 | AL5: =+AD5*AC5 -> 19587744 | AM5: =+AL5/$A$1 -> 4449.9901 | AO5: =+SUM(AC5+P5+C5) -> 28 | AP5: =+L5+Y5+AL5 -> 123462144 | AQ5: =+AP5/$A$1 -> 28048.423 | AR5: =+AP5*F5 -> 123462144 | AS5: =+AR5/$A$1 -> 28048.423 | AT5: =+AP5*I5 -> 0 | AU5: =+AT5/$A$1 -> 0 | AV5: 1 | AW5: 4122000 | AX5: =+AW5/$A$1 -> 936.44573 | BH5: =+AR5+AT5-AP5 -> 0
A6: =+'Summary Budget'!E9 -> 1.3. Cacao technical specialist | B6: month | C6: 12 | D6: =+AW6*AV6 -> 4122000 | E6: =+D6/$A$1 -> 936.44573 | F6: 1 | G6: =L6*F6 -> 49464000 | H6: =+G6/$A$1 -> 11237.349 | I6: 0 | J6: =L6*I6 -> 0 | K6: =+J6/$A$1 -> 0 | L6: =+D6*C6*AV6 -> 49464000 | M6: =+L6/$A$1 -> 11237.349 | O6: mes | P6: 12 | Q6: =+D6*(1+10%) -> 4534200 | R6: =+Q6/$A$1 -> 1030.0903 | S6: 1 | T6: =+S6*Y6 -> 54410400 | U6: =+T6/$A$1 -> 12361.084 | V6: 0 | W6: =+V6*Y6 -> 0 | X6: =+W6/$A$1 -> 0 | Y6: =+Q6*P6 -> 54410400 | Z6: =+Y6/$A$1 -> 12361.084 | AB6: mes | AC6: 4 | AD6: =+Q6*(1+8%) -> 4896936 | AE6: =+AD6/$A$1 -> 1112.4975 | AF6: 1 | AG6: =+AF6*AL6 -> 19587744 | AH6: =+AG6/$A$1 -> 4449.9901 | AI6: 0 | AJ6: =+AI6*AL6 -> 0 | AK6: =+AJ6/$A$1 -> 0 | AL6: =+AD6*AC6 -> 19587744 | AM6: =+AL6/$A$1 -> 4449.9901 | AO6: =+SUM(AC6+P6+C6) -> 28 | AP6: =+L6+Y6+AL6 -> 123462144 | AQ6: =+AP6/$A$1 -> 28048.423 | AR6: =+AP6*F6 -> 123462144 | AS6: =+AR6/$A$1 -> 28048.423 | AT6: =+AP6*I6 -> 0 | AU6: =+AT6/$A$1 -> 0 | AV6: 1 | AW6: 4122000 | AX6: =+AW6/$A$1 -> 936.44573 | BH6: =+AR6+AT6-AP6 -> 0
A7: =+'Summary Budget'!E10 -> 1.4. Organizational Professional | B7: month | C7: 12 | D7: =+AW7*AV7 -> 3200000 | E7: =+D7/$A$1 -> 726.98359 | F7: 0.75 | G7: =L7*F7 -> 28800000 | H7: =+G7/$A$1 -> 6542.8523 | I7: 0.25 | J7: =L7*I7 -> 9600000 | K7: =+J7/$A$1 -> 2180.9508 | L7: =+D7*C7 -> 38400000 | M7: =+L7/$A$1 -> 8723.803 | O7: mes | P7: 12 | Q7: =+D7*(1+10%) -> 3520000 | R7: =+Q7/$A$1 -> 799.68194 | S7: 0.75 | T7: =+S7*Y7 -> 31680000 | U7: =+T7/$A$1 -> 7197.1375 | V7: 0.25 | W7: =+V7*Y7 -> 10560000 | X7: =+W7/$A$1 -> 2399.0458 | Y7: =+Q7*P7 -> 42240000 | Z7: =+Y7/$A$1 -> 9596.1833 | AB7: mes | AC7: 4 | AD7: =+Q7*(1+8%) -> 3801600 | AE7: =+AD7/$A$1 -> 863.6565 | AF7: 0.75 | AG7: =+AF7*AL7 -> 11404800 | AH7: =+AG7/$A$1 -> 2590.9695 | AI7: 0.25 | AJ7: =+AI7*AL7 -> 3801600 | AK7: =+AJ7/$A$1 -> 863.6565 | AL7: =+AD7*AC7 -> 15206400 | AM7: =+AL7/$A$1 -> 3454.626 | AO7: =+SUM(AC7+P7+C7) -> 28 | AP7: =+L7+Y7+AL7 -> 95846400 | AQ7: =+AP7/$A$1 -> 21774.612 | AR7: =+AP7*F7 -> 71884800 | AS7: =+AR7/$A$1 -> 16330.959 | AT7: =+AP7*I7 -> 23961600 | AU7: =+AT7/$A$1 -> 5443.6531 | AV7: 0.8 | AW7: 4000000 | AX7: =+AW7/$A$1 -> 908.72948 | BA7: =+L7*20/100 -> 7680000 | BB7: =+Y7*20/100 -> 8448000 | BC7: =+AL7*20/100 -> 3041280 | BH7: =+AR7+AT7-AP7 -> 0
A8: =+'Summary Budget'!E11 -> 1.5. F&A Specialist | B8: month | C8: 12 | D8: =+AW8*AV8 -> 1900000 | E8: =+D8/$A$1 -> 431.6465 | F8: 1 | G8: =L8*F8 -> 22800000 | H8: =+G8/$A$1 -> 5179.7581 | I8: 0 | J8: =L8*I8 -> 0 | K8: =+J8/$A$1 -> 0 | L8: =+D8*C8 -> 22800000 | M8: =+L8/$A$1 -> 5179.7581 | O8: mes | P8: 12 | Q8: =+D8*(1+10%) -> 2090000 | R8: =+Q8/$A$1 -> 474.81115 | S8: 1 | T8: =+S8*Y8 -> 25080000 | U8: =+T8/$A$1 -> 5697.7339 | V8: 0 | W8: =+V8*Y8 -> 0 | X8: =+W8/$A$1 -> 0 | Y8: =+Q8*P8 -> 25080000 | Z8: =+Y8/$A$1 -> 5697.7339 | AB8: mes | AC8: 4 | AD8: =+Q8*(1+8%) -> 2257200 | AE8: =+AD8/$A$1 -> 512.79605 | AF8: 1 | AG8: =+AF8*AL8 -> 9028800 | AH8: =+AG8/$A$1 -> 2051.1842 | AI8: 0 | AJ8: =+AI8*AL8 -> 0 | AK8: =+AJ8/$A$1 -> 0 | AL8: =+AD8*AC8 -> 9028800 | AM8: =+AL8/$A$1 -> 2051.1842 | AO8: =+SUM(AC8+P8+C8) -> 28 | AP8: =+L8+Y8+AL8 -> 56908800 | AQ8: =+AP8/$A$1 -> 12928.676 | AR8: =+AP8*F8 -> 56908800 | AS8: =+AR8/$A$1 -> 12928.676 | AT8: =+AP8*I8 -> 0 | AU8: =+AT8/$A$1 -> 0 | AV8: 0.5 | AW8: 3800000 | AX8: =+AW8/$A$1 -> 863.29301 | BH8: =+AR8+AT8-AP8 -> 0
A9: =+'Summary Budget'!E12 -> 1.6. Business Partner Professional Antioquia, Córdoba 1 | B9: month | C9: 12 | D9: =+AW9*AV9 -> 3500000 | E9: =+D9/$A$1 -> 795.1383 | F9: 1 | G9: =L9*F9 -> 42000000 | H9: =+G9/$A$1 -> 9541.6596 | I9: 0 | J9: =L9*I9 -> 0 | K9: =+J9/$A$1 -> 0 | L9: =+D9*C9 -> 42000000 | M9: =+L9/$A$1 -> 9541.6596 | O9: mes | P9: 12 | Q9: =+D9*(1+10%) -> 3850000 | R9: =+Q9/$A$1 -> 874.65213 | S9: 1 | T9: =+S9*Y9 -> 46200000 | U9: =+T9/$A$1 -> 10495.826 | V9: 0 | W9: =+V9*Y9 -> 0 | X9: =+W9/$A$1 -> 0 | Y9: =+Q9*P9 -> 46200000 | Z9: =+Y9/$A$1 -> 10495.826 | AB9: mes | AC9: 3 | AD9: =+Q9*(1+8%) -> 4158000 | AE9: =+AD9/$A$1 -> 944.6243 | AF9: 1 | AG9: =+AF9*AL9 -> 12474000 | AH9: =+AG9/$A$1 -> 2833.8729 | AI9: 0 | AJ9: =+AI9*AL9 -> 0 | AK9: =+AJ9/$A$1 -> 0 | AL9: =+AD9*AC9 -> 12474000 | AM9: =+AL9/$A$1 -> 2833.8729 | AO9: =+SUM(AC9+P9+C9) -> 27 | AP9: =+L9+Y9+AL9 -> 100674000 | AQ9: =+AP9/$A$1 -> 22871.358 | AR9: =+AP9*F9 -> 100674000 | AS9: =+AR9/$A$1 -> 22871.358 | AT9: =+AP9*I9 -> 0 | AU9: =+AT9/$A$1 -> 0 | AV9: 1 | AW9: 3500000 | AX9: =+AW9/$A$1 -> 795.1383 | BH9: =+AR9+AT9-AP9 -> 0
A10: =+'Summary Budget'!E13 -> 1.7. Business Partner Professional Antioquia, Córdoba 2 | B10: month | C10: 12 | D10: =+AW10*AV10 -> 3500000 | E10: =+D10/$A$1 -> 795.1383 | F10: 1 | G10: =L10*F10 -> 42000000 | H10: =+G10/$A$1 -> 9541.6596 | I10: 0 | J10: =L10*I10 -> 0 | K10: =+J10/$A$1 -> 0 | L10: =+D10*C10 -> 42000000 | M10: =+L10/$A$1 -> 9541.6596 | O10: mes | P10: 12 | Q10: =+D10*(1+10%) -> 3850000 | R10: =+Q10/$A$1 -> 874.65213 | S10: 1 | T10: =+S10*Y10 -> 46200000 | U10: =+T10/$A$1 -> 10495.826 | V10: 0 | W10: =+V10*Y10 -> 0 | X10: =+W10/$A$1 -> 0 | Y10: =+Q10*P10 -> 46200000 | Z10: =+Y10/$A$1 -> 10495.826 | AB10: mes | AC10: 0 | AD10: =+Q10*(1+8%) -> 4158000 | AE10: =+AD10/$A$1 -> 944.6243 | AF10: 1 | AG10: =+AF10*AL10 -> 0 | AH10: =+AG10/$A$1 -> 0 | AI10: 0 | AJ10: =+AI10*AL10 -> 0 | AK10: =+AJ10/$A$1 -> 0 | AL10: =+AD10*AC10 -> 0 | AM10: =+AL10/$A$1 -> 0 | AO10: =+SUM(AC10+P10+C10) -> 24 | AP10: =+L10+Y10+AL10 -> 88200000 | AQ10: =+AP10/$A$1 -> 20037.485 | AR10: =+AP10*F10 -> 88200000 | AS10: =+AR10/$A$1 -> 20037.485 | AT10: =+AP10*I10 -> 0 | AU10: =+AT10/$A$1 -> 0 | AV10: 1 | AW10: 3500000 | AX10: =+AW10/$A$1 -> 795.1383 | BH10: =+AR10+AT10-AP10 -> 0
A11: =+'Summary Budget'!E14 -> 1.8. Business Partner Professional Caldas | B11: month | C11: 12 | D11: =+AW11*AV11 -> 3500000 | E11: =+D11/$A$1 -> 795.1383 | F11: 1 | G11: =L11*F11 -> 42000000 | H11: =+G11/$A$1 -> 9541.6596 | I11: 0 | J11: =L11*I11 -> 0 | K11: =+J11/$A$1 -> 0 | L11: =+D11*C11 -> 42000000 | M11: =+L11/$A$1 -> 9541.6596 | O11: mes | P11: 12 | Q11: =+D11*(1+10%) -> 3850000 | R11: =+Q11/$A$1 -> 874.65213 | S11: 1 | T11: =+S11*Y11 -> 46200000 | U11: =+T11/$A$1 -> 10495.826 | V11: 0 | W11: =+V11*Y11 -> 0 | X11: =+W11/$A$1 -> 0 | Y11: =+Q11*P11 -> 46200000 | Z11: =+Y11/$A$1 -> 10495.826 | AB11: mes | AC11: 3 | AD11: =+Q11*(1+8%) -> 4158000 | AE11: =+AD11/$A$1 -> 944.6243 | AF11: 1 | AG11: =+AF11*AL11 -> 12474000 | AH11: =+AG11/$A$1 -> 2833.8729 | AI11: 0 | AJ11: =+AI11*AL11 -> 0 | AK11: =+AJ11/$A$1 -> 0 | AL11: =+AD11*AC11 -> 12474000 | AM11: =+AL11/$A$1 -> 2833.8729 | AO11: =+SUM(AC11+P11+C11) -> 27 | AP11: =+L11+Y11+AL11 -> 100674000 | AQ11: =+AP11/$A$1 -> 22871.358 | AR11: =+AP11*F11 -> 100674000 | AS11: =+AR11/$A$1 -> 22871.358 | AT11: =+AP11*I11 -> 0 | AU11: =+AT11/$A$1 -> 0 | AV11: 1 | AW11: 3500000 | AX11: =+AW11/$A$1 -> 795.1383 | BH11: =+AR11+AT11-AP11 -> 0
A12: =+'Summary Budget'!E15 -> 1.9. Business Partner Professional Guajira, Cesar, Magdalena | B12: month | C12: 12 | D12: =+AW12*AV12 -> 3500000 | E12: =+D12/$A$1 -> 795.1383 | F12: 1 | G12: =L12*F12 -> 42000000 | H12: =+G12/$A$1 -> 9541.6596 | I12: 0 | J12: =L12*I12 -> 0 | K12: =+J12/$A$1 -> 0 | L12: =+D12*C12 -> 42000000 | M12: =+L12/$A$1 -> 9541.6596 | O12: mes | P12: 12 | Q12: =+D12*(1+10%) -> 3850000 | R12: =+Q12/$A$1 -> 874.65213 | S12: 1 | T12: =+S12*Y12 -> 46200000 | U12: =+T12/$A$1 -> 10495.826 | V12: 0 | W12: =+V12*Y12 -> 0 | X12: =+W12/$A$1 -> 0 | Y12: =+Q12*P12 -> 46200000 | Z12: =+Y12/$A$1 -> 10495.826 | AB12: mes | AC12: 3 | AD12: =+Q12*(1+8%) -> 4158000 | AE12: =+AD12/$A$1 -> 944.6243 | AF12: 1 | AG12: =+AF12*AL12 -> 12474000 | AH12: =+AG12/$A$1 -> 2833.8729 | AI12: 0 | AJ12: =+AI12*AL12 -> 0 | AK12: =+AJ12/$A$1 -> 0 | AL12: =+AD12*AC12 -> 12474000 | AM12: =+AL12/$A$1 -> 2833.8729 | AO12: =+SUM(AC12+P12+C12) -> 27 | AP12: =+L12+Y12+AL12 -> 100674000 | AQ12: =+AP12/$A$1 -> 22871.358 | AR12: =+AP12*F12 -> 100674000 | AS12: =+AR12/$A$1 -> 22871.358 | AT12: =+AP12*I12 -> 0 | AU12: =+AT12/$A$1 -> 0 | AV12: 1 | AW12: 3500000 | AX12: =+AW12/$A$1 -> 795.1383 | BH12: =+AR12+AT12-AP12 -> 0
A13: =+'Summary Budget'!E16 -> 1.10. Business Partner Professional Huila | B13: month | C13: 12 | D13: =+AW13*AV13 -> 3500000 | E13: =+D13/$A$1 -> 795.1383 | F13: 1 | G13: =L13*F13 -> 42000000 | H13: =+G13/$A$1 -> 9541.6596 | I13: 0 | J13: =L13*I13 -> 0 | K13: =+J13/$A$1 -> 0 | L13: =+D13*C13 -> 42000000 | M13: =+L13/$A$1 -> 9541.6596 | O13: mes | P13: 12 | Q13: =+D13*(1+10%) -> 3850000 | R13: =+Q13/$A$1 -> 874.65213 | S13: 1 | T13: =+S13*Y13 -> 46200000 | U13: =+T13/$A$1 -> 10495.826 | V13: 0 | W13: =+V13*Y13 -> 0 | X13: =+W13/$A$1 -> 0 | Y13: =+Q13*P13 -> 46200000 | Z13: =+Y13/$A$1 -> 10495.826 | AB13: mes | AC13: 3 | AD13: =+Q13*(1+8%) -> 4158000 | AE13: =+AD13/$A$1 -> 944.6243 | AF13: 1 | AG13: =+AF13*AL13 -> 12474000 | AH13: =+AG13/$A$1 -> 2833.8729 | AI13: 0 | AJ13: =+AI13*AL13 -> 0 | AK13: =+AJ13/$A$1 -> 0 | AL13: =+AD13*AC13 -> 12474000 | AM13: =+AL13/$A$1 -> 2833.8729 | AO13: =+SUM(AC13+P13+C13) -> 27 | AP13: =+L13+Y13+AL13 -> 100674000 | AQ13: =+AP13/$A$1 -> 22871.358 | AR13: =+AP13*F13 -> 100674000 | AS13: =+AR13/$A$1 -> 22871.358 | AT13: =+AP13*I13 -> 0 | AU13: =+AT13/$A$1 -> 0 | AV13: 1 | AW13: 3500000 | AX13: =+AW13/$A$1 -> 795.1383 | BH13: =+AR13+AT13-AP13 -> 0
A14: =+'Summary Budget'!E17 -> 1.11. Business Partner Professional Santander and Bolivar | B14: month | C14: 12 | D14: =+AW14*AV14 -> 3500000 | E14: =+D14/$A$1 -> 795.1383 | F14: 1 | G14: =L14*F14 -> 42000000 | H14: =+G14/$A$1 -> 9541.6596 | I14: 0 | J14: =L14*I14 -> 0 | K14: =+J14/$A$1 -> 0 | L14: =+D14*C14 -> 42000000 | M14: =+L14/$A$1 -> 9541.6596 | O14: mes | P14: 12 | Q14: =+D14*(1+10%) -> 3850000 | R14: =+Q14/$A$1 -> 874.65213 | S14: 1 | T14: =+S14*Y14 -> 46200000 | U14: =+T14/$A$1 -> 10495.826 | V14: 0 | W14: =+V14*Y14 -> 0 | X14: =+W14/$A$1 -> 0 | Y14: =+Q14*P14 -> 46200000 | Z14: =+Y14/$A$1 -> 10495.826 | AB14: mes | AC14: 0 | AD14: =+Q14*(1+8%) -> 4158000 | AE14: =+AD14/$A$1 -> 944.6243 | AF14: 1 | AG14: =+AF14*AL14 -> 0 | AH14: =+AG14/$A$1 -> 0 | AI14: 0 | AJ14: =+AI14*AL14 -> 0 | AK14: =+AJ14/$A$1 -> 0 | AL14: =+AD14*AC14 -> 0 | AM14: =+AL14/$A$1 -> 0 | AO14: =+SUM(AC14+P14+C14) -> 24 | AP14: =+L14+Y14+AL14 -> 88200000 | AQ14: =+AP14/$A$1 -> 20037.485 | AR14: =+AP14*F14 -> 88200000 | AS14: =+AR14/$A$1 -> 20037.485 | AT14: =+AP14*I14 -> 0 | AU14: =+AT14/$A$1 -> 0 | AV14: 1 | AW14: 3500000 | AX14: =+AW14/$A$1 -> 795.1383 | BH14: =+AR14+AT14-AP14 -> 0
A15: =+'Summary Budget'!E18 -> 1.12. Business Partner Professional Cauca | B15: month | C15: 12 | D15: =+AW15*AV15 -> 3500000 | E15: =+D15/$A$1 -> 795.1383 | F15: 1 | G15: =L15*F15 -> 42000000 | H15: =+G15/$A$1 -> 9541.6596 | I15: 0 | J15: =L15*I15 -> 0 | K15: =+J15/$A$1 -> 0 | L15: =+D15*C15 -> 42000000 | M15: =+L15/$A$1 -> 9541.6596 | O15: mes | P15: 12 | Q15: =+D15*(1+10%) -> 3850000 | R15: =+Q15/$A$1 -> 874.65213 | S15: 1 | T15: =+S15*Y15 -> 46200000 | U15: =+T15/$A$1 -> 10495.826 | V15: 0 | W15: =+V15*Y15 -> 0 | X15: =+W15/$A$1 -> 0 | Y15: =+Q15*P15 -> 46200000 | Z15: =+Y15/$A$1 -> 10495.826 | AB15: mes | AC15: 3 | AD15: =+Q15*(1+8%) -> 4158000 | AE15: =+AD15/$A$1 -> 944.6243 | AF15: 1 | AG15: =+AF15*AL15 -> 12474000 | AH15: =+AG15/$A$1 -> 2833.8729 | AI15: 0 | AJ15: =+AI15*AL15 -> 0 | AK15: =+AJ15/$A$1 -> 0 | AL15: =+AD15*AC15 -> 12474000 | AM15: =+AL15/$A$1 -> 2833.8729 | AO15: =+SUM(AC15+P15+C15) -> 27 | AP15: =+L15+Y15+AL15 -> 100674000 | AQ15: =+AP15/$A$1 -> 22871.358 | AR15: =+AP15*F15 -> 100674000 | AS15: =+AR15/$A$1 -> 22871.358 | AT15: =+AP15*I15 -> 0 | AU15: =+AT15/$A$1 -> 0 | AV15: 1 | AW15: 3500000 | AX15: =+AW15/$A$1 -> 795.1383 | BH15: =+AR15+AT15-AP15 -> 0
A16: =+'Summary Budget'!E19 -> 1.13. Business Partner Professional Tolima 1 | B16: month | C16: 12 | D16: =+AW16*AV16 -> 3500000 | E16: =+D16/$A$1 -> 795.1383 | F16: 1 | G16: =L16*F16 -> 42000000 | H16: =+G16/$A$1 -> 9541.6596 | I16: 0 | J16: =L16*I16 -> 0 | K16: =+J16/$A$1 -> 0 | L16: =+D16*C16 -> 42000000 | M16: =+L16/$A$1 -> 9541.6596 | O16: mes | P16: 12 | Q16: =+D16*(1+10%) -> 3850000 | R16: =+Q16/$A$1 -> 874.65213 | S16: 1 | T16: =+S16*Y16 -> 46200000 | U16: =+T16/$A$1 -> 10495.826 | V16: 0 | W16: =+V16*Y16 -> 0 | X16: =+W16/$A$1 -> 0 | Y16: =+Q16*P16 -> 46200000 | Z16: =+Y16/$A$1 -> 10495.826 | AB16: mes | AC16: 3 | AD16: =+Q16*(1+8%) -> 4158000 | AE16: =+AD16/$A$1 -> 944.6243 | AF16: 1 | AG16: =+AF16*AL16 -> 12474000 | AH16: =+AG16/$A$1 -> 2833.8729 | AI16: 0 | AJ16: =+AI16*AL16 -> 0 | AK16: =+AJ16/$A$1 -> 0 | AL16: =+AD16*AC16 -> 12474000 | AM16: =+AL16/$A$1 -> 2833.8729 | AO16: =+SUM(AC16+P16+C16) -> 27 | AP16: =+L16+Y16+AL16 -> 100674000 | AQ16: =+AP16/$A$1 -> 22871.358 | AR16: =+AP16*F16 -> 100674000 | AS16: =+AR16/$A$1 -> 22871.358 | AT16: =+AP16*I16 -> 0 | AU16: =+AT16/$A$1 -> 0 | AV16: 1 | AW16: 3500000 | AX16: =+AW16/$A$1 -> 795.1383 | BH16: =+AR16+AT16-AP16 -> 0
A17: =+'Summary Budget'!E20 -> 1.14. Business Partner Professional Tolima 2 | B17: month | C17: 12 | D17: =+AW17*AV17 -> 3500000 | E17: =+D17/$A$1 -> 795.1383 | F17: 1 | G17: =L17*F17 -> 42000000 | H17: =+G17/$A$1 -> 9541.6596 | I17: 0 | J17: =L17*I17 -> 0 | K17: =+J17/$A$1 -> 0 | L17: =+D17*C17 -> 42000000 | M17: =+L17/$A$1 -> 9541.6596 | O17: mes | P17: 12 | Q17: =+D17*(1+10%) -> 3850000 | R17: =+Q17/$A$1 -> 874.65213 | S17: 1 | T17: =+S17*Y17 -> 46200000 | U17: =+T17/$A$1 -> 10495.826 | V17: 0 | W17: =+V17*Y17 -> 0 | X17: =+W17/$A$1 -> 0 | Y17: =+Q17*P17 -> 46200000 | Z17: =+Y17/$A$1 -> 10495.826 | AB17: mes | AC17: 3 | AD17: =+Q17*(1+8%) -> 4158000 | AE17: =+AD17/$A$1 -> 944.6243 | AF17: 1 | AG17: =+AF17*AL17 -> 12474000 | AH17: =+AG17/$A$1 -> 2833.8729 | AI17: 0 | AJ17: =+AI17*AL17 -> 0 | AK17: =+AJ17/$A$1 -> 0 | AL17: =+AD17*AC17 -> 12474000 | AM17: =+AL17/$A$1 -> 2833.8729 | AO17: =+SUM(AC17+P17+C17) -> 27 | AP17: =+L17+Y17+AL17 -> 100674000 | AQ17: =+AP17/$A$1 -> 22871.358 | AR17: =+AP17*F17 -> 100674000 | AS17: =+AR17/$A$1 -> 22871.358 | AT17: =+AP17*I17 -> 0 | AU17: =+AT17/$A$1 -> 0 | AV17: 1 | AW17: 3500000 | AX17: =+AW17/$A$1 -> 795.1383 | BH17: =+AR17+AT17-AP17 -> 0
A18: =+'Summary Budget'!E21 -> 1.15. Business Partner Professional Tolima 3 | B18: month | C18: 12 | D18: =+AW18*AV18 -> 1750000 | E18: =+D18/$A$1 -> 397.56915 | F18: 0 | G18: =L18*F18 -> 0 | H18: =+G18/$A$1 -> 0 | I18: 1 | J18: =L18*I18 -> 21000000 | K18: =+J18/$A$1 -> 4770.8298 | L18: =+D18*C18 -> 21000000 | M18: =+L18/$A$1 -> 4770.8298 | O18: mes | P18: 12 | Q18: =+D18*(1+10%) -> 1925000 | R18: =+Q18/$A$1 -> 437.32606 | S18: 0 | T18: =+S18*Y18 -> 0 | U18: =+T18/$A$1 -> 0 | V18: 1 | W18: =+V18*Y18 -> 23100000 | X18: =+W18/$A$1 -> 5247.9128 | Y18: =+Q18*P18 -> 23100000 | Z18: =+Y18/$A$1 -> 5247.9128 | AB18: mes | AC18: 0 | AD18: =+Q18*(1+8%) -> 2079000 | AE18: =+AD18/$A$1 -> 472.31215 | AF18: 0 | AG18: =+AF18*AL18 -> 0 | AH18: =+AG18/$A$1 -> 0 | AI18: 1 | AJ18: =+AI18*AL18 -> 0 | AK18: =+AJ18/$A$1 -> 0 | AL18: =+AD18*AC18 -> 0 | AM18: =+AL18/$A$1 -> 0 | AO18: =+SUM(AC18+P18+C18) -> 24 | AP18: =+L18+Y18+AL18 -> 44100000 | AQ18: =+AP18/$A$1 -> 10018.743 | AR18: =+AP18*F18 -> 0 | AS18: =+AR18/$A$1 -> 0 | AT18: =+AP18*I18 -> 44100000 | AU18: =+AT18/$A$1 -> 10018.743 | AV18: 0.5 | AW18: 3500000 | AX18: =+AW18/$A$1 -> 795.1383 | BH18: =+AR18+AT18-AP18 -> 0
A19: =+'Summary Budget'!E22 -> 1.16. Administrative Coordinator | B19: month | C19: 12 | D19: =+AW19*AV19 -> 2000000 | E19: =+D19/$A$1 -> 454.36474 | F19: 0 | G19: =L19*F19 -> 0 | H19: =+G19/$A$1 -> 0 | I19: 1 | J19: =L19*I19 -> 24000000 | K19: =+J19/$A$1 -> 5452.3769 | L19: =+D19*C19 -> 24000000 | M19: =+L19/$A$1 -> 5452.3769 | O19: mes | P19: 12 | Q19: =+D19*(1+10%) -> 2200000 | R19: =+Q19/$A$1 -> 499.80122 | S19: 0 | T19: =+S19*Y19 -> 0 | U19: =+T19/$A$1 -> 0 | V19: 1 | W19: =+V19*Y19 -> 26400000 | X19: =+W19/$A$1 -> 5997.6146 | Y19: =+Q19*P19 -> 26400000 | Z19: =+Y19/$A$1 -> 5997.6146 | AB19: mes | AC19: 4 | AD19: =+Q19*(1+8%) -> 2376000 | AE19: =+AD19/$A$1 -> 539.78531 | AF19: 0 | AG19: =+AF19*AL19 -> 0 | AH19: =+AG19/$A$1 -> 0 | AI19: 1 | AJ19: =+AI19*AL19 -> 9504000 | AK19: =+AJ19/$A$1 -> 2159.1413 | AL19: =+AD19*AC19 -> 9504000 | AM19: =+AL19/$A$1 -> 2159.1413 | AO19: =+SUM(AC19+P19+C19) -> 28 | AP19: =+L19+Y19+AL19 -> 59904000 | AQ19: =+AP19/$A$1 -> 13609.133 | AR19: =+AP19*F19 -> 0 | AS19: =+AR19/$A$1 -> 0 | AT19: =+AP19*I19 -> 59904000 | AU19: =+AT19/$A$1 -> 13609.133 | AV19: 0.25 | AW19: 8000000 | AX19: =+AW19/$A$1 -> 1817.459 | BH19: =+AR19+AT19-AP19 -> 0
... A21: =+'Summary Budget'!E24 -> 1.18. Administrative Assistant | B21: month | C21: 12 | D21: =+AW21*AV21 -> 2400000 | E21: =+D21/$A$1 -> 545.23769 | F21: 1 | G21: =L21*F21 -> 28800000 | H21: =+G21/$A$1 -> 6542.8523 | I21: 0 | J21: =L21*I21 -> 0 | K21: =+J21/$A$1 -> 0 | L21: =+D21*C21 -> 28800000 | M21: =+L21/$A$1 -> 6542.8523 | O21: mes | P21: 12 | Q21: =+D21*(1+10%) -> 2640000 | R21: =+Q21/$A$1 -> 599.76146 | S21: 1 | T21: =+S21*Y21 -> 31680000 | U21: =+T21/$A$1 -> 7197.1375 | V21: 0 | W21: =+V21*Y21 -> 0 | X21: =+W21/$A$1 -> 0 | Y21: =+Q21*P21 -> 31680000 | Z21: =+Y21/$A$1 -> 7197.1375 | AB21: mes | AC21: 4 | AD21: =+Q21*(1+8%) -> 2851200 | AE21: =+AD21/$A$1 -> 647.74238 | AF21: 1 | AG21: =+AF21*AL21 -> 11404800 | AH21: =+AG21/$A$1 -> 2590.9695 | AI21: 0 | AJ21: =+AI21*AL21 -> 0 | AK21: =+AJ21/$A$1 -> 0 | AL21: =+AD21*AC21 -> 11404800 | AM21: =+AL21/$A$1 -> 2590.9695 | AO21: =+SUM(AC21+P21+C21) -> 28 | AP21: =+L21+Y21+AL21 -> 71884800 | AQ21: =+AP21/$A$1 -> 16330.959 | AR21: =+AP21*F21 -> 71884800 | AS21: =+AR21/$A$1 -> 16330.959 | AT21: =+AP21*I21 -> 0 | AU21: =+AT21/$A$1 -> 0 | AV21: 1 | AW21: 2400000 | AX21: =+AW21/$A$1 -> 545.23769 | BH21: =+AR21+AT21-AP21 -> 0
A22: =+'Summary Budget'!E25 -> 2. Fringe benefits | C22: 0.5829 | G22: =SUM(G23:G40) -> 3.4167777e+08 | H22: =SUM(H23:H40) -> 77623.166 | J22: =SUM(J23:J40) -> 44270340 | K22: =SUM(K23:K40) -> 10057.441 | L22: =+SUM(L23:L40) -> 3.8594811e+08 | M22: =SUM(M23:M40) -> 87680.607 | P22: 0.5829 | T22: =SUM(T23:T40) -> 3.7584555e+08 | U22: =SUM(U23:U40) -> 85385.483 | W22: =SUM(W23:W40) -> 48697374 | X22: =SUM(X23:X40) -> 11063.185 | Y22: =+SUM(Y23:Y40) -> 4.2454292e+08 | Z22: =SUM(Z23:Z40) -> 96448.668 | AC22: 0.5829 | AG22: =SUM(AG23:AG40) -> 98948924 | AH22: =SUM(AH23:AH40) -> 22479.451 | AJ22: =SUM(AJ23:AJ40) -> 12683658 | AK22: =SUM(AK23:AK40) -> 2881.5035 | AL22: =+SUM(AL23:AL40) -> 1.1163258e+08 | AM22: =SUM(AM23:AM40) -> 25360.955 | AP22: =+SUM(AP23:AP40) -> 9.2212362e+08 | AQ22: =SUM(AQ23:AQ40) -> 209490.23 | AR22: =+SUM(AR23:AR40) -> 8.1647224e+08 | AS22: =SUM(AS23:AS40) -> 185488.1 | AT22: =+SUM(AT23:AT40) -> 1.0565137e+08 | AU22: =SUM(AU23:AU40) -> 24002.129 | AV22: LOE (%) | AW22: Fringe benefits (%)
A23: =+A4 -> 1.1. Program Coordinator | B23: month | C23: =+C4 -> 12 | D23: =+D4*AW23 -> 1165800 | E23: =+D23/$A$1 -> 264.84921 | F23: =+F4 -> 0 | G23: =L23*F23 -> 0 | H23: =+G23/$A$1 -> 0 | I23: 1 | J23: =L23*I23 -> 13989600 | K23: =+J23/$A$1 -> 3178.1905 | L23: =+D23*C23 -> 13989600 | M23: =+L23/$A$1 -> 3178.1905 | O23: mes | P23: =+P4 -> 12 | Q23: =+Q4*AW23 -> 1282380 | R23: =+Q23/$A$1 -> 291.33413 | S23: =+S4 -> 0 | T23: =+S23*Y23 -> 0 | U23: =+T23/$A$1 -> 0 | V23: 1 | W23: =+V23*Y23 -> 15388560 | X23: =+W23/$A$1 -> 3496.0095 | Y23: =+Q23*P23 -> 15388560 | Z23: =+Y23/$A$1 -> 3496.0095 | AB23: mes | AC23: =+AC4 -> 4 | AD23: =+AD4*AW23 -> 1384970.4 | AE23: =+AD23/$A$1 -> 314.64086 | AF23: =+AF4 -> 0 | AG23: =+AF23*AL23 -> 0 | AH23: =+AG23/$A$1 -> 0 | AI23: 1 | AJ23: =+AI23*AL23 -> 5539881.6 | AK23: =+AJ23/$A$1 -> 1258.5634 | AL23: =+AD23*AC23 -> 5539881.6 | AM23: =+AL23/$A$1 -> 1258.5634 | AO23: =+AO4 -> 28 | AP23: =+L23+Y23+AL23 -> 34918042 | AQ23: =+AP23/$A$1 -> 7932.7635 | AR23: =+AP23*F23 -> 0 | AS23: =+AR23/$A$1 -> 0 | AT23: =+AP23*I23 -> 34918042 | AU23: =+AT23/$A$1 -> 7932.7635 | AV23: =+AV4 -> 0.2 | AW23: 0.5829 | BH23: =+AR23+AT23-AP23 -> 0
A24: =+A5 -> 1.2. Business Strengthening Coordinator | B24: month | C24: =+C5 -> 12 | D24: =+D5*AW24 -> 2402713.8 | E24: =+D24/$A$1 -> 545.85422 | F24: =+F5 -> 1 | G24: =L24*F24 -> 28832566 | H24: =+G24/$A$1 -> 6550.2506 | I24: 0 | J24: =L24*I24 -> 0 | K24: =+J24/$A$1 -> 0 | L24: =+D24*C24 -> 28832566 | M24: =+L24/$A$1 -> 6550.2506 | O24: mes | P24: =+P5 -> 12 | Q24: =+Q5*AW24 -> 2642985.2 | R24: =+Q24/$A$1 -> 600.43964 | S24: =+S5 -> 1 | T24: =+S24*Y24 -> 31715822 | U24: =+T24/$A$1 -> 7205.2757 | V24: 0 | W24: =+V24*Y24 -> 0 | X24: =+W24/$A$1 -> 0 | Y24: =+Q24*P24 -> 31715822 | Z24: =+Y24/$A$1 -> 7205.2757 | AB24: mes | AC24: =+AC5 -> 4 | AD24: =+AD5*AW24 -> 2854424 | AE24: =+AD24/$A$1 -> 648.47481 | AF24: =+AF5 -> 1 | AG24: =+AF24*AL24 -> 11417696 | AH24: =+AG24/$A$1 -> 2593.8992 | AI24: 0 | AJ24: =+AI24*AL24 -> 0 | AK24: =+AJ24/$A$1 -> 0 | AL24: =+AD24*AC24 -> 11417696 | AM24: =+AL24/$A$1 -> 2593.8992 | AO24: =+AO5 -> 28 | AP24: =+L24+Y24+AL24 -> 71966084 | AQ24: =+AP24/$A$1 -> 16349.426 | AR24: =+AP24*F24 -> 71966084 | AS24: =+AR24/$A$1 -> 16349.426 | AT24: =+AP24*I24 -> 0 | AU24: =+AT24/$A$1 -> 0 | AV24: =+AV5 -> 1 | AW24: 0.5829 | BH24: =+AR24+AT24-AP24 -> 0
A25: =+A6 -> 1.3. Cacao technical specialist | B25: month | C25: =+C6 -> 12 | D25: =+D6*AW25 -> 2402713.8 | E25: =+D25/$A$1 -> 545.85422 | F25: =+F6 -> 1 | G25: =L25*F25 -> 28832566 | H25: =+G25/$A$1 -> 6550.2506 | I25: 0 | J25: =L25*I25 -> 0 | K25: =+J25/$A$1 -> 0 | L25: =+D25*C25 -> 28832566 | M25: =+L25/$A$1 -> 6550.2506 | O25: mes | P25: =+P6 -> 12 | Q25: =+Q6*AW25 -> 2642985.2 | R25: =+Q25/$A$1 -> 600.43964 | S25: =+S6 -> 1 | T25: =+S25*Y25 -> 31715822 | U25: =+T25/$A$1 -> 7205.2757 | V25: 0 | W25: =+V25*Y25 -> 0 | X25: =+W25/$A$1 -> 0 | Y25: =+Q25*P25 -> 31715822 | Z25: =+Y25/$A$1 -> 7205.2757 | AB25: mes | AC25: =+AC6 -> 4 | AD25: =+AD6*AW25 -> 2854424 | AE25: =+AD25/$A$1 -> 648.47481 | AF25: =+AF6 -> 1 | AG25: =+AF25*AL25 -> 11417696 | AH25: =+AG25/$A$1 -> 2593.8992 | AI25: 0 | AJ25: =+AI25*AL25 -> 0 | AK25: =+AJ25/$A$1 -> 0 | AL25: =+AD25*AC25 -> 11417696 | AM25: =+AL25/$A$1 -> 2593.8992 | AO25: =+AO6 -> 28 | AP25: =+L25+Y25+AL25 -> 71966084 | AQ25: =+AP25/$A$1 -> 16349.426 | AR25: =+AP25*F25 -> 71966084 | AS25: =+AR25/$A$1 -> 16349.426 | AT25: =+AP25*I25 -> 0 | AU25: =+AT25/$A$1 -> 0 | AV25: =+AV6 -> 1 | AW25: 0.5829 | BH25: =+AR25+AT25-AP25 -> 0
A26: =+A7 -> 1.4. Organizational Professional | B26: month | C26: =+C7 -> 12 | D26: =+D7*AW26 -> 1865280 | E26: =+D26/$A$1 -> 423.75873 | F26: =+F7 -> 0.75 | G26: =L26*F26 -> 16787520 | H26: =+G26/$A$1 -> 3813.8286 | I26: 0.25 | J26: =L26*I26 -> 5595840 | K26: =+J26/$A$1 -> 1271.2762 | L26: =+D26*C26 -> 22383360 | M26: =+L26/$A$1 -> 5085.1048 | O26: mes | P26: =+P7 -> 12 | Q26: =+Q7*AW26 -> 2051808 | R26: =+Q26/$A$1 -> 466.13461 | S26: =+S7 -> 0.75 | T26: =+S26*Y26 -> 18466272 | U26: =+T26/$A$1 -> 4195.2114 | V26: 0.25 | W26: =+V26*Y26 -> 6155424 | X26: =+W26/$A$1 -> 1398.4038 | Y26: =+Q26*P26 -> 24621696 | Z26: =+Y26/$A$1 -> 5593.6153 | AB26: mes | AC26: =+AC7 -> 4 | AD26: =+AD7*AW26 -> 2215952.6 | AE26: =+AD26/$A$1 -> 503.42537 | AF26: =+AF7 -> 0.75 | AG26: =+AF26*AL26 -> 6647857.9 | AH26: =+AG26/$A$1 -> 1510.2761 | AI26: 0.25 | AJ26: =+AI26*AL26 -> 2215952.6 | AK26: =+AJ26/$A$1 -> 503.42537 | AL26: =+AD26*AC26 -> 8863810.6 | AM26: =+AL26/$A$1 -> 2013.7015 | AO26: =+AO7 -> 28 | AP26: =+L26+Y26+AL26 -> 55868867 | AQ26: =+AP26/$A$1 -> 12692.422 | AR26: =+AP26*F26 -> 41901650 | AS26: =+AR26/$A$1 -> 9519.3162 | AT26: =+AP26*I26 -> 13967217 | AU26: =+AT26/$A$1 -> 3173.1054 | AV26: =+AV7 -> 0.8 | AW26: 0.5829 | BH26: =+AR26+AT26-AP26 -> 0
A27: =+A8 -> 1.5. F&A Specialist | B27: month | C27: =+C8 -> 12 | D27: =+D8*AW27 -> 1107510 | E27: =+D27/$A$1 -> 251.60675 | F27: =+F8 -> 1 | G27: =L27*F27 -> 13290120 | H27: =+G27/$A$1 -> 3019.281 | I27: 0 | J27: =L27*I27 -> 0 | K27: =+J27/$A$1 -> 0 | L27: =+D27*C27 -> 13290120 | M27: =+L27/$A$1 -> 3019.281 | O27: mes | P27: =+P8 -> 12 | Q27: =+Q8*AW27 -> 1218261 | R27: =+Q27/$A$1 -> 276.76742 | S27: =+S8 -> 1 | T27: =+S27*Y27 -> 14619132 | U27: =+T27/$A$1 -> 3321.2091 | V27: 0 | W27: =+V27*Y27 -> 0 | X27: =+W27/$A$1 -> 0 | Y27: =+Q27*P27 -> 14619132 | Z27: =+Y27/$A$1 -> 3321.2091 | AB27: mes | AC27: =+AC8 -> 4 | AD27: =+AD8*AW27 -> 1315721.9 | AE27: =+AD27/$A$1 -> 298.90882 | AF27: =+AF8 -> 1 | AG27: =+AF27*AL27 -> 5262887.5 | AH27: =+AG27/$A$1 -> 1195.6353 | AI27: 0 | AJ27: =+AI27*AL27 -> 0 | AK27: =+AJ27/$A$1 -> 0 | AL27: =+AD27*AC27 -> 5262887.5 | AM27: =+AL27/$A$1 -> 1195.6353 | AO27: =+AO8 -> 28 | AP27: =+L27+Y27+AL27 -> 33172140 | AQ27: =+AP27/$A$1 -> 7536.1253 | AR27: =+AP27*F27 -> 33172140 | AS27: =+AR27/$A$1 -> 7536.1253 | AT27: =+AP27*I27 -> 0 | AU27: =+AT27/$A$1 -> 0 | AV27: =+AV8 -> 0.5 | AW27: 0.5829 | BH27: =+AR27+AT27-AP27 -> 0
A28: =+A9 -> 1.6. Business Partner Professional Antioquia, Córdoba 1 | B28: month | C28: =+C9 -> 12 | D28: =+D9*AW28 -> 2040150 | E28: =+D28/$A$1 -> 463.48611 | F28: =+F9 -> 1 | G28: =L28*F28 -> 24481800 | H28: =+G28/$A$1 -> 5561.8334 | I28: 0 | J28: =L28*I28 -> 0 | K28: =+J28/$A$1 -> 0 | L28: =+D28*C28 -> 24481800 | M28: =+L28/$A$1 -> 5561.8334 | O28: mes | P28: =+P9 -> 12 | Q28: =+Q9*AW28 -> 2244165 | R28: =+Q28/$A$1 -> 509.83472 | S28: =+S9 -> 1 | T28: =+S28*Y28 -> 26929980 | U28: =+T28/$A$1 -> 6118.0167 | V28: 0 | W28: =+V28*Y28 -> 0 | X28: =+W28/$A$1 -> 0 | Y28: =+Q28*P28 -> 26929980 | Z28: =+Y28/$A$1 -> 6118.0167 | AB28: mes | AC28: =+AC9 -> 3 | AD28: =+AD9*AW28 -> 2423698.2 | AE28: =+AD28/$A$1 -> 550.6215 | AF28: =+AF9 -> 1 | AG28: =+AF28*AL28 -> 7271094.6 | AH28: =+AG28/$A$1 -> 1651.8645 | AI28: 0 | AJ28: =+AI28*AL28 -> 0 | AK28: =+AJ28/$A$1 -> 0 | AL28: =+AD28*AC28 -> 7271094.6 | AM28: =+AL28/$A$1 -> 1651.8645 | AO28: =+AO9 -> 27 | AP28: =+L28+Y28+AL28 -> 58682875 | AQ28: =+AP28/$A$1 -> 13331.715 | AR28: =+AP28*F28 -> 58682875 | AS28: =+AR28/$A$1 -> 13331.715 | AT28: =+AP28*I28 -> 0 | AU28: =+AT28/$A$1 -> 0 | AV28: =+AV9 -> 1 | AW28: 0.5829 | BH28: =+AR28+AT28-AP28 -> 0
A29: =+A10 -> 1.7. Business Partner Professional Antioquia, Córdoba 2 | B29: month | C29: =+C10 -> 12 | D29: =+D10*AW29 -> 2040150 | E29: =+D29/$A$1 -> 463.48611 | F29: =+F10 -> 1 | G29: =L29*F29 -> 24481800 | H29: =+G29/$A$1 -> 5561.8334 | I29: 0 | J29: =L29*I29 -> 0 | K29: =+J29/$A$1 -> 0 | L29: =+D29*C29 -> 24481800 | M29: =+L29/$A$1 -> 5561.8334 | O29: mes | P29: =+P10 -> 12 | Q29: =+Q10*AW29 -> 2244165 | R29: =+Q29/$A$1 -> 509.83472 | S29: =+S10 -> 1 | T29: =+S29*Y29 -> 26929980 | U29: =+T29/$A$1 -> 6118.0167 | V29: 0 | W29: =+V29*Y29 -> 0 | X29: =+W29/$A$1 -> 0 | Y29: =+Q29*P29 -> 26929980 | Z29: =+Y29/$A$1 -> 6118.0167 | AB29: mes | AC29: =+AC10 -> 0 | AD29: =+AD10*AW29 -> 2423698.2 | AE29: =+AD29/$A$1 -> 550.6215 | AF29: =+AF10 -> 1 | AG29: =+AF29*AL29 -> 0 | AH29: =+AG29/$A$1 -> 0 | AI29: 0 | AJ29: =+AI29*AL29 -> 0 | AK29: =+AJ29/$A$1 -> 0 | AL29: =+AD29*AC29 -> 0 | AM29: =+AL29/$A$1 -> 0 | AO29: =+AO10 -> 24 | AP29: =+L29+Y29+AL29 -> 51411780 | AQ29: =+AP29/$A$1 -> 11679.85 | AR29: =+AP29*F29 -> 51411780 | AS29: =+AR29/$A$1 -> 11679.85 | AT29: =+AP29*I29 -> 0 | AU29: =+AT29/$A$1 -> 0 | AV29: =+AV10 -> 1 | AW29: 0.5829 | BH29: =+AR29+AT29-AP29 -> 0
A30: =+A11 -> 1.8. Business Partner Professional Caldas | B30: month | C30: =+C11 -> 12 | D30: =+D11*AW30 -> 2040150 | E30: =+D30/$A$1 -> 463.48611 | F30: =+F11 -> 1 | G30: =L30*F30 -> 24481800 | H30: =+G30/$A$1 -> 5561.8334 | I30: 0 | J30: =L30*I30 -> 0 | K30: =+J30/$A$1 -> 0 | L30: =+D30*C30 -> 24481800 | M30: =+L30/$A$1 -> 5561.8334 | O30: mes | P30: =+P11 -> 12 | Q30: =+Q11*AW30 -> 2244165 | R30: =+Q30/$A$1 -> 509.83472 | S30: =+S11 -> 1 | T30: =+S30*Y30 -> 26929980 | U30: =+T30/$A$1 -> 6118.0167 | V30: 0 | W30: =+V30*Y30 -> 0 | X30: =+W30/$A$1 -> 0 | Y30: =+Q30*P30 -> 26929980 | Z30: =+Y30/$A$1 -> 6118.0167 | AB30: mes | AC30: =+AC11 -> 3 | AD30: =+AD11*AW30 -> 2423698.2 | AE30: =+AD30/$A$1 -> 550.6215 | AF30: =+AF11 -> 1 | AG30: =+AF30*AL30 -> 7271094.6 | AH30: =+AG30/$A$1 -> 1651.8645 | AI30: 0 | AJ30: =+AI30*AL30 -> 0 | AK30: =+AJ30/$A$1 -> 0 | AL30: =+AD30*AC30 -> 7271094.6 | AM30: =+AL30/$A$1 -> 1651.8645 | AO30: =+AO11 -> 27 | AP30: =+L30+Y30+AL30 -> 58682875 | AQ30: =+AP30/$A$1 -> 13331.715 | AR30: =+AP30*F30 -> 58682875 | AS30: =+AR30/$A$1 -> 13331.715 | AT30: =+AP30*I30 -> 0 | AU30: =+AT30/$A$1 -> 0 | AV30: =+AV11 -> 1 | AW30: 0.5829 | BH30: =+AR30+AT30-AP30 -> 0
A31: =+A12 -> 1.9. Business Partner Professional Guajira, Cesar, Magdalena | B31: month | C31: =+C12 -> 12 | D31: =+D12*AW31 -> 2040150 | E31: =+D31/$A$1 -> 463.48611 | F31: =+F12 -> 1 | G31: =L31*F31 -> 24481800 | H31: =+G31/$A$1 -> 5561.8334 | I31: 0 | J31: =L31*I31 -> 0 | K31: =+J31/$A$1 -> 0 | L31: =+D31*C31 -> 24481800 | M31: =+L31/$A$1 -> 5561.8334 | O31: mes | P31: =+P12 -> 12 | Q31: =+Q12*AW31 -> 2244165 | R31: =+Q31/$A$1 -> 509.83472 | S31: =+S12 -> 1 | T31: =+S31*Y31 -> 26929980 | U31: =+T31/$A$1 -> 6118.0167 | V31: 0 | W31: =+V31*Y31 -> 0 | X31: =+W31/$A$1 -> 0 | Y31: =+Q31*P31 -> 26929980 | Z31: =+Y31/$A$1 -> 6118.0167 | AB31: mes | AC31: =+AC12 -> 3 | AD31: =+AD12*AW31 -> 2423698.2 | AE31: =+AD31/$A$1 -> 550.6215 | AF31: =+AF12 -> 1 | AG31: =+AF31*AL31 -> 7271094.6 | AH31: =+AG31/$A$1 -> 1651.8645 | AI31: 0 | AJ31: =+AI31*AL31 -> 0 | AK31: =+AJ31/$A$1 -> 0 | AL31: =+AD31*AC31 -> 7271094.6 | AM31: =+AL31/$A$1 -> 1651.8645 | AO31: =+AO12 -> 27 | AP31: =+L31+Y31+AL31 -> 58682875 | AQ31: =+AP31/$A$1 -> 13331.715 | AR31: =+AP31*F31 -> 58682875 | AS31: =+AR31/$A$1 -> 13331.715 | AT31: =+AP31*I31 -> 0 | AU31: =+AT31/$A$1 -> 0 | AV31: =+AV12 -> 1 | AW31: 0.5829 | BH31: =+AR31+AT31-AP31 -> 0
A32: =+A13 -> 1.10. Business Partner Professional Huila | B32: month | C32: =+C13 -> 12 | D32: =+D13*AW32 -> 2040150 | E32: =+D32/$A$1 -> 463.48611 | F32: =+F13 -> 1 | G32: =L32*F32 -> 24481800 | H32: =+G32/$A$1 -> 5561.8334 | I32: 0 | J32: =L32*I32 -> 0 | K32: =+J32/$A$1 -> 0 | L32: =+D32*C32 -> 24481800 | M32: =+L32/$A$1 -> 5561.8334 | O32: mes | P32: =+P13 -> 12 | Q32: =+Q13*AW32 -> 2244165 | R32: =+Q32/$A$1 -> 509.83472 | S32: =+S13 -> 1 | T32: =+S32*Y32 -> 26929980 | U32: =+T32/$A$1 -> 6118.0167 | V32: 0 | W32: =+V32*Y32 -> 0 | X32: =+W32/$A$1 -> 0 | Y32: =+Q32*P32 -> 26929980 | Z32: =+Y32/$A$1 -> 6118.0167 | AB32: mes | AC32: =+AC13 -> 3 | AD32: =+AD13*AW32 -> 2423698.2 | AE32: =+AD32/$A$1 -> 550.6215 | AF32: =+AF13 -> 1 | AG32: =+AF32*AL32 -> 7271094.6 | AH32: =+AG32/$A$1 -> 1651.8645 | AI32: 0 | AJ32: =+AI32*AL32 -> 0 | AK32: =+AJ32/$A$1 -> 0 | AL32: =+AD32*AC32 -> 7271094.6 | AM32: =+AL32/$A$1 -> 1651.8645 | AO32: =+AO13 -> 27 | AP32: =+L32+Y32+AL32 -> 58682875 | AQ32: =+AP32/$A$1 -> 13331.715 | AR32: =+AP32*F32 -> 58682875 | AS32: =+AR32/$A$1 -> 13331.715 | AT32: =+AP32*I32 -> 0 | AU32: =+AT32/$A$1 -> 0 | AV32: =+AV13 -> 1 | AW32: 0.5829 | BH32: =+AR32+AT32-AP32 -> 0
A33: =+A14 -> 1.11. Business Partner Professional Santander and Bolivar | B33: month | C33: =+C14 -> 12 | D33: =+D14*AW33 -> 2040150 | E33: =+D33/$A$1 -> 463.48611 | F33: =+F14 -> 1 | G33: =L33*F33 -> 24481800 | H33: =+G33/$A$1 -> 5561.8334 | I33: 0 | J33: =L33*I33 -> 0 | K33: =+J33/$A$1 -> 0 | L33: =+D33*C33 -> 24481800 | M33: =+L33/$A$1 -> 5561.8334 | O33: mes | P33: =+P14 -> 12 | Q33: =+Q14*AW33 -> 2244165 | R33: =+Q33/$A$1 -> 509.83472 | S33: =+S14 -> 1 | T33: =+S33*Y33 -> 26929980 | U33: =+T33/$A$1 -> 6118.0167 | V33: 0 | W33: =+V33*Y33 -> 0 | X33: =+W33/$A$1 -> 0 | Y33: =+Q33*P33 -> 26929980 | Z33: =+Y33/$A$1 -> 6118.0167 | AB33: mes | AC33: =+AC14 -> 0 | AD33: =+AD14*AW33 -> 2423698.2 | AE33: =+AD33/$A$1 -> 550.6215 | AF33: =+AF14 -> 1 | AG33: =+AF33*AL33 -> 0 | AH33: =+AG33/$A$1 -> 0 | AI33: 0 | AJ33: =+AI33*AL33 -> 0 | AK33: =+AJ33/$A$1 -> 0 | AL33: =+AD33*AC33 -> 0 | AM33: =+AL33/$A$1 -> 0 | AO33: =+AO14 -> 24 | AP33: =+L33+Y33+AL33 -> 51411780 | AQ33: =+AP33/$A$1 -> 11679.85 | AR33: =+AP33*F33 -> 51411780 | AS33: =+AR33/$A$1 -> 11679.85 | AT33: =+AP33*I33 -> 0 | AU33: =+AT33/$A$1 -> 0 | AV33: =+AV14 -> 1 | AW33: 0.5829 | BH33: =+AR33+AT33-AP33 -> 0
