Workbook

Sheet 2. Summary Budget
A1: Summary Cost Amendment Budget
A2: Partners of the Americas
A3: AGFUND100
A4: 4 Months (October 1, 2025 - January 31, 2026)
D6: Budget
A8: A | C8: Personnel | D8: ='3. Detailed Budget'!J9 -> 0
A9: B | C9: Fringe Benefits | D9: ='3. Detailed Budget'!J12 -> 0
A10: C | C10: Travel | D10: ='3. Detailed Budget'!J21 -> 7797
A11: D | C11: Equipment | D11: ='3. Detailed Budget'!J22 -> 0
A12: E | C12: Supplies | D12: ='3. Detailed Budget'!J25 -> 0
A13: F | C13: Contractual | D13: ='3. Detailed Budget'!J32 -> 61920.008
A14: G | C14: Construction | D14: ='3. Detailed Budget'!J33 -> 0
A15: H | C15: Other Direct Costs | D15: ='3. Detailed Budget'!J40 -> 17240
A16: I | C16: Total Direct charges | D16: =SUM(D8:D15) -> 86957.008
A17: J | C17: Total Indirect costs | D17: ='3. Detailed Budget'!J42 -> 13043
A18: K | C18: Total Project Cost | D18: =SUM(D16:D17) -> 100000.01

Sheet 3. Detailed Budget
C1: Partners of the Americas | H1: Project Title
A2: Grant: AGFUND100 | F2: AGFUND100
C3: 4 Months (October 1, 2025 - January 31, 2026) | H3: Project duration
F4: Unit Cost | J4: Budget
F5: Unit | G5: Number | H5: Amount | I5: Rate
C6: A | E6: Personnel | F6: months or years | H6: salary (monthly) | I6: % effort for Personnel ONLY
C7: A.1 | E7: US-Based personnel
C8: A.1.1 | E8: Senior Director | F8: months | G8: 0 | H8: =145000/12 -> 12083.333 | I8: 0.1 | J8: =I8*H8*G8 -> 0
C9: Subtotal Personnel | J9: =SUM(J8:J8) -> 0
C10: B | E10: Fringe Benefits
C11: B.1 | E11: US-Based Personnel Fringe Benefits | I11: 0.2347 | J11: =I11*J9 -> 0
C12: Subtotal Fringe Benefits | J12: =SUM(J11) -> 0
C13: C | E13: Travel | F13: # trips | G13: # trips/or days | H13: unit Cost
C14: C.1 | E14: Staff Travel
A15: STFTRAVEL | B15: 86050 | C15: C.1.1 | E15: Domestic M&IE | F15: =4*2 -> 8 | G15: 4 | H15: =35*50% -> 17.5 | I15: 1 | J15: =I15*H15*G15*F15 -> 560
A16: STFTRVCTS | B16: 86030 | C16: C.1.2 | E16: Domestic Lodging | F16: =4*2 -> 8 | G16: 3 | H16: 63 | I16: 1 | J16: =I16*H16*G16*F16 -> 1512
A17: STFTRVCTS | B17: 86000 | C17: C.1.3 | E17: Domestic Local Transportation (Fuel/Maintenance) | F17: =4*2 -> 8 | G17: =G15 -> 4 | H17: 50 | I17: 1 | J17: =I17*H17*G17*F17 -> 1600
A18: LOCAL TRVL | B18: 86000 | C18: C.1.4 | E18: Rental Car for Trips | F18: 4 | G18: 4 | H18: 150 | I18: 1 | J18: =I18*H18*G18*F18 -> 2400
C19: C.2 | E19: Travel for Crop Insurance Expert
A20: FLIGHT | B20: 86040 | C20: C.2.1 | E20: Flight for Crop Insurance Expert (Rwanda to NKC) | F20: 1 | G20: 1 | H20: 1725 | I20: 1 | J20: =I20*H20*G20*F20 -> 1725
C21: Subtotal Travel | J21: =SUM(J15:J20) -> 7797
C22: D | E22: Equipment (> $5,000 per unit ) | F22: unit | G22: # units | H22: unit cost
C23: E | E23: Supplies (< $5,000 per unit) | F23: unit | G23: # units | H23: unit cost
C24: E.1 | E24: None | F24: unit | G24: 0 | H24: 0 | I24: 0 | J24: =I24*H24*G24 -> 0
C25: Subtotal Supplies | J25: =SUM(J24) -> 0
C26: F | E26: Contractual (Subrecipients, Subcontracts, and Consultant fees)
C27: F.1 | E27: Consultants and Contracts
A28: CONSULT | B28: 81000 | C28: F.1.1 | E28: Project Director - Rym | F28: months | G28: 4 | H28: 14083.34 | I28: 0.3 | J28: =I28*H28*G28 -> 16900.008
A29: PROGCOORD | B29: 81000 | C29: F.1.2 | E29: Program Coordinator - Mounaya | F29: months | G29: 4 | H29: 2250 | I29: 1 | J29: =I29*H29*G29 -> 9000
A30: DRIVER | B30: 81000 | C30: F.1.3 | E30: Driver - Bah | F30: months | G30: 3 | H30: 680 | I30: 0.5 | J30: =I30*H30*G30 -> 1020
A31: CAWTAR | B31: 81010 | C31: F.1.4 | E31: CAWTAR Contract | F31: contract | G31: 1 | H31: 35000 | I31: 1 | J31: =I31*H31*G31 -> 35000
C32: Subtotal Contractual | J32: =SUM(J28:J31) -> 61920.008
C33: G | E33: Construction | F33: unit | G33: # units | H33: unit cost
C34: H | E34: Other Direct Costs
A35: TRAIN | B35: 86000 (Transport)/ 87000 (Training) | C35: H.1 | E35: Meals and Transportation for Trainings | F35: unit | G35: 1 | H35: 14000 | I35: 1 | J35: =I35*H35*G35 -> 14000
A36: PLATFORM | B36: 89400 | C36: H.2 | E36: E-Commerce Platform | F36: unit | G36: 1 | H36: 2800 | I36: 1 | J36: =I36*H36*G36 -> 2800
A37: BANK FEE | B37: 90900 | C37: H.3 | E37: Bank Fees | F37: months | G37: 4 | H37: 50 | I37: 1 | J37: =I37*H37*G37 -> 200
A38: MATL | B38: 82420 (Program Supplies)/ 85300 (Printing) | C38: H.4 | E38: Visual/Printing Materials | F38: unit | G38: 1 | H38: 180 | I38: 1 | J38: =I38*H38*G38 -> 180
A39: SUBSCRIPT | B39: 89400 | C39: H.5 | E39: Platform Subscriptions | F39: months | G39: 4 | H39: =(5*3) -> 15 | I39: 1 | J39: =I39*H39*G39 -> 60
C40: Subtotal Other Direct Costs | J40: =SUM(J35:J39) -> 17240
...
