Workbook

Sheet POA Compensation Analysis  
J1: 2019 Baseline * % increase: | L1: =1.05*1*1.03*1*1.03 -> 1.113945
S2: Analysis assuming 5% increase each year
C3: Partners of the Americas Salary Ranges for HONDURAS | T3: Years in | W3: Years in | Y3: NOTES:
C4: Job Positions & Bands | G4: Experience | H4: Minimum USD | I4: Minimum HNL | J4: Midpoint USD | K4: Midpoint HNL | L4: Maximum USD | M4: Maximum HNL | AX4: 37440
C5: Core competencies | E5: Level | F5: Yrs Exp | T5: Position | W5: Position | Y5: - Management Skills: Project mgmt | AX5: =AX4/H6 -> 5.7720592
B6: Officer | C6: Maintenance - Level I Driver - Level II Assistant - Level III | D6: Grade A | E6: I | F6: 0 | G6: Minimum: no degree; no experience; no technical skills. Maximum: Grad school started;or 0-6 month of experience; with some technical skills. | H6: =+('Birches Report Level'!AG13*12)/'Birches Report Level'!AG12 -> 6486.42 | I6: =H6*TRM!$I$9 -> 167920.44 | J6: =+'Grade A'!C7 -> 7348.0357 | K6: =J6*TRM!$I$9 -> 190225.95 | L6: =+'Grade A'!D7 -> 9634.2843 | M6: =L6*TRM!$I$9 -> 249412.35 | O6: =(L10-H6)/6 -> 968.09326 | S6: =H6*1.05 -> 6810.741 | T6: 1 | V6: =S11*1.05 -> 9127.0443 | W6: 7 | Y6: - Leadership Skills: Project mgmt and personnel mgmt
B7: ·Accountant Analyst – Field Office ·Administrative Officer ·Communications Officer ·Communication & Outreach Officer ·Membership Officer ·Program Officer, CPU ·Program Officer, EGC ·Program Officer, EDH | C7: Provide physical and mechanic support Core competencies required: -Ability to write effectively and think critically. -Ability to work in a team as well as independently and demonstrate consistency | H7: No degree. No experience. No technical skills. | S7: =S6*1.05 -> 7151.278 | T7: 2 | V7: =V6*1.05 -> 9583.3965 | W7: 8 | Y7: - I added calculations to show the % increase between each point; I will hide these before sharing | AY7: ,00
E8: II | F8: 2-4 | G8: Minimum: Level I + min 2 years of experience, with some technical skills. | H8: =MEDIAN(H6,J6) -> 6917.2278 | I8: =H8*TRM!$I$9 -> 179073.19 | J8: =+'Grade A'!H7 -> 8701.0731 | K8: =J8*TRM!$I$9 -> 225253.38 | L8: =+'Grade A'!I7 -> 11779.476 | M8: =L8*TRM!$I$9 -> 304947.08 | S8: =S7*1.05 -> 7508.8419 | T8: 3 | Y8: - Note that these % increases are higher than the max 5% estimated increase each year
J9: Bachelors degree + least 2 years of experience. Some technical skills or min 2 years in level I | Q9: =J8/H8 -> 1.2578844 | S9: =S8*1.05 -> 7884.284 | T9: 4
E10: III | F10: 4-6 | G10: Minimum: 2 years of experience in Level II. | H10: =+'Grade A'!L7 -> 7436 | I10: =H10*TRM!$I$9 -> 192503.17 | J10: =+'Grade A'!M7 -> 10176.792 | K10: =J10*TRM!$I$9 -> 263456.8 | L10: =+'Grade A'!N7 -> 12294.98 | M10: =L10*TRM!$I$9 -> 318292.43 | O10: =J10+O6 -> 11144.886 | S10: =S9*1.05 -> 8278.4982 | T10: 5 | AY10: =55000/63000 -> 0.87301587
L11: Masters degree + least 3 years experience level II; some technical skills; preferred min bilingual. | Q11: =L10/J10 -> 1.208139 | S11: =S10*1.05 -> 8692.4231 | T11: 6 | AY11: =100-87 -> 13
B13: Senior Officer | C13: Officer/Technical Officer - Level I Sr. Officer/Sr. Technical Officer - Level II | D13: Grade B | E13: I | F13: 4 | G13: Minimum: 2 years of experience in Officer Level II, or equivalent; management skills demonstrated. | H13: =+'Grade B'!B7 -> 7553 | I13: =H13*TRM!$I$9 -> 195532.06 | J13: =+'Grade B'!C7 -> 11988.5 | K13: =J13*TRM!$I$9 -> 310358.29 | L13: =+'Grade B'!D7 -> 16423.5 | M13: =L13*TRM!$I$9 -> 425171.57 | O13: =(L15-H13)/4 -> 3431 | S13: =H13*1.05 -> 7930.65 | T13: 1 | V13: =S16*1.05 -> 9639.7546 | W13: 5
B14: ·Senior Accountant ·Senior Program Officer, EDH ·Senior Program Officer, EGC ·Senior Program Officer, CPU | C14: Process basic transaction Execute intrincate transactions Core competencies: -Thorough understanding of federal award management (program SOs) -Ability to contribute high-quality subsections of donor/partner reports/proposals -Ability to competently contribute during donor/partner meetings -Ability to manage 1-2 interns | H14: 2 years of experience in Officer Level II, or equivalent; management skills demonstrated. | S14: =S13*1.05 -> 8327.1825 | T14: 2 | V14: =V13*1.05 -> 10121.742 | W14: 6 | AY14: 58000 | BA14: =AY14/AY15 -> 0.92063492 | BB14: =100-92 -> 8
E15: II | F15: 4-7 | G15: Minimum: Masters degree preferred + at least 4 years of experience; 1 year as Sr Officer level I; technical skills required; leadership experience and language desired. Ability to competently serve as interim-Associate Director when necessary. | H15: =+'Grade B'!G7 -> 8662.9823 | I15: =H15*TRM!$I$9 -> 224267.29 | J15: =+'Grade B'!H7 -> 14325.501 | K15: =J15*TRM!$I$9 -> 370858.57 | L15: =+'Grade B'!I7 -> 21277 | M15: =L15*TRM!$I$9 -> 550818.98 | O15: =J15+O13 -> 17756.501 | Q15: =J15/H15 -> 1.6536454 | S15: =S14*1.05 -> 8743.5416 | T15: 3 | V15: =V14*1.05 -> 10627.829 | W15: 7 | AY15: 63000
H16: =H15/L13 -> 0.5274748 | J16: =J15/H15 -> 1.6536454 | L16: Masters degree preferred; 7+ years experience; 3 years as Sr Officer level I; technical skills required and leadership knowledge desired; preferred min bilingual. | Q16: =L15/J15 -> 1.4852535 | S16: =S15*1.05 -> 9180.7187 | T16: 4
B18: Associate Director | C18: Coordinator - Level I Specialist - Level II Sr. Specialist - Level III | D18: Grade C | E18: I | F18: 6 | G18: Minimum: Bachelors degree. 6+ years experience; 2+ years as Sr Officer Level I or II; technical skills and leadership experience required; preferred min bilingual. | H18: =+'Gade C'!B7 -> 10720 | I18: =H18*TRM!$I$9 -> 277519.36 | J18: =+'Gade C'!C7 -> 17186.5 | K18: =J18*TRM!$I$9 -> 444924.11 | L18: =+'Gade C'!D7 -> 23652.5 | M18: =L18*TRM!$I$9 -> 612315.92 | O18: =(L22-H18)/6 -> 3914.0833 | S18: =H18*1.05 -> 11256 | T18: 1 | V18: =S23*1.05 -> 15084.117 | W18: 7 | Y18: - Note that AD level and above are part of the SMT (Senior Management Team)
B19: ·Associate Director, EDH - F2F ·Associate Director, EDH - AVOP ·Associate Director, EGC ·Associate Director, BD ·Associate Director, Membership ·Executive Administrative Officer | C19: Ensure process integrity Manage integrated processes In addition to grade B core competencies: -Ability to write high-quality full sections of proposals/reports -Ability to deliver high-quality, detail-oriented, and professional donor/partner reports -Ability to competently lead a donor/partner meeting -Ability to manage 2-3 staff and/or interns | H19: Bachelors degree. 6+ years experience; 2+ years as Sr Officer Level I or II; technical skills and leadership experience required; preferred min bilingual. | J19: =J18/H18 -> 1.6032183 | L19: =L18/J18 -> 1.3762255 | S19: =S18*1.05 -> 11818.8 | T19: 2 | V19: =V18*1.05 -> 15838.322 | W19: 8
E20: II | F20: 9 | G20: Minimum: 3 additional years experience as AD Level I, or equivalent; international experience desired; or Level I + Masters degree; international experience desired. | H20: =+'Gade C'!G7 -> 12034.189 | I20: =H20*TRM!$I$9 -> 311541.09 | J20: =+'Gade C'!H7 -> 19806.5 | K20: =J20*TRM!$I$9 -> 512750.67 | L20: =+'Gade C'!I7 -> 27185.5 | M20: =L20*TRM!$I$9 -> 703778.22 | S20: =S19*1.05 -> 12409.74 | T20: 3
H21: =H20/L18 -> 0.50879142 | J21: 4 yrs experience as manger/specialist level I; technical skills and leadership experience required; language required; international experience desired. | L21: =L20/J20 -> 1.3725545 | Q21: =J20/H20 -> 1.6458525 | S21: =S20*1.05 -> 13030.227 | T21: 4
E22: III | F22: 12 | G22: Minimum: Level II + Masters degree + 3 additional years experience as AD Level II; international experience desired. Ability to competently serve as interim-Director when necessary. | H22: =+'Gade C'!L7 -> 13049.878 | I22: =H22*TRM!$I$9 -> 337835.24 | J22: =+'Gade C'!M7 -> 23349.158 | K22: =J22*TRM!$I$9 -> 604462.99 | L22: =+'Gade C'!N7 -> 34204.5 | M22: =L22*TRM!$I$9 -> 885486.1 | O22: =J22+O18 -> 27263.241 | S22: =S21*1.05 -> 13681.738 | T22: 5
H23: =H22/L20 -> 0.48003082 | J23: =J22/H22 -> 1.7892242 | L23: Masters degree. 8+ years experience; 3 years as Manager or specialist Level II; international experience desired. | Q23: =L22/J22 -> 1.4649137 | S23: =S22*1.05 -> 14365.825 | T23: 6
B25: Director | C25: Manager - Level I Director - Level II Sr. Director - Level III | D25: Grade D | E25: I | F25: 8 | G25: Minimum: Masters degree and AD Level II or 3 years as AD Level I or equivalent; proven technical skills and leadership experience; 2nd language required; international experience desired. | H25: =+'Grade D'!B7 -> 11000 | I25: =H25*TRM!$I$9 -> 284768 | J25: =+'Grade D'!C7 -> 28000 | K25: =J25*TRM!$I$9 -> 724864 | L25: =+'Grade D'!D7 -> 45000 | M25: =L25*TRM!$I$9 -> 1164960 | O25: =(L29-H25)/6 -> 8470.4322 | S25: =H25*1.05 -> 11550 | T25: 1 | V25: =S30*1.05 -> 15478.105 | W25: 7
B26: ·Director of 100,000 Strong ·Director of EGC ·Director, BD | C26: Analyze - Adapt In addition to Grade C core competencies: -Ability to lead a full proposal (design, strategy, delegation of duties, etc.) -Ability to ensure full programmatic and financial compliance of a federal award from startup through closeout -Ability to manage 3-5 staff, including remote supervision of field staff | H26: manager/specialist Level I + Masters degree and 2 years as manager or equivalent; 2nd language required; international experience desired. | J26: =J25/H25 -> 2.5454545 | L26: =L25/J25 -> 1.6071429 | S26: =S25*1.05 -> 12127.5 | T26: 2 | V26: =V25*1.05 -> 16252.01 | W26: 8
E27: II | F27: 10 | G27: Minimum: At least 2 years as Director Level I, or equivalent. | H27: =+'Grade D'!G7 -> 16544.717 | I27: =H27*TRM!$I$9 -> 428309.64 | J27: =+'Grade D'!H7 -> 33579.5 | K27: =J27*TRM!$I$9 -> 869306.1 | L27: =+'Grade D'!I7 -> 46880.66 | M27: =L27*TRM!$I$9 -> 1213646.5 | S27: =S26*1.05 -> 12733.875 | T27: 3
H28: =H27/L25 -> 0.36766038 | J28: At least 3 years as Director Level I & II. | L28: =L27/J27 -> 1.3961095 | Q28: =J27/H27 -> 2.0296207 | S28: =S27*1.05 -> 13370.569 | T28: 4
E29: III | F29: 12-14 | G29: Minimum: At least 2 years as Director Level II. Ability to competently serve as interim-Sr Director when necessary. | H29: =+'Grade D'!L7 -> 27533.597 | I29: =H29*TRM!$I$9 -> 712789.76 | J29: =+'Grade D'!M7 -> 41447.93 | K29: =J29*TRM!$I$9 -> 1073004 | L29: =+'Grade D'!N7 -> 61822.593 | M29: =L29*TRM!$I$9 -> 1600463.3 | O29: =J29+O25 -> 49918.362 | S29: =S28*1.05 -> 14039.097 | T29: 5
H30: =H29/L27 -> 0.58731249 | J30: =J29/H29 -> 1.5053583 | L30: At least 4 years as Director Level II & III. | Q30: =L29/J29 -> 1.4915725 | S30: =S29*1.05 -> 14741.052 | T30: 6
B32: Director | C32: Deputy Chief of Party/Deputy Project Director - Level I-II Chief of Party/Project Director - Level II-III | D32: Grade E | E32: I | F32: 10 | G32: Minimum: At least 2 years as Director or equivalent; proven high confidence and decision - making; strong leader and manager | H32: =+'Grade E'!B7 -> 52692.549 | I32: =H32*TRM!$I$9 -> 1364104.7 | J32: =+'Grade E'!C7 -> 63939.467 | K32: =J32*TRM!$I$9 -> 1655264.9 | L32: =+'Grade E'!D7 -> 78000 | M32: =L32*TRM!$I$9 -> 2019264 | O32: =(L36-H32)/6 -> 11217.909 | S32: =H32*1.05 -> 55327.176 | T32: 1 | V32: =S37*1.05 -> 74143.708 | W32: 7
B33: ·Director of 100,000 Strong ·Director of EGC ·Director, BD | C33: In addition to Director competencies: -Ability to raise public and/or private funds -Ability to manage multiple federal awards -Ability to execute strategic and operational plans for the units - Ability to manage a full team (staff, interns, contractors), including remote supervision of field staff | H33: At least 2 years as Director; proven high confidence and decision-making; strong leader and manager. | J33: =J32/H32 -> 1.2134442 | L33: =L32/J32 -> 1.2199038 | S33: =S32*1.05 -> 58093.535 | T33: 2 | V33: =V32*1.05 -> 77850.893 | W33: 8
E34: II | F34: 12 | G34: Minimum: Dual or multiple Masters Degrees; at least 2 years as Sr. Director Level I; proven high confidence and decision-making; strong leader and manager. | H34: =+'Grade E'!G7 -> 22000 | I34: =H34*TRM!$I$9 -> 569536 | J34: =+'Grade E'!H7 -> 58000 | K34: =J34*TRM!$I$9 -> 1501504 | L34: =+'Grade E'!I7 -> 94000 | M34: =L34*TRM!$I$9 -> 2433472 | S34: =S33*1.05 -> 60998.212 | T34: 3
H35: =H34/L32 -> 0.28205128 | J35: Dual or multiple Masters Degrees; at least 3 years as Sr. Director; proven high confidence and decision-making; strong leader and manager | L35: =L34/J34 -> 1.6206897 | Q35: =J34/H34 -> 2.6363636 | S35: =S34*1.05 -> 64048.123 | T35: 4
E36: III | F36: 14 | G36: Minimum: PhD "preference"; at least 2 years as Sr. Director. Ability to competently serve as interim Vice - President when necesary. | H36: =+'Grade E'!L7 -> 62633.248 | I36: =H36*TRM!$I$9 -> 1621449.5 | J36: =+'Grade E'!M7 -> 80238.342 | K36: =J36*TRM!$I$9 -> 2077210.2 | L36: 120000 | M36: =L36*TRM!$I$9 -> 3106560 | O36: =J36+O32 -> 91456.25 | S36: =S35*1.05 -> 67250.529 | T36: 5
H37: =H36/L34 -> 0.66631115 | J37: =J36/H36 -> 1.2810822 | L37: PhD preferance required.14+ years of experience; at least 4 years as Sr. Director or equivalent_x000D_ | Q37: =L36/J36 -> 1.4955444 | S37: =S36*1.05 -> 70613.055 | T37: 6

Sheet Birches Report 
G1: Birchis 2023 | N1: Estimado 2024 con incremento del 3.88% | U1: Estimado 2025 con incremento del 4.16%
A2: Level | B2: Purpose | C2: Proposed Field Office Grade | D2: Purpose | E2: Famili | F2: Titulo del trabajo | H2: Bajo | I2: Percentil 25 | J2: Percentil 50 | K2: Percentil 75 | L2: Alto | M2: Media | O2: Bajo | P2: Percentil 25 | Q2: Percentil 50 | R2: Percentil 75 | S2: Alto | T2: Media | V2: Bajo | W2: Percentil 25 | X2: Percentil 50 | Y2: Percentil 75 | Z2: Alto | AA2: Media | AB2: https://www.trabajo.gob.hn/tabla-de-salario-minimo/?utm_source=chatgpt.com
A3: BG-12 | B3: Integrate-Transform | C3: Poa-E | D3: BG-12 Executive/DCOP | E3: GEN-12 | F3: Gerente / Experto reconocido | G3: Máx. | H3: 1453935 | I3: 1603580 | J3: 1753226 | K3: 1958113 | L3: 2163000 | M3: 1790054 | N3: Máx. | O3: =((H3*$AB$15)+H3)/$AB$17 -> 58341.613 | P3: =((I3*$AB$15)+I3)/$AB$17 -> 64346.373 | Q3: =((J3*$AB$15)+J3)/$AB$17 -> 70351.173 | R3: =((K3*$AB$15)+K3)/$AB$17 -> 78572.612 | S3: =((L3*$AB$15)+L3)/$AB$17 -> 86794.051 | T3: =+((1281000*$AB$15)+M3)/$AB$17 -> 71066.007 | U3: Máx. | V3: =((O3*$AB$16)+O3) -> 60768.624 | W3: =((P3*$AB$16)+P3) -> 67023.182 | X3: =((Q3*$AB$16)+Q3) -> 73277.782 | Y3: =((R3*$AB$16)+R3) -> 81841.233 | Z3: =((S3*$AB$16)+S3) -> 90404.684 | AA3: =MEDIAN(V3:Z3) -> 73277.782
G4: Med | H4: 1453835 | I4: 1585506 | J4: 1717176 | K4: 1940088 | L4: 2163000 | M4: 1778004 | N4: Med | O4: =((H4*$AB$15)+H4)/$AB$17 -> 58337.6 | P4: =((I4*$AB$15)+I4)/$AB$17 -> 63621.123 | Q4: =((J4*$AB$15)+J4)/$AB$17 -> 68904.606 | R4: =((K4*$AB$15)+K4)/$AB$17 -> 77849.328 | S4: =((L4*$AB$15)+L4)/$AB$17 -> 86794.051 | T4: =MEDIAN(O4:S4) -> 68904.606 | U4: Med | V4: =((O4*$AB$16)+O4) -> 60764.445 | W4: =((P4*$AB$16)+P4) -> 66267.762 | X4: =((Q4*$AB$16)+Q4) -> 71771.037 | Y4: =((R4*$AB$16)+R4) -> 81087.86 | Z4: =((S4*$AB$16)+S4) -> 90404.684 | AA4: =MEDIAN(V4:Z4) -> 71771.037 | AB4: Para una empresa con 11 a 50 empleados, los incrementos al salario mínimo en Honduras han sido del 5.5 % para 2024 y de nuevo del 5.5 % para 2025. trabajo.gob.hn+2Bloomberg Línea Brasil+2
G5: Min. | H5: 1453735 | I5: 1567430 | J5: 1681126 | K5: 1922063 | L5: 2163000 | M5: 1765954 | N5: Min. | O5: =((H5*$AB$15)+H5)/$AB$17 -> 58333.588 | P5: =((I5*$AB$15)+I5)/$AB$17 -> 62895.793 | Q5: =((J5*$AB$15)+J5)/$AB$17 -> 67458.038 | R5: =((K5*$AB$15)+K5)/$AB$17 -> 77126.045 | S5: =((L5*$AB$15)+L5)/$AB$17 -> 86794.051 | T5: =MEDIAN(O5:S5) -> 67458.038 | U5: Min. | V5: =((O5*$AB$16)+O5) -> 60760.265 | W5: =((P5*$AB$16)+P5) -> 65512.258 | X5: =((Q5*$AB$16)+Q5) -> 70264.292 | Y5: =((R5*$AB$16)+R5) -> 80334.488 | Z5: =((S5*$AB$16)+S5) -> 90404.684 | AA5: =MEDIAN(V5:Z5) -> 70264.292 | AB5: Si tomamos como base un salario mínimo de L 12,560.96 en enero de 2023, el estimado acumulado para octubre de 2025 sería:
E6: DPM-12 | F6: Director nacional | G6: Máx. | H6: 1281000 | I6: 1739664 | J6: 1761060 | K6: 2163000 | L6: 2800000 | M6: 1934687 | N6: Máx. | O6: =((H6*$AB$15)+H6)/$AB$17 -> 51402.302 | P6: =((I6*$AB$15)+I6)/$AB$17 -> 69806.975 | Q6: =((J6*$AB$15)+J6)/$AB$17 -> 70665.526 | R6: =((K6*$AB$15)+K6)/$AB$17 -> 86794.051 | S6: =((L6*$AB$15)+L6)/$AB$17 -> 112354.76 | T6: =MEDIAN(O6:S6) -> 70665.526 | U6: Máx. | V6: =((O6*$AB$16)+O6) -> 53540.638 | W6: =((P6*$AB$16)+P6) -> 72710.945 | X6: =((Q6*$AB$16)+Q6) -> 73605.212 | Y6: =((R6*$AB$16)+R6) -> 90404.684 | Z6: =((S6*$AB$16)+S6) -> 117028.72 | AA6: =MEDIAN(V6:Z6) -> 73605.212
G7: Med | H7: 1281000 | I7: 1467550 | J7: 1739005 | K7: 1862190 | L7: 2333333 | M7: 1750725 | N7: Med | O7: =((H7*$AB$15)+H7)/$AB$17 -> 51402.302 | P7: =((I7*$AB$15)+I7)/$AB$17 -> 58887.938 | Q7: =((J7*$AB$15)+J7)/$AB$17 -> 69780.531 | R7: =((K7*$AB$15)+K7)/$AB$17 -> 74723.539 | S7: =((L7*$AB$15)+L7)/$AB$17 -> 93628.952 | T7: =MEDIAN(O7:S7) -> 69780.531 | U7: Med | V7: =((O7*$AB$16)+O7) -> 53540.638 | W7: =((P7*$AB$16)+P7) -> 61337.676 | X7: =((Q7*$AB$16)+Q7) -> 72683.401 | Y7: =((R7*$AB$16)+R7) -> 77832.038 | Z7: =((S7*$AB$16)+S7) -> 97523.917 | AA7: =MEDIAN(V7:Z7) -> 72683.401
G8: Min. | H8: 1174040 | I8: 1363558 | J8: 1453735 | K8: 1738346 | L8: 2163000 | M8: 1566764 | N8: Min. | O8: =((H8*$AB$15)+H8)/$AB$17 -> 47110.35 | P8: =((I8*$AB$15)+I8)/$AB$17 -> 54715.082 | Q8: =((J8*$AB$15)+J8)/$AB$17 -> 58333.588 | R8: =((K8*$AB$15)+K8)/$AB$17 -> 69754.088 | S8: =((L8*$AB$15)+L8)/$AB$17 -> 86794.051 | T8: =MEDIAN(O8:S8) -> 58333.588 | U8: Min. | V8: =((O8*$AB$16)+O8) -> 49070.141 | W8: =((P8*$AB$16)+P8) -> 56991.23 | X8: =((Q8*$AB$16)+Q8) -> 60760.265 | Y8: =((R8*$AB$16)+R8) -> 72655.858 | Z8: =((S8*$AB$16)+S8) -> 90404.684 | AA8: =MEDIAN(V8:Z8) -> 60760.265
A9: BG-11 | B9: Innovate | D9: BG-11 Country Directors/COP | E9: GEN-11 | F9: Gerente / Especialista con Autoridad | G9: Máx. | H9: 941347 | I9: 1542070 | J9: 1886528 | K9: 2129776 | L9: 3450528 | M9: 1961246 | N9: Máx. | O9: =((H9*$AB$15)+H9)/$AB$17 -> 37773.148 | P9: =((I9*$AB$15)+I9)/$AB$17 -> 61878.18 | Q9: =((J9*$AB$15)+J9)/$AB$17 -> 75700.142 | R9: =((K9*$AB$15)+K9)/$AB$17 -> 85460.882 | S9: =((L9*$AB$15)+L9)/$AB$17 -> 138458.3 | T9: =MEDIAN(O9:S9) -> 75700.142 | U9: Máx. | V9: =((O9*$AB$16)+O9) -> 39344.511 | W9: =((P9*$AB$16)+P9) -> 64452.312 | X9: =((Q9*$AB$16)+Q9) -> 78849.268 | Y9: =((R9*$AB$16)+R9) -> 89016.055 | Z9: =((S9*$AB$16)+S9) -> 144218.17 | AA9: =MEDIAN(V9:Z9) -> 78849.268 | AB9: Después del primer ajuste (2024): L 12,560.96 × 1.055 ≈ L 13,250.11
G10: Med | H10: 760167 | I10: 1309132 | J10: 1452829 | K10: 1846013 | L10: 2239464 | M10: 1538094 | N10: Med | O10: =((H10*$AB$15)+H10)/$AB$17 -> 30502.993 | P10: =((I10*$AB$15)+I10)/$AB$17 -> 52531.147 | Q10: =((J10*$AB$15)+J10)/$AB$17 -> 58297.233 | R10: =((K10*$AB$15)+K10)/$AB$17 -> 74074.409 | S10: =((L10*$AB$15)+L10)/$AB$17 -> 89862.299 | T10: =MEDIAN(O10:S10) -> 58297.233 | U10: Med | V10: =((O10*$AB$16)+O10) -> 31771.917 | W10: =((P10*$AB$16)+P10) -> 54716.442 | X10: =((Q10*$AB$16)+Q10) -> 60722.398 | Y10: =((R10*$AB$16)+R10) -> 77155.905 | Z10: =((S10*$AB$16)+S10) -> 93600.571 | AA10: =MEDIAN(V10:Z10) -> 60722.398 | AB10: Después del segundo ajuste (2025): L 13,250.11 × 1.055 ≈ L 13,993.37
G11: Min. | H11: 578987 | I11: 961524 | J11: 1036042 | K11: 1150800 | L11: 1898048 | M11: 1114941 | N11: Min. | O11: =((H11*$AB$15)+H11)/$AB$17 -> 23232.837 | P11: =((I11*$AB$15)+I11)/$AB$17 -> 38582.785 | Q11: =((J11*$AB$15)+J11)/$AB$17 -> 41572.946 | R11: =((K11*$AB$15)+K11)/$AB$17 -> 46177.806 | S11: =((L11*$AB$15)+L11)/$AB$17 -> 76162.402 | T11: =MEDIAN(O11:S11) -> 41572.946 | U11: Min. | V11: =((O11*$AB$16)+O11) -> 24199.323 | W11: =((P11*$AB$16)+P11) -> 40187.829 | X11: =((Q11*$AB$16)+Q11) -> 43302.381 | Y11: =((R11*$AB$16)+R11) -> 48098.803 | Z11: =((S11*$AB$16)+S11) -> 79330.758 | AA11: =MEDIAN(V11:Z11) -> 43302.381 | AB11: Por tanto, un estimado razonable del salario mínimo para esa categoría en octubre de 2025 sería aproximadamente L 13,993.37, lo que representa un incremento acumulado de alrededor del 11.4 % desde enero de 2023.
E12: DPM-11 | F12: Responsable de programa senior | G12: Máx. | H12: 941347 | I12: 1593906 | J12: 1875008 | K12: 2087050 | L12: 3450528 | M12: 1974961 | N12: Máx. | O12: =((H12*$AB$15)+H12)/$AB$17 -> 37773.148 | P12: =((I12*$AB$15)+I12)/$AB$17 -> 63958.187 | Q12: =((J12*$AB$15)+J12)/$AB$17 -> 75237.883 | R12: =((K12*$AB$15)+K12)/$AB$17 -> 83746.428 | S12: =((L12*$AB$15)+L12)/$AB$17 -> 138458.3 | T12: =MEDIAN(O12:S12) -> 75237.883 | U12: Máx. | V12: =((O12*$AB$16)+O12) -> 39344.511 | W12: =((P12*$AB$16)+P12) -> 66618.848 | X12: =((Q12*$AB$16)+Q12) -> 78367.779 | Y12: =((R12*$AB$16)+R12) -> 87230.28 | Z12: =((S12*$AB$16)+S12) -> 144218.17 | AA12: =MEDIAN(V12:Z12) -> 78367.779
G13: Med | H13: 760167 | I13: 1309132 | J13: 1446312 | K13: 1846013 | L13: 2239464 | M13: 1541168 | N13: Med | O13: =((H13*$AB$15)+H13)/$AB$17 -> 30502.993 | P13: =((I13*$AB$15)+I13)/$AB$17 -> 52531.147 | Q13: =((J13*$AB$15)+J13)/$AB$17 -> 58035.727 | R13: =((K13*$AB$15)+K13)/$AB$17 -> 74074.409 | S13: =((L13*$AB$15)+L13)/$AB$17 -> 89862.299 | T13: =MEDIAN(O13:S13) -> 58035.727 | U13: Med | V13: =((O13*$AB$16)+O13) -> 31771.917 | W13: =((P13*$AB$16)+P13) -> 54716.442 | X13: =((Q13*$AB$16)+Q13) -> 60450.013 | Y13: =((R13*$AB$16)+R13) -> 77155.905 | Z13: =((S13*$AB$16)+S13) -> 93600.571 | AA13: =MEDIAN(V13:Z13) -> 60450.013
G14: Min. | H14: 578987 | I14: 973893 | J14: 1028400 | K14: 1120000 | L14: 1898048 | M14: 1107374 | N14: Min. | O14: =((H14*$AB$15)+H14)/$AB$17 -> 23232.837 | P14: =((I14*$AB$15)+I14)/$AB$17 -> 39079.112 | Q14: =((J14*$AB$15)+J14)/$AB$17 -> 41266.298 | R14: =((K14*$AB$15)+K14)/$AB$17 -> 44941.904 | S14: =((L14*$AB$15)+L14)/$AB$17 -> 76162.402 | T14: =MEDIAN(O14:S14) -> 41266.298 | U14: Min. | V14: =((O14*$AB$16)+O14) -> 24199.323 | W14: =((P14*$AB$16)+P14) -> 40704.803 | X14: =((Q14*$AB$16)+Q14) -> 42982.976 | Y14: =((R14*$AB$16)+R14) -> 46811.487 | Z14: =((S14*$AB$16)+S14) -> 79330.758 | AA14: =MEDIAN(V14:Z14) -> 42982.976
A15: BG-10 | B15: Adapt | C15: Poa-D | D15: BG-10 Project Director | E15: GEN-10 | F15: Profesional experto nivel operativo | G15: Máx. | H15: 815061 | I15: 960251 | J15: 1211352 | K15: 1391583 | L15: 1670873 | M15: 1200348 | N15: Máx. | O15: =((H15*$AB$15)+H15)/$AB$17 -> 32705.708 | P15: =((I15*$AB$15)+I15)/$AB$17 -> 38531.703 | Q15: =((J15*$AB$15)+J15)/$AB$17 -> 48607.558 | R15: =((K15*$AB$15)+K15)/$AB$17 -> 55839.633 | S15: =((L15*$AB$15)+L15)/$AB$17 -> 67046.619 | T15: =MEDIAN(O15:S15) -> 48607.558 | U15: Máx. | V15: =((O15*$AB$16)+O15) -> 34066.265 | W15: =((P15*$AB$16)+P15) -> 40134.622 | X15: =((Q15*$AB$16)+Q15) -> 50629.632 | Y15: =((R15*$AB$16)+R15) -> 58162.562 | Z15: =((S15*$AB$16)+S15) -> 69835.758 | AA15: =MEDIAN(V15:Z15) -> 50629.632 | AB15: 0.0388 | AC15: Inflación del 2024"fuente, Secretaria de Finanzas de Honduras": https://www.sefin.gob.hn/download_file.php?download_file=/wp-content/uploads/2025/liquidacion2024/2-Informe-Cierre-Fiscal-2024.pdf
G16: Med | H16: 658762 | I16: 884411 | J16: 1065812 | K16: 1111487 | L16: 1386043 | M16: 1013324 | N16: Med | O16: =((H16*$AB$15)+H16)/$AB$17 -> 26433.945 | P16: =((I16*$AB$15)+I16)/$AB$17 -> 35488.495 | Q16: =((J16*$AB$15)+J16)/$AB$17 -> 42767.518 | R16: =((K16*$AB$15)+K16)/$AB$17 -> 44600.305 | S16: =((L16*$AB$15)+L16)/$AB$17 -> 55617.331 | T16: =MEDIAN(O16:S16) -> 42767.518 | U16: Med | V16: =((O16*$AB$16)+O16) -> 27533.597 | W16: =((P16*$AB$16)+P16) -> 36964.816 | X16: =((Q16*$AB$16)+Q16) -> 44546.647 | Y16: =((R16*$AB$16)+R16) -> 46455.678 | Z16: =((S16*$AB$16)+S16) -> 57931.012 | AA16: =MEDIAN(V16:Z16) -> 44546.647 | AB16: 0.0416 | AC16: Inflación del 2025 "Fuente Banco central de Honduras": chrome-extension://efaidnbmnnnibpcajpcglclefindmkaj/https://www.bch.hn/estadisticos/GIE/LIBIPC/%C3%8Dndice%20de%20Precios%20al%20Consumidor%20Agosto%202025.pdf
G17: Min. | H17: 457498 | I17: 692264 | J17: 806580 | K17: 1047138 | L17: 1101212 | M17: 826299 | N17: Min. | O17: =((H17*$AB$15)+H17)/$AB$17 -> 18357.885 | P17: =((I17*$AB$15)+I17)/$AB$17 -> 27778.27 | Q17: =((J17*$AB$15)+J17)/$AB$17 -> 32365.393 | R17: =((K17*$AB$15)+K17)/$AB$17 -> 42018.192 | S17: =((L17*$AB$15)+L17)/$AB$17 -> 44188.003 | T17: =MEDIAN(O17:S17) -> 32365.393 | U17: Min. | V17: =((O17*$AB$16)+O17) -> 19121.573 | W17: =((P17*$AB$16)+P17) -> 28933.846 | X17: =((Q17*$AB$16)+Q17) -> 33711.794 | Y17: =((R17*$AB$16)+R17) -> 43766.149 | Z17: =((S17*$AB$16)+S17) -> 46026.224 | AA17: =MEDIAN(V17:Z17) -> 33711.794 | AB17: 25.888 | AC17: TRM
E18: ADM-10 | F18: Especialista Servicios Admin. | G18: Máx. | H18: 1065812 | I18: 1215095 | J18: 1243828 | K18: 1312275 | L18: 1595668 | M18: 1281624 | N18: Máx. | O18: =((H18*$AB$15)+H18)/$AB$17 -> 42767.518 | P18: =((I18*$AB$15)+I18)/$AB$17 -> 48757.752 | Q18: =((J18*$AB$15)+J18)/$AB$17 -> 49910.713 | R18: =((K18*$AB$15)+K18)/$AB$17 -> 52657.265 | S18: =((L18*$AB$15)+L18)/$AB$17 -> 64028.891 | T18: =MEDIAN(O18:S18) -> 49910.713 | U18: Máx. | V18: =((O18*$AB$16)+O18) -> 44546.647 | W18: =((P18*$AB$16)+P18) -> 50786.075 | X18: =((Q18*$AB$16)+Q18) -> 51986.998 | Y18: =((R18*$AB$16)+R18) -> 54847.807 | Z18: =((S18*$AB$16)+S18) -> 66692.492 | AA18: =MEDIAN(V18:Z18) -> 51986.998
G19: Med | H19: 876510 | I19: 1046596 | J19: 1068106 | K19: 1177590 | L19: 1285805 | M19: 1092006 | N19: Med | O19: =((H19*$AB$15)+H19)/$AB$17 -> 35171.453 | P19: =((I19*$AB$15)+I19)/$AB$17 -> 41996.443 | Q19: =((J19*$AB$15)+J19)/$AB$17 -> 42859.569 | R19: =((K19*$AB$15)+K19)/$AB$17 -> 47252.8 | S19: =((L19*$AB$15)+L19)/$AB$17 -> 51595.111 | T19: =MEDIAN(O19:S19) -> 42859.569 | U19: Med | V19: =((O19*$AB$16)+O19) -> 36634.586 | W19: =((P19*$AB$16)+P19) -> 43743.495 | X19: =((Q19*$AB$16)+Q19) -> 44642.527 | Y19: =((R19*$AB$16)+R19) -> 49218.517 | Z19: =((S19*$AB$16)+S19) -> 53741.468 | AA19: =MEDIAN(V19:Z19) -> 44642.527
G20: Min. | H20: 545311 | I20: 816706 | J20: 909534 | K20: 1043345 | L20: 1176239 | M20: 902388 | N20: Min. | O20: =((H20*$AB$15)+H20)/$AB$17 -> 21881.531 | P20: =((I20*$AB$15)+I20)/$AB$17 -> 32771.716 | Q20: =((J20*$AB$15)+J20)/$AB$17 -> 36496.598 | R20: =((K20*$AB$15)+K20)/$AB$17 -> 41865.991 | S20: =((L20*$AB$15)+L20)/$AB$17 -> 47198.589 | T20: =MEDIAN(O20:S20) -> 36496.598 | U20: Min. | V20: =((O20*$AB$16)+O20) -> 22791.802 | W20: =((P20*$AB$16)+P20) -> 34135.02 | X20: =((Q20*$AB$16)+Q20) -> 38014.856 | Y20: =((R20*$AB$16)+R20) -> 43607.617 | Z20: =((S20*$AB$16)+S20) -> 49162.05 | AA20: =MEDIAN(V20:Z20) -> 38014.856
E21: DPM-10 | F21: Responsable de programa senior | G21: Máx. | H21: 857087 | I21: 1111499 | J21: 1274246 | K21: 1584249 | L21: 2126740 | M21: 1367979 | N21: Máx. | O21: =((H21*$AB$15)+H21)/$AB$17 -> 34392.073 | P21: =((I21*$AB$15)+I21)/$AB$17 -> 44600.787 | Q21: =((J21*$AB$15)+J21)/$AB$17 -> 51131.286 | R21: =((K21*$AB$15)+K21)/$AB$17 -> 63570.684 | S21: =((L21*$AB$15)+L21)/$AB$17 -> 85339.057 | T21: =MEDIAN(O21:S21) -> 51131.286 | U21: Máx. | V21: =((O21*$AB$16)+O21) -> 35822.783 | W21: =((P21*$AB$16)+P21) -> 46456.179 | X21: =((Q21*$AB$16)+Q21) -> 53258.348 | Y21: =((R21*$AB$16)+R21) -> 66215.224 | Z21: =((S21*$AB$16)+S21) -> 88889.162 | AA21: =MEDIAN(V21:Z21) -> 53258.348
G22: Med | H22: 680033 | I22: 964818 | J22: 1057479 | K22: 1260085 | L22: 1452336 | M22: 1109861 | N22: Med | O22: =((H22*$AB$15)+H22)/$AB$17 -> 27287.48 | P22: =((I22*$AB$15)+I22)/$AB$17 -> 38714.962 | Q22: =((J22*$AB$15)+J22)/$AB$17 -> 42433.142 | R22: =((K22*$AB$15)+K22)/$AB$17 -> 50563.052 | S22: =((L22*$AB$15)+L22)/$AB$17 -> 58277.45 | T22: =MEDIAN(O22:S22) -> 42433.142 | U22: Med | V22: =((O22*$AB$16)+O22) -> 28422.639 | W22: =((P22*$AB$16)+P22) -> 40325.505 | X22: =((Q22*$AB$16)+Q22) -> 44198.361 | Y22: =((R22*$AB$16)+R22) -> 52666.475 | Z22: =((S22*$AB$16)+S22) -> 60701.792 | AA22: =MEDIAN(V22:Z22) -> 44198.361
G23: Min. | H23: 502979 | I23: 716872 | J23: 807240 | K23: 996061 | L23: 1243740 | M23: 851744 | N23: Min. | O23: =((H23*$AB$15)+H23)/$AB$17 -> 20182.887 | P23: =((I23*$AB$15)+I23)/$AB$17 -> 28765.707 | Q23: =((J23*$AB$15)+J23)/$AB$17 -> 32391.877 | R23: =((K23*$AB$15)+K23)/$AB$17 -> 39968.641 | S23: =((L23*$AB$15)+L23)/$AB$17 -> 49907.181 | T23: =MEDIAN(O23:S23) -> 32391.877 | U23: Min. | V23: =((O23*$AB$16)+O23) -> 21022.495 | W23: =((P23*$AB$16)+P23) -> 29962.361 | X23: =((Q23*$AB$16)+Q23) -> 33739.379 | Y23: =((R23*$AB$16)+R23) -> 41631.336 | Z23: =((S23*$AB$16)+S23) -> 51983.32 | AA23: =MEDIAN(V23:Z23) -> 33739.379
E24: FIN-10 | F24: Experto contable | G24: Máx. | H24: 857087 | I24: 1136760 | J24: 1237256 | K24: 1299991 | L24: 1595668 | M24: 1213294 | N24: Máx. | O24: =((H24*$AB$15)+H24)/$AB$17 -> 34392.073 | P24: =((I24*$AB$15)+I24)/$AB$17 -> 45614.427 | Q24: =((J24*$AB$15)+J24)/$AB$17 -> 49647 | R24: =((K24*$AB$15)+K24)/$AB$17 -> 52164.348 | S24: =((L24*$AB$15)+L24)/$AB$17 -> 64028.891 | T24: =MEDIAN(O24:S24) -> 49647 | U24: Máx. | V24: =((O24*$AB$16)+O24) -> 35822.783 | W24: =((P24*$AB$16)+P24) -> 47511.987 | X24: =((Q24*$AB$16)+Q24) -> 51712.315 | Y24: =((R24*$AB$16)+R24) -> 54334.385 | Z24: =((S24*$AB$16)+S24) -> 66692.492 | AA24: =MEDIAN(V24:Z24) -> 51712.315
G25: Med | H25: 658762 | I25: 887053 | J25: 1053541 | K25: 1173703 | L25: 1297569 | M25: 1012638 | N25: Med | O25: =((H25*$AB$15)+H25)/$AB$17 -> 26433.945 | P25: =((I25*$AB$15)+I25)/$AB$17 -> 35594.509 | Q25: =((J25*$AB$15)+J25)/$AB$17 -> 42275.123 | R25: =((K25*$AB$15)+K25)/$AB$17 -> 47096.828 | S25: =((L25*$AB$15)+L25)/$AB$17 -> 52067.162 | T25: =MEDIAN(O25:S25) -> 42275.123 | U25: Med | V25: =((O25*$AB$16)+O25) -> 27533.597 | W25: =((P25*$AB$16)+P25) -> 37075.241 | X25: =((Q25*$AB$16)+Q25) -> 44033.768 | Y25: =((R25*$AB$16)+R25) -> 49056.056 | Z25: =((S25*$AB$16)+S25) -> 54233.155 | AA25: =MEDIAN(V25:Z25) -> 44033.768
G26: Min. | H26: 457498 | I26: 524145 | J26: 843126 | K26: 1028145 | L26: 1176239 | M26: 811983 | N26: Min. | O26: =((H26*$AB$15)+H26)/$AB$17 -> 18357.885 | P26: =((I26*$AB$15)+I26)/$AB$17 -> 21032.209 | Q26: =((J26*$AB$15)+J26)/$AB$17 -> 33831.864 | R26: =((K26*$AB$15)+K26)/$AB$17 -> 41256.066 | S26: =((L26*$AB$15)+L26)/$AB$17 -> 47198.589 | T26: =MEDIAN(O26:S26) -> 33831.864 | U26: Min. | V26: =((O26*$AB$16)+O26) -> 19121.573 | W26: =((P26*$AB$16)+P26) -> 21907.149 | X26: =((Q26*$AB$16)+Q26) -> 35239.269 | Y26: =((R26*$AB$16)+R26) -> 42972.318 | Z26: =((S26*$AB$16)+S26) -> 49162.05 | AA26: =MEDIAN(V26:Z26) -> 35239.269
E27: FND-10 | F27: Senior Fundraising Post, Fundraising Manager | G27: Máx. | H27: 857087 | I27: 871891 | J27: 984273 | K27: 1184027 | L27: 1460946 | M27: 1071645 | N27: Máx. | O27: =((H27*$AB$15)+H27)/$AB$17 -> 34392.073 | P27: =((I27*$AB$15)+I27)/$AB$17 -> 34986.108 | Q27: =((J27*$AB$15)+J27)/$AB$17 -> 39495.627 | R27: =((K27*$AB$15)+K27)/$AB$17 -> 47511.096 | S27: =((L27*$AB$15)+L27)/$AB$17 -> 58622.941 | T27: =MEDIAN(O27:S27) -> 39495.627 | U27: Máx. | V27: =((O27*$AB$16)+O27) -> 35822.783 | W27: =((P27*$AB$16)+P27) -> 36441.53 | X27: =((Q27*$AB$16)+Q27) -> 41138.645 | Y27: =((R27*$AB$16)+R27) -> 49487.557 | Z27: =((S27*$AB$16)+S27) -> 61061.656 | AA27: =MEDIAN(V27:Z27) -> 41138.645
G28: Med | H28: 680033 | I28: 709429 | J28: 814509 | K28: 987744 | L28: 1221604 | M28: 882664 | N28: Med | O28: =((H28*$AB$15)+H28)/$AB$17 -> 27287.48 | P28: =((I28*$AB$15)+I28)/$AB$17 -> 28467.044 | Q28: =((J28*$AB$15)+J28)/$AB$17 -> 32683.558 | R28: =((K28*$AB$15)+K28)/$AB$17 -> 39634.907 | S28: =((L28*$AB$15)+L28)/$AB$17 -> 49018.937 | T28: =MEDIAN(O28:S28) -> 32683.558 | U28: Med | V28: =((O28*$AB$16)+O28) -> 28422.639 | W28: =((P28*$AB$16)+P28) -> 29651.273 | X28: =((Q28*$AB$16)+Q28) -> 34043.194 | Y28: =((R28*$AB$16)+R28) -> 41283.719 | Z28: =((S28*$AB$16)+S28) -> 51058.125 | AA28: =MEDIAN(V28:Z28) -> 34043.194
G29: Min. | H29: 502979 | I29: 546967 | J29: 644745 | K29: 791460 | L29: 982262 | M29: 693683 | N29: Min. | O29: =((H29*$AB$15)+H29)/$AB$17 -> 20182.887 | P29: =((I29*$AB$15)+I29)/$AB$17 -> 21947.981 | Q29: =((J29*$AB$15)+J29)/$AB$17 -> 25871.489 | R29: =((K29*$AB$15)+K29)/$AB$17 -> 31758.678 | S29: =((L29*$AB$15)+L29)/$AB$17 -> 39414.932 | T29: =MEDIAN(O29:S29) -> 25871.489 | U29: Min. | V29: =((O29*$AB$16)+O29) -> 21022.495 | W29: =((P29*$AB$16)+P29) -> 22861.017 | X29: =((Q29*$AB$16)+Q29) -> 26947.743 | Y29: =((R29*$AB$16)+R29) -> 33079.839 | Z29: =((S29*$AB$16)+S29) -> 41054.593 | AA29: =MEDIAN(V29:Z29) -> 26947.743
E30: HR-10 | F30: Experto en RR.HH. | G30: Máx. | H30: 857087 | I30: 1162995 | J30: 1460946 | K30: 1555867 | L30: 2100460 | M30: 1408031 | N30: Máx. | O30: =((H30*$AB$15)+H30)/$AB$17 -> 34392.073 | P30: =((I30*$AB$15)+I30)/$AB$17 -> 46667.151 | Q30: =((J30*$AB$15)+J30)/$AB$17 -> 58622.941 | R30: =((K30*$AB$15)+K30)/$AB$17 -> 62431.808 | S30: =((L30*$AB$15)+L30)/$AB$17 -> 84284.528 | T30: =MEDIAN(O30:S30) -> 58622.941 | U30: Máx. | V30: =((O30*$AB$16)+O30) -> 35822.783 | W30: =((P30*$AB$16)+P30) -> 48608.505 | X30: =((Q30*$AB$16)+Q30) -> 61061.656 | Y30: =((R30*$AB$16)+R30) -> 65028.971 | Z30: =((S30*$AB$16)+S30) -> 87790.764 | AA30: =MEDIAN(V30:Z30) -> 61061.656
G31: Med | H31: 680033 | I31: 1025330 | J31: 1180125 | K31: 1240225 | L31: 1479152 | M31: 1124346 | N31: Med | O31: =((H31*$AB$15)+H31)/$AB$17 -> 27287.48 | P31: =((I31*$AB$15)+I31)/$AB$17 -> 41143.109 | Q31: =((J31*$AB$15)+J31)/$AB$17 -> 47354.521 | R31: =((K31*$AB$15)+K31)/$AB$17 -> 49766.136 | S31: =((L31*$AB$15)+L31)/$AB$17 -> 59353.488 | T31: =MEDIAN(O31:S31) -> 47354.521 | U31: Med | V31: =((O31*$AB$16)+O31) -> 28422.639 | W31: =((P31*$AB$16)+P31) -> 42854.662 | X31: =((Q31*$AB$16)+Q31) -> 49324.469 | Y31: =((R31*$AB$16)+R31) -> 51836.407 | Z31: =((S31*$AB$16)+S31) -> 61822.593 | AA31: =MEDIAN(V31:Z31) -> 49324.469
G32: Min. | H32: 502979 | I32: 781346 | J32: 857845 | K32: 952144 | L32: 1056820 | M32: 840660 | N32: Min. | O32: =((H32*$AB$15)+H32)/$AB$17 -> 20182.887 | P32: =((I32*$AB$15)+I32)/$AB$17 -> 31352.836 | Q32: =((J32*$AB$15)+J32)/$AB$17 -> 34422.489 | R32: =((K32*$AB$15)+K32)/$AB$17 -> 38206.396 | S32: =((L32*$AB$15)+L32)/$AB$17 -> 42406.699 | T32: =MEDIAN(O32:S32) -> 34422.489 | U32: Min. | V32: =((O32*$AB$16)+O32) -> 21022.495 | W32: =((P32*$AB$16)+P32) -> 32657.114 | X32: =((Q32*$AB$16)+Q32) -> 35854.464 | Y32: =((R32*$AB$16)+R32) -> 39795.782 | Z32: =((S32*$AB$16)+S32) -> 44170.817 | AA32: =MEDIAN(V32:Z32) -> 35854.464
A33: BG-9 | B33: Analyze | D33: BG-9 DCOP/DPD/Director of Function XX | E33: GEN-09 | F33: Profesional nivel operativo | G33: Máx. | H33: 431487 | I33: 820593 | J33: 859600 | K33: 1144676 | L33: 1946078 | M33: 974641 | N33: Máx. | O33: =((H33*$AB$15)+H33)/$AB$17 -> 17314.149 | P33: =((I33*$AB$15)+I33)/$AB$17 -> 32927.689 | Q33: =((J33*$AB$15)+J33)/$AB$17 -> 34492.911 | R33: =((K33*$AB$15)+K33)/$AB$17 -> 45932.07 | S33: =((L33*$AB$15)+L33)/$AB$17 -> 78089.687 | T33: =MEDIAN(O33:S33) -> 34492.911 | U33: Máx. | V33: =((O33*$AB$16)+O33) -> 18034.418 | W33: =((P33*$AB$16)+P33) -> 34297.481 | X33: =((Q33*$AB$16)+Q33) -> 35927.816 | Y33: =((R33*$AB$16)+R33) -> 47842.844 | Z33: =((S33*$AB$16)+S33) -> 81338.218 | AA33: =MEDIAN(V33:Z33) -> 35927.816
G34: Med | H34: 414767 | I34: 675902 | J34: 784178 | K34: 912905 | L34: 1622087 | M34: 823932 | N34: Med | O34: =((H34*$AB$15)+H34)/$AB$17 -> 16643.231 | P34: =((I34*$AB$15)+I34)/$AB$17 -> 27121.717 | Q34: =((J34*$AB$15)+J34)/$AB$17 -> 31466.475 | R34: =((K34*$AB$15)+K34)/$AB$17 -> 36631.865 | S34: =((L34*$AB$15)+L34)/$AB$17 -> 65088.998 | T34: =MEDIAN(O34:S34) -> 31466.475 | U34: Med | V34: =((O34*$AB$16)+O34) -> 17335.589 | W34: =((P34*$AB$16)+P34) -> 28249.98 | X34: =((Q34*$AB$16)+Q34) -> 32775.48 | Y34: =((R34*$AB$16)+R34) -> 38155.75 | Z34: =((S34*$AB$16)+S34) -> 67796.7 | AA34: =MEDIAN(V34:Z34) -> 32775.48
G35: Min. | H35: 398046 | I35: 544206 | J35: 605500 | K35: 690891 | L35: 1374707 | M35: 673222 | N35: Min. | O35: =((H35*$AB$15)+H35)/$AB$17 -> 15972.272 | P35: =((I35*$AB$15)+I35)/$AB$17 -> 21837.191 | Q35: =((J35*$AB$15)+J35)/$AB$17 -> 24296.717 | R35: =((K35*$AB$15)+K35)/$AB$17 -> 27723.176 | S35: =((L35*$AB$15)+L35)/$AB$17 -> 55162.455 | T35: =MEDIAN(O35:S35) -> 24296.717 | U35: Min. | V35: =((O35*$AB$16)+O35) -> 16636.719 | W35: =((P35*$AB$16)+P35) -> 22745.618 | X35: =((Q35*$AB$16)+Q35) -> 25307.46 | Y35: =((R35*$AB$16)+R35) -> 28876.46 | Z35: =((S35*$AB$16)+S35) -> 57457.213 | AA35: =MEDIAN(V35:Z35) -> 25307.46
E36: ADM-09 | F36: Responsable Servicios Administrativos | G36: Máx. | H36: 563226 | I36: 669647 | J36: 816237 | K36: 891313 | L36: 1519105 | M36: 875321 | N36: Máx. | O36: =((H36*$AB$15)+H36)/$AB$17 -> 22600.401 | P36: =((I36*$AB$15)+I36)/$AB$17 -> 26870.724 | Q36: =((J36*$AB$15)+J36)/$AB$17 -> 32752.897 | R36: =((K36*$AB$15)+K36)/$AB$17 -> 35765.449 | S36: =((L36*$AB$15)+L36)/$AB$17 -> 60956.67 | T36: =MEDIAN(O36:S36) -> 32752.897 | U36: Máx. | V36: =((O36*$AB$16)+O36) -> 23540.577 | W36: =((P36*$AB$16)+P36) -> 27988.546 | X36: =((Q36*$AB$16)+Q36) -> 34115.417 | Y36: =((R36*$AB$16)+R36) -> 37253.292 | Z36: =((S36*$AB$16)+S36) -> 63492.468 | AA36: =MEDIAN(V36:Z36) -> 34115.417
G37: Med | H37: 495221 | I37: 645518 | J37: 743226 | K37: 830399 | L37: 1012737 | M37: 744469 | N37: Med | O37: =((H37*$AB$15)+H37)/$AB$17 -> 19871.584 | P37: =((I37*$AB$15)+I37)/$AB$17 -> 25902.507 | Q37: =((J37*$AB$15)+J37)/$AB$17 -> 29823.206 | R37: =((K37*$AB$15)+K37)/$AB$17 -> 33321.171 | S37: =((L37*$AB$15)+L37)/$AB$17 -> 40637.793 | T37: =MEDIAN(O37:S37) -> 29823.206 | U37: Med | V37: =((O37*$AB$16)+O37) -> 20698.242 | W37: =((P37*$AB$16)+P37) -> 26980.051 | X37: =((Q37*$AB$16)+Q37) -> 31063.852 | Y37: =((R37*$AB$16)+R37) -> 34707.332 | Z37: =((S37*$AB$16)+S37) -> 42328.326 | AA37: =MEDIAN(V37:Z37) -> 31063.852
G38: Min. | H38: 427216 | I38: 520001 | J38: 589430 | K38: 739138 | L38: 789728 | M38: 613617 | N38: Min. | O38: =((H38*$AB$15)+H38)/$AB$17 -> 17142.768 | P38: =((I38*$AB$15)+I38)/$AB$17 -> 20865.924 | Q38: =((J38*$AB$15)+J38)/$AB$17 -> 23651.881 | R38: =((K38*$AB$15)+K38)/$AB$17 -> 29659.169 | S38: =((L38*$AB$15)+L38)/$AB$17 -> 31689.178 | T38: =MEDIAN(O38:S38) -> 23651.881 | U38: Min. | V38: =((O38*$AB$16)+O38) -> 17855.907 | W38: =((P38*$AB$16)+P38) -> 21733.946 | X38: =((Q38*$AB$16)+Q38) -> 24635.799 | Y38: =((R38*$AB$16)+R38) -> 30892.99 | Z38: =((S38*$AB$16)+S38) -> 33007.448 | AA38: =MEDIAN(V38:Z38) -> 24635.799
E39: DPM-09 | F39: Responsable de proyecto | G39: Máx. | H39: 489209 | I39: 819342 | J39: 859600 | K39: 1267082 | L39: 1946078 | M39: 1029938 | N39: Máx. | O39: =((H39*$AB$15)+H39)/$AB$17 -> 19630.343 | P39: =((I39*$AB$15)+I39)/$AB$17 -> 32877.49 | Q39: =((J39*$AB$15)+J39)/$AB$17 -> 34492.911 | R39: =((K39*$AB$15)+K39)/$AB$17 -> 50843.819 | S39: =((L39*$AB$15)+L39)/$AB$17 -> 78089.687 | T39: =MEDIAN(O39:S39) -> 34492.911 | U39: Máx. | V39: =((O39*$AB$16)+O39) -> 20446.965 | W39: =((P39*$AB$16)+P39) -> 34245.194 | X39: =((Q39*$AB$16)+Q39) -> 35927.816 | Y39: =((R39*$AB$16)+R39) -> 52958.922 | Z39: =((S39*$AB$16)+S39) -> 81338.218 | AA39: =MEDIAN(V39:Z39) -> 35927.816
G40: Med | H40: 489209 | I40: 690468 | J40: 780720 | K40: 1012737 | L40: 1622087 | M40: 852407 | N40: Med | O40: =((H40*$AB$15)+H40)/$AB$17 -> 19630.343 | P40: =((I40*$AB$15)+I40)/$AB$17 -> 27706.202 | Q40: =((J40*$AB$15)+J40)/$AB$17 -> 31327.717 | R40: =((K40*$AB$15)+K40)/$AB$17 -> 40637.793 | S40: =((L40*$AB$15)+L40)/$AB$17 -> 65088.998 | T40: =MEDIAN(O40:S40) -> 31327.717 | U40: Med | V40: =((O40*$AB$16)+O40) -> 20446.965 | W40: =((P40*$AB$16)+P40) -> 28858.78 | X40: =((Q40*$AB$16)+Q40) -> 32630.95 | Y40: =((R40*$AB$16)+R40) -> 42328.326 | Z40: =((S40*$AB$16)+S40) -> 67796.7 | AA40: =MEDIAN(V40:Z40) -> 32630.95
...

Sheet Grade A
A1: Maintenance (Nivel I) | F1: Driver (Nivel II) | K1: Assistant (Nivel III)
B2: Minimum | C2: Median | D2: Maximum | G2: Minimum | H2: Median | I2: Maximum | L2: Minimum | M2: Median | N2: Maximum
A3: Birtches | B3: 6755.3573 | C3: 7875.0713 | D3: 10675.569 | F3: Birtches | G3: 7250.556 | H3: 9219.1462 | I3: 13250.953 | K3: Birtches | L3: 7884.8098 | M3: 10532.585 | N3: 12215.959
A4: PayLab | B4: 6060 | C4: 10542 | D4: 15024 | F4: PayLab | G4: 6825 | H4: 11161 | I4: 15498 | K4: PayLab | L4: 7604 | M4: 11348 | N4: 15092
A5: ONG Local | B5: 5048 | C5: 6821 | D5: 8593 | F5: ONG Local | G5: 6060 | H5: 8183 | I5: 10308 | K5: ONG Local | L5: 7268 | M5: 9821 | N5: 12374
A6: World Salaries | B6: 1778.0439 | C6: 3893.3096 | D6: 6161.1557 | F6: =+A6 -> World Salaries | G6: 2051.9159 | H6: 4001.0816 | I6: 6327.2559 | K6: =+A6 -> World Salaries | L6: 3247.2574 | M6: 6964.6168 | N6: 11037.933
A7: Media | B7: =MEDIAN(B3:B6) -> 5554 | C7: =MEDIAN(C3:C6) -> 7348.0357 | D7: =MEDIAN(D3:D6) -> 9634.2843 | F7: Media | G7: =MEDIAN(G3:G6) -> 6442.5 | H7: =MEDIAN(H3:H6) -> 8701.0731 | I7: =MEDIAN(I3:I6) -> 11779.476 | K7: Media | L7: =MEDIAN(L3:L6) -> 7436 | M7: =MEDIAN(M3:M6) -> 10176.792 | N7: =MEDIAN(N3:N6) -> 12294.98
A8: Promedio | B8: =AVERAGE(B3:B5) -> 5954.4524 | C8: =AVERAGE(C3:C6) -> 7282.8452 | D8: =AVERAGE(D3:D6) -> 10113.431 | F8: Promedio | G8: =AVERAGE(G3:G5) -> 6711.852 | H8: =AVERAGE(H3:H6) -> 8141.0569 | I8: =AVERAGE(I3:I6) -> 11346.052 | K8: Promedio | L8: =AVERAGE(L3:L5) -> 7585.6033 | M8: =AVERAGE(M3:M6) -> 9666.5503 | N8: =AVERAGE(N3:N6) -> 12679.973
A10: HNL Anual | B10: =+B7*TRM!$I$9 -> 143781.95 | C10: =+C7*TRM!$I$9 -> 190225.95 | D10: =+D7*TRM!$I$9 -> 249412.35 | F10: HNL Anual | G10: =+G7*TRM!$I$9 -> 166783.44 | H10: =+H7*TRM!$I$9 -> 225253.38 | I10: =+I7*TRM!$I$9 -> 304947.08 | K10: HNL Anual | L10: =+L7*TRM!$I$9 -> 192503.17 | M10: =+M7*TRM!$I$9 -> 263456.8 | N10: =+N7*TRM!$I$9 -> 318292.43
A11: HNL Mensual | B11: =+B10/12 -> 11981.829 | C11: =+C10/12 -> 15852.162 | D11: =+D10/12 -> 20784.363 | F11: HNL Mensual | G11: =+G10/12 -> 13898.62 | H11: =+H10/12 -> 18771.115 | I11: =+I10/12 -> 25412.257 | K11: HNL Mensual | L11: =+L10/12 -> 16041.931 | M11: =+M10/12 -> 21954.733 | N11: =+N10/12 -> 26524.369
A12: SMLMV / Mes | B12: =+B11/'Birches Report Level'!$AG$13 -> 0.85625045 | C12: =+C11/'Birches Report Level'!$AG$13 -> 1.1328338 | D12: =+D11/'Birches Report Level'!$AG$13 -> 1.4853007 | F12: SMLMV / Mes | G12: =+G11/'Birches Report Level'!$AG$13 -> 0.99322894 | H12: =+H11/'Birches Report Level'!$AG$13 -> 1.3414292 | I12: =+I11/'Birches Report Level'!$AG$13 -> 1.8160212 | K12: SMLMV / Mes | L12: =+L11/'Birches Report Level'!$AG$13 -> 1.1463951 | M12: =+M11/'Birches Report Level'!$AG$13 -> 1.5689382 | N12: =+N11/'Birches Report Level'!$AG$13 -> 1.8954954

Sheet Grade B
A1: Program Officer (Nivel I) | F1: Senior Program Officer (Nivel II)
B2: Minimum | C2: Median | D2: Maximum | G2: Minimum | H2: Median | I2: Maximum
A3: Birtches | B3: 9406.1413 | C3: 12215.959 | D3: 36453.86 | F3: Birtches | G3: 8109.9647 | H3: 14506.002 | I3: 30075.962
A4: PayLab | B4: 6385 | C4: 12187 | D4: 17989 | E4: Admin officer | F4: PayLab | G4: 9216 | H4: 16974 | I4: 24732 | J4: (sales officer)
A5: ONG local | B5: 8721 | C5: 11790 | D5: 14858 | F5: ONG local | G5: 10468 | H5: 14145 | I5: 17822
A6: =+'Grade A'!A6 -> World Salaries | B6: 3530.9796 | C6: 7455.1916 | D6: 11684.951 | F6: =+A6 -> World Salaries | G6: 4113.1026 | H6: 8141.4813 | I6: 12533.478
A7: Media | B7: =MEDIAN(B3:B6) -> 7553 | C7: =MEDIAN(C3:C6) -> 11988.5 | D7: =MEDIAN(D3:D6) -> 16423.5 | F7: Media | G7: =MEDIAN(G3:G6) -> 8662.9823 | H7: =MEDIAN(H3:H6) -> 14325.501 | I7: =MEDIAN(I3:I6) -> 21277
A8: Promedio | B8: =AVERAGE(B3:B6) -> 7010.7802 | C8: =AVERAGE(C3:C6) -> 10912.038 | D8: =AVERAGE(D3:D6) -> 20246.453 | F8: Promedio | G8: =AVERAGE(G3:G6) -> 7976.7668 | H8: =AVERAGE(H3:H6) -> 13441.621 | I8: =AVERAGE(I3:I6) -> 21290.86
A10: HNL Anual | B10: =+B7*TRM!$I$9 -> 195532.06 | C10: =+C7*TRM!$I$9 -> 310358.29 | D10: =+D7*TRM!$I$9 -> 425171.57 | F10: HNL Anual | G10: =+G7*TRM!$I$9 -> 224267.29 | H10: =+H7*TRM!$I$9 -> 370858.57 | I10: =+I7*TRM!$I$9 -> 550818.98
A11: HNL Mensual | B11: =+B10/12 -> 16294.339 | C11: =+C10/12 -> 25863.191 | D11: =+D10/12 -> 35430.964 | F11: HNL Mensual | G11: =+G10/12 -> 18688.941 | H11: =+H10/12 -> 30904.881 | I11: =+I10/12 -> 45901.581
A12: SMLMV / Mes | B12: =+B11/'Birches Report Level'!$AG$13 -> 1.1644328 | C12: =+C11/'Birches Report Level'!$AG$13 -> 1.848246 | D12: =+D11/'Birches Report Level'!$AG$13 -> 2.5319822 | F12: SMLMV / Mes | G12: =+G11/'Birches Report Level'!$AG$13 -> 1.3355568 | H12: =+H11/'Birches Report Level'!$AG$13 -> 2.2085374 | I12: =+I11/'Birches Report Level'!$AG$13 -> 3.2802378

Sheet Gade C
A1: Program Coordinator (Nivel I) | F1: Technical Specialist (Nivel II) | K1: Senior Specialist (Nivel III)
B2: Minimum | C2: Median | D2: Maximum | G2: Minimum | H2: Median | I2: Maximum | L2: Minimum | M2: Median | N2: Maximum
A3: Birtches | B3: 12995.496 | C3: 18034.083 | D3: 32261.599 | F3: Birtches | G3: 14910.378 | H3: 22186.68 | I3: 40743.255 | K3: Birtches | L3: 15099.756 | M3: 23698.315 | N3: 51229.321
A4: PayLab | B4: 8880 | C4: 17400 | D4: 25920 | F4: PayLab | G4: 9158 | H4: 18382 | I4: 27606 | K4: PayLab | L4: 11000 | M4: 23000 | N4: 35000 | O4: Project Manager
A5: ONG local | B5: 12560 | C5: 16973 | D5: 21385 | F5: ONG Local | G5: 15697 | H5: 21231 | I5: 26765 | L5: 19627 | M5: 26518 | N5: 33409
A6: =+'Grade B'!A6 -> World Salaries | B6: 4113.1026 | C6: 8141.4813 | D6: 16897.79 | F6: =+A6 -> World Salaries | G6: 5836.6811 | H6: 11399.104 | I6: 17510.043 | K6: =+F6 -> World Salaries | L6: 8208.4363 | M6: 17938.813 | N6: 28399.258
A7: Media | B7: =MEDIAN(B3:B6) -> 10720 | C7: =MEDIAN(C3:C6) -> 17186.5 | D7: =MEDIAN(D3:D6) -> 23652.5 | F7: Media | G7: =MEDIAN(G3:G6) -> 12034.189 | H7: =MEDIAN(H3:H6) -> 19806.5 | I7: =MEDIAN(I3:I6) -> 27185.5 | K7: Media | L7: =MEDIAN(L3:L6) -> 13049.878 | M7: =MEDIAN(M3:M6) -> 23349.158 | N7: =MEDIAN(N3:N6) -> 34204.5
A8: Promedio | B8: =AVERAGE(B3:B6) -> 9637.1496 | C8: =AVERAGE(C3:C6) -> 15137.141 | D8: =AVERAGE(D3:D6) -> 24116.097 | F8: Promedio | G8: =AVERAGE(G3:G6) -> 11400.515 | H8: =AVERAGE(H3:H6) -> 18299.696 | I8: =AVERAGE(I3:I6) -> 28156.075 | K8: Promedio | L8: =AVERAGE(L3:L6) -> 13483.798 | M8: =AVERAGE(M3:M6) -> 22788.782 | N8: =AVERAGE(N3:N6) -> 37009.395
A10: HNL Anual | B10: =+B7*TRM!$I$9 -> 277519.36 | C10: =+C7*TRM!$I$9 -> 444924.11 | D10: =+D7*TRM!$I$9 -> 612315.92 | F10: HNL Anual | G10: =+G7*TRM!$I$9 -> 311541.09 | H10: =+H7*TRM!$I$9 -> 512750.67 | I10: =+I7*TRM!$I$9 -> 703778.22 | K10: HNL Anual | L10: =+L7*TRM!$I$9 -> 337835.24 | M10: =+M7*TRM!$I$9 -> 604462.99 | N10: =+N7*TRM!$I$9 -> 885486.1
A11: HNL Mensual | B11: =+B10/12 -> 23126.613 | C11: =+C10/12 -> 37077.009 | D11: =+D10/12 -> 51026.327 | F11: HNL Mensual | G11: =+G10/12 -> 25961.757 | H11: =+H10/12 -> 42729.223 | I11: =+I10/12 -> 58648.185 | K11: HNL Mensual | L11: =+L10/12 -> 28152.936 | M11: =+M10/12 -> 50371.916 | N11: =+N10/12 -> 73790.508
A12: SMLMV / Mes | B12: =+B11/'Birches Report Level'!$AG$13 -> 1.6526836 | C12: =+C11/'Birches Report Level'!$AG$13 -> 2.6496126 | D12: =+D11/'Birches Report Level'!$AG$13 -> 3.6464645 | F12: SMLMV / Mes | G12: =+G11/'Birches Report Level'!$AG$13 -> 1.8552898 | H12: =+H11/'Birches Report Level'!$AG$13 -> 3.0535334 | I12: =+I11/'Birches Report Level'!$AG$13 -> 4.1911409 | K12: SMLMV / Mes | L12: =+L11/'Birches Report Level'!$AG$13 -> 2.0118768 | M12: =+M11/'Birches Report Level'!$AG$13 -> 3.5996987 | N12: =+N11/'Birches Report Level'!$AG$13 -> 5.2732478

Sheet Grade D
A1: Project Manager (Nivel I) | F1: Director (Nivel II) | K1: Senior Director (Nivel III)
B2: Minimum | C2: Median | D2: Maximum | G2: Minimum | H2: Median | I2: Maximum | L2: Minimum | M2: Median | N2: Maximum
A3: Birtches | B3: 17335.589 | C3: 31273.835 | D3: 67796.7 | F3: Birtches | G3: 19121.573 | H3: 35108.615 | I3: 51983.32 | K3: Birtches | L3: 27533.597 | M3: 44546.647 | N3: 61822.593
A4: PayLab | B4: 11000 | C4: =(B4+D4)/2 -> 28000 | D4: 45000 | E4: Senior project Manager | F4: PayLab | G4: 13000 | H4: 34000 | I4: 55000 | J4: Technical Director | K4: PayLab | L4: 14000 | M4: 39500 | N4: 65000 | O4: Managing Director
A5: ONG Local | F5: ONG Local | G5: 24541 | H5: 33159 | I5: 41778 | K5: ONG Local | L5: 30671.199 | M5: 41447.93 | N5: 52224.197
A6: =+'Gade C'!A6 -> World Salaries | B6: 10960.677 | C6: 23825.711 | D6: 37870.828 | F6: =+A6 -> World Salaries | G6: 13967.862 | H6: 26773.022 | I6: 40856.768 | K6: =+F6 -> World Salaries
A7: Media | B7: =MEDIAN(+B3,B4,B6) -> 11000 | C7: =MEDIAN(+C3,C4,C6) -> 28000 | D7: =MEDIAN(+D3,D4,D6) -> 45000 | F7: Media | G7: =MEDIAN(G2:G6) -> 16544.717 | H7: =MEDIAN(H2:H6) -> 33579.5 | I7: =MEDIAN(I2:I6) -> 46880.66 | K7: Media | L7: =MEDIAN(L3:L5) -> 27533.597 | M7: =MEDIAN(M3:M5) -> 41447.93 | N7: =MEDIAN(N3:N5) -> 61822.593
A8: Promedio | B8: =AVERAGE(B3,B4,B6) -> 13098.755 | C8: =AVERAGE(C3,C4,C6) -> 27699.849 | D8: =AVERAGE(D3,D4,D6) -> 50222.509 | F8: Promedio | G8: =AVERAGE(G3:G6) -> 17657.609 | H8: =AVERAGE(H3:H6) -> 32260.159 | I8: =AVERAGE(I3:I6) -> 47404.522 | K8: Promedio | L8: =AVERAGE(L3:L5) -> 24068.265 | M8: =AVERAGE(M3:M5) -> 41831.525 | N8: =AVERAGE(N3:N5) -> 59682.263
A10: HNL Anual | B10: =+B7*TRM!$I$9 -> 284768 | C10: =+C7*TRM!$I$9 -> 724864 | D10: =+D7*TRM!$I$9 -> 1164960 | F10: HNL Anual | G10: =+G7*TRM!$I$9 -> 428309.64 | H10: =+H7*TRM!$I$9 -> 869306.1 | I10: =+I7*TRM!$I$9 -> 1213646.5 | K10: HNL Anual | L10: =+L7*TRM!$I$9 -> 712789.76 | M10: =+M7*TRM!$I$9 -> 1073004 | N10: =+N7*TRM!$I$9 -> 1600463.3
A11: HNL Mensual | B11: =+B10/12 -> 23730.667 | C11: =+C10/12 -> 60405.333 | D11: =+D10/12 -> 97080 | F11: HNL Mensual | G11: =+G10/12 -> 35692.47 | H11: =+H10/12 -> 72442.175 | I11: =+I10/12 -> 101137.21 | K11: HNL Mensual | L11: =+L10/12 -> 59399.147 | M11: =+M10/12 -> 89417 | N11: =+N10/12 -> 133371.94
A12: SMLMV / Mes | B12: =+B11/'Birches Report Level'!$AG$13 -> 1.6958507 | C12: =+C11/'Birches Report Level'!$AG$13 -> 4.3167109 | D12: =+D11/'Birches Report Level'!$AG$13 -> 6.9375711 | F12: SMLMV / Mes | G12: =+G11/'Birches Report Level'!$AG$13 -> 2.5506701 | H12: =+H11/'Birches Report Level'!$AG$13 -> 5.1768927 | I12: =+I11/'Birches Report Level'!$AG$13 -> 7.2275092 | K12: SMLMV / Mes | L12: =+L11/'Birches Report Level'!$AG$13 -> 4.2448064 | M12: =+M11/'Birches Report Level'!$AG$13 -> 6.3899547 | N12: =+N11/'Birches Report Level'!$AG$13 -> 9.5310809

Sheet Grade E
A1: (Nivel I) | F1: (Nivel II) | K1: (Nivel III)
B2: Minimum | C2: Median | D2: Maximum | G2: Minimum | H2: Median | I2: Maximum | L2: Minimum | M2: Median | N2: Maximum
A3: Birtches | B3: 65512.258 | C3: 73996.673 | D3: 90404.684 | F3: Birtches | G3: 72227.198 | H3: 80975.22 | I3: 97523.917 | K3: Birtches | L3: 73441.497 | M3: 90404.684 | N3: 117028.72
A4: PayLab | F4: PayLab | G4: 22000 | H4: 58000 | I4: 94000 | J4: chief executive officer | K4: PayLab
A5: ONG Local | B5: 39872.84 | C5: 53882.262 | D5: 67891.687 | F5: ONG Local | G5: 0 | H5: 0 | I5: 0 | L5: 51825 | M5: 70072 | N5: 88319
A6: Propuesta | D6: 78000 | K6: Presupuesto | N6: =+'Budget USDA Salary Categories'!D6 -> 114996
A7: Media | B7: =MEDIAN(B3:B6) -> 52692.549 | C7: =MEDIAN(C3:C6) -> 63939.467 | D7: =MEDIAN(D3:D6) -> 78000 | F7: Media | G7: =MEDIAN(G3:G5) -> 22000 | H7: =MEDIAN(H3:H5) -> 58000 | I7: =MEDIAN(I3:I5) -> 94000 | K7: Media | L7: =MEDIAN(L3:L5) -> 62633.248 | M7: =MEDIAN(M3:M5) -> 80238.342 | N7: =MEDIAN(N3:N6) -> 114996
A8: Promedio | B8: =AVERAGE(B3,B5) -> 52692.549 | C8: =AVERAGE(C3,C5) -> 63939.467 | D8: =AVERAGE(D3,D5,D6) -> 78765.457 | F8: Promedio | G8: =AVERAGE(G3,G4) -> 47113.599 | H8: =AVERAGE(H3,H4) -> 69487.61 | I8: =AVERAGE(I3,I4) -> 95761.958 | K8: Promedio | L8: =AVERAGE(L3) -> 73441.497 | M8: =AVERAGE(M3) -> 90404.684 | N8: =AVERAGE(N3,N5,N6) -> 106781.24
A10: HNL Anual | B10: =+B7*TRM!$I$9 -> 1364104.7 | C10: =+C7*TRM!$I$9 -> 1655264.9 | D10: =+D7*TRM!$I$9 -> 2019264 | F10: HNL Anual | G10: =+G7*TRM!$I$9 -> 569536 | H10: =+H7*TRM!$I$9 -> 1501504 | I10: =+I7*TRM!$I$9 -> 2433472 | K10: HNL Anual | L10: =+L7*TRM!$I$9 -> 1621449.5 | M10: =+M7*TRM!$I$9 -> 2077210.2 | N10: =+N7*TRM!$I$9 -> 2977016.4
A11: HNL Mensual | B11: =+B10/12 -> 113675.39 | C11: =+C10/12 -> 137938.74 | D11: =+D10/12 -> 168272 | F11: HNL Mensual | G11: =+G10/12 -> 47461.333 | H11: =+H10/12 -> 125125.33 | I11: =+I10/12 -> 202789.33 | K11: HNL Mensual | L11: =+L10/12 -> 135120.79 | M11: =+M10/12 -> 173100.85 | N11: =+N10/12 -> 248084.7
A12: SMLMV / Mes | B12: =+B11/'Birches Report Level'!$AG$13 -> 8.1235179 | C12: =+C11/'Birches Report Level'!$AG$13 -> 9.8574356 | D12: =+D11/'Birches Report Level'!$AG$13 -> 12.025123 | F12: SMLMV / Mes | G12: =+G11/'Birches Report Level'!$AG$13 -> 3.3917015 | H12: =+H11/'Birches Report Level'!$AG$13 -> 8.9417584 | I12: =+I11/'Birches Report Level'!$AG$13 -> 14.491815 | K12: SMLMV / Mes | L12: =+L11/'Birches Report Level'!$AG$13 -> 9.6560582 | M12: =+M11/'Birches Report Level'!$AG$13 -> 12.370205 | N12: =+N11/'Birches Report Level'!$AG$13 -> 17.728732

Sheet Budget USDA Salary Categories
C3: 12 | D3: TRM | E3: 25.9679
C4: 12 | D4: TRM | E4: 25.9679 | H4: For field offices
A5: CCN Honduran Field Staff (LOE) | B5: Salario mensaul UDS | C5: Salario mensual HNL | D5: Salario anual UDS | E5: Salario anual HNL | G5: Purpose | H5: Level | I5: Purpose | J5: Proposed Field Office Grade | K5: Purpose
A6: Key Personnel: Chief of Party | B6: 9583 | C6: =+B6*$E$3 -> 248850.39 | D6: =+B6*$C$3 -> 114996 | E6: =+D6*$E$3 -> 2986204.6 | F6: POA D | G6: BG-11 Country Directors | H6: BG-12 | I6: Integrate-Transform | J6: Poa-E | K6: BG-12 Executive
A7: Key Personnel: Deputy Chief of Party | B7: 6500 | C7: =+B7*$E$3 -> 168791.35 | D7: =+B7*$C$3 -> 78000 | E7: =+D7*$E$3 -> 2025496.2 | F7: POA D | G7: BG-9 DCOP/DPD/Director of Function XX | H7: BG-11 | I7: Innovate | K7: BG-11 Country Directors
A8: Policy & Sustainability Specialist | B8: 1500 | C8: =+B8*$E$3 -> 38951.85 | D8: =+B8*$C$3 -> 18000 | E8: =+D8*$E$3 -> 467422.2 | F8: POA C | G8: BG-7 Manager/Specialist | H8: BG-10 | I8: Adapt | J8: Poa-D | K8: BG-10 Project Director/COP
A9: Education Director | B9: 4583 | C9: =+B9*$E$3 -> 119010.89 | D9: =+B9*$C$3 -> 54996 | E9: =+D9*$E$3 -> 1428130.6 | F9: POA D | G9: BG-9 DCOP/DPD/Director of Function XX | H9: BG-9 | I9: Analyze | K9: BG-9 DCOP/DPD/Director of Function XX
A10: Education Specialist | B10: 2000 | C10: =+B10*$E$3 -> 51935.8 | D10: =+B10*$C$3 -> 24000 | E10: =+D10*$E$3 -> 623229.6 | F10: POA C | G10: BG-7 Manager/Specialist | H10: BG-8 | I10: Apply Basic Concepts | K10: BG-8 Transitional Managerial
A11: Education Officer | B11: 1000 | C11: =+B11*$E$3 -> 25967.9 | D11: =+B11*$C$3 -> 12000 | E11: =+D11*$E$3 -> 311614.8 | F11: POA B | G11: BG-4 Officer/Technical | H11: BG-7 | I11: Manage Integrated Processes | J11: Poa-C | K11: BG-7 Manager/Specialist
A12: Nutrition and Health Specialist | B12: 1500 | C12: =+B12*$E$3 -> 38951.85 | D12: =+B12*$C$3 -> 18000 | E12: =+D12*$E$3 -> 467422.2 | F12: POA C | G12: BG-7 Manager/Specialist | H12: BG-6 | I12: Ensure Process Integrity | K12: BG-6 Coordinator/Jr Specialist
A13: Nutrition Officer - (2 Individuals) | B13: 1000 | C13: =+B13*$E$3 -> 25967.9 | D13: =+B13*$C$3 -> 12000 | E13: =+D13*$E$3 -> 311614.8 | F13: POA B | G13: BG-4 Officer/Technical | H13: BG-5 | I13: Execute Intricate Transactions | J13: Poa-B | K13: BG-5 Sr. Officer/Sr. Technical
A14: School Feeding Specialist | B14: 1500 | C14: =+B14*$E$3 -> 38951.85 | D14: =+B14*$C$3 -> 18000 | E14: =+D14*$E$3 -> 467422.2 | F14: POA C | G14: BG-7 Manager/Specialist | H14: BG-4 | I14: Process Basic Transactions | K14: BG-4 Officer/Technical
A15: Food Aid Monitors - (2 Individuals) | B15: 1000 | C15: =+B15*$E$3 -> 25967.9 | D15: =+B15*$C$3 -> 12000 | E15: =+D15*$E$3 -> 311614.8 | F15: POA B | G15: BG-4 Officer/Technical | H15: BG-3 | I15: Provide General Support | J15: Poa-A | K15: BG-3 Assistant
A16: WASH Officer | B16: 1000 | C16: =+B16*$E$3 -> 25967.9 | D16: =+B16*$C$3 -> 12000 | E16: =+D16*$E$3 -> 311614.8 | F16: POA B | G16: BG-4 Officer/Technical | H16: BG-2 | I16: Provide Mechanical Support | K16: BG-2 Driver
A17: Communications Specialist | B17: 1500 | C17: =+B17*$E$3 -> 38951.85 | D17: =+B17*$C$3 -> 18000 | E17: =+D17*$E$3 -> 467422.2 | F17: POA C | G17: BG-7 Manager/Specialist | H17: BG-1 | I17: Provide Physical Support | K17: BG-1 Maintenance
A18: Communications Officer | B18: 1000 | C18: =+B18*$E$3 -> 25967.9 | D18: =+B18*$C$3 -> 12000 | E18: =+D18*$E$3 -> 311614.8 | F18: POA B | G18: BG-4 Officer/Technical
A19: Education & Community Engagement Specialist | B19: 1500 | C19: =+B19*$E$3 -> 38951.85 | D19: =+B19*$C$3 -> 18000 | E19: =+D19*$E$3 -> 467422.2 | F19: POA C | G19: BG-7 Manager/Specialist
A20: Education & Community Engagement Officer | B20: 1000 | C20: =+B20*$E$3 -> 25967.9 | D20: =+B20*$C$3 -> 12000 | E20: =+D20*$E$3 -> 311614.8 | F20: POA B | G20: BG-4 Officer/Technical
A21: Private Sector Specialist | B21: 1500 | C21: =+B21*$E$3 -> 38951.85 | D21: =+B21*$C$3 -> 18000 | E21: =+D21*$E$3 -> 467422.2 | F21: POA C | G21: BG-7 Manager/Specialist
A22: Key Personnel: M&E Director | B22: 4583 | C22: =+B22*$E$3 -> 119010.89 | D22: =+B22*$C$3 -> 54996 | E22: =+D22*$E$3 -> 1428130.6 | F22: POA D | G22: BG-9 DCOP/DPD/Director of Function XX
A23: M&E Specialist | B23: 2000 | C23: =+B23*$E$3 -> 51935.8 | D23: =+B23*$C$3 -> 24000 | E23: =+D23*$E$3 -> 623229.6 | F23: POA C | G23: BG-7 Manager/Specialist
A24: M&E Officer | B24: 1250 | C24: =+B24*$E$3 -> 32459.875 | D24: =+B24*$C$3 -> 15000 | E24: =+D24*$E$3 -> 389518.5 | F24: POA B | G24: BG-4 Officer/Technical
A25: Supply Chain Manager | B25: 5000 | C25: =+B25*$E$3 -> 129839.5 | D25: =+B25*$C$3 -> 60000 | E25: =+D25*$E$3 -> 1558074 | F25: POA D | G25: BG-9 DCOP/DPD/Director of Function XX
A26: In-Country Logistics Specialist | B26: 2000 | C26: =+B26*$E$3 -> 51935.8 | D26: =+B26*$C$3 -> 24000 | E26: =+D26*$E$3 -> 623229.6 | F26: POA C | G26: BG-7 Manager/Specialist
A27: US Commodity Logistics Specialist | B27: 2000 | C27: =+B27*$E$3 -> 51935.8 | D27: =+B27*$C$3 -> 24000 | E27: =+D27*$E$3 -> 623229.6 | F27: POA C | G27: BG-7 Manager/Specialist
A28: Warehouse Manager | B28: 1250 | C28: =+B28*$E$3 -> 32459.875 | D28: =+B28*$C$3 -> 15000 | E28: =+D28*$E$3 -> 389518.5 | F28: POA C | G28: BG-7 Manager/Specialist
A29: Warehouse Officer - (2 Individuals) | B29: 1000 | C29: =+B29*$E$3 -> 25967.9 | D29: =+B29*$C$3 -> 12000 | E29: =+D29*$E$3 -> 311614.8 | F29: POA B | G29: BG-4 Officer/Technical
... A39: Driver - (2 Individuals) | B39: 500 | C39: =+B39*$E$3 -> 12983.95 | D39: =+B39*$C$3 -> 6000 | E39: =+D39*$E$3 -> 155807.4 | F39: POA A | G39: BG-2 Driver

Sheet Birches Report Level
E1: Birchis 2023 | L1: Estimado 2025 con incremento del 11.4% | S1: Estimado 2024 con incremento del 3% | Z1: Estimado 2025 con incremento del 3%
A2: Level | B2: Purpose | C2: Proposed Field Office Grade | D2: Purpose | F2: Bajo | G2: Percentil 25 | H2: Percentil 50 | I2: Percentil 75 | J2: Alto | K2: Media | M2: Bajo | N2: Percentil 25 | O2: Percentil 50 | P2: Percentil 75 | Q2: Alto | R2: Media | T2: Bajo | U2: Percentil 25 | V2: Percentil 50 | W2: Percentil 75 | X2: Alto | Y2: Media | AA2: Bajo | AB2: Percentil 25 | AC2: Percentil 50 | AD2: Percentil 75 | AE2: Alto | AF2: Media | AG2: https://www.trabajo.gob.hn/tabla-de-salario-minimo/?utm_source=chatgpt.com
A3: BG-12 | B3: Integrate-Transform | C3: Poa-E | D3: BG-12 Executive/DCOP | E3: Máx. | F3: 1281000 | G3: 1668232 | H3: 1757143 | I3: 2163000 | J3: 2800000 | K3: 1898529 | L3: Máx. | M3: =((F3*$AG$11)+F3)/$AG$12 -> 54925.448 | N3: =((G3*$AG$11)+G3)/$AG$12 -> 71528.798 | O3: =((H3*$AG$11)+H3)/$AG$12 -> 75341.036 | P3: =((I3*$AG$11)+I3)/$AG$12 -> 92742.97 | Q3: =((J3*$AG$11)+J3)/$AG$12 -> 120055.62 | R3: =MEDIAN(M3:Q3) -> 75341.036 | S3: Máx. | T3: =((F3*$AG$9)+F3)/$AG$12 -> 50966.857 | U3: =((G3*$AG$9)+G3)/$AG$12 -> 66373.569 | V3: =((H3*$AG$9)+H3)/$AG$12 -> 69911.051 | W3: =((I3*$AG$9)+I3)/$AG$12 -> 86058.792 | X3: =((J3*$AG$9)+J3)/$AG$12 -> 111402.97 | Y3: =MEDIAN(T3:X3) -> 69911.051 | Z3: Máx. | AA3: =(T3*$AG$10)+T3 -> 52495.863 | AB3: =(U3*$AG$10)+U3 -> 68364.776 | AC3: =(V3*$AG$10)+V3 -> 72008.383 | AD3: =(W3*$AG$10)+W3 -> 88640.555 | AE3: =(X3*$AG$10)+X3 -> 114745.06 | AF3: =MEDIAN(AA3:AE3) -> 72008.383
