Workbook

Sheet Data1
A1: Respondent | B1: Pay1 | C1: Pay2 | D1: Pay3 | E1: Pay4 | F1: Pay5 | G1: HI1 | H1: HI2 | I1: HI3 | J1: HI4 | K1: HI5 | L1: HI6 | M1: VI1 | N1: VI2 | O1: VI3 | P1: VI4 | Q1: VI5 | R1: VI6 | S1: DI1 | T1: DI2 | U1: DI3 | V1: DI4 | W1: DI5 | X1: DI6 | Y1: STD1 | Z1: STD2 | AA1: STD3 | AB1: STD4 | AC1: STD5 | AD1: STD6 | AE1: LI1 | AF1: LI2 | AG1: LI3 | AH1: LI4 | AI1: LI5 | AJ1: LTD1 | AK1: LTD2 | AL1: LTD3 | AM1: LTD4 | AN1: LTD5 | AO1: 403B1 | AP1: 403B2 | AQ1: 403B3 | AR1: 403B4 | AS1: 403B5 | AT1: 403B6 | AU1: ALP1 | AV1: ALP2 | AW1: ALP3 | AX1: ALP4 | AY1: ALP5 | AZ1: ALP6 | BA1: SLP1 | BB1: SLP2 | BC1: SLP3 | BD1: SLP4 | BE1: SLP5 | BF1: SLB1 | BG1: SLB2 | BH1: SLB3 | BI1: SLB4 | BJ1: SLB5 | BK1: SLD1 | BL1: SLD2 | BM1: SLD3 | BN1: SLD4 | BO1: SLD5 | BP1: PLP1 | BQ1: PLP2 | BR1: PLP3 | BS1: PLP4 | BT1: PLP5 | BU1: CLP1 | BV1: CLP2 | BW1: CLP3 | BX1: CLP4 | BY1: CLP5 | BZ1: CLP6 | CA1: PHOL1 | CB1: PHOL2 | CC1: PHOL3 | CD1: PHOL4 | CE1: PHOL5 | CF1: FSA1 | CG1: FSA2 | CH1: FSA3 | CI1: FSA4 | CJ1: FSA5 | CK1: SB1 | CL1: SB2 | CM1: SB3 | CN1: SB4 | CO1: SB5 | CP1: FWA1 | CQ1: FWA2 | CR1: FWA3 | CS1: FWA4 | CT1: FWA5 | CU1: CPT1 | CV1: CPT2 | CW1: CPT3 | CX1: CPT4 | CY1: CPT5 | CZ1: PD1 | DA1: PD2 | DB1: PD3 | DC1: PD4 | DD1: PD5 | DE1: PD6 | DF1: 30MPL1 | DG1: 30MPL2 | DH1: 30MPL3 | DI1: 30MPL4 | DJ1: 30MPL5 | DK1: TCP1 | DL1: TCP2 | DM1: TCP3 | DN1: TCP4 | DO1: TCP5 | DP1: TCP6
A2: 1 | B2: 4 | C2: 5 | D2: 4 | E2: 3 | F2: 5 | G2: 3 | H2: 5 | I2: idk | J2: idk | K2: 2 | L2: 4 | M2: 1 | N2: 3 | O2: idk | P2: idk | Q2: 2 | R2: 3 | S2: 2 | T2: 5 | U2: idk | V2: idk | W2: 3 | X2: 3 | Y2: 4 | Z2: 5 | AA2: idk | AB2: idk | AC2: 5 | AD2: 5 | AE2: 2 | AF2: 3 | AG2: 5 | AH2: 5 | AI2: 1 | AJ2: 4 | AK2: 5 | AL2: 5 | AM2: 5 | AN2: 3 | AO2: 3 | AP2: 5 | AQ2: idk | AR2: idk | AS2: 2 | AT2: 2 | AU2: 4 | AV2: 5 | AW2: idk | AX2: 4 | AY2: na | AZ2: 4 | BA2: 4 | BB2: 5 | BC2: idk | BD2: 4 | BE2: 3 | BF2: 3 | BG2: 5 | BH2: idk | BI2: idk | BJ2: 2 | BK2: 2 | BL2: 4 | BM2: idk | BN2: 4 | BO2: 2 | BP2: 1 | BQ2: 1 | BR2: idk | BS2: idk | BT2: idk | BU2: 2 | BV2: 4 | BW2: idk | BX2: idk | BY2: 3 | BZ2: 1 | CA2: 3 | CB2: 5 | CC2: 5 | CD2: 5 | CE2: 2 | CF2: 3 | CG2: 4 | CH2: idk | CI2: idk | CJ2: idk | CK2: 3 | CL2: 5 | CM2: idk | CN2: 5 | CO2: 4 | CP2: 4 | CQ2: 5 | CR2: idk | CS2: 5 | CT2: 1 | CU2: 2 | CV2: 4 | CW2: idk | CX2: 1 | CY2: 5 | CZ2: 2 | DA2: 3 | DB2: idk | DC2: idk | DD2: 3 | DE2: 3 | DF2: 4 | DG2: 5 | DH2: idk | DI2: 5 | DJ2: 1 | DK2: 4 | DL2: 5 | DM2: 5 | DN2: 5 | DO2: 2
A3: 2 | B3: 4 | C3: 5 | D3: 5 | E3: 5 | F3: 2 | G3: 5 | H3: 5 | I3: 5 | J3: 5 | K3: 1 | L3: 1 | M3: 1 | N3: 2 | O3: 5 | P3: 5 | Q3: 1 | R3: 1 | S3: 1 | T3: 3 | U3: 4 | V3: 5 | W3: 1 | X3: 1 | Y3: 1 | Z3: 2 | AA3: 5 | AB3: 5 | AC3: 1 | AD3: 1 | AE3: 1 | AF3: 2 | AG3: 4 | AH3: 5 | AI3: 1 | AJ3: 1 | AK3: 1 | AL3: 5 | AM3: 5 | AN3: 1 | AO3: 3 | AP3: 5 | AQ3: 5 | AR3: 5 | AS3: 1 | AT3: 1 | AU3: 3 | AV3: 5 | AW3: 5 | AX3: 5 | AY3: 5 | AZ3: 1 | BA3: 3 | BB3: 5 | BC3: 5 | BD3: 5 | BE3: 1 | BF3: 3 | BG3: 5 | BH3: idk | BI3: 5 | BJ3: 1 | BK3: 1 | BL3: 5 | BM3: idk | BN3: 5 | BO3: 1 | BP3: 3 | BQ3: 5 | BR3: 3 | BS3: 5 | BT3: 1 | BU3: 3 | BV3: 5 | BW3: idk | BX3: idk | BY3: 5 | BZ3: 1 | CA3: 1 | CB3: 4 | CC3: 5 | CD3: 5 | CE3: 1 | CF3: 1 | CG3: 1 | CH3: idk | CI3: na | CJ3: 1 | CK3: 2 | CL3: 4 | CM3: 5 | CN3: 5 | CO3: 1 | CP3: 5 | CQ3: 5 | CR3: 5 | CS3: 5 | CT3: 1 | CU3: 4 | CV3: 5 | CW3: 5 | CX3: 5 | CY3: 1 | CZ3: 4 | DA3: 5 | DB3: idk | DC3: 2 | DD3: 1 | DE3: 2 | DF3: 4 | DG3: 5 | DH3: idk | DI3: 5 | DJ3: 1 | DK3: 5 | DL3: 5 | DM3: 5 | DN3: 5 | DO3: 1
A4: 3 | B4: 5 | C4: 5 | D4: 3 | E4: 3 | F4: 4 | G4: 3 | H4: 5 | I4: 5 | J4: 4 | K4: 1 | L4: 1 | M4: 4 | N4: 4 | O4: 3 | P4: 3 | Q4: 2 | R4: 2 | S4: 5 | T4: 5 | U4: 5 | V4: 5 | W4: 1 | X4: 1 | Y4: 3 | Z4: 3 | AA4: 3 | AB4: 3 | AC4: 3 | AD4: 3 | AE4: 1 | AF4: 4 | AG4: 3 | AH4: 3 | AI4: 1 | AJ4: idk | AK4: idk | AL4: idk | AM4: idk | AN4: idk | AO4: 5 | AP4: 5 | AQ4: 4 | AR4: 1 | AS4: 4 | AT4: 5 | AU4: 5 | AV4: 5 | AW4: 3 | AX4: 2 | AY4: 3 | AZ4: 5 | BA4: idk | BB4: idk | BC4: idk | BD4: idk | BE4: idk | BF4: 5 | BG4: 5 | BH4: 1 | BI4: 5 | BJ4: 1 | BK4: idk | BL4: idk | BM4: idk | BN4: idk | BO4: idk | BP4: 4 | BQ4: 4 | BR4: 1 | BS4: 1 | BT4: 4 | BU4: 5 | BV4: 5 | BW4: 1 | BX4: 1 | BY4: 1 | BZ4: 3 | CA4: 5 | CB4: 5 | CC4: 3 | CD4: 1 | CE4: 5 | CF4: idk | CG4: idk | CH4: idk | CI4: idk | CJ4: idk | CK4: na | CL4: na | CM4: na | CN4: na | CO4: na | CP4: 5 | CQ4: 5 | CR4: 4 | CS4: 3 | CT4: 2 | CU4: 5 | CV4: 5 | CW4: 1 | CX4: 1 | CY4: 2 | CZ4: 5 | DA4: 5 | DB4: 3 | DC4: 2 | DD4: 5 | DE4: 5 | DF4: 5 | DG4: 5 | DH4: 1 | DI4: 1 | DJ4: 2 | DK4: 3 | DL4: 2 | DM4: 2 | DN4: 2 | DO4: 4
A5: 4 | B5: 4 | C5: 5 | D5: 3 | E5: 2 | F5: 3 | G5: 3 | H5: 5 | I5: 4 | J5: 5 | K5: 2 | L5: 2 | M5: 1 | N5: 4 | O5: 2 | P5: 3 | Q5: 2 | R5: 2 | S5: 3 | T5: 5 | U5: 4 | V5: 4 | W5: 2 | X5: 2 | Y5: 2 | Z5: 4 | AA5: 2 | AB5: 1 | AC5: 2 | AD5: 2 | AE5: 3 | AF5: 5 | AG5: 5 | AH5: 5 | AI5: 2 | AJ5: 3 | AK5: 5 | AL5: 5 | AM5: 2 | AN5: 2 | AO5: 3 | AP5: 5 | AQ5: 2 | AR5: 3 | AS5: 3 | AT5: 3 | AU5: 3 | AV5: 5 | AW5: 2 | AX5: 3 | AY5: 2 | AZ5: 2 | BA5: 3 | BB5: 5 | BC5: 5 | BD5: 3 | BE5: 2 | BF5: 2 | BG5: 5 | BH5: 3 | BI5: 4 | BJ5: 2 | BK5: 3 | BL5: 5 | BM5: 2 | BN5: 3 | BO5: 2 | BP5: 3 | BQ5: 5 | BR5: 5 | BS5: 4 | BT5: 2 | BU5: 3 | BV5: 4 | BW5: 3 | BX5: 3 | BY5: 4 | BZ5: 2 | CA5: 3 | CB5: 4 | CC5: 3 | CD5: 3 | CE5: 2 | CF5: 2 | CG5: 3 | CH5: 4 | CI5: 4 | CJ5: 1 | CK5: 3 | CL5: 4 | CM5: 2 | CN5: 2 | CO5: 2 | CP5: 3 | CQ5: 5 | CR5: 5 | CS5: 4 | CT5: 3 | CU5: 2 | CV5: 4 | CW5: 1 | CX5: 1 | CY5: 2 | CZ5: 3 | DA5: 4 | DB5: 2 | DC5: 3 | DD5: 2 | DE5: 3 | DF5: 2 | DG5: 3 | DH5: 3 | DI5: 3 | DJ5: 3 | DK5: 4 | DL5: 4 | DM5: 3 | DN5: 4 | DO5: 3
A6: 5 | B6: 5 | C6: 5 | D6: 3 | E6: 4 | F6: 4 | G6: 5 | H6: 5 | I6: 4 | J6: 4 | K6: 3 | L6: 1 | M6: 1 | N6: 1 | O6: 3 | P6: na | Q6: 1 | R6: 1 | S6: 4 | T6: 4 | U6: idk | V6: 4 | W6: 1 | X6: 1 | Y6: 1 | Z6: 1 | AA6: idk | AB6: na | AC6: 3 | AD6: 2 | AE6: 4 | AF6: 3 | AG6: idk | AH6: 4 | AI6: 1 | AJ6: 4 | AK6: 3 | AL6: 3 | AM6: 4 | AN6: 1 | AO6: 4 | AP6: 3 | AQ6: 5 | AR6: 5 | AS6: 2 | AT6: 2 | AU6: 5 | AV6: 5 | AW6: 5 | AX6: 5 | AY6: na | AZ6: 1 | BA6: 5 | BB6: 4 | BC6: 5 | BD6: 5 | BE6: 2 | BF6: 5 | BG6: 5 | BH6: idk | BI6: 5 | BJ6: 1 | BK6: 3 | BL6: 3 | BM6: na | BN6: 3 | BO6: 1 | BP6: 4 | BQ6: 3 | BR6: idk | BS6: na | BT6: 1 | BU6: 4 | BV6: 5 | BW6: 3 | BX6: 3 | BY6: 2 | BZ6: 2 | CA6: 5 | CB6: 5 | CC6: 5 | CD6: 4 | CE6: 1 | CF6: 3 | CG6: 4 | CH6: 4 | CI6: 4 | CJ6: 2 | CK6: 5 | CL6: 5 | CM6: 4 | CN6: 5 | CO6: 1 | CP6: 5 | CQ6: 5 | CR6: 4 | CS6: 5 | CT6: 3 | CU6: 3 | CV6: 4 | CW6: 4 | CX6: 3 | CY6: 2 | CZ6: 5 | DA6: 5 | DB6: 3 | DC6: 4 | DD6: 4 | DE6: 4 | DF6: 4 | DG6: 4 | DH6: idk | DI6: 5 | DJ6: 1 | DK6: 4 | DL6: 5 | DM6: 4 | DN6: 4 | DO6: 3
A7: 6 | B7: 5 | C7: 5 | D7: 3 | E7: 3 | F7: idk | G7: 4 | H7: 4 | I7: idk | J7: 4 | K7: 2 | L7: 2 | M7: 4 | N7: 4 | O7: 4 | P7: 4 | Q7: 2 | R7: 2 | S7: 3 | T7: 3 | U7: idk | V7: 4 | W7: 1 | X7: 1 | Y7: 1 | Z7: 1 | AA7: idk | AB7: na | AC7: 1 | AD7: 1 | AE7: 3 | AF7: 3 | AG7: idk | AH7: na | AI7: 1 | AJ7: 2 | AK7: 2 | AL7: idk | AM7: na | AN7: 1 | AO7: 4 | AP7: 4 | AQ7: idk | AR7: 4 | AS7: idk | AT7: idk | AU7: 5 | AV7: 5 | AW7: 2 | AX7: 3 | AY7: 2 | AZ7: 3 | BF7: 3 | BG7: 3 | BH7: idk | BI7: 3 | BJ7: 2 | BK7: 2 | BL7: 2 | BM7: idk | BN7: 3 | BO7: na | BP7: na | BQ7: na | BR7: na | BS7: na | BT7: na | BU7: 3 | BV7: 3 | BW7: idk | BX7: idk | BY7: 4 | BZ7: 2 | CA7: 4 | CB7: 4 | CC7: idk | CD7: 4 | CE7: 2 | CF7: 3 | CG7: 3 | CH7: idk | CI7: 4 | CJ7: 2 | CK7: 4 | CL7: 4 | CM7: 2 | CN7: 4 | CO7: 2 | CP7: 4 | CQ7: 4 | CR7: 4 | CS7: 4 | CT7: 2 | CU7: 4 | CV7: 4 | CW7: idk | CX7: 1 | CY7: 2 | CZ7: 4 | DA7: 4 | DB7: idk | DC7: 3 | DD7: 4 | DE7: 4 | DF7: 4 | DG7: 4 | DH7: idk | DI7: 5 | DJ7: 1 | DK7: 4 | DL7: 5 | DM7: idk | DN7: 4 | DO7: 2
A8: 7 | B8: 5 | C8: 5 | D8: 2 | E8: 2 | F8: 4 | G8: 5 | H8: 5 | I8: 5 | J8: 5 | K8: 2 | L8: 2 | M8: na | N8: na | O8: na | P8: na | Q8: na | R8: na | S8: 4 | T8: 5 | U8: 4 | V8: 4 | W8: 2 | X8: 2 | Y8: na | Z8: na | AA8: na | AB8: na | AC8: na | AD8: na | AE8: na | AF8: na | AG8: na | AH8: na | AI8: na | AJ8: na | AK8: na | AL8: na | AM8: na | AN8: na | AO8: 5 | AP8: 5 | AQ8: idk | AR8: na | AS8: na | AT8: na | AU8: 4 | AV8: 4 | AW8: 4 | AX8: 3 | AY8: idk | AZ8: 2 | BA8: 3 | BB8: 4 | BC8: idk | BD8: 3 | BE8: 2 | BF8: 4 | BG8: 4 | BH8: idk | BI8: 4 | BJ8: 2 | BK8: 4 | BL8: 3 | BM8: idk | BN8: na | BO8: 3 | BP8: na | BQ8: na | BR8: na | BS8: na | BT8: na | BU8: 3 | BV8: 4 | BW8: idk | BX8: 4 | BY8: 3 | BZ8: 1 | CA8: 4 | CB8: 5 | CC8: 4 | CD8: 4 | CE8: 2 | CF8: na | CG8: na | CH8: na | CI8: na | CJ8: na | CK8: 4 | CL8: 4 | CM8: idk | CN8: 4 | CO8: 3 | CP8: 4 | CQ8: 4 | CR8: 3 | CS8: 3 | CT8: 4 | CU8: 4 | CV8: 4 | CW8: 4 | CX8: 4 | CY8: 2 | CZ8: 5 | DA8: 5 | DB8: 4 | DC8: 4 | DD8: 3 | DE8: 4 | DF8: 4 | DG8: 4 | DH8: 4 | DI8: 4 | DJ8: 3 | DK8: 4 | DL8: 5 | DM8: 4 | DN8: 4 | DO8: 3
A9: 8 | B9: 5 | C9: 5 | D9: idk | E9: 1 | F9: 5 | G9: 4 | H9: 4 | I9: idk | J9: na | K9: 4 | L9: 5 | M9: 3 | N9: 3 | O9: idk | P9: 3 | Q9: 4 | R9: 4 | S9: 3 | T9: 3 | U9: idk | V9: 3 | W9: 4 | X9: 4 | Y9: na | Z9: na | AA9: idk | AB9: na | AC9: idk | AD9: idk | AE9: 4 | AF9: 4 | AG9: idk | AH9: 5 | AI9: 1 | AJ9: 4 | AK9: 4 | AL9: idk | AM9: na | AN9: 4 | AO9: 4 | AP9: 4 | AQ9: idk | AR9: na | AS9: 2 | AT9: idk | AU9: 4 | AV9: 4 | AW9: idk | AX9: 2 | AY9: 3 | AZ9: 4 | BA9: 4 | BB9: 4 | BC9: idk | BD9: 3 | BE9: 4 | BF9: 4 | BG9: 4 | BH9: idk | BI9: 4 | BJ9: 3 | BK9: idk | BL9: idk | BM9: idk | BN9: idk | BO9: idk | BP9: na | BQ9: na | BR9: idk | BS9: 2 | BT9: 4 | BU9: 4 | BV9: 4 | BW9: idk | BX9: idk | BY9: 2 | BZ9: 4 | CA9: 4 | CB9: 4 | CC9: idk | CD9: 3 | CE9: 4 | CF9: na | CG9: na | CH9: idk | CI9: na | CJ9: na | CK9: 5 | CL9: 5 | CM9: idk | CN9: 3 | CO9: 4 | CP9: 4 | CQ9: 4 | CR9: idk | CS9: 5 | CT9: 3 | CU9: 4 | CV9: 4 | CW9: idk | CX9: 3 | CY9: 3 | CZ9: idk | DA9: 4 | DB9: idk | DC9: 3 | DD9: idk | DE9: 4 | DF9: 4 | DG9: 4 | DH9: idk | DI9: 3 | DJ9: 3 | DK9: 4 | DL9: 4 | DM9: idk | DN9: 3 | DO9: 5
A10: 9 | B10: 4 | C10: 4 | D10: 4 | E10: 3 | F10: 4 | G10: 3 | H10: 3 | I10: idk | J10: na | K10: 2 | L10: 1 | M10: 3 | N10: 3 | O10: idk | P10: na | Q10: 1 | R10: 1 | S10: 3 | T10: 4 | U10: idk | V10: na | W10: 2 | X10: 2 | Y10: 3 | Z10: 4 | AA10: idk | AB10: idk | AC10: 2 | AD10: 1 | AE10: 2 | AF10: 4 | AG10: idk | AH10: idk | AI10: 2 | AJ10: 3 | AK10: 4 | AL10: idk | AM10: idk | AN10: 2 | AO10: 4 | AP10: 5 | AQ10: 5 | AR10: 4 | AS10: 5 | AT10: 4 | AU10: 3 | AV10: 4 | AW10: 4 | AX10: 4 | AY10: 4 | AZ10: 3 | BA10: 2 | BB10: 3 | BC10: 4 | BD10: 4 | BE10: 2 | BF10: 2 | BG10: 3 | BH10: 4 | BI10: 5 | BJ10: 2 | BK10: 2 | BL10: 3 | BM10: 4 | BN10: 5 | BO10: 2 | BP10: 3 | BQ10: 4 | BR10: 3 | BS10: 4 | BT10: 2 | BU10: 2 | BV10: 4 | BW10: 4 | BX10: 4 | BY10: 4 | BZ10: 1 | CA10: 3 | CB10: 4 | CC10: 4 | CD10: 4 | CE10: 2 | CF10: 2 | CG10: idk | CH10: idk | CI10: idk | CJ10: 2 | CK10: 2 | CL10: 4 | CM10: 4 | CN10: 4 | CO10: 1 | CP10: 3 | CQ10: 5 | CR10: 4 | CS10: 5 | CT10: 4 | CU10: 4 | CV10: 5 | CW10: 4 | CX10: 4 | CY10: 4 | CZ10: 4 | DA10: 4 | DB10: idk | DC10: idk | DD10: 4 | DE10: 4 | DF10: 4 | DG10: 5 | DH10: 4 | DI10: 3 | DJ10: 2 | DK10: 3 | DL10: 5 | DM10: 4 | DN10: 4 | DO10: 3
A11: 10 | B11: 5 | C11: 5 | D11: 3 | E11: idk | F11: 4 | H11: 5 | I11: idk | J11: 4 | K11: 2 | L11: 3 | M11: 2 | N11: 5 | O11: idk | P11: idk | Q11: 2 | R11: 2 | S11: 2 | T11: 5 | U11: idk | V11: idk | W11: 2 | X11: 2 | Y11: 2 | Z11: 4 | AA11: idk | AB11: na | AC11: idk | AD11: idk | AE11: 2 | AF11: 3 | AG11: idk | AH11: na | AI11: 2 | AJ11: 2 | AK11: 5 | AL11: idk | AM11: 3 | AN11: 2 | AO11: 2 | AP11: 5 | AQ11: idk | AR11: 5 | AS11: 3 | AT11: 3 | AU11: 2 | AV11: 5 | AW11: 4 | AX11: 2 | AY11: 2 | AZ11: 3 | BA11: 2 | BB11: 4 | BC11: idk | BD11: 4 | BE11: 2 | BF11: 2 | BG11: 3 | BH11: idk | BI11: idk | BJ11: 2 | BK11: 2 | BL11: 3 | BM11: idk | BN11: 2 | BO11: 2 | BP11: 2 | BQ11: 3 | BR11: idk | BS11: 2 | BT11: 2 | BU11: 2 | BV11: 5 | BW11: idk | BX11: idk | BY11: 4 | BZ11: 2 | CA11: 2 | CB11: 5 | CC11: idk | CD11: 5 | CE11: 1 | CF11: 2 | CG11: 5 | CH11: idk | CI11: 5 | CJ11: 2 | CK11: 2 | CL11: 5 | CM11: idk | CN11: 5 | CO11: 4 | CP11: 2 | CQ11: 4 | CR11: idk | CS11: 4 | CT11: 2 | CU11: 2 | CV11: 5 | CW11: idk | CX11: 2 | CY11: 3 | CZ11: 2 | DA11: 5 | DB11: idk | DC11: 2 | DD11: 4 | DE11: 4 | DF11: 2 | DG11: 5 | DH11: idk | DI11: 2 | DJ11: 2 | DK11: 4 | DL11: 5 | DM11: idk | DN11: 2 | DO11: 5
A12: 11 | B12: 5 | C12: 5 | D12: idk | E12: 4 | F12: 2 | G12: 5 | H12: 5 | I12: idk | J12: 5 | K12: 1 | L12: 1 | M12: 2 | N12: 4 | O12: idk | P12: 3 | Q12: 2 | R12: 2 | S12: 5 | T12: 5 | U12: idk | V12: 5 | W12: 2 | X12: 2 | Y12: na | Z12: na | AA12: idk | AB12: na | AC12: na | AD12: na | AE12: 4 | AF12: 4 | AG12: idk | AH12: 4 | AI12: 2 | AJ12: 4 | AK12: 4 | AL12: idk | AM12: 4 | AN12: 2 | AO12: 5 | AP12: 5 | AQ12: idk | AR12: 5 | AS12: 2 | AT12: 2 | AU12: 5 | AV12: 5 | AW12: 5 | AX12: 3 | AY12: 5 | AZ12: 2 | BA12: 5 | BB12: 5 | BC12: idk | BD12: 5 | BE12: 2 | BF12: 5 | BG12: 5 | BH12: idk | BI12: 5 | BJ12: 2 | BK12: 5 | BL12: 5 | BM12: idk | BN12: 5 | BO12: 2 | BP12: na | BQ12: na | BR12: idk | BS12: na | BT12: 2 | BU12: 5 | BV12: 5 | BW12: idk | BX12: idk | BY12: 5 | BZ12: 2 | CA12: 5 | CB12: 5 | CC12: idk | CD12: 5 | CE12: 2 | CF12: na | CG12: na | CH12: idk | CI12: na | CJ12: 2 | CK12: 4 | CL12: 4 | CM12: idk | CN12: 4 | CO12: 2 | CP12: 5 | CQ12: 5 | CR12: idk | CS12: 5 | CT12: 2 | CU12: 4 | CV12: 4 | CW12: idk | CX12: 4 | CY12: 2 | CZ12: 5 | DA12: 5 | DB12: idk | DC12: 5 | DD12: 2 | DE12: 2 | DF12: 5 | DG12: 5 | DH12: idk | DI12: 5 | DJ12: 2 | DK12: 5 | DL12: 5 | DM12: idk | DN12: 5 | DO12: 2
A13: 12 | B13: 4 | C13: 5 | D13: 2 | E13: 2 | F13: 4 | G13: 3 | H13: 4 | I13: 4 | J13: 4 | K13: 2 | L13: 1 | M13: 1 | N13: 1 | O13: idk | P13: na | Q13: 1 | R13: 1 | S13: 3 | T13: 4 | U13: idk | V13: 4 | W13: 1 | X13: 1 | Y13: 1 | Z13: 3 | AA13: idk | AB13: na | AC13: na | AD13: na | AE13: 3 | AF13: 5 | AG13: idk | AH13: 3 | AI13: 3 | AJ13: 3 | AK13: 3 | AL13: idk | AM13: 3 | AN13: 3 | AO13: 4 | AP13: 4 | AQ13: 2 | AR13: 3 | AS13: 3 | AT13: 3 | AU13: 4 | AV13: 4 | AW13: 3 | AX13: 4 | AY13: 4 | AZ13: 2 | BA13: 2 | BB13: 3 | BC13: idk | BD13: 3 | BE13: 1 | BF13: 2 | BG13: 3 | BH13: 2 | BI13: 4 | BJ13: 1 | BK13: 2 | BL13: 3 | BM13: idk | BN13: 4 | BO13: 1 | BP13: 1 | BQ13: 3 | BR13: idk | BS13: 3 | BT13: 3 | BU13: 3 | BV13: 3 | BW13: idk | BX13: idk | BY13: 3 | BZ13: 3 | CA13: 4 | CB13: 4 | CC13: 4 | CD13: 4 | CE13: 3 | CF13: 1 | CG13: 1 | CH13: idk | CI13: 3 | CJ13: 1 | CK13: 3 | CL13: 4 | CM13: 2 | CN13: 3 | CO13: 2 | CP13: 3 | CQ13: 3 | CR13: 3 | CS13: 3 | CT13: 2 | CU13: 4 | CV13: 5 | CW13: idk | CX13: 2 | CY13: 3 | CZ13: 5 | DA13: 5 | DB13: idk | DC13: 3 | DD13: 4 | DE13: 4 | DF13: 3 | DG13: 3 | DH13: idk | DI13: 3 | DJ13: 3 | DK13: 3 | DL13: 5 | DM13: 3 | DN13: 3 | DO13: 5
A14: 13 | B14: 4 | C14: 4 | D14: idk | E14: 3 | F14: 3 | G14: 4 | H14: 5 | I14: idk | J14: 4 | K14: 3 | L14: 2 | M14: na | N14: na | O14: na | P14: na | Q14: na | R14: na | S14: 4 | T14: 4 | U14: idk | V14: 1 | W14: 3 | X14: 3 | Y14: 5 | Z14: 5 | AA14: 5 | AB14: 5 | AC14: 5 | AD14: 5 | AE14: 5 | AF14: 5 | AG14: idk | AH14: 5 | AI14: 5 | AJ14: 5 | AK14: 5 | AL14: idk | AM14: 5 | AN14: 5 | AO14: 5 | AP14: 4 | AQ14: idk | AR14: idk | AS14: 4 | AT14: 3 | AU14: 3 | AV14: 4 | AW14: idk | AX14: na | AY14: 4 | AZ14: 4 | BA14: 5 | BB14: 5 | BC14: idk | BD14: 3 | BE14: 3 | BF14: 4 | BG14: 4 | BH14: idk | BI14: 4 | BJ14: 2 | BK14: 3 | BL14: 4 | BM14: idk | BN14: 4 | BO14: 2 | BP14: 4 | BQ14: 5 | BR14: idk | BS14: 1 | BT14: 4 | BU14: 4 | BV14: 4 | BW14: idk | BX14: idk | BY14: 1 | BZ14: 3 | CA14: 4 | CB14: 4 | CC14: idk | CD14: 4 | CE14: 2 | CF14: 3 | CG14: 3 | CH14: idk | CI14: 2 | CJ14: 3 | CK14: 5 | CL14: 5 | CM14: idk | CN14: 4 | CO14: 2 | CP14: 5 | CQ14: 5 | CR14: idk | CS14: 5 | CT14: 3 | CU14: 5 | CV14: 5 | CW14: idk | CX14: 2 | CY14: 4 | CZ14: 5 | DA14: 5 | DB14: idk | DC14: 3 | DD14: 4 | DE14: 5 | DF14: 4 | DG14: 4 | DH14: idk | DI14: 4 | DJ14: 2 | DK14: 3 | DL14: 4 | DM14: idk | DN14: 5 | DO14: 4
A15: 14 | B15: 5 | C15: 5 | D15: 2 | E15: 2 | F15: 5 | G15: 4 | H15: 5 | I15: 5 | J15: 5 | K15: 2 | L15: 3 | M15: na | N15: na | O15: na | P15: na | Q15: na | R15: na | S15: 4 | T15: 4 | U15: 4 | V15: 4 | W15: 3 | X15: 3 | Y15: 2 | Z15: 2 | AA15: 3 | AB15: 4 | AC15: 3 | AD15: 3 | AE15: 3 | AF15: 2 | AG15: 3 | AH15: 3 | AI15: 3 | AJ15: 2 | AK15: 3 | AL15: 3 | AM15: 3 | AN15: 3 | AO15: 4 | AP15: 4 | AQ15: 3 | AR15: 3 | AS15: 3 | AT15: 4 | AU15: 4 | AV15: 5 | AW15: 2 | AX15: 2 | AY15: 2 | AZ15: 4 | BA15: 3 | BB15: 4 | BC15: 4 | BD15: 4 | BE15: 3 | BF15: 4 | BG15: 4 | BH15: 3 | BI15: 4 | BJ15: 3 | BK15: 5 | BL15: 5 | BM15: 3 | BN15: 5 | BO15: 3 | BP15: 4 | BQ15: 4 | BR15: 3 | BS15: 4 | BT15: 3 | BU15: 4 | BV15: 4 | BW15: 3 | BX15: 3 | BY15: 4 | BZ15: 3 | CA15: 4 | CB15: 4 | CC15: 4 | CD15: 4 | CE15: 3 | CF15: 2 | CG15: 2 | CH15: 3 | CI15: 3 | CJ15: 2 | CK15: 2 | CL15: 2 | CM15: 3 | CN15: 3 | CO15: 3 | CP15: 5 | CQ15: 5 | CR15: 3 | CS15: 3 | CT15: 4 | CU15: 3 | CV15: 4 | CW15: 4 | CX15: 4 | CY15: 3 | CZ15: 4 | DA15: 4 | DB15: 3 | DC15: 4 | DD15: 4 | DE15: 4 | DF15: 2 | DG15: 2 | DH15: 3 | DI15: 3 | DJ15: 3 | DK15: 2 | DL15: 4 | DM15: 3 | DN15: 2 | DO15: 5
A16: 15 | B16: 2 | C16: 5 | D16: idk | E16: 4 | F16: 1 | G16: 2 | H16: 5 | I16: 4 | J16: 5 | K16: 1 | L16: 1 | M16: 2 | N16: 5 | O16: 4 | P16: 4 | Q16: 1 | R16: 1 | S16: 2 | T16: 5 | U16: 4 | V16: 2 | W16: 1 | X16: 1 | Y16: 2 | Z16: 5 | AA16: 4 | AB16: 5 | AC16: 1 | AD16: 1 | AE16: 3 | AF16: 5 | AG16: idk | AH16: 4 | AI16: 1 | AJ16: 4 | AK16: 5 | AL16: idk | AM16: 5 | AN16: 2 | AO16: 4 | AP16: 5 | AQ16: idk | AR16: 5 | AS16: 3 | AT16: 4 | AU16: 2 | AV16: 5 | AW16: 2 | AX16: 2 | AY16: 2 | AZ16: 3 | BA16: 4 | BB16: 5 | BC16: idk | BD16: 2 | BE16: 2 | BF16: 4 | BG16: 5 | BH16: idk | BI16: 3 | BJ16: 3 | BK16: 4 | BL16: 5 | BM16: idk | BN16: 5 | BO16: 3 | BP16: 4 | BQ16: 4 | BR16: idk | BS16: 3 | BT16: 3 | BU16: 4 | BV16: 5 | BW16: idk | BX16: idk | BY16: 3 | BZ16: 3 | CA16: 4 | CB16: 5 | CD16: 4 | CE16: 2 | CF16: 4 | CG16: 5 | CH16: idk | CI16: 4 | CJ16: 2 | CK16: 4 | CL16: 5 | CM16: idk | CN16: 5 | CO16: 2 | CP16: 3 | CQ16: 4 | CR16: idk | CS16: 5 | CT16: 2 | CU16: 3 | CV16: 4 | CW16: idk | CX16: 4 | CY16: 2 | CZ16: 4 | DA16: 5 | DB16: idk | DC16: 3 | DD16: 3 | DE16: 3 | DF16: 2 | DG16: 4 | DH16: idk | DI16: 2 | DJ16: 1 | DK16: 4 | DL16: 5 | DM16: idk | DN16: 4 | DO16: 3
A17: 16 | B17: 3 | C17: 4 | D17: 4 | E17: 3 | F17: 4 | G17: 5 | H17: 5 | I17: 5 | J17: 5 | K17: 1 | L17: 2 | M17: 1 | N17: 2 | O17: idk | P17: 4 | Q17: 1 | R17: 1 | S17: 2 | T17: 3 | U17: idk | V17: 3 | W17: 1 | X17: 1 | Y17: 1 | Z17: 2 | AA17: idk | AB17: na | AC17: 1 | AD17: 1 | AE17: 1 | AF17: 2 | AG17: idk | AH17: na | AI17: 1 | AJ17: 2 | AK17: 3 | AL17: idk | AM17: na | AN17: 2 | AO17: 3 | AP17: 4 | AQ17: 5 | AR17: 5 | AS17: 1 | AT17: 2 | AU17: 4 | AV17: 5 | AW17: 2 | AX17: 4 | AY17: 2 | AZ17: 3 | BA17: 4 | BB17: 5 | BC17: 5 | BD17: 5 | BE17: 3 | BF17: 3 | BG17: 4 | BH17: idk | BI17: 5 | BJ17: 2 | BK17: 3 | BL17: 3 | BM17: idk | BN17: 5 | BO17: 2 | BP17: na | BQ17: na | BR17: na | BS17: na | BT17: na | BU17: 3 | BV17: 4 | BW17: idk | BX17: 5 | BY17: 3 | BZ17: 1 | CA17: 2 | CB17: 4 | CC17: 2 | CD17: 3 | CE17: 2 | CF17: 4 | CG17: 4 | CH17: idk | CI17: 5 | CJ17: 4 | CK17: 2 | CL17: 4 | CM17: 2 | CN17: 3 | CO17: 4 | CP17: 3 | CQ17: 4 | CR17: idk | CS17: 5 | CT17: 2 | CU17: 3 | CV17: 4 | CW17: idk | CX17: 2 | CY17: 2 | CZ17: 4 | DA17: 5 | DB17: 1 | DC17: 1 | DD17: 4 | DE17: 5 | DF17: 3 | DG17: 4 | DH17: idk | DI17: 4 | DJ17: 1 | DK17: 5 | DL17: 5 | DM17: 5 | DN17: 4 | DO17: 4
A18: 17 | B18: 4 | C18: 5 | D18: 2 | E18: 3 | F18: 4 | G18: 4 | H18: 4 | I18: 3 | J18: 4 | K18: 3 | L18: 2 | M18: 1 | N18: 2 | O18: 1 | P18: 1 | Q18: 1 | R18: 1 | S18: 2 | T18: 4 | U18: 3 | V18: 3 | W18: 2 | X18: 2 | Y18: na | Z18: na | AA18: na | AB18: na | AC18: na | AD18: na | AE18: na | AF18: na | AG18: na | AH18: na | AI18: na | AJ18: na | AK18: na | AL18: na | AM18: na | AN18: na | AO18: 2 | AP18: 4 | AQ18: 3 | AR18: 3 | AS18: 1 | AT18: 1 | AU18: 4 | AV18: 5 | AW18: 4 | AX18: 4 | AY18: 3 | AZ18: 3 | BA18: 3 | BB18: 4 | BC18: 4 | BD18: 4 | BE18: 3 | BF18: 4 | BG18: 4 | BH18: idk | BI18: 5 | BJ18: 3 | BK18: 3 | BL18: 5 | BM18: idk | BN18: 5 | BO18: 2 | BP18: 2 | BQ18: 5 | BR18: idk | BS18: 3 | BT18: 3 | BU18: 4 | BV18: 5 | BW18: idk | BX18: idk | BY18: 3 | BZ18: 1 | CA18: 4 | CB18: 5 | CC18: idk | CD18: 4 | CE18: 2 | CF18: na | CG18: na | CH18: na | CI18: na | CJ18: na | CK18: 3 | CL18: 5 | CM18: idk | CN18: 3 | CO18: 3 | CP18: 3 | CQ18: 4 | CR18: 4 | CS18: 2 | CT18: 4 | CU18: 4 | CV18: 5 | CW18: idk | CX18: 2 | CY18: 4 | CZ18: 3 | DA18: 5 | DB18: idk | DC18: 2 | DD18: 4 | DE18: 5 | DF18: 4 | DG18: 5 | DH18: idk | DI18: 4 | DJ18: 2 | DK18: 3 | DL18: 5 | DM18: 2 | DN18: 2 | DO18: 5
A19: 18 | B19: 4 | C19: 5 | D19: 4 | E19: 4 | F19: 3 | G19: 3 | H19: 4 | I19: 4 | J19: 4 | K19: 2 | L19: 2 | M19: 2 | N19: 3 | O19: 4 | P19: 4 | Q19: 2 | R19: 2 | S19: 3 | T19: 3 | U19: 4 | V19: 4 | W19: 2 | X19: 2 | Y19: 1 | Z19: 2 | AA19: 4 | AB19: 4 | AC19: 3 | AD19: 3 | AE19: 2 | AF19: 3 | AG19: 3 | AH19: 3 | AI19: 3 | AJ19: 4 | AK19: 4 | AL19: 4 | AM19: 4 | AN19: 2 | AO19: 3 | AP19: 5 | AQ19: 2 | AR19: 3 | AS19: 4 | AT19: 3 | AU19: 4 | AV19: 5 | AW19: 4 | AX19: 4 | AY19: 4 | AZ19: 3 | BA19: 4 | BB19: 4 | BC19: 3 | BD19: 3 | BE19: 3 | BF19: 2 | BG19: 3 | BH19: 1 | BI19: 5 | BJ19: 2 | BK19: 3 | BL19: 3 | BM19: 1 | BN19: 4 | BO19: 2 | BP19: na | BQ19: na | BR19: na | BS19: na | BT19: na | BU19: 5 | BV19: 5 | BW19: 5 | BX19: 3 | BY19: 4 | BZ19: 2 | CA19: 3 | CB19: 4 | CC19: 4 | CD19: 4 | CE19: 3 | CF19: na | CG19: na | CH19: na | CI19: na | CJ19: na | CK19: 3 | CL19: 4 | CM19: 3 | CN19: 4 | CO19: 3 | CP19: 4 | CQ19: 4 | CR19: 3 | CS19: 4 | CT19: 2 | CU19: 4 | CV19: 5 | CW19: idk | CX19: 4 | CY19: 3 | CZ19: 4 | DA19: 3 | DB19: 2 | DC19: 2 | DD19: 4 | DE19: 4 | DF19: 2 | DG19: 3 | DH19: 2 | DI19: 3 | DJ19: 3 | DK19: 4 | DL19: 4 | DM19: 4 | DN19: 4 | DO19: 2
A20: 19 | B20: 5 | C20: 5 | D20: 1 | E20: 1 | F20: 5 | G20: 4 | H20: 4 | I20: idk | J20: 5 | K20: 1 | L20: 2 | M20: 3 | N20: 3 | O20: idk | P20: 3 | Q20: 1 | R20: 1 | S20: 3 | T20: 4 | U20: idk | V20: 3 | W20: 3 | X20: 3 | Y20: 3 | Z20: 3 | AA20: idk | AB20: 3 | AC20: 3 | AD20: 3 | AE20: 3 | AF20: 3 | AG20: idk | AH20: 3 | AI20: 1 | AJ20: 3 | AK20: 3 | AL20: 3 | AM20: 3 | AN20: 3 | AO20: 3 | AP20: 3 | AQ20: 3 | AR20: 3 | AS20: 3 | AT20: 3 | AU20: 5 | AV20: 5 | AW20: 2 | AX20: 2 | AY20: na | AZ20: 5 | BA20: 5 | BB20: 5 | BC20: 2 | BD20: 2 | BE20: 4 | BF20: 4 | BG20: 3 | BH20: idk | BI20: 3 | BJ20: 4 | BK20: 3 | BL20: 3 | BM20: idk | BN20: 4 | BO20: 3 | BP20: 1 | BQ20: 1 | BR20: 3 | BS20: 3 | BT20: 1 | BU20: 4 | BV20: 5 | BW20: 4 | BX20: idk | BY20: 5 | BZ20: 5 | CA20: 5 | CB20: 5 | CC20: 1 | CD20: 2 | CE20: 5 | CF20: 3 | CG20: 3 | CH20: idk | CI20: 3 | CJ20: 3 | CK20: 1 | CL20: 1 | CM20: idk | CN20: 3 | CO20: 5 | CP20: 3 | CQ20: 3 | CR20: idk | CS20: 2 | CT20: 3 | CU20: 4 | CV20: 5 | CW20: 1 | CX20: 1 | CY20: 5 | CZ20: 5 | DA20: 5 | DB20: 1 | DC20: 1 | DD20: 5 | DE20: 5 | DF20: 3 | DG20: 4 | DH20: 1 | DI20: 1 | DJ20: 5 | DK20: 2 | DL20: 4 | DM20: 1 | DN20: 2 | DO20: 5
A21: 20 | B21: 4 | C21: 5 | D21: 3 | E21: 3 | F21: idk | G21: na | H21: 5 | I21: 3 | J21: na | K21: idk | L21: idk | M21: 1 | N21: 4 | O21: 4 | P21: 4 | Q21: idk | R21: idk | S21: 3 | T21: 3 | U21: 3 | V21: 3 | W21: idk | X21: idk | Y21: 2 | Z21: 3 | AA21: 3 | AB21: 2 | AC21: idk | AD21: idk | AE21: 3 | AF21: 5 | AG21: 3 | AH21: 4 | AI21: idk | AJ21: 3 | AK21: 4 | AL21: 3 | AM21: 4 | AN21: idk | AO21: 3 | AP21: 4 | AQ21: 3 | AR21: 3 | AS21: idk | AT21: idk | AU21: 3 | AV21: 4 | AW21: 4 | AX21: na | AY21: 4 | AZ21: 2 | BA21: 3 | BB21: 4 | BC21: 4 | BD21: 5 | BE21: 3 | BF21: 4 | BG21: 4 | BH21: 2 | BI21: 4 | BJ21: 3 | BK21: 5 | BL21: 4 | BM21: 2 | BN21: 4 | BO21: 3 | BP21: 4 | BQ21: 4 | BR21: 2 | BS21: 2 | BT21: 3 | BU21: 2 | BV21: 3 | BW21: 3 | BX21: 3 | BY21: 4 | BZ21: 1 | CA21: 3 | CB21: 3 | CC21: 5 | CD21: 5 | CE21: 1 | CF21: 2 | CG21: 2 | CH21: 2 | CI21: 3 | CJ21: 1 | CK21: 1 | CL21: 1 | CM21: 1 | CN21: 1 | CO21: 1 | CP21: 4 | CQ21: 4 | CR21: 3 | CS21: 4 | CT21: 2 | CU21: 2 | CV21: 3 | CW21: 5 | CX21: 4 | CY21: 2 | CZ21: 4 | DA21: 5 | DB21: 4 | DC21: 4 | DD21: 5 | DE21: 3 | DF21: 1 | DG21: 1 | DH21: 5 | DI21: 4 | DJ21: 1 | DK21: 3 | DL21: 4 | DM21: 3 | DN21: 3 | DO21: 3
A22: 21 | B22: 4 | C22: 4 | D22: 3 | E22: 2 | F22: 4 | G22: 3 | H22: 4 | I22: 5 | J22: 5 | K22: 4 | L22: 3 | M22: 2 | N22: 4 | O22: 4 | P22: 4 | Q22: 2 | R22: 2 | S22: na | T22: na | U22: na | V22: na | W22: na | X22: na | Y22: 1 | Z22: 2 | AA22: idk | AB22: na | AC22: 2 | AD22: 2 | AE22: 1 | AF22: 3 | AG22: idk | AH22: 5 | AI22: idk | AJ22: 1 | AK22: 3 | AL22: idk | AM22: 5 | AN22: 2 | AO22: 3 | AP22: 4 | AQ22: 4 | AR22: 4 | AS22: 3 | AT22: 2 | AU22: 4 | AV22: 5 | AW22: 3 | AX22: 2 | AY22: 3 | AZ22: 4 | BA22: 3 | BB22: 4 | BC22: 4 | BD22: 4 | BE22: 2 | BF22: 2 | BG22: 3 | BH22: idk | BI22: 4 | BJ22: 2 | BK22: 3 | BL22: 4 | BM22: idk | BN22: 5 | BO22: 1 | BP22: 2 | BQ22: 4 | BR22: idk | BS22: na | BT22: 4 | BU22: 2 | BV22: 4 | BW22: idk | BX22: idk | BY22: 4 | BZ22: 1 | CA22: 3 | CB22: 5 | CC22: 3 | CD22: 3 | CE22: 3 | CF22: 4 | CG22: 4 | CH22: idk | CI22: 4 | CJ22: 2 | CK22: 4 | CL22: 4 | CM22: 4 | CN22: 4 | CO22: 2 | CP22: 4 | CQ22: 5 | CR22: 5 | CS22: 4 | CT22: 2 | CU22: 4 | CV22: 5 | CW22: 2 | CX22: 2 | CY22: 3 | CZ22: 4 | DA22: 5 | DB22: idk | DC22: na | DD22: 3 | DE22: 3 | DF22: 2 | DG22: 4 | DH22: 3 | DI22: 3 | DJ22: 1 | DK22: 2 | DL22: 4 | DM22: 3 | DN22: 3 | DO22: 4
A23: 22 | B23: 5 | C23: 5 | D23: idk | E23: 2 | F23: 3 | G23: 3 | H23: 5 | I23: 5 | J23: 5 | K23: 1 | L23: 1 | M23: 1 | N23: 1 | O23: idk | P23: idk | Q23: 1 | R23: 1 | S23: 1 | T23: 1 | U23: idk | V23: idk | W23: 1 | X23: 1 | Y23: 1 | Z23: 4 | AA23: idk | AB23: idk | AC23: 1 | AD23: 1 | AE23: 1 | AF23: 4 | AG23: idk | AH23: 4 | AI23: 1 | AJ23: 1 | AK23: 4 | AL23: idk | AM23: 4 | AN23: 1 | AO23: 4 | AP23: 4 | AQ23: 5 | AR23: 5 | AS23: 1 | AT23: 1 | AU23: 4 | AV23: 5 | AW23: idk | AX23: 4 | AY23: 4 | AZ23: 2 | BA23: 2 | BB23: 5 | BC23: idk | BD23: 5 | BE23: 1 | BF23: 4 | BG23: 4 | BH23: idk | BI23: 5 | BJ23: 1 | BK23: 4 | BL23: 4 | BM23: idk | BN23: 4 | BO23: 1 | BP23: 5 | BQ23: 5 | BR23: idk | BS23: 5 | BT23: 2 | BU23: 2 | BV23: 4 | BW23: idk | BX23: idk | BY23: 3 | BZ23: 1 | CA23: 2 | CB23: 4 | CC23: idk | CD23: 4 | CE23: 1 | CF23: 2 | CG23: 4 | CH23: idk | CI23: 4 | CJ23: 1 | CK23: 2 | CL23: 3 | CM23: idk | CN23: 3 | CO23: 1 | CP23: 3 | CQ23: na | CR23: idk | CS23: 2 | CT23: 1 | CU23: 2 | CV23: 4 | CW23: idk | CX23: 4 | CY23: 1 | CZ23: 3 | DA23: 4 | DB23: idk | DC23: idk | DD23: 2 | DE23: 2 | DF23: 3 | DG23: 4 | DH23: idk | DI23: idk | DJ23: na | DK23: 5 | DL23: 5 | DM23: idk | DN23: 2 | DO23: 3
A24: 23 | B24: 5 | C24: 5 | D24: 4 | E24: 4 | F24: 4 | G24: 3 | H24: 5 | I24: 4 | J24: 3 | K24: 3 | L24: 3 | M24: 3 | N24: 5 | O24: idk | P24: idk | Q24: 3 | R24: 3 | S24: 3 | T24: 5 | U24: 4 | V24: 5 | W24: 3 | X24: 3 | Y24: 1 | Z24: 4 | AA24: idk | AB24: na | AC24: 2 | AD24: 2 | AE24: 2 | AF24: 3 | AG24: idk | AH24: na | AI24: 3 | AJ24: 3 | AK24: 4 | AL24: idk | AM24: 4 | AN24: 3 | AO24: 3 | AP24: 5 | AQ24: 4 | AR24: 4 | AS24: 3 | AT24: 3 | AU24: 5 | AV24: 5 | AW24: 4 | AX24: 4 | AY24: na | AZ24: 3 | BA24: 4 | BB24: 5 | BC24: 5 | BD24: 5 | BE24: 3 | BF24: 4 | BG24: 5 | BH24: 5 | BI24: 5 | BJ24: 3 | BK24: 3 | BL24: 5 | BM24: 3 | BN24: 4 | BO24: 3 | BP24: na | BQ24: na | BR24: idk | BS24: na | BT24: na | BU24: 3 | BV24: 4 | BW24: idk | BX24: idk | BY24: 3 | BZ24: 3 | CA24: 4 | CB24: 5 | CC24: 4 | CD24: 4 | CE24: 3 | CF24: na | CG24: na | CH24: na | CI24: na | CJ24: na | CK24: 3 | CL24: 4 | CM24: idk | CN24: 3 | CO24: 3 | CP24: 4 | CQ24: 5 | CR24: 4 | CS24: 4 | CT24: 3 | CU24: 3 | CV24: 5 | CW24: idk | CX24: 4 | CY24: 3 | CZ24: 3 | DA24: 5 | DB24: idk | DC24: 3 | DD24: 3 | DE24: 3 | DF24: 4 | DG24: 5 | DH24: idk | DI24: 4 | DJ24: 3 | DK24: 4 | DL24: 5 | DM24: 4 | DN24: 4 | DO24: 3
A25: 24 | B25: 1 | C25: 5 | D25: 3 | E25: 4 | F25: na | G25: 5 | H25: 5 | I25: 5 | J25: 5 | K25: 2 | L25: 4 | M25: 2 | N25: 4 | O25: 4 | P25: 4 | Q25: 2 | R25: 2 | S25: 4 | T25: 4 | U25: 2 | V25: 2 | W25: 3 | X25: 4 | Y25: 2 | Z25: 2 | AA25: 3 | AB25: 3 | AC25: 2 | AD25: 2 | AE25: 3 | AF25: 4 | AG25: 3 | AH25: 4 | AI25: 2 | AJ25: 4 | AK25: 4 | AL25: 4 | AM25: 4 | AN25: 2 | AO25: 5 | AP25: 5 | AQ25: 5 | AR25: 5 | AS25: 1 | AT25: 4 | AU25: 5 | AV25: 5 | AW25: 3 | AX25: 2 | AY25: 2 | AZ25: 5 | BA25: 5 | BB25: 5 | BC25: 4 | BD25: 4 | BE25: 2 | BF25: 5 | BG25: 5 | BH25: 5 | BI25: 5 | BJ25: 5 | BK25: 5 | BL25: 5 | BM25: 5 | BN25: 5 | BO25: 5 | BP25: 5 | BQ25: 5 | BR25: 4 | BS25: 3 | BT25: 3 | BU25: 4 | BV25: 5 | BW25: 4 | BX25: 4 | BY25: 2 | BZ25: 3 | CA25: 5 | CB25: 5 | CC25: 5 | CD25: 5 | CE25: 5 | CF25: 5 | CG25: 5 | CH25: 3 | CI25: 4 | CJ25: 4 | CK25: 4 | CL25: 3 | CM25: 5 | CN25: 5 | CO25: 2 | CP25: 5 | CQ25: 5 | CR25: 5 | CS25: 5 | CT25: 5 | CU25: 5 | CV25: 5 | CW25: 1 | CX25: 1 | CY25: 5 | CZ25: 5 | DA25: 5 | DB25: 3 | DC25: 2 | DD25: 4 | DE25: 5 | DF25: 2 | DG25: 2 | DH25: 1 | DI25: 2 | DJ25: 1 | DK25: 5 | DL25: 5 | DM25: 3 | DN25: 3 | DO25: 5
A26: 25 | B26: 5 | C26: 5 | D26: 2 | E26: 2 | F26: 4 | G26: 2 | H26: 5 | I26: 5 | J26: 5 | K26: 1 | L26: 1 | M26: 1 | N26: 1 | O26: idk | P26: na | Q26: 1 | R26: 1 | S26: 1 | T26: 4 | U26: 4 | V26: 4 | W26: 1 | X26: 1 | Y26: 2 | Z26: 2 | AA26: idk | AB26: na | AC26: 1 | AD26: 1 | AE26: 2 | AF26: 4 | AG26: 4 | AH26: 4 | AI26: 1 | AJ26: 2 | AK26: 4 | AL26: idk | AM26: 3 | AN26: 1 | AO26: 4 | AP26: 5 | AQ26: 5 | AR26: 5 | AS26: 3 | AT26: 3 | AU26: 2 | AV26: 5 | AW26: 4 | AX26: 2 | AY26: 2 | AZ26: 2 | BA26: 2 | BB26: 4 | BC26: 4 | BD26: 4 | BE26: 1 | BF26: 2 | BG26: 4 | BH26: idk | BI26: 5 | BJ26: 2 | BK26: 2 | BL26: 4 | BM26: 2 | BN26: 5 | BO26: 2 | BP26: 2 | BQ26: 5 | BR26: 2 | BS26: 2 | BT26: 2 | BU26: 2 | BV26: 2 | BW26: idk | BX26: idk | BY26: 4 | BZ26: 2 | CA26: 2 | CB26: 5 | CC26: 5 | CD26: 4 | CE26: 2 | CF26: 1 | CG26: 4 | CH26: 3 | CI26: 4 | CJ26: 2 | CK26: 1 | CL26: 1 | CM26: 2 | CN26: na | CO26: 1 | CP26: 2 | CQ26: 4 | CR26: 4 | CS26: 4 | CT26: 2 | CU26: 2 | CV26: 4 | CW26: 2 | CX26: 2 | CY26: 2 | CZ26: 2 | DA26: 4 | DB26: 2 | DC26: 2 | DD26: 2 | DE26: 2 | DF26: 2 | DG26: 2 | DH26: idk | DI26: 4 | DJ26: 2 | DK26: 5 | DL26: 5 | DM26: 2 | DN26: 2 | DO26: 5
A27: 26 | B27: 5 | C27: 5 | D27: 2 | E27: 2 | F27: 4 | G27: na | H27: na | I27: na | J27: na | K27: na | L27: na | M27: na | N27: na | O27: na | P27: na | Q27: na | R27: na | S27: 2 | T27: 4 | U27: 3 | V27: 4 | W27: 3 | X27: 3 | Y27: na | Z27: na | AA27: na | AB27: na | AC27: na | AD27: na | AE27: 2 | AF27: 3 | AG27: na | AH27: na | AI27: na | AJ27: idk | AK27: idk | AL27: idk | AM27: idk | AN27: idk | AO27: 3 | AP27: 5 | AQ27: 2 | AR27: 1 | AS27: 3 | AT27: 4 | AU27: 4 | AV27: 5 | AW27: 1 | AX27: 1 | AY27: idk | AZ27: 4 | BA27: 3 | BB27: 5 | BC27: 3 | BD27: 3 | BE27: 3 | BF27: na | BG27: 4 | BH27: idk | BI27: 5 | BJ27: idk | BK27: 3 | BL27: 5 | BM27: idk | BN27: 5 | BO27: 2 | BP27: 4 | BQ27: 5 | BR27: 1 | BS27: 1 | BT27: 4 | BU27: 3 | BV27: 4 | BW27: idk | BX27: 4 | BY27: 3 | BZ27: 2 | CA27: 3 | CB27: 4 | CC27: 4 | CD27: 4 | CE27: 3 | CF27: 2 | CG27: 4 | CH27: 4 | CI27: 4 | CJ27: 2 | CK27: 2 | CL27: 2 | CM27: 2 | CN27: 4 | CO27: 2 | CP27: 4 | CQ27: 5 | CR27: 5 | CS27: 4 | CT27: 3 | CU27: 3 | CV27: 5 | CW27: 2 | CX27: 2 | CY27: 3 | CZ27: 3 | DA27: 4 | DB27: 2 | DC27: 3 | DD27: 3 | DE27: 3 | DF27: 3 | DG27: 5 | DH27: 4 | DI27: 3 | DJ27: 3 | DK27: 5 | DL27: 5 | DM27: 2 | DN27: 3 | DO27: 5
A28: 27 | B28: 5 | C28: 5 | D28: idk | E28: 3 | F28: 4 | G28: na | H28: na | I28: na | J28: na | K28: na | L28: na | M28: na | N28: na | O28: na | P28: na | Q28: na | R28: na | S28: na | T28: na | U28: na | V28: na | W28: na | X28: na | Y28: na | Z28: na | AA28: na | AB28: na | AC28: na | AD28: na | AE28: 2 | AF28: 4 | AG28: idk | AH28: 4 | AI28: 1 | AJ28: 2 | AK28: 4 | AL28: idk | AM28: 4 | AN28: 1 | AO28: 5 | AP28: 5 | AQ28: 5 | AR28: 5 | AS28: 1 | AT28: 1 | AU28: 4 | AV28: 5 | AW28: 5 | AX28: na | AY28: 5 | AZ28: 1 | BA28: 4 | BB28: 5 | BC28: 5 | BD28: 5 | BE28: 1 | BF28: 3 | BG28: 4 | BH28: idk | BI28: 5 | BJ28: 1 | BK28: 3 | BL28: 4 | BM28: idk | BN28: 5 | BO28: 1 | BP28: 5 | BQ28: 5 | BR28: idk | BS28: 4 | BT28: 1 | BU28: 3 | BV28: 5 | BW28: idk | BX28: idk | BY28: 5 | BZ28: 1 | CA28: 4 | CB28: 5 | CC28: idk | CD28: 5 | CE28: 1 | CF28: 3 | CG28: 4 | CH28: idk | CI28: 5 | CJ28: 1 | CK28: 3 | CL28: 4 | CM28: 2 | CN28: 3 | CO28: 1 | CP28: 5 | CQ28: 5 | CR28: idk | CS28: 5 | CT28: 1 | CU28: 4 | CV28: 5 | CW28: idk | CX28: 5 | CY28: 1 | CZ28: 3 | DA28: 4 | DB28: 2 | DC28: 2 | DD28: 3 | DE28: 3 | DF28: 4 | DG28: 5 | DH28: idk | DI28: 5 | DJ28: 3 | DK28: 5 | DL28: 5 | DM28: 4 | DN28: 2 | DO28: 4
A29: 28
A30: 29
A31: 30
A32: 31
A33: 32
A34: 33
A35: 34
A36: 35

Sheet Data2
A1: Respondent | B1: Pay1 | C1: Pay2 | D1: Pay3 | E1: Pay4 | F1: Pay5 | G1: HI1 | H1: HI2 | I1: HI3 | J1: HI4 | K1: HI5 | L1: HI6 | M1: VI1 | N1: VI2 | O1: VI3 | P1: VI4 | Q1: VI5 | R1: VI6 | S1: DI1 | T1: DI2 | U1: DI3 | V1: DI4 | W1: DI5 | X1: DI6 | Y1: STD1 | Z1: STD2 | AA1: STD3 | AB1: STD4 | AC1: STD5 | AD1: STD6 | AE1: LI1 | AF1: LI2 | AG1: LI3 | AH1: LI4 | AI1: LI5 | AJ1: LTD1 | AK1: LTD2 | AL1: LTD3 | AM1: LTD4 | AN1: LTD5 | AO1: 403B1 | AP1: 403B2 | AQ1: 403B3 | AR1: 403B4 | AS1: 403B5 | AT1: 403B6 | AU1: ALP1 | AV1: ALP2 | AW1: ALP3 | AX1: ALP4 | AY1: ALP5 | AZ1: ALP6 | BA1: SLP1 | BB1: SLP2 | BC1: SLP3 | BD1: SLP4 | BE1: SLP5 | BF1: SLB1 | BG1: SLB2 | BH1: SLB3 | BI1: SLB4 | BJ1: SLB5 | BK1: SLD1 | BL1: SLD2 | BM1: SLD3 | BN1: SLD4 | BO1: SLD5 | BP1: PLP1 | BQ1: PLP2 | BR1: PLP3 | BS1: PLP4 | BT1: PLP5 | BU1: CLP1 | BV1: CLP2 | BW1: CLP3 | BX1: CLP4 | BY1: CLP5 | BZ1: CLP6 | CA1: PHOL1 | CB1: PHOL2 | CC1: PHOL3 | CD1: PHOL4 | CE1: PHOL5 | CF1: FSA1 | CG1: FSA2 | CH1: FSA3 | CI1: FSA4 | CJ1: FSA5 | CK1: SB1 | CL1: SB2 | CM1: SB3 | CN1: SB4 | CO1: SB5 | CP1: FWA1 | CQ1: FWA2 | CR1: FWA3 | CS1: FWA4 | CT1: FWA5 | CU1: CPT1 | CV1: CPT2 | CW1: CPT3 | CX1: CPT4 | CY1: CPT5 | CZ1: PD1 | DA1: PD2 | DB1: PD3 | DC1: PD4 | DD1: PD5 | DE1: PD6 | DF1: 30MPL1 | DG1: 30MPL2 | DH1: 30MPL3 | DI1: 30MPL4 | DJ1: 30MPL5 | DK1: TCP1 | DL1: TCP2 | DM1: TCP3 | DN1: TCP4 | DO1: TCP5 | DP1: TCP6
A2: 1 | B2: 4 | C2: 5 | D2: 4 | E2: 3 | F2: 5 | G2: 3 | H2: 5 | I2: idk | J2: idk | K2: 2 | L2: 4 | M2: 1 | N2: 3 | O2: idk | P2: idk | Q2: 2 | R2: 3 | S2: 2 | T2: 5 | U2: idk | V2: idk | W2: 3 | X2: 3 | Y2: 4 | Z2: 5 | AA2: idk | AB2: idk | AC2: 5 | AD2: 5 | AE2: 2 | AF2: 3 | AG2: 5 | AH2: 5 | AI2: 1 | AJ2: 4 | AK2: 5 | AL2: 5 | AM2: 5 | AN2: 3 | AO2: 3 | AP2: 5 | AQ2: idk | AR2: idk | AS2: 2 | AT2: 2 | AU2: 4 | AV2: 5 | AW2: idk | AX2: 4 | AY2: na | AZ2: 4 | BA2: 4 | BB2: 5 | BC2: idk | BD2: 4 | BE2: 3 | BF2: 3 | BG2: 5 | BH2: idk | BI2: idk | BJ2: 2 | BK2: 2 | BL2: 4 | BM2: idk | BN2: 4 | BO2: 2 | BP2: 1 | BQ2: 1 | BR2: idk | BS2: idk | BT2: idk | BU2: 2 | BV2: 4 | BW2: idk | BX2: idk | BY2: 3 | BZ2: 1 | CA2: 3 | CB2: 5 | CC2: 5 | CD2: 5 | CE2: 2 | CF2: 3 | CG2: 4 | CH2: idk | CI2: idk | CJ2: idk | CK2: 3 | CL2: 5 | CM2: idk | CN2: 5 | CO2: 4 | CP2: 4 | CQ2: 5 | CR2: idk | CS2: 5 | CT2: 1 | CU2: 2 | CV2: 4 | CW2: idk | CX2: 1 | CY2: 5 | CZ2: 2 | DA2: 3 | DB2: idk | DC2: idk | DD2: 3 | DE2: 3 | DF2: 4 | DG2: 5 | DH2: idk | DI2: 5 | DJ2: 1 | DK2: 4 | DL2: 5 | DM2: 5 | DN2: 5 | DO2: 2
A3: 2 | B3: 4 | C3: 5 | D3: 5 | E3: 5 | F3: 2 | G3: 5 | H3: 5 | I3: 5 | J3: 5 | K3: 1 | L3: 1 | M3: 1 | N3: 2 | O3: 5 | P3: 5 | Q3: 1 | R3: 1 | S3: 1 | T3: 3 | U3: 4 | V3: 5 | W3: 1 | X3: 1 | Y3: 1 | Z3: 2 | AA3: 5 | AB3: 5 | AC3: 1 | AD3: 1 | AE3: 1 | AF3: 2 | AG3: 4 | AH3: 5 | AI3: 1 | AJ3: 1 | AK3: 1 | AL3: 5 | AM3: 5 | AN3: 1 | AO3: 3 | AP3: 5 | AQ3: 5 | AR3: 5 | AS3: 1 | AT3: 1 | AU3: 3 | AV3: 5 | AW3: 5 | AX3: 5 | AY3: 5 | AZ3: 1 | BA3: 3 | BB3: 5 | BC3: 5 | BD3: 5 | BE3: 1 | BF3: 3 | BG3: 5 | BH3: idk | BI3: 5 | BJ3: 1 | BK3: 1 | BL3: 5 | BM3: idk | BN3: 5 | BO3: 1 | BP3: 3 | BQ3: 5 | BR3: 3 | BS3: 5 | BT3: 1 | BU3: 3 | BV3: 5 | BW3: idk | BX3: idk | BY3: 5 | BZ3: 1 | CA3: 1 | CB3: 4 | CC3: 5 | CD3: 5 | CE3: 1 | CF3: 1 | CG3: 1 | CH3: idk | CI3: na | CJ3: 1 | CK3: 2 | CL3: 4 | CM3: 5 | CN3: 5 | CO3: 1 | CP3: 5 | CQ3: 5 | CR3: 5 | CS3: 5 | CT3: 1 | CU3: 4 | CV3: 5 | CW3: 5 | CX3: 5 | CY3: 1 | CZ3: 4 | DA3: 5 | DB3: idk | DC3: 2 | DD3: 1 | DE3: 2 | DF3: 4 | DG3: 5 | DH3: idk | DI3: 5 | DJ3: 1 | DK3: 5 | DL3: 5 | DM3: 5 | DN3: 5 | DO3: 1
A4: 3 | B4: 5 | C4: 5 | D4: 3 | E4: 3 | F4: 4 | G4: 3 | H4: 5 | I4: 5 | J4: 4 | K4: 1 | L4: 1 | M4: 4 | N4: 4 | O4: 3 | P4: 3 | Q4: 2 | R4: 2 | S4: 5 | T4: 5 | U4: 5 | V4: 5 | W4: 1 | X4: 1 | Y4: 3 | Z4: 3 | AA4: 3 | AB4: 3 | AC4: 3 | AD4: 3 | AE4: 1 | AF4: 4 | AG4: 3 | AH4: 3 | AI4: 1 | AJ4: idk | AK4: idk | AL4: idk | AM4: idk | AN4: idk | AO4: 5 | AP4: 5 | AQ4: 4 | AR4: 1 | AS4: 4 | AT4: 5 | AU4: 5 | AV4: 5 | AW4: 3 | AX4: 2 | AY4: 3 | AZ4: 5 | BA4: idk | BB4: idk | BC4: idk | BD4: idk | BE4: idk | BF4: 5 | BG4: 5 | BH4: 1 | BI4: 5 | BJ4: 1 | BK4: idk | BL4: idk | BM4: idk | BN4: idk | BO4: idk | BP4: 4 | BQ4: 4 | BR4: 1 | BS4: 1 | BT4: 4 | BU4: 5 | BV4: 5 | BW4: 1 | BX4: 1 | BY4: 1 | BZ4: 3 | CA4: 5 | CB4: 5 | CC4: 3 | CD4: 1 | CE4: 5 | CF4: idk | CG4: idk | CH4: idk | CI4: idk | CJ4: idk | CK4: na | CL4: na | CM4: na | CN4: na | CO4: na | CP4: 5 | CQ4: 5 | CR4: 4 | CS4: 3 | CT4: 2 | CU4: 5 | CV4: 5 | CW4: 1 | CX4: 1 | CY4: 2 | CZ4: 5 | DA4: 5 | DB4: 3 | DC4: 2 | DD4: 5 | DE4: 5 | DF4: 5 | DG4: 5 | DH4: 1 | DI4: 1 | DJ4: 2 | DK4: 3 | DL4: 2 | DM4: 2 | DN4: 2 | DO4: 4
A5: 4 | B5: 4 | C5: 5 | D5: 3 | E5: 2 | F5: 3 | G5: 3 | H5: 5 | I5: 4 | J5: 5 | K5: 2 | L5: 2 | M5: 1 | N5: 4 | O5: 2 | P5: 3 | Q5: 2 | R5: 2 | S5: 3 | T5: 5 | U5: 4 | V5: 4 | W5: 2 | X5: 2 | Y5: 2 | Z5: 4 | AA5: 2 | AB5: 1 | AC5: 2 | AD5: 2 | AE5: 3 | AF5: 5 | AG5: 5 | AH5: 5 | AI5: 2 | AJ5: 3 | AK5: 5 | AL5: 5 | AM5: 2 | AN5: 2 | AO5: 3 | AP5: 5 | AQ5: 2 | AR5: 3 | AS5: 3 | AT5: 3 | AU5: 3 | AV5: 5 | AW5: 2 | AX5: 3 | AY5: 2 | AZ5: 2 | BA5: 3 | BB5: 5 | BC5: 5 | BD5: 3 | BE5: 2 | BF5: 2 | BG5: 5 | BH5: 3 | BI5: 4 | BJ5: 2 | BK5: 3 | BL5: 5 | BM5: 2 | BN5: 3 | BO5: 2 | BP5: 3 | BQ5: 5 | BR5: 5 | BS5: 4 | BT5: 2 | BU5: 3 | BV5: 4 | BW5: 3 | BX5: 3 | BY5: 4 | BZ5: 2 | CA5: 3 | CB5: 4 | CC5: 3 | CD5: 3 | CE5: 2 | CF5: 2 | CG5: 3 | CH5: 4 | CI5: 4 | CJ5: 1 | CK5: 3 | CL5: 4 | CM5: 2 | CN5: 2 | CO5: 2 | CP5: 3 | CQ5: 5 | CR5: 5 | CS5: 4 | CT5: 3 | CU5: 2 | CV5: 4 | CW5: 1 | CX5: 1 | CY5: 2 | CZ5: 3 | DA5: 4 | DB5: 2 | DC5: 3 | DD5: 2 | DE5: 3 | DF5: 2 | DG5: 3 | DH5: 3 | DI5: 3 | DJ5: 3 | DK5: 4 | DL5: 4 | DM5: 3 | DN5: 4 | DO5: 3
A6: 5 | B6: 5 | C6: 5 | D6: 3 | E6: 4 | F6: 4 | G6: 5 | H6: 5 | I6: 4 | J6: 4 | K6: 3 | L6: 1 | M6: 1 | N6: 1 | O6: 3 | P6: na | Q6: 1 | R6: 1 | S6: 4 | T6: 4 | U6: idk | V6: 4 | W6: 1 | X6: 1 | Y6: 1 | Z6: 1 | AA6: idk | AB6: na | AC6: 3 | AD6: 2 | AE6: 4 | AF6: 3 | AG6: idk | AH6: 4 | AI6: 1 | AJ6: 4 | AK6: 3 | AL6: 3 | AM6: 4 | AN6: 1 | AO6: 4 | AP6: 3 | AQ6: 5 | AR6: 5 | AS6: 2 | AT6: 2 | AU6: 5 | AV6: 5 | AW6: 5 | AX6: 5 | AY6: na | AZ6: 1 | BA6: 5 | BB6: 4 | BC6: 5 | BD6: 5 | BE6: 2 | BF6: 5 | BG6: 5 | BH6: idk | BI6: 5 | BJ6: 1 | BK6: 3 | BL6: 3 | BM6: na | BN6: 3 | BO6: 1 | BP6: 4 | BQ6: 3 | BR6: idk | BS6: na | BT6: 1 | BU6: 4 | BV6: 5 | BW6: 3 | BX6: 3 | BY6: 2 | BZ6: 2 | CA6: 5 | CB6: 5 | CC6: 5 | CD6: 4 | CE6: 1 | CF6: 3 | CG6: 4 | CH6: 4 | CI6: 4 | CJ6: 2 | CK6: 5 | CL6: 5 | CM6: 4 | CN6: 5 | CO6: 1 | CP6: 5 | CQ6: 5 | CR6: 4 | CS6: 5 | CT6: 3 | CU6: 3 | CV6: 4 | CW6: 4 | CX6: 3 | CY6: 2 | CZ6: 5 | DA6: 5 | DB6: 3 | DC6: 4 | DD6: 4 | DE6: 4 | DF6: 4 | DG6: 4 | DH6: idk | DI6: 5 | DJ6: 1 | DK6: 4 | DL6: 5 | DM6: 4 | DN6: 4 | DO6: 3
A7: 6 | B7: 5 | C7: 5 | D7: 3 | E7: 3 | F7: idk | G7: 4 | H7: 4 | I7: idk | J7: 4 | K7: 2 | L7: 2 | M7: 4 | N7: 4 | O7: 4 | P7: 4 | Q7: 2 | R7: 2 | S7: 3 | T7: 3 | U7: idk | V7: 4 | W7: 1 | X7: 1 | Y7: 1 | Z7: 1 | AA7: idk | AB7: na | AC7: 1 | AD7: 1 | AE7: 3 | AF7: 3 | AG7: idk | AH7: na | AI7: 1 | AJ7: 2 | AK7: 2 | AL7: idk | AM7: na | AN7: 1 | AO7: 4 | AP7: 4 | AQ7: idk | AR7: 4 | AS7: idk | AT7: idk | AU7: 5 | AV7: 5 | AW7: 2 | AX7: 3 | AY7: 2 | AZ7: 3 | BF7: 3 | BG7: 3 | BH7: idk | BI7: 3 | BJ7: 2 | BK7: 2 | BL7: 2 | BM7: idk | BN7: 3 | BO7: na | BP7: na | BQ7: na | BR7: na | BS7: na | BT7: na | BU7: 3 | BV7: 3 | BW7: idk | BX7: idk | BY7: 4 | BZ7: 2 | CA7: 4 | CB7: 4 | CC7: idk | CD7: 4 | CE7: 2 | CF7: 3 | CG7: 3 | CH7: idk | CI7: 4 | CJ7: 2 | CK7: 4 | CL7: 4 | CM7: 2 | CN7: 4 | CO7: 2 | CP7: 4 | CQ7: 4 | CR7: 4 | CS7: 4 | CT7: 2 | CU7: 4 | CV7: 4 | CW7: idk | CX7: 1 | CY7: 2 | CZ7: 4 | DA7: 4 | DB7: idk | DC7: 3 | DD7: 4 | DE7: 4 | DF7: 4 | DG7: 4 | DH7: idk | DI7: 5 | DJ7: 1 | DK7: 4 | DL7: 5 | DM7: idk | DN7: 4 | DO7: 2
A8: 7 | B8: 5 | C8: 5 | D8: 2 | E8: 2 | F8: 4 | G8: 5 | H8: 5 | I8: 5 | J8: 5 | K8: 2 | L8: 2 | M8: na | N8: na | O8: na | P8: na | Q8: na | R8: na | S8: 4 | T8: 5 | U8: 4 | V8: 4 | W8: 2 | X8: 2 | Y8: na | Z8: na | AA8: na | AB8: na | AC8: na | AD8: na | AE8: na | AF8: na | AG8: na | AH8: na | AI8: na | AJ8: na | AK8: na | AL8: na | AM8: na | AN8: na | AO8: 5 | AP8: 5 | AQ8: idk | AR8: na | AS8: na | AT8: na | AU8: 4 | AV8: 4 | AW8: 4 | AX8: 3 | AY8: idk | AZ8: 2 | BA8: 3 | BB8: 4 | BC8: idk | BD8: 3 | BE8: 2 | BF8: 4 | BG8: 4 | BH8: idk | BI8: 4 | BJ8: 2 | BK8: 4 | BL8: 3 | BM8: idk | BN8: na | BO8: 3 | BP8: na | BQ8: na | BR8: na | BS8: na | BT8: na | BU8: 3 | BV8: 4 | BW8: idk | BX8: 4 | BY8: 3 | BZ8: 1 | CA8: 4 | CB8: 5 | CC8: 4 | CD8: 4 | CE8: 2 | CF8: na | CG8: na | CH8: na | CI8: na | CJ8: na | CK8: 4 | CL8: 4 | CM8: idk | CN8: 4 | CO8: 3 | CP8: 4 | CQ8: 4 | CR8: 3 | CS8: 3 | CT8: 4 | CU8: 4 | CV8: 4 | CW8: 4 | CX8: 4 | CY8: 2 | CZ8: 5 | DA8: 5 | DB8: 4 | DC8: 4 | DD8: 3 | DE8: 4 | DF8: 4 | DG8: 4 | DH8: 4 | DI8: 4 | DJ8: 3 | DK8: 4 | DL8: 5 | DM8: 4 | DN8: 4 | DO8: 3
A9: 8 | B9: 5 | C9: 5 | D9: idk | E9: 1 | F9: 5 | G9: 4 | H9: 4 | I9: idk | J9: na | K9: 4 | L9: 5 | M9: 3 | N9: 3 | O9: idk | P9: 3 | Q9: 4 | R9: 4 | S9: 3 | T9: 3 | U9: idk | V9: 3 | W9: 4 | X9: 4 | Y9: na | Z9: na | AA9: idk | AB9: na | AC9: idk | AD9: idk | AE9: 4 | AF9: 4 | AG9: idk | AH9: 5 | AI9: 1 | AJ9: 4 | AK9: 4 | AL9: idk | AM9: na | AN9: 4 | AO9: 4 | AP9: 4 | AQ9: idk | AR9: na | AS9: 2 | AT9: idk | AU9: 4 | AV9: 4 | AW9: idk | AX9: 2 | AY9: 3 | AZ9: 4 | BA9: 4 | BB9: 4 | BC9: idk | BD9: 3 | BE9: 4 | BF9: 4 | BG9: 4 | BH9: idk | BI9: 4 | BJ9: 3 | BK9: idk | BL9: idk | BM9: idk | BN9: idk | BO9: idk | BP9: na | BQ9: na | BR9: idk | BS9: 2 | BT9: 4 | BU9: 4 | BV9: 4 | BW9: idk | BX9: idk | BY9: 2 | BZ9: 4 | CA9: 4 | CB9: 4 | CC9: idk | CD9: 3 | CE9: 4 | CF9: na | CG9: na | CH9: idk | CI9: na | CJ9: na | CK9: 5 | CL9: 5 | CM9: idk | CN9: 3 | CO9: 4 | CP9: 4 | CQ9: 4 | CR9: idk | CS9: 5 | CT9: 3 | CU9: 4 | CV9: 4 | CW9: idk | CX9: 3 | CY9: 3 | CZ9: idk | DA9: 4 | DB9: idk | DC9: 3 | DD9: idk | DE9: 4 | DF9: 4 | DG9: 4 | DH9: idk | DI9: 3 | DJ9: 3 | DK9: 4 | DL9: 4 | DM9: idk | DN9: 3 | DO9: 5
A10: 9 | B10: 4 | C10: 4 | D10: 4 | E10: 3 | F10: 4 | G10: 3 | H10: 3 | I10: idk | J10: na | K10: 2 | L10: 1 | M10: 3 | N10: 3 | O10: idk | P10: na | Q10: 1 | R10: 1 | S10: 3 | T10: 4 | U10: idk | V10: na | W10: 2 | X10: 2 | Y10: 3 | Z10: 4 | AA10: idk | AB10: idk | AC10: 2 | AD10: 1 | AE10: 2 | AF10: 4 | AG10: idk | AH10: idk | AI10: 2 | AJ10: 3 | AK10: 4 | AL10: idk | AM10: idk | AN10: 2 | AO10: 4 | AP10: 5 | AQ10: 5 | AR10: 4 | AS10: 5 | AT10: 4 | AU10: 3 | AV10: 4 | AW10: 4 | AX10: 4 | AY10: 4 | AZ10: 3 | BA10: 2 | BB10: 3 | BC10: 4 | BD10: 4 | BE10: 2 | BF10: 2 | BG10: 3 | BH10: 4 | BI10: 5 | BJ10: 2 | BK10: 2 | BL10: 3 | BM10: 4 | BN10: 5 | BO10: 2 | BP10: 3 | BQ10: 4 | BR10: 3 | BS10: 4 | BT10: 2 | BU10: 2 | BV10: 4 | BW10: 4 | BX10: 4 | BY10: 4 | BZ10: 1 | CA10: 3 | CB10: 4 | CC10: 4 | CD10: 4 | CE10: 2 | CF10: 2 | CG10: idk | CH10: idk | CI10: idk | CJ10: 2 | CK10: 2 | CL10: 4 | CM10: 4 | CN10: 4 | CO10: 1 | CP10: 3 | CQ10: 5 | CR10: 4 | CS10: 5 | CT10: 4 | CU10: 4 | CV10: 5 | CW10: 4 | CX10: 4 | CY10: 4 | CZ10: 4 | DA10: 4 | DB10: idk | DC10: idk | DD10: 4 | DE10: 4 | DF10: 4 | DG10: 5 | DH10: 4 | DI10: 3 | DJ10: 2 | DK10: 3 | DL10: 5 | DM10: 4 | DN10: 4 | DO10: 3
A11: 10 | B11: 5 | C11: 5 | D11: 3 | E11: idk | F11: 4 | H11: 5 | I11: idk | J11: 4 | K11: 2 | L11: 3 | M11: 2 | N11: 5 | O11: idk | P11: idk | Q11: 2 | R11: 2 | S11: 2 | T11: 5 | U11: idk | V11: idk | W11: 2 | X11: 2 | Y11: 2 | Z11: 4 | AA11: idk | AB11: na | AC11: idk | AD11: idk | AE11: 2 | AF11: 3 | AG11: idk | AH11: na | AI11: 2 | AJ11: 2 | AK11: 5 | AL11: idk | AM11: 3 | AN11: 2 | AO11: 2 | AP11: 5 | AQ11: idk | AR11: 5 | AS11: 3 | AT11: 3 | AU11: 2 | AV11: 5 | AW11: 4 | AX11: 2 | AY11: 2 | AZ11: 3 | BA11: 2 | BB11: 4 | BC11: idk | BD11: 4 | BE11: 2 | BF11: 2 | BG11: 3 | BH11: idk | BI11: idk | BJ11: 2 | BK11: 2 | BL11: 3 | BM11: idk | BN11: 2 | BO11: 2 | BP11: 2 | BQ11: 3 | BR11: idk | BS11: 2 | BT11: 2 | BU11: 2 | BV11: 5 | BW11: idk | BX11: idk | BY11: 4 | BZ11: 2 | CA11: 2 | CB11: 5 | CC11: idk | CD11: 5 | CE11: 1 | CF11: 2 | CG11: 5 | CH11: idk | CI11: 5 | CJ11: 2 | CK11: 2 | CL11: 5 | CM11: idk | CN11: 5 | CO11: 4 | CP11: 2 | CQ11: 4 | CR11: idk | CS11: 4 | CT11: 2 | CU11: 2 | CV11: 5 | CW11: idk | CX11: 2 | CY11: 3 | CZ11: 2 | DA11: 5 | DB11: idk | DC11: 2 | DD11: 4 | DE11: 4 | DF11: 2 | DG11: 5 | DH11: idk | DI11: 2 | DJ11: 2 | DK11: 4 | DL11: 5 | DM11: idk | DN11: 2 | DO11: 5
A12: 11 | B12: 5 | C12: 5 | D12: idk | E12: 4 | F12: 2 | G12: 5 | H12: 5 | I12: idk | J12: 5 | K12: 1 | L12: 1 | M12: 2 | N12: 4 | O12: idk | P12: 3 | Q12: 2 | R12: 2 | S12: 5 | T12: 5 | U12: idk | V12: 5 | W12: 2 | X12: 2 | Y12: na | Z12: na | AA12: idk | AB12: na | AC12: na | AD12: na | AE12: 4 | AF12: 4 | AG12: idk | AH12: 4 | AI12: 2 | AJ12: 4 | AK12: 4 | AL12: idk | AM12: 4 | AN12: 2 | AO12: 5 | AP12: 5 | AQ12: idk | AR12: 5 | AS12: 2 | AT12: 2 | AU12: 5 | AV12: 5 | AW12: 5 | AX12: 3 | AY12: 5 | AZ12: 2 | BA12: 5 | BB12: 5 | BC12: idk | BD12: 5 | BE12: 2 | BF12: 5 | BG12: 5 | BH12: idk | BI12: 5 | BJ12: 2 | BK12: 5 | BL12: 5 | BM12: idk | BN12: 5 | BO12: 2 | BP12: na | BQ12: na | BR12: idk | BS12: na | BT12: 2 | BU12: 5 | BV12: 5 | BW12: idk | BX12: idk | BY12: 5 | BZ12: 2 | CA12: 5 | CB12: 5 | CC12: idk | CD12: 5 | CE12: 2 | CF12: na | CG12: na | CH12: idk | CI12: na | CJ12: 2 | CK12: 4 | CL12: 4 | CM12: idk | CN12: 4 | CO12: 2 | CP12: 5 | CQ12: 5 | CR12: idk | CS12: 5 | CT12: 2 | CU12: 4 | CV12: 4 | CW12: idk | CX12: 4 | CY12: 2 | CZ12: 5 | DA12: 5 | DB12: idk | DC12: 5 | DD12: 2 | DE12: 2 | DF12: 5 | DG12: 5 | DH12: idk | DI12: 5 | DJ12: 2 | DK12: 5 | DL12: 5 | DM12: idk | DN12: 5 | DO12: 2
A13: 12 | B13: 4 | C13: 5 | D13: 2 | E13: 2 | F13: 4 | G13: 3 | H13: 4 | I13: 4 | J13: 4 | K13: 2 | L13: 1 | M13: 1 | N13: 1 | O13: idk | P13: na | Q13: 1 | R13: 1 | S13: 3 | T13: 4 | U13: idk | V13: 4 | W13: 1 | X13: 1 | Y13: 1 | Z13: 3 | AA13: idk | AB13: na | AC13: na | AD13: na | AE13: 3 | AF13: 5 | AG13: idk | AH13: 3 | AI13: 3 | AJ13: 3 | AK13: 3 | AL13: idk | AM13: 3 | AN13: 3 | AO13: 4 | AP13: 4 | AQ13: 2 | AR13: 3 | AS13: 3 | AT13: 3 | AU13: 4 | AV13: 4 | AW13: 3 | AX13: 4 | AY13: 4 | AZ13: 2 | BA13: 2 | BB13: 3 | BC13: idk | BD13: 3 | BE13: 1 | BF13: 2 | BG13: 3 | BH13: 2 | BI13: 4 | BJ13: 1 | BK13: 2 | BL13: 3 | BM13: idk | BN13: 4 | BO13: 1 | BP13: 1 | BQ13: 3 | BR13: idk | BS13: 3 | BT13: 3 | BU13: 3 | BV13: 3 | BW13: idk | BX13: idk | BY13: 3 | BZ13: 3 | CA13: 4 | CB13: 4 | CC13: 4 | CD13: 4 | CE13: 3 | CF13: 1 | CG13: 1 | CH13: idk | CI13: 3 | CJ13: 1 | CK13: 3 | CL13: 4 | CM13: 2 | CN13: 3 | CO13: 2 | CP13: 3 | CQ13: 3 | CR13: 3 | CS13: 3 | CT13: 2 | CU13: 4 | CV13: 5 | CW13: idk | CX13: 2 | CY13: 3 | CZ13: 5 | DA13: 5 | DB13: idk | DC13: 3 | DD13: 4 | DE13: 4 | DF13: 3 | DG13: 3 | DH13: idk | DI13: 3 | DJ13: 3 | DK13: 3 | DL13: 5 | DM13: 3 | DN13: 3 | DO13: 5
A14: 13 | B14: 4 | C14: 4 | D14: idk | E14: 3 | F14: 3 | G14: 4 | H14: 5 | I14: idk | J14: 4 | K14: 3 | L14: 2 | M14: na | N14: na | O14: na | P14: na | Q14: na | R14: na | S14: 4 | T14: 4 | U14: idk | V14: 1 | W14: 3 | X14: 3 | Y14: 5 | Z14: 5 | AA14: 5 | AB14: 5 | AC14: 5 | AD14: 5 | AE14: 5 | AF14: 5 | AG14: idk | AH14: 5 | AI14: 5 | AJ14: 5 | AK14: 5 | AL14: idk | AM14: 5 | AN14: 5 | AO14: 5 | AP14: 4 | AQ14: idk | AR14: idk | AS14: 4 | AT14: 3 | AU14: 3 | AV14: 4 | AW14: idk | AX14: na | AY14: 4 | AZ14: 4 | BA14: 5 | BB14: 5 | BC14: idk | BD14: 3 | BE14: 3 | BF14: 4 | BG14: 4 | BH14: idk | BI14: 4 | BJ14: 2 | BK14: 3 | BL14: 4 | BM14: idk | BN14: 4 | BO14: 2 | BP14: 4 | BQ14: 5 | BR14: idk | BS14: 1 | BT14: 4 | BU14: 4 | BV14: 4 | BW14: idk | BX14: idk | BY14: 1 | BZ14: 3 | CA14: 4 | CB14: 4 | CC14: idk | CD14: 4 | CE14: 2 | CF14: 3 | CG14: 3 | CH14: idk | CI14: 2 | CJ14: 3 | CK14: 5 | CL14: 5 | CM14: idk | CN14: 4 | CO14: 2 | CP14: 5 | CQ14: 5 | CR14: idk | CS14: 5 | CT14: 3 | CU14: 5 | CV14: 5 | CW14: idk | CX14: 2 | CY14: 4 | CZ14: 5 | DA14: 5 | DB14: idk | DC14: 3 | DD14: 4 | DE14: 5 | DF14: 4 | DG14: 4 | DH14: idk | DI14: 4 | DJ14: 2 | DK14: 3 | DL14: 4 | DM14: idk | DN14: 5 | DO14: 4
A15: 14 | B15: 5 | C15: 5 | D15: 2 | E15: 2 | F15: 5 | G15: 4 | H15: 5 | I15: 5 | J15: 5 | K15: 2 | L15: 3 | M15: na | N15: na | O15: na | P15: na | Q15: na | R15: na | S15: 4 | T15: 4 | U15: 4 | V15: 4 | W15: 3 | X15: 3 | Y15: 2 | Z15: 2 | AA15: 3 | AB15: 4 | AC15: 3 | AD15: 3 | AE15: 3 | AF15: 2 | AG15: 3 | AH15: 3 | AI15: 3 | AJ15: 2 | AK15: 3 | AL15: 3 | AM15: 3 | AN15: 3 | AO15: 4 | AP15: 4 | AQ15: 3 | AR15: 3 | AS15: 3 | AT15: 4 | AU15: 4 | AV15: 5 | AW15: 2 | AX15: 2 | AY15: 2 | AZ15: 4 | BA15: 3 | BB15: 4 | BC15: 4 | BD15: 4 | BE15: 3 | BF15: 4 | BG15: 4 | BH15: 3 | BI15: 4 | BJ15: 3 | BK15: 5 | BL15: 5 | BM15: 3 | BN15: 5 | BO15: 3 | BP15: 4 | BQ15: 4 | BR15: 3 | BS15: 4 | BT15: 3 | BU15: 4 | BV15: 4 | BW15: 3 | BX15: 3 | BY15: 4 | BZ15: 3 | CA15: 4 | CB15: 4 | CC15: 4 | CD15: 4 | CE15: 3 | CF15: 2 | CG15: 2 | CH15: 3 | CI15: 3 | CJ15: 2 | CK15: 2 | CL15: 2 | CM15: 3 | CN15: 3 | CO15: 3 | CP15: 5 | CQ15: 5 | CR15: 3 | CS15: 3 | CT15: 4 | CU15: 3 | CV15: 4 | CW15: 4 | CX15: 4 | CY15: 3 | CZ15: 4 | DA15: 4 | DB15: 3 | DC15: 4 | DD15: 4 | DE15: 4 | DF15: 2 | DG15: 2 | DH15: 3 | DI15: 3 | DJ15: 3 | DK15: 2 | DL15: 4 | DM15: 3 | DN15: 2 | DO15: 5
A16: 15 | B16: 2 | C16: 5 | D16: idk | E16: 4 | F16: 1 | G16: 2 | H16: 5 | I16: 4 | J16: 5 | K16: 1 | L16: 1 | M16: 2 | N16: 5 | O16: 4 | P16: 4 | Q16: 1 | R16: 1 | S16: 2 | T16: 5 | U16: 4 | V16: 2 | W16: 1 | X16: 1 | Y16: 2 | Z16: 5 | AA16: 4 | AB16: 5 | AC16: 1 | AD16: 1 | AE16: 3 | AF16: 5 | AG16: idk | AH16: 4 | AI16: 1 | AJ16: 4 | AK16: 5 | AL16: idk | AM16: 5 | AN16: 2 | AO16: 4 | AP16: 5 | AQ16: idk | AR16: 5 | AS16: 3 | AT16: 4 | AU16: 2 | AV16: 5 | AW16: 2 | AX16: 2 | AY16: 2 | AZ16: 3 | BA16: 4 | BB16: 5 | BC16: idk | BD16: 2 | BE16: 2 | BF16: 4 | BG16: 5 | BH16: idk | BI16: 3 | BJ16: 3 | BK16: 4 | BL16: 5 | BM16: idk | BN16: 5 | BO16: 3 | BP16: 4 | BQ16: 4 | BR16: idk | BS16: 3 | BT16: 3 | BU16: 4 | BV16: 5 | BW16: idk | BX16: idk | BY16: 3 | BZ16: 3 | CA16: 4 | CB16: 5 | CD16: 4 | CE16: 2 | CF16: 4 | CG16: 5 | CH16: idk | CI16: 4 | CJ16: 2 | CK16: 4 | CL16: 5 | CM16: idk | CN16: 5 | CO16: 2 | CP16: 3 | CQ16: 4 | CR16: idk | CS16: 5 | CT16: 2 | CU16: 3 | CV16: 4 | CW16: idk | CX16: 4 | CY16: 2 | CZ16: 4 | DA16: 5 | DB16: idk | DC16: 3 | DD16: 3 | DE16: 3 | DF16: 2 | DG16: 4 | DH16: idk | DI16: 2 | DJ16: 1 | DK16: 4 | DL16: 5 | DM16: idk | DN16: 4 | DO16: 3
A17: 16 | B17: 3 | C17: 4 | D17: 4 | E17: 3 | F17: 4 | G17: 5 | H17: 5 | I17: 5 | J17: 5 | K17: 1 | L17: 2 | M17: 1 | N17: 2 | O17: idk | P17: 4 | Q17: 1 | R17: 1 | S17: 2 | T17: 3 | U17: idk | V17: 3 | W17: 1 | X17: 1 | Y17: 1 | Z17: 2 | AA17: idk | AB17: na | AC17: 1 | AD17: 1 | AE17: 1 | AF17: 2 | AG17: idk | AH17: na | AI17: 1 | AJ17: 2 | AK17: 3 | AL17: idk | AM17: na | AN17: 2 | AO17: 3 | AP17: 4 | AQ17: 5 | AR17: 5 | AS17: 1 | AT17: 2 | AU17: 4 | AV17: 5 | AW17: 2 | AX17: 4 | AY17: 2 | AZ17: 3 | BA17: 4 | BB17: 5 | BC17: 5 | BD17: 5 | BE17: 3 | BF17: 3 | BG17: 4 | BH17: idk | BI17: 5 | BJ17: 2 | BK17: 3 | BL17: 3 | BM17: idk | BN17: 5 | BO17: 2 | BP17: na | BQ17: na | BR17: na | BS17: na | BT17: na | BU17: 3 | BV17: 4 | BW17: idk | BX17: 5 | BY17: 3 | BZ17: 1 | CA17: 2 | CB17: 4 | CC17: 2 | CD17: 3 | CE17: 2 | CF17: 4 | CG17: 4 | CH17: idk | CI17: 5 | CJ17: 4 | CK17: 2 | CL17: 4 | CM17: 2 | CN17: 3 | CO17: 4 | CP17: 3 | CQ17: 4 | CR17: idk | CS17: 5 | CT17: 2 | CU17: 3 | CV17: 4 | CW17: idk | CX17: 2 | CY17: 2 | CZ17: 4 | DA17: 5 | DB17: 1 | DC17: 1 | DD17: 4 | DE17: 5 | DF17: 3 | DG17: 4 | DH17: idk | DI17: 4 | DJ17: 1 | DK17: 5 | DL17: 5 | DM17: 5 | DN17: 4 | DO17: 4
A18: 17 | B18: 4 | C18: 5 | D18: 2 | E18: 3 | F18: 4 | G18: 4 | H18: 4 | I18: 3 | J18: 4 | K18: 3 | L18: 2 | M18: 1 | N18: 2 | O18: 1 | P18: 1 | Q18: 1 | R18: 1 | S18: 2 | T18: 4 | U18: 3 | V18: 3 | W18: 2 | X18: 2 | Y18: na | Z18: na | AA18: na | AB18: na | AC18: na | AD18: na | AE18: na | AF18: na | AG18: na | AH18: na | AI18: na | AJ18: na | AK18: na | AL18: na | AM18: na | AN18: na | AO18: 2 | AP18: 4 | AQ18: 3 | AR18: 3 | AS18: 1 | AT18: 1 | AU18: 4 | AV18: 5 | AW18: 4 | AX18: 4 | AY18: 3 | AZ18: 3 | BA18: 3 | BB18: 4 | BC18: 4 | BD18: 4 | BE18: 3 | BF18: 4 | BG18: 4 | BH18: idk | BI18: 5 | BJ18: 3 | BK18: 3 | BL18: 5 | BM18: idk | BN18: 5 | BO18: 2 | BP18: 2 | BQ18: 5 | BR18: idk | BS18: 3 | BT18: 3 | BU18: 4 | BV18: 5 | BW18: idk | BX18: idk | BY18: 3 | BZ18: 1 | CA18: 4 | CB18: 5 | CC18: idk | CD18: 4 | CE18: 2 | CF18: na | CG18: na | CH18: na | CI18: na | CJ18: na | CK18: 3 | CL18: 5 | CM18: idk | CN18: 3 | CO18: 3 | CP18: 3 | CQ18: 4 | CR18: 4 | CS18: 2 | CT18: 4 | CU18: 4 | CV18: 5 | CW18: idk | CX18: 2 | CY18: 4 | CZ18: 3 | DA18: 5 | DB18: idk | DC18: 2 | DD18: 4 | DE18: 5 | DF18: 4 | DG18: 5 | DH18: idk | DI18: 4 | DJ18: 2 | DK18: 3 | DL18: 5 | DM18: 2 | DN18: 2 | DO18: 5
A19: 18 | B19: 4 | C19: 5 | D19: 4 | E19: 4 | F19: 3 | G19: 3 | H19: 4 | I19: 4 | J19: 4 | K19: 2 | L19: 2 | M19: 2 | N19: 3 | O19: 4 | P19: 4 | Q19: 2 | R19: 2 | S19: 3 | T19: 3 | U19: 4 | V19: 4 | W19: 2 | X19: 2 | Y19: 1 | Z19: 2 | AA19: 4 | AB19: 4 | AC19: 3 | AD19: 3 | AE19: 2 | AF19: 3 | AG19: 3 | AH19: 3 | AI19: 3 | AJ19: 4 | AK19: 4 | AL19: 4 | AM19: 4 | AN19: 2 | AO19: 3 | AP19: 5 | AQ19: 2 | AR19: 3 | AS19: 4 | AT19: 3 | AU19: 4 | AV19: 5 | AW19: 4 | AX19: 4 | AY19: 4 | AZ19: 3 | BA19: 4 | BB19: 4 | BC19: 3 | BD19: 3 | BE19: 3 | BF19: 2 | BG19: 3 | BH19: 1 | BI19: 5 | BJ19: 2 | BK19: 3 | BL19: 3 | BM19: 1 | BN19: 4 | BO19: 2 | BP19: na | BQ19: na | BR19: na | BS19: na | BT19: na | BU19: 5 | BV19: 5 | BW19: 5 | BX19: 3 | BY19: 4 | BZ19: 2 | CA19: 3 | CB19: 4 | CC19: 4 | CD19: 4 | CE19: 3 | CF19: na | CG19: na | CH19: na | CI19: na | CJ19: na | CK19: 3 | CL19: 4 | CM19: 3 | CN19: 4 | CO19: 3 | CP19: 4 | CQ19: 4 | CR19: 3 | CS19: 4 | CT19: 2 | CU19: 4 | CV19: 5 | CW19: idk | CX19: 4 | CY19: 3 | CZ19: 4 | DA19: 5 | DB19: 2 | DC19: 2 | DD19: 4 | DE19: 4 | DF19: 2 | DG19: 3 | DH19: 2 | DI19: 3 | DJ19: 3 | DK19: 4 | DL19: 4 | DM19: 4 | DN19: 4 | DO19: 2
A20: 19 | B20: 5 | C20: 5 | D20: 1 | E20: 1 | F20: 5 | G20: 4 | H20: 4 | I20: idk | J20: 5 | K20: 1 | L20: 2 | M20: 3 | N20: 3 | O20: idk | P20: 3 | Q20: 1 | R20: 1 | S20: 3 | T20: 4 | U20: idk | V20: 3 | W20: 3 | X20: 3 | Y20: 3 | Z20: 3 | AA20: idk | AB20: 3 | AC20: 3 | AD20: 3 | AE20: 3 | AF20: 3 | AG20: idk | AH20: 3 | AI20: 1 | AJ20: 3 | AK20: 3 | AL20: 3 | AM20: 3 | AN20: 3 | AO20: 3 | AP20: 3 | AQ20: 3 | AR20: 3 | AS20: 3 | AT20: 3 | AU20: 5 | AV20: 5 | AW20: 2 | AX20: 2 | AY20: na | AZ20: 5 | BA20: 5 | BB20: 5 | BC20: 2 | BD20: 2 | BE20: 4 | BF20: 4 | BG20: 3 | BH20: idk | BI20: 3 | BJ20: 4 | BK20: 3 | BL20: 3 | BM20: idk | BN20: 4 | BO20: 3 | BP20: 1 | BQ20: 1 | BR20: 3 | BS20: 3 | BT20: 1 | BU20: 4 | BV20: 5 | BW20: 4 | BX20: idk | BY20: 5 | BZ20: 5 | CA20: 5 | CB20: 5 | CC20: 1 | CD20: 2 | CE20: 5 | CF20: 3 | CG20: 3 | CH20: idk | CI20: 3 | CJ20: 3 | CK20: 1 | CL20: 1 | CM20: idk | CN20: 3 | CO20: 5 | CP20: 3 | CQ20: 3 | CR20: idk | CS20: 2 | CT20: 3 | CU20: 4 | CV20: 5 | CW20: 1 | CX20: 1 | CY20: 5 | CZ20: 5 | DA20: 5 | DB20: 1 | DC20: 1 | DD20: 5 | DE20: 5 | DF20: 3 | DG20: 4 | DH20: 1 | DI20: 1 | DJ20: 5 | DK20: 2 | DL20: 4 | DM20: 1 | DN20: 2 | DO20: 5
A21: 20 | B21: 4 | C21: 5 | D21: 3 | E21: 3 | F21: idk | G21: na | H21: 5 | I21: 3 | J21: na | K21: idk | L21: idk | M21: 1 | N21: 4 | O21: 4 | P21: 4 | Q21: idk | R21: idk | S21: 3 | T21: 3 | U21: 3 | V21: 3 | W21: idk | X21: idk | Y21: 2 | Z21: 3 | AA21: 3 | AB21: 2 | AC21: idk | AD21: idk | AE21: 3 | AF21: 5 | AG21: 3 | AH21: 4 | AI21: idk | AJ21: 3 | AK21: 4 | AL21: 3 | AM21: 4 | AN21: idk | AO21: 3 | AP21: 4 | AQ21: 3 | AR21: 3 | AS21: idk | AT21: idk | AU21: 3 | AV21: 4 | AW21: 4 | AX21: na | AY21: 4 | AZ21: 2 | BA21: 3 | BB21: 4 | BC21: 4 | BD21: 5 | BE21: 3 | BF21: 4 | BG21: 4 | BH21: 2 | BI21: 4 | BJ21: 3 | BK21: 5 | BL21: 4 | BM21: 2 | BN21: 4 | BO21: 3 | BP21: 4 | BQ21: 4 | BR21: 2 | BS21: 2 | BT21: 3 | BU21: 2 | BV21: 3 | BW21: 3 | BX21: 3 | BY21: 4 | BZ21: 1 | CA21: 3 | CB21: 3 | CC21: 5 | CD21: 5 | CE21: 1 | CF21: 2 | CG21: 2 | CH21: 2 | CI21: 3 | CJ21: 1 | CK21: 1 | CL21: 1 | CM21: 1 | CN21: 1 | CO21: 1 | CP21: 4 | CQ21: 4 | CR21: 3 | CS21: 4 | CT21: 2 | CU21: 2 | CV21: 3 | CW21: 5 | CX21: 4 | CY21: 2 | CZ21: 4 | DA21: 5 | DB21: 4 | DC21: 4 | DD21: 5 | DE21: 3 | DF21: 1 | DG21: 1 | DH21: 5 | DI21: 4 | DJ21: 1 | DK21: 3 | DL21: 4 | DM21: 3 | DN21: 3 | DO21: 3
A22: 21 | B22: 4 | C22: 4 | D22: 3 | E22: 2 | F22: 4 | G22: 3 | H22: 4 | I22: 5 | J22: 5 | K22: 4 | L22: 3 | M22: 2 | N22: 4 | O22: 4 | P22: 4 | Q22: 2 | R22: 2 | S22: na | T22: na | U22: na | V22: na | W22: na | X22: na | Y22: 1 | Z22: 2 | AA22: idk | AB22: na | AC22: 2 | AD22: 2 | AE22: 1 | AF22: 3 | AG22: idk | AH22: 5 | AI22: idk | AJ22: 1 | AK22: 3 | AL22: idk | AM22: 5 | AN22: 2 | AO22: 3 | AP22: 4 | AQ22: 4 | AR22: 4 | AS22: 3 | AT22: 2 | AU22: 4 | AV22: 5 | AW22: 3 | AX22: 2 | AY22: 3 | AZ22: 4 | BA22: 3 | BB22: 4 | BC22: 4 | BD22: 4 | BE22: 2 | BF22: 2 | BG22: 3 | BH22: idk | BI22: 4 | BJ22: 2 | BK22: 3 | BL22: 4 | BM22: idk | BN22: 5 | BO22: 1 | BP22: 2 | BQ22: 4 | BR22: idk | BS22: na | BT22: 4 | BU22: 2 | BV22: 4 | BW22: idk | BX22: idk | BY22: 4 | BZ22: 1 | CA22: 3 | CB22: 5 | CC22: 3 | CD22: 3 | CE22: 3 | CF22: 4 | CG22: 4 | CH22: idk | CI22: 4 | CJ22: 2 | CK22: 4 | CL22: 4 | CM22: 4 | CN22: 4 | CO22: 2 | CP22: 4 | CQ22: 5 | CR22: 5 | CS22: 4 | CT22: 2 | CU22: 4 | CV22: 5 | CW22: 2 | CX22: 2 | CY22: 3 | CZ22: 4 | DA22: 5 | DB22: idk | DC22: na | DD22: 3 | DE22: 3 | DF22: 2 | DG22: 4 | DH22: 3 | DI22: 3 | DJ22: 1 | DK22: 2 | DL22: 4 | DM22: 3 | DN22: 3 | DO22: 4
A23: 22 | B23: 5 | C23: 5 | D23: idk | E23: 2 | F23: 3 | G23: 3 | H23: 5 | I23: 5 | J23: 5 | K23: 1 | L23: 1 | M23: 1 | N23: 1 | O23: idk | P23: idk | Q23: 1 | R23: 1 | S23: 1 | T23: 1 | U23: idk | V23: idk | W23: 1 | X23: 1 | Y23: 1 | Z23: 4 | AA23: idk | AB23: idk | AC23: 1 | AD23: 1 | AE23: 1 | AF23: 4 | AG23: idk | AH23: 4 | AI23: 1 | AJ23: 1 | AK23: 4 | AL23: idk | AM23: 4 | AN23: 1 | AO23: 4 | AP23: 4 | AQ23: 5 | AR23: 5 | AS23: 1 | AT23: 1 | AU23: 4 | AV23: 5 | AW23: idk | AX23: 4 | AY23: 4 | AZ23: 2 | BA23: 2 | BB23: 5 | BC23: idk | BD23: 5 | BE23: 1 | BF23: 4 | BG23: 4 | BH23: idk | BI23: 5 | BJ23: 1 | BK23: 4 | BL23: 4 | BM23: idk | BN23: 4 | BO23: 1 | BP23: 5 | BQ23: 5 | BR23: idk | BS23: 5 | BT23: 2 | BU23: 2 | BV23: 4 | BW23: idk | BX23: idk | BY23: 3 | BZ23: 1 | CA23: 2 | CB23: 4 | CC23: idk | CD23: 4 | CE23: 1 | CF23: 2 | CG23: 4 | CH23: idk | CI23: 4 | CJ23: 1 | CK23: 2 | CL23: 3 | CM23: idk | CN23: 3 | CO23: 1 | CP23: 3 | CQ23: na | CR23: idk | CS23: 2 | CT23: 1 | CU23: 2 | CV23: 4 | CW23: idk | CX23: 4 | CY23: 1 | CZ23: 3 | DA23: 4 | DB23: idk | DC23: idk | DD23: 2 | DE23: 2 | DF23: 3 | DG23: 4 | DH23: idk | DI23: idk | DJ23: na | DK23: 5 | DL23: 5 | DM23: idk | DN23: 2 | DO23: 3
