Workbook
Name \a: '[1]CUADRO No 4'!#REF!
Name \c: #REF!
Name \i: #REF!
Name \P: #REF!
Name \r: #REF!
Name __pd1: [2]Rates!$J$24
Name __pd6: [2]Rates!$J$30
Name __tix1: [2]Rates!$J$40
Name __tix2: [2]Rates!$J$41
Name __tix6: [2]Rates!$J$47
Name _1: #REF!
Name _1998: #REF!
Name _1999: #REF!
Name _2: #REF!
Name _2000: #REF!
Name _2001: #REF!
Name _2002: #REF!
Name _3: #REF!
Name _4: #REF!
Name _5: #REF!
Name _6: #REF!
Name _7: #REF!
Name _8: #REF!
Name _fmi1: [3]PAGOFMI!$A$1:$L$51
Name _fmi2: [3]PAGOFMI!$P$1:$AA$51
Name _fmi3: [3]PAGORES!$AC$1:$AN$43
Name _fmi4: [3]PAGORES!$AP$1:$BA$44
Name _PIB01: [4]SUPUESTOS!#REF!
Name _PIB02: [5]SUPUESTOS!#REF!
Name _PIB95: [4]SUPUESTOS!$J$47
Name _PIB96: [4]SUPUESTOS!$K$47
Name _PIB97: [6]SUPUESTOS!$L$47
Name _PIB98: [6]SUPUESTOS!$M$47
Name _PIB99: [6]SUPUESTOS!$N$47
Name _RES9397: #REF!
Name _rez2: '[3]PAGOS VIGENCIA t'!$A$57:$AH$108
Name _rez3: [3]PAGORES!$A$1:$M$37
Name _rez4: [3]PAGORES!$O$1:$AN$43
Name a: #REF!
Name A_2002: #REF!
Name A_CAPITAL: [9]Hoja4!$B$3:$O$34
Name A_DEPTOS: [9]Hoja4!$B$76:$N$108
Name A_impresión_IM: #REF!
Name A_MUNPIOS: [9]Hoja4!$B$39:$N$71
Name AAA: [10]proyecINGRESOS99!$L$1:$T$97
Name AEFormar: [11]Variables!$C$5
Name Ajustado: #REF!
Name almuerzo: [11]Variables!$C$18
Name alquilertableta: [11]Variables!$C$21
Name ANEXO_No.: #REF!
Name ANEXO_No._5: #REF!
Name ANPDH: '[12]Salary & PR Tax'!#REF!
Name aprnac: [13]GASTOS!#REF!
Name APROPIACIONES_PAC_Y_REZAGO_1999___2000: #REF!
Name aprprp: [13]GASTOS!#REF!
Name asigbas: #REF!
Name asigbasempu: #REF!
Name asigbasisten: #REF!
Name asigmen: #REF!
Name auxalm: #REF!

Sheet Budget Summary
B1: Partners of the Americas Fertilize Right Colombia Budget 2023
B2: USDA-FAS-10960-0700-10-23-0012 CFDA: 10.960 Technical Agricultural Assistance
A4: Line Items | B4: Year 1 | E4: Year 2 | H4: Year 3 | K4: Year 4 | N4: Total | O4: Total | P4: Grand
B5: USDA | C5: Cost Share | D5: Total | E5: USDA | F5: Cost Share | G5: Total | H5: USDA | I5: Cost Share | J5: Total | K5: USDA | L5: Cost Share | M5: Total | N5: USDA | O5: Cost Share | P5: Total
A7: Personnel | B7: =Budget!F29 -> 139520.83 | C7: =Budget!G29 -> 0 | D7: =SUM(B7:C7) -> 139520.83 | E7: =Budget!L29 -> 163800 | F7: =Budget!M29 -> 0 | G7: =SUM(E7:F7) -> 163800 | H7: =Budget!R29 -> 171990 | I7: =Budget!S29 -> 0 | J7: =SUM(H7:I7) -> 171990 | K7: =Budget!X29 -> 108322.35 | L7: =Budget!Y29 -> 0 | M7: =SUM(K7:L7) -> 108322.35 | N7: =Budget!AA29 -> 583633.18 | O7: =Budget!AB29 -> 0 | P7: =Budget!AC29 -> 583633.18
A9: Fringe Benefits | B9: =Budget!F41 -> 56107.429 | C9: =Budget!G41 -> 0 | D9: =Budget!H41 -> 56107.429 | E9: =Budget!L41 -> 66647.128 | F9: =Budget!M41 -> 0 | G9: =Budget!N41 -> 66647.128 | H9: =Budget!R41 -> 69979.484 | I9: =Budget!S41 -> 0 | J9: =Budget!T41 -> 69979.484 | K9: =Budget!X41 -> 44089.053 | L9: =Budget!Y41 -> 0 | M9: =Budget!Z41 -> 44089.053 | N9: =Budget!AA41 -> 236823.09 | O9: =Budget!AB41 -> 0 | P9: =Budget!AC41 -> 236823.09
A11: Travel | B11: =Budget!F64 -> 13735 | C11: =Budget!G64 -> 0 | D11: =Budget!H64 -> 13735 | E11: =Budget!L64 -> 16601.4 | F11: =Budget!M64 -> 0 | G11: =Budget!N64 -> 16601.4 | H11: =Budget!R64 -> 17034.162 | I11: =Budget!S64 -> 0 | J11: =Budget!T64 -> 17034.162 | K11: =Budget!X64 -> 13025.739 | L11: =Budget!Y64 -> 0 | M11: =Budget!Z64 -> 13025.739 | N11: =Budget!AA64 -> 60396.301 | O11: =Budget!AB64 -> 0 | P11: =Budget!AC64 -> 60396.301
A13: Equipment | B13: =Budget!F70 -> 0 | C13: =Budget!G70 -> 0 | D13: =Budget!H70 -> 0 | E13: =Budget!L70 -> 0 | F13: =Budget!M70 -> 0 | G13: =Budget!N70 -> 0 | H13: =Budget!R70 -> 0 | I13: =Budget!S70 -> 0 | J13: =Budget!T70 -> 0 | K13: =Budget!X70 -> 0 | L13: =Budget!Y70 -> 0 | M13: =Budget!Z70 -> 0 | N13: =Budget!AA70 -> 0 | O13: =Budget!AB70 -> 0 | P13: =Budget!AC70 -> 0
A15: Supplies | B15: =Budget!F85 -> 22000 | C15: =Budget!G85 -> 0 | D15: =Budget!H85 -> 22000 | E15: =Budget!L85 -> 4926 | F15: =Budget!M85 -> 0 | G15: =Budget!N85 -> 4926 | H15: =Budget!R85 -> 5055.42 | I15: =Budget!S85 -> 0 | J15: =Budget!T85 -> 5055.42 | K15: =Budget!X85 -> 3242.7221 | L15: =Budget!Y85 -> 0 | M15: =Budget!Z85 -> 3242.7221 | N15: =Budget!AA85 -> 35224.142 | O15: =Budget!AB85 -> 0 | P15: =Budget!AC85 -> 35224.142
A17: Contractual | B17: =Budget!F94 -> 103000 | C17: =Budget!G94 -> 0 | D17: =Budget!H94 -> 103000 | E17: =Budget!L94 -> 340000 | F17: =Budget!M94 -> 0 | G17: =Budget!N94 -> 340000 | H17: =Budget!R94 -> 340000 | I17: =Budget!S94 -> 0 | J17: =Budget!T94 -> 340000 | K17: =Budget!X94 -> 77000 | L17: =Budget!Y94 -> 0 | M17: =Budget!Z94 -> 77000 | N17: =Budget!AA94 -> 860000 | O17: =Budget!AB94 -> 0 | P17: =Budget!AC94 -> 860000
A19: Other Direct Costs | B19: =Budget!F132 -> 47825 | C19: =Budget!G132 -> 40000 | D19: =Budget!H132 -> 87825 | E19: =Budget!L132 -> 175081 | F19: =Budget!M132 -> 78250 | G19: =Budget!N132 -> 253331 | H19: =Budget!R132 -> 39986.73 | I19: =Budget!S132 -> 19750 | J19: =Budget!T132 -> 59736.73 | K19: =Budget!X132 -> 58642.416 | L19: =Budget!Y132 -> 13500 | M19: =Budget!Z132 -> 72142.416 | N19: =Budget!AA132 -> 321535.15 | O19: =Budget!AB132 -> 151500 | P19: =Budget!AC132 -> 473035.15
A21: Total Direct Costs | B21: =Budget!F134 -> 382188.26 | C21: =Budget!G134 -> 40000 | D21: =Budget!H134 -> 422188.26 | E21: =Budget!L134 -> 767055.53 | F21: =Budget!M134 -> 78250 | G21: =Budget!N134 -> 845305.53 | H21: =Budget!R134 -> 644045.8 | I21: =Budget!S134 -> 19750 | J21: =Budget!T134 -> 663795.8 | K21: =Budget!X134 -> 304322.28 | L21: =Budget!Y134 -> 13500 | M21: =Budget!Z134 -> 317822.28 | N21: =Budget!AA134 -> 2097611.9 | O21: =Budget!AB134 -> 151500 | P21: =Budget!AC134 -> 2249111.9
A22: Indirect Costs | B22: =Budget!F135 -> 108082.84 | C22: =Budget!G135 -> 0 | D22: =Budget!H135 -> 108082.84 | E22: =Budget!L135 -> 216923.3 | F22: =Budget!M135 -> 0 | G22: =Budget!N135 -> 216923.3 | H22: =Budget!R135 -> 182136.15 | I22: =Budget!S135 -> 0 | J22: =Budget!T135 -> 182136.15 | K22: =Budget!X135 -> 86062.34 | L22: =Budget!Y135 -> 0 | M22: =Budget!Z135 -> 86062.34 | N22: =Budget!AA135 -> 593204.64 | O22: =Budget!AB135 -> 0 | P22: =Budget!AC135 -> 593204.64
A23: Total | B23: =Budget!F136 -> 490271.1 | C23: =Budget!G136 -> 40000 | D23: =Budget!H136 -> 530271.1 | E23: =Budget!L136 -> 983978.83 | F23: =Budget!M136 -> 78250 | G23: =Budget!N136 -> 1062228.8 | H23: =Budget!R136 -> 826181.95 | I23: =Budget!S136 -> 19750 | J23: =Budget!T136 -> 845931.95 | K23: =Budget!X136 -> 390384.62 | L23: =Budget!Y136 -> 13500 | M23: =Budget!Z136 -> 403884.62 | N23: =Budget!AA136 -> 2690816.5 | O23: =Budget!AB136 -> 151500 | P23: =Budget!AC136 -> 2842316.5

Sheet Budget
B1: Partners of the Americas Fertilize Right Colombia Budget 2023
B2: USDA-FAS-10960-0700-10-23-0012 CFDA: 10.960 Technical Agricultural Assistance
B3: Duration: 3 Years, 7.5 months
B4: Country: Colombia
A5: Budget Assumptions
A6: Inflation - US Based Goods/Services - 2% | B6: 1.02
A7: Inflation - Locally Purchased Goods/Services - 3% | B7: 1.03
A8: Merit Based Increases for HQ & Field Staff - 5% | B8: 1.05
A10: *Key Personnel
A11: Line Items | F11: Year 1 | L11: Year 2 | O11: Year 3 | X11: Year 4 | AA11: Total | AB11: Total | AC11: Grand
B12: Unit | C12: Cost | D12: Duration | E12: Type | F12: USDA | G12: Cost Share | H12: Total | I12: Unit | J12: Cost | K12: Duration | L12: USDA | M12: Cost Share | N12: Total | O12: Unit | P12: Cost | Q12: Duration | R12: USDA | S12: Cost Share | T12: Total | U12: Unit | V12: Cost | W12: Duration | X12: USDA | Y12: Cost Share | Z12: Total | AA12: USDA | AB12: Cost Share | AC12: Total
A14: Personnel
A15: Headquarters Personnel | B15: LOE
A16: Program Director | B16: 0.1 | C16: =120000/12 -> 10000 | D16: 12 | E16: /months | F16: =D16*C16*B16 -> 12000 | G16: 0 | H16: =SUM(F16:G16) -> 12000 | I16: =B16 -> 0.1 | J16: =C16*$B$8 -> 10500 | K16: 12 | L16: =I16*J16*K16 -> 12600 | M16: 0 | N16: =SUM(L16:M16) -> 12600 | O16: =B16 -> 0.1 | P16: =C16*$B$8*$B$8 -> 11025 | Q16: 12 | R16: =O16*P16*Q16 -> 13230 | S16: 0 | T16: =SUM(R16:S16) -> 13230 | U16: =O16 -> 0.1 | V16: =C16*$B$8*$B$8*$B$8 -> 11576.25 | W16: 7.5 | X16: =U16*V16*W16 -> 8682.1875 | Y16: 0 | Z16: =SUM(X16:Y16) -> 8682.1875 | AA16: =F16+L16+R16+X16 -> 46512.188 | AB16: =G16+M16+S16+Y16 -> 0 | AC16: =SUM(AA16:AB16) -> 46512.188
A17: Technical Advisor - Senior Program Officer | B17: 0.55 | C17: =65000/12 -> 5416.6667 | D17: 12 | E17: /months | F17: =D17*C17*B17 -> 35750 | G17: 0 | H17: =SUM(F17:G17) -> 35750 | I17: =B17 -> 0.55 | J17: =C17*$B$8 -> 5687.5 | K17: 12 | L17: =I17*J17*K17 -> 37537.5 | M17: 0 | N17: =SUM(L17:M17) -> 37537.5 | O17: =I17 -> 0.55 | P17: =C17*$B$8*$B$8 -> 5971.875 | Q17: 12 | R17: =O17*P17*Q17 -> 39414.375 | S17: 0 | T17: =SUM(R17:S17) -> 39414.375 | U17: =O17 -> 0.55 | V17: =C17*$B$8*$B$8*$B$8 -> 6270.4688 | W17: 7.5 | X17: =U17*V17*W17 -> 25865.684 | Y17: 0 | Z17: =SUM(X17:Y17) -> 25865.684 | AA17: =F17+L17+R17+X17 -> 138567.56 | AB17: =G17+M17+S17+Y17 -> 0 | AC17: =SUM(AA17:AB17) -> 138567.56
A18: Subtotal HQ Personnel | F18: =SUM(F16:F17) -> 47750 | G18: =SUM(G16:G17) -> 0 | H18: =SUM(H16:H17) -> 47750 | L18: =SUM(L16:L17) -> 50137.5 | M18: =SUM(M16:M17) -> 0 | N18: =SUM(N16:N17) -> 50137.5 | R18: =SUM(R16:R17) -> 52644.375 | S18: =SUM(S16:S17) -> 0 | T18: =SUM(T16:T17) -> 52644.375 | X18: =SUM(X16:X17) -> 34547.871 | Y18: =SUM(Y16:Y17) -> 0 | Z18: =SUM(Z16:Z17) -> 34547.871 | AA18: =SUM(AA16:AA17) -> 185079.75 | AB18: =SUM(AB16:AB17) -> 0 | AC18: =SUM(AC16:AC17) -> 185079.75
A20: Field Personnel | B20: LOE
A21: Deputy Director* | B21: 1 | C21: =50000/12 -> 4166.6667 | D21: 11 | E21: /months | F21: =D21*C21*B21 -> 45833.333 | G21: 0 | H21: =SUM(F21:G21) -> 45833.333 | I21: =+B21 -> 1 | J21: =C21*$B$8 -> 4375 | K21: 12 | L21: =J21*K21*I21 -> 52500 | M21: 0 | N21: =SUM(L21:M21) -> 52500 | O21: =+B21 -> 1 | P21: =C21*$B$8*$B$8 -> 4593.75 | Q21: 12 | R21: =Q21*P21*O21 -> 55125 | S21: 0 | T21: =SUM(R21:S21) -> 55125 | U21: =+B21 -> 1 | V21: =C21*$B$8*$B$8*$B$8 -> 4823.4375 | W21: 7.5 | X21: =W21*V21*U21 -> 36175.781 | Y21: 0 | Z21: =SUM(X21:Y21) -> 36175.781 | AA21: =F21+L21+R21+X21 -> 189634.11 | AB21: =G21+M21+S21+Y21 -> 0 | AC21: =SUM(AA21:AB21) -> 189634.11
A22: Finance & Administration Director | B22: 0.15 | C22: =45000/12 -> 3750 | D22: 11 | E22: /months | F22: =D22*C22*B22 -> 6187.5 | G22: 0 | H22: =SUM(F22:G22) -> 6187.5 | I22: =+B22 -> 0.15 | J22: =C22*$B$8 -> 3937.5 | K22: 12 | L22: =J22*K22*I22 -> 7087.5 | M22: 0 | N22: =SUM(L22:M22) -> 7087.5 | O22: =+B22 -> 0.15 | P22: =C22*$B$8*$B$8 -> 4134.375 | Q22: 12 | R22: =Q22*P22*O22 -> 7441.875 | S22: 0 | T22: =SUM(R22:S22) -> 7441.875 | U22: =+B22 -> 0.15 | V22: =C22*$B$8*$B$8*$B$8 -> 4341.0938 | W22: 7.5 | X22: =W22*V22*U22 -> 4883.7305 | Y22: 0 | Z22: =SUM(X22:Y22) -> 4883.7305 | AA22: =F22+L22+R22+X22 -> 25600.605 | AB22: =G22+M22+S22+Y22 -> 0 | AC22: =SUM(AA22:AB22) -> 25600.605
A23: Communications Officer | B23: 0.15 | C23: =25000/12 -> 2083.3333 | D23: 9 | E23: /months | F23: =D23*C23*B23 -> 2812.5 | G23: 0 | H23: =SUM(F23:G23) -> 2812.5 | I23: =+B23 -> 0.15 | J23: =C23*$B$8 -> 2187.5 | K23: 12 | L23: =J23*K23*I23 -> 3937.5 | M23: 0 | N23: =SUM(L23:M23) -> 3937.5 | O23: =+B23 -> 0.15 | P23: =C23*$B$8*$B$8 -> 2296.875 | Q23: 12 | R23: =Q23*P23*O23 -> 4134.375 | S23: 0 | T23: =SUM(R23:S23) -> 4134.375 | U23: =+B23 -> 0.15 | V23: =C23*$B$8*$B$8*$B$8 -> 2411.7188 | W23: 6 | X23: =W23*V23*U23 -> 2170.5469 | Y23: 0 | Z23: =SUM(X23:Y23) -> 2170.5469 | AA23: =F23+L23+R23+X23 -> 13054.922 | AB23: =G23+M23+S23+Y23 -> 0 | AC23: =SUM(AA23:AB23) -> 13054.922
A24: Accountant | B24: 1 | C24: =21000/12 -> 1750 | D24: 9 | E24: /months | F24: =D24*C24*B24 -> 15750 | G24: 0 | H24: =SUM(F24:G24) -> 15750 | I24: =+B24 -> 1 | J24: =C24*$B$8 -> 1837.5 | K24: 12 | L24: =J24*K24*I24 -> 22050 | M24: 0 | N24: =SUM(L24:M24) -> 22050 | O24: =+B24 -> 1 | P24: =C24*$B$8*$B$8 -> 1929.375 | Q24: 12 | R24: =Q24*P24*O24 -> 23152.5 | S24: 0 | T24: =SUM(R24:S24) -> 23152.5 | U24: =+B24 -> 1 | V24: =C24*$B$8*$B$8*$B$8 -> 2025.8438 | W24: 6 | X24: =W24*V24*U24 -> 12155.062 | Y24: 0 | Z24: =SUM(X24:Y24) -> 12155.062 | AA24: =F24+L24+R24+X24 -> 73107.562 | AB24: =G24+M24+S24+Y24 -> 0 | AC24: =SUM(AA24:AB24) -> 73107.562
A25: M&E Director | B25: 0.15 | C25: =45000/12 -> 3750 | D25: 11 | E25: /months | F25: =D25*C25*B25 -> 6187.5 | G25: 0 | H25: =SUM(F25:G25) -> 6187.5 | I25: =+B25 -> 0.15 | J25: =C25*$B$8 -> 3937.5 | K25: 12 | L25: =J25*K25*I25 -> 7087.5 | M25: 0 | N25: =SUM(L25:M25) -> 7087.5 | O25: =+B25 -> 0.15 | P25: =C25*$B$8*$B$8 -> 4134.375 | Q25: 12 | R25: =Q25*P25*O25 -> 7441.875 | S25: 0 | T25: =SUM(R25:S25) -> 7441.875 | U25: =+B25 -> 0.15 | V25: =C25*$B$8*$B$8*$B$8 -> 4341.0938 | W25: 7.5 | X25: =W25*V25*U25 -> 4883.7305 | Y25: 0 | Z25: =SUM(X25:Y25) -> 4883.7305 | AA25: =F25+L25+R25+X25 -> 25600.605 | AB25: =G25+M25+S25+Y25 -> 0 | AC25: =SUM(AA25:AB25) -> 25600.605
A26: M&E Assistant | B26: 1 | C26: =20000/12 -> 1666.6667 | D26: 9 | E26: /months | F26: =D26*C26*B26 -> 15000 | G26: 0 | H26: =SUM(F26:G26) -> 15000 | I26: =+B26 -> 1 | J26: =C26*$B$8 -> 1750 | K26: 12 | L26: =J26*K26*I26 -> 21000 | M26: 0 | N26: =SUM(L26:M26) -> 21000 | O26: =+B26 -> 1 | P26: =C26*$B$8*$B$8 -> 1837.5 | Q26: 12 | R26: =Q26*P26*O26 -> 22050 | S26: 0 | T26: =SUM(R26:S26) -> 22050 | U26: =+B26 -> 1 | V26: =C26*$B$8*$B$8*$B$8 -> 1929.375 | W26: 7 | X26: =W26*V26*U26 -> 13505.625 | Y26: 0 | Z26: =SUM(X26:Y26) -> 13505.625 | AA26: =F26+L26+R26+X26 -> 71555.625 | AB26: =G26+M26+S26+Y26 -> 0 | AC26: =SUM(AA26:AB26) -> 71555.625
A27: Subtotal Field Personnel | F27: =SUM(F21:F26) -> 91770.833 | G27: =SUM(G21:G26) -> 0 | H27: =SUM(H21:H26) -> 91770.833 | L27: =SUM(L21:L26) -> 113662.5 | M27: =SUM(M21:M26) -> 0 | N27: =SUM(N21:N26) -> 113662.5 | R27: =SUM(R21:R26) -> 119345.63 | S27: =SUM(S21:S26) -> 0 | T27: =SUM(T21:T26) -> 119345.63 | X27: =SUM(X21:X26) -> 73774.477 | Y27: =SUM(Y21:Y26) -> 0 | Z27: =SUM(Z21:Z26) -> 73774.477 | AA27: =SUM(AA21:AA26) -> 398553.43 | AB27: =SUM(AB21:AB26) -> 0 | AC27: =SUM(AA27:AB27) -> 398553.43
A29: Personnel Total | F29: =F27+F18 -> 139520.83 | G29: =G27+G18 -> 0 | H29: =H27+H18 -> 139520.83 | L29: =L27+L18 -> 163800 | M29: =M27+M18 -> 0 | N29: =N27+N18 -> 163800 | R29: =R27+R18 -> 171990 | S29: =S27+S18 -> 0 | T29: =T27+T18 -> 171990 | X29: =X27+X18 -> 108322.35 | Y29: =Y27+Y18 -> 0 | Z29: =Z27+Z18 -> 108322.35 | AA29: =AA27+AA18 -> 583633.18 | AB29: =AB27+AB18 -> 0 | AC29: =AC27+AC18 -> 583633.18
A31: Fringe Benefits
A32: HQ Fringe Benefits | B32: LOE
A33: Fringe Benefits - Headquarters | B33: 0.2347 | F33: =(F18)*$B$33 -> 11206.925 | G33: 0 | H33: =SUM(F33:G33) -> 11206.925 | L33: =(L18)*$B$33 -> 11767.271 | M33: 0 | N33: =SUM(L33:M33) -> 11767.271 | R33: =(R18)*$B$33 -> 12355.635 | S33: 0 | T33: =SUM(R33:S33) -> 12355.635 | X33: =(X18)*$B$33 -> 8108.3853 | Y33: 0 | Z33: =SUM(X33:Y33) -> 8108.3853 | AA33: =F33+L33+R33+X33 -> 43438.216 | AB33: =G33+M33+S33+Y33 -> 0 | AC33: =SUM(AA33:AB33) -> 43438.216
A34: Subtotal HQ Fringe Benefits | F34: =SUM(F33:F33) -> 11206.925 | G34: =SUM(G33:G33) -> 0 | H34: =SUM(H33:H33) -> 11206.925 | L34: =SUM(L33:L33) -> 11767.271 | M34: =SUM(M33:M33) -> 0 | N34: =SUM(N33:N33) -> 11767.271 | R34: =SUM(R33:R33) -> 12355.635 | S34: =SUM(S33:S33) -> 0 | T34: =SUM(T33:T33) -> 12355.635 | X34: =SUM(X33:X33) -> 8108.3853 | Y34: =SUM(Y33:Y33) -> 0 | Z34: =SUM(Z33:Z33) -> 8108.3853 | AA34: =SUM(AA33:AA33) -> 43438.216 | AB34: =SUM(AB33:AB33) -> 0 | AC34: =SUM(AC33:AC33) -> 43438.216
A36: Field Fringe Benefits
A37: Fringe Benefits CCN - Colombia (above $3,100 monthly) | B37: 0.53864 | F37: =(F21+F22+F25)*$B$37 -> 31353.337 | G37: 0 | H37: =SUM(F37:G37) -> 31353.337 | L37: =(L21+L22+L25)*$B$37 -> 35913.822 | M37: 0 | N37: =SUM(L37:M37) -> 35913.822 | R37: =(R21+R22+R25)*$B$37 -> 37709.513 | S37: 0 | T37: =SUM(R37:S37) -> 37709.513 | X37: =(X21+X22+X25)*$B$37 -> 24746.868 | Y37: 0 | Z37: =SUM(X37:Y37) -> 24746.868 | AA37: =F37+L37+R37+X37 -> 129723.54 | AB37: =G37+M37+S37+Y37 -> 0 | AC37: =SUM(AA37:AB37) -> 129723.54
A38: Fringe Benefits CCN - Colombia (below $3,100 monthly) | B38: 0.40364 | F38: =(F24+F26+F23)*$B$38 -> 13547.167 | G38: 0 | H38: =SUM(F38:G38) -> 13547.167 | L38: =(L24+L26+L23)*$B$38 -> 18966.035 | M38: 0 | N38: =SUM(L38:M38) -> 18966.035 | R38: =(R24+R26+R23)*$B$38 -> 19914.336 | S38: 0 | T38: =SUM(R38:S38) -> 19914.336 | X38: =(X24+X26+X23)*$B$38 -> 11233.799 | Y38: 0 | Z38: =SUM(X38:Y38) -> 11233.799 | AA38: =F38+L38+R38+X38 -> 63661.338 | AB38: =G38+M38+S38+Y38 -> 0 | AC38: =SUM(AA38:AB38) -> 63661.338
A39: Subtotal Field Fringe Benefits | F39: =SUM(F37:F38) -> 44900.504 | G39: =SUM(G37:G38) -> 0 | H39: =SUM(H37:H38) -> 44900.504 | L39: =SUM(L37:L38) -> 54879.857 | M39: =SUM(M37:M38) -> 0 | N39: =SUM(N37:N38) -> 54879.857 | R39: =SUM(R37:R38) -> 57623.849 | S39: =SUM(S37:S38) -> 0 | T39: =SUM(T37:T38) -> 57623.849 | X39: =SUM(X37:X38) -> 35980.667 | Y39: =SUM(Y37:Y38) -> 0 | Z39: =SUM(Z37:Z38) -> 35980.667 | AA39: =SUM(AA37:AA38) -> 193384.88 | AB39: =SUM(AB37:AB38) -> 0 | AC39: =SUM(AC37:AC38) -> 193384.88
A41: Fringe Benefits Total | F41: =F39+F34 -> 56107.429 | G41: =G39+G34 -> 0 | H41: =H39+H34 -> 56107.429 | L41: =L39+L34 -> 66647.128 | M41: =M39+M34 -> 0 | N41: =N39+N34 -> 66647.128 | R41: =R39+R34 -> 69979.484 | S41: =S39+S34 -> 0 | T41: =T39+T34 -> 69979.484 | X41: =X39+X34 -> 44089.053 | Y41: =Y39+Y34 -> 0 | Z41: =Z39+Z34 -> 44089.053 | AA41: =AA39+AA34 -> 236823.09 | AB41: =AB39+AB34 -> 0 | AC41: =AC39+AC34 -> 236823.09
A43: Travel
A45: HQ Travel
A46: T.1 Project Management Travel to Field
A47: International Airfare to Colombia | B47: 2 | C47: 800 | D47: 1 | E47: /trip | F47: =D47*C47*B47 -> 1600 | G47: 0 | H47: =SUM(F47:G47) -> 1600 | I47: 2 | J47: =C47*$B$6 -> 816 | K47: 1 | L47: =I47*J47*K47 -> 1632 | M47: 0 | N47: =SUM(L47:M47) -> 1632 | O47: 2 | P47: =C47*$B$6*$B$6 -> 832.32 | Q47: 1 | R47: =O47*P47*Q47 -> 1664.64 | S47: 0 | T47: =SUM(R47:S47) -> 1664.64 | U47: 2 | V47: =C47*$B$6*$B$6*$B$6 -> 848.9664 | W47: 1 | X47: =U47*V47*W47 -> 1697.9328 | Y47: 0 | Z47: =SUM(X47:Y47) -> 1697.9328 | AA47: =F47+L47+R47+X47 -> 6594.5728 | AB47: =G47+M47+S47+Y47 -> 0 | AC47: =SUM(AA47:AB47) -> 6594.5728
A48: Meals and Incidentals | B48: =$B$47 -> 2 | C48: 90 | D48: 10 | E48: /day | F48: =D48*C48*B48 -> 1800 | G48: 0 | H48: =SUM(F48:G48) -> 1800 | I48: =$I$47 -> 2 | J48: =C48*$B$6 -> 91.8 | K48: 10 | L48: =I48*J48*K48 -> 1836 | M48: 0 | N48: =SUM(L48:M48) -> 1836 | O48: =$O$47 -> 2 | P48: =C48*$B$6*$B$6 -> 93.636 | Q48: 10 | R48: =O48*P48*Q48 -> 1872.72 | S48: 0 | T48: =SUM(R48:S48) -> 1872.72 | U48: =$U$47 -> 2 | V48: =C48*$B$6*$B$6*$B$6 -> 95.50872 | W48: 10 | X48: =U48*V48*W48 -> 1910.1744 | Y48: 0 | Z48: =SUM(X48:Y48) -> 1910.1744 | AA48: =F48+L48+R48+X48 -> 7418.8944 | AB48: =G48+M48+S48+Y48 -> 0 | AC48: =SUM(AA48:AB48) -> 7418.8944
A49: Lodging | B49: =$B$47 -> 2 | C49: 120 | D49: 10 | E49: /night | F49: =D49*C49*B49 -> 2400 | G49: 0 | H49: =SUM(F49:G49) -> 2400 | I49: =$I$47 -> 2 | J49: =C49*$B$6 -> 122.4 | K49: 10 | L49: =I49*J49*K49 -> 2448 | M49: 0 | N49: =SUM(L49:M49) -> 2448 | O49: =$O$47 -> 2 | P49: =C49*$B$6*$B$6 -> 124.848 | Q49: 10 | R49: =O49*P49*Q49 -> 2496.96 | S49: 0 | T49: =SUM(R49:S49) -> 2496.96 | U49: =$U$47 -> 2 | V49: =C49*$B$6*$B$6*$B$6 -> 127.34496 | W49: 10 | X49: =U49*V49*W49 -> 2546.8992 | Y49: 0 | Z49: =SUM(X49:Y49) -> 2546.8992 | AA49: =F49+L49+R49+X49 -> 9891.8592 | AB49: =G49+M49+S49+Y49 -> 0 | AC49: =SUM(AA49:AB49) -> 9891.8592
...
