Workbook
Name \A: #REF!
Name \A: #REF!
Name \P: #REF!
Name \P: #REF!
Name \S: #REF!
Name _______sho1: '[3]Detailed Budget-SAVE'!#REF!
Name __2DAI_1: #N/A
Name __3FEE: #N/A
Name __AFP1: #N/A
Name __AFP2: #N/A
Name __AFP3: #N/A
Name __AFP4: #N/A
Name __AMP1: #N/A
Name __AMP2: #N/A
Name __AMP3: #N/A
Name __AMP4: #N/A
Name __DAI4: #N/A
Name __EES1: #N/A
Name __EES2: #N/A
Name __EES3: #N/A
Name __EES4: #N/A
Name __EXT1: #N/A
Name __EXT2: #N/A
Name __EXT3: #N/A
Name __EXT4: #N/A
Name __FCP1: #N/A
Name __FCP2: #N/A
Name __FCP3: #N/A
Name __FCP4: #N/A
Name __FRI1: #N/A
Name __FRI4: #N/A
Name __HRA1: #N/A
Name __HRA2: #N/A
Name __HRA3: #N/A
Name __HRA4: #N/A
Name __inf1: #REF!
Name __LT4: [4]Parameters!$B$40
Name __ODC1: #N/A
Name __ODC2: #N/A
Name __POL1: #N/A
Name __POL2: #N/A
Name __POL3: #N/A
Name __POL4: #N/A
Name __TOT1: #N/A
Name __TOT2: #N/A
Name __TRV1: #N/A
Name __TRV2: #N/A
Name _060: #REF!
Name _1_1: #REF!
Name _13th_and_14th_month: [5]Parameters!$D$62
Name _2_1034: #REF!
Name _2DAI_1: #N/A
Name _3_1440: #REF!
Name _3FEE: #N/A
Name _4_2: #REF!
Name _5_3: #REF!
Name _AFP1: #N/A
Name _AFP2: #N/A
Name _AFP3: #N/A
Name _AFP4: #N/A

Sheet USDA Budget Summary
A1: ATTACHMENT C-1
A2: Budget Summary
A4: Program (FFPr or MGD): | B4: FFPr
A5: Country of Operation: | B5: Colombia
A6: Implementing Organization: | B6: Partners of the Americas Inc.
A7: Fiscal Year: | B7: 2024
A8: Agreement Number: | B8: USDA-FAS-10.606-0700-20-(514)
A10: Total Amount of Federal Funds Requested
A11: Funding Source (FAS for MGD) (CCC for FFPr) | B11: Funding Year | C11: Commodity Cost | D11: Freight Cost | E11: Administrative Costs (cash portion) | F11: Total Federal Funding Obligated
B12: 2020 | C12: 21924000 | D12: 9591750 | E12: 2280000 | F12: 33795750
B13: 2024 | C13: 9000000 | D13: 0 | E13: 0 | F13: =E13+D13+C13 -> 9000000
A15: Project Operating Budget
A16: Expense Type | B16: Monetization Proceeds (FFPr Only) | C16: FAS or CCC Funds (CCC is Admin Only) | D16: Cost Share | E16: Total w/out Cost Share | F16: Total w/Cost Share
A17: Administration
A18: Salaries/Personnel | B18: ='Program Budget'!T48-C18 -> 1352931.2 | C18: 430000 | D18: ='Program Budget'!U48 -> 0 | E18: =B18+C18 -> 1782931.2 | F18: =B18+C18+D18 -> 1782931.2
A19: Benefits | B19: ='Program Budget'!T60-C19 -> 735534.89 | C19: 225648 | D19: ='Program Budget'!U60 -> 0 | E19: =B19+C19 -> 961182.89 | F19: =B19+C19+D19 -> 961182.89
A20: Travel | B20: ='Program Budget'!T77-C20 -> 258899.22 | C20: 39104 | D20: ='Program Budget'!U77 -> 0 | E20: =B20+C20 -> 298003.22 | F20: =B20+C20+D20 -> 298003.22
A21: Professional Services/Contractual | B21: ='Program Budget'!T101-C21 -> 1563376.9 | C21: 862147.25 | D21: ='Program Budget'!U101 -> 0 | E21: =B21+C21 -> 2425524.1 | F21: =B21+C21+D21 -> 2425524.1
A22: Equipment | B22: ='Program Budget'!T106-C22 -> 0 | C22: 72554.43 | D22: ='Program Budget'!U106 -> 0 | E22: =B22+C22 -> 72554.43 | F22: =B22+C22+D22 -> 72554.43
A23: Office | B23: ='Program Budget'!T118-C23 -> 448367.27 | C23: 81389.57 | D23: ='Program Budget'!U118 -> 0 | E23: =B23+C23 -> 529756.84 | F23: =B23+C23+D23 -> 529756.84
A24: Supplies | B24: ='Program Budget'!T129-C24 -> 159456.88 | C24: 41096 | D24: ='Program Budget'!U129 -> 0 | E24: =B24+C24 -> 200552.88 | F24: =B24+C24+D24 -> 200552.88
A25: Other | B25: ='Program Budget'!T141-C25 -> 64958.728 | C25: 19760 | D25: ='Program Budget'!U141 -> 0 | E25: =B25+C25 -> 84718.728 | F25: =B25+C25+D25 -> 84718.728
A26: Total Administration | B26: =SUM(B18:B25) -> 4583525.1 | C26: =SUM(C18:C25) -> 1771699.2 | D26: =SUM(D18:D25) -> 0 | E26: =SUM(E18:E25) -> 6355224.3 | F26: =SUM(F18:F25) -> 6355224.3
A28: Activities
A29: Activity 1: Value Chain Development (Value Chain Analysis, Carbon Assessment, and Living Incomes) | B29: ='Program Budget'!T195 -> 272696.75 | C29: 0 | D29: ='Program Budget'!U195 -> 0 | E29: =B29+C29 -> 272696.75 | F29: =B29+C29+D29 -> 272696.75
A30: Activity 2: Producer Organization Development & Commercialization | B30: ='Program Budget'!T272 -> 2209930.1 | C30: 0 | D30: ='Program Budget'!U272 -> 312219.19 | E30: =B30+C30 -> 2209930.1 | F30: =B30+C30+D30 -> 2522149.3
A31: Activity 3: Agriculture Extension and Production Support | B31: ='Program Budget'!T369 -> 7469424.7 | C31: 0 | D31: ='Program Budget'!U369 -> 939590.56 | E31: =B31+C31 -> 7469424.7 | F31: =B31+C31+D31 -> 8409015.3
A32: Activity 4: Post-Harvest Aggregation & Processing | B32: ='Program Budget'!T442 -> 1992268.2 | C32: 0 | D32: ='Program Budget'!U442 -> 141928.5 | E32: =B32+C32 -> 1992268.2 | F32: =B32+C32+D32 -> 2134196.7
A33: Activity 5: Ensure Financial Service/ Capital Access for Actors in the Value Chains | B33: ='Program Budget'!T516 -> 1105173.6 | C33: 0 | D33: ='Program Budget'!U516 -> 584189.75 | E33: =B33+C33 -> 1105173.6 | F33: =B33+C33+D33 -> 1689363.4
A34: Activity 6: Innovation and Job Creation Through Youth Engagement | B34: ='Program Budget'!T596 -> 819624.4 | C34: 0 | D34: ='Program Budget'!U596 -> 0 | E34: =B34+C34 -> 819624.4 | F34: =B34+C34+D34 -> 819624.4
A35: Activity 7: Establishment of Regional Community of Practice | B35: ='Program Budget'!T666 -> 1274251 | C35: 0 | D35: ='Program Budget'!U666 -> 0 | E35: =B35+C35 -> 1274251 | F35: =B35+C35+D35 -> 1274251
A36: Activity 8: Financial Services: Endowment Establishment, Fundraising and Management | B36: ='Program Budget'!T729 -> 3539784.8 | C36: 0 | D36: ='Program Budget'!U729 -> 0 | E36: =B36+C36 -> 3539784.8 | F36: =B36+C36+D36 -> 3539784.8
A37: Total Activities | B37: =SUM(B29:B36) -> 18683154 | C37: =SUM(C29:C36) -> 0 | D37: =SUM(D29:D36) -> 1977928 | E37: =SUM(E29:E36) -> 18683154 | F37: =SUM(F29:F36) -> 20661082
A39: Commodity and Food Purchases (N/A to FFPr)
A40: Commodity Procurement | B40: 0 | C40: 0 | D40: 0 | E40: =B40+C40 -> 0 | F40: =B40+C40+D40 -> 0
A41: Food Vouchers (N/A to MGD)
A42: Cash Transfers (N/A to MGD)
A43: Total Commodity Procurement | B43: =SUM(B40:B42) -> 0 | C43: =SUM(C40:C42) -> 0 | D43: =SUM(D40:D42) -> 0 | E43: =SUM(E40:E42) -> 0 | F43: =SUM(F40:F42) -> 0
A45: ITSH (N/A to FFPr)
A46: Salaries | B46: 0 | C46: 0 | D46: 0 | E46: =B46+C46 -> 0 | F46: =B46+C46+D46 -> 0
...

Sheet Program Budget
D1: Partners of the Americas – Food for Progress Colombia
D2: NOFO: USDA-FAS-10.606-0700-20-(514) [Original], USDA-FAS-10606-0700-Merit2024 [Merit Extension]
D3: Duration: 7.5 Years
D4: Country: Colombia
D5: Budget Assumptions:
A6: Entity: | B6: P | D6: Inflation - US Based Goods/Services | E6: 1.03
A7: Program-Dept.: | B7: 30100 | D7: Inflation - Locally Purchased Goods/Services | E7: 1.04
A8: Funder-Grant: | B8: USDA700 | D8: Merit Based Increases for HQ & Field Staff | E8: 1.05
A10: Activity (Budget Code) | B10: Account Code | C10: Country Code (USA or COL2) | D10: BUDGET ITEM | E10: Year 1 - 4 Total inception through 09/30/2024 | F10: UNIT | G10: RATE/ UNIT | H10: Level of Effort (LOE) Year 5 | I10: # of Units | J10: Year 5 (10/1/24 - 9/30/25) | K10: Level of Effort (LOE) Year 6 | L10: # of Units | M10: Year 6 (10/1/25 - 09/30/26) | N10: Level of Effort (LOE) Year 7 | O10: # of Units | P10: Year 7 (10/1/26 - 09/30/27) | Q10: Level of Effort (LOE) Year 8 | R10: # of Units | S10: Year 8 (10/1/27 - 3/31/28) | T10: TOTAL USDA | U10: TOTAL COST SHARE | V10: PROJECT GRAND TOTAL
D11: Salaries/Personnel (Administration)
D12: CCN Colombia Field Staff (LOE)
A13: PERSNL | B13: 50000 | C13: USA | D13: Key Personnel: Chief of Party | E13: 225257 | F13: Month | G13: =171000/12 -> 14250 | H13: ='LOE Breakdown by Year'!D11 -> 0.1 | I13: 12 | J13: =I13*G13*H13 -> 17100 | K13: ='LOE Breakdown by Year'!D51 -> 0.05 | L13: 12 | M13: =L13*G13*$K13*$E$8 -> 8977.5 | N13: ='LOE Breakdown by Year'!D91 -> 0.05 | O13: 12 | P13: =O13*G13*$N13*$E$8*$E$8 -> 9426.375 | Q13: ='LOE Breakdown by Year'!D131 -> 0.05 | R13: 0 | S13: =R13*G13*$Q13*$E$8*$E$8*$E$8 -> 0 | T13: =SUM(P13,M13,J13,E13,S13) -> 260760.88 | U13: 0 | V13: =SUM(T13:U13) -> 260760.88
A14: PERSNL | B14: 70000 | C14: COL2 | D14: Deputy Chief of Party / Value Chain Strengthening Director | F14: Month | G14: =60000/12 -> 5000 | H14: ='LOE Breakdown by Year'!D12 -> 0.1 | I14: 12 | J14: =I14*G14*H14 -> 6000 | K14: ='LOE Breakdown by Year'!D52 -> 0.25 | L14: 12 | M14: =L14*G14*$K14*$E$8 -> 15750 | N14: ='LOE Breakdown by Year'!D92 -> 0.25 | O14: 12 | P14: =O14*G14*$N14*$E$8*$E$8 -> 16537.5 | Q14: ='LOE Breakdown by Year'!D132 -> 0.25 | R14: 6 | S14: =R14*G14*$Q14*$E$8*$E$8*$E$8 -> 8682.1875 | T14: =SUM(P14,M14,J14,E14,S14) -> 46969.688 | U14: 0 | V14: =SUM(T14:U14) -> 46969.688
A15: PERSNL | B15: 70000 | C15: COL2 | D15: Key Personnel: Technical Director | E15: 0 | F15: Month | G15: =55000/12 -> 4583.3333 | H15: ='LOE Breakdown by Year'!D13 -> 0.05 | I15: 12 | J15: =I15*G15*H15 -> 2750 | K15: ='LOE Breakdown by Year'!D53 -> 0.05 | L15: 12 | M15: =L15*G15*$K15*$E$8 -> 2887.5 | N15: ='LOE Breakdown by Year'!D93 -> 0.05 | O15: 12 | P15: =O15*G15*$N15*$E$8*$E$8 -> 3031.875 | Q15: ='LOE Breakdown by Year'!D133 -> 0.05 | R15: 5 | S15: =R15*G15*$Q15*$E$8*$E$8*$E$8 -> 1326.4453 | T15: =SUM(P15,M15,J15,E15,S15) -> 9995.8203 | U15: 0 | V15: =SUM(T15:U15) -> 9995.8203
A16: PERSNL | B16: 70000 | C16: COL2 | D16: Activity Lead Agribusiness Senior Specialist (Cacao) | E16: 0 | F16: Month | G16: =34000/12 -> 2833.3333 | H16: ='LOE Breakdown by Year'!D14 -> 0.1 | I16: 12 | J16: =I16*G16*H16 -> 3400 | K16: ='LOE Breakdown by Year'!D54 -> 0 | L16: 12 | M16: =L16*G16*$K16*$E$8 -> 0 | N16: ='LOE Breakdown by Year'!D94 -> 0 | O16: 12 | P16: =O16*G16*$N16*$E$8*$E$8 -> 0 | Q16: ='LOE Breakdown by Year'!D134 -> 0 | R16: 2 | S16: =R16*G16*$Q16*$E$8*$E$8*$E$8 -> 0 | T16: =SUM(P16,M16,J16,E16,S16) -> 3400 | U16: 0 | V16: =SUM(T16:U16) -> 3400
A17: PERSNL | B17: 70000 | C17: COL2 | D17: Cacao Field Officer | F17: Month | G17: =16000/12 -> 1333.3333 | H17: ='LOE Breakdown by Year'!D15 -> 0 | I17: 12 | J17: =I17*G17*H17 -> 0 | K17: ='LOE Breakdown by Year'!D55 -> 0 | L17: 12 | M17: =L17*G17*$K17*$E$8 -> 0 | N17: ='LOE Breakdown by Year'!D95 -> 0 | O17: 12 | P17: =O17*G17*$N17*$E$8*$E$8 -> 0 | Q17: ='LOE Breakdown by Year'!D135 -> 0 | R17: 0 | S17: =R17*G17*$Q17*$E$8*$E$8*$E$8 -> 0 | T17: =SUM(P17,M17,J17,E17,S17) -> 0 | U17: 0 | V17: =SUM(T17:U17) -> 0
A18: PERSNL | B18: 70000 | C18: COL2 | D18: Cacao & Complementary Crop Technical Field Leader (2) | F18: Month | G18: =(21000/12)*2 -> 3500 | H18: ='LOE Breakdown by Year'!D16 -> 0 | I18: 6 | J18: =I18*G18*H18 -> 0 | K18: ='LOE Breakdown by Year'!D56 -> 0 | L18: 12 | M18: =L18*G18*$K18*$E$8 -> 0 | N18: ='LOE Breakdown by Year'!D96 -> 0 | O18: 12 | P18: =O18*G18*$N18*$E$8*$E$8 -> 0 | Q18: ='LOE Breakdown by Year'!D136 -> 0 | R18: 0 | S18: =R18*G18*$Q18*$E$8*$E$8*$E$8 -> 0 | T18: =SUM(P18,M18,J18,E18,S18) -> 0 | U18: 0 | V18: =SUM(T18:U18) -> 0
A19: PERSNL | B19: 70000 | C19: COL2 | D19: Extension Agents (45 in Y5 and 25 in Y6) | E19: 0 | F19: Month | G19: =1000 -> 1000 | H19: ='LOE Breakdown by Year'!D17 -> 0 | I19: 12 | J19: =I19*(G19*45)*H19 -> 0 | K19: ='LOE Breakdown by Year'!D57 -> 0 | L19: 12 | M19: =L19*((G19*25))*$K19*$E$8 -> 0 | N19: ='LOE Breakdown by Year'!D97 -> 0 | O19: 0 | P19: =O19*(G19*0)*$N19*$E$8*$E$8 -> 0 | Q19: ='LOE Breakdown by Year'!D137 -> 0 | R19: 0 | S19: =R19*G19*$Q19*$E$8*$E$8*$E$8 -> 0 | T19: =SUM(P19,M19,J19,E19,S19) -> 0 | U19: 0 | V19: =SUM(T19:U19) -> 0
A20: PERSNL | B20: 70000 | C20: COL2 | D20: Activity Lead Agribusiness Senior Specialist (Complementary Crop) | E20: 0 | F20: Month | G20: =34000/12 -> 2833.3333 | H20: ='LOE Breakdown by Year'!D18 -> 0 | I20: 12 | J20: =I20*G20*H20 -> 0 | K20: ='LOE Breakdown by Year'!D58 -> 0 | L20: 12 | M20: =L20*G20*$K20*$E$8 -> 0 | N20: ='LOE Breakdown by Year'!D98 -> 0 | O20: 12 | P20: =O20*G20*$N20*$E$8*$E$8 -> 0 | Q20: ='LOE Breakdown by Year'!D138 -> 0 | R20: 0 | S20: =R20*G20*$Q20*$E$8*$E$8*$E$8 -> 0 | T20: =SUM(P20,M20,J20,E20,S20) -> 0 | U20: 0 | V20: =SUM(T20:U20) -> 0
A21: PERSNL | B21: 70000 | C21: COL2 | D21: Complementary Crops Field Officer | F21: Month | G21: =0/12 -> 0 | H21: ='LOE Breakdown by Year'!D19 -> 0 | I21: 0 | J21: =I21*G21*H21 -> 0 | K21: ='LOE Breakdown by Year'!D59 -> 0 | L21: 12 | M21: =L21*G21*$K21*$E$8 -> 0 | N21: ='LOE Breakdown by Year'!D99 -> 0 | O21: 12 | P21: =O21*G21*$N21*$E$8*$E$8 -> 0 | Q21: ='LOE Breakdown by Year'!D139 -> 0 | R21: 0 | S21: =R21*G21*$Q21*$E$8*$E$8*$E$8 -> 0 | T21: =SUM(P21,M21,J21,E21,S21) -> 0 | U21: 0 | V21: =SUM(T21:U21) -> 0
A22: PERSNL | B22: 70000 | C22: COL2 | D22: EPSEAS Specialist | E22: 0 | F22: Month | G22: =0/12 -> 0 | H22: ='LOE Breakdown by Year'!D20 -> 0 | I22: 0 | J22: =I22*G22*H22 -> 0 | K22: ='LOE Breakdown by Year'!D60 -> 0 | L22: 12 | M22: =L22*G22*$K22*$E$8 -> 0 | N22: ='LOE Breakdown by Year'!D100 -> 0 | O22: 12 | P22: =O22*G22*$N22*$E$8*$E$8 -> 0 | Q22: ='LOE Breakdown by Year'!D140 -> 0 | R22: 0 | S22: =R22*G22*$Q22*$E$8*$E$8*$E$8 -> 0 | T22: =SUM(P22,M22,J22,E22,S22) -> 0 | U22: 0 | V22: =SUM(T22:U22) -> 0
A23: PERSNL | B23: 70000 | C23: COL2 | D23: Extension Agents for EPSEAS (20 in Y6 and 25 in Y7) | E23: 0 | F23: Month | G23: 1000 | H23: ='LOE Breakdown by Year'!D21 -> 0 | I23: 0 | J23: =I23*G23*H23 -> 0 | K23: ='LOE Breakdown by Year'!D61 -> 0 | L23: 12 | M23: =L23*((1000*20))*$K23*$E$8 -> 0 | N23: ='LOE Breakdown by Year'!D101 -> 0 | O23: 12 | P23: =O23*G23*$N23*$E$8*$E$8 -> 0 | Q23: ='LOE Breakdown by Year'!D141 -> 0 | R23: 0 | S23: =R23*G23*$Q23*$E$8*$E$8*$E$8 -> 0 | T23: =SUM(P23,M23,J23,E23,S23) -> 0 | U23: 0 | V23: =SUM(T23:U23) -> 0
A24: PERSNL | B24: 70000 | C24: COL2 | D24: Senior M&E Director | E24: 28275.7 | F24: Month | G24: =75000/12 -> 6250 | H24: ='LOE Breakdown by Year'!D22 -> 0.1 | I24: 12 | J24: =I24*G24*H24 -> 7500 | K24: ='LOE Breakdown by Year'!D62 -> 0.05 | L24: 12 | M24: =L24*G24*$K24*$E$8 -> 3937.5 | N24: ='LOE Breakdown by Year'!D102 -> 0.05 | O24: 12 | P24: =O24*G24*$N24*$E$8*$E$8 -> 4134.375 | Q24: ='LOE Breakdown by Year'!D142 -> 0.05 | R24: 6 | S24: =R24*G24*$Q24*$E$8*$E$8*$E$8 -> 2170.5469 | T24: =SUM(P24,M24,J24,E24,S24) -> 46018.122 | U24: 0 | V24: =SUM(T24:U24) -> 46018.122
A25: PERSNL | B25: 70000 | C25: COL2 | D25: Senior M&E Specialist | E25: 24675.7 | F25: Month | G25: =34000/12 -> 2833.3333 | H25: ='LOE Breakdown by Year'!D23 -> 0.1 | I25: 12 | J25: =I25*G25*H25 -> 3400 | K25: ='LOE Breakdown by Year'!D63 -> 0.05 | L25: 12 | M25: =L25*G25*$K25*$E$8 -> 1785 | N25: ='LOE Breakdown by Year'!D103 -> 0.05 | O25: 12 | P25: =O25*G25*$N25*$E$8*$E$8 -> 1874.25 | Q25: ='LOE Breakdown by Year'!D143 -> 0.05 | R25: 6 | S25: =R25*G25*$Q25*$E$8*$E$8*$E$8 -> 983.98125 | T25: =SUM(P25,M25,J25,E25,S25) -> 32718.931 | U25: 0 | V25: =SUM(T25:U25) -> 32718.931
A26: PERSNL | B26: 70000 | C26: COL2 | D26: M&E Specialist | E26: 22491.26 | F26: Month | G26: =30000/12 -> 2500 | H26: ='LOE Breakdown by Year'!D24 -> 0.1 | I26: 12 | J26: =I26*G26*H26 -> 3000 | K26: ='LOE Breakdown by Year'!D64 -> 0.05 | L26: 12 | M26: =L26*G26*$K26*$E$8 -> 1575 | N26: ='LOE Breakdown by Year'!D104 -> 0.05 | O26: 12 | P26: =O26*G26*$N26*$E$8*$E$8 -> 1653.75 | Q26: ='LOE Breakdown by Year'!D144 -> 0.05 | R26: 3 | S26: =R26*G26*$Q26*$E$8*$E$8*$E$8 -> 434.10938 | T26: =SUM(P26,M26,J26,E26,S26) -> 29154.119 | U26: 0 | V26: =SUM(T26:U26) -> 29154.119
A27: PERSNL | B27: 70000 | C27: COL2 | D27: M&E Officer | E27: 30491.26 | F27: Month | G27: =12000/12 -> 1000 | H27: ='LOE Breakdown by Year'!D25 -> 0.1 | I27: 12 | J27: =I27*G27*H27 -> 1200 | K27: ='LOE Breakdown by Year'!D65 -> 0.05 | L27: 12 | M27: =L27*G27*$K27*$E$8 -> 630 | N27: ='LOE Breakdown by Year'!D105 -> 0.05 | O27: 12 | P27: =O27*G27*$N27*$E$8*$E$8 -> 661.5 | Q27: ='LOE Breakdown by Year'!D145 -> 0.05 | R27: 3 | S27: =R27*G27*$Q27*$E$8*$E$8*$E$8 -> 173.64375 | T27: =SUM(P27,M27,J27,E27,S27) -> 33156.404 | U27: 0 | V27: =SUM(T27:U27) -> 33156.404
A28: PERSNL | B28: 70000 | C28: COL2 | D28: Partnerships and Investment Director | E28: 36550 | F28: Month | G28: =55000/12 -> 4583.3333 | H28: ='LOE Breakdown by Year'!D26 -> 0.1 | I28: 12 | J28: =I28*G28*H28 -> 5500 | K28: ='LOE Breakdown by Year'!D66 -> 0.05 | L28: 12 | M28: =L28*G28*$K28*$E$8 -> 2887.5 | N28: ='LOE Breakdown by Year'!D106 -> 0.05 | O28: 12 | P28: =O28*G28*$N28*$E$8*$E$8 -> 3031.875 | Q28: ='LOE Breakdown by Year'!D146 -> 0.05 | R28: 0 | S28: =R28*G28*$Q28*$E$8*$E$8*$E$8 -> 0 | T28: =SUM(P28,M28,J28,E28,S28) -> 47969.375 | U28: 0 | V28: =SUM(T28:U28) -> 47969.375
A29: PERSNL | B29: 70000 | C29: COL2 | D29: Partnerships and Investment Specialist | E29: 0 | F29: Month | G29: =21000/12 -> 1750 | H29: ='LOE Breakdown by Year'!D27 -> 0.1 | I29: 12 | J29: =I29*G29*H29 -> 2100 | K29: ='LOE Breakdown by Year'!D67 -> 0 | L29: 12 | M29: =L29*G29*$K29*$E$8 -> 0 | N29: ='LOE Breakdown by Year'!D107 -> 0 | O29: 12 | P29: =O29*G29*$N29*$E$8*$E$8 -> 0 | Q29: ='LOE Breakdown by Year'!D147 -> 0 | R29: 0 | S29: =R29*G29*$Q29*$E$8*$E$8*$E$8 -> 0 | T29: =SUM(P29,M29,J29,E29,S29) -> 2100 | U29: 0 | V29: =SUM(T29:U29) -> 2100
A30: PERSNL | B30: 70000 | C30: COL2 | D30: Organizational Strengthening Specialist | E30: 0 | F30: Month | G30: =21000/12 -> 1750 | H30: ='LOE Breakdown by Year'!D28 -> 0.1 | I30: 12 | J30: =I30*G30*H30 -> 2100 | K30: ='LOE Breakdown by Year'!D68 -> 0 | L30: 12 | M30: =L30*G30*$K30*$E$8 -> 0 | N30: ='LOE Breakdown by Year'!D108 -> 0 | O30: 12 | P30: =O30*G30*$N30*$E$8*$E$8 -> 0 | Q30: ='LOE Breakdown by Year'!D148 -> 0 | R30: 0 | S30: =R30*G30*$Q30*$E$8*$E$8*$E$8 -> 0 | T30: =SUM(P30,M30,J30,E30,S30) -> 2100 | U30: 0 | V30: =SUM(T30:U30) -> 2100
A31: PERSNL | B31: 70000 | C31: COL2 | D31: Value Chain Strengthening Director | E31: 0 | F31: Month | G31: =0/12 -> 0 | H31: ='LOE Breakdown by Year'!D29 -> 0.1 | I31: 12 | J31: =I31*G31*H31 -> 0 | K31: ='LOE Breakdown by Year'!D69 -> 0.05 | L31: 12 | M31: =L31*G31*$K31*$E$8 -> 0 | N31: ='LOE Breakdown by Year'!D109 -> 0.05 | O31: 12 | P31: =O31*G31*$N31*$E$8*$E$8 -> 0 | Q31: ='LOE Breakdown by Year'!D149 -> 0.05 | R31: 4 | S31: =R31*G31*$Q31*$E$8*$E$8*$E$8 -> 0 | T31: =SUM(P31,M31,J31,E31,S31) -> 0 | U31: 0 | V31: =SUM(T31:U31) -> 0
A32: PERSNL | B32: 70000 | C32: COL2 | D32: Communications Specialist | E32: 0 | F32: Month | G32: =21000/12 -> 1750 | H32: ='LOE Breakdown by Year'!D30 -> 0.1 | I32: 12 | J32: =I32*G32*H32 -> 2100 | K32: ='LOE Breakdown by Year'!D70 -> 0.1 | L32: 12 | M32: =L32*G32*$K32*$E$8 -> 2205 | N32: ='LOE Breakdown by Year'!D110 -> 0.1 | O32: 12 | P32: =O32*G32*$N32*$E$8*$E$8 -> 2315.25 | Q32: ='LOE Breakdown by Year'!D150 -> 0.1 | R32: 0 | S32: =R32*G32*$Q32*$E$8*$E$8*$E$8 -> 0 | T32: =SUM(P32,M32,J32,E32,S32) -> 6620.25 | U32: 0 | V32: =SUM(T32:U32) -> 6620.25
A33: PERSNL | B33: 70000 | C33: COL2 | D33: Value Chain Specialist | E33: 0 | F33: Month | G33: =30000/12 -> 2500 | H33: ='LOE Breakdown by Year'!D31 -> 0.1 | I33: 12 | J33: =I33*G33*H33 -> 3000 | K33: ='LOE Breakdown by Year'!D71 -> 0 | L33: 12 | M33: =L33*G33*$K33*$E$8 -> 0 | N33: ='LOE Breakdown by Year'!D111 -> 0 | O33: 12 | P33: =O33*G33*$N33*$E$8*$E$8 -> 0 | Q33: ='LOE Breakdown by Year'!D151 -> 0 | R33: 0 | S33: =R33*G33*$Q33*$E$8*$E$8*$E$8 -> 0 | T33: =SUM(P33,M33,J33,E33,S33) -> 3000 | U33: 0 | V33: =SUM(T33:U33) -> 3000
A34: PERSNL | B34: 70000 | C34: COL2 | D34: Contracts & Compliance Director | E34: 29123.27 | F34: Month | G34: =55000/12 -> 4583.3333 | H34: ='LOE Breakdown by Year'!D32 -> 0.1 | I34: 12 | J34: =I34*G34*H34 -> 5500 | K34: ='LOE Breakdown by Year'!D72 -> 0.1 | L34: 12 | M34: =L34*G34*$K34*$E$8 -> 5775 | N34: ='LOE Breakdown by Year'!D112 -> 0.1 | O34: 12 | P34: =O34*G34*$N34*$E$8*$E$8 -> 6063.75 | Q34: ='LOE Breakdown by Year'!D152 -> 0.1 | R34: 3 | S34: =R34*G34*$Q34*$E$8*$E$8*$E$8 -> 1591.7344 | T34: =SUM(P34,M34,J34,E34,S34) -> 48053.754 | U34: 0 | V34: =SUM(T34:U34) -> 48053.754
A35: PERSNL | B35: 70000 | C35: COL2 | D35: Grants & Procurement Specialist (2) | E35: 0 | F35: Month | G35: =(21000/12)*2 -> 3500 | H35: ='LOE Breakdown by Year'!D33 -> 0.05 | I35: 12 | J35: =I35*G35*H35 -> 2100 | K35: ='LOE Breakdown by Year'!D73 -> 0.1 | L35: 12 | M35: =L35*G35*$K35*$E$8 -> 4410 | N35: ='LOE Breakdown by Year'!D113 -> 0.1 | O35: 12 | P35: =O35*G35*$N35*$E$8*$E$8 -> 4630.5 | Q35: ='LOE Breakdown by Year'!D153 -> 0.1 | R35: 0 | S35: =R35*G35*$Q35*$E$8*$E$8*$E$8 -> 0 | T35: =SUM(P35,M35,J35,E35,S35) -> 11140.5 | U35: 0 | V35: =SUM(T35:U35) -> 11140.5
A36: PERSNL | B36: 70000 | C36: COL2 | D36: F&A Director | E36: 170750.48 | F36: Month | G36: =(72000/12)*87.99% -> 5279.4 | H36: ='LOE Breakdown by Year'!D34 -> 0.15 | I36: 12 | J36: =I36*G36*H36 -> 9502.92 | K36: ='LOE Breakdown by Year'!D74 -> 0.15 | L36: 12 | M36: =L36*G36*$K36*$E$8 -> 9978.066 | N36: ='LOE Breakdown by Year'!D114 -> 0.15 | O36: 12 | P36: =O36*G36*$N36*$E$8*$E$8 -> 10476.969 | Q36: ='LOE Breakdown by Year'!D154 -> 0.15 | R36: 6 | S36: =R36*G36*$Q36*$E$8*$E$8*$E$8 -> 5500.4089 | T36: =SUM(P36,M36,J36,E36,S36) -> 206208.84 | U36: 0 | V36: =SUM(T36:U36) -> 206208.84
A37: PERSNL | B37: 70000 | C37: COL2 | D37: Accounting & Finance Specialist | E37: 0 | F37: Month | G37: =21000/12 -> 1750 | H37: ='LOE Breakdown by Year'!D35 -> 0.1 | I37: 12 | J37: =I37*G37*H37 -> 2100 | K37: ='LOE Breakdown by Year'!D75 -> 0.2 | L37: 12 | M37: =L37*G37*$K37*$E$8 -> 4410 | N37: ='LOE Breakdown by Year'!D115 -> 0.2 | O37: 12 | P37: =O37*G37*$N37*$E$8*$E$8 -> 4630.5 | Q37: ='LOE Breakdown by Year'!D155 -> 0.2 | R37: 3 | S37: =R37*G37*$Q37*$E$8*$E$8*$E$8 -> 1215.5063 | T37: =SUM(P37,M37,J37,E37,S37) -> 12356.006 | U37: 0 | V37: =SUM(T37:U37) -> 12356.006
A38: PERSNL | B38: 70000 | C38: COL2 | D38: Accountant | E38: 57428.39 | F38: Month | G38: =(21000/12) -> 1750 | H38: ='LOE Breakdown by Year'!D36 -> 0.1 | I38: 12 | J38: =I38*G38*H38 -> 2100 | K38: ='LOE Breakdown by Year'!D76 -> 0.2 | L38: 12 | M38: =L38*G38*$K38*$E$8 -> 4410 | N38: ='LOE Breakdown by Year'!D116 -> 0.2 | O38: 12 | P38: =O38*G38*$N38*$E$8*$E$8 -> 4630.5 | Q38: ='LOE Breakdown by Year'!D156 -> 0.2 | R38: 5 | S38: =R38*G38*$Q38*$E$8*$E$8*$E$8 -> 2025.8438 | T38: =SUM(P38,M38,J38,E38,S38) -> 70594.734 | U38: 0 | V38: =SUM(T38:U38) -> 70594.734
A39: PERSNL | B39: 70000 | C39: COL2 | D39: Finance & Admin Coordinator - 50% LOE | E39: 0 | F39: Month | G39: =31000/12 -> 2583.3333 | H39: ='LOE Breakdown by Year'!D37 -> 0.1 | I39: 12 | J39: =I39*G39*H39 -> 3100 | K39: ='LOE Breakdown by Year'!D77 -> 0.1 | L39: 12 | M39: =L39*G39*$K39*$E$8 -> 3255 | N39: ='LOE Breakdown by Year'!D117 -> 0.1 | O39: 12 | P39: =O39*G39*$N39*$E$8*$E$8 -> 3417.75 | Q39: ='LOE Breakdown by Year'!D157 -> 0.1 | R39: 6 | S39: =R39*G39*$Q39*$E$8*$E$8*$E$8 -> 1794.3188 | T39: =SUM(P39,M39,J39,E39,S39) -> 11567.069 | U39: 0 | V39: =SUM(T39:U39) -> 11567.069
A40: PERSNL | B40: 70000 | C40: COL2 | D40: Administrative Officer | E40: 31713.93 | F40: Month | G40: =12000/12 -> 1000 | H40: ='LOE Breakdown by Year'!D38 -> 0.1 | I40: 12 | J40: =I40*G40*H40 -> 1200 | K40: ='LOE Breakdown by Year'!D78 -> 0.3 | L40: 12 | M40: =L40*G40*$K40*$E$8 -> 3780 | N40: ='LOE Breakdown by Year'!D118 -> 0.3 | O40: 12 | P40: =O40*G40*$N40*$E$8*$E$8 -> 3969 | Q40: ='LOE Breakdown by Year'!D158 -> 0.3 | R40: 3 | S40: =R40*G40*$Q40*$E$8*$E$8*$E$8 -> 1041.8625 | T40: =SUM(P40,M40,J40,E40,S40) -> 41704.793 | U40: 0 | V40: =SUM(T40:U40) -> 41704.793
A41: PERSNL | B41: 70000 | C41: COL2 | D41: Human Resource Manager | E41: 0 | F41: Month | G41: =(35000/12)*67% -> 1954.1667 | H41: ='LOE Breakdown by Year'!D39 -> 0.1 | I41: 12 | J41: =I41*G41*H41 -> 2345 | K41: ='LOE Breakdown by Year'!D79 -> 0.3 | L41: 12 | M41: =L41*G41*$K41*$E$8 -> 7386.75 | N41: ='LOE Breakdown by Year'!D119 -> 0.3 | O41: 12 | P41: =O41*G41*$N41*$E$8*$E$8 -> 7756.0875 | Q41: ='LOE Breakdown by Year'!D159 -> 0.3 | R41: 6 | S41: =R41*G41*$Q41*$E$8*$E$8*$E$8 -> 4071.9459 | T41: =SUM(P41,M41,J41,E41,S41) -> 21559.783 | U41: 0 | V41: =SUM(T41:U41) -> 21559.783
...

Sheet Project Funds Snapshots
B2: FFPR Program Budget Summary Sheet
C3: Total USDA Project | D3: Direct $ | E3: Direct % | F3: Indirect Costs $ | G3: Indirect %
B5: OVERALL PROJECT BUDGET | C5: ='USDA Budget Summary'!F66 -> 33320792 | D5: ='USDA Budget Summary'!F55 -> 27016306 | E5: =D5/C5 -> 0.81079423 | F5: ='USDA Budget Summary'!E62 -> 6304486.1 | G5: =F5/C5 -> 0.18920577
B6: USDA | C6: ='USDA Budget Summary'!B66+'USDA Budget Summary'!C66 -> 31342864 | D6: ='USDA Budget Summary'!E55 -> 25038378 | E6: =D6/C6 -> 0.79885418 | F6: ='USDA Budget Summary'!E62 -> 6304486.1 | G6: =F6/C6 -> 0.20114582
B7: Cost Share | C7: ='USDA Budget Summary'!D66 -> 1977928 | D7: ='USDA Budget Summary'!D26+'USDA Budget Summary'!D37 -> 1977928 | E7: =D7/C7 -> 1 | F7: 0 | G7: =F7/C7 -> 0
C9: Total USDA Project | D9: Direct $ | E9: Direct % | F9: Indirect Costs $ | G9: Cost Share $ | H9: % of Direct Funds by Partner
B11: BUDGET BY PARTNER
B12: POA | C12: ='USDA Budget Summary'!F66-C13 -> 32318199 | D12: =C12-F12-G12-G13 -> 24035785 | E12: =D12/SUM($C$12:$C$13) -> 0.72134495 | F12: ='USDA Budget Summary'!E62 -> 6304486.1 | G12: ='USDA Budget Summary'!D37-'Project Funds Snapshots'!G13 -> 1965708.8 | H12: =(G12+D12)/SUM($C$12:$C$13) -> 0.78033841
B13: Sub 1 - Fundación Julio y Astrida Carrizosa ONG | C13: ='Detailed Budget'!T107 -> 1002592.9 | D13: ='Sub Budget Fundacion IC'!T103 -> 953995.54 | E13: =D13/SUM($C$12:$C$13) -> 0.028630638 | F13: ='Sub Budget Fundacion IC'!T107 -> 48596.357 | G13: ='Sub Budget Fundacion IC'!T110 -> 12219.19 | H13: =(G13+D13)/SUM($C$12:$C$13) -> 0.028997352
C15: Total USDA Project | D15: Direct $ | E15: Direct % | F15: Indirect Costs $ | G15: Cost Share $ | H15: % of Direct Funds by Activity
B16: BUDGET BY ACTIVITY
B17: Admin | C17: =F17+D17+G17 -> 8183592.5 | D17: ='USDA Budget Summary'!E26 -> 6355224.3 | E17: =D17/SUM($C$17:$C$25) -> 0.19072817 | F17: =Admin!T144 -> 1828368.2 | G17: 0 | H17: =(G17+D17)/SUM($C$17:$C$25) -> 0.19072817
B18: Activity 1 | C18: =F18+D18+G18 -> 352228.29 | D18: ='USDA Budget Summary'!B29 -> 272696.75 | E18: =D18/SUM($C$17:$C$25) -> 0.0081839679 | F18: ='Activity 1'!T84 -> 79531.545 | G18: 0 | H18: =(G18+D18)/SUM($C$17:$C$25) -> 0.0081839679
B19: Activity 2 | C19: =F19+D19+G19 -> 3152067.9 | D19: ='USDA Budget Summary'!B30 -> 2209930.1 | E19: =D19/SUM($C$17:$C$25) -> 0.066322745 | F19: ='Activity 2'!T92 -> 629918.83 | G19: 312219 | H19: =(G19+D19)/SUM($C$17:$C$25) -> 0.075692824
B20: Activity 3 | C20: =F20+D20+G20 -> 10538868 | D20: ='USDA Budget Summary'!B31 -> 7469424.7 | E20: =D20/SUM($C$17:$C$25) -> 0.2241667 | F20: ='Activity 3'!T111 -> 2129853.1 | G20: 939590.56 | H20: =(G20+D20)/SUM($C$17:$C$25) -> 0.25236498
B21: Activity 4 | C21: =F21+D21+G21 -> 2703803.2 | D21: ='USDA Budget Summary'!B32 -> 1992268.2 | E21: =D21/SUM($C$17:$C$25) -> 0.05979044 | F21: ='Activity 4'!T93 -> 569606.02 | G21: 141929 | H21: =(G21+D21)/SUM($C$17:$C$25) -> 0.064049905
B22: Activity 5 | C22: =F22+D22+G22 -> 2003731.7 | D22: ='USDA Budget Summary'!B33 -> 1105173.6 | E22: =D22/SUM($C$17:$C$25) -> 0.033167632 | F22: ='Activity 5'!T86 -> 314368.06 | G22: 584190 | H22: =(G22+D22)/SUM($C$17:$C$25) -> 0.050699899
B23: Activity 6 | C23: =F23+D23+G23 -> 1053847.6 | D23: ='USDA Budget Summary'!B34 -> 819624.4 | E23: =D23/SUM($C$17:$C$25) -> 0.024597946 | F23: ='Activity 6'!T93 -> 234223.2 | G23: 0 | H23: =(G23+D23)/SUM($C$17:$C$25) -> 0.024597946
B24: Activity 7 | C24: =F24+D24+G24 -> 1637495.4 | D24: ='USDA Budget Summary'!B35 -> 1274251 | E24: =D24/SUM($C$17:$C$25) -> 0.038241854 | F24: ='Activity 7'!T90 -> 363244.35 | G24: 0 | H24: =(G24+D24)/SUM($C$17:$C$25) -> 0.038241854
B25: Activity 8 | C25: =F25+D25+G25 -> 3695213.1 | D25: ='USDA Budget Summary'!B36 -> 3539784.8 | E25: =D25/SUM($C$17:$C$25) -> 0.10623333 | F25: ='Activity 8'!T81 -> 155428.33 | G25: 0 | H25: =(G25+D25)/SUM($C$17:$C$25) -> 0.10623333
C27: Total USDA Project | D27: Direct $ | E27: Direct % | F27: Indirect Costs $ | G27: Cost Share $ | H27: % of Direct Funds by Activity and Subrecipient
B28: DETAILS BY ACTIVITY & SUBRECIPIENT
B29: Admin - POA | C29: =C17 -> 8183592.5 | D29: =D17 -> 6355224.3 | E29: =D29/SUM($C$29:$C$38) -> 0.19072817 | F29: =Admin!T144 -> 1828368.2 | G29: =Admin!T147 -> 0 | H29: =(G29+D29)/SUM($C$29:$C$38) -> 0.19072817
B30: Activity 1 - POA | C30: =C18 -> 352228.29 | D30: =D18 -> 272696.75 | E30: =D30/SUM($C$29:$C$38) -> 0.0081839679 | F30: ='Activity 1'!T84 -> 79531.545 | G30: ='Activity 1'!T87 -> 0 | H30: =(G30+D30)/SUM($C$29:$C$38) -> 0.0081839679
B31: Activity 2 - POA | C31: =C19-C32 -> 2149475 | D31: =D19-D32 -> 1255934.6 | E31: =D31/SUM($C$29:$C$38) -> 0.037692155 | F31: ='Activity 2'!T92 -> 629918.83 | G31: ='Activity 2'!T96 -> 300000 | H31: =(G31+D31)/SUM($C$29:$C$38) -> 0.046695527
B32: Activity 2 - Sub 1 - Fundación Julio y Astrida Carrizosa ONG | C32: =C13 -> 1002592.9 | D32: ='Sub Budget Fundacion IC'!T103 -> 953995.54 | E32: =D32/SUM($C$29:$C$38) -> 0.02863059 | F32: ='Sub Budget Fundacion IC'!T107 -> 48596.357 | G32: ='Sub Budget Fundacion IC'!T110 -> 12219.19 | H32: =(G32+D32)/SUM($C$29:$C$38) -> 0.028997303
B33: Activity 3 - POA | C33: =C20 -> 10538868 | D33: =D20 -> 7469424.7 | E33: =D33/SUM($C$29:$C$38) -> 0.2241667 | F33: ='Activity 3'!T111 -> 2129853.1 | G33: ='Activity 3'!T114+'Activity 3'!T115+'Activity 3'!T116 -> 939590.56 | H33: =(G33+D33)/SUM($C$29:$C$38) -> 0.25236498
B34: Activity 4 - POA | C34: =C21 -> 2703803.2 | D34: =D21 -> 1992268.2 | E34: =D34/SUM($C$29:$C$38) -> 0.05979044 | F34: ='Activity 4'!T93 -> 569606.02 | G34: ='Activity 4'!T96+'Activity 4'!T97 -> 141928.58 | H34: =(G34+D34)/SUM($C$29:$C$38) -> 0.064049893
B35: Activity 5 - POA | C35: =C22 -> 2003731.7 | D35: =D22 -> 1105173.6 | E35: =D35/SUM($C$29:$C$38) -> 0.033167632 | F35: ='Activity 5'!T86 -> 314368.06 | G35: ='Activity 5'!T89 -> 584189.75 | H35: =(G35+D35)/SUM($C$29:$C$38) -> 0.050699892
B36: Activity 6 - POA | C36: =C23 -> 1053847.6 | D36: =D23 -> 819624.4 | E36: =D36/SUM($C$29:$C$38) -> 0.024597946 | F36: ='Activity 6'!T93 -> 234223.2 | G36: ='Activity 6'!T96 -> 0 | H36: =(G36+D36)/SUM($C$29:$C$38) -> 0.024597946
B37: Activity 7 - POA | C37: =C24 -> 1637495.4 | D37: =D24 -> 1274251 | E37: =D37/SUM($C$29:$C$38) -> 0.038241854 | F37: ='Activity 7'!T90 -> 363244.35 | G37: ='Activity 7'!T93 -> 0 | H37: =(G37+D37)/SUM($C$29:$C$38) -> 0.038241854
B38: Activity 8 - POA | C38: =C25 -> 3695213.1 | D38: =D25 -> 3539784.8 | E38: =D38/SUM($C$29:$C$38) -> 0.10623333 | F38: ='Activity 8'!T81 -> 155428.33 | G38: ='Activity 8'!T84 -> 0 | H38: =(G38+D38)/SUM($C$29:$C$38) -> 0.10623333

Sheet Detailed Budget
A2: Item | B2: Type of Unit | C2: Year 1 -4 Total Inception through 09/30/2024 | D2: Year 5 (10/1/24 - 9/30/25) | H2: Year 6 (10/1/25 - 09/30/26) | L2: Year 7 (10/1/26 - 09/30/27) | P2: Year 8 (10/1/27 - 3/31/28) | T2: Total
D3: Cost | E3: Quantity | F3: Percent Allocated | G3: Total | H3: Cost | I3: Quantity | J3: Percent Allocated | K3: Total | L3: Cost | M3: Quantity | N3: Percent Allocated | O3: Total | P3: Cost | Q3: Quantity | R3: Percent Allocated | S3: Total
A4: Direct Costs
A5: Salaries
A6: USN/TCN Staff
A7: ='Program Budget'!D13 -> Key Personnel: Chief of Party | B7: ='Program Budget'!F15 -> Month | C7: =Admin!C7+'Activity 1'!C7+'Activity 2'!C7+'Activity 3'!C7+'Activity 4'!C7+'Activity 5'!C7+'Activity 6'!C7+'Activity 7'!C7+'Activity 8'!C7 -> 568684.69 | D7: ='Program Budget'!G13 -> 14250 | E7: ='Program Budget'!I13 -> 12 | F7: =Admin!F7+'Activity 1'!F7+'Activity 2'!F7+'Activity 3'!F7+'Activity 4'!F7+'Activity 5'!F7+'Activity 6'!F7+'Activity 7'!F7+'Activity 8'!F7 -> 1 | G7: =D7*E7*F7 -> 171000 | H7: =D7*1.05 -> 14962.5 | I7: ='Program Budget'!L13 -> 12 | J7: =Admin!J7+'Activity 1'!J7+'Activity 2'!J7+'Activity 3'!J7+'Activity 4'!J7+'Activity 5'!J7+'Activity 6'!J7+'Activity 7'!J7+'Activity 8'!J7 -> 1 | K7: =H7*I7*J7 -> 179550 | L7: =H7*1.05 -> 15710.625 | M7: ='Program Budget'!O13 -> 12 | N7: =Admin!N7+'Activity 1'!N7+'Activity 2'!N7+'Activity 3'!N7+'Activity 4'!N7+'Activity 5'!N7+'Activity 6'!N7+'Activity 7'!N7+'Activity 8'!N7 -> 1 | O7: =L7*M7*N7 -> 188527.5 | P7: =L7*1.05 -> 16496.156 | Q7: ='Program Budget'!R13 -> 0 | R7: =Admin!R10+'Activity 1'!R10+'Activity 2'!R10+'Activity 3'!R10+'Activity 4'!R10+'Activity 5'!R10+'Activity 6'!R10+'Activity 7'!R10+'Activity 8'!R10 -> 1 | S7: =P7*Q7*R4 -> 0 | T7: =C7+G7+K7+O7+S7 -> 1107762.2
A8: Total: Expatriate Salaries & Wages | C8: =SUM(C7:C7) -> 568684.69 | G8: =SUM(G7:G7) -> 171000 | K8: =SUM(K7:K7) -> 179550 | O8: =SUM(O7:O7) -> 188527.5 | S8: =SUM(S7:S7) -> 0 | T8: =+C8+G8+K8+O8+S8 -> 1107762.2
A9: CNN Staff
A10: ='Program Budget'!D14 -> Deputy Chief of Party / Value Chain Strengthening Director | B10: ='Program Budget'!F14 -> Month | C10: =Admin!C10+'Activity 1'!C10+'Activity 2'!C10+'Activity 3'!C10+'Activity 4'!C10+'Activity 5'!C10+'Activity 6'!C10+'Activity 7'!C10+'Activity 8'!C10 -> 0 | D10: ='Program Budget'!G14 -> 5000 | E10: ='Program Budget'!I14 -> 12 | F10: =Admin!F10+'Activity 1'!F10+'Activity 2'!F10+'Activity 3'!F10+'Activity 4'!F10+'Activity 5'!F10+'Activity 6'!F10+'Activity 7'!F10+'Activity 8'!F10 -> 1 | G10: =D10*E10*F10 -> 60000 | H10: =D10*1.05 -> 5250 | I10: ='Program Budget'!L14 -> 12 | J10: =Admin!J10+'Activity 1'!J10+'Activity 2'!J10+'Activity 3'!J10+'Activity 4'!J10+'Activity 5'!J10+'Activity 6'!J10+'Activity 7'!J10+'Activity 8'!J10 -> 1 | K10: =H10*I10*J10 -> 63000 | L10: =H10*1.05 -> 5512.5 | M10: ='Program Budget'!O14 -> 12 | N10: =Admin!N10+'Activity 1'!N10+'Activity 2'!N10+'Activity 3'!N10+'Activity 4'!N10+'Activity 5'!N10+'Activity 6'!N10+'Activity 7'!N10+'Activity 8'!N10 -> 1 | O10: =L10*M10*N10 -> 66150 | P10: =L10*1.05 -> 5788.125 | Q10: ='Program Budget'!R14 -> 6 | R10: =Admin!R10+'Activity 1'!R10+'Activity 2'!R10+'Activity 3'!R10+'Activity 4'!R10+'Activity 5'!R10+'Activity 6'!R10+'Activity 7'!R10+'Activity 8'!R10 -> 1 | S10: =P10*Q10*R7 -> 34728.75 | T10: =C10+G10+K10+O10+S10 -> 223878.75
A11: ='Program Budget'!D15 -> Key Personnel: Technical Director | B11: ='Program Budget'!F15 -> Month | C11: =Admin!C11+'Activity 1'!C11+'Activity 2'!C11+'Activity 3'!C11+'Activity 4'!C11+'Activity 5'!C11+'Activity 6'!C11+'Activity 7'!C11+'Activity 8'!C11 -> 296291.11 | D11: ='Program Budget'!G15 -> 4583.3333 | E11: ='Program Budget'!I15 -> 12 | F11: =Admin!F11+'Activity 1'!F11+'Activity 2'!F11+'Activity 3'!F11+'Activity 4'!F11+'Activity 5'!F11+'Activity 6'!F11+'Activity 7'!F11+'Activity 8'!F11 -> 1 | G11: =D11*E11*F11 -> 55000 | H11: =D11*1.05 -> 4812.5 | I11: ='Program Budget'!L15 -> 12 | J11: =Admin!J11+'Activity 1'!J11+'Activity 2'!J11+'Activity 3'!J11+'Activity 4'!J11+'Activity 5'!J11+'Activity 6'!J11+'Activity 7'!J11+'Activity 8'!J11 -> 1 | K11: =H11*I11*J11 -> 57750 | L11: =H11*1.05 -> 5053.125 | M11: ='Program Budget'!O15 -> 12 | N11: =Admin!N11+'Activity 1'!N11+'Activity 2'!N11+'Activity 3'!N11+'Activity 4'!N11+'Activity 5'!N11+'Activity 6'!N11+'Activity 7'!N11+'Activity 8'!N11 -> 1 | O11: =L11*M11*N11 -> 60637.5 | P11: =L11*1.05 -> 5305.7812 | Q11: ='Program Budget'!R15 -> 5 | R11: =Admin!R11+'Activity 1'!R11+'Activity 2'!R11+'Activity 3'!R11+'Activity 4'!R11+'Activity 5'!R11+'Activity 6'!R11+'Activity 7'!R11+'Activity 8'!R11 -> 1 | S11: =P11*Q11*R11 -> 26528.906 | T11: =C11+G11+K11+O11+S11 -> 496207.52
A12: ='Program Budget'!D16 -> Activity Lead Agribusiness Senior Specialist (Cacao) | B12: ='Program Budget'!F16 -> Month | C12: =Admin!C12+'Activity 1'!C12+'Activity 2'!C12+'Activity 3'!C12+'Activity 4'!C12+'Activity 5'!C12+'Activity 6'!C12+'Activity 7'!C12+'Activity 8'!C12 -> 160735.87 | D12: ='Program Budget'!G16 -> 2833.3333 | E12: ='Program Budget'!I16 -> 12 | F12: =Admin!F12+'Activity 1'!F12+'Activity 2'!F12+'Activity 3'!F12+'Activity 4'!F12+'Activity 5'!F12+'Activity 6'!F12+'Activity 7'!F12+'Activity 8'!F12 -> 1 | G12: =D12*E12*F12 -> 34000 | H12: =D12*1.05 -> 2975 | I12: ='Program Budget'!L16 -> 12 | J12: =Admin!J12+'Activity 1'!J12+'Activity 2'!J12+'Activity 3'!J12+'Activity 4'!J12+'Activity 5'!J12+'Activity 6'!J12+'Activity 7'!J12+'Activity 8'!J12 -> 1 | K12: =H12*I12*J12 -> 35700 | L12: =H12*1.05 -> 3123.75 | M12: ='Program Budget'!O16 -> 12 | N12: =Admin!N12+'Activity 1'!N12+'Activity 2'!N12+'Activity 3'!N12+'Activity 4'!N12+'Activity 5'!N12+'Activity 6'!N12+'Activity 7'!N12+'Activity 8'!N12 -> 1 | O12: =L12*M12*N12 -> 37485 | P12: =L12*1.05 -> 3279.9375 | Q12: ='Program Budget'!R16 -> 2 | R12: =Admin!R12+'Activity 1'!R12+'Activity 2'!R12+'Activity 3'!R12+'Activity 4'!R12+'Activity 5'!R12+'Activity 6'!R12+'Activity 7'!R12+'Activity 8'!R12 -> 1 | S12: =P12*Q12*R12 -> 6559.875 | T12: =C12+G12+K12+O12+S12 -> 274480.74
A13: ='Program Budget'!D17 -> Cacao Field Officer | B13: ='Program Budget'!F17 -> Month | C13: =Admin!C13+'Activity 1'!C13+'Activity 2'!C13+'Activity 3'!C13+'Activity 4'!C13+'Activity 5'!C13+'Activity 6'!C13+'Activity 7'!C13+'Activity 8'!C13 -> 0 | D13: ='Program Budget'!G17 -> 1333.3333 | E13: ='Program Budget'!I17 -> 12 | F13: =Admin!F13+'Activity 1'!F13+'Activity 2'!F13+'Activity 3'!F13+'Activity 4'!F13+'Activity 5'!F13+'Activity 6'!F13+'Activity 7'!F13+'Activity 8'!F13 -> 1 | G13: =D13*E13*F13 -> 16000 | H13: =D13*1.05 -> 1400 | I13: ='Program Budget'!L17 -> 12 | J13: =Admin!J13+'Activity 1'!J13+'Activity 2'!J13+'Activity 3'!J13+'Activity 4'!J13+'Activity 5'!J13+'Activity 6'!J13+'Activity 7'!J13+'Activity 8'!J13 -> 1 | K13: =H13*I13*J13 -> 16800 | L13: =H13*1.05 -> 1470 | M13: ='Program Budget'!O17 -> 12 | N13: =Admin!N13+'Activity 1'!N13+'Activity 2'!N13+'Activity 3'!N13+'Activity 4'!N13+'Activity 5'!N13+'Activity 6'!N13+'Activity 7'!N13+'Activity 8'!N13 -> 1 | O13: =L13*M13*N13 -> 17640 | P13: =L13*1.05 -> 1543.5 | Q13: ='Program Budget'!R17 -> 0 | R13: =Admin!R13+'Activity 1'!R13+'Activity 2'!R13+'Activity 3'!R13+'Activity 4'!R13+'Activity 5'!R13+'Activity 6'!R13+'Activity 7'!R13+'Activity 8'!R13 -> 1 | S13: =P13*Q13*R13 -> 0 | T13: =C13+G13+K13+O13+S13 -> 50440
A14: ='Program Budget'!D18 -> Cacao & Complementary Crop Technical Field Leader (2) | B14: ='Program Budget'!F18 -> Month | C14: =Admin!C14+'Activity 1'!C14+'Activity 2'!C14+'Activity 3'!C14+'Activity 4'!C14+'Activity 5'!C14+'Activity 6'!C14+'Activity 7'!C14+'Activity 8'!C14 -> 0 | D14: ='Program Budget'!G18 -> 3500 | E14: ='Program Budget'!I18 -> 6 | F14: =Admin!F14+'Activity 1'!F14+'Activity 2'!F14+'Activity 3'!F14+'Activity 4'!F14+'Activity 5'!F14+'Activity 6'!F14+'Activity 7'!F14+'Activity 8'!F14 -> 1 | G14: =D14*E14*F14 -> 21000 | H14: =D14*1.05 -> 3675 | I14: ='Program Budget'!L18 -> 12 | J14: =Admin!J14+'Activity 1'!J14+'Activity 2'!J14+'Activity 3'!J14+'Activity 4'!J14+'Activity 5'!J14+'Activity 6'!J14+'Activity 7'!J14+'Activity 8'!J14 -> 1 | K14: =H14*I14*J14 -> 44100 | L14: =H14*1.05 -> 3858.75 | M14: ='Program Budget'!O18 -> 12 | N14: =Admin!N14+'Activity 1'!N14+'Activity 2'!N14+'Activity 3'!N14+'Activity 4'!N14+'Activity 5'!N14+'Activity 6'!N14+'Activity 7'!N14+'Activity 8'!N14 -> 1 | O14: =L14*M14*N14 -> 46305 | P14: =L14*1.05 -> 4051.6875 | Q14: ='Program Budget'!R18 -> 0 | R14: =Admin!R14+'Activity 1'!R14+'Activity 2'!R14+'Activity 3'!R14+'Activity 4'!R14+'Activity 5'!R14+'Activity 6'!R14+'Activity 7'!R14+'Activity 8'!R14 -> 1 | S14: =P14*Q14*R14 -> 0 | T14: =C14+G14+K14+O14+S14 -> 111405
A15: ='Program Budget'!D19 -> Extension Agents (45 in Y5 and 25 in Y6) | B15: ='Program Budget'!F19 -> Month | C15: =Admin!C15+'Activity 1'!C15+'Activity 2'!C15+'Activity 3'!C15+'Activity 4'!C15+'Activity 5'!C15+'Activity 6'!C15+'Activity 7'!C15+'Activity 8'!C15 -> 187435.61 | D15: ='Program Budget'!G19 -> 1000 | E15: ='Program Budget'!I19 -> 12 | F15: =Admin!F15+'Activity 1'!F15+'Activity 2'!F15+'Activity 3'!F15+'Activity 4'!F15+'Activity 5'!F15+'Activity 6'!F15+'Activity 7'!F15+'Activity 8'!F15 -> 1 | G15: =(D15*45)*E15*F15 -> 540000 | H15: =D15*1.05 -> 1050 | I15: ='Program Budget'!L19 -> 12 | J15: =Admin!J15+'Activity 1'!J15+'Activity 2'!J15+'Activity 3'!J15+'Activity 4'!J15+'Activity 5'!J15+'Activity 6'!J15+'Activity 7'!J15+'Activity 8'!J15 -> 1 | K15: =(H15*25)*I15*J15 -> 315000 | L15: =H15*1.05 -> 1102.5 | M15: ='Program Budget'!O19 -> 0 | N15: =Admin!N15+'Activity 1'!N15+'Activity 2'!N15+'Activity 3'!N15+'Activity 4'!N15+'Activity 5'!N15+'Activity 6'!N15+'Activity 7'!N15+'Activity 8'!N15 -> 1 | O15: =L15*M15*N15 -> 0 | P15: =L15*1.05 -> 1157.625 | Q15: ='Program Budget'!R19 -> 0 | R15: =Admin!R15+'Activity 1'!R15+'Activity 2'!R15+'Activity 3'!R15+'Activity 4'!R15+'Activity 5'!R15+'Activity 6'!R15+'Activity 7'!R15+'Activity 8'!R15 -> 1 | S15: =P15*Q15*R15 -> 0 | T15: =C15+G15+K15+O15+S15 -> 1042435.6
A16: ='Program Budget'!D20 -> Activity Lead Agribusiness Senior Specialist (Complementary Crop) | B16: ='Program Budget'!F20 -> Month | C16: =Admin!C16+'Activity 1'!C16+'Activity 2'!C16+'Activity 3'!C16+'Activity 4'!C16+'Activity 5'!C16+'Activity 6'!C16+'Activity 7'!C16+'Activity 8'!C16 -> 151336.3 | D16: ='Program Budget'!G20 -> 2833.3333 | E16: ='Program Budget'!I20 -> 12 | F16: =Admin!F16+'Activity 1'!F16+'Activity 2'!F16+'Activity 3'!F16+'Activity 4'!F16+'Activity 5'!F16+'Activity 6'!F16+'Activity 7'!F16+'Activity 8'!F16 -> 1 | G16: =D16*E16*F16 -> 34000 | H16: =D16*1.05 -> 2975 | I16: ='Program Budget'!L20 -> 12 | J16: =Admin!J16+'Activity 1'!J16+'Activity 2'!J16+'Activity 3'!J16+'Activity 4'!J16+'Activity 5'!J16+'Activity 6'!J16+'Activity 7'!J16+'Activity 8'!J16 -> 1 | K16: =H16*I16*J16 -> 35700 | L16: =H16*1.05 -> 3123.75 | M16: ='Program Budget'!O20 -> 12 | N16: =Admin!N16+'Activity 1'!N16+'Activity 2'!N16+'Activity 3'!N16+'Activity 4'!N16+'Activity 5'!N16+'Activity 6'!N16+'Activity 7'!N16+'Activity 8'!N16 -> 1 | O16: =L16*M16*N16 -> 37485 | P16: =L16*1.05 -> 3279.9375 | Q16: ='Program Budget'!R20 -> 0 | R16: =Admin!R16+'Activity 1'!R16+'Activity 2'!R16+'Activity 3'!R16+'Activity 4'!R16+'Activity 5'!R16+'Activity 6'!R16+'Activity 7'!R16+'Activity 8'!R16 -> 1 | S16: =P16*Q16*R16 -> 0 | T16: =C16+G16+K16+O16+S16 -> 258521.3
A17: ='Program Budget'!D21 -> Complementary Crops Field Officer | B17: ='Program Budget'!F21 -> Month | C17: =Admin!C17+'Activity 1'!C17+'Activity 2'!C17+'Activity 3'!C17+'Activity 4'!C17+'Activity 5'!C17+'Activity 6'!C17+'Activity 7'!C17+'Activity 8'!C17 -> 0 | D17: ='Program Budget'!G21 -> 0 | E17: ='Program Budget'!I21 -> 0 | F17: =Admin!F17+'Activity 1'!F17+'Activity 2'!F17+'Activity 3'!F17+'Activity 4'!F17+'Activity 5'!F17+'Activity 6'!F17+'Activity 7'!F17+'Activity 8'!F17 -> 1 | G17: =D17*E17*F17 -> 0 | H17: =D17*1.05 -> 0 | I17: ='Program Budget'!L21 -> 12 | J17: =Admin!J17+'Activity 1'!J17+'Activity 2'!J17+'Activity 3'!J17+'Activity 4'!J17+'Activity 5'!J17+'Activity 6'!J17+'Activity 7'!J17+'Activity 8'!J17 -> 1 | K17: =H17*I17*J17 -> 0 | L17: =H17*1.05 -> 0 | M17: ='Program Budget'!O21 -> 12 | N17: =Admin!N17+'Activity 1'!N17+'Activity 2'!N17+'Activity 3'!N17+'Activity 4'!N17+'Activity 5'!N17+'Activity 6'!N17+'Activity 7'!N17+'Activity 8'!N17 -> 1 | O17: =L17*M17*N17 -> 0 | P17: =L17*1.05 -> 0 | Q17: ='Program Budget'!R21 -> 0 | R17: =Admin!R17+'Activity 1'!R17+'Activity 2'!R17+'Activity 3'!R17+'Activity 4'!R17+'Activity 5'!R17+'Activity 6'!R17+'Activity 7'!R17+'Activity 8'!R17 -> 1 | S17: =P17*Q17*R17 -> 0 | T17: =C17+G17+K17+O17+S17 -> 0
A18: ='Program Budget'!D22 -> EPSEAS Specialist | B18: ='Program Budget'!F22 -> Month | C18: =Admin!C18+'Activity 1'!C18+'Activity 2'!C18+'Activity 3'!C18+'Activity 4'!C18+'Activity 5'!C18+'Activity 6'!C18+'Activity 7'!C18+'Activity 8'!C18 -> 0 | D18: ='Program Budget'!G22 -> 0 | E18: ='Program Budget'!I22 -> 0 | F18: =Admin!F18+'Activity 1'!F18+'Activity 2'!F18+'Activity 3'!F18+'Activity 4'!F18+'Activity 5'!F18+'Activity 6'!F18+'Activity 7'!F18+'Activity 8'!F18 -> 1 | G18: =D18*E18*F18 -> 0 | H18: =D18*1.05 -> 0 | I18: ='Program Budget'!L22 -> 12 | J18: =Admin!J18+'Activity 1'!J18+'Activity 2'!J18+'Activity 3'!J18+'Activity 4'!J18+'Activity 5'!J18+'Activity 6'!J18+'Activity 7'!J18+'Activity 8'!J18 -> 1 | K18: =H18*I18*J18 -> 0 | L18: =H18*1.05 -> 0 | M18: ='Program Budget'!O22 -> 12 | N18: =Admin!N18+'Activity 1'!N18+'Activity 2'!N18+'Activity 3'!N18+'Activity 4'!N18+'Activity 5'!N18+'Activity 6'!N18+'Activity 7'!N18+'Activity 8'!N18 -> 1 | O18: =L18*M18*N18 -> 0 | P18: =L18*1.05 -> 0 | Q18: ='Program Budget'!R22 -> 0 | R18: =Admin!R18+'Activity 1'!R18+'Activity 2'!R18+'Activity 3'!R18+'Activity 4'!R18+'Activity 5'!R18+'Activity 6'!R18+'Activity 7'!R18+'Activity 8'!R18 -> 1 | S18: =P18*Q18*R18 -> 0 | T18: =C18+G18+K18+O18+S18 -> 0
A19: ='Program Budget'!D23 -> Extension Agents for EPSEAS (20 in Y6 and 25 in Y7) | B19: ='Program Budget'!F23 -> Month | C19: =Admin!C19+'Activity 1'!C19+'Activity 2'!C19+'Activity 3'!C19+'Activity 4'!C19+'Activity 5'!C19+'Activity 6'!C19+'Activity 7'!C19+'Activity 8'!C19 -> 0 | D19: ='Program Budget'!G23 -> 1000 | E19: ='Program Budget'!I23 -> 0 | F19: =Admin!F19+'Activity 1'!F19+'Activity 2'!F19+'Activity 3'!F19+'Activity 4'!F19+'Activity 5'!F19+'Activity 6'!F19+'Activity 7'!F19+'Activity 8'!F19 -> 1 | G19: =D19*E19*F19 -> 0 | H19: =D19*1.05 -> 1050 | I19: ='Program Budget'!L23 -> 12 | J19: =Admin!J19+'Activity 1'!J19+'Activity 2'!J19+'Activity 3'!J19+'Activity 4'!J19+'Activity 5'!J19+'Activity 6'!J19+'Activity 7'!J19+'Activity 8'!J19 -> 1 | K19: =(H19*20)*I19*J19 -> 252000 | L19: =H19*1.05 -> 1102.5 | M19: ='Program Budget'!O23 -> 12 | N19: =Admin!N19+'Activity 1'!N19+'Activity 2'!N19+'Activity 3'!N19+'Activity 4'!N19+'Activity 5'!N19+'Activity 6'!N19+'Activity 7'!N19+'Activity 8'!N19 -> 1 | O19: =(L19*25)*M19*N19 -> 330750 | P19: =L19*1.05 -> 1157.625 | Q19: ='Program Budget'!R23 -> 0 | R19: =Admin!R19+'Activity 1'!R19+'Activity 2'!R19+'Activity 3'!R19+'Activity 4'!R19+'Activity 5'!R19+'Activity 6'!R19+'Activity 7'!R19+'Activity 8'!R19 -> 1 | S19: =P19*Q19*R19 -> 0 | T19: =C19+G19+K19+O19+S19 -> 582750
A20: ='Program Budget'!D24 -> Senior M&E Director | B20: ='Program Budget'!F24 -> Month | C20: =Admin!C20+'Activity 1'!C20+'Activity 2'!C20+'Activity 3'!C20+'Activity 4'!C20+'Activity 5'!C20+'Activity 6'!C20+'Activity 7'!C20+'Activity 8'!C20 -> 124292.19 | D20: ='Program Budget'!G24 -> 6250 | E20: ='Program Budget'!I24 -> 12 | F20: =Admin!F20+'Activity 1'!F20+'Activity 2'!F20+'Activity 3'!F20+'Activity 4'!F20+'Activity 5'!F20+'Activity 6'!F20+'Activity 7'!F20+'Activity 8'!F20 -> 1 | G20: =D20*E20*F20 -> 75000 | H20: =D20*1.05 -> 6562.5 | I20: ='Program Budget'!L24 -> 12 | J20: =Admin!J20+'Activity 1'!J20+'Activity 2'!J20+'Activity 3'!J20+'Activity 4'!J20+'Activity 5'!J20+'Activity 6'!J20+'Activity 7'!J20+'Activity 8'!J20 -> 1 | K20: =H20*I20*J20 -> 78750 | L20: =H20*1.05 -> 6890.625 | M20: ='Program Budget'!O24 -> 12 | N20: =Admin!N20+'Activity 1'!N20+'Activity 2'!N20+'Activity 3'!N20+'Activity 4'!N20+'Activity 5'!N20+'Activity 6'!N20+'Activity 7'!N20+'Activity 8'!N20 -> 1 | O20: =L20*M20*N20 -> 82687.5 | P20: =L20*1.05 -> 7235.1562 | Q20: ='Program Budget'!R24 -> 6 | R20: =Admin!R20+'Activity 1'!R20+'Activity 2'!R20+'Activity 3'!R20+'Activity 4'!R20+'Activity 5'!R20+'Activity 6'!R20+'Activity 7'!R20+'Activity 8'!R20 -> 1 | S20: =P20*Q20*R20 -> 43410.938 | T20: =C20+G20+K20+O20+S20 -> 404140.63
A21: ='Program Budget'!D25 -> Senior M&E Specialist | B21: ='Program Budget'!F25 -> Month | C21: =Admin!C21+'Activity 1'!C21+'Activity 2'!C21+'Activity 3'!C21+'Activity 4'!C21+'Activity 5'!C21+'Activity 6'!C21+'Activity 7'!C21+'Activity 8'!C21 -> 97588.95 | D21: ='Program Budget'!G25 -> 2833.3333 | E21: ='Program Budget'!I25 -> 12 | F21: =Admin!F21+'Activity 1'!F21+'Activity 2'!F21+'Activity 3'!F21+'Activity 4'!F21+'Activity 5'!F21+'Activity 6'!F21+'Activity 7'!F21+'Activity 8'!F21 -> 1 | G21: =D21*E21*F21 -> 34000 | H21: =D21*1.05 -> 2975 | I21: ='Program Budget'!L25 -> 12 | J21: =Admin!J21+'Activity 1'!J21+'Activity 2'!J21+'Activity 3'!J21+'Activity 4'!J21+'Activity 5'!J21+'Activity 6'!J21+'Activity 7'!J21+'Activity 8'!J21 -> 1 | K21: =H21*I21*J21 -> 35700 | L21: =H21*1.05 -> 3123.75 | M21: ='Program Budget'!O25 -> 12 | N21: =Admin!N21+'Activity 1'!N21+'Activity 2'!N21+'Activity 3'!N21+'Activity 4'!N21+'Activity 5'!N21+'Activity 6'!N21+'Activity 7'!N21+'Activity 8'!N21 -> 1 | O21: =L21*M21*N21 -> 37485 | P21: =L21*1.05 -> 3279.9375 | Q21: ='Program Budget'!R25 -> 6 | R21: =Admin!R21+'Activity 1'!R21+'Activity 2'!R21+'Activity 3'!R21+'Activity 4'!R21+'Activity 5'!R21+'Activity 6'!R21+'Activity 7'!R21+'Activity 8'!R21 -> 1 | S21: =P21*Q21*R21 -> 19679.625 | T21: =C21+G21+K21+O21+S21 -> 224453.58
A22: ='Program Budget'!D26 -> M&E Specialist | B22: ='Program Budget'!F26 -> Month | C22: =Admin!C22+'Activity 1'!C22+'Activity 2'!C22+'Activity 3'!C22+'Activity 4'!C22+'Activity 5'!C22+'Activity 6'!C22+'Activity 7'!C22+'Activity 8'!C22 -> 77001.795 | D22: ='Program Budget'!G26 -> 2500 | E22: ='Program Budget'!I26 -> 12 | F22: =Admin!F22+'Activity 1'!F22+'Activity 2'!F22+'Activity 3'!F22+'Activity 4'!F22+'Activity 5'!F22+'Activity 6'!F22+'Activity 7'!F22+'Activity 8'!F22 -> 1 | G22: =D22*E22*F22 -> 30000 | H22: =D22*1.05 -> 2625 | I22: ='Program Budget'!L26 -> 12 | J22: =Admin!J22+'Activity 1'!J22+'Activity 2'!J22+'Activity 3'!J22+'Activity 4'!J22+'Activity 5'!J22+'Activity 6'!J22+'Activity 7'!J22+'Activity 8'!J22 -> 1 | K22: =H22*I22*J22 -> 31500 | L22: =H22*1.05 -> 2756.25 | M22: ='Program Budget'!O26 -> 12 | N22: =Admin!N22+'Activity 1'!N22+'Activity 2'!N22+'Activity 3'!N22+'Activity 4'!N22+'Activity 5'!N22+'Activity 6'!N22+'Activity 7'!N22+'Activity 8'!N22 -> 1 | O22: =L22*M22*N22 -> 33075 | P22: =L22*1.05 -> 2894.0625 | Q22: ='Program Budget'!R26 -> 3 | R22: =Admin!R22+'Activity 1'!R22+'Activity 2'!R22+'Activity 3'!R22+'Activity 4'!R22+'Activity 5'!R22+'Activity 6'!R22+'Activity 7'!R22+'Activity 8'!R22 -> 1 | S22: =P22*Q22*R22 -> 8682.1875 | T22: =C22+G22+K22+O22+S22 -> 180258.98
A23: ='Program Budget'!D27 -> M&E Officer | B23: ='Program Budget'!F27 -> Month | C23: =Admin!C23+'Activity 1'!C23+'Activity 2'!C23+'Activity 3'!C23+'Activity 4'!C23+'Activity 5'!C23+'Activity 6'!C23+'Activity 7'!C23+'Activity 8'!C23 -> 48959.525 | D23: ='Program Budget'!G27 -> 1000 | E23: ='Program Budget'!I27 -> 12 | F23: =Admin!F23+'Activity 1'!F23+'Activity 2'!F23+'Activity 3'!F23+'Activity 4'!F23+'Activity 5'!F23+'Activity 6'!F23+'Activity 7'!F23+'Activity 8'!F23 -> 1 | G23: =D23*E23*F23 -> 12000 | H23: =D23*1.05 -> 1050 | I23: ='Program Budget'!L27 -> 12 | J23: =Admin!J23+'Activity 1'!J23+'Activity 2'!J23+'Activity 3'!J23+'Activity 4'!J23+'Activity 5'!J23+'Activity 6'!J23+'Activity 7'!J23+'Activity 8'!J23 -> 1 | K23: =H23*I23*J23 -> 12600 | L23: =H23*1.05 -> 1102.5 | M23: ='Program Budget'!O27 -> 12 | N23: =Admin!N23+'Activity 1'!N23+'Activity 2'!N23+'Activity 3'!N23+'Activity 4'!N23+'Activity 5'!N23+'Activity 6'!N23+'Activity 7'!N23+'Activity 8'!N23 -> 1 | O23: =L23*M23*N23 -> 13230 | P23: =L23*1.05 -> 1157.625 | Q23: ='Program Budget'!R27 -> 3 | R23: =Admin!R23+'Activity 1'!R23+'Activity 2'!R23+'Activity 3'!R23+'Activity 4'!R23+'Activity 5'!R23+'Activity 6'!R23+'Activity 7'!R23+'Activity 8'!R23 -> 1 | S23: =P23*Q23*R23 -> 3472.875 | T23: =C23+G23+K23+O23+S23 -> 90262.4
A24: ='Program Budget'!D28 -> Partnerships and Investment Director | B24: ='Program Budget'!F28 -> Month | C24: =Admin!C24+'Activity 1'!C24+'Activity 2'!C24+'Activity 3'!C24+'Activity 4'!C24+'Activity 5'!C24+'Activity 6'!C24+'Activity 7'!C24+'Activity 8'!C24 -> 235574.48 | D24: ='Program Budget'!G28 -> 4583.3333 | E24: ='Program Budget'!I28 -> 12 | F24: =Admin!F24+'Activity 1'!F24+'Activity 2'!F24+'Activity 3'!F24+'Activity 4'!F24+'Activity 5'!F24+'Activity 6'!F24+'Activity 7'!F24+'Activity 8'!F24 -> 1 | G24: =D24*E24*F24 -> 55000 | H24: =D24*1.05 -> 4812.5 | I24: ='Program Budget'!L28 -> 12 | J24: =Admin!J24+'Activity 1'!J24+'Activity 2'!J24+'Activity 3'!J24+'Activity 4'!J24+'Activity 5'!J24+'Activity 6'!J24+'Activity 7'!J24+'Activity 8'!J24 -> 1 | K24: =H24*I24*J24 -> 57750 | L24: =H24*1.05 -> 5053.125 | M24: ='Program Budget'!O28 -> 12 | N24: =Admin!N24+'Activity 1'!N24+'Activity 2'!N24+'Activity 3'!N24+'Activity 4'!N24+'Activity 5'!N24+'Activity 6'!N24+'Activity 7'!N24+'Activity 8'!N24 -> 1 | O24: =L24*M24*N24 -> 60637.5 | P24: =L24*1.05 -> 5305.7812 | Q24: ='Program Budget'!R28 -> 0 | R24: =Admin!R24+'Activity 1'!R24+'Activity 2'!R24+'Activity 3'!R24+'Activity 4'!R24+'Activity 5'!R24+'Activity 6'!R24+'Activity 7'!R24+'Activity 8'!R24 -> 1 | S24: =P24*Q24*R24 -> 0 | T24: =C24+G24+K24+O24+S24 -> 408961.98
A25: ='Program Budget'!D29 -> Partnerships and Investment Specialist | B25: ='Program Budget'!F29 -> Month | C25: =Admin!C25+'Activity 1'!C25+'Activity 2'!C25+'Activity 3'!C25+'Activity 4'!C25+'Activity 5'!C25+'Activity 6'!C25+'Activity 7'!C25+'Activity 8'!C25 -> 0 | D25: ='Program Budget'!G29 -> 1750 | E25: ='Program Budget'!I29 -> 12 | F25: =Admin!F25+'Activity 1'!F25+'Activity 2'!F25+'Activity 3'!F25+'Activity 4'!F25+'Activity 5'!F25+'Activity 6'!F25+'Activity 7'!F25+'Activity 8'!F25 -> 1 | G25: =D25*E25*F25 -> 21000 | H25: =D25*1.05 -> 1837.5 | I25: ='Program Budget'!L29 -> 12 | J25: =Admin!J25+'Activity 1'!J25+'Activity 2'!J25+'Activity 3'!J25+'Activity 4'!J25+'Activity 5'!J25+'Activity 6'!J25+'Activity 7'!J25+'Activity 8'!J25 -> 1 | K25: =H25*I25*J25 -> 22050 | L25: =H25*1.05 -> 1929.375 | M25: ='Program Budget'!O29 -> 12 | N25: =Admin!N25+'Activity 1'!N25+'Activity 2'!N25+'Activity 3'!N25+'Activity 4'!N25+'Activity 5'!N25+'Activity 6'!N25+'Activity 7'!N25+'Activity 8'!N25 -> 1 | O25: =L25*M25*N25 -> 23152.5 | P25: =L25*1.05 -> 2025.8438 | Q25: ='Program Budget'!R29 -> 0 | R25: =Admin!R25+'Activity 1'!R25+'Activity 2'!R25+'Activity 3'!R25+'Activity 4'!R25+'Activity 5'!R25+'Activity 6'!R25+'Activity 7'!R25+'Activity 8'!R25 -> 1 | S25: =P25*Q25*R25 -> 0 | T25: =C25+G25+K25+O25+S25 -> 66202.5
A26: ='Program Budget'!D30 -> Organizational Strengthening Specialist | B26: ='Program Budget'!F30 -> Month | C26: =Admin!C26+'Activity 1'!C26+'Activity 2'!C26+'Activity 3'!C26+'Activity 4'!C26+'Activity 5'!C26+'Activity 6'!C26+'Activity 7'!C26+'Activity 8'!C26 -> 0 | D26: ='Program Budget'!G30 -> 1750 | E26: ='Program Budget'!I30 -> 12 | F26: =Admin!F26+'Activity 1'!F26+'Activity 2'!F26+'Activity 3'!F26+'Activity 4'!F26+'Activity 5'!F26+'Activity 6'!F26+'Activity 7'!F26+'Activity 8'!F26 -> 1 | G26: =D26*E26*F26 -> 21000 | H26: =D26*1.05 -> 1837.5 | I26: ='Program Budget'!L30 -> 12 | J26: =Admin!J26+'Activity 1'!J26+'Activity 2'!J26+'Activity 3'!J26+'Activity 4'!J26+'Activity 5'!J26+'Activity 6'!J26+'Activity 7'!J26+'Activity 8'!J26 -> 1 | K26: =H26*I26*J26 -> 22050 | L26: =H26*1.05 -> 1929.375 | M26: ='Program Budget'!O30 -> 12 | N26: =Admin!N26+'Activity 1'!N26+'Activity 2'!N26+'Activity 3'!N26+'Activity 4'!N26+'Activity 5'!N26+'Activity 6'!N26+'Activity 7'!N26+'Activity 8'!N26 -> 1 | O26: =L26*M26*N26 -> 23152.5 | P26: =L26*1.05 -> 2025.8438 | Q26: ='Program Budget'!R30 -> 0 | R26: =Admin!R26+'Activity 1'!R26+'Activity 2'!R26+'Activity 3'!R26+'Activity 4'!R26+'Activity 5'!R26+'Activity 6'!R26+'Activity 7'!R26+'Activity 8'!R26 -> 1 | S26: =P26*Q26*R26 -> 0 | T26: =C26+G26+K26+O26+S26 -> 66202.5
A27: ='Program Budget'!D31 -> Value Chain Strengthening Director | B27: ='Program Budget'!F31 -> Month | C27: =Admin!C27+'Activity 1'!C27+'Activity 2'!C27+'Activity 3'!C27+'Activity 4'!C27+'Activity 5'!C27+'Activity 6'!C27+'Activity 7'!C27+'Activity 8'!C27 -> 0 | D27: ='Program Budget'!G31 -> 0 | E27: ='Program Budget'!I31 -> 12 | F27: =Admin!F27+'Activity 1'!F27+'Activity 2'!F27+'Activity 3'!F27+'Activity 4'!F27+'Activity 5'!F27+'Activity 6'!F27+'Activity 7'!F27+'Activity 8'!F27 -> 1 | G27: =D27*E27*F27 -> 0 | H27: =D27*1.05 -> 0 | I27: ='Program Budget'!L31 -> 12 | J27: =Admin!J27+'Activity 1'!J27+'Activity 2'!J27+'Activity 3'!J27+'Activity 4'!J27+'Activity 5'!J27+'Activity 6'!J27+'Activity 7'!J27+'Activity 8'!J27 -> 1 | K27: =H27*I27*J27 -> 0 | L27: =H27*1.05 -> 0 | M27: ='Program Budget'!O31 -> 12 | N27: =Admin!N27+'Activity 1'!N27+'Activity 2'!N27+'Activity 3'!N27+'Activity 4'!N27+'Activity 5'!N27+'Activity 6'!N27+'Activity 7'!N27+'Activity 8'!N27 -> 1 | O27: =L27*M27*N27 -> 0 | P27: =L27*1.05 -> 0 | Q27: ='Program Budget'!R31 -> 4 | R27: =Admin!R27+'Activity 1'!R27+'Activity 2'!R27+'Activity 3'!R27+'Activity 4'!R27+'Activity 5'!R27+'Activity 6'!R27+'Activity 7'!R27+'Activity 8'!R27 -> 1 | S27: =P27*Q27*R27 -> 0 | T27: =C27+G27+K27+O27+S27 -> 0
A28: ='Program Budget'!D32 -> Communications Specialist | B28: ='Program Budget'!F32 -> Month | C28: =Admin!C28+'Activity 1'!C28+'Activity 2'!C28+'Activity 3'!C28+'Activity 4'!C28+'Activity 5'!C28+'Activity 6'!C28+'Activity 7'!C28+'Activity 8'!C28 -> 0 | D28: ='Program Budget'!G32 -> 1750 | E28: ='Program Budget'!I32 -> 12 | F28: =Admin!F28+'Activity 1'!F28+'Activity 2'!F28+'Activity 3'!F28+'Activity 4'!F28+'Activity 5'!F28+'Activity 6'!F28+'Activity 7'!F28+'Activity 8'!F28 -> 1 | G28: =D28*E28*F28 -> 21000 | H28: =D28*1.05 -> 1837.5 | I28: ='Program Budget'!L32 -> 12 | J28: =Admin!J28+'Activity 1'!J28+'Activity 2'!J28+'Activity 3'!J28+'Activity 4'!J28+'Activity 5'!J28+'Activity 6'!J28+'Activity 7'!J28+'Activity 8'!J28 -> 1 | K28: =H28*I28*J28 -> 22050 | L28: =H28*1.05 -> 1929.375 | M28: ='Program Budget'!O32 -> 12 | N28: =Admin!N28+'Activity 1'!N28+'Activity 2'!N28+'Activity 3'!N28+'Activity 4'!N28+'Activity 5'!N28+'Activity 6'!N28+'Activity 7'!N28+'Activity 8'!N28 -> 1 | O28: =L28*M28*N28 -> 23152.5 | P28: =L28*1.05 -> 2025.8438 | Q28: ='Program Budget'!R32 -> 0 | R28: =Admin!R28+'Activity 1'!R28+'Activity 2'!R28+'Activity 3'!R28+'Activity 4'!R28+'Activity 5'!R28+'Activity 6'!R28+'Activity 7'!R28+'Activity 8'!R28 -> 1 | S28: =P28*Q28*R28 -> 0 | T28: =C28+G28+K28+O28+S28 -> 66202.5
A29: ='Program Budget'!D33 -> Value Chain Specialist | B29: ='Program Budget'!F33 -> Month | C29: =Admin!C29+'Activity 1'!C29+'Activity 2'!C29+'Activity 3'!C29+'Activity 4'!C29+'Activity 5'!C29+'Activity 6'!C29+'Activity 7'!C29+'Activity 8'!C29 -> 0 | D29: ='Program Budget'!G33 -> 2500 | E29: ='Program Budget'!I33 -> 12 | F29: =Admin!F29+'Activity 1'!F29+'Activity 2'!F29+'Activity 3'!F29+'Activity 4'!F29+'Activity 5'!F29+'Activity 6'!F29+'Activity 7'!F29+'Activity 8'!F29 -> 1 | G29: =D29*E29*F29 -> 30000 | H29: =D29*1.05 -> 2625 | I29: ='Program Budget'!L33 -> 12 | J29: =Admin!J29+'Activity 1'!J29+'Activity 2'!J29+'Activity 3'!J29+'Activity 4'!J29+'Activity 5'!J29+'Activity 6'!J29+'Activity 7'!J29+'Activity 8'!J29 -> 1 | K29: =H29*I29*J29 -> 31500 | L29: =H29*1.05 -> 2756.25 | M29: ='Program Budget'!O33 -> 12 | N29: =Admin!N29+'Activity 1'!N29+'Activity 2'!N29+'Activity 3'!N29+'Activity 4'!N29+'Activity 5'!N29+'Activity 6'!N29+'Activity 7'!N29+'Activity 8'!N29 -> 1 | O29: =L29*M29*N29 -> 33075 | P29: =L29*1.05 -> 2894.0625 | Q29: ='Program Budget'!R33 -> 0 | R29: =Admin!R29+'Activity 1'!R29+'Activity 2'!R29+'Activity 3'!R29+'Activity 4'!R29+'Activity 5'!R29+'Activity 6'!R29+'Activity 7'!R29+'Activity 8'!R29 -> 1 | S29: =P29*Q29*R29 -> 0 | T29: =C29+G29+K29+O29+S29 -> 94575
A30: ='Program Budget'!D34 -> Contracts & Compliance Director | B30: ='Program Budget'!F34 -> Month | C30: =Admin!C30+'Activity 1'!C30+'Activity 2'!C30+'Activity 3'!C30+'Activity 4'!C30+'Activity 5'!C30+'Activity 6'!C30+'Activity 7'!C30+'Activity 8'!C30 -> 166155.63 | D30: ='Program Budget'!G34 -> 4583.3333 | E30: ='Program Budget'!I34 -> 12 | F30: =Admin!F30+'Activity 1'!F30+'Activity 2'!F30+'Activity 3'!F30+'Activity 4'!F30+'Activity 5'!F30+'Activity 6'!F30+'Activity 7'!F30+'Activity 8'!F30 -> 1 | G30: =D30*E30*F30 -> 55000 | H30: =D30*1.05 -> 4812.5 | I30: ='Program Budget'!L34 -> 12 | J30: =Admin!J30+'Activity 1'!J30+'Activity 2'!J30+'Activity 3'!J30+'Activity 4'!J30+'Activity 5'!J30+'Activity 6'!J30+'Activity 7'!J30+'Activity 8'!J30 -> 1 | K30: =H30*I30*J30 -> 57750 | L30: =H30*1.05 -> 5053.125 | M30: ='Program Budget'!O34 -> 12 | N30: =Admin!N30+'Activity 1'!N30+'Activity 2'!N30+'Activity 3'!N30+'Activity 4'!N30+'Activity 5'!N30+'Activity 6'!N30+'Activity 7'!N30+'Activity 8'!N30 -> 1 | O30: =L30*M30*N30 -> 60637.5 | P30: =L30*1.05 -> 5305.7812 | Q30: ='Program Budget'!R34 -> 3 | R30: =Admin!R30+'Activity 1'!R30+'Activity 2'!R30+'Activity 3'!R30+'Activity 4'!R30+'Activity 5'!R30+'Activity 6'!R30+'Activity 7'!R30+'Activity 8'!R30 -> 1 | S30: =P30*Q30*R30 -> 15917.344 | T30: =C30+G30+K30+O30+S30 -> 355460.47
