Workbook
Name agentfee: #REF!
Name agentfee: Assumptions!$D$51
Name avrent: #REF!
Name avrent: Assumptions!$D$93
Name Category: #REF!
Name Check25: 'SF424'!$A$5
Name Check26: 'SF424'!$A$6
Name Check27: 'SF424'!$A$7
Name Check28: 'SF424'!$D$5
Name Check29: 'SF424'!$D$6
Name Check30: 'SF424'!$D$7
Name Check32: 'SF424'!$A$126
Name Check33: 'SF424'!$A$127
Name Check35: 'SF424'!$A$129
Name Check36: 'SF424'!$A$131
Name coffee: #REF!
Name coffee: Assumptions!$D$90
Name consairfare: #REF!
Name consairfare: Assumptions!$D$76
Name consground: #REF!
Name consground: Assumptions!$D$77
Name conslodg: #REF!
Name conslodg: Assumptions!$D$78
Name consmeals: #REF!
Name consmeals: Assumptions!$D$79
Name consmisc: #REF!
Name consmisc: Assumptions!$D$80
Name DL_Country: '[1]Line-Item Budget'!#REF!
Name DL_Country: #REF!
Name DL_TotalDOL: #REF!
Name Dropdown1: 'SF424'!$G$5
Name Dropdown2: 'SF424'!#REF!
Name EQ_Country: '[1]Line-Item Budget'!#REF!
Name EQ_Country: #REF!
Name EQ_TotalDOL: '[1]Line-Item Budget'!#REF!
Name EQ_TotalDOL: #REF!
Name er: #REF!
Name er: Assumptions!$B$13
Name ground: #REF!
Name ground: Assumptions!$D$55
Name inmuniz: #REF!
Name inmuniz: Assumptions!$D$53
Name intairfare: #REF!
Name intairfare: Assumptions!$D$48
Name intcalls: #REF!
Name intcalls: Assumptions!#REF!
Name intcons: #REF!
Name intcons: Assumptions!$D$73
Name intmisc: #REF!
Name intmisc: Assumptions!$D$56
Name livingq: #REF!
Name livingq: Assumptions!#REF!
Name Local_transport_part: [1]Assumptions!$B$10:$D$10
Name localairfare: #REF!
Name localairfare: Assumptions!$D$69
Name localcons: #REF!
Name localcons: Assumptions!$D$75
Name locallodg: #REF!
Name locallodg: Assumptions!$D$66
Name localmeals: #REF!

Sheet Assumptions
A1: GENERAL ASSUMPTIONS
A3: Header Information:
B4: Partners of America
B5: DONOR: | C5: USDOL
B6: Country: | C6: Ecuador
B7: Program Name: | C7: Project to Improve Adherence to International Labor Standards in the Agricultural Sector in Ecuador
B8: Grant Number: | C8: FOA-ILAB-23-28
B9: Period of Performance: | C9: 48 months | F9: to
A11: Rates:
B12: 0.2828 | C12: NICRA - POA
B13: 0 | C13: Exchange Rate
B14: Inflation - US Based Goods/Services | C14: 1.03
B15: Inflation - Locally Purchased Goods/Services | C15: 1.04
B16: Merit Based Increases for HO & Field Staff | C16: 1.05
A19: ODC Escalation
B20: Escalation Percentage: | D20: 0.03 | G20: Year 1 | H20: Year 2 | I20: Year 3 | J20: Year 2 | M20: Year 3 | N20: Year 2 | O20: Year 2 | P20: Year 4 | Q20: Year 2 | R20: Year 2 | S20: Year 5 | T20: Year 2 | U20: Year 2 | V20: Year 6 | W20: Year 2 | X20: Year 2 | Y20: Year 7 | Z20: Year 2 | AA20: Year 2 | AB20: Year 8 | AC20: Year 2 | AD20: Year 2 | AE20: Year 9 | AF20: Year 2 | AG20: Year 2 | AH20: Year 10
G21: 45292
G22: 45657
G23: 1 | J23: =G23*SUM(1+$D$20) -> 1.03 | M23: =J23*SUM(1+$D$20) -> 1.0609 | P23: =M23*SUM(1+$D$20) -> 1.092727 | S23: =P23*SUM(1+$D$20) -> 1.1255088 | V23: =S23*SUM(1+$D$20) -> 1.1592741 | Y23: =V23*SUM(1+$D$20) -> 1.1940523 | AB23: =Y23*SUM(1+$D$20) -> 1.2298739 | AE23: =AB23*SUM(1+$D$20) -> 1.2667701 | AH23: =AE23*SUM(1+$D$20) -> 1.3047732
A26: Annual Salary Increases for International Staff
A28: Standard Increase Percentage: | D28: 0.04
A29: Annual Salary Escalation Date: | D29: 45566
M30: Percent | S30: Increase Factor | AB30: Percent | AH30: Increase Factor
B32: Year 1 | C32: =G21 -> 45292 | D32: =D29 -> 45566 | E32: =ROUND((D32-C32)/30,0) -> 9 | F32: / | G32: 12 | J32: @ | M32: 0 | P32: =E32/G32*M32 -> 0 | V32: 12 | Y32: @ | AB32: 0 | AE32: =T32/V32*AB32 -> 0
E33: =12-E32 -> 3 | F33: / | G33: 12 | J33: @ | M33: =IF(M32=0,D28,SUM(M32+1)*SUM(1+D28)-1) -> 0.04 | P33: =E33/G33*M33 -> 0.01 | S33: =SUM(1+SUM(P32:P33)) -> 1.01 | V33: 12 | Y33: @ | AB33: =IF(AB32=0,S28,SUM(AB32+1)*SUM(1+S28)-1) -> 0 | AE33: =T33/V33*AB33 -> 0 | AH33: =SUM(1+SUM(AE32:AE33)) -> 1
A35: Annual Salary Increases for Local Staff
A37: Standard Increase Percentage: | D37: 0.05
A38: Annual Salary Escalation Date: | D38: 45474
M39: Percent | S39: Increase Factor | AB39: Percent | AH39: Increase Factor
B41: Year 1 | C41: =G21 -> 45292 | D41: =D38 -> 45474 | E41: =ROUND((D41-C41)/30,0) -> 6 | F41: / | G41: 12 | J41: @ | M41: 0 | P41: =E41/G41*M41 -> 0 | V41: 12 | Y41: @ | AB41: 0 | AE41: =T41/V41*AB41 -> 0
E42: =12-E41 -> 6 | F42: / | G42: 12 | J42: @ | M42: =IF(M41=0,D37,SUM(M41+1)*SUM(1+D38)-1) -> 0.05 | P42: =E42/G42*M42 -> 0.025 | S42: =SUM(1+SUM(P41:P42)) -> 1.025 | V42: 12 | Y42: @ | AB42: =IF(AB41=0,S37,SUM(AB41+1)*SUM(1+S38)-1) -> 0 | AE42: =T42/V42*AB42 -> 0 | AH42: =SUM(1+SUM(AE41:AE42)) -> 1
B46: International Travel | C46: Cell Name | D46: Unit Cost | E46: Base
B47: Quito
B48: Airfare | C48: intairfare | E48: round trip coach
B49: Lodging | C49: usaidlodg | D49: 200 | E49: per night
B50: Meals and Incidentals | C50: usaidmeals | D50: 119 | E50: per day
B51: Agent fee | C51: agentfee | E51: per ticket
B52: Visa | C52: visa | D52: 150
B53: Inmunizations | C53: inmuniz | D53: 150
B54: Medex | C54: medex
...

Sheet Budget Summary
A1: Project Budget Summary
A2: Partners of the Americas
A3: Project to Improve Adherence to International Labor Standards in the Agricultural Sector in Ecuador Improve Adherence to International Labor Standards in the Agricultural Sector in Ecuador
A4: 48 Months
A6: BUDGET SUMMARY CATEGORIES | B6: YEAR 1 | C6: YEAR 2 | D6: YEAR 3 | E6: YEAR 4 | F6: TOTAL FEDERAL FUNDS REQUESTED
A8: 1. PERSONNEL | B8: ='Line-Item Budget'!J29 -> 300905 | C8: ='Line-Item Budget'!L29 -> 375921 | D8: ='Line-Item Budget'!N29 -> 394717.05 | E8: ='Line-Item Budget'!P29 -> 375790.16 | F8: =SUM(B8:E8) -> 1447333.2
A9: 2. FRINGE BENEFITS | B9: ='Line-Item Budget'!J36 -> 128207.47 | C9: ='Line-Item Budget'!L36 -> 155066.69 | D9: ='Line-Item Budget'!N36 -> 162820.03 | E9: ='Line-Item Budget'!P36 -> 154208.46 | F9: =SUM(B9:E9) -> 600302.65
A10: 3. TRAVEL | B10: ='Line-Item Budget'!J54 -> 6938 | C10: ='Line-Item Budget'!L54 -> 42561.48 | D10: ='Line-Item Budget'!N54 -> 42194.838 | E10: ='Line-Item Budget'!P54 -> 33203.173 | F10: =SUM(B10:E10) -> 124897.49
A11: 4. EQUIPMENT | B11: ='Line-Item Budget'!J58 -> 0 | C11: ='Line-Item Budget'!L58 -> 0 | D11: ='Line-Item Budget'!N58 -> 0 | E11: ='Line-Item Budget'!P58 -> 0 | F11: =SUM(B11:E11) -> 0
A12: 5. SUPPLIES | B12: ='Line-Item Budget'!J63 -> 9907.2 | C12: ='Line-Item Budget'!L63 -> 1560 | D12: ='Line-Item Budget'!N63 -> 1622.4 | E12: ='Line-Item Budget'!P63 -> 1687.296 | F12: =SUM(B12:E12) -> 14776.896
A13: 6. CONTRACTUAL | B13: ='Line-Item Budget'!J72 -> 144056.5 | C13: ='Line-Item Budget'!L72 -> 259736.74 | D13: ='Line-Item Budget'!N72 -> 282479.41 | E13: ='Line-Item Budget'!P72 -> 164016.89 | F13: =SUM(B13:E13) -> 850289.54
A14: 7. CONSTRUCTION | B14: 0 | C14: 0 | D14: 0 | E14: 0 | F14: =SUM(B14:E14) -> 0
A15: 8. OTHER DIRECT COSTS | B15: ='Line-Item Budget'!J142 -> 176625.2 | C15: ='Line-Item Budget'!L142 -> 190655.96 | D15: ='Line-Item Budget'!N142 -> 151871.03 | E15: ='Line-Item Budget'!P142 -> 138290.45 | F15: =SUM(B15:E15) -> 657442.64
A17: 9. TOTAL DIRECT COSTS (Lines 1-8) | B17: =SUM(B8:B15) -> 766639.36 | C17: =SUM(C8:C15) -> 1025501.9 | D17: =SUM(D8:D15) -> 1035704.8 | E17: =SUM(E8:E15) -> 867196.43 | F17: =SUM(F8:F15) -> 3695042.4
A18: 10. INDIRECT COSTS | B18: ='Line-Item Budget'!J146 -> 216805.61 | C18: ='Line-Item Budget'!L146 -> 290011.93 | D18: ='Line-Item Budget'!N146 -> 292897.3 | E18: ='Line-Item Budget'!P146 -> 245243.15 | F18: =SUM(B18:E18) -> 1044958
A19: 11. TOTAL COSTS (Lines 9-10) | B19: =SUM(B17:B18) -> 983444.98 | C19: =SUM(C17:C18) -> 1315513.8 | D19: =SUM(D17:D18) -> 1328602.1 | E19: =SUM(E17:E18) -> 1112439.6 | F19: =SUM(F17:F18) -> 4740000.4

Sheet Line-Item Budget
D1: Project Line-Item Budget
D2: Partners of the Americas
D3: Project to Improve Adherence to International Labor Standards in the Agricultural Sector in Ecuador Improve Adherence to International Labor Standards in the Agricultural Sector in Ecuador
D4: 48 Months
A5: Entity: | B5: P | D5: Cost Assumptions
A6: Program-Dept.: | B6: 20200 | D6: Inflation - US Based Goods/Services | E6: 1.03
A7: Funder-Grant: | B7: DOL427 | D7: Inflation - Locally Purchased Goods/Services | E7: 1.04
D8: Merit Based Increases for HO & Field Staff | E8: 1.05
A10: Activity Code | B10: Account Code | C10: Country Code | D10: BUDGET ITEM | E10: CATEGORY | F10: LOE | G10: UNIT | H10: # of Units | I10: RATE / UNIT | J10: Year 1 | K10: # of Units | L10: Year 2 | M10: # of Units | N10: Year 3 | O10: # of Units | P10: Year 4 | Q10: TOTAL DOL | R10: TOTAL COST SHARING | S10: PROJECT GRAND TOTAL
D11: Personnel
D12: Key Personnel
A13: PERSNL-PD | B13: 70000 | C13: ECU | D13: Project Director (100%) - Alexis Naranjo | E13: Salaries | F13: 1 | G13: Month | H13: 12 | I13: =72000/12 -> 6000 | J13: =H13*I13*F13 -> 72000 | K13: 12 | L13: =K13*I13*$E$8 -> 75600 | M13: 12 | N13: =(M13*I13*$E$8*$E$8) -> 79380 | O13: 12 | P13: =O13*I13*$E$8*$E$8*$E$8 -> 83349 | Q13: =SUM(J13+L13+N13+P13) -> 310329 | R13: 0 | S13: =SUM(Q13:R13) -> 310329
A14: PERSNL-M&E | B14: 70000 | C14: ECU | D14: Monitoring and Evaluation (M&E) Officer (100%) - Mónica Rentería | E14: Salaries | F14: 1 | G14: Month | H14: 12 | I14: =40000/12 -> 3333.3333 | J14: =H14*I14*F14 -> 40000 | K14: 12 | L14: =K14*I14*$E$8 -> 42000 | M14: 12 | N14: =(M14*I14*$E$8*$E$8) -> 44100 | O14: 12 | P14: =O14*I14*$E$8*$E$8*$E$8 -> 46305 | Q14: =SUM(J14+L14+N14+P14) -> 172405 | R14: 0 | S14: =SUM(Q14:R14) -> 172405
D16: Other Professional Personnel
A17: PERSNL-PSL | B17: 70000 | C17: ECU | D17: Public Sector Liaison (100%)- Luis Almagor | E17: Salaries | F17: 1 | G17: Month | H17: 9 | I17: =35000/12 -> 2916.6667 | J17: =H17*I17*F17 -> 26250 | K17: 12 | L17: =K17*I17*$E$8 -> 36750 | M17: 12 | N17: =(M17*I17*$E$8*$E$8) -> 38587.5 | O17: 9 | P17: =O17*I17*$E$8*$E$8*$E$8 -> 30387.656 | Q17: =SUM(J17+L17+N17+P17) -> 131975.16 | R17: 0 | S17: =SUM(Q17:R17) -> 131975.16
A18: PERSNL-COM | B18: 70000 | C18: ECU | D18: Communications Specialist (100%) - Emilia Bayas | E18: Salaries | F18: 1 | G18: Month | H18: 9 | I18: 1979 | J18: =H18*I18*F18 -> 17811 | K18: 12 | L18: =K18*I18*$E$8 -> 24935.4 | M18: 12 | N18: =(M18*I18*$E$8*$E$8) -> 26182.17 | O18: 9 | P18: =O18*I18*$E$8*$E$8*$E$8 -> 20618.459 | Q18: =SUM(J18+L18+N18+P18) -> 89547.029 | R18: 0 | S18: =SUM(Q18:R18) -> 89547.029
A19: PERSNL-SAF | B19: 70000 | C19: ECU | D19: Occupational Safety and Health Specialist (100%) - César Ávila | E19: Salaries | F19: 1 | G19: Month | H19: 9 | I19: =35000/12 -> 2916.6667 | J19: =H19*I19*F19 -> 26250 | K19: 12 | L19: =K19*I19*$E$8 -> 36750 | M19: 12 | N19: =(M19*I19*$E$8*$E$8) -> 38587.5 | O19: 9 | P19: =O19*I19*$E$8*$E$8*$E$8 -> 30387.656 | Q19: =SUM(J19+L19+N19+P19) -> 131975.16 | R19: 0 | S19: =SUM(Q19:R19) -> 131975.16
A20: PERSNL-F&A | B20: 70000 | C20: ECU | D20: Finance & Administration Manager (100%) | E20: Salaries | F20: 1 | G20: Month | H20: 12 | I20: 4355 | J20: =H20*I20*F20 -> 52260 | K20: 12 | L20: =K20*I20*$E$8 -> 54873 | M20: 12 | N20: =(M20*I20*$E$8*$E$8) -> 57616.65 | O20: 12 | P20: =O20*I20*$E$8*$E$8*$E$8 -> 60497.483 | Q20: =SUM(J20+L20+N20+P20) -> 225247.13 | R20: 0 | S20: =SUM(Q20:R20) -> 225247.13
A21: PERSNL-OPS | B21: 70000 | C21: ECU | D21: Operations Coordinator (100%) | E21: Salaries | F21: 1 | G21: Month | H21: 12 | I21: =34000/12 -> 2833.3333 | J21: =H21*I21*F21 -> 34000 | K21: 12 | L21: =K21*I21*$E$8 -> 35700 | M21: 12 | N21: =(M21*I21*$E$8*$E$8) -> 37485 | O21: 11 | P21: =O21*I21*$E$8*$E$8*$E$8 -> 36079.313 | Q21: =SUM(J21+L21+N21+P21) -> 143264.31 | R21: 0 | S21: =SUM(Q21:R21) -> 143264.31
A22: PERSNL-RCC | B22: 70000 | C22: ECU | D22: Regional Coordinator 1, Cotopaxi (100%) | E22: Salaries | F22: 1 | G22: Month | H22: 9 | I22: =15000/12-62 -> 1188 | J22: =H22*I22*F22 -> 10692 | K22: 12 | L22: =K22*I22*$E$8 -> 14968.8 | M22: 12 | N22: =(M22*I22*$E$8*$E$8) -> 15717.24 | O22: 9 | P22: =O22*I22*$E$8*$E$8*$E$8 -> 12377.327 | Q22: =SUM(J22+L22+N22+P22) -> 53755.367 | R22: 0 | S22: =SUM(Q22:R22) -> 53755.367
A23: PERSNL-RCO | B23: 70000 | C23: ECU | D23: Regional Coordinator 2, El Oro (100%) | E23: Salaries | F23: 1 | G23: Month | H23: 9 | I23: =15000/12-62 -> 1188 | J23: =H23*I23*F23 -> 10692 | K23: 12 | L23: =K23*I23*$E$8 -> 14968.8 | M23: 12 | N23: =(M23*I23*$E$8*$E$8) -> 15717.24 | O23: 9 | P23: =O23*I23*$E$8*$E$8*$E$8 -> 12377.327 | Q23: =SUM(J23+L23+N23+P23) -> 53755.367 | R23: 0 | S23: =SUM(Q23:R23) -> 53755.367
D25: Home Office Support
A26: PERSNL-PM | B26: 50000 | C26: USA | D26: Project Manager (10%) | E26: Salaries | F26: 0.1 | G26: Month | H26: 12 | I26: =(135000/12)*0.1 -> 1125 | J26: =H26*I26*F26 -> 1350 | K26: 12 | L26: =K26*I26*$E$8 -> 14175 | M26: 12 | N26: =(M26*I26*$E$8*$E$8) -> 14883.75 | O26: 12 | P26: =O26*I26*$E$8*$E$8*$E$8 -> 15627.938 | Q26: =SUM(J26+L26+N26+P26) -> 46036.688 | R26: 0 | S26: =SUM(Q26:R26) -> 46036.688
A27: PERSNL-PO | B27: 50000 | C27: USA | D27: Program Officer (40%) | E27: Salaries | F27: 0.4 | G27: Month | H27: 12 | I27: =(60000/12)*0.4 -> 2000 | J27: =H27*I27*F27 -> 9600 | K27: 12 | L27: =K27*I27*$E$8 -> 25200 | M27: 12 | N27: =(M27*I27*$E$8*$E$8) -> 26460 | O27: 12 | P27: =O27*I27*$E$8*$E$8*$E$8 -> 27783 | Q27: =SUM(J27+L27+N27+P27) -> 89043 | R27: 0 | S27: =SUM(Q27:R27) -> 89043
D29: Total Personnel | J29: =SUM(J13:J27) -> 300905 | L29: =SUM(L13:L27) -> 375921 | N29: =SUM(N13:N27) -> 394717.05 | P29: =SUM(P13:P27) -> 375790.16 | Q29: =SUM(Q13:Q27) -> 1447333.2 | R29: =SUM(R13:R27) -> 0 | S29: =SUM(Q29:R29) -> 1447333.2
D30: Fringe Benefits
D32: Fringe Benefits
A33: FRINGE-EC | B33: 70015 | C33: ECU | D33: Fringe benefits - Ecuador | E33: Fringe Benefits | G33: Month | I33: 0.4333 | J33: =SUM(J13:J23)*$I33 -> 125637.5 | L33: =SUM(L13:L23)*$I33 -> 145825.38 | N33: =SUM(N13:N23)*$I33 -> 153116.65 | P33: =SUM(P13:P23)*$I33 -> 144019.92 | Q33: =SUM(J33+L33+N33+P33) -> 568599.45 | R33: 0 | S33: =SUM(Q33:R33) -> 568599.45
A34: FRINGE | B34: 50900 | C34: USA | D34: Fringe benefits - Home Office Support | E34: Fringe Benefits | G34: Month | I34: 0.2347 | J34: =SUM(J26:J27)*$I$34 -> 2569.965 | L34: =SUM(L26:L27)*$I$34 -> 9241.3125 | N34: =SUM(N26:N27)*$I$34 -> 9703.3781 | P34: =SUM(P26:P27)*$I$34 -> 10188.547 | Q34: =SUM(J34+L34+N34+P34) -> 31703.203 | R34: 0 | S34: =SUM(Q34:R34) -> 31703.203
D36: Total Fringe Benefits | J36: =SUM(J33:J35) -> 128207.47 | L36: =SUM(L33:L35) -> 155066.69 | N36: =SUM(N33:N35) -> 162820.03 | P36: =SUM(P33:P35) -> 154208.46 | Q36: =SUM(Q33:Q35) -> 600302.65 | R36: =SUM(R34:R34) -> 0 | S36: =SUM(S33:S35) -> 600302.65
D37: Travel
D38: T1: Post-award Meeting with ILAB
A39: EC.T1.A | B39: 86040 | C39: ECU/USA | D39: Airfare - Ecuador-DC | E39: Travel | G39: Trip | I39: 650 | J39: =H39*I39 -> 0 | K39: 2 | L39: =K39*I39*$E$7 -> 1352 | M39: 0 | N39: =M39*I39*$E$7*$E$7 -> 0 | O39: 0 | P39: =O39*I39*$E$7*$E$7*$E$7 -> 0 | Q39: =SUM(J39+L39+N39+P39) -> 1352 | R39: - | S39: =SUM(Q39:R39) -> 1352
A40: EC.T1.B | B40: 86030 (Lodging)/ 86050 (M&IE) | C40: ECU/USA | D40: Lodging and M&IE in DC | E40: Travel | G40: Day | I40: =(258+79)*90% -> 303.3 | J40: =H40*I40 -> 0 | K40: 10 | L40: =K40*I40*$E$7 -> 3154.32 | M40: 0 | N40: =M40*I40*$E$7*$E$7 -> 0 | O40: 0 | P40: =O40*I40*$E$7*$E$7*$E$7 -> 0 | Q40: =SUM(J40+L40+N40+P40) -> 3154.32 | R40: - | S40: =SUM(Q40:R40) -> 3154.32
A41: EC.T1.C | B41: 86000 | C41: ECU/USA | D41: Local transportation in DC | E41: Travel | G41: Day | I41: 60 | J41: =H41*I41 -> 0 | K41: 10 | L41: =K41*I41*$E$7 -> 624 | M41: 0 | N41: =M41*I41*$E$7*$E$7 -> 0 | O41: 0 | P41: =O41*I41*$E$7*$E$7*$E$7 -> 0 | Q41: =SUM(J41+L41+N41+P41) -> 624 | R41: - | S41: =SUM(Q41:R41) -> 624
A42: EC.T1.D | B42: 86050 | C42: ECU/USA | D42: U.S. Visa Fees | E42: Travel | G42: Trip | I42: 160 | J42: =H42*I42 -> 0 | K42: 2 | L42: =K42*I42*$E$7 -> 332.8 | M42: 0 | N42: =M42*I42*$E$7*$E$7 -> 0 | O42: 0 | P42: =O42*I42*$E$7*$E$7*$E$7 -> 0 | Q42: =SUM(J42+L42+N42+P42) -> 332.8 | R42: - | S42: =SUM(Q42:R42) -> 332.8
D43: T2: Field Personnel Annual Visits with ILAB
A44: EC.T2.A | B44: 86040 | C44: ECU | D44: Airfare - Ecuador-DC | E44: Travel | G44: Trip | H44: 2 | I44: 650 | J44: =H44*I44 -> 1300 | K44: 2 | L44: =K44*I44*$E$7 -> 1352 | M44: 2 | N44: =M44*I44*$E$7*$E$7 -> 1406.08 | O44: 2 | P44: =O44*I44*$E$7*$E$7*$E$7 -> 1462.3232 | Q44: =SUM(J44+L44+N44+P44) -> 5520.4032 | R44: - | S44: =SUM(Q44:R44) -> 5520.4032
A45: EC.T2.B | B45: 86030 (Lodging)/ 86050 (M&IE) | C45: ECU | D45: Lodging and M&IE in DC | E45: Travel | G45: Day | H45: 5 | I45: =(258+79)*90% -> 303.3 | J45: =H45*I45 -> 1516.5 | K45: 10 | L45: =K45*I45*$E$7 -> 3154.32 | M45: 10 | N45: =M45*I45*$E$7*$E$7 -> 3280.4928 | O45: 10 | P45: =O45*I45*$E$7*$E$7*$E$7 -> 3411.7125 | Q45: =SUM(J45+L45+N45+P45) -> 11363.025 | R45: - | S45: =SUM(Q45:R45) -> 11363.025
A46: EC.T2.C | B46: 86000 | C46: ECU | D46: Local transportation in DC | E46: Travel | G46: Day | H46: 5 | I46: 60 | J46: =H46*I46 -> 300 | K46: 10 | L46: =K46*I46*$E$7 -> 624 | M46: 10 | N46: =M46*I46*$E$7*$E$7 -> 648.96 | O46: 10 | P46: =O46*I46*$E$7*$E$7*$E$7 -> 674.9184 | Q46: =SUM(J46+L46+N46+P46) -> 2247.8784 | R46: - | S46: =SUM(Q46:R46) -> 2247.8784
...

Sheet US & Local Summaries
A1: =Assumptions!B4 -> Partners of America
A2: =Assumptions!B5 -> DONOR: | F2: =Assumptions!C5 -> USDOL
A3: =Assumptions!B6 -> Country: | F3: =Assumptions!C6 -> Ecuador
A4: =Assumptions!B7 -> Program Name: | F4: =Assumptions!C7 -> Project to Improve Adherence to International Labor Standards in the Agricultural Sector in Ecuador
A5: =Assumptions!B8 -> Grant Number: | F5: =Assumptions!C8 -> FOA-ILAB-23-28
A6: =Assumptions!B9 -> Period of Performance: | F6: =Assumptions!C9 -> 48 months | I6: =Assumptions!G9 -> 0
A8: US COSTS
A10: Line Item | F10: =#REF! -> #REF! | I10: =#REF! -> #REF! | L10: =#REF! -> #REF! | O10: =#REF! -> #REF! | R10: =#REF! -> #REF! | U10: Total
A12: Salaries | F12: =#REF! -> #REF! | I12: =#REF! -> #REF! | L12: =#REF! -> #REF! | O12: =#REF! -> #REF! | R12: =#REF! -> #REF! | U12: =SUM(F12,I12,L12,O12,R12) -> #REF!
A13: Fringe Benefits | F13: =#REF! -> #REF! | I13: =#REF! -> #REF! | L13: =#REF! -> #REF! | O13: =#REF! -> #REF! | R13: =#REF! -> #REF! | U13: =SUM(F13,I13,L13,O13,R13) -> #REF!
A14: Travel | F14: =#REF! -> #REF! | I14: =#REF! -> #REF! | L14: =#REF! -> #REF! | O14: =#REF! -> #REF! | R14: =#REF! -> #REF! | U14: =SUM(F14,I14,L14,O14,R14) -> #REF!
A15: Equipment | F15: =#REF! -> #REF! | I15: =#REF! -> #REF! | L15: =#REF! -> #REF! | O15: =#REF! -> #REF! | R15: =#REF! -> #REF! | U15: =SUM(F15,I15,L15,O15,R15) -> #REF!
A16: Materials and Supplies | F16: =#REF! -> #REF! | I16: =#REF! -> #REF! | L16: =#REF! -> #REF! | O16: =#REF! -> #REF! | R16: =#REF! -> #REF! | U16: =SUM(F16,I16,L16,O16,R16) -> #REF!
A17: Consultants | F17: =#REF! -> #REF! | I17: =#REF! -> #REF! | L17: =#REF! -> #REF! | O17: =#REF! -> #REF! | R17: =#REF! -> #REF! | U17: =SUM(F17,I17,L17,O17,R17) -> #REF!
A18: Contractual | F18: =#REF! -> #REF! | I18: =#REF! -> #REF! | L18: =#REF! -> #REF! | O18: =#REF! -> #REF! | R18: =#REF! -> #REF! | U18: =SUM(F18,I18,L18,O18,R18) -> #REF!
A19: Other Direct Costs | F19: =#REF! -> #REF! | I19: =#REF! -> #REF! | L19: =#REF! -> #REF! | O19: =#REF! -> #REF! | R19: =#REF! -> #REF! | U19: =SUM(F19,I19,L19,O19,R19) -> #REF!
A20: Subtotal | F20: =#REF! -> #REF! | I20: =#REF! -> #REF! | L20: =#REF! -> #REF! | O20: =#REF! -> #REF! | R20: =#REF! -> #REF! | U20: =SUM(F20,I20,L20,O20,R20) -> #REF!
A22: Service Center (excluding subcontractors) | F22: =#REF! -> #REF! | I22: =#REF! -> #REF! | L22: =#REF! -> #REF! | O22: =#REF! -> #REF! | R22: =#REF! -> #REF! | U22: =SUM(F22,I22,L22,O22,R22) -> #REF!
A23: Service Center on Subcontractors | F23: =#REF! -> #REF! | I23: =#REF! -> #REF! | L23: =#REF! -> #REF! | O23: =#REF! -> #REF! | R23: =#REF! -> #REF! | U23: =SUM(F23,I23,L23,O23,R23) -> #REF!
A25: F&A Costs | F25: =#REF! -> #REF! | I25: =#REF! -> #REF! | L25: =#REF! -> #REF! | O25: =#REF! -> #REF! | R25: =#REF! -> #REF! | U25: =SUM(F25,I25,L25,O25,R25) -> #REF!
A26: F&A Costs (Applied to Subcontracts) | F26: =#REF! -> #REF! | I26: =#REF! -> #REF! | L26: =#REF! -> #REF! | O26: =#REF! -> #REF! | R26: =#REF! -> #REF! | U26: =SUM(F26,I26,L26,O26,R26) -> #REF!
A28: Total per year | F28: =SUM(F20:F27) -> #REF! | I28: =SUM(I20:I27) -> #REF! | L28: =SUM(L20:L27) -> #REF! | O28: =SUM(O20:O27) -> #REF! | R28: =SUM(R20:R27) -> #REF! | U28: =SUM(E28:T28) -> #REF!
A30: IN-COUNTRY COSTS
A32: Line Item | F32: =F10 -> #REF! | I32: =I10 -> #REF! | L32: =L10 -> #REF! | O32: =O10 -> #REF! | R32: =R10 -> #REF! | U32: =U10 -> Total
A34: Salaries | F34: =#REF! -> #REF! | I34: =#REF! -> #REF! | L34: =#REF! -> #REF! | O34: =#REF! -> #REF! | R34: =#REF! -> #REF! | U34: =SUM(F34,I34,L34,O34,R34) -> #REF!
A35: Fringe Benefits | F35: =#REF! -> #REF! | I35: =#REF! -> #REF! | L35: =#REF! -> #REF! | O35: =#REF! -> #REF! | R35: =#REF! -> #REF! | U35: =SUM(F35,I35,L35,O35,R35) -> #REF!
A36: Travel | F36: =#REF! -> #REF! | I36: =#REF! -> #REF! | L36: =#REF! -> #REF! | O36: =#REF! -> #REF! | R36: =#REF! -> #REF! | U36: =SUM(F36,I36,L36,O36,R36) -> #REF!
A37: Equipment | F37: =#REF! -> #REF! | I37: =#REF! -> #REF! | L37: =#REF! -> #REF! | O37: =#REF! -> #REF! | R37: =#REF! -> #REF! | U37: =SUM(F37,I37,L37,O37,R37) -> #REF!
A38: Materials and Supplies | F38: =#REF! -> #REF! | I38: =#REF! -> #REF! | L38: =#REF! -> #REF! | O38: =#REF! -> #REF! | R38: =#REF! -> #REF! | U38: =SUM(F38,I38,L38,O38,R38) -> #REF!
A39: Consultants | F39: =#REF! -> #REF! | I39: =#REF! -> #REF! | L39: =#REF! -> #REF! | O39: =#REF! -> #REF! | R39: =#REF! -> #REF! | U39: =SUM(F39,I39,L39,O39,R39) -> #REF!
A40: Contractual | F40: =#REF! -> #REF! | I40: =#REF! -> #REF! | L40: =#REF! -> #REF! | O40: =#REF! -> #REF! | R40: =#REF! -> #REF! | U40: =SUM(F40,I40,L40,O40,R40) -> #REF!
A41: Other Direct Costs | F41: =#REF! -> #REF! | I41: =#REF! -> #REF! | L41: =#REF! -> #REF! | O41: =#REF! -> #REF! | R41: =#REF! -> #REF! | U41: =SUM(F41,I41,L41,O41,R41) -> #REF!
A42: Subtotal | F42: =#REF! -> #REF! | I42: =#REF! -> #REF! | L42: =#REF! -> #REF! | O42: =#REF! -> #REF! | R42: =#REF! -> #REF! | U42: =SUM(F42,I42,L42,O42,R42) -> #REF!
A44: Service Center (excluding subcontractors) | F44: =#REF! -> #REF! | I44: =#REF! -> #REF! | L44: =#REF! -> #REF! | O44: =#REF! -> #REF! | R44: =#REF! -> #REF! | U44: =SUM(F44,I44,L44,O44,R44) -> #REF!
A45: Service Center on Subcontractors | F45: =#REF! -> #REF! | I45: =#REF! -> #REF! | L45: =#REF! -> #REF! | O45: =#REF! -> #REF! | R45: =#REF! -> #REF! | U45: =SUM(F45,I45,L45,O45,R45) -> #REF!
A47: F&A Costs | F47: =#REF! -> #REF! | I47: =#REF! -> #REF! | L47: =#REF! -> #REF! | O47: =#REF! -> #REF! | R47: =#REF! -> #REF! | U47: =SUM(F47,I47,L47,O47,R47) -> #REF!
A48: F&A Costs (Applied to Subcontracts) | F48: =#REF! -> #REF! | I48: =#REF! -> #REF! | L48: =#REF! -> #REF! | O48: =#REF! -> #REF! | R48: =#REF! -> #REF! | U48: =SUM(F48,I48,L48,O48,R48) -> #REF!
A50: Total per year | F50: =SUM(F42:F49) -> #REF! | I50: =SUM(I42:I49) -> #REF! | L50: =SUM(L42:L49) -> #REF! | O50: =SUM(O42:O49) -> #REF! | R50: =SUM(R42:R49) -> #REF! | U50: =SUM(F50,I50,L50,O50,R50) -> #REF!
A52: Grand Total | F52: =SUM(F50,F28) -> #REF! | I52: =SUM(I50,I28) -> #REF! | L52: =SUM(L50,L28) -> #REF! | O52: =SUM(O50,O28) -> #REF! | R52: =SUM(R50,R28) -> #REF! | U52: =SUM(F52,I52,L52,O52,R52) -> #REF!

Sheet TA Summary
B1: =Assumptions!$B$4 -> Partners of America
B2: =CONCATENATE(Assumptions!$B5," ",Assumptions!$C5) -> DONOR: USDOL
B3: =CONCATENATE(Assumptions!$B6," ",Assumptions!$C6) -> Country: Ecuador
B4: =CONCATENATE(Assumptions!$B7," ",Assumptions!$C7) -> Program Name: Project to Improve Adherence to International Labor Standards in the Agricultural Sector in Ecuador
B5: =CONCATENATE(Assumptions!$B8," ",Assumptions!$C8) -> Grant Number: FOA-ILAB-23-28
B7: TOTAL FUNDING FOR EXPATRIATE AND IN-COUNTRY TECHNICAL ASSISTANCE
B9: Line Item | C9: =#REF! -> #REF! | F9: =#REF! -> #REF! | I9: =#REF! -> #REF! | L9: =#REF! -> #REF! | O9: =#REF! -> #REF! | S9: Total
A11: 6.a | B11: Expatriate Technical Assistance
B12: Program and Technical Staff - US Hires | C12: =SUM(#REF!,#REF!) -> #REF! | F12: =SUM(#REF!,#REF!) -> #REF! | I12: =SUM(#REF!,#REF!) -> #REF! | L12: =SUM(#REF!,#REF!) -> #REF! | O12: =SUM(#REF!,#REF!) -> #REF! | S12: =SUM(C12:O12) -> #REF!
B13: STA US Hires | C13: =SUM(#REF!) -> #REF! | F13: =SUM(#REF!) -> #REF! | I13: =SUM(#REF!) -> #REF! | L13: =SUM(#REF!) -> #REF! | O13: =SUM(#REF!) -> #REF! | S13: =SUM(C13:O13) -> #REF!
B14: Regional Hires | C14: =SUM(#REF!,#REF!) -> #REF! | F14: =SUM(#REF!,#REF!) -> #REF! | I14: =SUM(#REF!,#REF!) -> #REF! | L14: =SUM(#REF!,#REF!) -> #REF! | O14: =SUM(#REF!,#REF!) -> #REF! | S14: =SUM(C14:O14) -> #REF!
B15: International Consultants | C15: =SUM(#REF!) -> #REF! | F15: =SUM(#REF!) -> #REF! | I15: =SUM(#REF!) -> #REF! | L15: =SUM(#REF!) -> #REF! | O15: =SUM(#REF!) -> #REF! | S15: =SUM(C15:O15) -> #REF!
B16: Fringe Benefits US Hires | C16: =SUM(#REF!,#REF!,#REF!) -> #REF! | F16: =SUM(#REF!,#REF!,#REF!) -> #REF! | I16: =SUM(#REF!,#REF!,#REF!) -> #REF! | L16: =SUM(#REF!,#REF!,#REF!) -> #REF! | O16: =SUM(#REF!,#REF!,#REF!) -> #REF! | S16: =SUM(C16:O16) -> #REF!
B17: Fringe Benefits Regional Hires | C17: =SUM(#REF!) -> #REF! | F17: =SUM(#REF!) -> #REF! | I17: =SUM(#REF!) -> #REF! | L17: =SUM(#REF!) -> #REF! | O17: =SUM(#REF!) -> #REF! | S17: =SUM(C17:O17) -> #REF!
B18: Allowances | C18: =SUM(#REF!) -> #REF! | F18: =SUM(#REF!) -> #REF! | I18: =SUM(#REF!) -> #REF! | L18: =SUM(#REF!) -> #REF! | O18: =SUM(#REF!) -> #REF! | S18: =SUM(C18:O18) -> #REF!
B19: International Travel | C19: =#REF! -> #REF! | F19: =#REF! -> #REF! | I19: =#REF! -> #REF! | L19: =#REF! -> #REF! | O19: =#REF! -> #REF! | S19: =SUM(C19:O19) -> #REF!
B20: International Consultants Travel | C20: =SUM(#REF!) -> #REF! | F20: =SUM(#REF!) -> #REF! | I20: =SUM(#REF!) -> #REF! | L20: =SUM(#REF!) -> #REF! | O20: =SUM(#REF!) -> #REF! | S20: =SUM(C20:O20) -> #REF!
B21: Total Expatriate TA | C21: =SUM(C12:C20) -> #REF! | F21: =SUM(F12:F20) -> #REF! | I21: =SUM(I12:I20) -> #REF! | L21: =SUM(L12:L20) -> #REF! | O21: =SUM(O12:O20) -> #REF! | S21: =SUM(C21:O21) -> #REF!
B23: Country Offices
B24: Program and Technical Staff - Local Hires | C24: =#REF! -> #REF! | F24: =#REF! -> #REF! | I24: =#REF! -> #REF! | L24: =#REF! -> #REF! | O24: =#REF! -> #REF! | S24: =SUM(O24,C24,F24,I24,L24) -> #REF!
B25: Support Staff - Local Hires | C25: =#REF! -> #REF! | F25: =#REF! -> #REF! | I25: =#REF! -> #REF! | L25: =#REF! -> #REF! | O25: =#REF! -> #REF! | S25: =SUM(O25,C25,F25,I25,L25) -> #REF!
B26: Local Consultants Labor | C26: =SUM(#REF!) -> #REF! | F26: =SUM(#REF!) -> #REF! | I26: =SUM(#REF!) -> #REF! | L26: =SUM(#REF!) -> #REF! | O26: =SUM(#REF!) -> #REF! | S26: =SUM(O26,C26,F26,I26,L26) -> #REF!
B27: Fringe Benefits - Local Hires | C27: =#REF! -> #REF! | F27: =#REF! -> #REF! | I27: =#REF! -> #REF! | L27: =#REF! -> #REF! | O27: =#REF! -> #REF! | S27: =SUM(O27,C27,F27,I27,L27) -> #REF!
B28: Domestic Travel | C28: =#REF! -> #REF! | F28: =#REF! -> #REF! | I28: =#REF! -> #REF! | L28: =#REF! -> #REF! | O28: =#REF! -> #REF! | S28: =SUM(O28,C28,F28,I28,L28) -> #REF!
B29: Local Consultants Travel | C29: =SUM(#REF!) -> #REF! | F29: =SUM(#REF!) -> #REF! | I29: =SUM(#REF!) -> #REF! | L29: =SUM(#REF!) -> #REF! | O29: =SUM(#REF!) -> #REF! | S29: =SUM(O29,C29,F29,I29,L29) -> #REF!
B30: Total Cooperating Country Nationals TA | C30: =SUM(C23:C29) -> #REF! | F30: =SUM(F23:F29) -> #REF! | I30: =SUM(I23:I29) -> #REF! | L30: =SUM(L23:L29) -> #REF! | O30: =SUM(O23:O29) -> #REF! | S30: =SUM(C30:O30) -> #REF!
B32: Total Technical Assistance Costs | C32: =SUM(C30,C21) -> #REF! | F32: =SUM(F30,F21) -> #REF! | I32: =SUM(I30,I21) -> #REF! | L32: =SUM(L30,L21) -> #REF! | O32: =SUM(O30,O21) -> #REF! | S32: =SUM(C32:O32) -> #REF!

Sheet Funding By Partner
A1: =Assumptions!$B$4 -> Partners of America
A2: =CONCATENATE(Assumptions!$B5," ",Assumptions!$C5) -> DONOR: USDOL
A3: =CONCATENATE(Assumptions!$B6," ",Assumptions!$C6) -> Country: Ecuador
A4: =CONCATENATE(Assumptions!$B7," ",Assumptions!$C7) -> Program Name: Project to Improve Adherence to International Labor Standards in the Agricultural Sector in Ecuador
A5: =CONCATENATE(Assumptions!$B8," ",Assumptions!$C8) -> Grant Number: FOA-ILAB-23-28
A7: TOTAL FUNDING BY PARTNER
A9: Partner | B9: =Assumptions!G20 -> Year 1 | E9: =Assumptions!J20 -> Year 2 | H9: =Assumptions!M20 -> Year 3 | K9: =Assumptions!P20 -> Year 4 | N9: =Assumptions!S20 -> Year 5 | Q9: Total
B10: Federal Funding | C10: Non-Federal Funding | E10: Federal Funding | F10: Non-Federal Funding | H10: Federal Funding | I10: Non-Federal Funding | K10: Federal Funding | L10: Non-Federal Funding | N10: Federal Funding | O10: Non-Federal Funding | Q10: Federal Funding | R10: Non-Federal Funding | T10: If RFA requests for Cost Share - Unhide columns "C", "F", "I", "L", "O" and "Q"
T11: Double-checks
A12: Jhpiego Corporation | B12: =B35-SUM(B13:B33) -> #REF! | E12: =E35-SUM(E13:E33) -> #REF! | H12: =H35-SUM(H13:H33) -> #REF! | K12: =K35-SUM(K13:K33) -> #REF! | N12: =N35-SUM(N13:N33) -> #REF! | Q12: =SUM(B12,E12,H12,K12,N12) -> #REF! | R12: =SUM(C12,F12,I12,L12,O12,#REF!,#REF!,#REF!,#REF!,#REF!) -> #REF! | T12: =SUM(B12:P12) -> #REF!
A14: =#REF! -> #REF! | B14: =#REF! -> #REF! | E14: =#REF! -> #REF! | H14: =#REF! -> #REF! | K14: =#REF! -> #REF! | N14: =#REF! -> #REF! | Q14: =SUM(B14,E14,H14,K14,N14) -> #REF! | R14: =SUM(O14,L14,I14,F14,C14) -> 0 | T14: =SUM(B14:P14) -> #REF!
A16: =#REF! -> #REF! | B16: =#REF! -> #REF! | E16: =#REF! -> #REF! | H16: =#REF! -> #REF! | K16: =#REF! -> #REF! | N16: =#REF! -> #REF! | Q16: =SUM(B16,E16,H16,K16,N16) -> #REF! | R16: =SUM(O16,L16,I16,F16,C16) -> 0 | T16: =SUM(B16:P16) -> #REF!
A18: =#REF! -> #REF! | B18: =#REF! -> #REF! | E18: =#REF! -> #REF! | H18: =#REF! -> #REF! | K18: =#REF! -> #REF! | N18: =#REF! -> #REF! | Q18: =SUM(B18,E18,H18,K18,N18) -> #REF! | R18: =SUM(O18,L18,I18,F18,C18) -> 0 | T18: =SUM(B18:P18) -> #REF!
A20: =#REF! -> #REF! | B20: =#REF! -> #REF! | E20: =#REF! -> #REF! | H20: =#REF! -> #REF! | K20: =#REF! -> #REF! | N20: =#REF! -> #REF! | Q20: =SUM(B20,E20,H20,K20,N20) -> #REF! | R20: =SUM(O20,L20,I20,F20,C20) -> 0 | T20: =SUM(B20:P20) -> #REF!
A22: =#REF! -> #REF! | B22: =#REF! -> #REF! | E22: =#REF! -> #REF! | H22: =#REF! -> #REF! | K22: =#REF! -> #REF! | N22: =#REF! -> #REF! | Q22: =SUM(B22,E22,H22,K22,N22) -> #REF! | R22: =SUM(O22,L22,I22,F22,C22) -> 0 | T22: =SUM(B22:P22) -> #REF!
A24: =#REF! -> #REF! | B24: =#REF! -> #REF! | E24: =#REF! -> #REF! | H24: =#REF! -> #REF! | K24: =#REF! -> #REF! | N24: =#REF! -> #REF! | Q24: =SUM(B24,E24,H24,K24,N24) -> #REF! | R24: =SUM(O24,L24,I24,F24,C24) -> 0 | T24: =SUM(B24:P24) -> #REF!
A26: =#REF! -> #REF! | B26: =#REF! -> #REF! | E26: =#REF! -> #REF! | H26: =#REF! -> #REF! | K26: =#REF! -> #REF! | N26: =#REF! -> #REF! | Q26: =SUM(B26,E26,H26,K26,N26) -> #REF! | R26: =SUM(O26,L26,I26,F26,C26) -> 0 | T26: =SUM(B26:P26) -> #REF!
A28: =#REF! -> #REF! | B28: =#REF! -> #REF! | E28: =#REF! -> #REF! | H28: =#REF! -> #REF! | K28: =#REF! -> #REF! | N28: =#REF! -> #REF! | Q28: =SUM(B28,E28,H28,K28,N28) -> #REF! | R28: =SUM(O28,L28,I28,F28,C28) -> 0 | T28: =SUM(B28:P28) -> #REF!
A30: =#REF! -> #REF! | B30: =#REF! -> #REF! | E30: =#REF! -> #REF! | H30: =#REF! -> #REF! | K30: =#REF! -> #REF! | N30: =#REF! -> #REF! | Q30: =SUM(B30,E30,H30,K30,N30) -> #REF! | R30: =SUM(O30,L30,I30,F30,C30) -> 0 | T30: =SUM(B30:P30) -> #REF!
Q32: =SUM(N32,K32,H32,E32,B32) -> 0 | R32: =SUM(O32,L32,I32,F32,C32) -> 0 | T32: =SUM(B32:P32) -> 0
A35: TOTAL COSTS | B35: =#REF! -> #REF! | C35: =SUM(C11:C34) -> 0 | E35: =#REF! -> #REF! | F35: =SUM(F11:F34) -> 0 | H35: =#REF! -> #REF! | I35: =SUM(I11:I34) -> 0 | K35: =#REF! -> #REF! | L35: =SUM(L11:L34) -> 0 | N35: =#REF! -> #REF! | O35: =SUM(O11:O34) -> 0 | Q35: =SUM(B35,E35,H35,K35,N35) -> #REF! | R35: =SUM(O35,L35,I35,F35,C35) -> 0 | T35: =SUM(B35:P35) -> #REF!

Sheet LOE Table
A1: =Assumptions!$B$4 -> Partners of America
A2: =CONCATENATE(Assumptions!$B5," ",Assumptions!$C5) -> DONOR: USDOL | Q2: Escalation Factor:
A3: =CONCATENATE(Assumptions!$B6," ",Assumptions!$C6) -> Country: Ecuador | Q3: Inflation Rate:
A4: =CONCATENATE(Assumptions!$B7," ",Assumptions!$C7) -> Program Name: Project to Improve Adherence to International Labor Standards in the Agricultural Sector in Ecuador
A5: =CONCATENATE(Assumptions!$B8," ",Assumptions!$C8) -> Grant Number: FOA-ILAB-23-28
A7: LEVEL OF EFFORT TABLE
A9: PERSONNEL | C9: =#REF! -> #REF! | F9: =#REF! -> #REF! | I9: =Assumptions!M20 -> Year 3 | L9: =#REF! -> #REF! | O9: =#REF! -> #REF! | R9: Total | T9: Calculation
A10: Position Description | B10: Unit | C10: Units | F10: Units | I10: Units | L10: Units | O10: Units | R10: % | S10: US$ | T10: Check: | V10: show
V11: =IF(SUM(S12:S190)=0,"hide","show") -> #REF!
A12: =#REF! -> #REF! | V12: =IF(SUM(S20:S190)=0,"hide","show") -> #REF!
A13: =#REF! -> #REF! | V13: =IF(SUM(S14:S18)=0,"hide","show") -> #REF!
A14: =#REF! -> #REF! | B14: % | C14: =#REF! -> #REF! | F14: =#REF! -> #REF! | I14: =#REF! -> #REF! | L14: =#REF! -> #REF! | O14: =#REF! -> #REF! | R14: =C14+F14+I14+L14+O14 -> #REF! | S14: =#REF! -> #REF! | V14: =IF(S14=0,"hide","show") -> #REF!
A15: =#REF! -> #REF! | B15: % | C15: =#REF! -> #REF! | F15: =#REF! -> #REF! | I15: =#REF! -> #REF! | L15: =#REF! -> #REF! | O15: =#REF! -> #REF! | R15: =C15+F15+I15+L15+O15 -> #REF! | S15: =#REF! -> #REF! | V15: =IF(S15=0,"hide","show") -> #REF!
A16: =#REF! -> #REF! | B16: % | C16: =#REF! -> #REF! | F16: =#REF! -> #REF! | I16: =#REF! -> #REF! | L16: =#REF! -> #REF! | O16: =#REF! -> #REF! | R16: =C16+F16+I16+L16+O16 -> #REF! | S16: =#REF! -> #REF! | V16: =IF(S16=0,"hide","show") -> #REF!
A17: =#REF! -> #REF! | B17: % | C17: =#REF! -> #REF! | F17: =#REF! -> #REF! | I17: =#REF! -> #REF! | L17: =#REF! -> #REF! | O17: =#REF! -> #REF! | R17: =C17+F17+I17+L17+O17 -> #REF! | S17: =#REF! -> #REF! | V17: =IF(S17=0,"hide","show") -> #REF!
A18: =#REF! -> #REF! | B18: % | C18: =#REF! -> #REF! | F18: =#REF! -> #REF! | I18: =#REF! -> #REF! | L18: =#REF! -> #REF! | O18: =#REF! -> #REF! | R18: =C18+F18+I18+L18+O18 -> #REF! | S18: =#REF! -> #REF! | V18: =IF(S18=0,"hide","show") -> #REF!
V19: =IF(SUM(S20:S110)=0,"hide","show") -> #REF!
A20: =#REF! -> #REF! | V20: =IF(SUM(S21:S25)=0,"hide","show") -> #REF!
A21: =#REF! -> #REF! | B21: % | C21: =#REF! -> #REF! | F21: =#REF! -> #REF! | I21: =#REF! -> #REF! | L21: =#REF! -> #REF! | O21: =#REF! -> #REF! | R21: =C21+F21+I21+L21+O21 -> #REF! | S21: =#REF! -> #REF! | V21: =IF(S21=0,"hide","show") -> #REF!
A22: =#REF! -> #REF! | B22: % | C22: =#REF! -> #REF! | F22: =#REF! -> #REF! | I22: =#REF! -> #REF! | L22: =#REF! -> #REF! | O22: =#REF! -> #REF! | R22: =C22+F22+I22+L22+O22 -> #REF! | S22: =#REF! -> #REF! | V22: =IF(S22=0,"hide","show") -> #REF!
A23: =#REF! -> #REF! | B23: % | C23: =#REF! -> #REF! | F23: =#REF! -> #REF! | I23: =#REF! -> #REF! | L23: =#REF! -> #REF! | O23: =#REF! -> #REF! | R23: =C23+F23+I23+L23+O23 -> #REF! | S23: =#REF! -> #REF! | V23: =IF(S23=0,"hide","show") -> #REF!
A24: =#REF! -> #REF! | B24: % | C24: =#REF! -> #REF! | F24: =#REF! -> #REF! | I24: =#REF! -> #REF! | L24: =#REF! -> #REF! | O24: =#REF! -> #REF! | R24: =C24+F24+I24+L24+O24 -> #REF! | S24: =#REF! -> #REF! | V24: =IF(S24=0,"hide","show") -> #REF!
A25: =#REF! -> #REF! | B25: % | C25: =#REF! -> #REF! | F25: =#REF! -> #REF! | I25: =#REF! -> #REF! | L25: =#REF! -> #REF! | O25: =#REF! -> #REF! | R25: =C25+F25+I25+L25+O25 -> #REF! | S25: =#REF! -> #REF! | V25: =IF(S25=0,"hide","show") -> #REF!
V26: =IF(SUM(S27:S190)=0,"hide","show") -> #REF!
A27: =#REF! -> #REF! | V27: =IF(SUM(S28:S190)=0,"hide","show") -> #REF!
A28: =#REF! -> #REF! | V28: =IF(SUM(S29:S110)=0,"hide","show") -> #REF!
A29: =#REF! -> #REF! | B29: % | C29: =#REF! -> #REF! | F29: =#REF! -> #REF! | I29: =#REF! -> #REF! | L29: =#REF! -> #REF! | O29: =#REF! -> #REF! | R29: =C29+F29+I29+L29+O29 -> #REF! | S29: =#REF! -> #REF! | V29: =IF(S29=0,"hide","show") -> #REF!
A30: =#REF! -> #REF! | B30: % | C30: =#REF! -> #REF! | F30: =#REF! -> #REF! | I30: =#REF! -> #REF! | L30: =#REF! -> #REF! | O30: =#REF! -> #REF! | R30: =C30+F30+I30+L30+O30 -> #REF! | S30: =#REF! -> #REF! | V30: =IF(S30=0,"hide","show") -> #REF!
A31: =#REF! -> #REF! | B31: % | C31: =#REF! -> #REF! | F31: =#REF! -> #REF! | I31: =#REF! -> #REF! | L31: =#REF! -> #REF! | O31: =#REF! -> #REF! | R31: =C31+F31+I31+L31+O31 -> #REF! | S31: =#REF! -> #REF! | V31: =IF(S31=0,"hide","show") -> #REF!
A32: =#REF! -> #REF! | B32: % | C32: =#REF! -> #REF! | F32: =#REF! -> #REF! | I32: =#REF! -> #REF! | L32: =#REF! -> #REF! | O32: =#REF! -> #REF! | R32: =C32+F32+I32+L32+O32 -> #REF! | S32: =#REF! -> #REF! | V32: =IF(S32=0,"hide","show") -> #REF!
A33: =#REF! -> #REF! | B33: % | C33: =#REF! -> #REF! | F33: =#REF! -> #REF! | I33: =#REF! -> #REF! | L33: =#REF! -> #REF! | O33: =#REF! -> #REF! | R33: =C33+F33+I33+L33+O33 -> #REF! | S33: =#REF! -> #REF! | V33: =IF(S33=0,"hide","show") -> #REF!
A34: =#REF! -> #REF! | B34: % | C34: =#REF! -> #REF! | F34: =#REF! -> #REF! | I34: =#REF! -> #REF! | L34: =#REF! -> #REF! | O34: =#REF! -> #REF! | R34: =C34+F34+I34+L34+O34 -> #REF! | S34: =#REF! -> #REF! | V34: =IF(S34=0,"hide","show") -> #REF!
A35: =#REF! -> #REF! | B35: % | C35: =#REF! -> #REF! | F35: =#REF! -> #REF! | I35: =#REF! -> #REF! | L35: =#REF! -> #REF! | O35: =#REF! -> #REF! | R35: =C35+F35+I35+L35+O35 -> #REF! | S35: =#REF! -> #REF! | V35: =IF(S35=0,"hide","show") -> #REF!
A36: =#REF! -> #REF! | B36: % | C36: =#REF! -> #REF! | F36: =#REF! -> #REF! | I36: =#REF! -> #REF! | L36: =#REF! -> #REF! | O36: =#REF! -> #REF! | R36: =C36+F36+I36+L36+O36 -> #REF! | S36: =#REF! -> #REF! | V36: =IF(S36=0,"hide","show") -> #REF!
A37: =#REF! -> #REF! | B37: % | C37: =#REF! -> #REF! | F37: =#REF! -> #REF! | I37: =#REF! -> #REF! | L37: =#REF! -> #REF! | O37: =#REF! -> #REF! | R37: =C37+F37+I37+L37+O37 -> #REF! | S37: =#REF! -> #REF! | V37: =IF(S37=0,"hide","show") -> #REF!
A38: =#REF! -> #REF! | B38: % | C38: =#REF! -> #REF! | F38: =#REF! -> #REF! | I38: =#REF! -> #REF! | L38: =#REF! -> #REF! | O38: =#REF! -> #REF! | R38: =C38+F38+I38+L38+O38 -> #REF! | S38: =#REF! -> #REF! | V38: =IF(S38=0,"hide","show") -> #REF!
A39: =#REF! -> #REF! | B39: % | C39: =#REF! -> #REF! | F39: =#REF! -> #REF! | I39: =#REF! -> #REF! | L39: =#REF! -> #REF! | O39: =#REF! -> #REF! | R39: =C39+F39+I39+L39+O39 -> #REF! | S39: =#REF! -> #REF! | V39: =IF(S39=0,"hide","show") -> #REF!
A40: =#REF! -> #REF! | B40: % | C40: =#REF! -> #REF! | F40: =#REF! -> #REF! | I40: =#REF! -> #REF! | L40: =#REF! -> #REF! | O40: =#REF! -> #REF! | R40: =C40+F40+I40+L40+O40 -> #REF! | S40: =#REF! -> #REF! | V40: =IF(S40=0,"hide","show") -> #REF!
... A114: =#REF! -> #REF! | B114: % | C114: =#REF! -> #REF! | F114: =#REF! -> #REF! | I114: =#REF! -> #REF! | L114: =#REF! -> #REF! | O114: =#REF! -> #REF! | R114: =C114+F114+I114+L114+O114 -> #REF! | S114: =#REF! -> #REF! | V114: =IF(S114=0,"hide","show") -> #REF!
V115: =IF(SUM(S117:S190)=0,"hide","show") -> #REF!
...

Sheet Total Budget by Sponsored Class
B1: =Assumptions!B4 -> Partners of America
B2: =Assumptions!B5 -> DONOR: | C2: =Assumptions!C5 -> USDOL
B3: =Assumptions!B6 -> Country: | C3: =Assumptions!C6 -> Ecuador
B4: =Assumptions!B7 -> Program Name: | C4: =Assumptions!C7 -> Project to Improve Adherence to International Labor Standards in the Agricultural Sector in Ecuador
B5: =Assumptions!B8 -> Grant Number: | C5: =Assumptions!C8 -> FOA-ILAB-23-28
B6: =Assumptions!B9 -> Period of Performance: | C6: =Assumptions!C9 -> 48 months | H6: =Assumptions!G9 -> 0
B8: TOTAL BUDGET SUMMARY BY SPONSORED CLASS
H10: US COSTS for ION | I10: 78 - 12345678
A12: SF424a | B12: Sponsored Class | C12: Description | D12: G/L | E12: Description | H12: Total | I12: =#REF! -> #REF! | L12: =#REF! -> #REF! | O12: =#REF! -> #REF! | R12: =#REF! -> #REF! | U12: =#REF! -> #REF!
A14: Personnel | B14: 610000 | C14: Salaries & Wages: Faculty and Senior Staff | H14: =SUM(I14,L14,O14,R14,U14) -> #REF! | I14: =SUM('US Costs by Sponsored Class'!I14,'Incountry Costs by GL USD'!I15) -> #REF! | L14: =SUM('US Costs by Sponsored Class'!L14,'Incountry Costs by GL USD'!L15) -> #REF! | O14: =SUM('US Costs by Sponsored Class'!O14,'Incountry Costs by GL USD'!O15) -> #REF! | R14: =SUM('US Costs by Sponsored Class'!R14,'Incountry Costs by GL USD'!R15) -> #REF! | U14: =SUM('US Costs by Sponsored Class'!U14,'Incountry Costs by GL USD'!U15) -> #REF!
B15: 612000 | C15: Salaries & Wages: Administrative Staff | H15: =SUM(I15,L15,O15,R15,U15) -> #REF! | I15: ='US Costs by Sponsored Class'!I15 -> #REF! | L15: ='US Costs by Sponsored Class'!L15 -> #REF! | O15: ='US Costs by Sponsored Class'!O15 -> #REF! | R15: ='US Costs by Sponsored Class'!R15 -> #REF! | U15: ='US Costs by Sponsored Class'!U15 -> #REF!
A17: Fringe Benefits | B17: 620000 | C17: Fringe Benefits | H17: =SUM(I17,L17,O17,R17,U17) -> #REF! | I17: =SUM('US Costs by Sponsored Class'!I16,'Incountry Costs by GL USD'!I16) -> #REF! | L17: =SUM('US Costs by Sponsored Class'!L16,'Incountry Costs by GL USD'!L16) -> #REF! | O17: =SUM('US Costs by Sponsored Class'!O16,'Incountry Costs by GL USD'!O16) -> #REF! | R17: =SUM('US Costs by Sponsored Class'!R16,'Incountry Costs by GL USD'!R16) -> #REF! | U17: =SUM('US Costs by Sponsored Class'!U16,'Incountry Costs by GL USD'!U16) -> #REF!
A19: Travel | B19: 652000 | C19: Travel Domestic | H19: =SUM(I19,L19,O19,R19,U19) -> #REF! | I19: =SUM('US Costs by Sponsored Class'!I18,'Incountry Costs by GL USD'!I17) -> #REF! | L19: =SUM('US Costs by Sponsored Class'!L18,'Incountry Costs by GL USD'!L17) -> #REF! | O19: =SUM('US Costs by Sponsored Class'!O18,'Incountry Costs by GL USD'!O17) -> #REF! | R19: =SUM('US Costs by Sponsored Class'!R18,'Incountry Costs by GL USD'!R17) -> #REF! | U19: =SUM('US Costs by Sponsored Class'!U18,'Incountry Costs by GL USD'!U17) -> #REF!
B20: 652100 | C20: Travel Foreign | H20: =SUM(I20,L20,O20,R20,U20) -> #REF! | I20: =SUM('US Costs by Sponsored Class'!H19,'Incountry Costs by GL USD'!I18:I19) -> #REF! | L20: =SUM('US Costs by Sponsored Class'!K19,'Incountry Costs by GL USD'!L18:L19) -> #REF! | O20: =SUM('US Costs by Sponsored Class'!N19,'Incountry Costs by GL USD'!O18:O19) -> #REF! | R20: =SUM('US Costs by Sponsored Class'!Q19,'Incountry Costs by GL USD'!R18:R19) -> #REF! | U20: =SUM('US Costs by Sponsored Class'!T19,'Incountry Costs by GL USD'!U18:U19) -> #REF!
A22: Supplies | B22: 630000 | C22: Supplies & Materials | H22: =SUM(I22,L22,O22,R22,U22) -> #REF! | I22: =SUM('US Costs by Sponsored Class'!I21:I22,'Incountry Costs by GL USD'!I20:I29) -> #REF! | L22: =SUM('US Costs by Sponsored Class'!L21:L22,'Incountry Costs by GL USD'!L20:L29) -> #REF! | O22: =SUM('US Costs by Sponsored Class'!O21:O22,'Incountry Costs by GL USD'!O20:O29) -> #REF! | R22: =SUM('US Costs by Sponsored Class'!R21:R22,'Incountry Costs by GL USD'!R20:R29) -> #REF! | U22: =SUM('US Costs by Sponsored Class'!U21:U22,'Incountry Costs by GL USD'!U20:U29) -> #REF!
D24: 633032 | E24: Office Supplies
D25: 633037 | E25: Publications/Journals/Subscriptions
D26: 635001 | E26: Electricity
D27: 635010 | E27: Utilities: Water
D28: 640282 | E28: Delivery/Courier Service
A30: Equipment | B30: 653400 | C30: Equipment | H30: =SUM(I30,L30,O30,R30,U30) -> #REF! | I30: =SUM('US Costs by Sponsored Class'!I29,'Incountry Costs by GL USD'!I30) -> #REF! | L30: =SUM('US Costs by Sponsored Class'!L29,'Incountry Costs by GL USD'!L30) -> #REF! | O30: =SUM('US Costs by Sponsored Class'!O29,'Incountry Costs by GL USD'!O30) -> #REF! | R30: =SUM('US Costs by Sponsored Class'!R29,'Incountry Costs by GL USD'!R30) -> #REF! | U30: =SUM('US Costs by Sponsored Class'!U29,'Incountry Costs by GL USD'!U30) -> #REF!
A32: Contractual | B32: 640300 | C32: Contractual Services | H32: =SUM(I32,L32,O32,R32,U32) -> #REF! | I32: =SUM('US Costs by Sponsored Class'!I31,'Incountry Costs by GL USD'!I32:I44) -> #REF! | L32: =SUM('US Costs by Sponsored Class'!L31,'Incountry Costs by GL USD'!L32:L44) -> #REF! | O32: =SUM('US Costs by Sponsored Class'!O31,'Incountry Costs by GL USD'!O32:O44) -> #REF! | R32: =SUM('US Costs by Sponsored Class'!R31,'Incountry Costs by GL USD'!R32:R44) -> #REF! | U32: =SUM('US Costs by Sponsored Class'!U31,'Incountry Costs by GL USD'!U32:U44) -> #REF!
B33: 640500 | C33: Consultant | H33: =SUM(I33,L33,O33,R33,U33) -> #REF! | I33: =SUM('US Costs by Sponsored Class'!I32,'Incountry Costs by GL USD'!I45) -> #REF! | L33: =SUM('US Costs by Sponsored Class'!L32,'Incountry Costs by GL USD'!L45) -> #REF! | O33: =SUM('US Costs by Sponsored Class'!O32,'Incountry Costs by GL USD'!O45) -> #REF! | R33: =SUM('US Costs by Sponsored Class'!R32,'Incountry Costs by GL USD'!R45) -> #REF! | U33: =SUM('US Costs by Sponsored Class'!U32,'Incountry Costs by GL USD'!U45) -> #REF!
B34: 642400 | C34: Subaward | H34: =SUM(I34,L34,O34,R34,U34) -> #REF! | I34: =SUM('US Costs by Sponsored Class'!I33,'Incountry Costs by GL USD'!I46) -> #REF! | L34: =SUM('US Costs by Sponsored Class'!L33,'Incountry Costs by GL USD'!L46) -> #REF! | O34: =SUM('US Costs by Sponsored Class'!O33,'Incountry Costs by GL USD'!O46) -> #REF! | R34: =SUM('US Costs by Sponsored Class'!R33,'Incountry Costs by GL USD'!R46) -> #REF! | U34: =SUM('US Costs by Sponsored Class'!U33,'Incountry Costs by GL USD'!U46) -> #REF!
B35: 637000 | C35: Repairs & Maintenance | H35: =SUM(I35,L35,O35,R35,U35) -> #REF! | I35: =SUM('US Costs by Sponsored Class'!I34,'Incountry Costs by GL USD'!I31) -> #REF! | L35: =SUM('US Costs by Sponsored Class'!L34,'Incountry Costs by GL USD'!L31) -> #REF! | O35: =SUM('US Costs by Sponsored Class'!O34,'Incountry Costs by GL USD'!O31) -> #REF! | R35: =SUM('US Costs by Sponsored Class'!R34,'Incountry Costs by GL USD'!R31) -> #REF! | U35: =SUM('US Costs by Sponsored Class'!U34,'Incountry Costs by GL USD'!U31) -> #REF!
A37: Other | B37: 640102 | C37: Leased Facilities External | H37: =SUM(I37,L37,O37,R37,U37) -> #REF! | I37: =SUM('US Costs by Sponsored Class'!I36,'Incountry Costs by GL USD'!I47) -> #REF! | L37: =SUM('US Costs by Sponsored Class'!L36,'Incountry Costs by GL USD'!L47) -> #REF! | O37: =SUM('US Costs by Sponsored Class'!O36,'Incountry Costs by GL USD'!O47) -> #REF! | R37: =SUM('US Costs by Sponsored Class'!R36,'Incountry Costs by GL USD'!R47) -> #REF! | U37: =SUM('US Costs by Sponsored Class'!U36,'Incountry Costs by GL USD'!U47) -> #REF!
B38: 641400 | C38: Telecommunications | H38: =SUM(I38,L38,O38,R38,U38) -> #REF! | I38: =SUM('US Costs by Sponsored Class'!I37,'Incountry Costs by GL USD'!I48) -> #REF! | L38: =SUM('US Costs by Sponsored Class'!L37,'Incountry Costs by GL USD'!L48) -> #REF! | O38: =SUM('US Costs by Sponsored Class'!O37,'Incountry Costs by GL USD'!O48) -> #REF! | R38: =SUM('US Costs by Sponsored Class'!R37,'Incountry Costs by GL USD'!R48) -> #REF! | U38: =SUM('US Costs by Sponsored Class'!U37,'Incountry Costs by GL USD'!U48) -> #REF!
B39: 642500 | C39: Other Expenses | H39: =SUM(I39,L39,O39,R39,U39) -> #REF! | I39: =SUM('US Costs by Sponsored Class'!I38,'Incountry Costs by GL USD'!I49:I54) -> #REF! | L39: =SUM('US Costs by Sponsored Class'!L38,'Incountry Costs by GL USD'!L49:L54) -> #REF! | O39: =SUM('US Costs by Sponsored Class'!O38,'Incountry Costs by GL USD'!O49:O54) -> #REF! | R39: =SUM('US Costs by Sponsored Class'!R38,'Incountry Costs by GL USD'!R49:R54) -> #REF! | U39: =SUM('US Costs by Sponsored Class'!U38,'Incountry Costs by GL USD'!U49:U54) -> #REF!
B40: 643000 | C40: Other Expenses (Excluded from F&A) | H40: =SUM(I40,L40,O40,R40,U40) -> #REF! | I40: =SUM('US Costs by Sponsored Class'!I39,'Incountry Costs by GL USD'!I55:I56) -> #REF! | L40: =SUM('US Costs by Sponsored Class'!L39,'Incountry Costs by GL USD'!L55:L56) -> #REF! | O40: =SUM('US Costs by Sponsored Class'!O39,'Incountry Costs by GL USD'!O55:O56) -> #REF! | R40: =SUM('US Costs by Sponsored Class'!R39,'Incountry Costs by GL USD'!R55:R56) -> #REF! | U40: =SUM('US Costs by Sponsored Class'!U39,'Incountry Costs by GL USD'!U55:U56) -> #REF!
B42: Subtotal | H42: =SUM(I42,L42,O42,R42,U42) -> #REF! | I42: =SUM(I13:I41) -> #REF! | L42: =SUM(L13:L41) -> #REF! | O42: =SUM(O13:O41) -> #REF! | R42: =SUM(R13:R41) -> #REF! | U42: =SUM(U13:U41) -> #REF!
B44: 690007 | C44: Service Center | H44: =SUM(I44,L44,O44,R44,U44) -> #REF! | I44: ='US Costs by Sponsored Class'!I43 -> #REF! | L44: ='US Costs by Sponsored Class'!L43 -> #REF! | O44: ='US Costs by Sponsored Class'!O43 -> #REF! | R44: ='US Costs by Sponsored Class'!R43 -> #REF! | U44: ='US Costs by Sponsored Class'!U43 -> #REF!
B46: 699999 | C46: F&A | H46: =SUM(I46,L46,O46,R46,U46) -> #REF! | I46: ='US Costs by Sponsored Class'!I45 -> #REF! | L46: ='US Costs by Sponsored Class'!L45 -> #REF! | O46: ='US Costs by Sponsored Class'!O45 -> #REF! | R46: ='US Costs by Sponsored Class'!R45 -> #REF! | U46: ='US Costs by Sponsored Class'!U45 -> #REF!
B48: Total per year | H48: =SUM(I48,L48,O48,R48,U48) -> #REF! | I48: =SUM(I42:I47) -> #REF! | L48: =SUM(L42:L47) -> #REF! | O48: =SUM(O42:O47) -> #REF! | R48: =SUM(R42:R47) -> #REF! | U48: =SUM(U42:U47) -> #REF!
B50: Calculation check

Sheet US Costs by Sponsored Class
B1: =Assumptions!B4 -> Partners of America
B2: =Assumptions!B5 -> DONOR: | C2: =Assumptions!C5 -> USDOL
B3: =Assumptions!B6 -> Country: | C3: =Assumptions!C6 -> Ecuador
B4: =Assumptions!B7 -> Program Name: | C4: =Assumptions!C7 -> Project to Improve Adherence to International Labor Standards in the Agricultural Sector in Ecuador
B5: =Assumptions!B8 -> Grant Number: | C5: =Assumptions!C8 -> FOA-ILAB-23-28
B6: =Assumptions!B9 -> Period of Performance: | C6: =Assumptions!C9 -> 48 months | E6: =Assumptions!G9 -> 0
B8: BUDGET SUMMARY BY G/L
D10: US COSTS for ION | E10: 78 - 12345678
A12: SF424a | B12: Sponsored Class | C12: Description | D12: G/L | E12: Description | H12: Workplan Year Budget | I12: =#REF! -> #REF! | L12: =#REF! -> #REF! | O12: =#REF! -> #REF! | R12: =#REF! -> #REF! | U12: =#REF! -> #REF!
A14: Personnel | B14: 610000 | C14: Salaries & Wages: Faculty and Senior Staff | D14: 613001 | E14: Salary: Non-Administrative Staff | H14: =SUM(I14,L14,O14,R14,U14) -> #REF! | I14: =SUMIF(#REF!,$B$14,#REF!) -> #REF! | L14: =SUMIF(#REF!,$B$14,#REF!) -> #REF! | O14: =SUMIF(#REF!,$B$14,#REF!) -> #REF! | R14: =SUMIF(#REF!,$B$14,#REF!) -> #REF! | U14: =SUMIF(#REF!,$B$14,#REF!) -> #REF!
B15: 612000 | C15: Salaries & Wages: Administrative Staff | D15: 612001 | E15: Salary: Administrative Staff | H15: =SUM(I15,L15,O15,R15,U15) -> #REF! | I15: =SUMIF(#REF!,$B$15,#REF!) -> #REF! | L15: =SUMIF(#REF!,$B$15,#REF!) -> #REF! | O15: =SUMIF(#REF!,$B$15,#REF!) -> #REF! | R15: =SUMIF(#REF!,$B$15,#REF!) -> #REF! | U15: =SUMIF(#REF!,$B$15,#REF!) -> #REF!
A16: Fringe Benefits | B16: 620000 | C16: Fringe Benefits | D16: 620001 | E16: Fringe Benefits: Staff | H16: =SUM(I16,L16,O16,R16,U16) -> #REF! | I16: =SUMIF(#REF!,$B$16,#REF!) -> #REF! | L16: =SUMIF(#REF!,$B$16,#REF!) -> #REF! | O16: =SUMIF(#REF!,$B$16,#REF!) -> #REF! | R16: =SUMIF(#REF!,$B$16,#REF!) -> #REF! | U16: =SUMIF(#REF!,$B$16,#REF!) -> #REF!
D17: 620002 | E17: Fringe Benefits: Allowances
A18: Travel | B18: 652000 | C18: Travel Domestic | H18: =SUM(I18,L18,O18,R18,U18) -> #REF! | I18: =SUMIF(#REF!,$B$18,#REF!) -> #REF! | L18: =SUMIF(#REF!,$B$18,#REF!) -> #REF! | O18: =SUMIF(#REF!,$B$18,#REF!) -> #REF! | R18: =SUMIF(#REF!,$B$18,#REF!) -> #REF! | U18: =SUMIF(#REF!,$B$18,#REF!) -> #REF!
B19: 652100 | C19: Travel Foreign | H19: =SUM(I19,L19,O19,R19,U19) -> #REF! | I19: =SUMIF(#REF!,$B$19,#REF!) -> #REF! | L19: =SUMIF(#REF!,$B$19,#REF!) -> #REF! | O19: =SUMIF(#REF!,$B$19,#REF!) -> #REF! | R19: =SUMIF(#REF!,$B$19,#REF!) -> #REF! | U19: =SUMIF(#REF!,$B$19,#REF!) -> #REF!
A21: Supplies | B21: 630000 | C21: Supplies & Materials | D21: 631001 | E21: Furniture | H21: =SUM(I21,L21,O21,R21,U21) -> #REF! | I21: =SUMIF(#REF!,$B$21,#REF!) -> #REF! | L21: =SUMIF(#REF!,$B$21,#REF!) -> #REF! | O21: =SUMIF(#REF!,$B$21,#REF!) -> #REF! | R21: =SUMIF(#REF!,$B$21,#REF!) -> #REF! | U21: =SUMIF(#REF!,$B$21,#REF!) -> #REF!
D22: 631003 | E22: Non-capital PC purchases | H22: =SUM(I22,L22,O22,R22,U22) -> #REF! | I22: =SUMIF(#REF!,$B$21,#REF!) -> #REF! | L22: =SUMIF(#REF!,$B$21,#REF!) -> #REF! | O22: =SUMIF(#REF!,$B$21,#REF!) -> #REF! | R22: =SUMIF(#REF!,$B$21,#REF!) -> #REF! | U22: =SUMIF(#REF!,$B$21,#REF!) -> #REF!
D23: 633032 | E23: Office Supplies | H23: =SUM(I23,L23,O23,R23,U23,#REF!,#REF!,#REF!,#REF!,#REF!) -> #REF!
D24: 633037 | E24: Publications/Journals/Subscriptions | H24: =SUM(I24,L24,O24,R24,U24,#REF!,#REF!,#REF!,#REF!,#REF!) -> #REF!
D25: 635001 | E25: Electricity | H25: =SUM(I25,L25,O25,R25,U25,#REF!,#REF!,#REF!,#REF!,#REF!) -> #REF!
D26: 635010 | E26: Utilities: Water | H26: =SUM(I26,L26,O26,R26,U26,#REF!,#REF!,#REF!,#REF!,#REF!) -> #REF!
D27: 640282 | E27: Delivery/Courier Service | H27: =SUM(I27,L27,O27,R27,U27,#REF!,#REF!,#REF!,#REF!,#REF!) -> #REF!
A29: Equipment | B29: 653400 | C29: Equipment | H29: =SUM(I29,L29,O29,R29,U29) -> #REF! | I29: =SUMIF(#REF!,$B$29,#REF!) -> #REF! | L29: =SUMIF(#REF!,$B$29,#REF!) -> #REF! | O29: =SUMIF(#REF!,$B$29,#REF!) -> #REF! | R29: =SUMIF(#REF!,$B$29,#REF!) -> #REF! | U29: =SUMIF(#REF!,$B$29,#REF!) -> #REF!
A31: Contractual | B31: 640300 | C31: Contractual Services | H31: =SUM(I31,L31,O31,R31,U31) -> #REF! | I31: =SUMIF(#REF!,$B$31,#REF!) -> #REF! | L31: =SUMIF(#REF!,$B$31,#REF!) -> #REF! | O31: =SUMIF(#REF!,$B$31,#REF!) -> #REF! | R31: =SUMIF(#REF!,$B$31,#REF!) -> #REF! | U31: =SUMIF(#REF!,$B$31,#REF!) -> #REF!
B32: 640500 | C32: Consultant | H32: =SUM(I32,L32,O32,R32,U32) -> #REF! | I32: =SUMIF(#REF!,$B$32,#REF!) -> #REF! | L32: =SUMIF(#REF!,$B$32,#REF!) -> #REF! | O32: =SUMIF(#REF!,$B$32,#REF!) -> #REF! | R32: =SUMIF(#REF!,$B$32,#REF!) -> #REF! | U32: =SUMIF(#REF!,$B$32,#REF!) -> #REF!
B33: 642400 | C33: Subaward | H33: =SUM(I33,L33,O33,R33,U33) -> #REF! | I33: =SUMIF(#REF!,$B$33,#REF!) -> #REF! | L33: =SUMIF(#REF!,$B$33,#REF!) -> #REF! | O33: =SUMIF(#REF!,$B$33,#REF!) -> #REF! | R33: =SUMIF(#REF!,$B$33,#REF!) -> #REF! | U33: =SUMIF(#REF!,$B$33,#REF!) -> #REF!
B34: 637000 | C34: Repairs & Maintenance | H34: =SUM(I34,L34,O34,R34,U34) -> #REF! | I34: =SUMIF(#REF!,$B$34,#REF!) -> #REF! | L34: =SUMIF(#REF!,$B$34,#REF!) -> #REF! | O34: =SUMIF(#REF!,$B$34,#REF!) -> #REF! | R34: =SUMIF(#REF!,$B$34,#REF!) -> #REF! | U34: =SUMIF(#REF!,$B$34,#REF!) -> #REF!
A36: Other | B36: 640102 | C36: Leased Facilities External | H36: =SUM(I36,L36,O36,R36,U36) -> #REF! | I36: =SUMIF(#REF!,$B$36,#REF!) -> #REF! | L36: =SUMIF(#REF!,$B$36,#REF!) -> #REF! | O36: =SUMIF(#REF!,$B$36,#REF!) -> #REF! | R36: =SUMIF(#REF!,$B$36,#REF!) -> #REF! | U36: =SUMIF(#REF!,$B$36,#REF!) -> #REF!
B37: 641400 | C37: Telecommunications | H37: =SUM(I37,L37,O37,R37,U37) -> #REF! | I37: =SUMIF(#REF!,$B$37,#REF!) -> #REF! | L37: =SUMIF(#REF!,$B$37,#REF!) -> #REF! | O37: =SUMIF(#REF!,$B$37,#REF!) -> #REF! | R37: =SUMIF(#REF!,$B$37,#REF!) -> #REF! | U37: =SUMIF(#REF!,$B$37,#REF!) -> #REF!
B38: 642500 | C38: Other Expenses | H38: =SUM(I38,L38,O38,R38,U38) -> #REF! | I38: =SUMIF(#REF!,$B$38,#REF!) -> #REF! | L38: =SUMIF(#REF!,$B$38,#REF!) -> #REF! | O38: =SUMIF(#REF!,$B$38,#REF!) -> #REF! | R38: =SUMIF(#REF!,$B$38,#REF!) -> #REF! | U38: =SUMIF(#REF!,$B$38,#REF!) -> #REF!
B39: 643000 | C39: Other Expenses (Excluded from F&A) | H39: =SUM(I39,L39,O39,R39,U39) -> #REF! | I39: =SUMIF(#REF!,$B$39,#REF!) -> #REF! | L39: =SUMIF(#REF!,$B$39,#REF!) -> #REF! | O39: =SUMIF(#REF!,$B$39,#REF!) -> #REF! | R39: =SUMIF(#REF!,$B$39,#REF!) -> #REF! | U39: =SUMIF(#REF!,$B$39,#REF!) -> #REF!
B41: Subtotal | H41: =SUM(I41,L41,O41,R41,U41) -> #REF! | I41: =SUM(L13:L40) -> #REF! | L41: =SUM(O13:O40) -> #REF! | O41: =SUM(R13:R40) -> #REF! | R41: =SUM(U13:U40) -> #REF! | U41: =SUM(X13:X40) -> 0
B43: 690007 | C43: Service Center | H43: =SUM(I43,L43,O43,R43,U43) -> #REF! | I43: =SUMIF(#REF!,$B$43,#REF!) -> #REF! | L43: =SUMIF(#REF!,$B$43,#REF!) -> #REF! | O43: =SUMIF(#REF!,$B$43,#REF!) -> #REF! | R43: =SUMIF(#REF!,$B$43,#REF!) -> #REF! | U43: =SUMIF(#REF!,$B$43,#REF!) -> #REF!
B45: 699999 | C45: F&A | H45: =SUM(I45,L45,O45,R45,U45) -> #REF! | I45: =SUMIF(#REF!,$B$45,#REF!) -> #REF! | L45: =SUMIF(#REF!,$B$45,#REF!) -> #REF! | O45: =SUMIF(#REF!,$B$45,#REF!) -> #REF! | R45: =SUMIF(#REF!,$B$45,#REF!) -> #REF! | U45: =SUMIF(#REF!,$B$45,#REF!) -> #REF!
B47: Total per year | H47: =SUM(H41:H46) -> #REF! | I47: =SUM(I41:I46) -> #REF! | L47: =SUM(L41:L46) -> #REF! | O47: =SUM(O41:O46) -> #REF! | R47: =SUM(R41:R46) -> #REF! | U47: =SUM(U41:U46) -> #REF!
B49: Calculation check | I49: =SUM(#REF!,#REF!,#REF!) -> #REF! | L49: =SUM(#REF!,#REF!,#REF!) -> #REF! | O49: =SUM(#REF!,#REF!,#REF!) -> #REF! | R49: =SUM(#REF!,#REF!,#REF!) -> #REF! | U49: =SUM(#REF!,#REF!,#REF!) -> #REF!

Sheet Incountry Costs by GL USD
D1: Jhpiego Corporation
D2: =Assumptions!B5 -> DONOR: | E2: =Assumptions!C5 -> USDOL
D3: =Assumptions!B6 -> Country: | E3: =Assumptions!C6 -> Ecuador
D4: =Assumptions!B7 -> Program Name: | E4: =Assumptions!C7 -> Project to Improve Adherence to International Labor Standards in the Agricultural Sector in Ecuador
D5: =Assumptions!B8 -> Grant Number: | E5: =Assumptions!C8 -> FOA-ILAB-23-28
D6: =Assumptions!B9 -> Period of Performance: | E6: =Assumptions!C9 -> 48 months | H6: =Assumptions!G9 -> 0
D8: BUDGET SUMMARY BY G/L in USD
D10: IN-COUNTRY COSTS by Jhpiego FISCAL YEAR
E11: IN-COUNTRY ION: | I11: 21 - 987654321 | L11: 22 - 987654322 | O11: 23 - 987654323 | R11: 24 - 987654324 | U11: 25 - 987654325
A13: SF424a | B13: Sponsored Class | C13: Description | D13: G/L | E13: Description | H13: Workplan Year Budget | I13: =#REF! -> #REF! | L13: =#REF! -> #REF! | O13: =#REF! -> #REF! | R13: =#REF! -> #REF! | U13: =#REF! -> #REF!
A15: Personnel | B15: 610000 | C15: Salaries & Wages | D15: 616112 | E15: In-country Salaries | H15: =SUM(I15,L15,O15,R15,U15) -> #REF! | I15: =SUMIF(#REF!,$D$15,#REF!) -> #REF! | L15: =SUMIF(#REF!,$D$15,#REF!) -> #REF! | O15: =SUMIF(#REF!,$D$15,#REF!) -> #REF! | R15: =SUMIF(#REF!,$D$15,#REF!) -> #REF! | U15: =SUMIF(#REF!,$D$15,#REF!) -> #REF!
A16: Fringe Benefits | B16: 620000 | C16: Fringe Benefits | D16: 620112 | E16: In-country Fringe | H16: =SUM(I16,L16,O16,R16,U16) -> #REF! | I16: =SUMIF(#REF!,$D$16,#REF!) -> #REF! | L16: =SUMIF(#REF!,$D$16,#REF!) -> #REF! | O16: =SUMIF(#REF!,$D$16,#REF!) -> #REF! | R16: =SUMIF(#REF!,$D$16,#REF!) -> #REF! | U16: =SUMIF(#REF!,$D$16,#REF!) -> #REF!
A17: Travel | B17: 652000 | C17: Travel Domestic | D17: 652201 | E17: Trainee Travel | H17: =SUM(I17,L17,O17,R17,U17) -> #REF! | I17: =SUMIF(#REF!,$D$17,#REF!) -> #REF! | L17: =SUMIF(#REF!,$D$17,#REF!) -> #REF! | O17: =SUMIF(#REF!,$D$17,#REF!) -> #REF! | R17: =SUMIF(#REF!,$D$17,#REF!) -> #REF! | U17: =SUMIF(#REF!,$D$17,#REF!) -> #REF!
B18: 652100 | C18: Travel Foreign | D18: 652101 | E18: Travel Foreign | H18: =SUM(I18,L18,O18,R18,U18) -> #REF! | I18: =SUMIF(#REF!,$D$18,#REF!) -> #REF! | L18: =SUMIF(#REF!,$D$18,#REF!) -> #REF! | O18: =SUMIF(#REF!,$D$18,#REF!) -> #REF! | R18: =SUMIF(#REF!,$D$18,#REF!) -> #REF! | U18: =SUMIF(#REF!,$D$18,#REF!) -> #REF!
D19: 652102 | E19: Travel Overseas Local | H19: =SUM(I19,L19,O19,R19,U19) -> #REF! | I19: =SUMIF(#REF!,$D$19,#REF!) -> #REF! | L19: =SUMIF(#REF!,$D$19,#REF!) -> #REF! | O19: =SUMIF(#REF!,$D$19,#REF!) -> #REF! | R19: =SUMIF(#REF!,$D$19,#REF!) -> #REF! | U19: =SUMIF(#REF!,$D$19,#REF!) -> #REF!
A20: Supplies | B20: 630000 | C20: Supplies & Materials | D20: 631001 | E20: Furniture | H20: =SUM(I20,L20,O20,R20,U20) -> #REF! | I20: =SUMIF(#REF!,$D$20,#REF!) -> #REF! | L20: =SUMIF(#REF!,$D$20,#REF!) -> #REF! | O20: =SUMIF(#REF!,$D$20,#REF!) -> #REF! | R20: =SUMIF(#REF!,$D$20,#REF!) -> #REF! | U20: =SUMIF(#REF!,$D$20,#REF!) -> #REF!
B21: 630000 | C21: Supplies & Materials | D21: 631003 | E21: Non-capital PC purchases | H21: =SUM(I21,L21,O21,R21,U21) -> #REF! | I21: =SUMIF(#REF!,$D$21,#REF!) -> #REF! | L21: =SUMIF(#REF!,$D$21,#REF!) -> #REF! | O21: =SUMIF(#REF!,$D$21,#REF!) -> #REF! | R21: =SUMIF(#REF!,$D$21,#REF!) -> #REF! | U21: =SUMIF(#REF!,$D$21,#REF!) -> #REF!
