Workbook

Sheet Fiche récapitulative
B2: Fiche récapitulative du dossier de formation
C4: Organisation : | J4: Pays : | Q4: Projet : | X4: Année : | Z4: 2012
C6: Janvier | E6: Février | G6: Mars | I6: Avil | K6: Mai | M6: Juin | O6: Juillet | Q6: Août | S6: Septembre | U6: Octobre | W6: Novembre | Y6: Décembre | AA6: Totaux
C7: Homme | D7: Femme | E7: Homme | F7: Femme | G7: Homme | H7: Femme | I7: Homme | J7: Femme | K7: Homme | L7: Femme | M7: Homme | N7: Femme | O7: Homme | P7: Femme | Q7: Homme | R7: Femme | S7: Homme | T7: Femme | U7: Homme | V7: Femme | W7: Homme | X7: Femme | Y7: Homme | Z7: Femme
B8: Formation en milieu hostile | C8: =Jan!C20 -> 0 | D8: =Jan!D20 -> 0 | E8: =Fév!C20 -> 0 | F8: =Fév!D20 -> 0 | G8: =Mar!C20 -> 0 | H8: =Mar!D20 -> 0 | I8: =Avr!C20 -> 0 | J8: =Avr!D20 -> 0 | K8: =Mai!C20 -> 0 | L8: =Mai!D20 -> 0 | M8: =Juin!C20 -> 0 | N8: =Juin!D20 -> 0 | O8: =Juil!C20 -> 0 | P8: =Juil!D20 -> 0 | Q8: =Août!C20 -> 0 | R8: =Août!D20 -> 0 | S8: =Sep!C20 -> 0 | T8: =Sep!D20 -> 0 | U8: =Oct!C20 -> 0 | V8: =Oct!D20 -> 0 | W8: =Nov!C20 -> 0 | X8: =Nov!D20 -> 0 | Y8: =Déc!C20 -> 0 | Z8: =Déc!D20 -> 0 | AA8: =SUM(C8:Z8) -> 0
B9: Direction de crise | C9: =Jan!C42 -> 0 | D9: =Jan!D42 -> 0 | E9: =Fév!C42 -> 0 | F9: =Fév!D42 -> 0 | G9: =Mar!C42 -> 0 | H9: =Mar!D42 -> 0 | I9: =Avr!C42 -> 0 | J9: =Avr!D42 -> 0 | K9: =Mai!C42 -> 0 | L9: =Mai!D42 -> 0 | M9: =Juin!C42 -> 0 | N9: =Juin!D42 -> 0 | O9: =Juil!C42 -> 0 | P9: =Juil!D42 -> 0 | Q9: =Août!C42 -> 0 | R9: =Août!D42 -> 0 | S9: =Sep!C42 -> 0 | T9: =Sep!D42 -> 0 | U9: =Oct!C42 -> 0 | V9: =Oct!D42 -> 0 | W9: =Nov!C42 -> 0 | X9: =Nov!D42 -> 0 | Y9: =Déc!C42 -> 0 | Z9: =Déc!D42 -> 0 | AA9: =SUM(C9:Z9) -> 0
B10: Gestion des évacuations | C10: =Fév!C58 -> 0 | D10: =Jan!D58 -> 0 | E10: =Fév!C58 -> 0 | F10: =Fév!D58 -> 0 | G10: =Mar!C58 -> 0 | H10: =Mar!D58 -> 0 | I10: =Avr!C58 -> 0 | J10: =Avr!D58 -> 0 | K10: =Mai!C58 -> 0 | L10: =Mai!D58 -> 0 | M10: =Juin!C58 -> 0 | N10: =Juin!D58 -> 0 | O10: =Juil!C58 -> 0 | P10: =Juil!D58 -> 0 | Q10: =Août!C58 -> 0 | R10: =Août!D58 -> 0 | S10: =Sep!C58 -> 0 | T10: =Sep!D58 -> 0 | U10: =Oct!C58 -> 0 | V10: =Oct!D58 -> 0 | W10: =Nov!C58 -> 0 | X10: =Nov!D58 -> 0 | Y10: =Déc!C58 -> 0 | Z10: =Déc!D58 -> 0 | AA10: =SUM(C10:Z10) -> 0
B11: Gestion des pandémies | C11: =Jan!C74 -> 0 | D11: =Jan!D74 -> 0 | E11: =Fév!C74 -> 0 | F11: =Fév!D74 -> 0 | G11: =Mar!C74 -> 0 | H11: =Mar!D74 -> 0 | I11: =Avr!C74 -> 0 | J11: =Avr!D74 -> 0 | K11: =Mai!C74 -> 0 | L11: =Mai!D74 -> 0 | M11: =Juin!C74 -> 0 | N11: =Juin!D74 -> 0 | O11: =Juil!C74 -> 0 | P11: =Juil!D74 -> 0 | Q11: =Août!C74 -> 0 | R11: =Août!D74 -> 0 | S11: =Sep!C74 -> 0 | T11: =Sep!D74 -> 0 | U11: =Oct!C74 -> 0 | V11: =Oct!D74 -> 0 | W11: =Nov!C74 -> 0 | X11: =Nov!D74 -> 0 | Y11: =Déc!C74 -> 0 | Z11: =Déc!D74 -> 0 | AA11: =SUM(C11:Z11) -> 0
B12: Enlèvement et rançon | C12: =Jan!C91 -> 0 | D12: =Jan!D91 -> 0 | E12: =Fév!C91 -> 0 | F12: =Fév!D91 -> 0 | G12: =Mar!C91 -> 0 | H12: =Mar!D91 -> 0 | I12: =Avr!C91 -> 0 | J12: =Avr!D91 -> 0 | K12: =Mai!C91 -> 0 | L12: =Mai!D91 -> 0 | M12: =Juin!C91 -> 0 | N12: =Juin!D91 -> 0 | O12: =Juil!C91 -> 0 | P12: =Juil!D91 -> 0 | Q12: =Août!C91 -> 0 | R12: =Août!D91 -> 0 | S12: =Sep!C91 -> 0 | T12: =Sep!D91 -> 0 | U12: =Oct!C91 -> 0 | V12: =Oct!D91 -> 0 | W12: =Nov!C91 -> 0 | X12: =Nov!D91 -> 0 | Y12: =Déc!C91 -> 0 | Z12: =Déc!D91 -> 0 | AA12: =SUM(C12:Z12) -> 0
B13: Conseil en risques | C13: =Jan!C107 -> 0 | D13: =Jan!D107 -> 0 | E13: =Fév!C107 -> 0 | F13: =Fév!D107 -> 0 | G13: =Mar!C107 -> 0 | H13: =Mar!D107 -> 0 | I13: =Avr!C107 -> 0 | J13: =Avr!D107 -> 0 | K13: =Mai!C107 -> 0 | L13: =Mai!D107 -> 0 | M13: =Juin!C107 -> 0 | N13: =Juin!D107 -> 0 | O13: =Juil!C107 -> 0 | P13: =Juil!D107 -> 0 | Q13: =Août!C107 -> 0 | R13: =Août!D107 -> 0 | S13: =Sep!C107 -> 0 | T13: =Sep!D107 -> 0 | U13: =Oct!C107 -> 0 | V13: =Oct!D107 -> 0 | W13: =Nov!C107 -> 0 | X13: =Nov!D107 -> 0 | Y13: =Déc!C107 -> 0 | Z13: =Déc!D107 -> 0 | AA13: =SUM(C13:Z13) -> 0
B14: Gestion du rapatriement | C14: =Jan!C123 -> 0 | D14: =Jan!D123 -> 0 | E14: =Fév!C123 -> 0 | F14: =Fév!D123 -> 0 | G14: =Mar!C123 -> 0 | H14: =Mar!D123 -> 0 | I14: =Avr!C123 -> 0 | J14: =Avr!D123 -> 0 | K14: =Mai!C123 -> 0 | L14: =Mai!D123 -> 0 | M14: =Juin!C123 -> 0 | N14: =Juin!D123 -> 0 | O14: =Juil!C123 -> 0 | P14: =Juil!D123 -> 0 | Q14: =Août!C123 -> 0 | R14: =Août!D123 -> 0 | S14: =Sep!C123 -> 0 | T14: =Sep!D123 -> 0 | U14: =Oct!C123 -> 0 | V14: =Oct!D123 -> 0 | W14: =Nov!C123 -> 0 | X14: =Nov!D123 -> 0 | Y14: =Déc!C123 -> 0 | Z14: =Déc!D123 -> 0 | AA14: =SUM(C14:Z14) -> 0
B15: Gestion des accidents | C15: =Jan!C139 -> 0 | D15: =Jan!D139 -> 0 | E15: =Fév!C139 -> 0 | F15: =Fév!D139 -> 0 | G15: =Mar!C139 -> 0 | H15: =Mar!D139 -> 0 | I15: =Avr!C139 -> 0 | J15: =Avr!D139 -> 0 | K15: =Mai!C139 -> 0 | L15: =Mai!D139 -> 0 | M15: =Juin!C139 -> 0 | N15: =Juin!D139 -> 0 | O15: =Juil!C139 -> 0 | P15: =Juil!D139 -> 0 | Q15: =Août!C139 -> 0 | R15: =Août!D139 -> 0 | S15: =Sep!C139 -> 0 | T15: =Sep!D139 -> 0 | U15: =Oct!C139 -> 0 | V15: =Oct!D139 -> 0 | W15: =Nov!C139 -> 0 | X15: =Nov!D139 -> 0 | Y15: =Déc!C139 -> 0 | Z15: =Déc!D139 -> 0 | AA15: =SUM(C15:Z15) -> 0
B16: Formation à la sécurité des conducteurs | C16: =Jan!I20 -> 0 | D16: =Jan!J20 -> 0 | E16: =Fév!I20 -> 0 | F16: =Fév!J20 -> 0 | G16: =Mar!I20 -> 0 | H16: =Mar!J20 -> 0 | I16: =Avr!I20 -> 0 | J16: =Avr!J20 -> 0 | K16: =Mai!I20 -> 0 | L16: =Mai!J20 -> 0 | M16: =Juin!I20 -> 0 | N16: =Juin!J20 -> 0 | O16: =Juil!I20 -> 0 | P16: =Juil!J20 -> 0 | Q16: =Août!I20 -> 0 | R16: =Août!J20 -> 0 | S16: =Sep!I20 -> 0 | T16: =Sep!J20 -> 0 | U16: =Oct!I20 -> 0 | V16: =Oct!J20 -> 0 | W16: =Nov!I20 -> 0 | X16: =Nov!J20 -> 0 | Y16: =Déc!I20 -> 0 | Z16: =Déc!J20 -> 0 | AA16: =SUM(C16:Z16) -> 0
B17: Gestion de la sécurité | C17: =Jan!I42 -> 0 | D17: =Jan!J42 -> 0 | E17: =Fév!I42 -> 0 | F17: =Fév!J42 -> 0 | G17: =Mar!I42 -> 0 | H17: =Mar!J42 -> 0 | I17: =Avr!I42 -> 0 | J17: =Avr!J42 -> 0 | K17: =Mai!I42 -> 0 | L17: =Mai!J42 -> 0 | M17: =Juin!I42 -> 0 | N17: =Juin!J42 -> 0 | O17: =Juil!I42 -> 0 | P17: =Juil!J42 -> 0 | Q17: =Août!I42 -> 0 | R17: =Août!J42 -> 0 | S17: =Sep!I42 -> 0 | T17: =Sep!J42 -> 0 | U17: =Oct!I42 -> 0 | V17: =Oct!J42 -> 0 | W17: =Nov!I42 -> 0 | X17: =Nov!J42 -> 0 | Y17: =Déc!I42 -> 0 | Z17: =Déc!J42 -> 0 | AA17: =SUM(C17:Z17) -> 0
B18: Gestion des catastrophes | C18: =Jan!I58 -> 0 | D18: =Jan!J58 -> 0 | E18: =Fév!I58 -> 0 | F18: =Fév!J58 -> 0 | G18: =Mar!I58 -> 0 | H18: =Mar!J58 -> 0 | I18: =Avr!I58 -> 0 | J18: =Avr!J58 -> 0 | K18: =Mai!I58 -> 0 | L18: =Mai!J58 -> 0 | M18: =Juin!I58 -> 0 | N18: =Juin!J58 -> 0 | O18: =Juil!I58 -> 0 | P18: =Juil!J58 -> 0 | Q18: =Août!I58 -> 0 | R18: =Août!J58 -> 0 | S18: =Sep!I58 -> 0 | T18: =Sep!J58 -> 0 | U18: =Oct!I58 -> 0 | V18: =Oct!J58 -> 0 | W18: =Nov!I58 -> 0 | X18: =Nov!J58 -> 0 | Y18: =Déc!I58 -> 0 | Z18: =Déc!J58 -> 0 | AA18: =SUM(C18:Z18) -> 0
B19: Fraude et corruption | C19: =Jan!I74 -> 0 | D19: =Jan!J74 -> 0 | E19: =Fév!I74 -> 0 | F19: =Fév!J74 -> 0 | G19: =Mar!I74 -> 0 | H19: =Mar!J74 -> 0 | I19: =Avr!I74 -> 0 | J19: =Avr!J74 -> 0 | K19: =Mai!I74 -> 0 | L19: =Mai!J74 -> 0 | M19: =Juin!I74 -> 0 | N19: =Juin!J74 -> 0 | O19: =Juil!I74 -> 0 | P19: =Juil!J74 -> 0 | Q19: =Août!I74 -> 0 | R19: =Août!J74 -> 0 | S19: =Sep!I74 -> 0 | T19: =Sep!J74 -> 0 | U19: =Oct!I74 -> 0 | V19: =Oct!J74 -> 0 | W19: =Nov!I74 -> 0 | X19: =Nov!J74 -> 0 | Y19: =Déc!I74 -> 0 | Z19: =Déc!J74 -> 0 | AA19: =SUM(C19:Z19) -> 0
B20: Intimidation et coercition | C20: =Jan!I91 -> 0 | D20: =Jan!J91 -> 0 | E20: =Fév!I91 -> 0 | F20: =Fév!J91 -> 0 | G20: =Mar!I91 -> 0 | H20: =Mar!J91 -> 0 | I20: =Avr!I74 -> 0 | J20: =Avr!J74 -> 0 | K20: =Mai!I91 -> 0 | L20: =Mai!J91 -> 0 | M20: =Juin!I91 -> 0 | N20: =Juin!J91 -> 0 | O20: =Juil!I91 -> 0 | P20: =Juil!J91 -> 0 | Q20: =Août!I91 -> 0 | R20: =Août!J91 -> 0 | S20: =Sep!I91 -> 0 | T20: =Sep!J91 -> 0 | U20: =Oct!I91 -> 0 | V20: =Oct!J91 -> 0 | W20: =Nov!I91 -> 0 | X20: =Nov!J91 -> 0 | Y20: =Déc!I91 -> 0 | Z20: =Déc!J91 -> 0 | AA20: =SUM(C20:Z20) -> 0
B21: Arrestation et détention | C21: =Jan!I107 -> 0 | D21: =Jan!J107 -> 0 | E21: =Fév!I107 -> 0 | F21: =Fév!J107 -> 0 | G21: =Mar!I107 -> 0 | H21: =Mar!J107 -> 0 | I21: =Avr!I107 -> 0 | J21: =Avr!J107 -> 0 | K21: =Mai!I107 -> 0 | L21: =Mai!J107 -> 0 | M21: =Juin!I107 -> 0 | N21: =Juin!J107 -> 0 | O21: =Juil!I107 -> 0 | P21: =Juil!J107 -> 0 | Q21: =Août!I107 -> 0 | R21: =Août!J107 -> 0 | S21: =Sep!I107 -> 0 | T21: =Sep!J107 -> 0 | U21: =Oct!I107 -> 0 | V21: =Oct!J107 -> 0 | W21: =Nov!I107 -> 0 | X21: =Nov!J107 -> 0 | Y21: =Déc!I107 -> 0 | Z21: =Déc!J107 -> 0 | AA21: =SUM(C21:Z21) -> 0
B22: Méthodes d'enseignement | C22: =Jan!I123 -> 0 | D22: =Jan!J123 -> 0 | E22: =Fév!I123 -> 0 | F22: =Fév!J123 -> 0 | G22: =Mar!I123 -> 0 | H22: =Mar!J123 -> 0 | I22: =Avr!I123 -> 0 | J22: =Avr!J123 -> 0 | K22: =Mai!I123 -> 0 | L22: =Mai!J123 -> 0 | M22: =Juin!I123 -> 0 | N22: =Juin!J123 -> 0 | O22: =Juil!I123 -> 0 | P22: =Juil!J123 -> 0 | Q22: =Août!I123 -> 0 | R22: =Août!J123 -> 0 | S22: =Sep!I123 -> 0 | T22: =Sep!J123 -> 0 | U22: =Oct!I123 -> 0 | V22: =Oct!J123 -> 0 | W22: =Nov!I123 -> 0 | X22: =Nov!J123 -> 0 | Y22: =Déc!I123 -> 0 | Z22: =Déc!J123 -> 0 | AA22: =SUM(C22:Z22) -> 0
B23: Logistique et approvisionnement | C23: =Jan!I139 -> 0 | D23: =Jan!J139 -> 0 | E23: =Fév!C139 -> 0 | F23: =Fév!D139 -> 0 | G23: =Mar!C139 -> 0 | H23: =Mar!D139 -> 0 | I23: =Avr!C139 -> 0 | J23: =Avr!D139 -> 0 | K23: =Mai!C139 -> 0 | L23: =Mai!D139 -> 0 | M23: =Juin!C139 -> 0 | N23: =Juin!D139 -> 0 | O23: =Juil!C139 -> 0 | P23: =Juil!D139 -> 0 | Q23: =Août!C139 -> 0 | R23: =Août!D139 -> 0 | S23: =Sep!C139 -> 0 | T23: =Sep!D139 -> 0 | U23: =Oct!C139 -> 0 | V23: =Oct!D139 -> 0 | W23: =Nov!C139 -> 0 | X23: =Nov!D139 -> 0 | Y23: =Déc!I139 -> 0 | Z23: =Déc!J139 -> 0 | AA23: =SUM(C23:Z23) -> 0
B33: Sous-totaux | C33: =SUM(C8:C32) -> 0 | D33: =SUM(D8:D32) -> 0 | E33: =SUM(E8:E32) -> 0 | F33: =SUM(F8:F32) -> 0 | G33: =SUM(G8:G32) -> 0 | H33: =SUM(H8:H32) -> 0 | I33: =SUM(I8:I32) -> 0 | J33: =SUM(J8:J32) -> 0 | ... AA33: =SUM(AA8:AA32) -> 0
B35: Hommes | C35: =C33+E33+G33+I33+K33+M33+O33+Q33+S33+U33+W33+Y33 -> 0
B36: Femmes | C36: =D33+F33+H33+J33+L33+N33+P33+R33+T33+V33+X33+Z33 -> 0
B37: Totaux finaux | C37: =SUM(C35:C36) -> 0
B39: Notes:

Sheet Jan
B2: Dossiers de formation
B4: Mois | C4: Janvier | F4: Année | H4: 2012
B6: Formation en milieu hostile | C6: Expatriés | E6: Locaux | H6: Formation à la sécurité des conducteurs | I6: Expatriés | K6: Locaux
C7: Homme | D7: Femme | E7: Homme | F7: Femme | I7: Homme | J7: Femme | K7: Homme | L7: Femme
B8: Risques d'origine humaine | H8: Introduction
B9: Risques naturels | H9: Sûreté et sécurité du véhicule
B10: Déplacements terrestres | H10: Les exercices du poste de pilotage
B11: Sécurité personnelle | H11: Exercices d'observation
B12: Aléas culturels et sociaux | H12: Positionnement routier
B13: Sécurité du véhicule | H13: Techniques de pilotage
B14: Enlèvement et rançon | H14: Le système de commande du véhicule
B15: Formation d'intégration | H15: Contrôles du véhicule
B16: Exercices d'intervention d'urgence | H16: Forces agissant sur les véhicules
B17: Santé et hygiène | H17: Dépassement et positionnement
B18: Travailler avec une équipe de sécurité | H18: Traverser et pilonnage
B19: Totaux | C19: =SUM(C8:C18) -> 0 | D19: =SUM(D8:D18) -> 0 | E19: =SUM(E8:E18) -> 0 | F19: =SUM(F8:F18) -> 0 | H19: Totaux | I19: =SUM(I8:I18) -> 0 | J19: =SUM(J8:J18) -> 0 | K19: =SUM(K8:K18) -> 0 | L19: =SUM(L8:L18) -> 0
B20: Homme et femme | C20: =C19+E19 -> 0 | D20: =D19+F19 -> 0 | H20: Homme et femme | I20: =I19+K19 -> 0 | J20: =J19+L19 -> 0
B22: Direction de crise | C22: Expatriés | E22: Locaux | H22: Gestion de la sécurité | I22: Expatriés | K22: Locaux
C23: Homme | D23: Femme | E23: Homme | F23: Femme | I23: Homme | J23: Femme | K23: Homme | L23: Femme
B24: Comprendre les événements de crise | H24: Élaboration de politiques et de plans
B25: Gestion de crise | H25: Pratique : conception de la politique
B26: Points d'échec courants | H26: Gestion de la sécurité
B27: Systèmes et outils de gestion des risques | H27: Gestion des forces de garde
B28: Plan de gestion des incidents | H28: Évaluations des menaces
B29: Plan de continuité des activités | H29: Planification de l'entrée sur le marché
B30: Reprise des affaires | H30: Sécurité et processus d'appel d'offres
B31: Exercices de table | H31: Sécurité mobile - concept
H32: Sécurité mobile - stratégies
H33: Sécurité mobile - opérations
H34: Sécurité mobile - tactiques
H35: Procédures d'utilisation normalisées
H36: Planification d'événements
H37: Mobilisation et coordination
H38: Espèces en transit
H39: Gestion de la sécurité de l'établissement
H40: Construction de la sécurité de l'établissement
B41: Totaux | C41: =SUM(C24:C40) -> 0 | D41: =SUM(D24:D40) -> 0 | E41: =SUM(E24:E40) -> 0 | F41: =SUM(F24:F40) -> 0 | H41: Totaux | I41: =SUM(I24:I40) -> 0 | J41: =SUM(J24:J40) -> 0 | K41: =SUM(K24:K40) -> 0 | L41: =SUM(L24:L40) -> 0
B42: Homme et femme | C42: =C41+E41 -> 0 | D42: =D41+F41 -> 0 | H42: Homme et femme | I42: =I41+K41 -> 0 | J42: =J41+L41 -> 0
B44: Gestion des évacuations | C44: Expatriés | E44: Locaux | H44: Gestion des catastrophes | I44: Expatriés | K44: Locaux
C45: Homme | D45: Femme | E45: Homme | F45: Femme | I45: Homme | J45: Femme | K45: Homme | L45: Femme
...

Sheet Fév
B2: Dossiers de formation
B4: Mois | C4: Février | F4: Année | H4: 2012
B6: Formation en milieu hostile | C6: Expatriés | E6: Locaux | H6: Formation à la sécurité des conducteurs | I6: Expatriés | K6: Locaux
C7: Homme | D7: Femme | E7: Homme | F7: Femme | I7: Homme | J7: Femme | K7: Homme | L7: Femme
B8: Risques d'origine humaine | H8: Introduction
B9: Risques naturels | H9: Sûreté et sécurité du véhicule
B10: Déplacements terrestres | H10: Les exercices du poste de pilotage
B11: Sécurité personnelle | H11: Exercices d'observation
B12: Aléas culturels et sociaux | H12: Positionnement routier
B13: Sécurité du véhicule | H13: Techniques de pilotage
B14: Enlèvement et rançon | H14: Le système de commande du véhicule
B15: Formation d'intégration | H15: Contrôles du véhicule
B16: Exercices d'intervention d'urgence | H16: Forces agissant sur les véhicules
B17: Santé et hygiène | H17: Dépassement et positionnement
B18: Travailler avec une équipe de sécurité | H18: Traverser et pilonnage
B19: Totaux | C19: =SUM(C8:C18) -> 0 | D19: =SUM(D8:D18) -> 0 | E19: =SUM(E8:E18) -> 0 | F19: =SUM(F8:F18) -> 0 | H19: Totaux | I19: =SUM(I8:I18) -> 0 | J19: =SUM(J8:J18) -> 0 | K19: =SUM(K8:K18) -> 0 | L19: =SUM(L8:L18) -> 0
B20: Homme et femme | C20: =C19+E19 -> 0 | D20: =D19+F19 -> 0 | H20: Homme et femme | I20: =I19+K19 -> 0 | J20: =J19+L19 -> 0
B22: Direction de crise | C22: Expatriés | E22: Locaux | H22: Gestion de la sécurité | I22: Expatriés | K22: Locaux
C23: Homme | D23: Femme | E23: Homme | F23: Femme | I23: Homme | J23: Femme | K23: Homme | L23: Femme
B24: Comprendre les événements de crise | H24: Élaboration de politiques et de plans
B25: Gestion de crise | H25: Pratique : conception de la politique
B26: Points d'échec courants | H26: Gestion de la sécurité
B27: Systèmes et outils de gestion des risques | H27: Gestion des forces de garde
B28: Plan de gestion des incidents | H28: Évaluations des menaces
B29: Plan de continuité des activités | H29: Planification de l'entrée sur le marché
B30: Reprise des affaires | H30: Sécurité et processus d'appel d'offres
B31: Exercices de table | H31: Sécurité mobile - concept
H32: Sécurité mobile - stratégies
H33: Sécurité mobile - opérations
H34: Sécurité mobile - tactiques
H35: Procédures d'utilisation normalisées
H36: Planification d'événements
H37: Mobilisation et coordination
H38: Espèces en transit
H39: Gestion de la sécurité de l'établissement
H40: Construction de la sécurité de l'établissement
B41: Totaux | C41: =SUM(C24:C40) -> 0 | D41: =SUM(D24:D40) -> 0 | E41: =SUM(E24:E40) -> 0 | F41: =SUM(F24:F40) -> 0 | H41: Totaux | I41: =SUM(I24:I40) -> 0 | J41: =SUM(J24:J40) -> 0 | K41: =SUM(K24:K40) -> 0 | L41: =SUM(L24:L40) -> 0
B42: Homme et femme | C42: =C41+E41 -> 0 | D42: =D41+F41 -> 0 | H42: Homme et femme | I42: =I41+K41 -> 0 | J42: =J41+L41 -> 0
B44: Gestion des évacuations | C44: Expatriés | E44: Locaux | H44: Gestion des catastrophes | I44: Expatriés | K44: Locaux
C45: Homme | D45: Femme | E45: Homme | F45: Femme | I45: Homme | J45: Femme | K45: Homme | L45: Femme
...

Sheet Mar
B2: Dossiers de formation
B4: Mois | C4: Mars | F4: Année | H4: 2012
B6: Formation en milieu hostile | C6: Expatriés | E6: Locaux | H6: Formation à la sécurité des conducteurs | I6: Expatriés | K6: Locaux
C7: Homme | D7: Femme | E7: Homme | F7: Femme | I7: Homme | J7: Femme | K7: Homme | L7: Femme
B8: Risques d'origine humaine | H8: Introduction
B9: Risques naturels | H9: Sûreté et sécurité du véhicule
B10: Déplacements terrestres | H10: Les exercices du poste de pilotage
B11: Sécurité personnelle | H11: Exercices d'observation
B12: Aléas culturels et sociaux | H12: Positionnement routier
B13: Sécurité du véhicule | H13: Techniques de pilotage
B14: Enlèvement et rançon | H14: Le système de commande du véhicule
B15: Formation d'intégration | H15: Contrôles du véhicule
B16: Exercices d'intervention d'urgence | H16: Forces agissant sur les véhicules
B17: Santé et hygiène | H17: Dépassement et positionnement
B18: Travailler avec une équipe de sécurité | H18: Traverser et pilonnage
B19: Totaux | C19: =SUM(C8:C18) -> 0 | D19: =SUM(D8:D18) -> 0 | E19: =SUM(E8:E18) -> 0 | F19: =SUM(F8:F18) -> 0 | H19: Totaux | I19: =SUM(I8:I18) -> 0 | J19: =SUM(J8:J18) -> 0 | K19: =SUM(K8:K18) -> 0 | L19: =SUM(L8:L18) -> 0
B20: Homme et femme | C20: =C19+E19 -> 0 | D20: =D19+F19 -> 0 | H20: Homme et femme | I20: =I19+K19 -> 0 | J20: =J19+L19 -> 0
B22: Direction de crise | C22: Expatriés | E22: Locaux | H22: Gestion de la sécurité | I22: Expatriés | K22: Locaux
C23: Homme | D23: Femme | E23: Homme | F23: Femme | I23: Homme | J23: Femme | K23: Homme | L23: Femme
B24: Comprendre les événements de crise | H24: Élaboration de politiques et de plans
B25: Gestion de crise | H25: Pratique : conception de la politique
B26: Points d'échec courants | H26: Gestion de la sécurité
B27: Systèmes et outils de gestion des risques | H27: Gestion des forces de garde
B28: Plan de gestion des incidents | H28: Évaluations des menaces
B29: Plan de continuité des activités | H29: Planification de l'entrée sur le marché
B30: Reprise des affaires | H30: Sécurité et processus d'appel d'offres
B31: Exercices de table | H31: Sécurité mobile - concept
H32: Sécurité mobile - stratégies
H33: Sécurité mobile - opérations
H34: Sécurité mobile - tactiques
H35: Procédures d'utilisation normalisées
H36: Planification d'événements
H37: Mobilisation et coordination
H38: Espèces en transit
H39: Gestion de la sécurité de l'établissement
H40: Construction de la sécurité de l'établissement
B41: Totaux | C41: =SUM(C24:C40) -> 0 | D41: =SUM(D24:D40) -> 0 | E41: =SUM(E24:E40) -> 0 | F41: =SUM(F24:F40) -> 0 | H41: Totaux | I41: =SUM(I24:I40) -> 0 | J41: =SUM(J24:J40) -> 0 | K41: =SUM(K24:K40) -> 0 | L41: =SUM(L24:L40) -> 0
B42: Homme et femme | C42: =C41+E41 -> 0 | D42: =D41+F41 -> 0 | H42: Homme et femme | I42: =I41+K41 -> 0 | J42: =J41+L41 -> 0
B44: Gestion des évacuations | C44: Expatriés | E44: Locaux | H44: Gestion des catastrophes | I44: Expatriés | K44: Locaux
C45: Homme | D45: Femme | E45: Homme | F45: Femme | I45: Homme | J45: Femme | K45: Homme | L45: Femme
...

Sheet Avr
B2: Dossiers de formation
B4: Mois | C4: Avril | F4: Année | H4: 2012
B6: Formation en milieu hostile | C6: Expatriés | E6: Locaux | H6: Formation à la sécurité des conducteurs | I6: Expatriés | K6: Locaux
C7: Homme | D7: Femme | E7: Homme | F7: Femme | I7: Homme | J7: Femme | K7: Homme | L7: Femme
B8: Risques d'origine humaine | H8: Introduction
B9: Risques naturels | H9: Sûreté et sécurité du véhicule
B10: Déplacements terrestres | H10: Les exercices du poste de pilotage
B11: Sécurité personnelle | H11: Exercices d'observation
B12: Aléas culturels et sociaux | H12: Positionnement routier
B13: Sécurité du véhicule | H13: Techniques de pilotage
B14: Enlèvement et rançon | H14: Le système de commande du véhicule
B15: Formation d'intégration | H15: Contrôles du véhicule
B16: Exercices d'intervention d'urgence | H16: Forces agissant sur les véhicules
B17: Santé et hygiène | H17: Dépassement et positionnement
B18: Travailler avec une équipe de sécurité | H18: Traverser et pilonnage
B19: Totaux | C19: =SUM(C8:C18) -> 0 | D19: =SUM(D8:D18) -> 0 | E19: =SUM(E8:E18) -> 0 | F19: =SUM(F8:F18) -> 0 | H19: Totaux | I19: =SUM(I8:I18) -> 0 | J19: =SUM(J8:J18) -> 0 | K19: =SUM(K8:K18) -> 0 | L19: =SUM(L8:L18) -> 0
B20: Homme et femme | C20: =C19+E19 -> 0 | D20: =D19+F19 -> 0 | H20: Homme et femme | I20: =I19+K19 -> 0 | J20: =J19+L19 -> 0
B22: Direction de crise | C22: Expatriés | E22: Locaux | H22: Gestion de la sécurité | I22: Expatriés | K22: Locaux
C23: Homme | D23: Femme | E23: Homme | F23: Femme | I23: Homme | J23: Femme | K23: Homme | L23: Femme
B24: Comprendre les événements de crise | H24: Élaboration de politiques et de plans
B25: Gestion de crise | H25: Pratique : conception de la politique
B26: Points d'échec courants | H26: Gestion de la sécurité
B27: Systèmes et outils de gestion des risques | H27: Gestion des forces de garde
B28: Plan de gestion des incidents | H28: Évaluations des menaces
B29: Plan de continuité des activités | H29: Planification de l'entrée sur le marché
B30: Reprise des affaires | H30: Sécurité et processus d'appel d'offres
B31: Exercices de table | H31: Sécurité mobile - concept
H32: Sécurité mobile - stratégies
H33: Sécurité mobile - opérations
H34: Sécurité mobile - tactiques
H35: Procédures d'utilisation normalisées
H36: Planification d'événements
H37: Mobilisation et coordination
H38: Espèces en transit
H39: Gestion de la sécurité de l'établissement
H40: Construction de la sécurité de l'établissement
B41: Totaux | C41: =SUM(C24:C40) -> 0 | D41: =SUM(D24:D40) -> 0 | E41: =SUM(E24:E40) -> 0 | F41: =SUM(F24:F40) -> 0 | H41: Totaux | I41: =SUM(I24:I40) -> 0 | J41: =SUM(J24:J40) -> 0 | K41: =SUM(K24:K40) -> 0 | L41: =SUM(L24:L40) -> 0
B42: Homme et femme | C42: =C41+E41 -> 0 | D42: =D41+F41 -> 0 | H42: Homme et femme | I42: =I41+K41 -> 0 | J42: =J41+L41 -> 0
B44: Gestion des évacuations | C44: Expatriés | E44: Locaux | H44: Gestion des catastrophes | I44: Expatriés | K44: Locaux
C45: Homme | D45: Femme | E45: Homme | F45: Femme | I45: Homme | J45: Femme | K45: Homme | L45: Femme
...

Sheet Mai
B2: Dossiers de formation
B4: Mois | C4: Avril | F4: Année | H4: 2012
B6: Formation en milieu hostile | C6: Expatriés | E6: Locaux | H6: Formation à la sécurité des conducteurs | I6: Expatriés | K6: Locaux
C7: Homme | D7: Femme | E7: Homme | F7: Femme | I7: Homme | J7: Femme | K7: Homme | L7: Femme
B8: Risques d'origine humaine | H8: Introduction
B9: Risques naturels | H9: Sûreté et sécurité du véhicule
B10: Déplacements terrestres | H10: Les exercices du poste de pilotage
B11: Sécurité personnelle | H11: Exercices d'observation
B12: Aléas culturels et sociaux | H12: Positionnement routier
B13: Sécurité du véhicule | H13: Techniques de pilotage
B14: Enlèvement et rançon | H14: Le système de commande du véhicule
B15: Formation d'intégration | H15: Contrôles du véhicule
B16: Exercices d'intervention d'urgence | H16: Forces agissant sur les véhicules
B17: Santé et hygiène | H17: Dépassement et positionnement
B18: Travailler avec une équipe de sécurité | H18: Traverser et pilonnage
B19: Totaux | C19: =SUM(C8:C18) -> 0 | D19: =SUM(D8:D18) -> 0 | E19: =SUM(E8:E18) -> 0 | F19: =SUM(F8:F18) -> 0 | H19: Totaux | I19: =SUM(I8:I18) -> 0 | J19: =SUM(J8:J18) -> 0 | K19: =SUM(K8:K18) -> 0 | L19: =SUM(L8:L18) -> 0
B20: Homme et femme | C20: =C19+E19 -> 0 | D20: =D19+F19 -> 0 | H20: Homme et femme | I20: =I19+K19 -> 0 | J20: =J19+L19 -> 0
B22: Direction de crise | C22: Expatriés | E22: Locaux | H22: Gestion de la sécurité | I22: Expatriés | K22: Locaux
C23: Homme | D23: Femme | E23: Homme | F23: Femme | I23: Homme | J23: Femme | K23: Homme | L23: Femme
B24: Comprendre les événements de crise | H24: Élaboration de politiques et de plans
B25: Gestion de crise | H25: Pratique : conception de la politique
B26: Points d'échec courants | H26: Gestion de la sécurité
B27: Systèmes et outils de gestion des risques | H27: Gestion des forces de garde
B28: Plan de gestion des incidents | H28: Évaluations des menaces
B29: Plan de continuité des activités | H29: Planification de l'entrée sur le marché
B30: Reprise des affaires | H30: Sécurité et processus d'appel d'offres
B31: Exercices de table | H31: Sécurité mobile - concept
H32: Sécurité mobile - stratégies
H33: Sécurité mobile - opérations
H34: Sécurité mobile - tactiques
H35: Procédures d'utilisation normalisées
H36: Planification d'événements
H37: Mobilisation et coordination
H38: Espèces en transit
H39: Gestion de la sécurité de l'établissement
H40: Construction de la sécurité de l'établissement
B41: Totaux | C41: =SUM(C24:C40) -> 0 | D41: =SUM(D24:D40) -> 0 | E41: =SUM(E24:E40) -> 0 | F41: =SUM(F24:F40) -> 0 | H41: Totaux | I41: =SUM(I24:I40) -> 0 | J41: =SUM(J24:J40) -> 0 | K41: =SUM(K24:K40) -> 0 | L41: =SUM(L24:L40) -> 0
B42: Homme et femme | C42: =C41+E41 -> 0 | D42: =D41+F41 -> 0 | H42: Homme et femme | I42: =I41+K41 -> 0 | J42: =J41+L41 -> 0
B44: Gestion des évacuations | C44: Expatriés | E44: Locaux | H44: Gestion des catastrophes | I44: Expatriés | K44: Locaux
C45: Homme | D45: Femme | E45: Homme | F45: Femme | I45: Homme | J45: Femme | K45: Homme | L45: Femme
...

Sheet Juin
B2: Dossiers de formation
B4: Mois | C4: Juin | F4: Année | H4: 2012
B6: Formation en milieu hostile | C6: Expatriés | E6: Locaux | H6: Formation à la sécurité des conducteurs | I6: Expatriés | K6: Locaux
C7: Homme | D7: Femme | E7: Homme | F7: Femme | I7: Homme | J7: Femme | K7: Homme | L7: Femme
B8: Risques d'origine humaine | H8: Introduction
B9: Risques naturels | H9: Sûreté et sécurité du véhicule
B10: Déplacements terrestres | H10: Les exercices du poste de pilotage
B11: Sécurité personnelle | H11: Exercices d'observation
B12: Aléas culturels et sociaux | H12: Positionnement routier
B13: Sécurité du véhicule | H13: Techniques de pilotage
B14: Enlèvement et rançon | H14: Le système de commande du véhicule
B15: Formation d'intégration | H15: Contrôles du véhicule
B16: Exercices d'intervention d'urgence | H16: Forces agissant sur les véhicules
B17: Santé et hygiène | H17: Dépassement et positionnement
B18: Travailler avec une équipe de sécurité | H18: Traverser et pilonnage
B19: Totaux | C19: =SUM(C8:C18) -> 0 | D19: =SUM(D8:D18) -> 0 | E19: =SUM(E8:E18) -> 0 | F19: =SUM(F8:F18) -> 0 | H19: Totaux | I19: =SUM(I8:I18) -> 0 | J19: =SUM(J8:J18) -> 0 | K19: =SUM(K8:K18) -> 0 | L19: =SUM(L8:L18) -> 0
B20: Homme et femme | C20: =C19+E19 -> 0 | D20: =D19+F19 -> 0 | H20: Homme et femme | I20: =I19+K19 -> 0 | J20: =J19+L19 -> 0
B22: Direction de crise | C22: Expatriés | E22: Locaux | H22: Gestion de la sécurité | I22: Expatriés | K22: Locaux
C23: Homme | D23: Femme | E23: Homme | F23: Femme | I23: Homme | J23: Femme | K23: Homme | L23: Femme
B24: Comprendre les événements de crise | H24: Élaboration de politiques et de plans
B25: Gestion de crise | H25: Pratique : conception de la politique
B26: Points d'échec courants | H26: Gestion de la sécurité
B27: Systèmes et outils de gestion des risques | H27: Gestion des forces de garde
B28: Plan de gestion des incidents | H28: Évaluations des menaces
B29: Plan de continuité des activités | H29: Planification de l'entrée sur le marché
B30: Reprise des affaires | H30: Sécurité et processus d'appel d'offres
B31: Exercices de table | H31: Sécurité mobile - concept
H32: Sécurité mobile - stratégies
H33: Sécurité mobile - opérations
H34: Sécurité mobile - tactiques
H35: Procédures d'utilisation normalisées
H36: Planification d'événements
H37: Mobilisation et coordination
H38: Espèces en transit
H39: Gestion de la sécurité de l'établissement
H40: Construction de la sécurité de l'établissement
B41: Totaux | C41: =SUM(C24:C40) -> 0 | D41: =SUM(D24:D40) -> 0 | E41: =SUM(E24:E40) -> 0 | F41: =SUM(F24:F40) -> 0 | H41: Totaux | I41: =SUM(I24:I40) -> 0 | J41: =SUM(J24:J40) -> 0 | K41: =SUM(K24:K40) -> 0 | L41: =SUM(L24:L40) -> 0
B42: Homme et femme | C42: =C41+E41 -> 0 | D42: =D41+F41 -> 0 | H42: Homme et femme | I42: =I41+K41 -> 0 | J42: =J41+L41 -> 0
B44: Gestion des évacuations | C44: Expatriés | E44: Locaux | H44: Gestion des catastrophes | I44: Expatriés | K44: Locaux
C45: Homme | D45: Femme | E45: Homme | F45: Femme | I45: Homme | J45: Femme | K45: Homme | L45: Femme
...

Sheet Juil
B2: Dossiers de formation
B4: Mois | C4: Juillet | F4: Année | H4: 2012
B6: Formation en milieu hostile | C6: Expatriés | E6: Locaux | H6: Formation à la sécurité des conducteurs | I6: Expatriés | K6: Locaux
C7: Homme | D7: Femme | E7: Homme | F7: Femme | I7: Homme | J7: Femme | K7: Homme | L7: Femme
B8: Risques d'origine humaine | H8: Introduction
B9: Risques naturels | H9: Sûreté et sécurité du véhicule
B10: Déplacements terrestres | H10: Les exercices du poste de pilotage
B11: Sécurité personnelle | H11: Exercices d'observation
B12: Aléas culturels et sociaux | H12: Positionnement routier
B13: Sécurité du véhicule | H13: Techniques de pilotage
B14: Enlèvement et rançon | H14: Le système de commande du véhicule
B15: Formation d'intégration | H15: Contrôles du véhicule
B16: Exercices d'intervention d'urgence | H16: Forces agissant sur les véhicules
B17: Santé et hygiène | H17: Dépassement et positionnement
B18: Travailler avec une équipe de sécurité | H18: Traverser et pilonnage
B19: Totaux | C19: =SUM(C8:C18) -> 0 | D19: =SUM(D8:D18) -> 0 | E19: =SUM(E8:E18) -> 0 | F19: =SUM(F8:F18) -> 0 | H19: Totaux | I19: =SUM(I8:I18) -> 0 | J19: =SUM(J8:J18) -> 0 | K19: =SUM(K8:K18) -> 0 | L19: =SUM(L8:L18) -> 0
B20: Homme et femme | C20: =C19+E19 -> 0 | D20: =D19+F19 -> 0 | H20: Homme et femme | I20: =I19+K19 -> 0 | J20: =J19+L19 -> 0
B22: Direction de crise | C22: Expatriés | E22: Locaux | H22: Gestion de la sécurité | I22: Expatriés | K22: Locaux
C23: Homme | D23: Femme | E23: Homme | F23: Femme | I23: Homme | J23: Femme | K23: Homme | L23: Femme
B24: Comprendre les événements de crise | H24: Élaboration de politiques et de plans
B25: Gestion de crise | H25: Pratique : conception de la politique
B26: Points d'échec courants | H26: Gestion de la sécurité
B27: Systèmes et outils de gestion des risques | H27: Gestion des forces de garde
B28: Plan de gestion des incidents | H28: Évaluations des menaces
B29: Plan de continuité des activités | H29: Planification de l'entrée sur le marché
B30: Reprise des affaires | H30: Sécurité et processus d'appel d'offres
B31: Exercices de table | H31: Sécurité mobile - concept
H32: Sécurité mobile - stratégies
H33: Sécurité mobile - opérations
H34: Sécurité mobile - tactiques
H35: Procédures d'utilisation normalisées
H36: Planification d'événements
H37: Mobilisation et coordination
H38: Espèces en transit
H39: Gestion de la sécurité de l'établissement
H40: Construction de la sécurité de l'établissement
B41: Totaux | C41: =SUM(C24:C40) -> 0 | D41: =SUM(D24:D40) -> 0 | E41: =SUM(E24:E40) -> 0 | F41: =SUM(F24:F40) -> 0 | H41: Totaux | I41: =SUM(I24:I40) -> 0 | J41: =SUM(J24:J40) -> 0 | K41: =SUM(K24:K40) -> 0 | L41: =SUM(L24:L40) -> 0
B42: Homme et femme | C42: =C41+E41 -> 0 | D42: =D41+F41 -> 0 | H42: Homme et femme | I42: =I41+K41 -> 0 | J42: =J41+L41 -> 0
B44: Gestion des évacuations | C44: Expatriés | E44: Locaux | H44: Gestion des catastrophes | I44: Expatriés | K44: Locaux
C45: Homme | D45: Femme | E45: Homme | F45: Femme | I45: Homme | J45: Femme | K45: Homme | L45: Femme
...

Sheet Août
B2: Dossiers de formation
B4: Mois | C4: Août | F4: Année | H4: 2012
B6: Formation en milieu hostile | C6: Expatriés | E6: Locaux | H6: Formation à la sécurité des conducteurs | I6: Expatriés | K6: Locaux
C7: Homme | D7: Femme | E7: Homme | F7: Femme | I7: Homme | J7: Femme | K7: Homme | L7: Femme
B8: Risques d'origine humaine | H8: Introduction
B9: Risques naturels | H9: Sûreté et sécurité du véhicule
B10: Déplacements terrestres | H10: Les exercices du poste de pilotage
B11: Sécurité personnelle | H11: Exercices d'observation
B12: Aléas culturels et sociaux | H12: Positionnement routier
B13: Sécurité du véhicule | H13: Techniques de pilotage
B14: Enlèvement et rançon | H14: Le système de commande du véhicule
B15: Formation d'intégration | H15: Contrôles du véhicule
B16: Exercices d'intervention d'urgence | H16: Forces agissant sur les véhicules
B17: Santé et hygiène | H17: Dépassement et positionnement
B18: Travailler avec une équipe de sécurité | H18: Traverser et pilonnage
B19: Totaux | C19: =SUM(C8:C18) -> 0 | D19: =SUM(D8:D18) -> 0 | E19: =SUM(E8:E18) -> 0 | F19: =SUM(F8:F18) -> 0 | H19: Totaux | I19: =SUM(I8:I18) -> 0 | J19: =SUM(J8:J18) -> 0 | K19: =SUM(K8:K18) -> 0 | L19: =SUM(L8:L18) -> 0
B20: Homme et femme | C20: =C19+E19 -> 0 | D20: =D19+F19 -> 0 | H20: Homme et femme | I20: =I19+K19 -> 0 | J20: =J19+L19 -> 0
B22: Direction de crise | C22: Expatriés | E22: Locaux | H22: Gestion de la sécurité | I22: Expatriés | K22: Locaux
C23: Homme | D23: Femme | E23: Homme | F23: Femme | I23: Homme | J23: Femme | K23: Homme | L23: Femme
B24: Comprendre les événements de crise | H24: Élaboration de politiques et de plans
B25: Gestion de crise | H25: Pratique : conception de la politique
B26: Points d'échec courants | H26: Gestion de la sécurité
B27: Systèmes et outils de gestion des risques | H27: Gestion des forces de garde
B28: Plan de gestion des incidents | H28: Évaluations des menaces
B29: Plan de continuité des activités | H29: Planification de l'entrée sur le marché
B30: Reprise des affaires | H30: Sécurité et processus d'appel d'offres
B31: Exercices de table | H31: Sécurité mobile - concept
H32: Sécurité mobile - stratégies
H33: Sécurité mobile - opérations
H34: Sécurité mobile - tactiques
H35: Procédures d'utilisation normalisées
H36: Planification d'événements
H37: Mobilisation et coordination
H38: Espèces en transit
H39: Gestion de la sécurité de l'établissement
H40: Construction de la sécurité de l'établissement
B41: Totaux | C41: =SUM(C24:C40) -> 0 | D41: =SUM(D24:D40) -> 0 | E41: =SUM(E24:E40) -> 0 | F41: =SUM(F24:F40) -> 0 | H41: Totaux | I41: =SUM(I24:I40) -> 0 | J41: =SUM(J24:J40) -> 0 | K41: =SUM(K24:K40) -> 0 | L41: =SUM(L24:L40) -> 0
B42: Homme et femme | C42: =C41+E41 -> 0 | D42: =D41+F41 -> 0 | H42: Homme et femme | I42: =I41+K41 -> 0 | J42: =J41+L41 -> 0
B44: Gestion des évacuations | C44: Expatriés | E44: Locaux | H44: Gestion des catastrophes | I44: Expatriés | K44: Locaux
C45: Homme | D45: Femme | E45: Homme | F45: Femme | I45: Homme | J45: Femme | K45: Homme | L45: Femme
...

Sheet Sep
B2: Dossiers de formation
B4: Mois | C4: Septembre | F4: Année | H4: 2012
B6: Formation en milieu hostile | C6: Expatriés | E6: Locaux | H6: Formation à la sécurité des conducteurs | I6: Expatriés | K6: Locaux
C7: Homme | D7: Femme | E7: Homme | F7: Femme | I7: Homme | J7: Femme | K7: Homme | L7: Femme
B8: Risques d'origine humaine | H8: Introduction
B9: Risques naturels | H9: Sûreté et sécurité du véhicule
B10: Déplacements terrestres | H10: Les exercices du poste de pilotage
B11: Sécurité personnelle | H11: Exercices d'observation
B12: Aléas culturels et sociaux | H12: Positionnement routier
B13: Sécurité du véhicule | H13: Techniques de pilotage
B14: Enlèvement et rançon | H14: Le système de commande du véhicule
B15: Formation d'intégration | H15: Contrôles du véhicule
B16: Exercices d'intervention d'urgence | H16: Forces agissant sur les véhicules
B17: Santé et hygiène | H17: Dépassement et positionnement
B18: Travailler avec une équipe de sécurité | H18: Traverser et pilonnage
B19: Totaux | C19: =SUM(C8:C18) -> 0 | D19: =SUM(D8:D18) -> 0 | E19: =SUM(E8:E18) -> 0 | F19: =SUM(F8:F18) -> 0 | H19: Totaux | I19: =SUM(I8:I18) -> 0 | J19: =SUM(J8:J18) -> 0 | K19: =SUM(K8:K18) -> 0 | L19: =SUM(L8:L18) -> 0
B20: Homme et femme | C20: =C19+E19 -> 0 | D20: =D19+F19 -> 0 | H20: Homme et femme | I20: =I19+K19 -> 0 | J20: =J19+L19 -> 0
B22: Direction de crise | C22: Expatriés | E22: Locaux | H22: Gestion de la sécurité | I22: Expatriés | K22: Locaux
C23: Homme | D23: Femme | E23: Homme | F23: Femme | I23: Homme | J23: Femme | K23: Homme | L23: Femme
B24: Comprendre les événements de crise | H24: Élaboration de politiques et de plans
B25: Gestion de crise | H25: Pratique : conception de la politique
B26: Points d'échec courants | H26: Gestion de la sécurité
B27: Systèmes et outils de gestion des risques | H27: Gestion des forces de garde
B28: Plan de gestion des incidents | H28: Évaluations des menaces
B29: Plan de continuité des activités | H29: Planification de l'entrée sur le marché
B30: Reprise des affaires | H30: Sécurité et processus d'appel d'offres
B31: Exercices de table | H31: Sécurité mobile - concept
H32: Sécurité mobile - stratégies
H33: Sécurité mobile - opérations
H34: Sécurité mobile - tactiques
H35: Procédures d'utilisation normalisées
H36: Planification d'événements
H37: Mobilisation et coordination
H38: Espèces en transit
H39: Gestion de la sécurité de l'établissement
H40: Construction de la sécurité de l'établissement
B41: Totaux | C41: =SUM(C24:C40) -> 0 | D41: =SUM(D24:D40) -> 0 | E41: =SUM(E24:E40) -> 0 | F41: =SUM(F24:F40) -> 0 | H41: Totaux | I41: =SUM(I24:I40) -> 0 | J41: =SUM(J24:J40) -> 0 | K41: =SUM(K24:K40) -> 0 | L41: =SUM(L24:L40) -> 0
B42: Homme et femme | C42: =C41+E41 -> 0 | D42: =D41+F41 -> 0 | H42: Homme et femme | I42: =I41+K41 -> 0 | J42: =J41+L41 -> 0
B44: Gestion des évacuations | C44: Expatriés | E44: Locaux | H44: Gestion des catastrophes | I44: Expatriés | K44: Locaux
C45: Homme | D45: Femme | E45: Homme | F45: Femme | I45: Homme | J45: Femme | K45: Homme | L45: Femme
...

Sheet Oct
B2: Dossiers de formation
B4: Mois | C4: Octobre | F4: Année | H4: 2012
B6: Formation en milieu hostile | C6: Expatriés | E6: Locaux | H6: Formation à la sécurité des conducteurs | I6: Expatriés | K6: Locaux
C7: Homme | D7: Femme | E7: Homme | F7: Femme | I7: Homme | J7: Femme | K7: Homme | L7: Femme
B8: Risques d'origine humaine | H8: Introduction
B9: Risques naturels | H9: Sûreté et sécurité du véhicule
B10: Déplacements terrestres | H10: Les exercices du poste de pilotage
B11: Sécurité personnelle | H11: Exercices d'observation
B12: Aléas culturels et sociaux | H12: Positionnement routier
B13: Sécurité du véhicule | H13: Techniques de pilotage
B14: Enlèvement et rançon | H14: Le système de commande du véhicule
B15: Formation d'intégration | H15: Contrôles du véhicule
B16: Exercices d'intervention d'urgence | H16: Forces agissant sur les véhicules
B17: Santé et hygiène | H17: Dépassement et positionnement
B18: Travailler avec une équipe de sécurité | H18: Traverser et pilonnage
B19: Totaux | C19: =SUM(C8:C18) -> 0 | D19: =SUM(D8:D18) -> 0 | E19: =SUM(E8:E18) -> 0 | F19: =SUM(F8:F18) -> 0 | H19: Totaux | I19: =SUM(I8:I18) -> 0 | J19: =SUM(J8:J18) -> 0 | K19: =SUM(K8:K18) -> 0 | L19: =SUM(L8:L18) -> 0
B20: Homme et femme | C20: =C19+E19 -> 0 | D20: =D19+F19 -> 0 | H20: Homme et femme | I20: =I19+K19 -> 0 | J20: =J19+L19 -> 0
B22: Direction de crise | C22: Expatriés | E22: Locaux | H22: Gestion de la sécurité | I22: Expatriés | K22: Locaux
C23: Homme | D23: Femme | E23: Homme | F23: Femme | I23: Homme | J23: Femme | K23: Homme | L23: Femme
B24: Comprendre les événements de crise | H24: Élaboration de politiques et de plans
B25: Gestion de crise | H25: Pratique : conception de la politique
B26: Points d'échec courants | H26: Gestion de la sécurité
B27: Systèmes et outils de gestion des risques | H27: Gestion des forces de garde
B28: Plan de gestion des incidents | H28: Évaluations des menaces
B29: Plan de continuité des activités | H29: Planification de l'entrée sur le marché
B30: Reprise des affaires | H30: Sécurité et processus d'appel d'offres
B31: Exercices de table | H31: Sécurité mobile - concept
H32: Sécurité mobile - stratégies
H33: Sécurité mobile - opérations
H34: Sécurité mobile - tactiques
H35: Procédures d'utilisation normalisées
H36: Planification d'événements
H37: Mobilisation et coordination
H38: Espèces en transit
H39: Gestion de la sécurité de l'établissement
H40: Construction de la sécurité de l'établissement
B41: Totaux | C41: =SUM(C24:C40) -> 0 | D41: =SUM(D24:D40) -> 0 | E41: =SUM(E24:E40) -> 0 | F41: =SUM(F24:F40) -> 0 | H41: Totaux | I41: =SUM(I24:I40) -> 0 | J41: =SUM(J24:J40) -> 0 | K41: =SUM(K24:K40) -> 0 | L41: =SUM(L24:L40) -> 0
B42: Homme et femme | C42: =C41+E41 -> 0 | D42: =D41+F41 -> 0 | H42: Homme et femme | I42: =I41+K41 -> 0 | J42: =J41+L41 -> 0
B44: Gestion des évacuations | C44: Expatriés | E44: Locaux | H44: Gestion des catastrophes | I44: Expatriés | K44: Locaux
C45: Homme | D45: Femme | E45: Homme | F45: Femme | I45: Homme | J45: Femme | K45: Homme | L45: Femme
...

Sheet Nov
B2: Dossiers de formation
B4: Mois | C4: Novembre | F4: Année | H4: 2012
B6: Formation en milieu hostile | C6: Expatriés | E6: Locaux | H6: Formation à la sécurité des conducteurs | I6: Expatriés | K6: Locaux
C7: Homme | D7: Femme | E7: Homme | F7: Femme | I7: Homme | J7: Femme | K7: Homme | L7: Femme
B8: Risques d'origine humaine | H8: Introduction
B9: Risques naturels | H9: Sûreté et sécurité du véhicule
B10: Déplacements terrestres | H10: Les exercices du poste de pilotage
B11: Sécurité personnelle | H11: Exercices d'observation
B12: Aléas culturels et sociaux | H12: Positionnement routier
B13: Sécurité du véhicule | H13: Techniques de pilotage
B14: Enlèvement et rançon | H14: Le système de commande du véhicule
B15: Formation d'intégration | H15: Contrôles du véhicule
B16: Exercices d'intervention d'urgence | H16: Forces agissant sur les véhicules
B17: Santé et hygiène | H17: Dépassement et positionnement
B18: Travailler avec une équipe de sécurité | H18: Traverser et pilonnage
B19: Totaux | C19: =SUM(C8:C18) -> 0 | D19: =SUM(D8:D18) -> 0 | E19: =SUM(E8:E18) -> 0 | F19: =SUM(F8:F18) -> 0 | H19: Totaux | I19: =SUM(I8:I18) -> 0 | J19: =SUM(J8:J18) -> 0 | K19: =SUM(K8:K18) -> 0 | L19: =SUM(L8:L18) -> 0
B20: Homme et femme | C20: =C19+E19 -> 0 | D20: =D19+F19 -> 0 | H20: Homme et femme | I20: =I19+K19 -> 0 | J20: =J19+L19 -> 0
B22: Direction de crise | C22: Expatriés | E22: Locaux | H22: Gestion de la sécurité | I22: Expatriés | K22: Locaux
C23: Homme | D23: Femme | E23: Homme | F23: Femme | I23: Homme | J23: Femme | K23: Homme | L23: Femme
B24: Comprendre les événements de crise | H24: Élaboration de politiques et de plans
B25: Gestion de crise | H25: Pratique : conception de la politique
B26: Points d'échec courants | H26: Gestion de la sécurité
B27: Systèmes et outils de gestion des risques | H27: Gestion des forces de garde
B28: Plan de gestion des incidents | H28: Évaluations des menaces
B29: Plan de continuité des activités | H29: Planification de l'entrée sur le marché
B30: Reprise des affaires | H30: Sécurité et processus d'appel d'offres
B31: Exercices de table | H31: Sécurité mobile - concept
H32: Sécurité mobile - stratégies
H33: Sécurité mobile - opérations
H34: Sécurité mobile - tactiques
H35: Procédures d'utilisation normalisées
H36: Planification d'événements
H37: Mobilisation et coordination
H38: Espèces en transit
H39: Gestion de la sécurité de l'établissement
H40: Construction de la sécurité de l'établissement
B41: Totaux | C41: =SUM(C24:C40) -> 0 | D41: =SUM(D24:D40) -> 0 | E41: =SUM(E24:E40) -> 0 | F41: =SUM(F24:F40) -> 0 | H41: Totaux | I41: =SUM(I24:I40) -> 0 | J41: =SUM(J24:J40) -> 0 | K41: =SUM(K24:K40) -> 0 | L41: =SUM(L24:L40) -> 0
B42: Homme et femme | C42: =C41+E41 -> 0 | D42: =D41+F41 -> 0 | H42: Homme et femme | I42: =I41+K41 -> 0 | J42: =J41+L41 -> 0
B44: Gestion des évacuations | C44: Expatriés | E44: Locaux | H44: Gestion des catastrophes | I44: Expatriés | K44: Locaux
C45: Homme | D45: Femme | E45: Homme | F45: Femme | I45: Homme | J45: Femme | K45: Homme | L45: Femme
...

Sheet Déc
B2: Dossiers de formation
B4: Mois | C4: Décembre | F4: Année | H4: 2012
B6: Formation en milieu hostile | C6: Expatriés | E6: Locaux | H6: Formation à la sécurité des conducteurs | I6: Expatriés | K6: Locaux
C7: Homme | D7: Femme | E7: Homme | F7: Femme | I7: Homme | J7: Femme | K7: Homme | L7: Femme
B8: Risques d'origine humaine | H8: Introduction
B9: Risques naturels | H9: Sûreté et sécurité du véhicule
B10: Déplacements terrestres | H10: Les exercices du poste de pilotage
B11: Sécurité personnelle | H11: Exercices d'observation
B12: Aléas culturels et sociaux | H12: Positionnement routier
B13: Sécurité du véhicule | H13: Techniques de pilotage
B14: Enlèvement et rançon | H14: Le système de commande du véhicule
B15: Formation d'intégration | H15: Contrôles du véhicule
B16: Exercices d'intervention d'urgence | H16: Forces agissant sur les véhicules
B17: Santé et hygiène | H17: Dépassement et positionnement
B18: Travailler avec une équipe de sécurité | H18: Traverser et pilonnage
B19: Totaux | C19: =SUM(C8:C18) -> 0 | D19: =SUM(D8:D18) -> 0 | E19: =SUM(E8:E18) -> 0 | F19: =SUM(F8:F18) -> 0 | H19: Totaux | I19: =SUM(I8:I18) -> 0 | J19: =SUM(J8:J18) -> 0 | K19: =SUM(K8:K18) -> 0 | L19: =SUM(L8:L18) -> 0
B20: Homme et femme | C20: =C19+E19 -> 0 | D20: =D19+F19 -> 0 | H20: Homme et femme | I20: =I19+K19 -> 0 | J20: =J19+L19 -> 0
B22: Direction de crise | C22: Expatriés | E22: Locaux | H22: Gestion de la sécurité | I22: Expatriés | K22: Locaux
C23: Homme | D23: Femme | E23: Homme | F23: Femme | I23: Homme | J23: Femme | K23: Homme | L23: Femme
B24: Comprendre les événements de crise | H24: Élaboration de politiques et de plans
B25: Gestion de crise | H25: Pratique : conception de la politique
B26: Points d'échec courants | H26: Gestion de la sécurité
B27: Systèmes et outils de gestion des risques | H27: Gestion des forces de garde
B28: Plan de gestion des incidents | H28: Évaluations des menaces
B29: Plan de continuité des activités | H29: Planification de l'entrée sur le marché
B30: Reprise des affaires | H30: Sécurité et processus d'appel d'offres
B31: Exercices de table | H31: Sécurité mobile - concept
H32: Sécurité mobile - stratégies
H33: Sécurité mobile - opérations
H34: Sécurité mobile - tactiques
H35: Procédures d'utilisation normalisées
H36: Planification d'événements
H37: Mobilisation et coordination
H38: Espèces en transit
H39: Gestion de la sécurité de l'établissement
H40: Construction de la sécurité de l'établissement
B41: Totaux | C41: =SUM(C24:C40) -> 0 | D41: =SUM(D24:D40) -> 0 | E41: =SUM(E24:E40) -> 0 | F41: =SUM(F24:F40) -> 0 | H41: Totaux | I41: =SUM(I24:I40) -> 0 | J41: =SUM(J24:J40) -> 0 | K41: =SUM(K24:K40) -> 0 | L41: =SUM(L24:L40) -> 0
B42: Homme et femme | C42: =C41+E41 -> 0 | D42: =D41+F41 -> 0 | H42: Homme et femme | I42: =I41+K41 -> 0 | J42: =J41+L41 -> 0
B44: Gestion des évacuations | C44: Expatriés | E44: Locaux | H44: Gestion des catastrophes | I44: Expatriés | K44: Locaux
C45: Homme | D45: Femme | E45: Homme | F45: Femme | I45: Homme | J45: Femme | K45: Homme | L45: Femme
...

Sheet Fiche d'inscription
B2: Registre des formations
B4: Organisation : | D4: Projet : | F4: Lieu :
B6: Date : | D6: Sujet : | F6: Instructeur :
B8: Nom | D8: Titre | F8: Nationalité | G8: Sexe
B43: Note : | C43: Conservez une copie imprimée de ce dossier
