Workbook
Name \A: #REF!
Name \P: #REF!
Name \S: #REF!
Name _______sho1: #REF!
Name __2DAI_1: #N/A
Name __3FEE: #N/A
Name __AFP1: #N/A
Name __AFP2: #N/A
Name __AFP3: #N/A
Name __AFP4: #N/A
Name __AMP1: #N/A
Name __AMP2: #N/A
Name __AMP3: #N/A
Name __AMP4: #N/A
Name __DAI4: #N/A
Name __EES1: #N/A
Name __EES2: #N/A
Name __EES3: #N/A
Name __EES4: #N/A
Name __EXT1: #N/A
Name __EXT2: #N/A
Name __EXT3: #N/A
Name __EXT4: #N/A
Name __FCP1: #N/A
Name __FCP2: #N/A
Name __FCP3: #N/A
Name __FCP4: #N/A
Name __FRI1: #N/A
Name __FRI4: #N/A
Name __HRA1: #N/A
Name __HRA2: #N/A
Name __HRA3: #N/A
Name __HRA4: #N/A
Name __inf1: #REF!
Name __LT4: #REF!
Name __ODC1: #N/A
Name __ODC2: #N/A
Name __POL1: #N/A
Name __POL2: #N/A
Name __POL3: #N/A
Name __POL4: #N/A
Name __TOT1: #N/A
Name __TOT2: #N/A
Name __TRV1: #N/A
Name __TRV2: #N/A
Name _060: #REF!
Name _1_1: #REF!
Name _13th_and_14th_month: #REF!
Name _2_1034: #REF!
Name _2DAI_1: #N/A
Name _3_1440: #REF!
Name _3FEE: #N/A
Name _4_2: #REF!
Name _5_3: #REF!
Name _AFP1: #N/A
Name _AFP2: #N/A
Name _AFP3: #N/A
Name _AFP4: #N/A
Name _AMP1: #N/A
Name _AMP2: #N/A

Sheet USDA Budget Summary
A1: Attachment 9
A2: Proposed Budget Summary
A4: Program (FFPr or MGD): | B4: FFPr
A5: Country of Operation: | B5: Mauritania
A6: Implementing Organization: | B6: Partners of the Americas Inc.
A7: Fiscal Year: | B7: 2023
A8: Agreement Number: | B8: USDA-FAS-10.606-0700-23-(557) | H8: 39.656979
A10: Total Amount of Federal Funds Requested
A11: Funding Source (FAS for MGD) (CCC for FFPr) | B11: Funding Year | C11: Commodity Cost | D11: Freight Cost | E11: Administrative Costs (cash portion) | F11: Total Federal Funding Obligated
B12: 2023 | C12: 28250000 | D12: 5900000 | E12: 1400000 | F12: =E12+D12+C12 -> 35550000
A14: Project Operating Budget
A15: Expense Type | B15: Monetization Proceeds (FFPr Only) | C15: FAS or CCC Funds (CCC is Admin Only) | D15: Cost Share | E15: Total w/out Cost Share | F15: Total w/Cost Share
A16: Administration
A17: Salaries/Personnel | B17: =Admin!W33-C17 -> 340514.28 | C17: 484000 | D17: ='Program Budget'!W34 -> 0 | E17: =B17+C17 -> 824514.28 | F17: =B17+C17+D17 -> 824514.28
A18: Benefits | B18: =Admin!W51-C18 -> 140988.73 | C18: 265417 | D18: ='Program Budget'!W49 -> 0 | E18: =B18+C18 -> 406405.73 | F18: =B18+C18+D18 -> 406405.73
A19: Travel | B19: =Admin!W68-C19 -> 170974.97 | C19: 37563 | D19: ='Program Budget'!W66 -> 0 | E19: =B19+C19 -> 208537.97 | F19: =B19+C19+D19 -> 208537.97
A20: Professional Services/Contractual | B20: =Admin!W91-C20 -> 1167600 | C20: 250000 | D20: ='Program Budget'!W92 -> 0 | E20: =B20+C20 -> 1417600 | F20: =B20+C20+D20 -> 1417600
A21: Equipment | B21: =Admin!W95-C21 -> 130000 | C21: 0 | D21: ='Program Budget'!W97 -> 0 | E21: =B21+C21 -> 130000 | F21: =B21+C21+D21 -> 130000
A22: Office | B22: =Admin!W108-C22 -> 369492.55 | C22: 14990 | D22: ='Program Budget'!W114 -> 0 | E22: =B22+C22 -> 384482.55 | F22: =B22+C22+D22 -> 384482.55
A23: Supplies | B23: =Admin!W122-C23 -> 11144.42 | C23: 25968 | D23: ='Program Budget'!W129 -> 0 | E23: =B23+C23 -> 37112.42 | F23: =B23+C23+D23 -> 37112.42
A24: Other | B24: =Admin!W135-C24 -> 65166.843 | C24: 13425 | D24: 0 | E24: =B24+C24 -> 78591.843 | F24: =B24+C24+D24 -> 78591.843
A25: Total Administration | B25: =SUM(B17:B24) -> 2395881.8 | C25: =SUM(C17:C24) -> 1091363 | D25: =SUM(D17:D24) -> 0 | E25: =SUM(E17:E24) -> 3487244.8 | F25: =SUM(F17:F24) -> 3487244.8
A27: Activities
A28: Activity 1: Increase Production and Farmer Resiliency | B28: ='Activity 1'!W78 -> 2088882 | C28: 0 | D28: ='Program Budget'!W201 -> 0 | E28: =B28+C28 -> 2088882 | F28: =B28+C28+D28 -> 2088882
A29: Activity 2: Promote Regenerative Agriculture with Agropastoralists | B29: ='Activity 2'!W75 -> 1825819 | C29: 0 | D29: ='Program Budget'!W259 -> 0 | E29: =B29+C29 -> 1825819 | F29: =B29+C29+D29 -> 1825819
A30: Activity 3: Improve the Agricultural-Enabling Environment | B30: ='Activity 3'!W84 -> 1995172.4 | C30: 0 | D30: =ROUND('Program Budget'!W326,0) -> 0 | E30: =B30+C30 -> 1995172.4 | F30: =B30+C30+D30 -> 1995172.4
A31: Activity 4: Build Capacity for Post-harvest | B31: ='Activity 4'!W82 -> 2604012.7 | C31: 0 | D31: =ROUNDUP(SUM('Activity 4'!W91:W94),0) -> 600000 | E31: =B31+C31 -> 2604012.7 | F31: =B31+C31+D31 -> 3204012.7
A32: Total Activities | B32: =SUM(B28:B31) -> 8513886.2 | C32: =SUM(C28:C31) -> 0 | D32: =SUM(D28:D31) -> 600000 | E32: =SUM(E28:E31) -> 8513886.2 | F32: =SUM(F28:F31) -> 9113886.2
A34: Commodity and Food Purchases (N/A to FFPr)
A35: Commodity Procurement | B35: 0 | C35: 0 | D35: 0 | E35: =B35+C35 -> 0 | F35: =B35+C35+D35 -> 0
A36: Food Vouchers (N/A to MGD)
A37: Cash Transfers (N/A to MGD)
A38: Total Commodity Procurement | B38: =SUM(B35:B37) -> 0 | C38: =SUM(C35:C37) -> 0 | D38: =SUM(D35:D37) -> 0 | E38: =SUM(E35:E37) -> 0 | F38: =SUM(F35:F37) -> 0
A40: ITSH (N/A to FFPr)
A41: Salaries | B41: 0 | C41: 0 | D41: 0 | E41: =B41+C41 -> 0 | F41: =B41+C41+D41 -> 0
A42: Benefits | B42: 0 | C42: 0 | D42: 0 | E42: =B42+C42 -> 0 | F42: =B42+C42+D42 -> 0
A43: Transportation | B43: 0 | C43: 0 | D43: 0 | E43: =B43+C43 -> 0 | F43: =B43+C43+D43 -> 0
A44: Professional Services | B44: 0 | C44: 0 | D44: =0 -> 0 | E44: =B44+C44 -> 0 | F44: =B44+C44+D44 -> 0
A45: Warehouse | B45: 0 | C45: 0 | D45: 0 | E45: =B45+C45 -> 0 | F45: =B45+C45+D45 -> 0
A46: Supplies | B46: 0 | C46: 0 | D46: 0 | E46: =B46+C46 -> 0 | F46: =B46+C46+D46 -> 0
...

Sheet Detailed Budget
A2: Item | B2: Type of Unit | C2: Year 1 | G2: Year 2 | K2: Year 3 | O2: Year 4 | S2: Year 5 | W2: Total
C3: Cost | D3: Quantity | E3: Percent Allocated | F3: Total | G3: Cost | H3: Quantity | I3: Percent Allocated | J3: Total | K3: Cost | L3: Quantity | M3: Percent Allocated | N3: Total | O3: Cost | P3: Quantity | Q3: Percent Allocated | R3: Total | S3: Cost | T3: Quantity | U3: Percent Allocated | V3: Total
A4: Direct Costs
A5: Salaries
A6: USN/TCN Staff
A7: ='Program Budget'!D12 -> Key Personnel: Ex-pat Chief of Party | B7: ='Program Budget'!F13 -> Month | C7: ='Program Budget'!H12 -> 12083.333 | D7: ='Program Budget'!G12 -> 12 | E7: =Admin!E7+'Activity 1'!E7+'Activity 2'!E7+'Activity 3'!E7+'Activity 4'!E7 -> 1 | F7: =C7*D7*E7 -> 145000 | G7: =C7*1.04 -> 12566.667 | H7: ='Program Budget'!K12 -> 12 | I7: =Admin!I7+'Activity 1'!I7+'Activity 2'!I7+'Activity 3'!I7+'Activity 4'!I7 -> 1 | J7: =G7*H7*I7 -> 150800 | K7: =G7*1.04 -> 13069.333 | L7: ='Program Budget'!N12 -> 12 | M7: =Admin!M7+'Activity 1'!M7+'Activity 2'!M7+'Activity 3'!M7+'Activity 4'!M7 -> 1 | N7: =K7*L7*M7 -> 156832 | O7: =K7*1.04 -> 13592.107 | P7: ='Program Budget'!Q12 -> 12 | Q7: =Admin!Q7+'Activity 1'!Q7+'Activity 2'!Q7+'Activity 3'!Q7+'Activity 4'!Q7 -> 1 | R7: =O7*P7*Q7 -> 163105.28 | S7: =O7*1.04 -> 14135.791 | T7: ='Program Budget'!T12 -> 12 | U7: =Admin!U7+'Activity 1'!U7+'Activity 2'!U7+'Activity 3'!U7+'Activity 4'!U7 -> 1 | V7: =S7*T7*U7 -> 169629.49 | W7: =F7+J7+N7+R7+V7 -> 785366.77
A8: Total: Expatriate Salaries & Wages | F8: =SUM(F7:F7) -> 145000 | J8: =SUM(J7:J7) -> 150800 | N8: =SUM(N7:N7) -> 156832 | R8: =SUM(R7:R7) -> 163105.28 | V8: =SUM(V7:V7) -> 169629.49 | W8: =+F8+J8+N8+R8+V8 -> 785366.77
A9: CNN Staff
A10: ='Program Budget'!D13 -> Deputy Chief of Party | B10: ='Program Budget'!F12 -> Month | C10: ='Program Budget'!H13 -> 7500 | D10: ='Program Budget'!G13 -> 6 | E10: =Admin!E10+'Activity 1'!E10+'Activity 2'!E10+'Activity 3'!E10+'Activity 4'!E10 -> 1 | F10: =C10*D10*E10 -> 45000 | G10: =C10*1.04 -> 7800 | H10: ='Program Budget'!K13 -> 12 | I10: =Admin!I10+'Activity 1'!I10+'Activity 2'!I10+'Activity 3'!I10+'Activity 4'!I10 -> 1 | J10: =G10*H10*I10 -> 93600 | K10: =G10*1.04 -> 8112 | L10: ='Program Budget'!N13 -> 12 | M10: =Admin!M10+'Activity 1'!M10+'Activity 2'!M10+'Activity 3'!M10+'Activity 4'!M10 -> 1 | N10: =K10*L10*M10 -> 97344 | O10: =K10*1.04 -> 8436.48 | P10: ='Program Budget'!Q13 -> 12 | Q10: =Admin!Q10+'Activity 1'!Q10+'Activity 2'!Q10+'Activity 3'!Q10+'Activity 4'!Q10 -> 1 | R10: =O10*P10*Q10 -> 101237.76 | S10: =O10*1.04 -> 8773.9392 | T10: ='Program Budget'!T13 -> 6 | U10: =Admin!U10+'Activity 1'!U10+'Activity 2'!U10+'Activity 3'!U10+'Activity 4'!U10 -> 1 | V10: =S10*T10*U10 -> 52643.635 | W10: =F10+J10+N10+R10+V10 -> 389825.4
A11: ='Program Budget'!D14 -> Technical Lead Component 1 | B11: ='Program Budget'!F14 -> Month | C11: ='Program Budget'!H14 -> 3333.3333 | D11: ='Program Budget'!G14 -> 6 | E11: =Admin!E11+'Activity 1'!E11+'Activity 2'!E11+'Activity 3'!E11+'Activity 4'!E11 -> 1 | F11: =C11*D11*E11 -> 20000 | G11: =C11*1.04 -> 3466.6667 | H11: ='Program Budget'!K14 -> 12 | I11: =Admin!I11+'Activity 1'!I11+'Activity 2'!I11+'Activity 3'!I11+'Activity 4'!I11 -> 1 | J11: =G11*H11*I11 -> 41600 | K11: =G11*1.04 -> 3605.3333 | L11: ='Program Budget'!N14 -> 12 | M11: =Admin!M11+'Activity 1'!M11+'Activity 2'!M11+'Activity 3'!M11+'Activity 4'!M11 -> 1 | N11: =K11*L11*M11 -> 43264 | O11: =K11*1.04 -> 3749.5467 | P11: ='Program Budget'!Q14 -> 12 | Q11: =Admin!Q11+'Activity 1'!Q11+'Activity 2'!Q11+'Activity 3'!Q11+'Activity 4'!Q11 -> 1 | R11: =O11*P11*Q11 -> 44994.56 | S11: =O11*1.04 -> 3899.5285 | T11: ='Program Budget'!T14 -> 9 | U11: =Admin!U11+'Activity 1'!U11+'Activity 2'!U11+'Activity 3'!U11+'Activity 4'!U11 -> 1 | V11: =S11*T11*U11 -> 35095.757 | W11: =F11+J11+N11+R11+V11 -> 184954.32
A12: ='Program Budget'!D15 -> Technical Lead Component 2 | B12: ='Program Budget'!F15 -> Month | C12: ='Program Budget'!H15 -> 3333.3333 | D12: ='Program Budget'!G15 -> 6 | E12: =Admin!E12+'Activity 1'!E12+'Activity 2'!E12+'Activity 3'!E12+'Activity 4'!E12 -> 1 | F12: =C12*D12*E12 -> 20000 | G12: =C12*1.04 -> 3466.6667 | H12: ='Program Budget'!K15 -> 12 | I12: =Admin!I12+'Activity 1'!I12+'Activity 2'!I12+'Activity 3'!I12+'Activity 4'!I12 -> 1 | J12: =G12*H12*I12 -> 41600 | K12: =G12*1.04 -> 3605.3333 | L12: ='Program Budget'!N15 -> 12 | M12: =Admin!M12+'Activity 1'!M12+'Activity 2'!M12+'Activity 3'!M12+'Activity 4'!M12 -> 1 | N12: =K12*L12*M12 -> 43264 | O12: =K12*1.04 -> 3749.5467 | P12: ='Program Budget'!Q15 -> 12 | Q12: =Admin!Q12+'Activity 1'!Q12+'Activity 2'!Q12+'Activity 3'!Q12+'Activity 4'!Q12 -> 1 | R12: =O12*P12*Q12 -> 44994.56 | S12: =O12*1.04 -> 3899.5285 | T12: ='Program Budget'!T15 -> 9 | U12: =Admin!U12+'Activity 1'!U12+'Activity 2'!U12+'Activity 3'!U12+'Activity 4'!U12 -> 1 | V12: =S12*T12*U12 -> 35095.757 | W12: =F12+J12+N12+R12+V12 -> 184954.32
A13: ='Program Budget'!D16 -> Technical Lead Component 3 | B13: ='Program Budget'!F16 -> Month | C13: ='Program Budget'!H16 -> 3333.3333 | D13: ='Program Budget'!G16 -> 6 | E13: =Admin!E13+'Activity 1'!E13+'Activity 2'!E13+'Activity 3'!E13+'Activity 4'!E13 -> 1 | F13: =C13*D13*E13 -> 20000 | G13: =C13*1.04 -> 3466.6667 | H13: ='Program Budget'!K16 -> 12 | I13: =Admin!I13+'Activity 1'!I13+'Activity 2'!I13+'Activity 3'!I13+'Activity 4'!I13 -> 1 | J13: =G13*H13*I13 -> 41600 | K13: =G13*1.04 -> 3605.3333 | L13: ='Program Budget'!N16 -> 12 | M13: =Admin!M13+'Activity 1'!M13+'Activity 2'!M13+'Activity 3'!M13+'Activity 4'!M13 -> 1 | N13: =K13*L13*M13 -> 43264 | O13: =K13*1.04 -> 3749.5467 | P13: ='Program Budget'!Q16 -> 12 | Q13: =Admin!Q13+'Activity 1'!Q13+'Activity 2'!Q13+'Activity 3'!Q13+'Activity 4'!Q13 -> 1 | R13: =O13*P13*Q13 -> 44994.56 | S13: =O13*1.04 -> 3899.5285 | T13: ='Program Budget'!T16 -> 9 | U13: =Admin!U13+'Activity 1'!U13+'Activity 2'!U13+'Activity 3'!U13+'Activity 4'!U13 -> 1 | V13: =S13*T13*U13 -> 35095.757 | W13: =F13+J13+N13+R13+V13 -> 184954.32
A14: ='Program Budget'!D17 -> Specialist Component 2 | B14: ='Program Budget'!F17 -> Month | C14: ='Program Budget'!H17 -> 1666.6667 | D14: ='Program Budget'!G17 -> 6 | E14: =Admin!E14+'Activity 1'!E14+'Activity 2'!E14+'Activity 3'!E14+'Activity 4'!E14 -> 1 | F14: =C14*D14*E14 -> 10000 | G14: =C14*1.04 -> 1733.3333 | H14: ='Program Budget'!K17 -> 12 | I14: =Admin!I14+'Activity 1'!I14+'Activity 2'!I14+'Activity 3'!I14+'Activity 4'!I14 -> 1 | J14: =G14*H14*I14 -> 20800 | K14: =G14*1.04 -> 1802.6667 | L14: ='Program Budget'!N17 -> 12 | M14: =Admin!M14+'Activity 1'!M14+'Activity 2'!M14+'Activity 3'!M14+'Activity 4'!M14 -> 1 | N14: =K14*L14*M14 -> 21632 | O14: =K14*1.04 -> 1874.7733 | P14: ='Program Budget'!Q17 -> 12 | Q14: =Admin!Q14+'Activity 1'!Q14+'Activity 2'!Q14+'Activity 3'!Q14+'Activity 4'!Q14 -> 1 | R14: =O14*P14*Q14 -> 22497.28 | S14: =O14*1.04 -> 1949.7643 | T14: ='Program Budget'!T17 -> 6 | U14: =Admin!U14+'Activity 1'!U14+'Activity 2'!U14+'Activity 3'!U14+'Activity 4'!U14 -> 1 | V14: =S14*T14*U14 -> 11698.586 | W14: =F14+J14+N14+R14+V14 -> 86627.866
A15: ='Program Budget'!D18 -> Specialist Component 3 | B15: ='Program Budget'!F18 -> Month | C15: ='Program Budget'!H18 -> 1666.6667 | D15: ='Program Budget'!G18 -> 6 | E15: =Admin!E15+'Activity 1'!E15+'Activity 2'!E15+'Activity 3'!E15+'Activity 4'!E15 -> 1 | F15: =C15*D15*E15 -> 10000 | G15: =C15*1.04 -> 1733.3333 | H15: ='Program Budget'!K18 -> 12 | I15: =Admin!I15+'Activity 1'!I15+'Activity 2'!I15+'Activity 3'!I15+'Activity 4'!I15 -> 1 | J15: =G15*H15*I15 -> 20800 | K15: =G15*1.04 -> 1802.6667 | L15: ='Program Budget'!N18 -> 12 | M15: =Admin!M15+'Activity 1'!M15+'Activity 2'!M15+'Activity 3'!M15+'Activity 4'!M15 -> 1 | N15: =K15*L15*M15 -> 21632 | O15: =K15*1.04 -> 1874.7733 | P15: ='Program Budget'!Q18 -> 12 | Q15: =Admin!Q15+'Activity 1'!Q15+'Activity 2'!Q15+'Activity 3'!Q15+'Activity 4'!Q15 -> 1 | R15: =O15*P15*Q15 -> 22497.28 | S15: =O15*1.04 -> 1949.7643 | T15: ='Program Budget'!T18 -> 6 | U15: =Admin!U15+'Activity 1'!U15+'Activity 2'!U15+'Activity 3'!U15+'Activity 4'!U15 -> 1 | V15: =S15*T15*U15 -> 11698.586 | W15: =F15+J15+N15+R15+V15 -> 86627.866
A16: ='Program Budget'!D19 -> Specialist Component 4 | B16: ='Program Budget'!F19 -> Month | C16: ='Program Budget'!H19 -> 1666.6667 | D16: ='Program Budget'!G19 -> 6 | E16: =Admin!E16+'Activity 1'!E16+'Activity 2'!E16+'Activity 3'!E16+'Activity 4'!E16 -> 1 | F16: =C16*D16*E16 -> 10000 | G16: =C16*1.04 -> 1733.3333 | H16: ='Program Budget'!K19 -> 12 | I16: =Admin!I16+'Activity 1'!I16+'Activity 2'!I16+'Activity 3'!I16+'Activity 4'!I16 -> 1 | J16: =G16*H16*I16 -> 20800 | K16: =G16*1.04 -> 1802.6667 | L16: ='Program Budget'!N19 -> 12 | M16: =Admin!M16+'Activity 1'!M16+'Activity 2'!M16+'Activity 3'!M16+'Activity 4'!M16 -> 1 | N16: =K16*L16*M16 -> 21632 | O16: =K16*1.04 -> 1874.7733 | P16: ='Program Budget'!Q19 -> 12 | Q16: =Admin!Q16+'Activity 1'!Q16+'Activity 2'!Q16+'Activity 3'!Q16+'Activity 4'!Q16 -> 1 | R16: =O16*P16*Q16 -> 22497.28 | S16: =O16*1.04 -> 1949.7643 | T16: ='Program Budget'!T19 -> 6 | U16: =Admin!U16+'Activity 1'!U16+'Activity 2'!U16+'Activity 3'!U16+'Activity 4'!U16 -> 1 | V16: =S16*T16*U16 -> 11698.586 | W16: =F16+J16+N16+R16+V16 -> 86627.866
A17: ='Program Budget'!D20 -> Extension Agents (20 Individuals) | B17: ='Program Budget'!F20 -> Month | C17: ='Program Budget'!H20 -> 23333.333 | D17: ='Program Budget'!G20 -> 3 | E17: 1 | F17: =C17*D17*E17 -> 70000 | G17: =C17*1.04 -> 24266.667 | H17: ='Program Budget'!K20 -> 12 | I17: =Admin!I14+'Activity 1'!I17+'Activity 2'!I17+'Activity 3'!I17+'Activity 4'!I17 -> 1 | J17: =G17*H17*I17 -> 291200 | K17: =G17*1.04 -> 25237.333 | L17: ='Program Budget'!N20 -> 6 | M17: =Admin!M14+'Activity 1'!M17+'Activity 2'!M17+'Activity 3'!M17+'Activity 4'!M17 -> 1 | N17: =K17*L17*M17 -> 151424 | O17: =K17*1.04 -> 26246.827 | P17: ='Program Budget'!Q20 -> 0 | Q17: =Admin!Q14+'Activity 1'!Q17+'Activity 2'!Q17+'Activity 3'!Q17+'Activity 4'!Q17 -> 0 | R17: =O17*P17*Q17 -> 0 | S17: =O17*1.04 -> 27296.7 | T17: ='Program Budget'!T20 -> 0 | U17: =Admin!U14+'Activity 1'!U17+'Activity 2'!U17+'Activity 3'!U17+'Activity 4'!U17 -> 0 | V17: =S17*T17*U17 -> 0 | W17: =F17+J17+N17+R17+V17 -> 512624
A18: ='Program Budget'!D21 -> M&E Director | B18: ='Program Budget'!F21 -> Month | C18: ='Program Budget'!H21 -> 3750 | D18: ='Program Budget'!G21 -> 9 | E18: =Admin!E18+'Activity 1'!E18+'Activity 2'!E18+'Activity 3'!E18+'Activity 4'!E18 -> 1 | F18: =C18*D18*E18 -> 33750 | G18: =C18*1.04 -> 3900 | H18: ='Program Budget'!K21 -> 12 | I18: =Admin!I18+'Activity 1'!I18+'Activity 2'!I18+'Activity 3'!I18+'Activity 4'!I18 -> 1 | J18: =G18*H18*I18 -> 46800 | K18: =G18*1.04 -> 4056 | L18: ='Program Budget'!N21 -> 12 | M18: =Admin!M18+'Activity 1'!M18+'Activity 2'!M18+'Activity 3'!M18+'Activity 4'!M18 -> 1 | N18: =K18*L18*M18 -> 48672 | O18: =K18*1.04 -> 4218.24 | P18: ='Program Budget'!Q21 -> 12 | Q18: =Admin!Q18+'Activity 1'!Q18+'Activity 2'!Q18+'Activity 3'!Q18+'Activity 4'!Q18 -> 1 | R18: =O18*P18*Q18 -> 50618.88 | S18: =O18*1.04 -> 4386.9696 | T18: ='Program Budget'!T21 -> 12 | U18: =Admin!U18+'Activity 1'!U18+'Activity 2'!U18+'Activity 3'!U18+'Activity 4'!U18 -> 1 | V18: =S18*T18*U18 -> 52643.635 | W18: =F18+J18+N18+R18+V18 -> 232484.52
A19: ='Program Budget'!D22 -> M&E Specialist | B19: ='Program Budget'!F22 -> Month | C19: ='Program Budget'!H22 -> 2083.3333 | D19: ='Program Budget'!G22 -> 6 | E19: =Admin!E19+'Activity 1'!E19+'Activity 2'!E19+'Activity 3'!E19+'Activity 4'!E19 -> 1 | F19: =C19*D19*E19 -> 12500 | G19: =C19*1.04 -> 2166.6667 | H19: ='Program Budget'!K22 -> 12 | I19: =Admin!I19+'Activity 1'!I19+'Activity 2'!I19+'Activity 3'!I19+'Activity 4'!I19 -> 1 | J19: =G19*H19*I19 -> 26000 | K19: =G19*1.04 -> 2253.3333 | L19: ='Program Budget'!N22 -> 12 | M19: =Admin!M19+'Activity 1'!M19+'Activity 2'!M19+'Activity 3'!M19+'Activity 4'!M19 -> 1 | N19: =K19*L19*M19 -> 27040 | O19: =K19*1.04 -> 2343.4667 | P19: ='Program Budget'!Q22 -> 12 | Q19: =Admin!Q19+'Activity 1'!Q19+'Activity 2'!Q19+'Activity 3'!Q19+'Activity 4'!Q19 -> 1 | R19: =O19*P19*Q19 -> 28121.6 | S19: =O19*1.04 -> 2437.2053 | T19: ='Program Budget'!T22 -> 10 | U19: =Admin!U19+'Activity 1'!U19+'Activity 2'!U19+'Activity 3'!U19+'Activity 4'!U19 -> 1 | V19: =S19*T19*U19 -> 24372.053 | W19: =F19+J19+N19+R19+V19 -> 118033.65
A20: ='Program Budget'!D23 -> F&A Director | B20: ='Program Budget'!F23 -> Month | C20: ='Program Budget'!H23 -> 6666.6667 | D20: ='Program Budget'!G23 -> 9 | E20: =Admin!E20+'Activity 1'!E20+'Activity 2'!E20+'Activity 3'!E20+'Activity 4'!E20 -> 1 | F20: =C20*D20*E20 -> 60000 | G20: =C20*1.04 -> 6933.3333 | H20: ='Program Budget'!K23 -> 12 | I20: =Admin!I20+'Activity 1'!I20+'Activity 2'!I20+'Activity 3'!I20+'Activity 4'!I20 -> 1 | J20: =G20*H20*I20 -> 83200 | K20: =G20*1.04 -> 7210.6667 | L20: ='Program Budget'!N23 -> 12 | M20: =Admin!M20+'Activity 1'!M20+'Activity 2'!M20+'Activity 3'!M20+'Activity 4'!M20 -> 1 | N20: =K20*L20*M20 -> 86528 | O20: =K20*1.04 -> 7499.0933 | P20: ='Program Budget'!Q23 -> 12 | Q20: =Admin!Q20+'Activity 1'!Q20+'Activity 2'!Q20+'Activity 3'!Q20+'Activity 4'!Q20 -> 1 | R20: =O20*P20*Q20 -> 89989.12 | S20: =O20*1.04 -> 7799.0571 | T20: ='Program Budget'!T23 -> 12 | U20: =Admin!U20+'Activity 1'!U20+'Activity 2'!U20+'Activity 3'!U20+'Activity 4'!U20 -> 1 | V20: =S20*T20*U20 -> 93588.685 | W20: =F20+J20+N20+R20+V20 -> 413305.8
A21: ='Program Budget'!D24 -> Human Resource Manager | B21: ='Program Budget'!F24 -> Month | C21: ='Program Budget'!H24 -> 2916.6667 | D21: ='Program Budget'!G24 -> 9 | E21: =Admin!E21+'Activity 1'!E21+'Activity 2'!E21+'Activity 3'!E21+'Activity 4'!E21 -> 1 | F21: =C21*D21*E21 -> 26250 | G21: =C21*1.04 -> 3033.3333 | H21: ='Program Budget'!K24 -> 12 | I21: =Admin!I21+'Activity 1'!I21+'Activity 2'!I21+'Activity 3'!I21+'Activity 4'!I21 -> 1 | J21: =G21*H21*I21 -> 36400 | K21: =G21*1.04 -> 3154.6667 | L21: ='Program Budget'!N24 -> 12 | M21: =Admin!M21+'Activity 1'!M21+'Activity 2'!M21+'Activity 3'!M21+'Activity 4'!M21 -> 1 | N21: =K21*L21*M21 -> 37856 | O21: =K21*1.04 -> 3280.8533 | P21: ='Program Budget'!Q24 -> 12 | Q21: =Admin!Q21+'Activity 1'!Q21+'Activity 2'!Q21+'Activity 3'!Q21+'Activity 4'!Q21 -> 1 | R21: =O21*P21*Q21 -> 39370.24 | S21: =O21*1.04 -> 3412.0875 | T21: ='Program Budget'!T24 -> 10 | U21: =Admin!U21+'Activity 1'!U21+'Activity 2'!U21+'Activity 3'!U21+'Activity 4'!U21 -> 1 | V21: =S21*T21*U21 -> 34120.875 | W21: =F21+J21+N21+R21+V21 -> 173997.11
A22: ='Program Budget'!D25 -> Contracts & Compliance Specialist | B22: ='Program Budget'!F25 -> Month | C22: ='Program Budget'!H25 -> 2916.6667 | D22: ='Program Budget'!G25 -> 6 | E22: =Admin!E22+'Activity 1'!E22+'Activity 2'!E22+'Activity 3'!E22+'Activity 4'!E22 -> 1 | F22: =C22*D22*E22 -> 17500 | G22: =C22*1.04 -> 3033.3333 | H22: ='Program Budget'!K25 -> 12 | I22: =Admin!I22+'Activity 1'!I22+'Activity 2'!I22+'Activity 3'!I22+'Activity 4'!I22 -> 1 | J22: =G22*H22*I22 -> 36400 | K22: =G22*1.04 -> 3154.6667 | L22: ='Program Budget'!N25 -> 12 | M22: =Admin!M22+'Activity 1'!M22+'Activity 2'!M22+'Activity 3'!M22+'Activity 4'!M22 -> 1 | N22: =K22*L22*M22 -> 37856 | O22: =K22*1.04 -> 3280.8533 | P22: ='Program Budget'!Q25 -> 12 | Q22: =Admin!Q22+'Activity 1'!Q22+'Activity 2'!Q22+'Activity 3'!Q22+'Activity 4'!Q22 -> 1 | R22: =O22*P22*Q22 -> 39370.24 | S22: =O22*1.04 -> 3412.0875 | T22: ='Program Budget'!T25 -> 9 | U22: =Admin!U22+'Activity 1'!U22+'Activity 2'!U22+'Activity 3'!U22+'Activity 4'!U22 -> 1 | V22: =S22*T22*U22 -> 30708.787 | W22: =F22+J22+N22+R22+V22 -> 161835.03
A23: ='Program Budget'!D26 -> Accountant | B23: ='Program Budget'!F26 -> Month | C23: ='Program Budget'!H26 -> 1666.6667 | D23: 20 | E23: =Admin!E23+'Activity 1'!E23+'Activity 2'!E23+'Activity 3'!E23+'Activity 4'!E23 -> 1 | F23: =C23*D23*E23 -> 33333.333 | G23: =C23*1.04 -> 1733.3333 | H23: ='Program Budget'!K26 -> 12 | I23: =Admin!I23+'Activity 1'!I23+'Activity 2'!I23+'Activity 3'!I23+'Activity 4'!I23 -> 1 | J23: =G23*H23*I23 -> 20800 | K23: =G23*1.04 -> 1802.6667 | L23: ='Program Budget'!N26 -> 12 | M23: =Admin!M23+'Activity 1'!M23+'Activity 2'!M23+'Activity 3'!M23+'Activity 4'!M23 -> 1 | N23: =K23*L23*M23 -> 21632 | O23: =K23*1.04 -> 1874.7733 | P23: ='Program Budget'!Q26 -> 12 | Q23: =Admin!Q23+'Activity 1'!Q23+'Activity 2'!Q23+'Activity 3'!Q23+'Activity 4'!Q23 -> 1 | R23: =O23*P23*Q23 -> 22497.28 | S23: =O23*1.04 -> 1949.7643 | T23: ='Program Budget'!T26 -> 10 | U23: =Admin!U23+'Activity 1'!U23+'Activity 2'!U23+'Activity 3'!U23+'Activity 4'!U23 -> 1 | V23: =S23*T23*U23 -> 19497.643 | W23: =F23+J23+N23+R23+V23 -> 117760.26
A24: ='Program Budget'!D27 -> Administrative Assistant | B24: ='Program Budget'!F27 -> Month | C24: ='Program Budget'!H27 -> 833.33333 | D24: ='Program Budget'!G27 -> 7 | E24: =Admin!E24+'Activity 1'!E24+'Activity 2'!E24+'Activity 3'!E24+'Activity 4'!E24 -> 1 | F24: =C24*D24*E24 -> 5833.3333 | G24: =C24*1.04 -> 866.66667 | H24: ='Program Budget'!K27 -> 12 | I24: =Admin!I24+'Activity 1'!I24+'Activity 2'!I24+'Activity 3'!I24+'Activity 4'!I24 -> 1 | J24: =G24*H24*I24 -> 10400 | K24: =G24*1.04 -> 901.33333 | L24: ='Program Budget'!N27 -> 12 | M24: =Admin!M24+'Activity 1'!M24+'Activity 2'!M24+'Activity 3'!M24+'Activity 4'!M24 -> 1 | N24: =K24*L24*M24 -> 10816 | O24: =K24*1.04 -> 937.38667 | P24: ='Program Budget'!Q27 -> 12 | Q24: =Admin!Q24+'Activity 1'!Q24+'Activity 2'!Q24+'Activity 3'!Q24+'Activity 4'!Q24 -> 1 | R24: =O24*P24*Q24 -> 11248.64 | S24: =O24*1.04 -> 974.88213 | T24: ='Program Budget'!T27 -> 10 | U24: =Admin!U24+'Activity 1'!U24+'Activity 2'!U24+'Activity 3'!U24+'Activity 4'!U24 -> 1 | V24: =S24*T24*U24 -> 9748.8213 | W24: =F24+J24+N24+R24+V24 -> 48046.795
A25: ='Program Budget'!D28 -> Security Guards | B25: ='Program Budget'!F28 -> Month | C25: ='Program Budget'!H28 -> 666.66667 | D25: ='Program Budget'!G28 -> 8 | E25: =Admin!E25+'Activity 1'!E25+'Activity 2'!E25+'Activity 3'!E25+'Activity 4'!E25 -> 1 | F25: =C25*D25*E25 -> 5333.3333 | G25: =C25*1.04 -> 693.33333 | H25: ='Program Budget'!K28 -> 12 | I25: =Admin!I25+'Activity 1'!I25+'Activity 2'!I25+'Activity 3'!I25+'Activity 4'!I25 -> 1 | J25: =G25*H25*I25 -> 8320 | K25: =G25*1.04 -> 721.06667 | L25: ='Program Budget'!N28 -> 12 | M25: =Admin!M25+'Activity 1'!M25+'Activity 2'!M25+'Activity 3'!M25+'Activity 4'!M25 -> 1 | N25: =K25*L25*M25 -> 8652.8 | O25: =K25*1.04 -> 749.90933 | P25: ='Program Budget'!Q28 -> 12 | Q25: =Admin!Q25+'Activity 1'!Q25+'Activity 2'!Q25+'Activity 3'!Q25+'Activity 4'!Q25 -> 1 | R25: =O25*P25*Q25 -> 8998.912 | S25: =O25*1.04 -> 779.90571 | T25: ='Program Budget'!T28 -> 10 | U25: =Admin!U25+'Activity 1'!U25+'Activity 2'!U25+'Activity 3'!U25+'Activity 4'!U25 -> 1 | V25: =S25*T25*U25 -> 7799.0571 | W25: =F25+J25+N25+R25+V25 -> 39104.102
A26: ='Program Budget'!D29 -> Driver (2 Individuals) | B26: ='Program Budget'!F29 -> Month | C26: ='Program Budget'!H29 -> 1333.3333 | D26: ='Program Budget'!G29 -> 6 | E26: =Admin!E26+'Activity 1'!E26+'Activity 2'!E26+'Activity 3'!E26+'Activity 4'!E26 -> 1 | F26: =C26*D26*E26 -> 8000 | G26: =C26*1.04 -> 1386.6667 | H26: ='Program Budget'!K29 -> 12 | I26: =Admin!I26+'Activity 1'!I26+'Activity 2'!I26+'Activity 3'!I26+'Activity 4'!I26 -> 1 | J26: =G26*H26*I26 -> 16640 | K26: =G26*1.04 -> 1442.1333 | L26: ='Program Budget'!N29 -> 12 | M26: =Admin!M26+'Activity 1'!M26+'Activity 2'!M26+'Activity 3'!M26+'Activity 4'!M26 -> 1 | N26: =K26*L26*M26 -> 17305.6 | O26: =K26*1.04 -> 1499.8187 | P26: ='Program Budget'!Q29 -> 12 | Q26: =Admin!Q26+'Activity 1'!Q26+'Activity 2'!Q26+'Activity 3'!Q26+'Activity 4'!Q26 -> 1 | R26: =O26*P26*Q26 -> 17997.824 | S26: =O26*1.04 -> 1559.8114 | T26: ='Program Budget'!T29 -> 9 | U26: =Admin!U26+'Activity 1'!U26+'Activity 2'!U26+'Activity 3'!U26+'Activity 4'!U26 -> 1 | V26: =S26*T26*U26 -> 14038.303 | W26: =F26+J26+N26+R26+V26 -> 73981.727
A27: Total Local Salary Cost | F27: =SUM(F10:F26) -> 407500 | J27: =SUM(J10:J26) -> 856960 | N27: =SUM(N10:N26) -> 739814.4 | R27: =SUM(R10:R26) -> 611926.02 | V27: =SUM(V10:V26) -> 479544.52 | W27: =F27+J27+N27+R27+V27 -> 3095744.9
A28: HQ Staff
A29: ='Program Budget'!D31 -> Senior Program Director | B29: ='Program Budget'!F31 -> Month | C29: ='Program Budget'!H31 -> 11250 | D29: ='Program Budget'!G31 -> 12 | E29: ='Program Budget'!E31 -> 0.2 | F29: =C29*D29*E29 -> 27000 | G29: =C29*1.04 -> 11700 | H29: ='Program Budget'!K31 -> 12 | I29: ='Program Budget'!J31 -> 0.2 | J29: =G29*H29*I29 -> 28080 | K29: =G29*1.04 -> 12168 | L29: ='Program Budget'!N31 -> 12 | M29: ='Program Budget'!M31 -> 0.2 | N29: =K29*L29*M29 -> 29203.2 | O29: =K29*1.04 -> 12654.72 | P29: ='Program Budget'!Q31 -> 12 | Q29: ='Program Budget'!P31 -> 0.2 | R29: =O29*P29*Q29 -> 30371.328 | S29: =O29*1.04 -> 13160.909 | T29: ='Program Budget'!T31 -> 12 | U29: ='Program Budget'!S31 -> 0.2 | V29: =S29*T29*U29 -> 31586.181 | W29: =F29+J29+N29+R29+V29 -> 146240.71
A30: ='Program Budget'!D32 -> HO Project Manager | B30: ='Program Budget'!F32 -> Month | C30: ='Program Budget'!H32 -> 6916.6667 | D30: ='Program Budget'!G32 -> 12 | E30: ='Program Budget'!E32 -> 1 | F30: =C30*D30*E30 -> 83000 | G30: =C30*1.04 -> 7193.3333 | H30: ='Program Budget'!K32 -> 12 | I30: ='Program Budget'!J32 -> 1 | J30: =G30*H30*I30 -> 86320 | K30: =G30*1.04 -> 7481.0667 | L30: ='Program Budget'!N32 -> 12 | M30: ='Program Budget'!M32 -> 1 | N30: =K30*L30*M30 -> 89772.8 | O30: =K30*1.04 -> 7780.3093 | P30: ='Program Budget'!Q32 -> 12 | Q30: ='Program Budget'!P32 -> 1 | R30: =O30*P30*Q30 -> 93363.712 | S30: =O30*1.04 -> 8091.5217 | T30: ='Program Budget'!T32 -> 12 | U30: ='Program Budget'!S32 -> 1 | V30: =S30*T30*U30 -> 97098.26 | W30: =F30+J30+N30+R30+V30 -> 449554.77
A31: Total HQ Staff | F31: =SUM(F29:F30) -> 110000 | J31: =SUM(J29:J30) -> 114400 | N31: =SUM(N29:N30) -> 118976 | R31: =SUM(R29:R30) -> 123735.04 | V31: =SUM(V29:V30) -> 128684.44 | W31: =+F31+J31+N31+R31+V31 -> 595795.48
A33: Subtotal: Salaries & Wages | F33: =F31+F27+F8 -> 662500 | J33: =J31+J27+J8 -> 1122160 | N33: =N31+N27+N8 -> 1015622.4 | R33: =R31+R27+R8 -> 898766.34 | V33: =V31+V27+V8 -> 777858.45 | W33: =+F33+J33+N33+R33+V33 -> 4476907.2
A34: Fringe
A35: USN/TCN Staff | B35: ='Program Budget'!F37 -> % | C35: =F8 -> 145000 | D35: 1 | E35: ='Program Budget'!H39 -> 0.2347 | F35: =C35*D35*E35 -> 34031.5 | G35: =J8 -> 150800 | H35: 1 | I35: =E35 -> 0.2347 | J35: =G35*H35*I35 -> 35392.76 | K35: =N8 -> 156832 | L35: 1 | M35: =I35 -> 0.2347 | N35: =K35*L35*M35 -> 36808.47 | O35: =R8 -> 163105.28 | P35: 1 | Q35: =M35 -> 0.2347 | R35: =O35*P35*Q35 -> 38280.809 | S35: =V8 -> 169629.49 | T35: 1 | U35: =Q35 -> 0.2347 | V35: =S35*T35*U35 -> 39812.042 | W35: =F35+J35+N35+R35+V35 -> 184325.58
A36: CCN Staff | B36: ='Program Budget'!F38 -> % | C36: =F27 -> 407500 | D36: 1 | E36: ='Program Budget'!H37 -> 0.2692 | F36: =C36*D36*E36 -> 109699 | G36: =J27 -> 856960 | H36: 1 | I36: =E36 -> 0.2692 | J36: =G36*H36*I36 -> 230693.63 | K36: =N27 -> 739814.4 | L36: 1 | M36: =I36 -> 0.2692 | N36: =K36*L36*M36 -> 199158.04 | O36: =R27 -> 611926.02 | P36: 1 | Q36: =M36 -> 0.2692 | R36: =O36*P36*Q36 -> 164730.48 | S36: =V27 -> 479544.52 | T36: 1 | U36: =Q36 -> 0.2692 | V36: =S36*T36*U36 -> 129093.39 | W36: =F36+J36+N36+R36+V36 -> 833374.54
A37: HQ Staff | B37: ='Program Budget'!F39 -> % | C37: =F31 -> 110000 | D37: 1 | E37: ='Program Budget'!H38 -> 0.2347 | F37: =C37*D37*E37 -> 25817 | G37: =J31 -> 114400 | H37: 1 | I37: =E37 -> 0.2347 | J37: =G37*H37*I37 -> 26849.68 | K37: =N31 -> 118976 | L37: 1 | M37: =I37 -> 0.2347 | N37: =K37*L37*M37 -> 27923.667 | O37: =R31 -> 123735.04 | P37: 1 | Q37: =M37 -> 0.2347 | R37: =O37*P37*Q37 -> 29040.614 | S37: =V31 -> 128684.44 | T37: 1 | U37: =Q37 -> 0.2347 | V37: =S37*T37*U37 -> 30202.238 | W37: =F37+J37+N37+R37+V37 -> 139833.2
A38: Total: Fringe Benefits | F38: =+SUM(F35:F37) -> 169547.5 | J38: =+SUM(J35:J37) -> 292936.07 | N38: =+SUM(N35:N37) -> 263890.17 | R38: =+SUM(R35:R37) -> 232051.91 | V38: =+SUM(V35:V37) -> 199107.67 | W38: =+F38+J38+N38+R38+V38 -> 1157533.3
A39: Allowances
A40: USN/TCN Staff
A41: ='Program Budget'!D40 -> Cost of Living Adjustment for Ex-pat Chief of Party | B41: ='Program Budget'!F40 -> % | C41: =F8 -> 145000 | D41: 1 | E41: ='Program Budget'!H40 -> 0.15 | F41: =C41*D41*E41 -> 21750 | G41: =J8 -> 150800 | H41: 1 | I41: =E41 -> 0.15 | J41: =G41*H41*I41 -> 22620 | K41: =N8 -> 156832 | L41: 1 | M41: =I41 -> 0.15 | N41: =K41*L41*M41 -> 23524.8 | O41: =R8 -> 163105.28 | P41: 1 | Q41: =M41 -> 0.15 | R41: =O41*P41*Q41 -> 24465.792 | S41: =V8 -> 169629.49 | T41: 1 | U41: =Q41 -> 0.15 | V41: =S41*T41*U41 -> 25444.424 | W41: =F41+J41+N41+R41+V41 -> 117805.02
A42: ='Program Budget'!D41 -> Post Hardship for Ex-pat Chief of Party | B42: ='Program Budget'!F41 -> % | C42: =F7 -> 145000 | D42: 1 | E42: ='Program Budget'!H41 -> 0.35 | F42: =C42*D42*E42 -> 50750 | G42: =J7 -> 150800 | H42: 1 | I42: =E42 -> 0.35 | J42: =G42*H42*I42 -> 52780 | K42: =N7 -> 156832 | L42: 1 | M42: =I42 -> 0.35 | N42: =K42*L42*M42 -> 54891.2 | O42: =R7 -> 163105.28 | P42: 1 | Q42: =M42 -> 0.35 | R42: =O42*P42*Q42 -> 57086.848 | S42: =V7 -> 169629.49 | T42: 1 | U42: =Q42 -> 0.35 | V42: =S42*T42*U42 -> 59370.322 | W42: =F42+J42+N42+R42+V42 -> 274878.37
...

Sheet Admin
A2: Item | B2: Type of Unit | C2: Year 1 | G2: Year 2 | K2: Year 3 | O2: Year 4 | S2: Year 5 | W2: Total
C3: Cost | D3: Quantity | E3: Percent Allocated | F3: Total | G3: Cost | H3: Quantity | I3: Percent Allocated | J3: Total | K3: Cost | L3: Quantity | M3: Percent Allocated | N3: Total | O3: Cost | P3: Quantity | Q3: Percent Allocated | R3: Total | S3: Cost | T3: Quantity | U3: Percent Allocated | V3: Total | AF3: Chart of Accounts
A4: Direct Costs | AE4: Line# | AF4: Account | AG4: Account Name
A5: Salaries
A6: USN/TCN Staff
A7: ='Program Budget'!D12 -> Key Personnel: Ex-pat Chief of Party | B7: ='Program Budget'!F13 -> Month | C7: ='Program Budget'!H12 -> 12083.333 | D7: ='Program Budget'!G12 -> 12 | E7: ='Program Budget'!E12 -> 0.2 | F7: =C7*D7*E7 -> 29000 | G7: =C7*1.04 -> 12566.667 | H7: ='Program Budget'!K12 -> 12 | I7: ='Program Budget'!J12 -> 0.05 | J7: =G7*H7*I7 -> 7540 | K7: =G7*1.04 -> 13069.333 | L7: ='Program Budget'!N12 -> 12 | M7: ='Program Budget'!M12 -> 0.05 | N7: =K7*L7*M7 -> 7841.6 | O7: =K7*1.04 -> 13592.107 | P7: ='Program Budget'!Q12 -> 12 | Q7: ='Program Budget'!P12 -> 0.05 | R7: =O7*P7*Q7 -> 8155.264 | S7: =O7*1.04 -> 14135.791 | T7: ='Program Budget'!T12 -> 12 | U7: ='Program Budget'!S12 -> 0.05 | V7: =S7*T7*U7 -> 8481.4746 | W7: =F7+J7+N7+R7+V7 -> 61018.339 | AE7: 180 | AF7: 50-01-2-020 | AG7: DIR-USN (Expat) Labor
A8: Total: Expatriate Salaries & Wages | F8: =SUM(F7:F7) -> 29000 | J8: =SUM(J7:J7) -> 7540 | N8: =SUM(N7:N7) -> 7841.6 | R8: =SUM(R7:R7) -> 8155.264 | V8: =SUM(V7:V7) -> 8481.4746 | W8: =+F8+J8+N8+R8+V8 -> 61018.339
A9: CNN Staff
A10: ='Program Budget'!D13 -> Deputy Chief of Party | B10: ='Program Budget'!F12 -> Month | C10: ='Program Budget'!H13 -> 7500 | D10: ='Program Budget'!G13 -> 6 | E10: ='Program Budget'!E13 -> 0.2 | F10: =C10*D10*E10 -> 9000 | G10: =C10*1.04 -> 7800 | H10: ='Program Budget'!K13 -> 12 | I10: ='Program Budget'!J13 -> 0 | J10: =G10*H10*I10 -> 0 | K10: =G10*1.04 -> 8112 | L10: ='Program Budget'!N13 -> 12 | M10: ='Program Budget'!M13 -> 0 | N10: =K10*L10*M10 -> 0 | O10: =K10*1.04 -> 8436.48 | P10: ='Program Budget'!Q13 -> 12 | Q10: ='Program Budget'!P13 -> 0 | R10: =O10*P10*Q10 -> 0 | S10: =O10*1.04 -> 8773.9392 | T10: ='Program Budget'!T13 -> 6 | U10: ='Program Budget'!S13 -> 0 | V10: =S10*T10*U10 -> 0 | W10: =F10+J10+N10+R10+V10 -> 9000 | AE10: 180 | AF10: 50-01-2-020 | AG10: DIR-USN (Expat) Labor
A11: ='Program Budget'!D14 -> Technical Lead Component 1 | B11: ='Program Budget'!F14 -> Month | C11: ='Program Budget'!H14 -> 3333.3333 | D11: ='Program Budget'!G14 -> 6 | E11: ='Program Budget'!E14 -> 0.25 | F11: =C11*D11*E11 -> 5000 | G11: =C11*1.04 -> 3466.6667 | H11: ='Program Budget'!K14 -> 12 | I11: ='Program Budget'!J14 -> 0 | J11: =G11*H11*I11 -> 0 | K11: =G11*1.04 -> 3605.3333 | L11: ='Program Budget'!N14 -> 12 | M11: ='Program Budget'!M14 -> 0 | N11: =K11*L11*M11 -> 0 | O11: =K11*1.04 -> 3749.5467 | P11: ='Program Budget'!Q14 -> 12 | Q11: ='Program Budget'!P14 -> 0 | R11: =O11*P11*Q11 -> 0 | S11: =O11*1.04 -> 3899.5285 | T11: ='Program Budget'!T14 -> 9 | U11: ='Program Budget'!S14 -> 0 | V11: =S11*T11*U11 -> 0 | W11: =F11+J11+N11+R11+V11 -> 5000 | AE11: 180 | AF11: 50-01-2-020 | AG11: DIR-USN (Expat) Labor
A12: ='Program Budget'!D15 -> Technical Lead Component 2 | B12: ='Program Budget'!F15 -> Month | C12: ='Program Budget'!H15 -> 3333.3333 | D12: ='Program Budget'!G15 -> 6 | E12: ='Program Budget'!E15 -> 0.25 | F12: =C12*D12*E12 -> 5000 | G12: =C12*1.04 -> 3466.6667 | H12: ='Program Budget'!K15 -> 12 | I12: ='Program Budget'!J15 -> 0 | J12: =G12*H12*I12 -> 0 | K12: =G12*1.04 -> 3605.3333 | L12: ='Program Budget'!N15 -> 12 | M12: ='Program Budget'!M15 -> 0 | N12: =K12*L12*M12 -> 0 | O12: =K12*1.04 -> 3749.5467 | P12: ='Program Budget'!Q15 -> 12 | Q12: ='Program Budget'!P15 -> 0 | R12: =O12*P12*Q12 -> 0 | S12: =O12*1.04 -> 3899.5285 | T12: ='Program Budget'!T15 -> 9 | U12: ='Program Budget'!S15 -> 0 | V12: =S12*T12*U12 -> 0 | W12: =F12+J12+N12+R12+V12 -> 5000 | AE12: 180 | AF12: 50-01-2-020 | AG12: DIR-USN (Expat) Labor
A13: ='Program Budget'!D16 -> Technical Lead Component 3 | B13: ='Program Budget'!F16 -> Month | C13: ='Program Budget'!H16 -> 3333.3333 | D13: ='Program Budget'!G16 -> 6 | E13: ='Program Budget'!E16 -> 0.25 | F13: =C13*D13*E13 -> 5000 | G13: =C13*1.04 -> 3466.6667 | H13: ='Program Budget'!K16 -> 12 | I13: ='Program Budget'!J16 -> 0 | J13: =G13*H13*I13 -> 0 | K13: =G13*1.04 -> 3605.3333 | L13: ='Program Budget'!N16 -> 12 | M13: ='Program Budget'!M16 -> 0 | N13: =K13*L13*M13 -> 0 | O13: =K13*1.04 -> 3749.5467 | P13: ='Program Budget'!Q16 -> 12 | Q13: ='Program Budget'!P16 -> 0 | R13: =O13*P13*Q13 -> 0 | S13: =O13*1.04 -> 3899.5285 | T13: ='Program Budget'!T16 -> 9 | U13: ='Program Budget'!S16 -> 0 | V13: =S13*T13*U13 -> 0 | W13: =F13+J13+N13+R13+V13 -> 5000 | AE13: 180 | AF13: 50-01-2-020 | AG13: DIR-USN (Expat) Labor
A14: ='Program Budget'!D17 -> Specialist Component 2 | B14: ='Program Budget'!F17 -> Month | C14: ='Program Budget'!H17 -> 1666.6667 | D14: ='Program Budget'!G17 -> 6 | E14: ='Program Budget'!E17 -> 0.2 | F14: =C14*D14*E14 -> 2000 | G14: =C14*1.04 -> 1733.3333 | H14: ='Program Budget'!K17 -> 12 | I14: ='Program Budget'!J17 -> 0 | J14: =G14*H14*I14 -> 0 | K14: =G14*1.04 -> 1802.6667 | L14: ='Program Budget'!N17 -> 12 | M14: ='Program Budget'!M17 -> 0 | N14: =K14*L14*M14 -> 0 | O14: =K14*1.04 -> 1874.7733 | P14: ='Program Budget'!Q17 -> 12 | Q14: ='Program Budget'!P17 -> 0 | R14: =O14*P14*Q14 -> 0 | S14: =O14*1.04 -> 1949.7643 | T14: ='Program Budget'!T17 -> 6 | U14: ='Program Budget'!S17 -> 0 | V14: =S14*T14*U14 -> 0 | W14: =F14+J14+N14+R14+V14 -> 2000 | AE14: 180 | AF14: 50-01-2-020 | AG14: DIR-USN (Expat) Labor
A15: ='Program Budget'!D18 -> Specialist Component 3 | B15: ='Program Budget'!F18 -> Month | C15: ='Program Budget'!H18 -> 1666.6667 | D15: ='Program Budget'!G18 -> 6 | E15: ='Program Budget'!E18 -> 0.2 | F15: =C15*D15*E15 -> 2000 | G15: =C15*1.04 -> 1733.3333 | H15: ='Program Budget'!K18 -> 12 | I15: ='Program Budget'!J18 -> 0 | J15: =G15*H15*I15 -> 0 | K15: =G15*1.04 -> 1802.6667 | L15: ='Program Budget'!N18 -> 12 | M15: ='Program Budget'!M18 -> 0 | N15: =K15*L15*M15 -> 0 | O15: =K15*1.04 -> 1874.7733 | P15: ='Program Budget'!Q18 -> 12 | Q15: ='Program Budget'!P18 -> 0 | R15: =O15*P15*Q15 -> 0 | S15: =O15*1.04 -> 1949.7643 | T15: ='Program Budget'!T18 -> 6 | U15: ='Program Budget'!S18 -> 0 | V15: =S15*T15*U15 -> 0 | W15: =F15+J15+N15+R15+V15 -> 2000
A16: ='Program Budget'!D19 -> Specialist Component 4 | B16: ='Program Budget'!F19 -> Month | C16: ='Program Budget'!H19 -> 1666.6667 | D16: ='Program Budget'!G19 -> 6 | E16: ='Program Budget'!E19 -> 0.2 | F16: =C16*D16*E16 -> 2000 | G16: =C16*1.04 -> 1733.3333 | H16: ='Program Budget'!K19 -> 12 | I16: ='Program Budget'!J19 -> 0 | J16: =G16*H16*I16 -> 0 | K16: =G16*1.04 -> 1802.6667 | L16: ='Program Budget'!N19 -> 12 | M16: ='Program Budget'!M19 -> 0 | N16: =K16*L16*M16 -> 0 | O16: =K16*1.04 -> 1874.7733 | P16: ='Program Budget'!Q19 -> 12 | Q16: ='Program Budget'!P19 -> 0 | R16: =O16*P16*Q16 -> 0 | S16: =O16*1.04 -> 1949.7643 | T16: ='Program Budget'!T19 -> 6 | U16: ='Program Budget'!S19 -> 0 | V16: =S16*T16*U16 -> 0 | W16: =F16+J16+N16+R16+V16 -> 2000
A17: ='Program Budget'!D20 -> Extension Agents (20 Individuals) | B17: ='Program Budget'!F20 -> Month | C17: ='Program Budget'!H20 -> 23333.333 | D17: ='Program Budget'!G20 -> 3 | E17: ='Program Budget'!E20 -> 0.1 | F17: =C17*D17*E17 -> 7000 | G17: =C17*1.04 -> 24266.667 | H17: ='Program Budget'!K20 -> 12 | I17: ='Program Budget'!J20 -> 0 | J17: =G17*H17*I17 -> 0 | K17: =G17*1.04 -> 25237.333 | L17: ='Program Budget'!N20 -> 6 | M17: ='Program Budget'!M20 -> 0 | N17: =K17*L17*M17 -> 0 | O17: =K17*1.04 -> 26246.827 | P17: ='Program Budget'!Q20 -> 0 | Q17: ='Program Budget'!P20 -> 0 | R17: =O17*P17*Q17 -> 0 | S17: =O17*1.04 -> 27296.7 | T17: ='Program Budget'!T20 -> 0 | U17: ='Program Budget'!S20 -> 0 | V17: =S17*T17*U17 -> 0 | W17: =F17+J17+N17+R17+V17 -> 7000
A18: ='Program Budget'!D21 -> M&E Director | B18: ='Program Budget'!F21 -> Month | C18: ='Program Budget'!H21 -> 3750 | D18: ='Program Budget'!G21 -> 9 | E18: ='Program Budget'!E21 -> 0.15 | F18: =C18*D18*E18 -> 5062.5 | G18: =C18*1.04 -> 3900 | H18: ='Program Budget'!K21 -> 12 | I18: ='Program Budget'!J21 -> 0.05 | J18: =G18*H18*I18 -> 2340 | K18: =G18*1.04 -> 4056 | L18: ='Program Budget'!N21 -> 12 | M18: ='Program Budget'!M21 -> 0.05 | N18: =K18*L18*M18 -> 2433.6 | O18: =K18*1.04 -> 4218.24 | P18: ='Program Budget'!Q21 -> 12 | Q18: ='Program Budget'!P21 -> 0.05 | R18: =O18*P18*Q18 -> 2530.944 | S18: =O18*1.04 -> 4386.9696 | T18: ='Program Budget'!T21 -> 12 | U18: ='Program Budget'!S21 -> 0.05 | V18: =S18*T18*U18 -> 2632.1818 | W18: =F18+J18+N18+R18+V18 -> 14999.226 | AE18: 180 | AF18: 50-01-2-020 | AG18: DIR-USN (Expat) Labor
A19: ='Program Budget'!D22 -> M&E Specialist | B19: ='Program Budget'!F22 -> Month | C19: ='Program Budget'!H22 -> 2083.3333 | D19: ='Program Budget'!G22 -> 6 | E19: ='Program Budget'!E22 -> 0.15 | F19: =C19*D19*E19 -> 1875 | G19: =C19*1.04 -> 2166.6667 | H19: ='Program Budget'!K22 -> 12 | I19: ='Program Budget'!J22 -> 0.05 | J19: =G19*H19*I19 -> 1300 | K19: =G19*1.04 -> 2253.3333 | L19: ='Program Budget'!N22 -> 12 | M19: ='Program Budget'!M22 -> 0.05 | N19: =K19*L19*M19 -> 1352 | O19: =K19*1.04 -> 2343.4667 | P19: ='Program Budget'!Q22 -> 12 | Q19: ='Program Budget'!P22 -> 0.05 | R19: =O19*P19*Q19 -> 1406.08 | S19: =O19*1.04 -> 2437.2053 | T19: ='Program Budget'!T22 -> 10 | U19: ='Program Budget'!S22 -> 0.05 | V19: =S19*T19*U19 -> 1218.6027 | W19: =F19+J19+N19+R19+V19 -> 7151.6827 | AE19: 180 | AF19: 50-01-2-020 | AG19: DIR-USN (Expat) Labor
A20: ='Program Budget'!D23 -> F&A Director | B20: ='Program Budget'!F23 -> Month | C20: ='Program Budget'!H23 -> 6666.6667 | D20: ='Program Budget'!G23 -> 9 | E20: ='Program Budget'!E23 -> 0.2 | F20: =C20*D20*E20 -> 12000 | G20: =C20*1.04 -> 6933.3333 | H20: ='Program Budget'!K23 -> 12 | I20: ='Program Budget'!J23 -> 0.1 | J20: =G20*H20*I20 -> 8320 | K20: =G20*1.04 -> 7210.6667 | L20: ='Program Budget'!N23 -> 12 | M20: ='Program Budget'!M23 -> 0.1 | N20: =K20*L20*M20 -> 8652.8 | O20: =K20*1.04 -> 7499.0933 | P20: ='Program Budget'!Q23 -> 12 | Q20: ='Program Budget'!P23 -> 0.1 | R20: =O20*P20*Q20 -> 8998.912 | S20: =O20*1.04 -> 7799.0571 | T20: ='Program Budget'!T23 -> 12 | U20: ='Program Budget'!S23 -> 0.1 | V20: =S20*T20*U20 -> 9358.8685 | W20: =F20+J20+N20+R20+V20 -> 47330.58 | AE20: 180 | AF20: 50-01-2-020 | AG20: DIR-USN (Expat) Labor
A21: ='Program Budget'!D24 -> Human Resource Manager | B21: ='Program Budget'!F24 -> Month | C21: ='Program Budget'!H24 -> 2916.6667 | D21: ='Program Budget'!G24 -> 9 | E21: ='Program Budget'!E24 -> 0.25 | F21: =C21*D21*E21 -> 6562.5 | G21: =C21*1.04 -> 3033.3333 | H21: ='Program Budget'!K24 -> 12 | I21: ='Program Budget'!J24 -> 0.1 | J21: =G21*H21*I21 -> 3640 | K21: =G21*1.04 -> 3154.6667 | L21: ='Program Budget'!N24 -> 12 | M21: ='Program Budget'!M24 -> 0.05 | N21: =K21*L21*M21 -> 1892.8 | O21: =K21*1.04 -> 3280.8533 | P21: ='Program Budget'!Q24 -> 12 | Q21: ='Program Budget'!P24 -> 0.05 | R21: =O21*P21*Q21 -> 1968.512 | S21: =O21*1.04 -> 3412.0875 | T21: ='Program Budget'!T24 -> 10 | U21: ='Program Budget'!S24 -> 0.05 | V21: =S21*T21*U21 -> 1706.0437 | W21: =F21+J21+N21+R21+V21 -> 15769.856
A22: ='Program Budget'!D25 -> Contracts & Compliance Specialist | B22: ='Program Budget'!F25 -> Month | C22: ='Program Budget'!H25 -> 2916.6667 | D22: ='Program Budget'!G25 -> 6 | E22: ='Program Budget'!E25 -> 0.1 | F22: =C22*D22*E22 -> 1750 | G22: =C22*1.04 -> 3033.3333 | H22: ='Program Budget'!K25 -> 12 | I22: ='Program Budget'!J25 -> 0.05 | J22: =G22*H22*I22 -> 1820 | K22: =G22*1.04 -> 3154.6667 | L22: ='Program Budget'!N25 -> 12 | M22: ='Program Budget'!M25 -> 0.05 | N22: =K22*L22*M22 -> 1892.8 | O22: =K22*1.04 -> 3280.8533 | P22: ='Program Budget'!Q25 -> 12 | Q22: ='Program Budget'!P25 -> 0.05 | R22: =O22*P22*Q22 -> 1968.512 | S22: =O22*1.04 -> 3412.0875 | T22: ='Program Budget'!T25 -> 9 | U22: ='Program Budget'!S25 -> 0.05 | V22: =S22*T22*U22 -> 1535.4394 | W22: =F22+J22+N22+R22+V22 -> 8966.7514 | AE22: 180 | AF22: 50-01-2-020 | AG22: DIR-USN (Expat) Labor
A23: ='Program Budget'!D26 -> Accountant | B23: ='Program Budget'!F26 -> Month | C23: ='Program Budget'!H26 -> 1666.6667 | D23: ='Program Budget'!G26 -> 7 | E23: ='Program Budget'!E26 -> 0.2 | F23: =C23*D23*E23 -> 2333.3333 | G23: =C23*1.04 -> 1733.3333 | H23: ='Program Budget'!K26 -> 12 | I23: ='Program Budget'!J26 -> 0.2 | J23: =G23*H23*I23 -> 4160 | K23: =G23*1.04 -> 1802.6667 | L23: ='Program Budget'!N26 -> 12 | M23: ='Program Budget'!M26 -> 0.2 | N23: =K23*L23*M23 -> 4326.4 | O23: =K23*1.04 -> 1874.7733 | P23: ='Program Budget'!Q26 -> 12 | Q23: ='Program Budget'!P26 -> 0.2 | R23: =O23*P23*Q23 -> 4499.456 | S23: =O23*1.04 -> 1949.7643 | T23: ='Program Budget'!T26 -> 10 | U23: ='Program Budget'!S26 -> 0.2 | V23: =S23*T23*U23 -> 3899.5285 | W23: =F23+J23+N23+R23+V23 -> 19218.718 | AE23: 180 | AF23: 50-01-2-020 | AG23: DIR-USN (Expat) Labor
A24: ='Program Budget'!D27 -> Administrative Assistant | B24: ='Program Budget'!F27 -> Month | C24: ='Program Budget'!H27 -> 833.33333 | D24: ='Program Budget'!G27 -> 7 | E24: ='Program Budget'!E27 -> 0.2 | F24: =C24*D24*E24 -> 1166.6667 | G24: =C24*1.04 -> 866.66667 | H24: ='Program Budget'!K27 -> 12 | I24: ='Program Budget'!J27 -> 0.2 | J24: =G24*H24*I24 -> 2080 | K24: =G24*1.04 -> 901.33333 | L24: ='Program Budget'!N27 -> 12 | M24: ='Program Budget'!M27 -> 0.2 | N24: =K24*L24*M24 -> 2163.2 | O24: =K24*1.04 -> 937.38667 | P24: ='Program Budget'!Q27 -> 12 | Q24: ='Program Budget'!P27 -> 0.2 | R24: =O24*P24*Q24 -> 2249.728 | S24: =O24*1.04 -> 974.88213 | T24: ='Program Budget'!T27 -> 10 | U24: ='Program Budget'!S27 -> 0.2 | V24: =S24*T24*U24 -> 1949.7643 | W24: =F24+J24+N24+R24+V24 -> 9609.3589 | AE24: 180 | AF24: 50-01-2-020 | AG24: DIR-USN (Expat) Labor
A25: ='Program Budget'!D28 -> Security Guards | B25: ='Program Budget'!F28 -> Month | C25: ='Program Budget'!H28 -> 666.66667 | D25: ='Program Budget'!G28 -> 8 | E25: ='Program Budget'!E28 -> 0.2 | F25: =C25*D25*E25 -> 1066.6667 | G25: =C25*1.04 -> 693.33333 | H25: ='Program Budget'!K28 -> 12 | I25: ='Program Budget'!J28 -> 0.05 | J25: =G25*H25*I25 -> 416 | K25: =G25*1.04 -> 721.06667 | L25: ='Program Budget'!N28 -> 12 | M25: ='Program Budget'!M28 -> 0.05 | N25: =K25*L25*M25 -> 432.64 | O25: =K25*1.04 -> 749.90933 | P25: ='Program Budget'!Q28 -> 12 | Q25: ='Program Budget'!P28 -> 0.05 | R25: =O25*P25*Q25 -> 449.9456 | S25: =O25*1.04 -> 779.90571 | T25: ='Program Budget'!T28 -> 10 | U25: ='Program Budget'!S28 -> 0.05 | V25: =S25*T25*U25 -> 389.95285 | W25: =F25+J25+N25+R25+V25 -> 2755.2051 | AE25: 180 | AF25: 50-01-2-020 | AG25: DIR-USN (Expat) Labor
A26: ='Program Budget'!D29 -> Driver (2 Individuals) | B26: ='Program Budget'!F29 -> Month | C26: ='Program Budget'!H29 -> 1333.3333 | D26: ='Program Budget'!G29 -> 6 | E26: ='Program Budget'!E29 -> 0.2 | F26: =C26*D26*E26 -> 1600 | G26: =C26*1.04 -> 1386.6667 | H26: ='Program Budget'!K29 -> 12 | I26: ='Program Budget'!J29 -> 0.05 | J26: =G26*H26*I26 -> 832 | K26: =G26*1.04 -> 1442.1333 | L26: ='Program Budget'!N29 -> 12 | M26: ='Program Budget'!M29 -> 0.05 | N26: =K26*L26*M26 -> 865.28 | O26: =K26*1.04 -> 1499.8187 | P26: ='Program Budget'!Q29 -> 12 | Q26: ='Program Budget'!P29 -> 0.05 | R26: =O26*P26*Q26 -> 899.8912 | S26: =O26*1.04 -> 1559.8114 | T26: ='Program Budget'!T29 -> 9 | U26: ='Program Budget'!S29 -> 0.05 | V26: =S26*T26*U26 -> 701.91514 | W26: =F26+J26+N26+R26+V26 -> 4899.0863 | AE26: 180 | AF26: 50-01-2-020 | AG26: DIR-USN (Expat) Labor
A27: Total Local Salary Cost | F27: =SUM(F10:F26) -> 70416.667 | J27: =SUM(J10:J26) -> 24908 | N27: =SUM(N10:N26) -> 24011.52 | R27: =SUM(R10:R26) -> 24971.981 | V27: =SUM(V10:V26) -> 23392.297 | W27: =F27+J27+N27+R27+V27 -> 167700.46
A28: HQ Staff
A29: ='Program Budget'!D31 -> Senior Program Director | B29: ='Program Budget'!F31 -> Month | C29: ='Program Budget'!H31 -> 11250 | D29: ='Program Budget'!G31 -> 12 | E29: ='Program Budget'!E31 -> 0.2 | F29: =C29*D29*E29 -> 27000 | G29: =C29*1.04 -> 11700 | H29: ='Program Budget'!K31 -> 12 | I29: ='Program Budget'!J31 -> 0.2 | J29: =G29*H29*I29 -> 28080 | K29: =G29*1.04 -> 12168 | L29: ='Program Budget'!N31 -> 12 | M29: ='Program Budget'!M31 -> 0.2 | N29: =K29*L29*M29 -> 29203.2 | O29: =K29*1.04 -> 12654.72 | P29: ='Program Budget'!Q31 -> 12 | Q29: ='Program Budget'!P31 -> 0.2 | R29: =O29*P29*Q29 -> 30371.328 | S29: =O29*1.04 -> 13160.909 | T29: ='Program Budget'!T31 -> 12 | U29: ='Program Budget'!S31 -> 0.2 | V29: =S29*T29*U29 -> 31586.181 | W29: =F29+J29+N29+R29+V29 -> 146240.71 | AE29: 180 | AF29: 50-01-2-020 | AG29: DIR-USN (Expat) Labor
A30: ='Program Budget'!D32 -> HO Project Manager | B30: ='Program Budget'!F32 -> Month | C30: ='Program Budget'!H32 -> 6916.6667 | D30: ='Program Budget'!G32 -> 12 | E30: ='Program Budget'!E32 -> 1 | F30: =C30*D30*E30 -> 83000 | G30: =C30*1.04 -> 7193.3333 | H30: ='Program Budget'!K32 -> 12 | I30: ='Program Budget'!J32 -> 1 | J30: =G30*H30*I30 -> 86320 | K30: =G30*1.04 -> 7481.0667 | L30: ='Program Budget'!N32 -> 12 | M30: ='Program Budget'!M32 -> 1 | N30: =K30*L30*M30 -> 89772.8 | O30: =K30*1.04 -> 7780.3093 | P30: ='Program Budget'!Q32 -> 12 | Q30: ='Program Budget'!P32 -> 1 | R30: =O30*P30*Q30 -> 93363.712 | S30: =O30*1.04 -> 8091.5217 | T30: ='Program Budget'!T32 -> 12 | U30: ='Program Budget'!S32 -> 1 | V30: =S30*T30*U30 -> 97098.26 | W30: =F30+J30+N30+R30+V30 -> 449554.77 | AE30: 180 | AF30: 50-01-2-020 | AG30: DIR-USN (Expat) Labor
A31: Total HQ Staff | F31: =SUM(F29:F30) -> 110000 | J31: =SUM(J29:J30) -> 114400 | N31: =SUM(N29:N30) -> 118976 | R31: =SUM(R29:R30) -> 123735.04 | V31: =SUM(V29:V30) -> 128684.44 | W31: =+F31+J31+N31+R31+V31 -> 595795.48
A33: Subtotal: Salaries & Wages | F33: =F31+F27+F8 -> 209416.67 | J33: =J31+J27+J8 -> 146848 | N33: =N31+N27+N8 -> 150829.12 | R33: =R31+R27+R8 -> 156862.28 | V33: =V31+V27+V8 -> 160558.21 | W33: =+F33+J33+N33+R33+V33 -> 824514.28
A34: Fringe
A35: USN/TCN Staff | B35: ='Program Budget'!F37 -> % | C35: =F8 -> 29000 | D35: 1 | E35: ='Program Budget'!H39 -> 0.2347 | F35: =C35*D35*E35 -> 6806.3 | G35: =J8 -> 7540 | H35: 1 | I35: =E35 -> 0.2347 | J35: =G35*H35*I35 -> 1769.638 | K35: =N8 -> 7841.6 | L35: 1 | M35: =I35 -> 0.2347 | N35: =K35*L35*M35 -> 1840.4235 | O35: =R8 -> 8155.264 | P35: 1 | Q35: =M35 -> 0.2347 | R35: =O35*P35*Q35 -> 1914.0405 | S35: =V8 -> 8481.4746 | T35: 1 | U35: =Q35 -> 0.2347 | V35: =S35*T35*U35 -> 1990.6021 | W35: =F35+J35+N35+R35+V35 -> 14321.004 | AE35: 194 | AF35: 50-03-0-020 | AG35: DIR-Allocated USN Fringe
A36: CCN Staff | B36: ='Program Budget'!F38 -> % | C36: =F27 -> 70416.667 | D36: 1 | E36: ='Program Budget'!H37 -> 0.2692 | F36: =C36*D36*E36 -> 18956.167 | G36: =J27 -> 24908 | H36: 1 | I36: =E36 -> 0.2692 | J36: =G36*H36*I36 -> 6705.2336 | K36: =N27 -> 24011.52 | L36: 1 | M36: =I36 -> 0.2692 | N36: =K36*L36*M36 -> 6463.9012 | O36: =R27 -> 24971.981 | P36: 1 | Q36: =M36 -> 0.2692 | R36: =O36*P36*Q36 -> 6722.4572 | S36: =V27 -> 23392.297 | T36: 1 | U36: =Q36 -> 0.2692 | V36: =S36*T36*U36 -> 6297.2063 | W36: =F36+J36+N36+R36+V36 -> 45144.965 | AE36: 197 | AF36: 50-03-0-050 | AG36: DIR-CCN Fringe
A37: HQ Staff | B37: ='Program Budget'!F39 -> % | C37: =F31 -> 110000 | D37: 1 | E37: ='Program Budget'!H38 -> 0.2347 | F37: =C37*D37*E37 -> 25817 | G37: =J31 -> 114400 | H37: 1 | I37: =E37 -> 0.2347 | J37: =G37*H37*I37 -> 26849.68 | K37: =N31 -> 118976 | L37: 1 | M37: =I37 -> 0.2347 | N37: =K37*L37*M37 -> 27923.667 | O37: =R31 -> 123735.04 | P37: 1 | Q37: =M37 -> 0.2347 | R37: =O37*P37*Q37 -> 29040.614 | S37: =V31 -> 128684.44 | T37: 1 | U37: =Q37 -> 0.2347 | V37: =S37*T37*U37 -> 30202.238 | W37: =F37+J37+N37+R37+V37 -> 139833.2 | AE37: 193 | AF37: 50-03-0-010 | AG37: DIR-Allocated HQ Fringe
A38: Total: Fringe Benefits | F38: =+SUM(F35:F37) -> 51579.467 | J38: =+SUM(J35:J37) -> 35324.552 | N38: =+SUM(N35:N37) -> 36227.992 | R38: =+SUM(R35:R37) -> 37677.112 | V38: =+SUM(V35:V37) -> 38490.047 | W38: =+F38+J38+N38+R38+V38 -> 199299.17
A39: Allowances
A40: USN/TCN Staff | AE40: 202 | AF40: 50-04-8-003 | AG40: DIR-COLA
A41: ='Program Budget'!D40 -> Cost of Living Adjustment for Ex-pat Chief of Party | B41: ='Program Budget'!F40 -> % | C41: =F8 -> 29000 | D41: 1 | E41: ='Program Budget'!H40 -> 0.15 | F41: =C41*D41*E41 -> 4350 | G41: =J8 -> 7540 | H41: 1 | I41: =E41 -> 0.15 | J41: =G41*H41*I41 -> 1131 | K41: =N8 -> 7841.6 | L41: 1 | M41: =I41 -> 0.15 | N41: =K41*L41*M41 -> 1176.24 | O41: =R8 -> 8155.264 | P41: 1 | Q41: =M41 -> 0.15 | R41: =O41*P41*Q41 -> 1223.2896 | S41: =V8 -> 8481.4746 | T41: 1 | U41: =Q41 -> 0.15 | V41: =S41*T41*U41 -> 1272.2212 | W41: =F41+J41+N41+R41+V41 -> 9152.7508
A42: ='Program Budget'!D41 -> Post Hardship for Ex-pat Chief of Party | B42: ='Program Budget'!F41 -> % | C42: =F7 -> 29000 | D42: 1 | E42: ='Program Budget'!H41 -> 0.35 | F42: =C42*D42*E42 -> 10150 | G42: =J7 -> 7540 | H42: 1 | I42: =E42 -> 0.35 | J42: =G42*H42*I42 -> 2639 | K42: =N7 -> 7841.6 | L42: 1 | M42: =I42 -> 0.35 | N42: =K42*L42*M42 -> 2744.56 | O42: =R7 -> 8155.264 | P42: 1 | Q42: =M42 -> 0.35 | R42: =O42*P42*Q42 -> 2854.3424 | S42: =V7 -> 8481.4746 | T42: 1 | U42: =Q42 -> 0.35 | V42: =S42*T42*U42 -> 2968.5161 | W42: =F42+J42+N42+R42+V42 -> 21356.418
...

Sheet Activity 1
A2: Item | B2: Type of Unit | C2: Year 1 | G2: Year 2 | K2: Year 3 | O2: Year 4 | S2: Year 5 | W2: Total
C3: Cost | D3: Quantity | E3: Percent Allocated | F3: Total | G3: Cost | H3: Quantity | I3: Percent Allocated | J3: Total | K3: Cost | L3: Quantity | M3: Percent Allocated | N3: Total | O3: Cost | P3: Quantity | Q3: Percent Allocated | R3: Total | S3: Cost | T3: Quantity | U3: Percent Allocated | V3: Total | AF3: Chart of Accounts
A4: Direct Costs | AE4: Line# | AF4: Account | AG4: Account Name
A5: Salaries
A6: USN/TCN Staff
A7: ='Program Budget'!D12 -> Key Personnel: Ex-pat Chief of Party | B7: ='Program Budget'!F13 -> Month | C7: ='Program Budget'!H12 -> 12083.333 | D7: ='Program Budget'!G12 -> 12 | E7: ='Program Budget'!E146 -> 0.2 | F7: =C7*D7*E7 -> 29000 | G7: =C7*1.04 -> 12566.667 | H7: ='Program Budget'!K12 -> 12 | I7: ='Program Budget'!J146 -> 0.25 | J7: =G7*H7*I7 -> 37700 | K7: =G7*1.04 -> 13069.333 | L7: ='Program Budget'!N12 -> 12 | M7: ='Program Budget'!M146 -> 0.25 | N7: =K7*L7*M7 -> 39208 | O7: =K7*1.04 -> 13592.107 | P7: ='Program Budget'!Q12 -> 12 | Q7: ='Program Budget'!P146 -> 0.25 | R7: =O7*P7*Q7 -> 40776.32 | S7: =O7*1.04 -> 14135.791 | T7: ='Program Budget'!T12 -> 12 | U7: ='Program Budget'!S146 -> 0.25 | V7: =S7*T7*U7 -> 42407.373 | W7: =F7+J7+N7+R7+V7 -> 189091.69 | AE7: 180 | AF7: 50-01-2-020 | AG7: DIR-USN (Expat) Labor
A8: Total: Expatriate Salaries & Wages | F8: =SUM(F7:F7) -> 29000 | J8: =SUM(J7:J7) -> 37700 | N8: =SUM(N7:N7) -> 39208 | R8: =SUM(R7:R7) -> 40776.32 | V8: =SUM(V7:V7) -> 42407.373 | W8: =+F8+J8+N8+R8+V8 -> 189091.69
A9: CCN Staff
A10: ='Program Budget'!D13 -> Deputy Chief of Party | B10: ='Program Budget'!F12 -> Month | C10: ='Program Budget'!H13 -> 7500 | D10: ='Program Budget'!G13 -> 6 | E10: ='Program Budget'!E147 -> 0.1 | F10: =C10*D10*E10 -> 4500 | G10: =C10*1.04 -> 7800 | H10: ='Program Budget'!K13 -> 12 | I10: ='Program Budget'!J147 -> 0.1 | J10: =G10*H10*I10 -> 9360 | K10: =G10*1.04 -> 8112 | L10: ='Program Budget'!N13 -> 12 | M10: ='Program Budget'!M147 -> 0.1 | N10: =K10*L10*M10 -> 9734.4 | O10: =K10*1.04 -> 8436.48 | P10: ='Program Budget'!Q13 -> 12 | Q10: ='Program Budget'!P147 -> 0.1 | R10: =O10*P10*Q10 -> 10123.776 | S10: =O10*1.04 -> 8773.9392 | T10: ='Program Budget'!T13 -> 6 | U10: ='Program Budget'!S147 -> 0.1 | V10: =S10*T10*U10 -> 5264.3635 | W10: =F10+J10+N10+R10+V10 -> 38982.54 | AE10: 180 | AF10: 50-01-2-020 | AG10: DIR-USN (Expat) Labor
A11: ='Program Budget'!D148 -> Technical Lead Component 1 | B11: ='Program Budget'!F14 -> Month | C11: ='Program Budget'!H148 -> 3333.3333 | D11: ='Program Budget'!G148 -> 6 | E11: ='Program Budget'!E148 -> 0.75 | F11: =C11*D11*E11 -> 15000 | G11: =C11*1.04 -> 3466.6667 | H11: ='Program Budget'!K148 -> 12 | I11: ='Program Budget'!J148 -> 1 | J11: =G11*H11*I11 -> 41600 | K11: =G11*1.04 -> 3605.3333 | L11: ='Program Budget'!N148 -> 12 | M11: ='Program Budget'!M148 -> 1 | N11: =K11*L11*M11 -> 43264 | O11: =K11*1.04 -> 3749.5467 | P11: ='Program Budget'!Q148 -> 12 | Q11: ='Program Budget'!P148 -> 1 | R11: =O11*P11*Q11 -> 44994.56 | S11: =O11*1.04 -> 3899.5285 | T11: ='Program Budget'!T148 -> 9 | U11: ='Program Budget'!S148 -> 1 | V11: =S11*T11*U11 -> 35095.757 | W11: =F11+J11+N11+R11+V11 -> 179954.32 | AE11: 180 | AF11: 50-01-2-020 | AG11: DIR-USN (Expat) Labor
A12: ='Program Budget'!D149 -> Technical Lead Component 2 | B12: ='Program Budget'!F15 -> Month | C12: ='Program Budget'!H149 -> 3333.3333 | D12: ='Program Budget'!G149 -> 6 | E12: ='Program Budget'!E149 -> 0 | F12: =C12*D12*E12 -> 0 | G12: =C12*1.04 -> 3466.6667 | H12: ='Program Budget'!K149 -> 12 | I12: ='Program Budget'!J149 -> 0 | J12: =G12*H12*I12 -> 0 | K12: =G12*1.04 -> 3605.3333 | L12: ='Program Budget'!N149 -> 12 | M12: ='Program Budget'!M149 -> 0 | N12: =K12*L12*M12 -> 0 | O12: =K12*1.04 -> 3749.5467 | P12: ='Program Budget'!Q149 -> 12 | Q12: ='Program Budget'!P149 -> 0 | R12: =O12*P12*Q12 -> 0 | S12: =O12*1.04 -> 3899.5285 | T12: ='Program Budget'!T149 -> 9 | U12: ='Program Budget'!S149 -> 0 | V12: =S12*T12*U12 -> 0 | W12: =F12+J12+N12+R12+V12 -> 0 | AE12: 180 | AF12: 50-01-2-020 | AG12: DIR-USN (Expat) Labor
A13: ='Program Budget'!D150 -> Technical Lead Component 3 | B13: ='Program Budget'!F16 -> Month | C13: ='Program Budget'!H150 -> 3333.3333 | D13: ='Program Budget'!G150 -> 6 | E13: ='Program Budget'!E150 -> 0 | F13: =C13*D13*E13 -> 0 | G13: =C13*1.04 -> 3466.6667 | H13: ='Program Budget'!K150 -> 12 | I13: ='Program Budget'!J150 -> 0 | J13: =G13*H13*I13 -> 0 | K13: =G13*1.04 -> 3605.3333 | L13: ='Program Budget'!N150 -> 12 | M13: ='Program Budget'!M150 -> 0 | N13: =K13*L13*M13 -> 0 | O13: =K13*1.04 -> 3749.5467 | P13: ='Program Budget'!Q150 -> 12 | Q13: ='Program Budget'!P150 -> 0 | R13: =O13*P13*Q13 -> 0 | S13: =O13*1.04 -> 3899.5285 | T13: ='Program Budget'!T150 -> 9 | U13: ='Program Budget'!S150 -> 0 | V13: =S13*T13*U13 -> 0 | W13: =F13+J13+N13+R13+V13 -> 0 | AE13: 180 | AF13: 50-01-2-020 | AG13: DIR-USN (Expat) Labor
A14: ='Program Budget'!D151 -> Specialist Component 2 | B14: ='Program Budget'!F17 -> Month | C14: ='Program Budget'!H151 -> 1666.6667 | D14: ='Program Budget'!G151 -> 6 | E14: ='Program Budget'!E151 -> 0 | F14: =C14*D14*E14 -> 0 | G14: =C14*1.04 -> 1733.3333 | H14: ='Program Budget'!K151 -> 12 | I14: ='Program Budget'!J151 -> 0 | J14: =G14*H14*I14 -> 0 | K14: =G14*1.04 -> 1802.6667 | L14: ='Program Budget'!N151 -> 12 | M14: ='Program Budget'!M151 -> 0 | N14: =K14*L14*M14 -> 0 | O14: =K14*1.04 -> 1874.7733 | P14: ='Program Budget'!Q151 -> 12 | Q14: ='Program Budget'!P151 -> 0 | R14: =O14*P14*Q14 -> 0 | S14: =O14*1.04 -> 1949.7643 | T14: ='Program Budget'!T151 -> 6 | U14: ='Program Budget'!S151 -> 0 | V14: =S14*T14*U14 -> 0 | W14: =F14+J14+N14+R14+V14 -> 0
A15: ='Program Budget'!D152 -> Specialist Component 3 | B15: ='Program Budget'!F18 -> Month | C15: ='Program Budget'!H152 -> 1666.6667 | D15: ='Program Budget'!G152 -> 6 | E15: ='Program Budget'!E152 -> 0 | F15: =C15*D15*E15 -> 0 | G15: =C15*1.04 -> 1733.3333 | H15: ='Program Budget'!K152 -> 12 | I15: ='Program Budget'!J152 -> 0 | J15: =G15*H15*I15 -> 0 | K15: =G15*1.04 -> 1802.6667 | L15: ='Program Budget'!N152 -> 12 | M15: ='Program Budget'!M152 -> 0 | N15: =K15*L15*M15 -> 0 | O15: =K15*1.04 -> 1874.7733 | P15: ='Program Budget'!Q152 -> 12 | Q15: ='Program Budget'!P152 -> 0 | R15: =O15*P15*Q15 -> 0 | S15: =O15*1.04 -> 1949.7643 | T15: ='Program Budget'!T152 -> 6 | U15: ='Program Budget'!S152 -> 0 | V15: =S15*T15*U15 -> 0 | W15: =F15+J15+N15+R15+V15 -> 0
A16: ='Program Budget'!D153 -> Specialist Component 4 | B16: ='Program Budget'!F19 -> Month | C16: ='Program Budget'!H153 -> 1666.6667 | D16: ='Program Budget'!G153 -> 6 | E16: ='Program Budget'!E153 -> 0 | F16: =C16*D16*E16 -> 0 | G16: =C16*1.04 -> 1733.3333 | H16: ='Program Budget'!K153 -> 12 | I16: ='Program Budget'!J153 -> 0 | J16: =G16*H16*I16 -> 0 | K16: =G16*1.04 -> 1802.6667 | L16: ='Program Budget'!N153 -> 12 | M16: ='Program Budget'!M153 -> 0 | N16: =K16*L16*M16 -> 0 | O16: =K16*1.04 -> 1874.7733 | P16: ='Program Budget'!Q153 -> 12 | Q16: ='Program Budget'!P153 -> 0 | R16: =O16*P16*Q16 -> 0 | S16: =O16*1.04 -> 1949.7643 | T16: ='Program Budget'!T153 -> 6 | U16: ='Program Budget'!S153 -> 0 | V16: =S16*T16*U16 -> 0 | W16: =F16+J16+N16+R16+V16 -> 0
