Workbook
Name agentfee: #REF!
Name avrent: #REF!
Name Category: #REF!
Name coffee: #REF!
Name consairfare: #REF!
Name consground: #REF!
Name conslodg: #REF!
Name consmeals: #REF!
Name consmisc: #REF!
Name DL_Country: #REF!
Name DL_TotalDOL: #REF!
Name EQ_Country: #REF!
Name EQ_TotalDOL: #REF!
Name er: #REF!
Name ground: #REF!
Name guideprint: #REF!
Name inmuniz: #REF!
Name intairfare: #REF!
Name intcalls: #REF!
Name intcons: #REF!
Name intmisc: #REF!
Name livingq: #REF!
Name Local_transport_part: #REF!
Name localairfare: #REF!
Name localcons: #REF!
Name locallodg: #REF!
Name localmeals: #REF!
Name localmisc: #REF!
Name lunch: #REF!
Name mats: #REF!
Name ME_TotalDOL: #REF!
Name medex: #REF!
Name meetcost: #REF!+#REF!
Name mileage: #REF!
Name natcalls: #REF!
Name O1_Country: #REF!
Name O1_TotalDOL: #REF!
Name O2_Country: #REF!
Name O2_TotalDOL: #REF!
Name partairfare: #REF!
Name partground: #REF!
Name partlodg: #REF!
Name partmats: #REF!
Name partmeals: #REF!
Name partmisc: #REF!
Name partprint: #REF!
Name parttransp: #REF!
Name print: #REF!
Name regcons: #REF!
Name roomrent: #REF!
Name SU_Country: #REF!
Name SU_TotalDOL: #REF!
Name surveyor: #REF!
Name tdlunch: #REF!
Name TotalDOL: #REF!
Name TR_Country: #REF!
Name TR_TotalDOL: #REF!
Name travmisc: #REF!+#REF!+#REF!
Name usaidlodg: #REF!
Name usaidmeal: #REF!

Sheet Budget Summary
A3: Project Budget Summary
A4: Partners of the Americas
A5: ='POA General Budget'!D3 -> Leveling the Field for American Workers in U.S.-Mexico Trade
A6: 54 Months
A8: BUDGET SUMMARY CATEGORIES | B8: YEAR 1 | C8: YEAR 2 | D8: YEAR 3 | E8: YEAR 4 | F8: YEAR 5 | G8: TOTAL FEDERAL FUNDS REQUESTED
A10: 1. PERSONNEL | B10: =+'POA General Budget'!J24 -> 475499.97 | C10: =+'POA General Budget'!L24 -> 580649.97 | D10: =+'POA General Budget'!N24 -> 609682.47 | E10: =+'POA General Budget'!P24 -> 640166.59 | F10: =+'POA General Budget'!R24 -> 263157.09 | G10: =SUM(B10:F10) -> 2569156.1
A11: 2. FRINGE BENEFITS | B11: =+'POA General Budget'!J28 -> 172270.79 | C11: =+'POA General Budget'!L28 -> 214654.96 | D11: =+'POA General Budget'!N28 -> 225387.71 | E11: =+'POA General Budget'!P28 -> 236657.09 | F11: =+'POA General Budget'!R28 -> 93978.867 | G11: =SUM(B11:F11) -> 942949.42
A12: 3. TRAVEL | B12: =+'POA General Budget'!J77 -> 62289.573 | C12: =+'POA General Budget'!L77 -> 71787.781 | D12: =+'POA General Budget'!N77 -> 64240.73 | E12: =+'POA General Budget'!P77 -> 63348.573 | F12: =+'POA General Budget'!R77 -> 10261.051 | G12: =SUM(B12:F12) -> 271927.71
A13: 4. EQUIPMENT | B13: =+'POA General Budget'!J80 -> 0 | C13: =+'POA General Budget'!L80 -> 0 | D13: =+'POA General Budget'!N80 -> 0 | E13: =+'POA General Budget'!P80 -> 0 | F13: =+'POA General Budget'!R80 -> 0 | G13: =SUM(B13:F13) -> 0
A14: 5. SUPPLIES | B14: =+'POA General Budget'!J85 -> 10202 | C14: =+'POA General Budget'!L85 -> 1872 | D14: =+'POA General Budget'!N85 -> 1946.88 | E14: =+'POA General Budget'!P85 -> 2024.7552 | F14: =+'POA General Budget'!R85 -> 1052.8727 | G14: =SUM(B14:F14) -> 17098.508
A15: 6. CONTRACTUAL | B15: =+'POA General Budget'!J96 -> 415327.56 | C15: =+'POA General Budget'!L96 -> 1345025.8 | D15: =+'POA General Budget'!N96 -> 1211382.7 | E15: =+'POA General Budget'!P96 -> 856735.7 | F15: =+'POA General Budget'!R96 -> 45528.727 | G15: =SUM(B15:F15) -> 3874000.5
A16: 7. CONSTRUCTION | B16: =+'POA General Budget'!J99 -> 0 | C16: =+'POA General Budget'!L99 -> 0 | D16: =+'POA General Budget'!N99 -> 0 | E16: =+'POA General Budget'!P99 -> 0 | F16: =+'POA General Budget'!R99 -> 0 | G16: =SUM(B16:F16) -> 0
A17: 8. OTHER DIRECT COSTS | B17: =+'POA General Budget'!J158 -> 152676 | C17: =+'POA General Budget'!L158 -> 364098.64 | D17: =+'POA General Budget'!N158 -> 347427.13 | E17: =+'POA General Budget'!P158 -> 352225.46 | F17: =+'POA General Budget'!R158 -> 42603.909 | G17: =SUM(B17:F17) -> 1259031.1
A19: 9. TOTAL DIRECT COSTS (Lines 1-8) | B19: =SUM(B10:B17) -> 1288265.9 | C19: =SUM(C10:C17) -> 2578089.2 | D19: =SUM(D10:D17) -> 2460067.6 | E19: =SUM(E10:E17) -> 2151158.2 | F19: =SUM(F10:F17) -> 456582.51 | G19: =SUM(G10:G17) -> 8934163.4
A20: 10. INDIRECT COSTS | B20: =+'POA General Budget'!J165 -> 169933.68 | C20: =+'POA General Budget'!L165 -> 292026.51 | D20: =+'POA General Budget'!N165 -> 278014.54 | E20: =+'POA General Budget'!P165 -> 257374.48 | F20: =+'POA General Budget'!R165 -> 68487.377 | G20: =SUM(B20:F20) -> 1065836.6
A21: 11. TOTAL COSTS (Lines 9-10) | B21: =SUM(B19:B20) -> 1458199.6 | C21: =SUM(C19:C20) -> 2870115.7 | D21: =SUM(D19:D20) -> 2738082.2 | E21: =SUM(E19:E20) -> 2408532.7 | F21: =SUM(F19:F20) -> 525069.89 | G21: =SUM(G19:G20) -> 10000000

Sheet POA General Budget
D1: Project Line-Item Budget
D2: Partners of the Americas
D3: Leveling the Field for American Workers in U.S.-Mexico Trade
A4: Entity: | B4: P | D4: 54 Months
A5: Program-Dept.: | B5: 20200 | D5: Cost Assumptions
A6: Funder-Grant: | B6: DOL427 | D6: Inflation - Goods/Services | E6: 1.04
D7: Merit Based Increases for HO & Field Staff | E7: 1.05
A9: Activity Code | B9: Account Code | C9: Country Code | D9: BUDGET ITEM | E9: CATEGORY | F9: LOE | G9: UNIT | H9: # of Units | I9: RATE / UNIT | J9: Year 1 | K9: # of Units | L9: Year 2 | M9: # of Units | N9: Year 3 | O9: # of Units | P9: Year 4 | Q9: # of Units | R9: Year 5 | S9: TOTAL DOL | T9: TOTAL COST SHARING | U9: PROJECT GRAND TOTAL
D10: Personnel
D11: Key Personnel
A12: PERSNL-PD | B12: 70000 | C12: MEX | D12: Project Director: Ingrid Ceballos | E12: Salaries | F12: 1 | G12: Month | H12: 12 | I12: 10000 | J12: =H12*I12*F12 -> 120000 | K12: 12 | L12: =K12*$I12*$E$7*$F12 -> 126000 | M12: 12 | N12: =M12*$I12*$E$7*$F12*$E$7 -> 132300 | O12: 12 | P12: =O12*$I12*$E$7*$F12*$E$7*$E$7 -> 138915 | Q12: 6 | R12: =Q12*$I12*$E$7*$F12*$E$7*$E$7*$E$7 -> 72930.375 | S12: =SUM(J12+L12+N12+P12+R12) -> 590145.38 | T12: 0 | U12: =SUM(S12:T12) -> 590145.38
A13: PERSNL-M&E | B13: 70000 | C13: MEX | D13: M&E Officer: Luis Madrid | E13: Salaries | F13: 1 | G13: Month | H13: 11 | I13: =4500 -> 4500 | J13: =H13*I13*F13 -> 49500 | K13: 12 | L13: =K13*$I13*$E$7*$F13 -> 56700 | M13: 12 | N13: =M13*$I13*$E$7*$F13*$E$7 -> 59535 | O13: 12 | P13: =O13*$I13*$E$7*$F13*$E$7*$E$7 -> 62511.75 | Q13: 6 | R13: =Q13*$I13*$E$7*$F13*$E$7*$E$7*$E$7 -> 32818.669 | S13: =SUM(J13+L13+N13+P13+R13) -> 261065.42 | T13: 0 | U13: =SUM(S13:T13) -> 261065.42
A14: PERSNL-IRS | B14: 70000 | C14: MEX | D14: Industrial Relations Specialist: Darlene Rojas | E14: Salaries | F14: 1 | G14: Month | H14: 11 | I14: 7000 | J14: =H14*I14*F14 -> 77000 | K14: 12 | L14: =K14*$I14*$E$7*$F14 -> 88200 | M14: 12 | N14: =M14*$I14*$E$7*$F14*$E$7 -> 92610 | O14: 12 | P14: =O14*$I14*$E$7*$F14*$E$7*$E$7 -> 97240.5 | Q14: 2 | R14: =Q14*$I14*$E$7*$F14*$E$7*$E$7*$E$7 -> 17017.088 | S14: =SUM(J14+L14+N14+P14+R14) -> 372067.59 | T14: 0 | U14: =SUM(S14:T14) -> 372067.59
D15: Other Professional Personnel
A16: PERSNL-F&A | B16: 70000 | C16: MEX | D16: F&A Manager | E16: Salaries | F16: 1 | G16: Month | H16: 10 | I16: =5000 -> 5000 | J16: =H16*I16*F16 -> 50000 | K16: 12 | L16: =K16*$I16*$E$7*$F16 -> 63000 | M16: 12 | N16: =M16*$I16*$E$7*$F16*$E$7 -> 66150 | O16: 12 | P16: =O16*$I16*$E$7*$F16*$E$7*$E$7 -> 69457.5 | Q16: 6 | R16: =Q16*$I16*$E$7*$F16*$E$7*$E$7*$E$7 -> 36465.188 | S16: =SUM(J16+L16+N16+P16+R16) -> 285072.69 | T16: 0 | U16: =SUM(S16:T16) -> 285072.69
A17: PERSNL-OPS | B17: 70000 | C17: MEX | D17: Administration & Operations Specialist | E17: Salaries | F17: 1 | G17: Month | H17: 8 | I17: =4000 -> 4000 | J17: =H17*I17*F17 -> 32000 | K17: 12 | L17: =K17*$I17*$E$7*$F17 -> 50400 | M17: 12 | N17: =M17*$I17*$E$7*$F17*$E$7 -> 52920 | O17: 12 | P17: =O17*$I17*$E$7*$F17*$E$7*$E$7 -> 55566 | Q17: 2 | R17: =Q17*$I17*$E$7*$F17*$E$7*$E$7*$E$7 -> 9724.05 | S17: =SUM(J17+L17+N17+P17+R17) -> 200610.05 | T17: 0 | U17: =SUM(S17:T17) -> 200610.05
A18: PERSNL-TPS | B18: 70000 | C18: MEX | D18: Technology Project Specialist | E18: Salaries | F18: 1 | G18: Month | H18: 2 | I18: =4000 -> 4000 | J18: =H18*I18*F18 -> 8000 | K18: 12 | L18: =K18*$I18*$E$7*$F18 -> 50400 | M18: 12 | N18: =M18*$I18*$E$7*$F18*$E$7 -> 52920 | O18: 12 | P18: =O18*$I18*$E$7*$F18*$E$7*$E$7 -> 55566 | Q18: 2 | R18: =Q18*$I18*$E$7*$F18*$E$7*$E$7*$E$7 -> 9724.05 | S18: =SUM(J18+L18+N18+P18+R18) -> 176610.05 | T18: 0 | U18: =SUM(S18:T18) -> 176610.05
D19: Home Office Support
A20: PERSNL-PM | B20: 50000 | C20: USA | D20: Project Manager | E20: Salaries | F20: 0.3 | G20: Month | H20: 12 | I20: 12500 | J20: =H20*I20*F20 -> 45000 | K20: 12 | L20: =K20*$I20*$E$7*$F20 -> 47250 | M20: 12 | N20: =M20*$I20*$E$7*$F20*$E$7 -> 49612.5 | O20: 12 | P20: =(O20*I20*$E$7*$E$7*$E$7)*F20 -> 52093.125 | Q20: 6 | R20: =Q20*$I20*$E$7*$F20*$E$7*$E$7*$E$7 -> 27348.891 | S20: =SUM(J20+L20+N20+P20+R20) -> 221304.52 | T20: 0 | U20: =SUM(S20:T20) -> 221304.52
A21: PERSNL-PO | B21: 50000 | C21: USA | D21: Senior Program Officer | E21: Salaries | F21: 0.8 | G21: Month | H21: 12 | I21: 5833.33 | J21: =H21*I21*F21 -> 55999.968 | K21: 12 | L21: =K21*$I21*$E$7*$F21 -> 58799.966 | M21: 12 | N21: =M21*$I21*$E$7*$F21*$E$7 -> 61739.965 | O21: 12 | P21: =(O21*I21*$E$7*$E$7*$E$7)*F21 -> 64826.963 | Q21: 6 | R21: =Q21*$I21*$E$7*$F21*$E$7*$E$7*$E$7 -> 34034.156 | S21: =SUM(J21+L21+N21+P21+R21) -> 275401.02 | T21: 0 | U21: =SUM(S21:T21) -> 275401.02
A22: PERSNL | B22: 50000 | C22: USA | D22: Compliance & Contracts Director | E22: Salaries | F22: 0.1 | G22: Month | H22: 12 | I22: 9166.67 | J22: =H22*I22*F22 -> 11000.004 | K22: 12 | L22: =K22*$I22*$E$7*$F22 -> 11550.004 | M22: 12 | N22: =M22*$I22*$E$7*$F22*$E$7 -> 12127.504 | O22: 12 | P22: =(O22*I22*$E$7*$E$7*$E$7)*F22 -> 12733.88 | Q22: 6 | R22: =Q22*$I22*$E$7*$F22*$E$7*$E$7*$E$7 -> 6685.2868 | S22: =SUM(J22+L22+N22+P22+R22) -> 54096.679 | T22: 0 | U22: =SUM(S22:T22) -> 54096.679
A23: PERSNL | B23: 50000 | C23: USA | D23: Finance, HR, & Administration Support | E23: Salaries | F23: 0.3 | G23: Month | H23: 12 | I23: 7500 | J23: =H23*I23*F23 -> 27000 | K23: 12 | L23: =K23*$I23*$E$7*$F23 -> 28350 | M23: 12 | N23: =M23*$I23*$E$7*$F23*$E$7 -> 29767.5 | O23: 12 | P23: =(O23*I23*$E$7*$E$7*$E$7)*F23 -> 31255.875 | Q23: 6 | R23: =Q23*$I23*$E$7*$F23*$E$7*$E$7*$E$7 -> 16409.334 | S23: =SUM(J23+L23+N23+P23+R23) -> 132782.71 | T23: 0 | U23: =SUM(S23:T23) -> 132782.71
D24: Total Personnel | J24: =SUM(J12:J23) -> 475499.97 | L24: =SUM(L12:L23) -> 580649.97 | N24: =SUM(N12:N23) -> 609682.47 | P24: =SUM(P12:P23) -> 640166.59 | R24: =SUM(R12:R23) -> 263157.09 | S24: =SUM(S12:S23) -> 2569156.1 | T24: =SUM(T12:T23) -> 0 | U24: =SUM(S24:T24) -> 2569156.1
D25: Fringe Benefits
A26: FRINGE-MX | B26: 70015 | C26: MEX | D26: Fringe Benefits - MX | E26: Fringe Benefits | G26: Month | I26: 0.415 | J26: =SUM(J12:J18)*$I26 -> 139647.5 | L26: =SUM(L12:L18)*$I26 -> 180400.5 | N26: =SUM(N12:N18)*$I26 -> 189420.52 | P26: =SUM(P12:P18)*$I26 -> 198891.55 | R26: =SUM(R12:R18)*$I26 -> 74151.959 | S26: =SUM(J26+L26+N26+P26+R26) -> 782512.04 | T26: 0 | U26: =SUM(S26:T26) -> 782512.04
A27: FRINGE | B27: 50900 | C27: USA | D27: Fringe Benefits - HO | E27: Fringe Benefits | G27: Month | I27: 0.2347 | J27: =SUM(J20:J23)*$I$27 -> 32623.293 | L27: =SUM(L20:L23)*$I$27 -> 34254.458 | N27: =SUM(N20:N23)*$I$27 -> 35967.181 | P27: =SUM(P20:P23)*$I$27 -> 37765.54 | R27: =SUM(R20:R23)*$I$27 -> 19826.909 | S27: =SUM(J27+L27+N27+P27+R27) -> 160437.38 | T27: 0 | U27: =SUM(S27:T27) -> 160437.38
D28: Total Fringe Benefits | J28: =SUM(J26:J27) -> 172270.79 | L28: =SUM(L26:L27) -> 214654.96 | N28: =SUM(N26:N27) -> 225387.71 | P28: =SUM(P26:P27) -> 236657.09 | R28: =SUM(R26:R27) -> 93978.867 | S28: =SUM(S26:S27) -> 942949.42 | T28: =SUM(T26:T27) -> 0 | U28: =SUM(U26:U27) -> 942949.42
D29: Travel
D30: T1: Post-award Meeting with ILAB
A31: MX.T1.A | B31: 86040 | C31: USA | D31: Airfare - Mexico City-DC | E31: Travel | F31: 1 | G31: Trip | H31: 2 | I31: 700 | J31: =H31*$I31*$F31 -> 1400 | K31: 0 | L31: =+K31*$I31*$F31*$E$6 -> 0 | M31: 0 | N31: =+M31*$I31*$F31*$E$6*$E$6 -> 0 | O31: 0 | P31: =+O31*$I31*$F31*$E$6*$E$6*$E$6 -> 0 | Q31: 0 | R31: =+Q31*$I31*$F31*$E$6*$E$6*$E$6*$E$6 -> 0 | S31: =SUM(J31+L31+N31+P31+R31) -> 1400 | T31: 0 | U31: =SUM(S31:T31) -> 1400
A32: MX.T1.B | B32: 86030 (Lodging)/ 86050 (M&IE) | C32: USA | D32: Lodging and M&IE in DC | E32: Travel | F32: 1 | G32: Day | H32: =5*2 -> 10 | I32: =(92*0.9)+183 -> 265.8 | J32: =H32*$I32*$F32 -> 2658 | K32: 0 | L32: =+K32*$I32*$F32*$E$6 -> 0 | M32: 0 | N32: =+M32*$I32*$F32*$E$6*$E$6 -> 0 | O32: 0 | P32: =+O32*$I32*$F32*$E$6*$E$6*$E$6 -> 0 | Q32: 0 | R32: =+Q32*$I32*$F32*$E$6*$E$6*$E$6*$E$6 -> 0 | S32: =SUM(J32+L32+N32+P32+R32) -> 2658 | T32: 0 | U32: =SUM(S32:T32) -> 2658
A33: MX.T1.C | B33: 86000 | C33: USA | D33: Local transportation in DC | E33: Travel | F33: 1 | G33: Day | H33: =5*2 -> 10 | I33: 50 | J33: =H33*$I33*$F33 -> 500 | K33: 0 | L33: =+K33*$I33*$F33*$E$6 -> 0 | M33: 0 | N33: =+M33*$I33*$F33*$E$6*$E$6 -> 0 | O33: 0 | P33: =+O33*$I33*$F33*$E$6*$E$6*$E$6 -> 0 | Q33: 0 | R33: =+Q33*$I33*$F33*$E$6*$E$6*$E$6*$E$6 -> 0 | S33: =SUM(J33+L33+N33+P33+R33) -> 500 | T33: 0 | U33: =SUM(S33:T33) -> 500
A34: MX.T1.D | B34: 86050 | C34: USA | D34: U.S. Visa Fees | E34: Travel | F34: 1 | G34: Person | H34: 2 | I34: 185 | J34: =H34*$I34*$F34 -> 370 | K34: 0 | L34: =+K34*$I34*$F34*$E$6 -> 0 | M34: 0 | N34: =+M34*$I34*$F34*$E$6*$E$6 -> 0 | O34: 0 | P34: =+O34*$I34*$F34*$E$6*$E$6*$E$6 -> 0 | Q34: 0 | R34: =+Q34*$I34*$F34*$E$6*$E$6*$E$6*$E$6 -> 0 | S34: =SUM(J34+L34+N34+P34+R34) -> 370 | T34: 0 | U34: =SUM(S34:T34) -> 370
D35: T2: Field Personnel Annual Visits with ILAB
A36: MX.T2.A | B36: 86040 | C36: MEX | D36: Airfare - Mexico City-DC | E36: Travel | F36: 1 | G36: Trip | H36: 0 | I36: 700 | J36: =H36*$I36*$F36 -> 0 | K36: 2 | L36: =+K36*$I36*$F36*$E$6 -> 1456 | M36: 2 | N36: =+M36*$I36*$F36*$E$6*$E$6 -> 1514.24 | O36: 2 | P36: =+O36*$I36*$F36*$E$6*$E$6*$E$6 -> 1574.8096 | Q36: 2 | R36: =+Q36*$I36*$F36*$E$6*$E$6*$E$6*$E$6 -> 1637.802 | S36: =SUM(J36+L36+N36+P36+R36) -> 6182.8516 | T36: 0 | U36: =SUM(S36:T36) -> 6182.8516
A37: MX.T2.B | B37: 86030 (Lodging)/ 86050 (M&IE) | C37: MEX | D37: Lodging and M&IE in DC | E37: Travel | F37: 1 | G37: Day | H37: 0 | I37: =(92*0.9)+183 -> 265.8 | J37: =H37*$I37*$F37 -> 0 | K37: =5*2 -> 10 | L37: =+K37*$I37*$F37*$E$6 -> 2764.32 | M37: =5*2 -> 10 | N37: =+M37*$I37*$F37*$E$6*$E$6 -> 2874.8928 | O37: =5*2 -> 10 | P37: =+O37*$I37*$F37*$E$6*$E$6*$E$6 -> 2989.8885 | Q37: =5*2 -> 10 | R37: =+Q37*$I37*$F37*$E$6*$E$6*$E$6*$E$6 -> 3109.4841 | S37: =SUM(J37+L37+N37+P37+R37) -> 11738.585 | T37: 0 | U37: =SUM(S37:T37) -> 11738.585
A38: MX.T2.C | B38: 86000 | C38: MEX | D38: Local transportation in DC | E38: Travel | F38: 1 | G38: Day | H38: 0 | I38: 50 | J38: =H38*$I38*$F38 -> 0 | K38: =5*2 -> 10 | L38: =+K38*$I38*$F38*$E$6 -> 520 | M38: =5*2 -> 10 | N38: =+M38*$I38*$F38*$E$6*$E$6 -> 540.8 | O38: =5*2 -> 10 | P38: =+O38*$I38*$F38*$E$6*$E$6*$E$6 -> 562.432 | Q38: =5*2 -> 10 | R38: =+Q38*$I38*$F38*$E$6*$E$6*$E$6*$E$6 -> 584.92928 | S38: =SUM(J38+L38+N38+P38+R38) -> 2208.1613 | T38: 0 | U38: =SUM(S38:T38) -> 2208.1613
D39: T3: Program Management Visits to Field
A40: MX.T3.A | B40: 86040 | C40: MEX | D40: Airfare - DC - Mexico City | E40: Travel | F40: 1 | G40: Trip | H40: 2 | I40: 700 | J40: =H40*$I40*$F40 -> 1400 | K40: 2 | L40: =+K40*$I40*$F40*$E$6 -> 1456 | M40: 2 | N40: =+M40*$I40*$F40*$E$6*$E$6 -> 1514.24 | O40: 2 | P40: =+O40*$I40*$F40*$E$6*$E$6*$E$6 -> 1574.8096 | Q40: 2 | R40: =+Q40*$I40*$F40*$E$6*$E$6*$E$6*$E$6 -> 1637.802 | S40: =SUM(J40+L40+N40+P40+R40) -> 7582.8516 | T40: 0 | U40: =SUM(S40:T40) -> 7582.8516
A41: MX.T3.B | B41: 86030 (Lodging)/ 86050 (M&IE) | C41: MEX | D41: Lodging and M&IE in Mexico City | E41: Travel | F41: 1 | G41: Day | H41: =5*2 -> 10 | I41: =+Travel!B19+Travel!B20 -> 231.31892 | J41: =H41*$I41*$F41 -> 2313.1892 | K41: =5*2 -> 10 | L41: =+K41*$I41*$F41*$E$6 -> 2405.7168 | M41: =5*2 -> 10 | N41: =+M41*$I41*$F41*$E$6*$E$6 -> 2501.9454 | O41: =5*2 -> 10 | P41: =+O41*$I41*$F41*$E$6*$E$6*$E$6 -> 2602.0232 | Q41: =5*2 -> 10 | R41: =+Q41*$I41*$F41*$E$6*$E$6*$E$6*$E$6 -> 2706.1042 | S41: =SUM(J41+L41+N41+P41+R41) -> 12528.979 | T41: 0 | U41: =SUM(S41:T41) -> 12528.979
...

Sheet M&E Budget
A1: M&E Budget
A2: Partners of the Americas
A3: Leveling the Field for American Workers in U.S.-Mexico Trade
A4: 54 Months
A5: Cost Assumptions
A6: Inflation - Goods/Services | B6: 1.04
A7: Merit Based Increases for HO & Field Staff | B7: 1.05
A9: BUDGET ITEM | B9: CATEGORY | C9: LOE | D9: UNIT | E9: # of Units | F9: RATE / UNIT | G9: Year 1 | H9: # of Units | I9: Year 2 | J9: # of Units | K9: Year 3 | L9: # of Units | M9: Year 4 | N9: # of Units | O9: Year 5 | P9: TOTAL DOL | Q9: TOTAL COST SHARING | R9: PROJECT GRAND TOTAL
A10: Partners of the Americas Monitoring, Evaluation, and Collection of Reliable Data
A11: Travel
A12: M&E - Collection of Reliable Data and Processing of Monitoring Data
A13: M&E - Airfare - Field verification and data collection visits | B13: M&E | C13: 1 | D13: Trip | E13: =+'POA General Budget'!H69 -> 32 | F13: =+'POA General Budget'!I69 -> 363.30878 | G13: =+'POA General Budget'!J69 -> 11625.881 | H13: =+'POA General Budget'!K69 -> 48 | I13: =+'POA General Budget'!L69 -> 18136.374 | J13: =+'POA General Budget'!M69 -> 40 | K13: =+'POA General Budget'!N69 -> 15718.191 | L13: =+'POA General Budget'!O69 -> 40 | ... R13: =+'POA General Budget'!U69 -> 61827.366
A14: M&E - Lodging and M&IE - Field verification and data collection visits | B14: M&E | C14: 1 | D14: Day | E14: =+'POA General Budget'!H70 -> 64 | F14: =+'POA General Budget'!I70 -> 153.03504 | G14: =+'POA General Budget'!J70 -> 9794.2425 | H14: =+'POA General Budget'!K70 -> 96 | I14: =+'POA General Budget'!L70 -> 15279.018 | J14: =+'POA General Budget'!M70 -> 80 | K14: =+'POA General Budget'!N70 -> 13241.816 | L14: =+'POA General Budget'!O70 -> 80 | ... R14: =+'POA General Budget'!U70 -> 52086.565
A15: M&E - Local transportation | B15: M&E | C15: 1 | D15: Day | E15: =+'POA General Budget'!H71 -> 64 | F15: =+'POA General Budget'!I71 -> 50 | G15: =+'POA General Budget'!J71 -> 3200 | H15: =+'POA General Budget'!K71 -> 96 | I15: =+'POA General Budget'!L71 -> 4992 | J15: =+'POA General Budget'!M71 -> 80 | K15: =+'POA General Budget'!N71 -> 4326.4 | L15: =+'POA General Budget'!O71 -> 80 | ... R15: =+'POA General Budget'!U71 -> 17017.856
A16: M&E - Data collection materials and printing | B16: M&E | C16: 1 | D16: Unit | E16: =+'POA General Budget'!H72 -> 32 | F16: =+'POA General Budget'!I72 -> 50 | G16: =+'POA General Budget'!J72 -> 1600 | H16: =+'POA General Budget'!K72 -> 48 | I16: =+'POA General Budget'!L72 -> 2496 | J16: =+'POA General Budget'!M72 -> 40 | K16: =+'POA General Budget'!N72 -> 2163.2 | L16: =+'POA General Budget'!O72 -> 40 | ... R16: =+'POA General Budget'!U72 -> 8508.928
A17: M&E - Stakeholder Engagement and Strategy Validation | E17: =+'POA General Budget'!H73 -> 0 | F17: =+'POA General Budget'!I73 -> 0 | G17: =+'POA General Budget'!J73 -> 0 | H17: =+'POA General Budget'!K73 -> 0 | I17: =+'POA General Budget'!L73 -> 0 | J17: =+'POA General Budget'!M73 -> 0 | K17: =+'POA General Budget'!N73 -> 0 | L17: =+'POA General Budget'!O73 -> 0 | ... R17: =+'POA General Budget'!U73 -> 0
A18: M&E - Airfare | B18: Travel | C18: 1 | D18: Trip | E18: =+'POA General Budget'!H74 -> 20 | F18: =+'POA General Budget'!I74 -> 363.30878 | G18: =+'POA General Budget'!J74 -> 7266.1757 | H18: =+'POA General Budget'!K74 -> 0 | I18: =+'POA General Budget'!L74 -> 0 | J18: =+'POA General Budget'!M74 -> 0 | K18: =+'POA General Budget'!N74 -> 0 | L18: =+'POA General Budget'!O74 -> 0 | ... R18: =+'POA General Budget'!U74 -> 7266.1757
A19: M&E - Lodging and M&IE - Field verification and data collection visits | B19: M&E | C19: 1 | D19: Day | E19: =+'POA General Budget'!H75 -> 40 | F19: =+'POA General Budget'!I75 -> 153.03504 | G19: =+'POA General Budget'!J75 -> 6121.4015 | H19: =+'POA General Budget'!K75 -> 0 | I19: =+'POA General Budget'!L75 -> 0 | J19: =+'POA General Budget'!M75 -> 0 | K19: =+'POA General Budget'!N75 -> 0 | L19: =+'POA General Budget'!O75 -> 0 | ... R19: =+'POA General Budget'!U75 -> 6121.4015
A20: M&E - Local transportation | B20: M&E | C20: 1 | D20: Day | E20: =+'POA General Budget'!H76 -> 40 | F20: =+'POA General Budget'!I76 -> 50 | G20: =+'POA General Budget'!J76 -> 2000 | H20: =+'POA General Budget'!K76 -> 0 | I20: =+'POA General Budget'!L76 -> 0 | J20: =+'POA General Budget'!M76 -> 0 | K20: =+'POA General Budget'!N76 -> 0 | L20: =+'POA General Budget'!O76 -> 0 | ... R20: =+'POA General Budget'!U76 -> 2000
A21: Contracts
A22: Interim Performance Evaluation | B22: M&E | C22: 1 | D22: Evaluation | E22: =+'POA General Budget'!H94 -> 0 | F22: =+'POA General Budget'!I94 -> 35000 | G22: =+'POA General Budget'!J94 -> 0 | H22: =+'POA General Budget'!K94 -> 0 | I22: =+'POA General Budget'!L94 -> 0 | J22: =+'POA General Budget'!M94 -> 1 | K22: =+'POA General Budget'!N94 -> 35000 | L22: =+'POA General Budget'!O94 -> 0 | ... R22: =+'POA General Budget'!U94 -> 35000
A23: Final Performance Evaluation | B23: M&E | C23: 1 | D23: Evaluation | E23: =+'POA General Budget'!H95 -> 0 | F23: =+'POA General Budget'!I95 -> 35000 | G23: =+'POA General Budget'!J95 -> 0 | H23: =+'POA General Budget'!K95 -> 0 | I23: =+'POA General Budget'!L95 -> 0 | J23: =+'POA General Budget'!M95 -> 0 | K23: =+'POA General Budget'!N95 -> 0 | L23: =+'POA General Budget'!O95 -> 0 | ... R23: =+'POA General Budget'!U95 -> 35000
A24: Other Direct Costs
A25: Monitoring, Evaluation, and Collection of Reliable Data
A26: 4.1 On-going M&E Training
A27: On-going M&E training workshops | B27: M&E | C27: 1 | D27: Workshop | E27: =+'POA General Budget'!H147 -> 2 | F27: =+'POA General Budget'!I147 -> 240 | G27: =+'POA General Budget'!J147 -> 480 | H27: =+'POA General Budget'!K147 -> 8 | I27: =+'POA General Budget'!L147 -> 1996.8 | J27: =+'POA General Budget'!M147 -> 8 | K27: =+'POA General Budget'!N147 -> 2076.672 | L27: =+'POA General Budget'!O147 -> 8 | ... R27: =+'POA General Budget'!U147 -> 6713.2109
A28: 4.2 Development of Performance Monitoring Plan (PMP)
A29: Document translation | B29: M&E | C29: 1 | D29: Document | E29: =+'POA General Budget'!H149 -> 1 | F29: =+'POA General Budget'!I149 -> 3500 | G29: =+'POA General Budget'!J149 -> 3500 | H29: =+'POA General Budget'!K149 -> 0 | I29: =+'POA General Budget'!L149 -> 0 | J29: =+'POA General Budget'!M149 -> 0 | K29: =+'POA General Budget'!N149 -> 0 | L29: =+'POA General Budget'!O149 -> 0 | ... R29: =+'POA General Budget'!U149 -> 3500
A30: 4.3 Stakeholder Engagement and Strategy Validation
A31: Workshops with Stakeholders to validate project strategies | B31: M&E | C31: 1 | D31: Workshop | E31: =+'POA General Budget'!H151 -> 30 | F31: =+'POA General Budget'!I151 -> 1360 | G31: =+'POA General Budget'!J151 -> 40800 | H31: =+'POA General Budget'!K151 -> 0 | I31: =+'POA General Budget'!L151 -> 0 | J31: =+'POA General Budget'!M151 -> 0 | K31: =+'POA General Budget'!N151 -> 0 | L31: =+'POA General Budget'!O151 -> 0 | ... R31: =+'POA General Budget'!U151 -> 40800
A32: Printing materials | B32: M&E | C32: 1 | D32: Unit | E32: =+'POA General Budget'!H152 -> 40 | F32: =+'POA General Budget'!I152 -> 50 | G32: =+'POA General Budget'!J152 -> 2000 | H32: =+'POA General Budget'!K152 -> 0 | I32: =+'POA General Budget'!L152 -> 0 | J32: =+'POA General Budget'!M152 -> 0 | K32: =+'POA General Budget'!N152 -> 0 | L32: =+'POA General Budget'!O152 -> 0 | ... R32: =+'POA General Budget'!U152 -> 2000
A33: 4.4 Consultants
A34: M&E - Consultant fees for Database development | B34: M&E | C34: 1 | D34: Hour | E34: =+'POA General Budget'!H154 -> 360 | F34: =+'POA General Budget'!I154 -> 25 | G34: =+'POA General Budget'!J154 -> 9000 | H34: =+'POA General Budget'!K154 -> 480 | I34: =+'POA General Budget'!L154 -> 12480 | J34: =+'POA General Budget'!M154 -> 480 | K34: =+'POA General Budget'!N154 -> 12979.2 | L34: =+'POA General Budget'!O154 -> 480 | ... R34: =+'POA General Budget'!U154 -> 47957.568
A35: M&E - Consultant fees to draft written PMP | B35: M&E | C35: 1 | D35: Hour | E35: =+'POA General Budget'!H155 -> 180 | F35: =+'POA General Budget'!I155 -> 25 | G35: =+'POA General Budget'!J155 -> 4500 | H35: =+'POA General Budget'!K155 -> 0 | I35: =+'POA General Budget'!L155 -> 0 | J35: =+'POA General Budget'!M155 -> 0 | K35: =+'POA General Budget'!N155 -> 0 | L35: =+'POA General Budget'!O155 -> 0 | ... R35: =+'POA General Budget'!U155 -> 4500
A36: Subtotal Partners of the Americas Monitoring, Evaluation, and Collection of Reliable Data | G36: =SUM(G12:G35) -> 101887.7 | I36: =SUM(I12:I35) -> 55380.193 | K36: =SUM(K12:K35) -> 85505.479 | M36: =SUM(M12:M35) -> 52525.698 | O36: =SUM(O12:O35) -> 35000 | P36: =SUM(P12:P35) -> 330299.07 | Q36: =SUM(Q12:Q35) -> 0 | R36: =SUM(R12:R35) -> 330299.07
A37: FES Monitoring, Evaluation, and Collection of Reliable Data
A38: Travel
A39: M&E - Airfare - Field Verification & Data Collection Expenses | B39: Travel | C39: 1 | D39: Trip | E39: =+'FES Sub Budget'!E24 -> 0 | F39: =+'FES Sub Budget'!F24 -> 363.30878 | G39: =+'FES Sub Budget'!G24 -> 0 | H39: =+'FES Sub Budget'!H24 -> 14 | I39: =+'FES Sub Budget'!I24 -> 5086.323 | J39: =+'FES Sub Budget'!J24 -> 14 | K39: =+'FES Sub Budget'!K24 -> 5289.7759 | L39: =+'FES Sub Budget'!L24 -> 7 | ... R39: =+'FES Sub Budget'!R24 -> 13126.782
A40: M&E - Lodging and M&IE - Field Verification & Data Collection Expenses | B40: Travel | C40: 1 | D40: Day | E40: =+'FES Sub Budget'!E25 -> 0 | F40: =+'FES Sub Budget'!F25 -> 153.03504 | G40: =+'FES Sub Budget'!G25 -> 0 | H40: =+'FES Sub Budget'!H25 -> 14 | I40: =+'FES Sub Budget'!I25 -> 2142.4905 | J40: =+'FES Sub Budget'!J25 -> 14 | K40: =+'FES Sub Budget'!K25 -> 2228.1902 | L40: =+'FES Sub Budget'!L25 -> 7 | ... R40: =+'FES Sub Budget'!R25 -> 5529.3396
A41: M&E - Transportation - Field Verification & Data Collection Expenses | B41: Travel | C41: 1 | D41: Day | E41: =+'FES Sub Budget'!E26 -> 0 | F41: =+'FES Sub Budget'!F26 -> 50 | G41: =+'FES Sub Budget'!G26 -> 0 | H41: =+'FES Sub Budget'!H26 -> 14 | I41: =+'FES Sub Budget'!I26 -> 700 | J41: =+'FES Sub Budget'!J26 -> 14 | K41: =+'FES Sub Budget'!K26 -> 728 | L41: =+'FES Sub Budget'!L26 -> 7 | ... R41: =+'FES Sub Budget'!R26 -> 1806.56
...

Sheet ITAM Sub Budget Summary
A3: Project Budget Summary
A4: Partners of the Americas
A5: Instituto Tecnológico Autónomo de México (ITAM) Sub-Recipient / Sub-receptor Instituto Tecnológico Autónomo de México (ITAM) (UEI: DP38M16THBJ6)
A6: 42 Months
A8: BUDGET SUMMARY CATEGORIES | B8: YEAR 1 | C8: YEAR 2 | D8: YEAR 3 | E8: YEAR 4 | F8: YEAR 5 | G8: TOTAL FEDERAL FUNDS REQUESTED
A10: 1. PERSONNEL | B10: =+'ITAM Sub Budget'!G14 -> 51600 | C10: =+'ITAM Sub Budget'!I14 -> 108360 | D10: =+'ITAM Sub Budget'!K14 -> 113778 | E10: =+'ITAM Sub Budget'!M14 -> 119466.9 | F10: =+'ITAM Sub Budget'!O14 -> 0 | G10: =SUM(B10:F10) -> 393204.9
A11: 2. FRINGE BENEFITS | B11: =+'ITAM Sub Budget'!G17 -> 14504.28 | C11: =+'ITAM Sub Budget'!I17 -> 30458.988 | D11: =+'ITAM Sub Budget'!K17 -> 31981.937 | E11: =+'ITAM Sub Budget'!M17 -> 33581.034 | F11: =+'ITAM Sub Budget'!O17 -> 0 | G11: =SUM(B11:F11) -> 110526.24
A12: 3. TRAVEL | B12: =+'ITAM Sub Budget'!G61 -> 4088 | C12: =+'ITAM Sub Budget'!I61 -> 8503.04 | D12: =+'ITAM Sub Budget'!K61 -> 8843.1616 | E12: =+'ITAM Sub Budget'!M61 -> 9196.8881 | F12: =+'ITAM Sub Budget'!O61 -> 0 | G12: =SUM(B12:F12) -> 30631.09
A13: 4. EQUIPMENT | B13: =+'ITAM Sub Budget'!G64 -> 0 | C13: =+'ITAM Sub Budget'!I64 -> 0 | D13: =+'ITAM Sub Budget'!K64 -> 0 | E13: =+'ITAM Sub Budget'!M64 -> 0 | F13: =+'ITAM Sub Budget'!O64 -> 0 | G13: =SUM(B13:F13) -> 0
A14: 5. SUPPLIES | B14: =+'ITAM Sub Budget'!G67 -> 0 | C14: =+'ITAM Sub Budget'!I67 -> 0 | D14: =+'ITAM Sub Budget'!K67 -> 0 | E14: =+'ITAM Sub Budget'!M67 -> 0 | F14: =+'ITAM Sub Budget'!O67 -> 0 | G14: =SUM(B14:F14) -> 0
A15: 6. CONTRACTUAL | B15: =+'ITAM Sub Budget'!G93 -> 131694.3 | C15: =+'ITAM Sub Budget'!I93 -> 680597.63 | D15: =+'ITAM Sub Budget'!K93 -> 592752.71 | E15: =+'ITAM Sub Budget'!M93 -> 378112.91 | F15: =+'ITAM Sub Budget'!O93 -> 0 | G15: =SUM(B15:F15) -> 1783157.6
A16: 7. CONSTRUCTION | B16: =+'ITAM Sub Budget'!G96 -> 0 | C16: =+'ITAM Sub Budget'!I96 -> 0 | D16: =+'ITAM Sub Budget'!K96 -> 0 | E16: =+'ITAM Sub Budget'!M96 -> 0 | F16: =+'ITAM Sub Budget'!O96 -> 0 | G16: =SUM(B16:F16) -> 0
A17: 8. OTHER DIRECT COSTS | B17: =+'ITAM Sub Budget'!G106 -> 11400 | C17: =+'ITAM Sub Budget'!I106 -> 23712 | D17: =+'ITAM Sub Budget'!K106 -> 24660.48 | E17: =+'ITAM Sub Budget'!M106 -> 12823.45 | F17: =+'ITAM Sub Budget'!O106 -> 0 | G17: =SUM(B17:F17) -> 72595.93
A19: 9. TOTAL DIRECT COSTS (Lines 1-8) | B19: =SUM(B10:B17) -> 213286.58 | C19: =SUM(C10:C17) -> 851631.66 | D19: =SUM(D10:D17) -> 772016.29 | E19: =SUM(E10:E17) -> 553181.18 | F19: =SUM(F10:F17) -> 0 | G19: =SUM(G10:G17) -> 2390115.7
A20: 10. DE MINIMIS RATE | B20: =+B19*0.1 -> 21328.658 | C20: =+C19*0.1 -> 85163.166 | D20: =+D19*0.1 -> 77201.629 | E20: =+E19*0.1 -> 55318.118 | F20: =+F19*0.1 -> 0 | G20: =SUM(B20:F20) -> 239011.57
A21: 11. TOTAL COSTS (Lines 9-10) | B21: =SUM(B19:B20) -> 234615.24 | C21: =SUM(C19:C20) -> 936794.83 | D21: =SUM(D19:D20) -> 849217.92 | E21: =SUM(E19:E20) -> 608499.3 | F21: =SUM(F19:F20) -> 0 | G21: =SUM(G19:G20) -> 2629127.3

Sheet ITAM Sub Budget
A1: Project Line-Item Budget
A2: Instituto Tecnológico Autónomo de México (ITAM) Sub-Recipient / Sub-receptor Instituto Tecnológico Autónomo de México (ITAM) (UEI: DP38M16THBJ6)
A3: 42 Months
A4: Cost Assumptions
A5: Inflation - Goods/Services | B5: 1.04
A6: Merit Based Increases for HO & Field Staff | B6: 1.05
A8: BUDGET ITEM | B8: CATEGORY | C8: LOE | D8: UNIT | E8: # of Units | F8: RATE / UNIT | G8: Year 1 | H8: # of Units | I8: Year 2 | J8: # of Units | K8: Year 3 | L8: # of Units | M8: Year 4 | N8: # of Units | O8: Year 5 | P8: TOTAL US$ | Q8: TOTAL COST SHARING | R8: PROJECT GRAND TOTAL
A9: Personnel
A10: Professional Personnel
A11: Technical Director | B11: Salaries | C11: 0.2 | D11: Month | E11: 6 | F11: 12000 | G11: =F11*$E11*$C11 -> 14400 | H11: 12 | I11: =H11*$F11*$C11*$B$6 -> 30240 | J11: 12 | K11: =J11*$F11*$C11*$B$6*$B$6 -> 31752 | L11: 12 | M11: =L11*$F11*$C11*$B$6*$B$6*$B$6 -> 33339.6 | O11: =N11*$F11*$B$6*$B$6*$B$6*$B$6*20% -> 0 | P11: =SUM(G11,I11,K11,M11,O11) -> 109731.6 | Q11: 0 | R11: =SUM(P11:Q11) -> 109731.6
A12: Project Manager | B12: Salaries | C12: 1 | D12: Month | E12: 6 | F12: 2900 | G12: =F12*$E12*C12 -> 17400 | H12: 12 | I12: =H12*$F12*$C12*$B$6 -> 36540 | J12: 12 | K12: =J12*$F12*$C12*$B$6*$B$6 -> 38367 | L12: 12 | M12: =L12*$F12*$C12*$B$6*$B$6*$B$6 -> 40285.35 | O12: =N12*$F12*$C12*$B$6*$B$6*$B$6*$B$6 -> 0 | P12: =SUM(G12,I12,K12,M12,O12) -> 132592.35 | Q12: 0 | R12: =SUM(P12:Q12) -> 132592.35
A13: Product Manager | B13: Salaries | C13: 1 | D13: Month | E13: 6 | F13: 3300 | G13: =F13*$E13*C13 -> 19800 | H13: 12 | I13: =H13*$F13*$C13*$B$6 -> 41580 | J13: 12 | K13: =J13*$F13*$C13*$B$6*$B$6 -> 43659 | L13: 12 | M13: =L13*$F13*$C13*$B$6*$B$6*$B$6 -> 45841.95 | O13: =N13*$F13*$C13*$B$6*$B$6*$B$6*$B$6 -> 0 | P13: =SUM(G13,I13,K13,M13,O13) -> 150880.95 | Q13: 0 | R13: =SUM(P13:Q13) -> 150880.95
A14: Total Personnel | G14: =SUM(G11:G13) -> 51600 | I14: =SUM(I11:I13) -> 108360 | K14: =SUM(K11:K13) -> 113778 | M14: =SUM(M11:M13) -> 119466.9 | O14: =SUM(O11:O13) -> 0 | P14: =SUM(P11:P13) -> 393204.9 | Q14: =SUM(Q11:Q13) -> 0 | R14: =SUM(R11:R13) -> 393204.9
A15: Fringe Benefits
A16: Fringe Benefits - Mexico | B16: Fringe Benefits | D16: Month | F16: 0.3899 | G16: =SUM(G12:G13)*F16 -> 14504.28 | H16: =+F16 -> 0.3899 | I16: =SUM(I12:I13)*H16 -> 30458.988 | J16: =+H16 -> 0.3899 | K16: =SUM(K12:K13)*J16 -> 31981.937 | L16: =+J16 -> 0.3899 | M16: =SUM(M12:M13)*L16 -> 33581.034 | N16: =+L16 -> 0.3899 | O16: =SUM(O11:O13)*N16 -> 0 | P16: =SUM(G16,I16,K16,M16,O16) -> 110526.24 | Q16: 0 | R16: =SUM(P16:Q16) -> 110526.24
A17: Total Fringe Benefits | G17: =SUM(G16:G16) -> 14504.28 | I17: =SUM(I16:I16) -> 30458.988 | K17: =SUM(K16:K16) -> 31981.937 | M17: =SUM(M16:M16) -> 33581.034 | O17: =SUM(O16:O16) -> 0 | P17: =SUM(P16:P16) -> 110526.24 | Q17: =SUM(Q16:Q16) -> 0 | R17: =SUM(R16:R16) -> 110526.24
A18: Travel
A19: Country travel
A20: Travel Expenses Baja California (Mexicali)
A21: Lodging | B21: Travel | C21: 1 | D21: Night | E21: 2 | F21: 182 | G21: =F21*$E21*C21 -> 364 | H21: =2*2 -> 4 | I21: =H21*$F21*$C21*$B$5 -> 757.12 | K21: =J21*$F21*$C21*$B$5*$B$5 -> 0 | M21: =L21*$F21*$C21*$B$5*$B$5*$B$5 -> 0 | N21: 0 | O21: =N21*$F21*$C21*$B$5*$B$5*$B$5*$B$5 -> 0 | P21: =SUM(G21,I21,K21,M21,O21) -> 1121.12 | Q21: 0 | R21: =SUM(P21:Q21) -> 1121.12
A22: Per Diem | B22: Travel | C22: 1 | D22: Day | E22: 2 | F22: 116 | G22: =F22*$E22*C22 -> 232 | H22: =2*2 -> 4 | I22: =H22*$F22*$C22*$B$5 -> 482.56 | K22: =J22*$F22*$C22*$B$5*$B$5 -> 0 | M22: =L22*$F22*$C22*$B$5*$B$5*$B$5 -> 0 | O22: =N22*$F22*$C22*$B$5*$B$5*$B$5*$B$5 -> 0 | P22: =SUM(G22,I22,K22,M22,O22) -> 714.56 | Q22: 0 | R22: =SUM(P22:Q22) -> 714.56
A23: Local Transportation | B23: Travel | C23: 1 | D23: Day | E23: 1 | F23: 50 | G23: =F23*$E23*C23 -> 50 | H23: =2*1 -> 2 | I23: =H23*$F23*$C23*$B$5 -> 104 | K23: =J23*$F23*$C23*$B$5*$B$5 -> 0 | M23: =L23*$F23*$C23*$B$5*$B$5*$B$5 -> 0 | N23: 0 | O23: =N23*$F23*$C23*$B$5*$B$5*$B$5*$B$5 -> 0 | P23: =SUM(G23,I23,K23,M23,O23) -> 154 | Q23: 0 | R23: =SUM(P23:Q23) -> 154
A24: Airfare | B24: Travel | C24: 1 | D24: Trip | E24: 1 | F24: 500 | G24: =F24*$E24*C24 -> 500 | H24: =1*2 -> 2 | I24: =H24*$F24*$C24*$B$5 -> 1040 | K24: =J24*$F24*$C24*$B$5*$B$5 -> 0 | M24: =L24*$F24*$C24*$B$5*$B$5*$B$5 -> 0 | N24: 0 | O24: =N24*$F24*$C24*$B$5*$B$5*$B$5*$B$5 -> 0 | P24: =SUM(G24,I24,K24,M24,O24) -> 1540 | Q24: 0 | R24: =SUM(P24:Q24) -> 1540
A25: Travel Expenses Jalisco (Guadalajara)
A26: Lodging | B26: Travel | C26: 1 | D26: Night | E26: 2 | F26: 241 | G26: =F26*$E26*C26 -> 482 | H26: =2*2 -> 4 | I26: =H26*$F26*$C26*$B$5 -> 1002.56 | K26: =J26*$F26*$C26*$B$5*$B$5 -> 0 | M26: =L26*$F26*$C26*$B$5*$B$5*$B$5 -> 0 | N26: 0 | O26: =N26*$F26*$C26*$B$5*$B$5*$B$5*$B$5 -> 0 | P26: =SUM(G26,I26,K26,M26,O26) -> 1484.56 | Q26: 0 | R26: =SUM(P26:Q26) -> 1484.56
A27: Per Diem | B27: Travel | C27: 1 | D27: Day | E27: 2 | F27: 121 | G27: =F27*$E27*C27 -> 242 | H27: =2*2 -> 4 | I27: =H27*$F27*$C27*$B$5 -> 503.36 | K27: =J27*$F27*$C27*$B$5*$B$5 -> 0 | M27: =L27*$F27*$C27*$B$5*$B$5*$B$5 -> 0 | O27: =N27*$F27*$C27*$B$5*$B$5*$B$5*$B$5 -> 0 | P27: =SUM(G27,I27,K27,M27,O27) -> 745.36 | Q27: 0 | R27: =SUM(P27:Q27) -> 745.36
A28: Local Transportation | B28: Travel | C28: 1 | D28: Day | E28: 1 | F28: 50 | G28: =F28*$E28*C28 -> 50 | H28: =2*1 -> 2 | I28: =H28*$F28*$C28*$B$5 -> 104 | K28: =J28*$F28*$C28*$B$5*$B$5 -> 0 | M28: =L28*$F28*$C28*$B$5*$B$5*$B$5 -> 0 | N28: 0 | O28: =N28*$F28*$C28*$B$5*$B$5*$B$5*$B$5 -> 0 | P28: =SUM(G28,I28,K28,M28,O28) -> 154 | Q28: 0 | R28: =SUM(P28:Q28) -> 154
A29: Airfare | B29: Travel | C29: 1 | D29: Trip | E29: 1 | F29: 300 | G29: =F29*$E29*C29 -> 300 | H29: =1*2 -> 2 | I29: =H29*$F29*$C29*$B$5 -> 624 | K29: =J29*$F29*$C29*$B$5*$B$5 -> 0 | M29: =L29*$F29*$C29*$B$5*$B$5*$B$5 -> 0 | N29: 0 | O29: =N29*$F29*$C29*$B$5*$B$5*$B$5*$B$5 -> 0 | P29: =SUM(G29,I29,K29,M29,O29) -> 924 | Q29: 0 | R29: =SUM(P29:Q29) -> 924
A30: Travel Expenses Guanajuato (Other)
A31: Lodging | B31: Travel | C31: 1 | D31: Night | E31: 2 | F31: 141 | G31: =F31*$E31*C31 -> 282 | H31: =2*2 -> 4 | I31: =H31*$F31*$C31*$B$5 -> 586.56 | K31: =J31*$F31*$C31*$B$5*$B$5 -> 0 | M31: =L31*$F31*$C31*$B$5*$B$5*$B$5 -> 0 | N31: 0 | O31: =N31*$F31*$C31*$B$5*$B$5*$B$5*$B$5 -> 0 | P31: =SUM(G31,I31,K31,M31,O31) -> 868.56 | Q31: 0 | R31: =SUM(P31:Q31) -> 868.56
A32: Per Diem | B32: Travel | C32: 1 | D32: Day | E32: 2 | F32: 110 | G32: =F32*$E32*C32 -> 220 | H32: =2*2 -> 4 | I32: =H32*$F32*$C32*$B$5 -> 457.6 | K32: =J32*$F32*$C32*$B$5*$B$5 -> 0 | M32: =L32*$F32*$C32*$B$5*$B$5*$B$5 -> 0 | O32: =N32*$F32*$C32*$B$5*$B$5*$B$5*$B$5 -> 0 | P32: =SUM(G32,I32,K32,M32,O32) -> 677.6 | Q32: 0 | R32: =SUM(P32:Q32) -> 677.6
A33: Local Transportation | B33: Travel | C33: 1 | D33: Day | E33: 1 | F33: 50 | G33: =F33*$E33*C33 -> 50 | H33: =2*1 -> 2 | I33: =H33*$F33*$C33*$B$5 -> 104 | K33: =J33*$F33*$C33*$B$5*$B$5 -> 0 | M33: =L33*$F33*$C33*$B$5*$B$5*$B$5 -> 0 | N33: 0 | O33: =N33*$F33*$C33*$B$5*$B$5*$B$5*$B$5 -> 0 | P33: =SUM(G33,I33,K33,M33,O33) -> 154 | Q33: 0 | R33: =SUM(P33:Q33) -> 154
A34: Airfare | B34: Travel | C34: 1 | D34: Trip | E34: 1 | F34: 450 | G34: =F34*$E34*C34 -> 450 | H34: =1*2 -> 2 | I34: =H34*$F34*$C34*$B$5 -> 936 | K34: =J34*$F34*$C34*$B$5*$B$5 -> 0 | M34: =L34*$F34*$C34*$B$5*$B$5*$B$5 -> 0 | N34: 0 | O34: =N34*$F34*$C34*$B$5*$B$5*$B$5*$B$5 -> 0 | P34: =SUM(G34,I34,K34,M34,O34) -> 1386 | Q34: 0 | R34: =SUM(P34:Q34) -> 1386
A35: Travel Expenses Querétaro
A36: Lodging | B36: Travel | C36: 1 | D36: Night | E36: 2 | F36: 210 | G36: =F36*$E36*C36 -> 420 | H36: =2*2 -> 4 | I36: =H36*$F36*$C36*$B$5 -> 873.6 | K36: =J36*$F36*$C36*$B$5*$B$5 -> 0 | M36: =L36*$F36*$C36*$B$5*$B$5*$B$5 -> 0 | N36: 0 | O36: =N36*$F36*$C36*$B$5*$B$5*$B$5*$B$5 -> 0 | P36: =SUM(G36,I36,K36,M36,O36) -> 1293.6 | Q36: 0 | R36: =SUM(P36:Q36) -> 1293.6
A37: Per Diem | B37: Travel | C37: 1 | D37: Day | E37: 2 | F37: 123 | G37: =F37*$E37*C37 -> 246 | H37: =2*2 -> 4 | I37: =H37*$F37*$C37*$B$5 -> 511.68 | K37: =J37*$F37*$C37*$B$5*$B$5 -> 0 | M37: =L37*$F37*$C37*$B$5*$B$5*$B$5 -> 0 | O37: =N37*$F37*$C37*$B$5*$B$5*$B$5*$B$5 -> 0 | P37: =SUM(G37,I37,K37,M37,O37) -> 757.68 | Q37: 0 | R37: =SUM(P37:Q37) -> 757.68
A38: Local Transportation | B38: Travel | C38: 1 | D38: Day | E38: 1 | F38: 50 | G38: =F38*$E38*C38 -> 50 | H38: =2*1 -> 2 | I38: =H38*$F38*$C38*$B$5 -> 104 | K38: =J38*$F38*$C38*$B$5*$B$5 -> 0 | M38: =L38*$F38*$C38*$B$5*$B$5*$B$5 -> 0 | N38: 0 | O38: =N38*$F38*$C38*$B$5*$B$5*$B$5*$B$5 -> 0 | P38: =SUM(G38,I38,K38,M38,O38) -> 154 | Q38: 0 | R38: =SUM(P38:Q38) -> 154
A39: Airfare | B39: Travel | C39: 1 | D39: Trip | E39: 1 | F39: 150 | G39: =F39*$E39*C39 -> 150 | H39: =1*2 -> 2 | I39: =H39*$F39*$C39*$B$5 -> 312 | K39: =J39*$F39*$C39*$B$5*$B$5 -> 0 | M39: =L39*$F39*$C39*$B$5*$B$5*$B$5 -> 0 | N39: 0 | O39: =N39*$F39*$C39*$B$5*$B$5*$B$5*$B$5 -> 0 | P39: =SUM(G39,I39,K39,M39,O39) -> 462 | Q39: 0 | R39: =SUM(P39:Q39) -> 462
A40: Monitoring, Evaluation, and Collection of Reliable Data
A41: Travel Expenses for M&E Baja California (Mexicali)
...

Sheet FES Sub Budget Summary
A3: Project Budget Summary
A4: Partners of the Americas
A5: Friedrich-Ebert-Stiftung (FES) Sub-Recipient / Sub-receptor Friedrich-Ebert-Stiftung (FES)
A6: 37 Months
A8: BUDGET SUMMARY CATEGORIES | B8: YEAR 1 | C8: YEAR 2 | D8: YEAR 3 | E8: YEAR 4 | F8: YEAR 5 | G8: TOTAL FEDERAL FUNDS REQUESTED
A10: 1. PERSONNEL | B10: =+'FES Sub Budget'!G14 -> 31380 | C10: =+'FES Sub Budget'!I14 -> 91476 | D10: =+'FES Sub Budget'!K14 -> 96049.8 | E10: =+'FES Sub Budget'!M14 -> 54130.545 | F10: =+'FES Sub Budget'!O14 -> 0 | G10: =SUM(B10:F10) -> 273036.34
A11: 2. FRINGE BENEFITS | B11: =+'FES Sub Budget'!G17 -> 12235.062 | C11: =+'FES Sub Budget'!I17 -> 35666.492 | D11: =+'FES Sub Budget'!K17 -> 37449.817 | E11: =+'FES Sub Budget'!M17 -> 21105.499 | F11: =+'FES Sub Budget'!O17 -> 0 | G11: =SUM(B11:F11) -> 106456.87
A12: 3. TRAVEL | B12: =+'FES Sub Budget'!G27 -> 0 | C12: =+'FES Sub Budget'!I27 -> 23316.391 | D12: =+'FES Sub Budget'!K27 -> 24249.046 | E12: =+'FES Sub Budget'!M27 -> 10945.184 | F12: =+'FES Sub Budget'!O27 -> 0 | G12: =SUM(B12:F12) -> 58510.621
A13: 4. EQUIPMENT | B13: =+'FES Sub Budget'!G30 -> 0 | C13: =+'FES Sub Budget'!I30 -> 0 | D13: =+'FES Sub Budget'!K30 -> 0 | E13: =+'FES Sub Budget'!M30 -> 0 | F13: =+'FES Sub Budget'!O30 -> 0 | G13: =SUM(B13:F13) -> 0
A14: 5. SUPPLIES | B14: =+'FES Sub Budget'!G34 -> 4200 | C14: =+'FES Sub Budget'!I34 -> 1872 | D14: =+'FES Sub Budget'!K34 -> 1946.88 | E14: =+'FES Sub Budget'!M34 -> 1181.1072 | F14: =+'FES Sub Budget'!O34 -> 0 | G14: =SUM(B14:F14) -> 9199.9872
A15: 6. CONTRACTUAL | B15: =+'FES Sub Budget'!G38 -> 0 | C15: =+'FES Sub Budget'!I38 -> 39000 | D15: =+'FES Sub Budget'!K38 -> 43680 | E15: =+'FES Sub Budget'!M38 -> 25958.4 | F15: =+'FES Sub Budget'!O38 -> 0 | G15: =SUM(B15:F15) -> 108638.4
A16: 7. CONSTRUCTION | B16: =+'FES Sub Budget'!G41 -> 0 | C16: =+'FES Sub Budget'!I41 -> 0 | D16: =+'FES Sub Budget'!K41 -> 0 | E16: =+'FES Sub Budget'!M41 -> 0 | F16: =+'FES Sub Budget'!O41 -> 0 | G16: =SUM(B16:F16) -> 0
A17: 8. OTHER DIRECT COSTS | B17: =+'FES Sub Budget'!G61 -> 1500 | C17: =+'FES Sub Budget'!I61 -> 23270 | D17: =+'FES Sub Budget'!K61 -> 47256.8 | E17: =+'FES Sub Budget'!M61 -> 67323.872 | F17: =+'FES Sub Budget'!O61 -> 0 | G17: =SUM(B17:F17) -> 139350.67
A19: 9. TOTAL DIRECT COSTS (Lines 1-8) | B19: =SUM(B10:B17) -> 49315.062 | C19: =SUM(C10:C17) -> 214600.88 | D19: =SUM(D10:D17) -> 250632.34 | E19: =SUM(E10:E17) -> 180644.61 | F19: =SUM(F10:F17) -> 0 | G19: =SUM(G10:G17) -> 695192.9
A20: 10. DE MINIMIS RATE | B20: =+B19*0.15 -> 7397.2593 | C20: =+C19*0.15 -> 32190.132 | D20: =+D19*0.15 -> 37594.852 | E20: =+E19*0.15 -> 27096.691 | F20: =+F19*0.15 -> 0 | G20: =SUM(B20:F20) -> 104278.93
A21: 11. TOTAL COSTS (Lines 9-10) | B21: =SUM(B19:B20) -> 56712.321 | C21: =SUM(C19:C20) -> 246791.02 | D21: =SUM(D19:D20) -> 288227.19 | E21: =SUM(E19:E20) -> 207741.3 | F21: =SUM(F19:F20) -> 0 | G21: =SUM(G19:G20) -> 799471.83

Sheet FES Sub Budget
A1: Project Line-Item Budget
A2: Friedrich-Ebert-Stiftung (FES) Sub-Recipient / Sub-receptor Friedrich-Ebert-Stiftung (FES)
A3: 37 Months
A4: Cost Assumptions
A5: Inflation - Goods/Services | B5: 1.04
A6: Merit Based Increases for HO & Field Staff | B6: 1.05
A8: BUDGET ITEM | B8: CATEGORY | C8: LOE | D8: UNIT | E8: # of Units | F8: RATE / UNIT | G8: Year 1 | H8: # of Units | I8: Year 2 | J8: # of Units | K8: Year 3 | L8: # of Units | M8: Year 4 | N8: # of Units | O8: Year 5 | P8: TOTAL US$ | Q8: TOTAL COST SHARING | R8: PROJECT GRAND TOTAL
A9: Personnel
A10: Professional Personnel
A11: Project Coordinator | B11: Salaries | C11: 1 | D11: Month | E11: 6 | F11: 3200 | G11: =F11*$E11*$C11 -> 19200 | H11: 12 | I11: =H11*$F11*$C11*$B$6 -> 40320 | J11: 12 | K11: =J11*$F11*$C11*$B$6*$B$6 -> 42336 | L11: 7 | M11: =L11*$F11*$C11*$B$6*$B$6*$B$6 -> 25930.8 | O11: =N11*$F11*$C11*$B$6*$B$6*$B$6*$B$6 -> 0 | P11: =SUM(G11,I11,K11,M11,O11) -> 127786.8 | Q11: 0 | R11: =SUM(P11:Q11) -> 127786.8
A12: Project Specialist and M&E | B12: Salaries | C12: 1 | D12: Month | E12: 3 | F12: 2400 | G12: =F12*$E12*C12 -> 7200 | H12: 12 | I12: =H12*$F12*$C12*$B$6 -> 30240 | J12: 12 | K12: =J12*$F12*$C12*$B$6*$B$6 -> 31752 | L12: 6 | M12: =L12*$F12*$C12*$B$6*$B$6*$B$6 -> 16669.8 | O12: =N12*$F12*$C12*$B$6*$B$6*$B$6*$B$6 -> 0 | P12: =SUM(G12,I12,K12,M12,O12) -> 85861.8 | Q12: 0 | R12: =SUM(P12:Q12) -> 85861.8
A13: F&A Officer | B13: Salaries | C13: 1 | D13: Month | E13: 3 | F13: 1660 | G13: =F13*$E13*C13 -> 4980 | H13: 12 | I13: =H13*$F13*$C13*$B$6 -> 20916 | J13: 12 | K13: =J13*$F13*$C13*$B$6*$B$6 -> 21961.8 | L13: 6 | M13: =L13*$F13*$C13*$B$6*$B$6*$B$6 -> 11529.945 | O13: =N13*$F13*$C13*$B$6*$B$6*$B$6*$B$6 -> 0 | P13: =SUM(G13,I13,K13,M13,O13) -> 59387.745 | Q13: 0 | R13: =SUM(P13:Q13) -> 59387.745
A14: Total Personnel | G14: =SUM(G11:G13) -> 31380 | I14: =SUM(I11:I13) -> 91476 | K14: =SUM(K11:K13) -> 96049.8 | M14: =SUM(M11:M13) -> 54130.545 | O14: =SUM(O11:O13) -> 0 | P14: =SUM(P11:P13) -> 273036.35 | Q14: =SUM(Q11:Q13) -> 0 | R14: =SUM(R11:R13) -> 273036.35
A15: Fringe Benefits
A16: Fringe Benefits - Mexico | B16: Fringe Benefits | D16: Month | F16: 0.3899 | G16: =G14*F16 -> 12235.062 | H16: =+F16 -> 0.3899 | I16: =I14*H16 -> 35666.492 | J16: =+H16 -> 0.3899 | K16: =K14*J16 -> 37449.817 | L16: =+J16 -> 0.3899 | M16: =M14*L16 -> 21105.499 | N16: =+L16 -> 0.3899 | O16: =O14*N16 -> 0 | P16: =SUM(G16,I16,K16,M16,O16) -> 106456.87 | Q16: 0 | R16: =SUM(P16:Q16) -> 106456.87
A17: Total Fringe Benefits | G17: =SUM(G16:G16) -> 12235.062 | I17: =SUM(I16:I16) -> 35666.492 | K17: =SUM(K16:K16) -> 37449.817 | M17: =SUM(M16:M16) -> 21105.499 | O17: =SUM(O16:O16) -> 0 | P17: =SUM(P16:P16) -> 106456.87 | Q17: =SUM(Q16:Q16) -> 0 | R17: =SUM(R16:R16) -> 106456.87
A18: Travel
A19: Activity 11 — Escuela de Liderazgo Sindical: Annual Leadership Training for a New Generation of Union Leaders
A20: Airfare | B20: Travel | C20: 1 | D20: Trip | E20: 0 | F20: =+Travel!$D$11 -> 363.30878 | G20: =F20*E20*C20 -> 0 | H20: 20 | I20: =H20*$F20*$C20 -> 7266.1757 | J20: 20 | K20: =J20*$F20*$C20*$B$5 -> 7556.8227 | L20: 8 | M20: =L20*$F20*$C20*$B$5*$B$5 -> 3143.6382 | O20: =N20*$F20*$C20*$B$5*$B$5*$B$5*$B$5 -> 0 | P20: =SUM(G20,I20,K20,M20,O20) -> 17966.637 | Q20: 0 | R20: =SUM(P20:Q20) -> 17966.637
A21: Lodging and M&IE | B21: Travel | C21: 1 | D21: Day | E21: 0 | F21: =+Travel!$B$11+Travel!$C$12 -> 153.03504 | G21: =F21*E21*C21 -> 0 | H21: =2*20 -> 40 | I21: =H21*$F21*$C21 -> 6121.4015 | J21: =2*20 -> 40 | K21: =J21*$F21*$C21*$B$5 -> 6366.2576 | L21: 16 | M21: =L21*$F21*$C21*$B$5*$B$5 -> 2648.3632 | O21: =N21*$F21*$C21*$B$5*$B$5*$B$5*$B$5 -> 0 | P21: =SUM(G21,I21,K21,M21,O21) -> 15136.022 | Q21: 0 | R21: =SUM(P21:Q21) -> 15136.022
A22: Local transportation | B22: Travel | C22: 1 | D22: Day | E22: 0 | F22: 50 | G22: =F22*E22*C22 -> 0 | H22: =2*20 -> 40 | I22: =H22*$F22*$C22 -> 2000 | J22: =2*20 -> 40 | K22: =J22*$F22*$C22*$B$5 -> 2080 | L22: 16 | M22: =L22*$F22*$C22*$B$5*$B$5 -> 865.28 | O22: =N22*$F22*$C22*$B$5*$B$5*$B$5*$B$5 -> 0 | P22: =SUM(G22,I22,K22,M22,O22) -> 4945.28 | Q22: 0 | R22: =SUM(P22:Q22) -> 4945.28
A23: Monitoring, Evaluation, and Collection of Reliable Data
A24: M&E - Airfare - Field Verification & Data Collection Expenses | B24: Travel | C24: 1 | D24: Trip | E24: 0 | F24: =+Travel!$D$11 -> 363.30878 | G24: =F24*E24*C24 -> 0 | H24: =((2*2)+(4*2)+(2*1)) -> 14 | I24: =H24*$F24*$C24 -> 5086.323 | J24: =((2*2)+(4*2)+(2*1)) -> 14 | K24: =J24*$F24*$C24*$B$5 -> 5289.7759 | L24: 7 | M24: =L24*$F24*$C24*$B$5*$B$5 -> 2750.6835 | O24: =N24*$F24*$C24*$B$5*$B$5*$B$5*$B$5 -> 0 | P24: =SUM(G24,I24,K24,M24,O24) -> 13126.782 | Q24: 0 | R24: =SUM(P24:Q24) -> 13126.782
A25: M&E - Lodging and M&IE - Field Verification & Data Collection Expenses | B25: Travel | C25: 1 | D25: Day | E25: 0 | F25: =+Travel!$B$11+Travel!$C$12 -> 153.03504 | G25: =F25*E25*C25 -> 0 | H25: =((2*2)+(4*2)+(2*1)) -> 14 | I25: =H25*$F25*$C25 -> 2142.4905 | J25: =((2*2)+(4*2)+(2*1)) -> 14 | K25: =J25*$F25*$C25*$B$5 -> 2228.1902 | L25: 7 | M25: =L25*$F25*$C25*$B$5*$B$5 -> 1158.6589 | O25: =N25*$F25*$C25*$B$5*$B$5*$B$5*$B$5 -> 0 | P25: =SUM(G25,I25,K25,M25,O25) -> 5529.3396 | Q25: 0 | R25: =SUM(P25:Q25) -> 5529.3396
A26: M&E - Transportation - Field Verification & Data Collection Expenses | B26: Travel | C26: 1 | D26: Day | E26: 0 | F26: 50 | G26: =F26*E26*C26 -> 0 | H26: =((2*2)+(4*2)+(2*1)) -> 14 | I26: =H26*$F26*$C26 -> 700 | J26: =((2*2)+(4*2)+(2*1)) -> 14 | K26: =J26*$F26*$C26*$B$5 -> 728 | L26: 7 | M26: =L26*$F26*$C26*$B$5*$B$5 -> 378.56 | O26: =N26*$F26*$C26*$B$5*$B$5*$B$5*$B$5 -> 0 | P26: =SUM(G26,I26,K26,M26,O26) -> 1806.56 | Q26: 0 | R26: =SUM(P26:Q26) -> 1806.56
A27: Total Travel | G27: =SUM(G19:G26) -> 0 | I27: =SUM(I19:I26) -> 23316.391 | K27: =SUM(K19:K26) -> 24249.046 | M27: =SUM(M19:M26) -> 10945.184 | O27: =SUM(O19:O26) -> 0 | P27: =SUM(P19:P26) -> 58510.621 | Q27: =SUM(Q19:Q26) -> 0 | R27: =SUM(R19:R26) -> 58510.621
A28: Equipment
A29: None | E29: 0 | F29: 0 | G29: 0 | H29: 0 | I29: 0 | J29: 0 | K29: 0 | L29: 0 | M29: 0 | N29: 0 | O29: 0 | P29: =SUM(G29,I29,K29,M29,O29) -> 0 | Q29: 0 | R29: =SUM(P29:Q29) -> 0
A30: Total Equipment | G30: =SUM(G29) -> 0 | I30: =SUM(I29) -> 0 | K30: =SUM(K29) -> 0 | M30: =SUM(M29) -> 0 | O30: =SUM(O29) -> 0 | P30: =SUM(P29) -> 0 | Q30: =SUM(Q29) -> 0 | R30: =SUM(P30:Q30) -> 0
A31: Supplies
A32: Office supplies | B32: Supplies | C32: 1 | D32: Month | E32: 6 | F32: 150 | G32: =F32*E32*C32 -> 900 | H32: 12 | I32: =H32*$F32*$C32*$B$5 -> 1872 | J32: 12 | K32: =J32*$F32*$C32*$B$5*$B$5 -> 1946.88 | L32: 7 | M32: =L32*$F32*$C32*$B$5*$B$5*$B$5 -> 1181.1072 | O32: =N32*$F32*$C32*$B$5*$B$5*$B$5*$B$5 -> 0 | P32: =SUM(G32,I32,K32,M32,O32) -> 5899.9872 | Q32: 0 | R32: =SUM(P32:Q32) -> 5899.9872
A33: Computers | B33: Supplies | C33: 1 | D33: Month | E33: 3 | F33: 1100 | G33: =F33*E33*C33 -> 3300 | H33: 0 | I33: =H33*$F33*$C33*$B$5 -> 0 | J33: 0 | K33: =J33*$F33*$C33*$B$5*$B$5 -> 0 | L33: 0 | M33: =L33*$F33*$C33*$B$5*$B$5*$B$5 -> 0 | O33: =N33*$F33*$C33*$B$5*$B$5*$B$5*$B$5 -> 0 | P33: =SUM(G33,I33,K33,M33,O33) -> 3300 | Q33: 0 | R33: =SUM(P33:Q33) -> 3300
A34: Total Supplies | G34: =SUM(G32:G33) -> 4200 | I34: =SUM(I32:I33) -> 1872 | K34: =SUM(K32:K33) -> 1946.88 | M34: =SUM(M32:M33) -> 1181.1072 | O34: =SUM(O32:O33) -> 0 | P34: =SUM(P32:P33) -> 9199.9872 | Q34: =SUM(Q32:Q33) -> 0 | R34: =SUM(R32:R33) -> 9199.9872
A35: Contractual
A36: Activity 9 - Contract to deliver workshops to strengthen the capacity of unions to submit effective petitions under the Rapid Response Mechanism | B36: Contract | C36: 1 | D36: Contract | E36: 0 | F36: 1500 | G36: 0 | H36: 2 | I36: =H36*$F36*$C36 -> 3000 | J36: 4 | K36: =J36*$F36*$C36*$B$5 -> 6240 | L36: 4 | M36: =L36*$F36*$C36*$B$5*$B$5 -> 6489.6 | O36: 0 | P36: =SUM(G36,I36,K36,M36,O36) -> 15729.6 | Q36: 0 | R36: =SUM(P36:Q36) -> 15729.6
A37: Activity 11 — Escuela de Liderazgo Sindical: Consultants | B37: Contract | C37: 1 | D37: Contract | E37: 0 | F37: 3000 | G37: 0 | H37: 12 | I37: =H37*$F37*$C37 -> 36000 | J37: 12 | K37: =J37*$F37*$C37*$B$5 -> 37440 | L37: 6 | M37: =L37*$F37*$C37*$B$5*$B$5 -> 19468.8 | O37: 0 | P37: =SUM(G37,I37,K37,M37,O37) -> 92908.8 | Q37: 0 | R37: =SUM(P37:Q37) -> 92908.8
A38: Total Contractual | G38: =SUM(G36:G37) -> 0 | I38: =SUM(I36:I37) -> 39000 | K38: =SUM(K36:K37) -> 43680 | M38: =SUM(M36:M37) -> 25958.4 | O38: =SUM(O36:O37) -> 0 | P38: =SUM(P36:P37) -> 108638.4 | Q38: =SUM(Q36:Q37) -> 0 | R38: =SUM(R36:R37) -> 108638.4
A39: Construction
A40: None | E40: 0 | F40: 0 | G40: 0 | H40: 0 | I40: 0 | J40: 0 | K40: 0 | L40: 0 | M40: 0 | N40: 0 | O40: 0 | P40: =SUM(G40,I40,K40,M40,O40) -> 0 | Q40: 0 | R40: =SUM(P40:Q40) -> 0
A41: Total Construction | G41: =SUM(G40) -> 0 | I41: =SUM(I40) -> 0 | K41: =SUM(K40) -> 0 | M41: =SUM(M40) -> 0 | O41: =SUM(O40) -> 0 | P41: =SUM(P40) -> 0 | Q41: =SUM(Q40) -> 0 | R41: =SUM(P41:Q41) -> 0
...

Sheet Travel
A1: TC | B1: 18.5
A4: Domestic travel
B5: Lodging | C5: Per Diem | D5: Airfare (round) | E5: Ground transportation (round) | F5: Max lodging
A6: CDMX
A7: QRO | B7: =AVERAGE(2100,1750,1662,788,1746)/$B$1 -> 86.983784 | C7: =123 -> 123 | D7: =AVERAGE(10117,11683)/$B$1 -> 589.18919 | E7: 50 | F7: 210
A8: BC | B8: =AVERAGE(2343,2933,2273,1562,1889,2014)/$B$1 -> 117.24324 | C8: =101 -> 101 | D8: =AVERAGE(4274,4439,4532,4536,4547)/$B$1 -> 241.38378 | E8: 50 | F8: 193
A9: GTO | B9: =AVERAGE(2075,601,1984,777,1283,2355,2455)/$B$1 -> 89.034749 | C9: =110 -> 110 | D9: =AVERAGE(7356,7820,10470,10682)/$B$1 -> 490.91892 | E9: 50 | F9: 141
A10: JAL | B10: =AVERAGE(1203,2371,906,858,2371,2434)/$B$1 -> 91.378378 | C10: =121 -> 121 | D10: =AVERAGE(1543,2444,2879,2883)/$B$1 -> 131.74324 | E10: 50 | F10: 241
A11: Average | B11: =AVERAGE(B6:B10) -> 96.160039 | C11: =AVERAGE(C6:C10) -> 113.75 | D11: =AVERAGE(D6:D10) -> 363.30878 | E11: =AVERAGE(E6:E10) -> 50 | F11: =AVERAGE(F6:F10) -> 196.25
A12: 0.5 | C12: =+C11*0.5 -> 56.875
A16: International travel
A18: CDMX-DC | B18: =AVERAGE(14811,19251)/$B$1 -> 920.59459
A19: CDMX lodging | B19: =AVERAGE(3680,1721,1092,2233)/$B$1 -> 117.91892
A20: CDMX M&IE | B20: =126*0.9 -> 113.4
A21: DC lodging | B21: 183
A22: DC M&IE | B22: =92*0.9 -> 82.8
A27: International travel - labor experts
A28: Colombia-CDMX | B28: =AVERAGE(9986,10307,11289) -> 10527.333
A29: Paraguay-CDMX | B29: =AVERAGE(14336,14605,16704) -> 15215
A30: Uruguay-CDMX | B30: =AVERAGE(16220,17106,18138,20211,21372) -> 18609.4
A31: Argentina-CDMX | B31: =AVERAGE(17095,18998) -> 18046.5
A32: Chile-CDMX | B32: =AVERAGE(11637,12408,13044,13990) -> 12769.75
A33: Brazil-CDMX | B33: =AVERAGE(9364,9410,13836) -> 10870
A34: DC-CDMX | B34: 17031
A35: Average | B35: =AVERAGE(B28:B34) -> 14724.14
A36: Average USD | B36: =+B35/$B$1 -> 795.89949

Sheet Expenses - Unit Costs
A1: Unit cost
A3: Category | B3: Activity | C3: Unit | D3: # of persons | E3: Coffee break | F3: Lunch | G3: Printing materials | H3: Other logistic material | I3: Back | J3: Venue (A/V Equipment, Materials, etc.) | K3: Total
A4: Activity 1.1 - TRACE: Targeted Response and Coordination for Enforcement – ITAM | B4: State and Local Coordination Meetings to Launch and Monitor the Enforcement Information System | C4: Meeting | D4: 15 | E4: 5 | F4: 14 | G4: 5 | K4: =(SUM(E4:H4)*D4)+SUM(I4:J4) -> 360
A5: Activity 1.2 - Strengthening SINACOL as a National Data Platform | B5: National CONACENTROS Meetings to Promote Open Data Adoption | C5: Meeting | D5: 60 | E5: 5 | F5: 14 | G5: 5 | I5: 500 | J5: 4000 | K5: =(SUM(E5:H5)*D5)+SUM(I5:J5) -> 5940
A6: Activity 1.3 - Strengthening Collective Conciliation During the Pre-Strike (Bargaining) Period through Collective platform (Developed in partnership with ITAM) | B6: Coordination Meetings with State Labor Courts and Conciliation Centers | C6: Meeting | D6: 15 | E6: 5 | F6: 14 | G6: 5 | K6: =(SUM(E6:H6)*D6)+SUM(I6:J6) -> 360
A7: Activity 1.4 - Training Modules for State Labor Authorities | B7: Graduation Ceremonies for State Labor Authorities | C7: Ceremony | D7: 50 | E7: 5 | F7: 14 | G7: 10 | J7: 2500 | K7: =(SUM(E7:H7)*D7)+SUM(I7:J7) -> 3950
A8: Activity 2.1 - Improved Dialogue between Employers and Local Labor Authorities | B8: Summits to Strengthen Dialogue between Employers and Local Labor Authorities | C8: Summit | D8: 100 | E8: 5 | F8: 14 | G8: 10 | I8: 500 | J8: 4000 | K8: =(SUM(E8:H8)*D8)+SUM(I8:J8) -> 7400
A9: Activity 2.2 - Strengthen SMEs’ Knowledge of and Compliance with Labor Reforms and USMCA Commitments | B9: Workshops to Strengthen SMEs’ Knowledge of Labor Rights and Trade Commitments | C9: Training | D9: 30 | E9: 5 | F9: 14 | G9: 5 | J9: 1500 | K9: =(SUM(E9:H9)*D9)+SUM(I9:J9) -> 2220
A10: Activity 2.3 - Meetings to pilot Labor Rights Compliance Checklist to Strengthen Compliance Across Priority Sectors and States | B10: Meetings to pilot Labor Rights Compliance Checklist to Strengthen Compliance Across Priority Sectors and States | C10: Meetings | D10: 10 | E10: 5 | F10: 14 | G10: 5 | K10: =(SUM(E10:H10)*D10)+SUM(I10:J10) -> 240
A11: Activity 3.1 - CONDATOS: A Co-Developed Digital Platform to Benchmark Collective Bargaining Agreements, Expand Transparency, and Strengthen Workers’ Negotiating Power | B11: Meetings with democratically elected unions | C11: Meeting | D11: 10 | E11: 5 | F11: 14 | G11: 5 | K11: =(SUM(E11:H11)*D11)+SUM(I11:J11) -> 240
A12: Activity 3.1 - CONDATOS: A Co-Developed Digital Platform to Benchmark Collective Bargaining Agreements, Expand Transparency, and Strengthen Workers’ Negotiating Power | B12: Presentations with democratically elected unions | C12: Workshop | D12: 25 | E12: 5 | F12: 14 | G12: 5 | J12: 1000 | K12: =(SUM(E12:H12)*D12)+SUM(I12:J12) -> 1600
A13: Activity 3.2 - Strengthening Union Capacity to Submit Effective Petitions Under the Rapid Response Mechanism | B13: Workshop expenses to ensure outreach and consultation with stakeholders | C13: Workshop | D13: 10 | E13: 5 | F13: 14 | G13: 5 | K13: =(SUM(E13:H13)*D13)+SUM(I13:J13) -> 240
A14: Activity 3.2 - Strengthening Union Capacity to Submit Effective Petitions Under the Rapid Response Mechanism | B14: Printing and dissemination of developed tool | C14: Materials | D14: 700 | G14: 10 | K14: =(SUM(E14:H14)*D14)+SUM(I14:J14) -> 7000
A15: Activity 3.3 - Building Union-to-Union Exchanges to Strengthen Collective Bargaining Capacity | B15: International workshops to Strengthen Collective Bargaining Capacity | C15: Workshop | D15: 100 | E15: 5 | F15: 14 | G15: 10 | H15: 30 | I15: 500 | J15: 4000 | K15: =(SUM(E15:H15)*D15)+SUM(I15:J15) -> 10400
A16: Activity 3.3 - Building Union-to-Union Exchanges to Strengthen Collective Bargaining Capacity | B16: Printing materials | C16: Materials | D16: 50 | G16: 10 | K16: =(SUM(E16:H16)*D16)+SUM(I16:J16) -> 500
A17: 4.5 Stakeholder Engagement and Strategy Validation | B17: Workshops with Stakeholders to validate project strategies | C17: Meeting | D17: 15 | E17: 5 | F17: 14 | G17: 5 | J17: 1000 | K17: =(SUM(E17:H17)*D17)+SUM(I17:J17) -> 1360
