Workbook

Sheet Budget Summary
A1: PARTNERS OF THE AMERICAS
A2: SUMMARY BUDGET FOR MEXICO MIGRATION MESSAGING EXTENSION
B3: Year 1 | E3: Year 2 (Oct 2024 - Sept 2025) | H3: Year 3 (Oct 2025 - Sept 2026) | K3: Year 4 (Oct 2026 - Apr 2027) | N3: Total
A4: BUDGET SUMMARY CATEGORIES | B4: Grant | C4: Cost Share | D4: Total | E4: Grant | F4: Cost Share | G4: Total | H4: Grant | I4: Cost Share | J4: Total | K4: Grant | L4: Cost Share | M4: Total | N4: Grant | O4: Cost Share | P4: Total
A5: A. Personnel | B5: =+'Line Item Budget'!K20 -> 80210 | C5: =+'Line Item Budget'!L20 -> 0 | D5: =B5+C5 -> 80210 | E5: =+'Line Item Budget'!S20 -> 99954.4 | F5: =+'Line Item Budget'!T20 -> 0 | G5: =E5+F5 -> 99954.4 | H5: =+'Line Item Budget'!AA20 -> 114905.7 | I5: =+'Line Item Budget'!AB20 -> 0 | J5: =H5+I5 -> 114905.7 | K5: =+'Line Item Budget'!AI20 -> 59635.107 | L5: =+'Line Item Budget'!AJ20 -> 0 | M5: =K5+L5 -> 59635.107 | N5: =+B5+E5+H5+K5 -> 354705.21 | O5: =+C5+F5+I5+L5 -> 0 | P5: =+N5+O5 -> 354705.21
A6: B. Fringe Benefits | B6: =+'Line Item Budget'!K26 -> 27988.691 | C6: =+'Line Item Budget'!L26 -> 0 | D6: =B6+C6 -> 27988.691 | E6: =+'Line Item Budget'!S26 -> 32989.238 | F6: =+'Line Item Budget'!T26 -> 0 | G6: =E6+F6 -> 32989.238 | H6: =+'Line Item Budget'!AA26 -> 53739.035 | I6: =+'Line Item Budget'!AB26 -> 0 | J6: =H6+I6 -> 53739.035 | K6: =+'Line Item Budget'!AI26 -> 27864.962 | L6: =+'Line Item Budget'!AJ26 -> 0 | M6: =K6+L6 -> 27864.962 | N6: =+B6+E6+H6+K6 -> 142581.93 | O6: =+C6+F6+I6+L6 -> 0 | P6: =+N6+O6 -> 142581.93
A7: C. Travel | B7: =+'Line Item Budget'!K38 -> 7135 | C7: =+'Line Item Budget'!L38 -> 0 | D7: =B7+C7 -> 7135 | E7: =+'Line Item Budget'!S38 -> 7420.4 | F7: =+'Line Item Budget'!T38 -> 0 | G7: =E7+F7 -> 7420.4 | H7: =+'Line Item Budget'!AA38 -> 2573 | I7: =+'Line Item Budget'!AB38 -> 0 | J7: =H7+I7 -> 2573 | K7: =+'Line Item Budget'!AI38 -> 1175.2 | L7: =+'Line Item Budget'!AJ38 -> 0 | M7: =K7+L7 -> 1175.2 | N7: =+B7+E7+H7+K7 -> 18303.6 | O7: =+C7+F7+I7+L7 -> 0 | P7: =+N7+O7 -> 18303.6
A8: D. Equipment
A9: E. Supplies | B9: =+'Line Item Budget'!K44 -> 3600 | C9: =+'Line Item Budget'!L44 -> 0 | D9: =B9+C9 -> 3600 | E9: =+'Line Item Budget'!S44 -> 3046 | F9: =+'Line Item Budget'!T44 -> 0 | G9: =E9+F9 -> 3046 | H9: =+'Line Item Budget'!AA44 -> 374.4 | I9: =+'Line Item Budget'!AB44 -> 0 | J9: =H9+I9 -> 374.4 | K9: =+'Line Item Budget'!AI44 -> 193.8 | L9: =+'Line Item Budget'!AJ44 -> 0 | M9: =K9+L9 -> 193.8 | N9: =+B9+E9+H9+K9 -> 7214.2 | O9: =+C9+F9+I9+L9 -> 0 | P9: =+N9+O9 -> 7214.2
A10: F. Contractual and Subawards | B10: =+'Line Item Budget'!K61 -> 115900 | C10: =+'Line Item Budget'!L61 -> 0 | D10: =B10+C10 -> 115900 | E10: =+'Line Item Budget'!S61 -> 324287.42 | F10: =+'Line Item Budget'!T61 -> 0 | G10: =E10+F10 -> 324287.42 | H10: =+'Line Item Budget'!AA61 -> 535208.17 | I10: =+'Line Item Budget'!AB61 -> 0 | J10: =H10+I10 -> 535208.17 | K10: =+'Line Item Budget'!AI61 -> 46687.417 | L10: =+'Line Item Budget'!AJ61 -> 0 | M10: =K10+L10 -> 46687.417 | N10: =+B10+E10+H10+K10 -> 1022083 | O10: =+C10+F10+I10+L10 -> 0 | P10: =+N10+O10 -> 1022083
A11: G. Construction
A12: H. Other Direct Costs | B12: =+'Line Item Budget'!K86 -> 39031 | C12: =+'Line Item Budget'!L86 -> 0 | D12: =B12+C12 -> 39031 | E12: =+'Line Item Budget'!S86 -> 251211.64 | F12: =+'Line Item Budget'!T86 -> 0 | G12: =E12+F12 -> 251211.64 | H12: =+'Line Item Budget'!AA86 -> 48315.04 | I12: =+'Line Item Budget'!AB86 -> 0 | J12: =H12+I12 -> 48315.04 | K12: =+'Line Item Budget'!AI86 -> 23728.089 | L12: =+'Line Item Budget'!AJ86 -> 0 | M12: =K12+L12 -> 23728.089 | N12: =+B12+E12+H12+K12 -> 362285.77 | O12: =+C12+F12+I12+L12 -> 0 | P12: =+N12+O12 -> 362285.77
A13: I. Total Direct Costs | B13: =SUM(B5:B12) -> 273864.69 | C13: =SUM(C5:C12) -> 0 | D13: =B13+C13 -> 273864.69 | E13: =SUM(E5:E12) -> 718909.09 | F13: =SUM(F5:F12) -> 0 | G13: =E13+F13 -> 718909.09 | H13: =SUM(H5:H12) -> 755115.34 | I13: =SUM(I5:I12) -> 0 | J13: =H13+I13 -> 755115.34 | K13: =SUM(K5:K12) -> 159284.57 | L13: =SUM(L5:L12) -> 0 | M13: =K13+L13 -> 159284.57 | N13: =+B13+E13+H13+K13 -> 1907173.7 | O13: =+C13+F13+I13+L13 -> 0 | P13: =+N13+O13 -> 1907173.7
A14: J. Indirect Costs | B14: =+'Line Item Budget'!K89 -> 77448.935 | C14: =+'Line Item Budget'!L89 -> 0 | D14: =B14+C14 -> 77448.935 | E14: =+'Line Item Budget'!S89 -> 203307.49 | F14: =+'Line Item Budget'!T89 -> 0 | G14: =E14+F14 -> 203307.49 | H14: =+'Line Item Budget'!AA89 -> 213546.62 | I14: =+'Line Item Budget'!AB89 -> 0 | J14: =H14+I14 -> 213546.62 | K14: =+'Line Item Budget'!AI89 -> 45048.128 | L14: =+'Line Item Budget'!AJ89 -> 0 | M14: =K14+L14 -> 45048.128 | N14: =+B14+E14+H14+K14 -> 539351.17 | O14: =+C14+F14+I14+L14 -> 0 | P14: =+N14+O14 -> 539351.17
A15: K. Total Costs | B15: =+B13+B14 -> 351313.63 | C15: =+C13+C14 -> 0 | D15: =D13+D14 -> 351313.63 | E15: =+E13+E14 -> 922216.59 | F15: =+F13+F14 -> 0 | G15: =G13+G14 -> 922216.59 | H15: =+H13+H14 -> 968661.96 | I15: =+I13+I14 -> 0 | J15: =J13+J14 -> 968661.96 | K15: =+K13+K14 -> 204332.7 | L15: =+L13+L14 -> 0 | M15: =M13+M14 -> 204332.7 | N15: =N14+N13 -> 2446524.9 | O15: =+C15+F15+I15+L15 -> 0 | P15: =+N15+O15 -> 2446524.9

Sheet Line Item Budget
D1: PARTNERS OF THE AMERICAS - Mexico Migration Messaging Project (MMMP) - Cost Extension
A2: Entity: | B2: P | D2: Merit and Cost of Living Increases - 5% | E2: 1.05
A3: Program/Dept.: | B3: 20200 | D3: Inflation - 4% | E3: 1.04 | O3: Change in calculation component | R3: Green Text is Budget 01 | T3: Black Text is Budget 02 | V3: Purple Text has Budget 01 + 02
A4: Funder-Grant: | B4: DOS453
A5: Budget Code | B5: Account Code | C5: Country Code | D5: All costs in US$ | E5: Year 1 (Oct 2023 - Sept 2024) | M5: Year 2 (October 2024 - September 2025) | U5: Year 3 (October 2025 - September 2026) | AC5: Year 4 (October 2026 - April 2027) | AK5: Total
D6: Budget Line Items | E6: No. | F6: Unit Type | G6: Freq. | H6: % | I6: Rate | J6: Total | K6: Federal | L6: Cost Share | M6: No. | N6: Unit Type | O6: Freq. | P6: % | Q6: Rate | R6: Total | S6: Federal | T6: Cost Share | U6: No. | V6: Unit Type | W6: Freq. | X6: % | Y6: Rate | Z6: Total | AA6: Federal | AB6: Cost Share | AC6: No. | AD6: Unit Type | AE6: Freq. | AF6: % | AG6: Rate | AH6: Total | AI6: Federal | AJ6: Cost Share | AK6: Federal | AL6: Cost Share | AM6: Grand Total
D7: A. Personnel
D8: A.1 Field Staff Salaries
A9: PERSNL-CDM | B9: 70000 | C9: MEX | D9: A.1.1 Country Director Mexico | E9: 1 | F9: Month | G9: 12 | H9: 0.05 | I9: 13450 | J9: =E9*I9*G9*H9 -> 8070 | K9: =J9 -> 8070 | L9: =J9-K9 -> 0 | M9: 1 | N9: Month | O9: 12 | P9: 0.05 | Q9: =+I9*1.04 -> 13988 | R9: =M9*Q9*O9*P9 -> 8392.8 | S9: =R9 -> 8392.8 | T9: =R9-S9 -> 0 | AK9: =K9+S9+AA9+AI9 -> 16462.8 | AL9: =L9+T9+AB9+AJ9 -> 0 | AM9: =+AK9+AL9 -> 16462.8
A10: PERSNL-PD | B10: 70000 | C10: MEX | D10: A.1.2 Program Director/Coordinator | E10: 1 | F10: Month | G10: 12 | H10: 0.1 | I10: 8650 | J10: =E10*I10*G10*H10 -> 10380 | K10: =J10 -> 10380 | L10: =J10-K10 -> 0 | M10: 1 | N10: Month | O10: 12 | P10: 0.1 | Q10: =I10*$E$3 -> 8996 | R10: =M10*Q10*O10*P10 -> 10795.2 | S10: =R10 -> 10795.2 | T10: =R10-S10 -> 0 | U10: 1 | V10: Month | W10: 12 | X10: 1 | Y10: 4830 | Z10: =U10*Y10*W10*X10 -> 57960 | AA10: =Z10 -> 57960 | AB10: =Z10-AA10 -> 0 | AC10: 1 | AD10: Month | AE10: 7 | AF10: 1 | AG10: =Y10*$E$2 -> 5071.5 | AH10: =AC10*AG10*AE10*AF10 -> 35500.5 | AI10: =AH10 -> 35500.5 | AJ10: =AH10-AI10 -> 0 | AK10: =K10+S10+AA10+AI10 -> 114635.7 | AL10: =L10+T10+AB10+AJ10 -> 0 | AM10: =+AK10+AL10 -> 114635.7
A11: PERSNL-SCS | B11: 70000 | C11: MEX | D11: A.1.3 Senior Communications Specialist | E11: 1 | F11: Month | G11: 12 | H11: 0.3 | I11: 4100 | J11: =E11*I11*G11*H11 -> 14760 | K11: =J11 -> 14760 | L11: =J11-K11 -> 0 | M11: 1 | N11: Month | O11: 12 | P11: 0.3 | Q11: =+I11*1.04 -> 4264 | R11: =M11*Q11*O11*P11 -> 15350.4 | S11: =R11 -> 15350.4 | T11: =R11-S11 -> 0 | AK11: =K11+S11+AA11+AI11 -> 30110.4 | AL11: =L11+T11+AB11+AJ11 -> 0 | AM11: =+AK11+AL11 -> 30110.4
A12: PERSNL-COM | B12: 70000 | C12: MEX | D12: A.1.4 Communications Specialist | E12: 1 | F12: Month | G12: 12 | H12: 0.3 | I12: 3000 | J12: =E12*I12*G12*H12 -> 10800 | K12: =J12 -> 10800 | L12: =J12-K12 -> 0 | M12: 1 | N12: Month | O12: 12 | P12: 0.3 | Q12: =I12*E3 -> 3120 | R12: =M12*Q12*O12*P12 -> 11232 | S12: =R12 -> 11232 | T12: =R12-S12 -> 0 | U12: 1 | V12: Month | W12: 12 | X12: 0.75 | Y12: =2300*$E$2 -> 2415 | Z12: =U12*Y12*W12*X12 -> 21735 | AA12: =Z12 -> 21735 | AB12: =Z12-AA12 -> 0 | AC12: 1 | AD12: Month | AE12: 3 | AF12: 0.75 | AG12: =Y12*$E$2 -> 2535.75 | AH12: =AC12*AG12*AE12*AF12 -> 5705.4375 | AI12: =AH12 -> 5705.4375 | AJ12: =AH12-AI12 -> 0 | AK12: =K12+S12+AA12+AI12 -> 49472.438 | AL12: =L12+T12+AB12+AJ12 -> 0 | AM12: =+AK12+AL12 -> 49472.438
A13: PERSNL-SMA | B13: 70000 | C13: MEX | D13: A.1.5 Social Media Analyst | E13: 1 | F13: Month | G13: 12 | H13: 0.3 | I13: 2100 | J13: =E13*I13*G13*H13 -> 7560 | K13: =J13 -> 7560 | L13: =J13-K13 -> 0 | M13: 1 | N13: Month | O13: 12 | P13: 0.3 | Q13: =+I13*1.04 -> 2184 | R13: =M13*Q13*O13*P13 -> 7862.4 | S13: =R13 -> 7862.4 | T13: =R13-S13 -> 0 | AK13: =K13+S13+AA13+AI13 -> 15422.4 | AL13: =L13+T13+AB13+AJ13 -> 0 | AM13: =+AK13+AL13 -> 15422.4
A14: PERSNL-M&E | B14: 70000 | C14: MEX | D14: A.1.6 Monitoring, Evaluation, and Learning Officer | E14: 1 | F14: Month | G14: 12 | H14: 0.25 | I14: 3100 | J14: =E14*I14*G14*H14 -> 9300 | K14: =J14 -> 9300 | L14: =J14-K14 -> 0 | M14: 1 | N14: Month | O14: 12 | P14: 0.25 | Q14: =+I14*1.04 -> 3224 | R14: =M14*Q14*O14*P14 -> 9672 | S14: =R14 -> 9672 | T14: =R14-S14 -> 0 | AK14: =K14+S14+AA14+AI14 -> 18972 | AL14: =L14+T14+AB14+AJ14 -> 0 | AM14: =+AK14+AL14 -> 18972
A15: PERSNL-F&A | B15: 70000 | C15: MEX | D15: A.1.7 Finance & Administration Director | E15: 1 | F15: Month | G15: 12 | H15: 0.05 | I15: 5500 | J15: =E15*I15*G15*H15 -> 3300 | K15: =J15 -> 3300 | L15: =J15-K15 -> 0 | M15: 1 | N15: Month | O15: 12 | P15: 0.05 | Q15: =+I15*1.04 -> 5720 | R15: =M15*Q15*O15*P15 -> 3432 | S15: =R15 -> 3432 | T15: =R15-S15 -> 0 | AK15: =K15+S15+AA15+AI15 -> 6732 | AL15: =L15+T15+AB15+AJ15 -> 0 | AM15: =+AK15+AL15 -> 6732
A16: PERSNL-F&A | B16: 70000 | C16: MEX | D16: A.1.8 Finance & Administration Officer | E16: 1 | F16: Month | G16: 12 | H16: 0.2 | I16: 2100 | J16: =E16*I16*G16*H16 -> 5040 | K16: =J16 -> 5040 | L16: =J16-K16 -> 0 | M16: 1 | N16: Month | O16: 12 | P16: 0.2 | Q16: =I16*1.04 -> 2184 | R16: =M16*Q16*O16*P16 -> 5241.6 | S16: =R16 -> 5241.6 | T16: =R16-S16 -> 0 | U16: 1 | V16: Month | W16: 12 | X16: 0.5 | Y16: =1833*$E$2 -> 1924.65 | Z16: =U16*Y16*W16*X16 -> 11547.9 | AA16: =Z16 -> 11547.9 | AB16: =Z16-AA16 -> 0 | AC16: 1 | AD16: Month | AE16: 6 | AF16: 0.5 | AG16: =Y16*$E$2 -> 2020.8825 | AH16: =AC16*AG16*AE16*AF16 -> 6062.6475 | AI16: =AH16 -> 6062.6475 | AJ16: =AH16-AI16 -> 0 | AK16: =K16+S16+AA16+AI16 -> 27892.147 | AL16: =L16+T16+AB16+AJ16 -> 0 | AM16: =+AK16+AL16 -> 27892.147
D17: A.2 HQ Staff Salaries
A18: PERSNL | B18: 50000 | C18: USA | D18: A.2.1 Program Manager (HQ) | E18: 1 | F18: Month | G18: 12 | H18: 0.2 | I18: =55000/12 -> 4583.3333 | J18: =E18*I18*G18*H18 -> 11000 | K18: =J18 -> 11000 | L18: =J18-K18 -> 0 | M18: 1 | N18: Month | O18: 12 | P18: 0.2 | Q18: =I18*1.04 -> 4766.6667 | R18: =M18*Q18*O18*P18 -> 11440 | S18: =R18 -> 11440 | T18: =R18-S18 -> 0 | U18: 1 | V18: Month | W18: 12 | X18: 0.05 | Y18: =10000*$E$2 -> 10500 | Z18: =U18*Y18*W18*X18 -> 6300 | AA18: =Z18 -> 6300 | AB18: =Z18-AA18 -> 0 | AC18: 1 | AD18: Month | AE18: 7 | AF18: 0.05 | AG18: =Y18*$E$2 -> 11025 | AH18: =AC18*AG18*AE18*AF18 -> 3858.75 | AI18: =AH18 -> 3858.75 | AJ18: =AH18-AI18 -> 0 | AK18: =K18+S18+AA18+AI18 -> 32598.75 | AL18: =L18+T18+AB18+AJ18 -> 0 | AM18: =+AK18+AL18 -> 32598.75
A19: PERSNL-PO | B19: 50000 | C19: USA | D19: A.2.2. Program Officer (HQ) | E19: 0 | F19: Month | G19: 0 | J19: =E19*I19*G19*H19 -> 0 | K19: =J19 -> 0 | L19: =J19-K19 -> 0 | M19: 1 | N19: Month | O19: 12 | P19: 0.25 | Q19: 5512 | R19: =M19*Q19*O19*P19 -> 16536 | S19: =R19 -> 16536 | T19: =R19-S19 -> 0 | U19: 1 | V19: Month | W19: 12 | X19: 0.25 | Y19: =Q19*$E$2 -> 5787.6 | Z19: =U19*Y19*W19*X19 -> 17362.8 | AA19: =Z19 -> 17362.8 | AB19: =Z19-AA19 -> 0 | AC19: 1 | AD19: Month | AE19: 7 | AF19: 0.2 | AG19: =Y19*$E$2 -> 6076.98 | AH19: =AC19*AG19*AE19*AF19 -> 8507.772 | AI19: =AH19 -> 8507.772 | AJ19: =AH19-AI19 -> 0 | AK19: =K19+S19+AA19+AI19 -> 42406.572 | AL19: =L19+T19+AB19+AJ19 -> 0 | AM19: =+AK19+AL19 -> 42406.572
D20: Subtotal Personnel | J20: =SUM(J9:J19) -> 80210 | K20: =SUM(K9:K19) -> 80210 | L20: =SUM(L9:L19) -> 0 | R20: =SUM(R9:R19) -> 99954.4 | S20: =SUM(S9:S19) -> 99954.4 | T20: =SUM(T9:T19) -> 0 | Z20: =SUM(Z9:Z19) -> 114905.7 | AA20: =SUM(AA9:AA19) -> 114905.7 | AB20: =SUM(AB9:AB19) -> 0 | AH20: =SUM(AH9:AH19) -> 59635.107 | AI20: =SUM(AI9:AI19) -> 59635.107 | AJ20: =SUM(AJ9:AJ19) -> 0 | AK20: =SUM(AK9:AK19) -> 354705.21 | AL20: =SUM(AL9:AL19) -> 0 | AM20: =SUM(AM9:AM19) -> 354705.21
D21: B. Fringe Benefits
D22: B.1 HQ Fringe Benefits
A23: FRINGE | B23: 50900 | C23: USA | D23: B.1.1 U.S.-Based Personnel Fringe Benefits | F23: % | H23: 0.2347 | J23: =$H23*SUM(J18:J19) -> 2581.7 | K23: =J23 -> 2581.7 | L23: 0 | N23: % | P23: 0.2347 | R23: =P23*SUM(R18:R19) -> 6565.9672 | S23: =R23 -> 6565.9672 | T23: 0 | V23: % | X23: 0.2347 | Z23: =X23*SUM(Z18:Z19) -> 5553.6592 | AA23: =Z23 -> 5553.6592 | AB23: 0 | AD23: % | AF23: 0.2347 | AH23: =AF23*SUM(AH18:AH19) -> 2902.4227 | AI23: =AH23 -> 2902.4227 | AJ23: 0 | AK23: =K23+S23+AA23+AI23 -> 17603.749 | AL23: =L23+T23+AB23+AJ23 -> 0 | AM23: =+AK23+AL23 -> 17603.749
D24: B.2 Field Fringe Benefits
A25: FRINGE-MX | B25: 70015 | C25: MEX | D25: B.2.1 Mexico Field Staff Fringe Benefits | F25: % | H25: 0.3671 | J25: =$H25*SUM(J9:J16) -> 25406.991 | K25: =J25 -> 25406.991 | L25: 0 | N25: % | P25: =H25 -> 0.3671 | R25: =P25*SUM(R9:R16) -> 26423.271 | S25: =R25 -> 26423.271 | T25: 0 | V25: % | X25: 0.5281 | Z25: =X25*SUM(Z10:Z16) -> 48185.375 | AA25: =Z25 -> 48185.375 | AB25: 0 | AD25: % | AF25: 0.5281 | AH25: =AF25*SUM(AH10:AH16) -> 24962.54 | AI25: =AH25 -> 24962.54 | AJ25: 0 | AK25: =K25+S25+AA25+AI25 -> 124978.18 | AL25: =L25+T25+AB25+AJ25 -> 0 | AM25: =+AK25+AL25 -> 124978.18
D26: Subtotal Fringe Benefits | J26: =SUM(J23:J25) -> 27988.691 | K26: =SUM(K23:K25) -> 27988.691 | L26: =SUM(L23:L25) -> 0 | R26: =SUM(R23:R25) -> 32989.238 | S26: =SUM(S23:S25) -> 32989.238 | T26: =SUM(T23:T25) -> 0 | Z26: =SUM(Z23:Z25) -> 53739.035 | AA26: =SUM(AA23:AA25) -> 53739.035 | AB26: =SUM(AB23:AB25) -> 0 | AH26: =SUM(AH23:AH25) -> 27864.962 | AI26: =SUM(AI23:AI25) -> 27864.962 | AJ26: =SUM(AJ23:AJ25) -> 0 | AK26: =SUM(AK23:AK25) -> 142581.93 | AL26: =SUM(AL23:AL25) -> 0 | AM26: =SUM(AM23:AM25) -> 142581.93
D27: C. Travel
D28: C.1 HQ Staff International Travel
A29: STFTRAVEL | B29: 86040 | C29: USA | D29: C.1.1 International Airfare (DC-MX) | E29: 1 | F29: Flight | G29: 1 | H29: 1 | I29: 700 | J29: =E29*I29*G29 -> 700 | K29: =J29 -> 700 | L29: =J29-K29 -> 0 | M29: 1 | N29: Flight | O29: 1 | P29: 1 | Q29: =+I29*1.04 -> 728 | R29: =M29*Q29*O29*P29 -> 728 | S29: =R29 -> 728 | T29: =R29-S29 -> 0 | AK29: =K29+S29+AA29+AI29 -> 1428 | AL29: =L29+T29+AB29+AJ29 -> 0 | AM29: =+AK29+AL29 -> 1428
A30: GROUNDTRAN | B30: 86000 | C30: USA | D30: C.1.2 Ground Transportation | E30: 1 | F30: Trip | G30: 1 | H30: 1 | I30: 100 | J30: =E30*I30*G30 -> 100 | K30: =J30 -> 100 | L30: =J30-K30 -> 0 | M30: 1 | N30: Trip | O30: 1 | P30: 1 | Q30: =+I30*1.04 -> 104 | R30: =M30*Q30*O30*P30 -> 104 | S30: =R30 -> 104 | T30: =R30-S30 -> 0 | AK30: =K30+S30+AA30+AI30 -> 204 | AL30: =L30+T30+AB30+AJ30 -> 0 | AM30: =+AK30+AL30 -> 204
A31: LODGING | B31: 86030 | C31: USA | D31: C.1.3 Lodging | E31: 1 | F31: Night | G31: 4 | H31: 1 | I31: 120 | J31: =E31*I31*G31 -> 480 | K31: =J31 -> 480 | L31: =J31-K31 -> 0 | M31: 1 | N31: Night | O31: 4 | P31: 1 | Q31: =+I31*1.04 -> 124.8 | R31: =M31*Q31*O31*P31 -> 499.2 | S31: =R31 -> 499.2 | T31: =R31-S31 -> 0 | AK31: =K31+S31+AA31+AI31 -> 979.2 | AL31: =L31+T31+AB31+AJ31 -> 0 | AM31: =+AK31+AL31 -> 979.2
A32: STFCN DIEM | B32: 86050 | C32: USA | D32: C.1.4 M&IE | E32: 1 | F32: Day | G32: 5 | H32: 1 | I32: 95 | J32: =E32*I32*G32 -> 475 | K32: =J32 -> 475 | L32: =J32-K32 -> 0 | M32: 1 | N32: Day | O32: 5 | P32: 1 | Q32: =+I32*1.04 -> 98.8 | R32: =M32*Q32*O32*P32 -> 494 | S32: =R32 -> 494 | T32: =R32-S32 -> 0 | AK32: =K32+S32+AA32+AI32 -> 969 | AL32: =L32+T32+AB32+AJ32 -> 0 | AM32: =+AK32+AL32 -> 969
D33: C.2 Local Staff In-Country Travel to Target Geographic Regions
A34: LSDOMAIR | B34: 86030 | C34: MEX | D34: C.2.1 Domestic Airfare | E34: 2 | F34: Flight | G34: 1 | H34: 1 | I34: 200 | J34: =E34*I34*G34 -> 400 | K34: =J34 -> 400 | L34: =J34-K34 -> 0 | M34: 2 | N34: Flight | O34: 1 | P34: 1 | Q34: =+I34*1.04 -> 208 | R34: =M34*Q34*O34*P34 -> 416 | S34: =R34 -> 416 | T34: =R34-S34 -> 0 | U34: 2 | V34: Flight | W34: 1 | X34: 1 | Y34: 208 | Z34: =+Y34*W34*U34*X34 -> 416 | AA34: =Z34 -> 416 | AB34: =Z34-AA34 -> 0 | AC34: 1 | AD34: Flight | AE34: 1 | AF34: 1 | AG34: =Y34*$E$3 -> 216.32 | AH34: =+AG34*AE34*AC34*$H34 -> 216.32 | AI34: =AH34 -> 216.32 | AJ34: =AH34-AI34 -> 0 | AK34: =K34+S34+AA34+AI34 -> 1448.32 | AL34: =L34+T34+AB34+AJ34 -> 0 | AM34: =+AK34+AL34 -> 1448.32
A35: LSLODGING | B35: 86050 | C35: MEX | D35: C.2.2 Lodging | E35: 6 | F35: Night | G35: 3 | H35: 1 | I35: 100 | J35: =E35*I35*G35 -> 1800 | K35: =J35 -> 1800 | L35: =J35-K35 -> 0 | M35: 6 | N35: Night | O35: 3 | P35: 1 | Q35: =+I35*1.04 -> 104 | R35: =M35*Q35*O35*P35 -> 1872 | S35: =R35 -> 1872 | T35: =R35-S35 -> 0 | U35: 2 | V35: Night | W35: 3 | X35: 1 | Y35: 130 | Z35: =+Y35*W35*U35*X35 -> 780 | AA35: =Z35 -> 780 | AB35: =Z35-AA35 -> 0 | AC35: 1 | AD35: Night | AE35: 3 | AF35: 1 | AG35: =Y35*$E$3 -> 135.2 | AH35: =+AG35*AE35*AC35*$H35 -> 405.6 | AI35: =AH35 -> 405.6 | AJ35: =AH35-AI35 -> 0 | AK35: =K35+S35+AA35+AI35 -> 4857.6 | AL35: =L35+T35+AB35+AJ35 -> 0 | AM35: =+AK35+AL35 -> 4857.6
A36: LSM&IE | B36: 86000 | C36: MEX | D36: C.2.3 M&IE | E36: 6 | F36: Day | G36: 4 | H36: 1 | I36: 70 | J36: =E36*I36*G36 -> 1680 | K36: =J36 -> 1680 | L36: =J36-K36 -> 0 | M36: 6 | N36: Day | O36: 4 | P36: 1 | Q36: =+I36*1.04 -> 72.8 | R36: =M36*Q36*O36*P36 -> 1747.2 | S36: =R36 -> 1747.2 | T36: =R36-S36 -> 0 | U36: 2 | V36: Day | W36: 4 | X36: 1 | Y36: 55 | Z36: 441 | AA36: =Z36 -> 441 | AB36: =Z36-AA36 -> 0 | AC36: 1 | AD36: Day | AE36: 4 | AF36: 1 | AG36: =Y36*$E$3 -> 57.2 | AH36: =+AG36*AE36*AC36*$H36 -> 228.8 | AI36: =AH36 -> 228.8 | AJ36: =AH36-AI36 -> 0 | AK36: =K36+S36+AA36+AI36 -> 4097 | AL36: =L36+T36+AB36+AJ36 -> 0 | AM36: =+AK36+AL36 -> 4097
A37: LSTRANS | B37: 86040 | C37: MEX | D37: C.2.4 Ground Transportation | E37: 1 | F37: Month | G37: 10 | H37: 1 | I37: 150 | J37: =E37*I37*G37 -> 1500 | K37: =J37 -> 1500 | L37: =J37-K37 -> 0 | M37: 1 | N37: Month | O37: 10 | P37: 1 | Q37: =+I37*1.04 -> 156 | R37: =M37*Q37*O37*P37 -> 1560 | S37: =R37 -> 1560 | T37: =R37-S37 -> 0 | U37: 1 | V37: Month | W37: 12 | X37: 1 | Y37: 78 | Z37: =+Y37*W37*U37*X37 -> 936 | AA37: =Z37 -> 936 | AB37: =Z37-AA37 -> 0 | AC37: 1 | AD37: Month | AE37: 4 | AF37: 1 | AG37: =Y37*$E$3 -> 81.12 | AH37: =+AG37*AE37*AC37*$H37 -> 324.48 | AI37: =AH37 -> 324.48 | AJ37: =AH37-AI37 -> 0 | AK37: =K37+S37+AA37+AI37 -> 4320.48 | AL37: =L37+T37+AB37+AJ37 -> 0 | AM37: =+AK37+AL37 -> 4320.48
D38: Subtotal Travel | J38: =SUM(J29:J37) -> 7135 | K38: =SUM(K29:K37) -> 7135 | L38: =SUM(L29:L37) -> 0 | R38: =SUM(R29:R37) -> 7420.4 | S38: =SUM(S29:S37) -> 7420.4 | T38: =SUM(T29:T37) -> 0 | Z38: =SUM(Z29:Z37) -> 2573 | AA38: =SUM(AA29:AA37) -> 2573 | AB38: =SUM(AB29:AB37) -> 0 | AH38: =SUM(AH29:AH37) -> 1175.2 | AI38: =SUM(AI29:AI37) -> 1175.2 | AJ38: =SUM(AJ29:AJ37) -> 0 | AK38: =SUM(AK29:AK37) -> 18303.6 | AL38: =SUM(AL29:AL37) -> 0 | AM38: =SUM(AM29:AM37) -> 18303.6
D39: D. Equipment
D40: E. Supplies
...

Sheet Color Coded Merged Budget
A1: PARTNERS OF THE AMERICAS - Mexico Migration Messaging Project (MMMP) - Cost Extension
A2: Merit and Cost of Living Increases - 5% | B2: 1.05
A3: Inflation - 4% | B3: 1.04 | L3: Budget 01 | M3: Budget 02 | N3: Budget 01+02
A5: All costs in US$ | B5: Year 1 (Oct 2023 - Sept 2024) | J5: Year 2 (October 2024 - September 2025) | R5: Year 3 (October 2025 - September 2026) | Z5: Year 4 (October 2026 - April 2027) | AH5: Total
A6: Budget Line Items | B6: No. | C6: Unit Type | D6: Freq. | E6: % | F6: Rate | G6: Total | H6: Federal | I6: Cost Share | J6: No. | K6: Unit Type | L6: Freq. | M6: % | N6: Rate | O6: Total | P6: Federal | Q6: Cost Share | R6: No. | S6: Unit Type | T6: Freq. | U6: % | V6: Rate | W6: Total | X6: Federal | Y6: Cost Share | Z6: No. | AA6: Unit Type | AB6: Freq. | AC6: % | AD6: Rate | AE6: Total | AF6: Federal | AG6: Cost Share | AH6: Federal | AI6: Cost Share | AJ6: Grand Total
A7: A. Personnel
A8: A.1 Field Staff Salaries
A9: A.1.1 Country Director Mexico | B9: 1 | C9: Month | D9: 12 | E9: 0.05 | F9: 13450 | G9: =B9*F9*D9*E9 -> 8070 | H9: =G9 -> 8070 | I9: =G9-H9 -> 0 | J9: 1 | K9: Month | L9: 12 | M9: 0.05 | N9: =+F9*1.04 -> 13988 | O9: =J9*N9*L9*M9 -> 8392.8 | P9: =O9 -> 8392.8 | Q9: =O9-P9 -> 0 | AH9: =H9+P9+X9+AF9 -> 16462.8 | AI9: =I9+Q9+Y9+AG9 -> 0 | AJ9: =+AH9+AI9 -> 16462.8
A10: A.1.2 Program Director/Coordinator | B10: 1 | C10: Month | D10: 12 | E10: 0.1 | F10: 8650 | G10: =B10*F10*D10*E10 -> 10380 | H10: =G10 -> 10380 | I10: =G10-H10 -> 0 | J10: 1 | K10: Month | L10: 12 | M10: 0.1 | N10: =F10*$B$3 -> 8996 | O10: =J10*N10*L10*M10 -> 10795.2 | P10: =O10 -> 10795.2 | Q10: =O10-P10 -> 0 | R10: 1 | S10: Month | T10: 12 | U10: 1 | V10: 4830 | W10: =R10*V10*T10*U10 -> 57960 | X10: =W10 -> 57960 | Y10: =W10-X10 -> 0 | Z10: 1 | AA10: Month | AB10: 7 | AC10: 1 | AD10: =V10*$B$2 -> 5071.5 | AE10: =Z10*AD10*AB10*AC10 -> 35500.5 | AF10: =AE10 -> 35500.5 | AG10: =AE10-AF10 -> 0 | AH10: =H10+P10+X10+AF10 -> 114635.7 | AI10: =I10+Q10+Y10+AG10 -> 0 | AJ10: =+AH10+AI10 -> 114635.7
A11: A.1.3 Senior Communications Specialist | B11: 1 | C11: Month | D11: 12 | E11: 0.3 | F11: 4100 | G11: =B11*F11*D11*E11 -> 14760 | H11: =G11 -> 14760 | I11: =G11-H11 -> 0 | J11: 1 | K11: Month | L11: 12 | M11: 0.3 | N11: =+F11*1.04 -> 4264 | O11: =J11*N11*L11*M11 -> 15350.4 | P11: =O11 -> 15350.4 | Q11: =O11-P11 -> 0 | AH11: =H11+P11+X11+AF11 -> 30110.4 | AI11: =I11+Q11+Y11+AG11 -> 0 | AJ11: =+AH11+AI11 -> 30110.4
A12: A.1.4 Communications Specialist | B12: 1 | C12: Month | D12: 12 | E12: 0.3 | F12: 3000 | G12: =B12*F12*D12*E12 -> 10800 | H12: =G12 -> 10800 | I12: =G12-H12 -> 0 | J12: 1 | K12: Month | L12: 12 | M12: 0.3 | N12: =F12*B3 -> 3120 | O12: =J12*N12*L12*M12 -> 11232 | P12: =O12 -> 11232 | Q12: =O12-P12 -> 0 | R12: 1 | S12: Month | T12: 12 | U12: 0.75 | V12: =2300*$B$2 -> 2415 | W12: =R12*V12*T12*U12 -> 21735 | X12: =W12 -> 21735 | Y12: =W12-X12 -> 0 | Z12: 1 | AA12: Month | AB12: 3 | AC12: 0.75 | AD12: =V12*$B$2 -> 2535.75 | AE12: =Z12*AD12*AB12*AC12 -> 5705.4375 | AF12: =AE12 -> 5705.4375 | AG12: =AE12-AF12 -> 0 | AH12: =H12+P12+X12+AF12 -> 49472.438 | AI12: =I12+Q12+Y12+AG12 -> 0 | AJ12: =+AH12+AI12 -> 49472.438
A13: A.1.5 Social Media Analyst | B13: 1 | C13: Month | D13: 12 | E13: 0.3 | F13: 2100 | G13: =B13*F13*D13*E13 -> 7560 | H13: =G13 -> 7560 | I13: =G13-H13 -> 0 | J13: 1 | K13: Month | L13: 12 | M13: 0.3 | N13: =+F13*1.04 -> 2184 | O13: =J13*N13*L13*M13 -> 7862.4 | P13: =O13 -> 7862.4 | Q13: =O13-P13 -> 0 | AH13: =H13+P13+X13+AF13 -> 15422.4 | AI13: =I13+Q13+Y13+AG13 -> 0 | AJ13: =+AH13+AI13 -> 15422.4
A14: A.1.6 Monitoring, Evaluation, and Learning Officer | B14: 1 | C14: Month | D14: 12 | E14: 0.25 | F14: 3100 | G14: =B14*F14*D14*E14 -> 9300 | H14: =G14 -> 9300 | I14: =G14-H14 -> 0 | J14: 1 | K14: Month | L14: 12 | M14: 0.25 | N14: =+F14*1.04 -> 3224 | O14: =J14*N14*L14*M14 -> 9672 | P14: =O14 -> 9672 | Q14: =O14-P14 -> 0 | AH14: =H14+P14+X14+AF14 -> 18972 | AI14: =I14+Q14+Y14+AG14 -> 0 | AJ14: =+AH14+AI14 -> 18972
A15: A.1.7 Finance & Administration Director | B15: 1 | C15: Month | D15: 12 | E15: 0.05 | F15: 5500 | G15: =B15*F15*D15*E15 -> 3300 | H15: =G15 -> 3300 | I15: =G15-H15 -> 0 | J15: 1 | K15: Month | L15: 12 | M15: 0.05 | N15: =+F15*1.04 -> 5720 | O15: =J15*N15*L15*M15 -> 3432 | P15: =O15 -> 3432 | Q15: =O15-P15 -> 0 | AH15: =H15+P15+X15+AF15 -> 6732 | AI15: =I15+Q15+Y15+AG15 -> 0 | AJ15: =+AH15+AI15 -> 6732
A16: A.1.8 Finance & Administration Officer | B16: 1 | C16: Month | D16: 12 | E16: 0.2 | F16: 2100 | G16: =B16*F16*D16*E16 -> 5040 | H16: =G16 -> 5040 | I16: =G16-H16 -> 0 | J16: 1 | K16: Month | L16: 12 | M16: 0.2 | N16: =F16*1.04 -> 2184 | O16: =J16*N16*L16*M16 -> 5241.6 | P16: =O16 -> 5241.6 | Q16: =O16-P16 -> 0 | R16: 1 | S16: Month | T16: 12 | U16: 0.5 | V16: =1833*$B$2 -> 1924.65 | W16: =R16*V16*T16*U16 -> 11547.9 | X16: =W16 -> 11547.9 | Y16: =W16-X16 -> 0 | Z16: 1 | AA16: Month | AB16: 6 | AC16: 0.5 | AD16: =V16*$B$2 -> 2020.8825 | AE16: =Z16*AD16*AB16*AC16 -> 6062.6475 | AF16: =AE16 -> 6062.6475 | AG16: =AE16-AF16 -> 0 | AH16: =H16+P16+X16+AF16 -> 27892.147 | AI16: =I16+Q16+Y16+AG16 -> 0 | AJ16: =+AH16+AI16 -> 27892.147
A17: A.2 HQ Staff Salaries
A18: A.2.1 Program Manager (HQ) | B18: 1 | C18: Month | D18: 12 | E18: 0.2 | F18: =55000/12 -> 4583.3333 | G18: =B18*F18*D18*E18 -> 11000 | H18: =G18 -> 11000 | I18: =G18-H18 -> 0 | J18: 1 | K18: Month | L18: 12 | M18: 0.2 | N18: =F18*1.04 -> 4766.6667 | O18: =J18*N18*L18*M18 -> 11440 | P18: =O18 -> 11440 | Q18: =O18-P18 -> 0 | R18: 1 | S18: Month | T18: 12 | U18: 0.05 | V18: =10000*$B$2 -> 10500 | W18: =R18*V18*T18*U18 -> 6300 | X18: =W18 -> 6300 | Y18: =W18-X18 -> 0 | Z18: 1 | AA18: Month | AB18: 7 | AC18: 0.05 | AD18: =V18*$B$2 -> 11025 | AE18: =Z18*AD18*AB18*AC18 -> 3858.75 | AF18: =AE18 -> 3858.75 | AG18: =AE18-AF18 -> 0 | AH18: =H18+P18+X18+AF18 -> 32598.75 | AI18: =I18+Q18+Y18+AG18 -> 0 | AJ18: =+AH18+AI18 -> 32598.75
A19: A.2.2. Program Officer (HQ) | B19: 0 | G19: =B19*F19*D19*E19 -> 0 | H19: =G19 -> 0 | I19: =G19-H19 -> 0 | J19: 1 | K19: Month | L19: 12 | M19: 0.25 | N19: 5512 | O19: =J19*N19*L19*M19 -> 16536 | P19: =O19 -> 16536 | Q19: =O19-P19 -> 0 | R19: 1 | S19: Month | T19: 12 | U19: 0.25 | V19: =N19*$B$2 -> 5787.6 | W19: =R19*V19*T19*U19 -> 17362.8 | X19: =W19 -> 17362.8 | Y19: =W19-X19 -> 0 | Z19: 1 | AA19: Month | AB19: 7 | AC19: 0.2 | AD19: =V19*$B$2 -> 6076.98 | AE19: =Z19*AD19*AB19*AC19 -> 8507.772 | AF19: =AE19 -> 8507.772 | AG19: =AE19-AF19 -> 0 | AH19: =H19+P19+X19+AF19 -> 42406.572 | AI19: =I19+Q19+Y19+AG19 -> 0 | AJ19: =+AH19+AI19 -> 42406.572
A20: Subtotal Personnel | G20: =SUM(G9:G19) -> 80210 | H20: =SUM(H9:H19) -> 80210 | I20: =SUM(I9:I19) -> 0 | O20: =SUM(O9:O19) -> 99954.4 | P20: =SUM(P9:P19) -> 99954.4 | Q20: =SUM(Q9:Q19) -> 0 | W20: =SUM(W9:W19) -> 114905.7 | X20: =SUM(X9:X19) -> 114905.7 | Y20: =SUM(Y9:Y19) -> 0 | AE20: =SUM(AE9:AE19) -> 59635.107 | AF20: =SUM(AF9:AF19) -> 59635.107 | AG20: =SUM(AG9:AG19) -> 0 | AH20: =SUM(AH9:AH19) -> 354705.21 | AI20: =SUM(AI9:AI19) -> 0 | AJ20: =SUM(AJ9:AJ19) -> 354705.21
A21: B. Fringe Benefits
A22: B.1 HQ Fringe Benefits
A23: B.1.1 U.S.-Based Personnel Fringe Benefits | C23: % | E23: 0.2347 | G23: =$E23*SUM(G18:G19) -> 2581.7 | H23: =G23 -> 2581.7 | I23: 0 | K23: % | M23: 0.2347 | O23: =M23*SUM(O18:O19) -> 6565.9672 | P23: =O23 -> 6565.9672 | Q23: 0 | S23: % | U23: 0.2347 | W23: =U23*SUM(W18:W19) -> 5553.6592 | X23: =W23 -> 5553.6592 | Y23: 0 | AA23: % | AC23: 0.2347 | AE23: =AC23*SUM(AE18:AE19) -> 2902.4227 | AF23: =AE23 -> 2902.4227 | AG23: 0 | AH23: =H23+P23+X23+AF23 -> 17603.749 | AI23: =I23+Q23+Y23+AG23 -> 0 | AJ23: =+AH23+AI23 -> 17603.749
A24: B.2 Field Fringe Benefits
A25: B.2.1 Mexico Field Staff Fringe Benefits | C25: % | E25: 0.3671 | G25: =$E25*SUM(G9:G16) -> 25406.991 | H25: =G25 -> 25406.991 | I25: 0 | K25: % | M25: =E25 -> 0.3671 | O25: =M25*SUM(O9:O16) -> 26423.271 | P25: =O25 -> 26423.271 | Q25: 0 | S25: % | U25: 0.5281 | W25: =U25*SUM(W10:W16) -> 48185.375 | X25: =W25 -> 48185.375 | Y25: 0 | AA25: % | AC25: 0.5281 | AE25: =AC25*SUM(AE10:AE16) -> 24962.54 | AF25: =AE25 -> 24962.54 | AG25: 0 | AH25: =H25+P25+X25+AF25 -> 124978.18 | AI25: =I25+Q25+Y25+AG25 -> 0 | AJ25: =+AH25+AI25 -> 124978.18
A26: Subtotal Fringe Benefits | G26: =SUM(G23:G25) -> 27988.691 | H26: =SUM(H23:H25) -> 27988.691 | I26: =SUM(I23:I25) -> 0 | O26: =SUM(O23:O25) -> 32989.238 | P26: =SUM(P23:P25) -> 32989.238 | Q26: =SUM(Q23:Q25) -> 0 | W26: =SUM(W23:W25) -> 53739.035 | X26: =SUM(X23:X25) -> 53739.035 | Y26: =SUM(Y23:Y25) -> 0 | AE26: =SUM(AE23:AE25) -> 27864.962 | AF26: =SUM(AF23:AF25) -> 27864.962 | AG26: =SUM(AG23:AG25) -> 0 | AH26: =SUM(AH23:AH25) -> 142581.93 | AI26: =SUM(AI23:AI25) -> 0 | AJ26: =SUM(AJ23:AJ25) -> 142581.93
A27: C. Travel
A28: C.1 HQ Staff International Travel
A29: C.1.1 International Airfare (DC-MX) | B29: 1 | C29: Flight | D29: 1 | E29: 1 | F29: 700 | G29: =B29*F29*D29 -> 700 | H29: =G29 -> 700 | I29: =G29-H29 -> 0 | J29: 1 | K29: Flight | L29: 1 | M29: 1 | N29: =+F29*1.04 -> 728 | O29: =J29*N29*L29*M29 -> 728 | P29: =O29 -> 728 | Q29: =O29-P29 -> 0 | AH29: =H29+P29+X29+AF29 -> 1428 | AI29: =I29+Q29+Y29+AG29 -> 0 | AJ29: =+AH29+AI29 -> 1428
A30: C.1.2 Ground Transportation | B30: 1 | C30: Trip | D30: 1 | E30: 1 | F30: 100 | G30: =B30*F30*D30 -> 100 | H30: =G30 -> 100 | I30: =G30-H30 -> 0 | J30: 1 | K30: Trip | L30: 1 | M30: 1 | N30: =+F30*1.04 -> 104 | O30: =J30*N30*L30*M30 -> 104 | P30: =O30 -> 104 | Q30: =O30-P30 -> 0 | AH30: =H30+P30+X30+AF30 -> 204 | AI30: =I30+Q30+Y30+AG30 -> 0 | AJ30: =+AH30+AI30 -> 204
A31: C.1.3 Lodging | B31: 1 | C31: Night | D31: 4 | E31: 1 | F31: 120 | G31: =B31*F31*D31 -> 480 | H31: =G31 -> 480 | I31: =G31-H31 -> 0 | J31: 1 | K31: Night | L31: 4 | M31: 1 | N31: =+F31*1.04 -> 124.8 | O31: =J31*N31*L31*M31 -> 499.2 | P31: =O31 -> 499.2 | Q31: =O31-P31 -> 0 | AH31: =H31+P31+X31+AF31 -> 979.2 | AI31: =I31+Q31+Y31+AG31 -> 0 | AJ31: =+AH31+AI31 -> 979.2
A32: C.1.4 M&IE | B32: 1 | C32: Day | D32: 5 | E32: 1 | F32: 95 | G32: =B32*F32*D32 -> 475 | H32: =G32 -> 475 | I32: =G32-H32 -> 0 | J32: 1 | K32: Day | L32: 5 | M32: 1 | N32: =+F32*1.04 -> 98.8 | O32: =J32*N32*L32*M32 -> 494 | P32: =O32 -> 494 | Q32: =O32-P32 -> 0 | AH32: =H32+P32+X32+AF32 -> 969 | AI32: =I32+Q32+Y32+AG32 -> 0 | AJ32: =+AH32+AI32 -> 969
A33: C.2 Local Staff In-Country Travel to Target Geographic Regions
A34: C.2.1 Domestic Airfare | B34: 2 | C34: Flight | D34: 1 | E34: 1 | F34: 200 | G34: =B34*F34*D34 -> 400 | H34: =G34 -> 400 | I34: =G34-H34 -> 0 | J34: 2 | K34: Flight | L34: 1 | M34: 1 | N34: =+F34*1.04 -> 208 | O34: =J34*N34*L34*M34 -> 416 | P34: =O34 -> 416 | Q34: =O34-P34 -> 0 | R34: 2 | S34: Flight | T34: 1 | U34: 1 | V34: 208 | W34: =+V34*T34*R34*U34 -> 416 | X34: =W34 -> 416 | Y34: =W34-X34 -> 0 | Z34: 1 | AA34: Flight | AB34: 1 | AC34: 1 | AD34: =V34*$B$3 -> 216.32 | AE34: =+AD34*AB34*Z34*$E34 -> 216.32 | AF34: =AE34 -> 216.32 | AG34: =AE34-AF34 -> 0 | AH34: =H34+P34+X34+AF34 -> 1448.32 | AI34: =I34+Q34+Y34+AG34 -> 0 | AJ34: =+AH34+AI34 -> 1448.32
A35: C.2.2 Lodging | B35: 6 | C35: Night | D35: 3 | E35: 1 | F35: 100 | G35: =B35*F35*D35 -> 1800 | H35: =G35 -> 1800 | I35: =G35-H35 -> 0 | J35: 6 | K35: Night | L35: 3 | M35: 1 | N35: =+F35*1.04 -> 104 | O35: =J35*N35*L35*M35 -> 1872 | P35: =O35 -> 1872 | Q35: =O35-P35 -> 0 | R35: 2 | S35: Night | T35: 3 | U35: 1 | V35: 130 | W35: =+V35*T35*R35*U35 -> 780 | X35: =W35 -> 780 | Y35: =W35-X35 -> 0 | Z35: 1 | AA35: Night | AB35: 3 | AC35: 1 | AD35: =V35*$B$3 -> 135.2 | AE35: =+AD35*AB35*Z35*$E35 -> 405.6 | AF35: =AE35 -> 405.6 | AG35: =AE35-AF35 -> 0 | AH35: =H35+P35+X35+AF35 -> 4857.6 | AI35: =I35+Q35+Y35+AG35 -> 0 | AJ35: =+AH35+AI35 -> 4857.6
A36: C.2.3 M&IE | B36: 6 | C36: Day | D36: 4 | E36: 1 | F36: 70 | G36: =B36*F36*D36 -> 1680 | H36: =G36 -> 1680 | I36: =G36-H36 -> 0 | J36: 6 | K36: Day | L36: 4 | M36: 1 | N36: =+F36*1.04 -> 72.8 | O36: =J36*N36*L36*M36 -> 1747.2 | P36: =O36 -> 1747.2 | Q36: =O36-P36 -> 0 | R36: 2 | S36: Day | T36: 4 | U36: 1 | V36: 55 | W36: 441 | X36: =W36 -> 441 | Y36: =W36-X36 -> 0 | Z36: 1 | AA36: Day | AB36: 4 | AC36: 1 | AD36: =V36*$B$3 -> 57.2 | AE36: =+AD36*AB36*Z36*$E36 -> 228.8 | AF36: =AE36 -> 228.8 | AG36: =AE36-AF36 -> 0 | AH36: =H36+P36+X36+AF36 -> 4097 | AI36: =I36+Q36+Y36+AG36 -> 0 | AJ36: =+AH36+AI36 -> 4097
A37: C.2.4 Ground Transportation | B37: 1 | C37: Month | D37: 10 | E37: 1 | F37: 150 | G37: =B37*F37*D37 -> 1500 | H37: =G37 -> 1500 | I37: =G37-H37 -> 0 | J37: 1 | K37: Month | L37: 10 | M37: 1 | N37: =+F37*1.04 -> 156 | O37: =J37*N37*L37*M37 -> 1560 | P37: =O37 -> 1560 | Q37: =O37-P37 -> 0 | R37: 1 | S37: Month | T37: 12 | U37: 1 | V37: 78 | W37: =+V37*T37*R37*U37 -> 936 | X37: =W37 -> 936 | Y37: =W37-X37 -> 0 | Z37: 1 | AA37: Month | AB37: 4 | AC37: 1 | AD37: =V37*$B$3 -> 81.12 | AE37: =+AD37*AB37*Z37*$E37 -> 324.48 | AF37: =AE37 -> 324.48 | AG37: =AE37-AF37 -> 0 | AH37: =H37+P37+X37+AF37 -> 4320.48 | AI37: =I37+Q37+Y37+AG37 -> 0 | AJ37: =+AH37+AI37 -> 4320.48
A38: Subtotal Travel | G38: =SUM(G29:G37) -> 7135 | H38: =SUM(H29:H37) -> 7135 | I38: =SUM(I29:I37) -> 0 | O38: =SUM(O29:O37) -> 7420.4 | P38: =SUM(P29:P37) -> 7420.4 | Q38: =SUM(Q29:Q37) -> 0 | W38: =SUM(W29:W37) -> 2573 | X38: =SUM(X29:X37) -> 2573 | Y38: =SUM(Y29:Y37) -> 0 | AE38: =SUM(AE29:AE37) -> 1175.2 | AF38: =SUM(AF29:AF37) -> 1175.2 | AG38: =SUM(AG29:AG37) -> 0 | AH38: =SUM(AH29:AH37) -> 18303.6 | AI38: =SUM(AI29:AI37) -> 0 | AJ38: =SUM(AJ29:AJ37) -> 18303.6
A39: D. Equipment
A40: E. Supplies
A41: E.1 Office Supplies | B41: 1 | C41: Month | D41: 12 | E41: 1 | F41: 50 | G41: =B41*F41*D41*E41 -> 600 | H41: =G41 -> 600 | I41: =G41-H41 -> 0 | J41: 1 | K41: Month | L41: 12 | M41: 1 | N41: =F41*$B$3 -> 52 | O41: =J41*N41*L41*M41 -> 624 | P41: =O41 -> 624 | Q41: =O41-P41 -> 0 | R41: 1 | S41: Month | T41: 12 | U41: 1 | V41: 31.2 | W41: =R41*V41*T41*U41 -> 374.4 | X41: =W41 -> 374.4 | Y41: =W41-X41 -> 0 | Z41: 1 | AA41: Month | AB41: 6 | AC41: 1 | AD41: =V41*$B$3 -> 32.448 | AE41: =Z41*AD41*AB41*AC41 -> 194.688 | AF41: =AE41 -> 194.688 | AG41: =AE41-AF41 -> 0 | AH41: =H41+P41+X41+AF41 -> 1793.088 | AI41: =I41+Q41+Y41+AG41 -> 0 | AJ41: =+AH41+AI41 -> 1793.088
...
