Workbook

Sheet Instrucciones
B3: Presupuesto
B4: Composición vertical
B5: Verticalmente se encuentran las siguientes seis (6) grupos presupuestales de un dígito que van del 1 al 6. El 1 y 2 siempre serán requeridos, aunque del 3 a la 6 deberán ser consultadas antes con COSUDE. Su orden o denominación no podrán ser modificados. Cada uno de estos grupo incluye partidas (2 dígitos o 1 decimal), los cuales a su vez incluyen subpartidas (3 dígitos o 2 decimales). Se debe calcular al final el total a nivel de grupo presupuestal y de partida.
B6: GRUPOS PRESUPUESTALES
B7: 1. Gestión del proyecto: Incluye los rubros del personal del proyecto, tanto las personas que están directamente involucradas directamente en implementar el proyecto (Oficial, asistente, tutores de protección, personal MERA) y personal que da soporte administrativo, financiero, logístico y demás a la operación sin incluir ningún personal expatriado. De igual manera incluye los gastos de viaje (alojamiento, transporte, alimentación, viáticos) del personal que realizan seguimiento técnico y actividades transversales y complementarias, capacitaciones al personal material pedagógico, locación, hospedaje, transporte, refrigerios, visibilidad (camiseta, pegatina, valla, pendón, espacio radial, fotografía, vídeo, cuaderno, afiche, publicación, estudios de caso y gestión de partes interesadas Advocacy), seguimiento – evaluación – sistematización, compra de equipos para la oficina del proyecto (Celulares, radios, equipo de computador), funcionamiento de la oficina (teléfonos, celulares, arriendo material de oficina y sistema de seguridad) para las personas en los lugares de implementación.
B8: 2. Inversiones: Inversiones del proyecto: Incluye los rubros de capacitaciones/actividades a la población meta los cuales comprenden un costo en desplazamiento importante a las distancias y material pedagógico, hospedaje, transporte, refrigerios); así mismo, infraestructura destinada a la población meta (adecuaciones, instalaciones, dotaciones, rehabilitaciones, mantenimiento, herramientas, terreno, arriendo espacios comunitario), componente nutricional en cada una de las actividades, componente lúdico - cultural (materiales de actividad recreativa, actividad deportiva, actividad cultural), estudios y/o recolección de datos (sectores salud, vivienda y/o educación). Visitas de seguimiento y gestión de casos (transportes de seguimiento, transportes de atención a casos urgentes de requerimiento de protección y materiales o cualquier tipo de recurso relaciona a atender la población meta. Intercambio en eventos de discusión e iniciativas de inversión especifica generadas por la población meta y sus intereses.
B9: 3. No aplica: Debe dejarse vacío. Se puede ocultar o eliminar sin cambiar la numeración de los siguientes
B10: 4. Auditoría: indica el valor para ejecutar una auditoría externa al proyecto. COSUDE anunciará si es necesaria según las condiciones del proyecto.
B11: 5. Monitoreo y seguimiento: Incluye los rubros de evaluación externa y sistematización (si se considera pertinente para el proyecto).
B12: Partidas o Rubros (2 dígitos o un decimal)
B13: Las partidas permiten clasificar mejor los gastos de inversiones y gestiones principalmente, por lo que no suelen usarse en otros grupos presupuestales. Existen unas categorías ya propuestas que podrían ser empleadas según la conveniencia y pertinencia para el proyecto en cuestión o modificadas al momento de construir el presupuesto, en cuyo caso deben ser enviadas a aprobación de COSUDE. Llevan 2 dígitos separados de un punto medio, por lo que también se habla de un decimal. (Ej: 1.1, 1.2, 2.1, etc.), aunque en casos excepcionales después del punto podría llegar a haber 2 dígitos (Ej: 1.10, 2.12, etc.) El primer dígito debe coincidir con el grupo presupuestal al que pertence. Los cambios en los montos asignados a este nivel que excedan el 10% del valor vigente deben ser consultados necesariamente con COSUDE.
B14: Sub-partidas o Sub-rubros (3 dígitos o dos decimales)
... B64: El propósito de este anexo es ver la composición de los activos y de los pasivos, según su tipo de liquidez. No se incluye patrimonio, pues cualquier sobrante o saldo no ejecutado debe ser devuelto a COSUDE. Dicho esto, el objetivo del balance es ver si el saldo en banco, cajas o cuentas por cobrar es debido a un sobrante en el proyecto -en cuyo caso, el monto debe coincidir con saldo de ingresos recibidos-, o si este será destinado a cuentas por pagar que hayan sido causadas. Debe tenerse en cuenta que para informes finales, no debería haber gastos causados pero no pagados.

Sheet Presupuesto original
D1: Anexo 1. Formato COSUDE Bogotá para la presentación del presupuesto de un proyecto.
D2: Nombre de la entidad ejecutora: Fundación Partners of the Americas
D3: Nombre del proyecto: PEP TUTOR
D4: Período que cubre el proyecto: 15/11/2024 al 15/12/2025
D5: Total período en meses: 13
D6: Efecto 1: | E6: =+N62 -> 88043307
A7: Program Dept.: | B7: 19400 | D7: Efecto 2: | E7: =+P62 -> 91678671
A8: Funder-Grant: | B8: COSUDE1 | D8: Efecto 3: | E8: =+R62 -> 1.5394767e+08
D9: Efecto 4: | E9: =+T62 -> 1.33997e+08
D11: Presupesto en COP (Pesos Colombianos)
F12: COSTOS TOTALES | L12: COSTOS INDIRECTOS Y POR EFECTOS (DIRECTOS) | V12: COSUDE | X12: Partners of the Americas | Z12: Otros | AB12: Comunidad | AF12: Exchange Rate | AG12: 4179.77
A13: Budget Code | B13: Account Code | C13: Country Code | D13: No. | E13: RUBROS PRESUPUESTALES | F13: Costo Unitario | G13: Unidad | H13: Cantidad | I13: Duración | K13: Costo Total | L13: C. Ad. | M13: % C. Ad. | N13: Efecto 1 | O13: % Efecto 1 | P13: Efecto 2 | Q13: % Efecto 2 | R13: Efecto 3 | S13: % Efecto 3 | T13: Efecto 4 | U13: % Efecto 4 | V13: Total COSUDE in COP | W13: % COSUDE | X13: ONG solic. | Y13: % ONG | Z13: Otros | AA13: % Otros | AB13: Comunidad | AC13: % Comun. | AE13: Total COSUDE in USD
I14: Unidad | J14: Cantidad
D15: 1 | E15: GESTIONES / TOTAL | K15: =K17+K23+K27+K32+K33+K35+K38+K28 -> 4.1886465e+08 | L15: 0 | N15: =N17+N23+N27+N32+N33+N35+N38+N28 -> 80973307 | O15: =N15/$K$15 -> 0.19331617 | P15: =P17+P23+P27+P32+P33+P35+P38+P28 -> 74408671 | Q15: =P15/$K$15 -> 0.17764371 | R15: =R17+R23+R27+R32+R33+R35+R38+R28 -> 1.3398567e+08 | S15: =R15/$K$15 -> 0.31987819 | T15: =T17+T23+T27+T32+T33+T35+T38+T28 -> 1.29497e+08 | U15: =T15/$K$15 -> 0.30916193 | V15: =V17+V23+V27+V32+V33+V35+V38+V28 -> 3.1674363e+08 | W15: =V15/$K$15 -> 0.75619566 | X15: =X17+X23+X27+X32+X33+X35+X38+X28 -> 1.0212102e+08 | Y15: =X15/$K$15 -> 0.24380434 | AE15: =AE17+AE23+AE27+AE32+AE33+AE35+AE38+AE28 -> 75780.157
E16: Porcentaje | K16: =+K15/K62 -> 0.84942616 | N16: =+N15/N62 -> 0.91969861 | P16: =+P15/P62 -> 0.81162467 | R16: =+R15/R62 -> 0.87033256 | T16: =+T15/T62 -> 0.96641716 | V16: =+V15/V62 -> 0.8142639 | X16: =+X15/X62 -> 0.98079158
D17: 1.1 | E17: Personal operativo | K17: =SUM(K18:K22) -> 3.637495e+08 | N17: =SUM(N18:N22) -> 72421522 | O17: =+N17/$K17 -> 0.19909724 | P17: =SUM(P18:P22) -> 65856886 | Q17: =+P17/$K17 -> 0.1810501 | R17: =SUM(R18:R22) -> 1.1497988e+08 | S17: =+R17/$K17 -> 0.31609632 | T17: =SUM(T18:T22) -> 1.1049122e+08 | U17: =+T17/$K17 -> 0.30375633 | V17: =SUM(V18:V22) -> 2.8486154e+08 | W17: =+V17/$K17 -> 0.78312557 | X17: =SUM(X18:X22) -> 78887968 | Y17: =+X17/$K17 -> 0.21687443 | AE17: =SUM(AE18:AE22) -> 68152.443
A18: PERSNL-TEC | B18: 70000 | C18: COL2 | D18: 1.1.1 | E18: Director Tecnico (Dedicación 30%) | F18: =(12000000+4832400)*30% -> 5049720 | G18: Director | H18: 1 | I18: Mes | J18: 13 | K18: =F18*H18*J18 -> 65646360 | N18: =+K18*O18 -> 26258544 | O18: 0.4 | P18: =+K18*Q18 -> 19693908 | Q18: 0.3 | R18: =+K18*S18 -> 9846954 | S18: 0.15 | T18: =+K18*U18 -> 9846954 | U18: 0.15 | V18: =+K18*W18 -> 39387816 | W18: 0.6 | X18: =+K18*Y18 -> 26258544 | Y18: 0.4 | AE18: =V18/$AG$12 -> 9423.441
A19: PERSNL-COR | B19: 70000 | C19: COL2 | D19: 1.1.2 | E19: Coordinador tecnico nacional (Dedicación 100%) | F19: =7000000+2818932.96 -> 9818933 | G19: Coordinador | H19: 1 | I19: Mes | J19: 9 | K19: =F19*H19*J19 -> 88370397 | N19: =+K19*O19 -> 22092599 | O19: 0.25 | P19: =+K19*Q19 -> 22092599 | Q19: 0.25 | R19: =+K19*S19 -> 22092599 | S19: 0.25 | T19: =+K19*U19 -> 22092599 | U19: 0.25 | V19: =+K19*W19 -> 88370397 | W19: 1 | AE19: =V19/$AG$12 -> 21142.407
A20: IN-KIND | B20: 96000 | C20: COL2 | D20: 1.1.3 | E20: Asesor tecnico (dedicación 15%) | F20: =(17600000+7087568.04)*15% -> 3703135.2 | G20: Asesor | H20: 1 | I20: Mes | J20: 13 | K20: =F20*H20*J20 -> 48140758 | N20: =+K20*O20 -> 24070379 | O20: 0.5 | P20: =+K20*Q20 -> 24070379 | Q20: 0.5 | X20: =+K20*Y20 -> 48140758 | Y20: 1
A21: PERSNL-GES | B21: 70000 | C21: COL2 | D21: 1.1.4 | E21: Gestores territoriales (Dedicación 100%) | F21: =4000000+1610833 -> 5610833 | G21: Gestores | H21: 4 | I21: Mes | J21: 7 | K21: =F21*H21*J21 -> 157103324 | R21: =+K21*S21 -> 78551662 | S21: 0.5 | T21: =+K21*U21 -> 78551662 | U21: 0.5 | V21: =+K21*W21 -> 157103324 | W21: 1 | AE21: =V21/$AG$12 -> 37586.595
A22: IN-KIND | B22: 96000 | C22: COL2 | D22: 1.1.5 | E22: Oficial territorial Cartagena (Dedicación 20%) | F22: =(4000000+1610833)*20% -> 1122166.6 | G22: Oficial | H22: 1 | I22: Mes | J22: 4 | K22: =F22*H22*J22 -> 4488666.4 | R22: =K22 -> 4488666.4 | S22: 1 | X22: =R22 -> 4488666.4 | Y22: 1
D23: 1.2 | E23: Personal administrativo | K23: =SUM(K24:K26) -> 23307142 | N23: =SUM(N24:N26) -> 5826785.5 | O23: =+N23/$K23 -> 0.25 | P23: =SUM(P24:P26) -> 5826785.5 | Q23: =+P23/$K23 -> 0.25 | R23: =SUM(R24:R26) -> 5826785.5 | S23: =+R23/$K23 -> 0.25 | T23: =SUM(T24:T26) -> 5826785.5 | U23: =+T23/$K23 -> 0.25 | V23: =SUM(V24:V26) -> 9624089.2 | W23: =+V23/$K23 -> 0.41292447 | X23: =SUM(X24:X26) -> 13683053 | Y23: =+X23/$K23 -> 0.58707553 | AE23: =SUM(AE24:AE26) -> 2302.5404
A24: PERSNL-AST | B24: 70000 | C24: COL2 | D24: 1.2.1 | E24: Asistente Administrativo (Dedicación 30%) | F24: =(2311000+1006733)*30% -> 995319.9 | G24: Asistente | H24: 1 | I24: Mes | J24: 13 | K24: =F24*H24*J24 -> 12939159 | N24: =+K24*O24 -> 3234789.7 | O24: 0.25 | P24: =+K24*Q24 -> 3234789.7 | Q24: 0.25 | R24: =+K24*S24 -> 3234789.7 | S24: 0.25 | T24: =K24*U24 -> 3234789.7 | U24: 0.25 | V24: =+K24*W24 -> 6469579.3 | W24: 0.5 | X24: =+K24*Y24 -> 6469579.3 | Y24: 0.5 | AE24: =V24/$AG$12 -> 1547.8314
A25: PERSNL-F&A | B25: 70000 | C25: COL2 | D25: 1.2.2 | E25: Coordinador Financiero y de Operaciones (Dedicación 15%) | F25: =+(7600000+2915033)*15% -> 1577254.9 | G25: Coordinador | H25: 1 | I25: Mes | J25: 4 | K25: =F25*H25*J25 -> 6309019.8 | N25: =+K25*O25 -> 1577254.9 | O25: 0.25 | P25: =+K25*Q25 -> 1577254.9 | Q25: 0.25 | R25: =+K25*S25 -> 1577254.9 | S25: 0.25 | T25: =K25*U25 -> 1577254.9 | U25: 0.25 | V25: =+K25*W25 -> 3154509.9 | W25: 0.5 | X25: =+K25*Y25 -> 3154509.9 | Y25: 0.5 | AE25: =V25/$AG$12 -> 754.70897
A26: IN-KIND | B26: 96000 | C26: COL2 | D26: 1.2.3 | E26: Oficial RR HH (Dedicación 20%) | F26: =+(3617124+1456580.24)*20% -> 1014740.8 | G26: Oficial | H26: 1 | I26: Mes | J26: 4 | K26: =F26*H26*J26 -> 4058963.4 | N26: =+K26*O26 -> 1014740.8 | O26: 0.25 | P26: =+K26*Q26 -> 1014740.8 | Q26: 0.25 | R26: =+K26*S26 -> 1014740.8 | S26: 0.25 | T26: =K26*U26 -> 1014740.8 | U26: 0.25 | V26: =+K26*W26 -> 0 | X26: =+K26*Y26 -> 4058963.4 | Y26: 1 | AE26: =+T26*AF26 -> 0
D27: 1.3 | E27: Consultores | K27: 0 | N27: 0 | O27: 0 | P27: 0 | Q27: 0 | R27: 0 | S27: 0 | T27: 0 | U27: 0 | V27: 0 | W27: 0 | X27: 0 | Y27: 0 | AE27: 0
D28: 1.4 | E28: Gastos viaje del personal + consultores | K28: =SUM(K29:K31) -> 20608000 | N28: =SUM(N29:N31) -> 0 | O28: =+N28/$K28 -> 0 | P28: =SUM(P29:P31) -> 0 | Q28: =+P28/$K28 -> 0 | R28: =SUM(R29:R31) -> 10304000 | S28: =+R28/$K28 -> 0.5 | T28: =SUM(T29:T31) -> 10304000 | U28: =+T28/$K28 -> 0.5 | V28: =SUM(V29:V31) -> 20608000 | W28: =+V28/$K28 -> 1 | X28: =SUM(X29:X31) -> 0 | Y28: =+X28/$K28 -> 0 | AE28: =SUM(AE29:AE31) -> 4930.4148
A29: STFTRAVEL | B29: 86040 | C29: COL2 | D29: 1.4.1 | E29: Tiquetes aéreos | F29: 850000 | G29: Viaje | H29: 1 | I29: Viaje | J29: 8 | K29: =F29*H29*J29 -> 6800000 | R29: =+K29*S29 -> 3400000 | S29: 0.5 | T29: =+K29*U29 -> 3400000 | U29: 0.5 | V29: =+K29*W29 -> 6800000 | W29: 1 | AE29: =V29/$AG$12 -> 1626.8838
A30: STFCN DIEM | B30: 86050 (M&IE)/ 86030 (Lodging)/ 86000 (Transport) | C30: COL2 | D30: 1.4.2 | E30: Dietas, transporte y hospedaje | F30: 826000 | G30: Viaje | H30: 1 | I30: Viaje | J30: 8 | K30: =F30*H30*J30 -> 6608000 | R30: =+K30*S30 -> 3304000 | S30: 0.5 | T30: =+K30*U30 -> 3304000 | U30: 0.5 | V30: =+K30*W30 -> 6608000 | W30: 1 | AE30: =V30/$AG$12 -> 1580.9482
A31: LOCAL TRVL | B31: 86000 | C31: COL2 | D31: 1.4.3 | E31: Desplazamiento local implementación para gestores territoriales | F31: 300000 | G31: Viaje | H31: 4 | I31: Viaje | J31: 6 | K31: =F31*H31*J31 -> 7200000 | R31: =+K31*S31 -> 3600000 | S31: 0.5 | T31: =+K31*U31 -> 3600000 | U31: 0.5 | V31: =+K31*W31 -> 7200000 | W31: 1 | AE31: =V31/$AG$12 -> 1722.5828
D32: 1.5 | E32: Capacitaciones al personal | K32: 0 | N32: 0 | O32: 0 | P32: 0 | Q32: 0 | R32: 0 | S32: 0 | T32: 0 | U32: 0 | V32: 0 | W32: 0 | X32: 0 | Y32: 0 | AE32: 0
D33: 1.6 | E33: Visibilidad | K33: =SUM(K34) -> 300000 | N33: =SUM(N34) -> 0 | O33: =+N33/$K33 -> 0 | P33: =SUM(P34) -> 0 | Q33: =+P33/$K33 -> 0 | R33: =SUM(R34) -> 150000 | S33: =+R33/$K33 -> 0.5 | T33: =SUM(T34) -> 150000 | U33: =+T33/$K33 -> 0.5 | V33: =SUM(V34) -> 300000 | W33: =+V33/$K33 -> 1 | X33: =SUM(X34) -> 0 | Y33: =+X33/$K33 -> 0 | AE33: =SUM(AE34) -> 71.774284
A34: MATL | B34: 82420 | C34: COL2 | D34: 1.6.2 | E34: Material POP (visibilidad personal operativo) | F34: 50000 | G34: Unidad | H34: 6 | I34: Unidad | J34: 1 | K34: =F34*H34*J34 -> 300000 | R34: =+K34*S34 -> 150000 | S34: 0.5 | T34: =+K34*U34 -> 150000 | U34: 0.5 | V34: =+K34*W34 -> 300000 | W34: 1 | AE34: =V34/$AG$12 -> 71.774284
D35: 1.7 | E35: Funcionamiento de la Oficina | K35: =SUM(K36:K37) -> 9550000 | N35: =SUM(N36:N37) -> 2387500 | O35: =+N35/$K35 -> 0.25 | P35: =SUM(P36:P37) -> 2387500 | Q35: =+P35/$K35 -> 0.25 | R35: =SUM(R36:R37) -> 2387500 | S35: =+R35/$K35 -> 0.25 | T35: =SUM(T36:T37) -> 2387500 | U35: =+T35/$K35 -> 0.25 | V35: =SUM(V36:V37) -> 0 | W35: =+V35/$K35 -> 0 | X35: =SUM(X36:X37) -> 9550000 | Y35: =+X35/$K35 -> 1 | AE35: =SUM(AE36:AE37) -> 0
A36: IN-KIND | B36: 96000 | C36: COL2 | D36: 1.7.1 | E36: Alquiler Puesto de trabajo (Coordinador Tecnico Nacional) | F36: 950000 | G36: Unidad | H36: 1 | I36: Mes | J36: 9 | K36: =F36*H36*J36 -> 8550000 | N36: =+K36*O36 -> 2137500 | O36: 0.25 | P36: =+K36*Q36 -> 2137500 | Q36: 0.25 | R36: =K36*S36 -> 2137500 | S36: 0.25 | T36: =K36*U36 -> 2137500 | U36: 0.25 | W36: 0.25 | X36: =+K36*Y36 -> 8550000 | Y36: 1
A37: IN-KIND | B37: 96000 | C37: COL2 | D37: 1.7.2 | E37: Alquiler de equipos de computo (para el uso de los 4 Gestores territoriales y Coordinador Tecnico Nacional) | F37: 200000 | G37: unidad | H37: 1 | I37: Persona | J37: 5 | K37: =F37*H37*J37 -> 1000000 | N37: =+K37*O37 -> 250000 | O37: 0.25 | P37: =+K37*Q37 -> 250000 | Q37: 0.25 | R37: =K37*S37 -> 250000 | S37: 0.25 | T37: =K37*U37 -> 250000 | U37: 0.25 | W37: 0.25 | X37: =+K37*Y37 -> 1000000 | Y37: 1
D38: 1.8 | E38: Seguimiento, evaluación, sistematización | K38: =SUM(K39) -> 1350000 | N38: =SUM(N39) -> 337500 | O38: =+N38/$K38 -> 0.25 | P38: =SUM(P39) -> 337500 | Q38: =+P38/$K38 -> 0.25 | R38: =SUM(R39) -> 337500 | S38: =+R38/$K38 -> 0.25 | T38: =SUM(T39) -> 337500 | U38: =+T38/$K38 -> 0.25 | V38: =SUM(V39) -> 1350000 | W38: =+V38/$K38 -> 1 | X38: =SUM(X39) -> 0 | Y38: =+X38/$K38 -> 0 | AE38: =SUM(AE39) -> 322.98428
A39: DIAGRAM | B39: 85300 | C39: COL2 | D39: 1.8.1 | E39: Diagramación e impresión documento de buenas práctias y barreras (DOC a COSUDE) | F39: 1350000 | G39: Producto | H39: 1 | I39: Producto | J39: 1 | K39: =F39*H39*J39 -> 1350000 | N39: =+K39*O39 -> 337500 | O39: 0.25 | P39: =+K39*Q39 -> 337500 | Q39: 0.25 | R39: =+K39*S39 -> 337500 | S39: 0.25 | T39: =+K39*U39 -> 337500 | U39: 0.25 | V39: =+K39*W39 -> 1350000 | W39: 1 | AE39: =V39/$AG$12 -> 322.98428
D40: 2 | E40: INVERSIONES / TOTAL | K40: =+K42+K52 -> 48802000 | L40: =SUM(L44:L59) -> 0 | N40: =+N42+N52 -> 7070000 | O40: =+N40/$K40 -> 0.14487111 | P40: =+P42+P52 -> 17270000 | Q40: =+P40/$K40 -> 0.35387894 | R40: =+R42+R52 -> 19962000 | S40: =+R40/$K40 -> 0.40904061 | T40: =+T42+T52 -> 4500000 | U40: =+T40/$K40 -> 0.092209336 | V40: =+V42+V52 -> 46802000 | W40: =+V40/$K40 -> 0.95901807 | X40: =+X42+X52 -> 2000000 | Y40: =+X40/$K40 -> 0.040981927 | AE40: =+AE42+AE52 -> 11197.267
E41: Porcentaje | K41: =+K40/K62 -> 0.098966804 | N41: =+N40/N62 -> 0.08030139 | P41: =+P40/P62 -> 0.18837533 | R41: =+R40/R62 -> 0.12966744 | T41: =+T40/T62 -> 0.033582841 | V41: =+V40/V62 -> 0.12031554 | X41: =+X40/X62 -> 0.019208417 | AE41: =+AE40/AE62 -> 0.12031554
...

Sheet Cuadro desembolsos
A2: Pago | B2: Fecha máxima de entrega de informes | C2: Fecha tentativa del pago | D2: Valor (Moneda) | E2: Condiciones | F2: Período informes (Desde - Hasta) | G2: % del total
A3: 1. Desembolso | B3: N/A | C3: 45582 | D3: ='Presupuesto original'!V62*0.8 -> 3.1119506e+08 | E3: Tras la firma del contrato, bajo la modalidad de anticipo. | F3: No aplica | G3: 0.8
A4: No desembolso | B4: 45811 | C4: No pago | D4: No pago | E4: Tras la recepción y aprobación por parte de COSUDE de: *Informe financiero parcial (IF) Informe operacional parcial | F4: IF: 10.15.2024 - 05/15/2025 IO: 10.15.2024 - 05/15/2025 | G4: No pago
A5: 2. Desembolso | B5: 45993 | C5: 46337 | D5: ='Presupuesto original'!V62*0.2 -> 77798764 | E5: Tras recepción y aprobación por parte de la COSUDE de: • Informe financiero final (IF). • Informe operativo finl(IO. | F5: IF: 10.15.2024 - 11/14/2025 IO: 10.15.2024 - 11/14/2025 | G5: 0.2
B6: TOTAL | D6: =+D5+D3 -> 3.8899382e+08
D8: 0
A9: *Los desembolsos se autorizan cuando se supera el 70% de ejecución, en el informe aprobado.
A10: ** IF = Informe Financiero, IO = Informe Operativo, IA = Informe de Auditoria
A11: *** El informe de auditoria se debe presentar dentro de los siguientes 45 días de la fecha de entrega de informes Operativo y Financiero.

Sheet Modif. presupuesto
A1: Anexo 1. Formato COSUDE Bogotá para la presentación del presupuesto de un proyecto.
A3: Nombre de la entidad ejecutora:
A4: Nombre del proyecto:
A5: Período que cubre el proyecto:
A6: Total período en meses:
A7: Efecto 1:
A8: Efecto 2:
A9: Efecto 3:
A11: Presupesto en COP (Pesos Colombianos)
C12: COSTOS TOTALES | J12: COSTOS INDIRECTOS Y POR EFECTOS (DIRECTOS) | R12: COSUDE | T12: ONG solic. | X12: Otros | Z12: Comunidad
A13: No. | B13: RUBROS PRESUPUESTALES | C13: Nuevo Costo Unitario | D13: Unidad | E13: Nueva Cantidad | F13: Nueva Duración | H13: Nuevo Costo Total | I13: Nuevo costo Total | J13: Costos Indirectos | K13: % C. Ad. | L13: Efecto 1 | M13: % Efecto 1 | N13: Efecto 2 | O13: % Efecto 2 | P13: Efecto 3 | Q13: % Efecto 3 | R13: Total COSUDE | S13: % COSUDE | T13: ONG solic. | U13: Ajustes Fecha XX.XX.XX | V13: Nuevo total ONG | W13: % ONG | X13: Otros | Y13: % Otros | Z13: Comunidad | AA13: % Comun.
F14: Unidad | G14: Nueva Cantidad
A15: 1 | B15: GESTIONES / TOTAL
B16: Porcentaje
A17: 1.1 | B17: Personal operativo
A18: 1.1.1 | B18: …
A19: 1.2 | B19: Personal administrativo
A20: 1.3 | B20: Consultores
A21: 1.4 | B21: Gastos viaje del personal + consultores
A22: 1.5 | B22: Capacitaciones al personal
A23: 1.6 | B23: Visibilidad
A24: 1.7 | B24: Funcionamiento de la Oficina
A25: 1.8 | B25: Seguimiento, evaluación, sistematización
A26: 2 | B26: INVERSIONES / TOTAL
B27: Porcentaje
A28: 2.1 | B28: Infraestructura destinada a la pobl. meta
A29: 2.2 | B29: Capacitaciones destinadas a la pobl. meta
A30: 2.3 | B30: Generación de Ingresos
A31: 2.4 | B31: Levantamiento de la Línea Base
A32: 3 | B32: OVERHEAD
A33: 4 | B33: AUDITORIA EXTERNA / TOTAL | R33: =C33 -> 0
B34: Porcentaje (sobre suma TOTAL 1 y 2)
B35: TOTAL GENERAL
B36: Porcentajes sobre el TOTAL GENERAL
J38: Asignación de los costos administrativos a los efectos
C39: Costos directos | L39: Efecto 1 | N39: Efecto 2 | P39: Efecto 3
C40: Costos indirectos | J40: % Admin./Efecto
J41: Costo Admin./Efec.
J42: Costo Efectos
J43: Total Costo Efectos*
...

Sheet Nuevo presupuesto
A1: Anexo 1. Formato COSUDE Bogotá para la presentación del presupuesto de un proyecto.
A3: Nombre de la entidad ejecutora:
A4: Nombre del proyecto:
A5: Período que cubre el proyecto:
A6: Total período en meses:
A7: Efecto 1:
A8: Efecto 2:
A9: Efecto 3:
A11: Presupesto en COP (Pesos Colombianos)
D12: COSTOS INDIRECTOS Y POR EFECTOS (DIRECTOS) | L12: COSUDE | N12: ONG solic. | R12: Otros | T12: Comunidad
A13: No. | B13: RUBROS PRESUPUESTALES | C13: Nuevo costo Total | D13: Costos Indirectos | E13: % C. Ad. | F13: Efecto 1 | G13: % Efecto 1 | H13: Efecto 2 | I13: % Efecto 2 | J13: Efecto 3 | K13: % Efecto 3 | L13: Total COSUDE anterior | M13: % COSUDE | N13: ONG solic. | O13: Ajustes Fecha XX.XX.XX | P13: Nuevo total ONG | Q13: % ONG | R13: Otros | S13: % Otros | T13: Comunidad | U13: % Comun.
A15: 1 | B15: GESTIONES / TOTAL
B16: Porcentaje
A17: 1.1 | B17: Personal operativo
A18: 1.1.1 | B18: …
A19: 1.2 | B19: Personal administrativo
A20: 1.3 | B20: Consultores
A21: 1.4 | B21: Gastos viaje del personal + consultores
A22: 1.5 | B22: Capacitaciones al personal
A23: 1.6 | B23: Visibilidad
A24: 1.7 | B24: Funcionamiento de la Oficina
A25: 1.8 | B25: Seguimiento, evaluación, sistematización
A26: 2 | B26: INVERSIONES / TOTAL
B27: Porcentaje
A28: 2.1 | B28: Infraestructura destinada a la pobl. meta
A29: 2.2 | B29: Capacitaciones destinadas a la pobl. meta
A30: 2.3 | B30: Generación de Ingresos
A31: 2.4 | B31: Levantamiento de la Línea Base
A32: 3 | B32: OVERHEAD
A33: 4 | B33: AUDITORIA EXTERNA / TOTAL | L33: =#REF! -> #REF!
B34: Porcentaje (sobre suma TOTAL 1 y 2)
B35: TOTAL GENERAL
B36: Porcentajes sobre el TOTAL GENERAL
D38: Asignación de los costos administrativos a los efectos
F39: Efecto 1 | H39: Efecto 2 | J39: Efecto 3
D40: % Admin./Efecto
D41: Costo Admin./Efec.
D42: Costo Efectos
D43: Total Costo Efectos*
D44: * (costos admin. y efecto)

Sheet Informe Financiero
A1: Anexo 2. Formato COSUDE Bogotá para la presentación de los informes financieros de un proyecto.
A3: Nombre de la entidad ejecutora:
A4: Nombre del proyecto:
A5: Período que cubre el proyecto:
A6: Período que cubre el informe:
A7: Efecto 1:
A8: Efecto 2:
A10: en COP (Pesos Colombianos)
C11: Totales | O11: COSUDE | X11: ONG solic. | AA11: Otros | AD11: Comunidad
A12: No. | B12: RUBROS PRESUPUESTALES | C12: Total General Aprobado | D12: Total General Ejecutado | E12: %Ejec. Total | F12: Aprobado Total Admin. | G12: Ejecutado Acumulado Admin. | H12: %Ejec. Admin. | I12: Aprobado Total Efecto 1 | J12: Ejecutado Acumulado Efecto 1 | K12: %Ejec. Acum. Efecto 1 | L12: Aprobado Total Efecto 2 | M12: Ejecutado Acumulado Efecto 2 | N12: % Ejec. Acum. Efecto 2 | O12: Aprobado Total | P12: Ajustes Fecha… | Q12: Nuevo Aprobado Total | R12: Ejecutado 1. período | S12: Ejecutado 2. período | T12: Ejecutado 3. período | U12: Ejecutado 4. período | V12: Ejecutado Acumulado | W12: % Ejec. Acum. | X12: Aprobado Total | Y12: Ejecutado Acumulado | Z12: % Ejec. Acum. | AA12: Aprobado Total | AB12: Ejecutado Acumulado | AC12: % Ejec. Acum. | AD12: Aprobado Total | AE12: Ejecutado Acumulado | AF12: % Ejec. Acum.
A13: 1 | B13: GESTIONES / TOTAL | C13: 0 | H13: =G135/F13 -> #DIV/0! | K13: =J135/I13 -> #DIV/0! | N13: =M135/L13 -> #DIV/0! | W13: =V13/Q13 -> #DIV/0! | Z13: =Y13/X13 -> #DIV/0! | AC13: =AB13/AA13 -> #DIV/0! | AF13: =AE13/AD13 -> #DIV/0!
B14: Porcentaje sobre el total general | D14: =$D$13/$D$34 -> #DIV/0! | Q14: =Q13/$Q$34 -> #DIV/0!
A15: 1.1 | B15: Personal operativo
A16: 1.2 | B16: Personal administrativo
A17: 1.3 | B17: Consultores
A18: 1.4 | B18: Gastos viaje del personal + consultores
A19: 1.5 | B19: Capacitaciones al personal
A20: 1.6 | B20: Visibilidad
A21: 1.7 | B21: Funcionamiento de la Oficina
A22: 1.8 | B22: Seguimiento, evaluación, sistematización
A24: 2 | B24: INVERSIONES / TOTAL
B25: Porcentaje | D25: =$D$24/D34 -> #DIV/0! | Q25: =Q24/$Q$34 -> #DIV/0!
A26: 2.1 | B26: Infraestructura destinada a la pobl. meta
A27: 2.2 | B27: Capacitaciones destinadas a la pobl. meta
A28: 2.3 | B28: Generación de Ingresos
A29: 2.4 | B29: Levantamiento de la Línea Base
A32: 4 | B32: AUDITORIA EXTERNA / TOTAL | C32: 0 | O32: 0
B33: Porcentaje ( % sobre suma TOTAL 1 y 2) | E33: =$E$32/$E$35 -> #DIV/0! | Q33: =Q32/$Q$34 -> #DIV/0!
B34: TOTAL GENERAL | C34: 0 | O34: 0
B35: Porcentaje (sobre el Total General) | C35: 1
B38: Resumen Fondos COSUDE | I38: Asignación de los gastos administrativos a los efectos
C39: en COP | D39: % | K39: Efecto 1 | M39: Efecto 2
B40: Pagos recibidos: | I40: % Admin./Efecto
B41: Fecha...: | I41: Gasto Admin./Efec.
B42: Fecha...: | I42: Gastos Efectos
B43: Fecha...: | I43: Total Gastos Efectos*
B44: Fecha...: | I44: * (gastos admin. y efecto)
B45: Otros ingresos:
B46: Rendimientos Financieros:
B47: Total ingresos: | C47: =SUM(C41:C46) -> 0 | D47: 1
...

Sheet Estado de Resultados
A1: ESTADO DE RESULTADOS / CONCILIACION SALDOS
A4: Organización:
A5: Proyecto:
A6: No. 7F- COSUDE:
A7: Período:
A8: Moneda: Pesos Colombianos (COP)
A11: INGRESOS
A13: Aportes COSUDE a la fecha:
A14: 1. Desembolso | B14: 100
A15: 2. Desembolso | B15: ='Informe Financiero'!$C$42 -> 0
A16: 3. Desembolso | B16: ='Informe Financiero'!$C$43 -> 0
A17: 4. Desembolso | B17: ='Informe Financiero'!$C$44 -> 0
A18: etc.
A19: Otros Ingresos | B19: ='Informe Financiero'!$C$45 -> 0
A20: Total Aportes COSUDE a la fecha | B20: =SUM(B14:B19) -> 100
A22: Aportes Cofinanciación a la fecha:
A23: Cofinanciador 1 | B23: 1
A24: Cofinanciador 2
A25: Cofinanciador 3
A26: etc.
A27: Total Aportes Cofinanciación a la fecha | B27: =SUM($B$23:$B$26) -> 1
A29: Rendimientos Financieros COSUDE | B29: 0
A30: Rendimientos Financieros Confinanciación
A31: Total Rendimientos Financieros a la fecha | B31: =$B$29+$B$30 -> 0
A33: TOTAL INGRESOS | B33: =$B$20+$B$27+$B$31 -> 101
A35: EGRESOS
A36: Gastos con aportes COSUDE | B36: 99
A38: Gastos con aportes Cofinanciación | B38: 1
A40: TOTAL EGRESOS | B40: =$B$36+$B$38 -> 100
A42: SALDO DEL PROYECTO | B42: =$B$33-$B$40 -> 1
A44: CONCILIACION SALDO
A46: Efectivo en Bancos y Caja:
A47: Efectivo en Caja COSUDE
A48: Efectivo en Banco COSUDE | B48: 1
A49: Efectivo en Caja Cofinanciación
A50: Efectivo en Banco Confinanciación
A52: Cuentas por cobrar:
A53: a ser cargadas a COSUDE | B53: 40
A54: a ser cargadas a la Cofinanciación
A56: Cuentas por pagar:
...

Sheet Balance
A1: BALANCE
A4: Organización:
A5: Proyecto:
A6: No. 7F- COSUDE:
A7: Balance al:
A8: Moneda: Pesos Colombianos (COP)
A11: ACTIVOS
A13: COSUDE:
A14: Caja
A15: Banco XXX Cta. | B15: ='Estado de Resultados'!B48+'Estado de Resultados'!B50 -> 1
A16: TOTAL EFECTIVO COSUDE | B16: =B14+B15 -> 1
A18: Cofinanciación:
A19: Caja | B19: ='Estado de Resultados'!B49 -> 0
A20: Bancos
A21: TOTAL EFECTIVO COFINANCIACION | B21: =B19+B20 -> 0
A23: Cuentas por Cobrar:
A24: a ser cargadas a COSUDE
A25: a ser cargadas a la Cofinanciación
A27: TOTAL ACTIVOS | B27: =B16+B21+B24+B25 -> 1
A29: PASIVOS
A31: Saldo ingresos recibidos por:
A32: COSUDE | B32: ='Informe Financiero'!$C$49 -> 0
A33: Cofinanciación | B33: ='Estado de Resultados'!$B$27+'Estado de Resultados'!$B$31-'Estado de Resultados'!$B$38 -> 0
A34: TOTAL SALDO INGRESOS RECIBIDOS | B34: =B32+B33 -> 0
A36: Cuentas por Pagar:
A37: cargadas a COSUDE | B37: ='Estado de Resultados'!$B$57 -> 30
A38: cargadas a la Cofinanciación | B38: ='Estado de Resultados'!$B$58 -> 0
A39: TOTAL CUENTAS POR PAGAR | B39: =B37+B38 -> 30
A41: TOTAL PASIVOS | B41: =B34+B39 -> 30
B44: Aprobaciones
B45: Nombre | C45: Firma
A46: Representante Legal
A47: Contador o Revisor Fiscal

Sheet Informe Financiero (Ejemplo)
A1: Anexo 2. Formato COSUDE Bogotá para la presentación de los informes financieros de un proyecto.
A3: Nombre de la entidad ejecutora: Fundación P
A4: Nombre del proyecto: Asistencia Humanitaria
A5: Período que cubre el proyecto: 01.10.2021 - 31.03.2022
A6: Período que cubre el informe: 01.20.2021 - 31.12.2021
A7: Efecto 1:
A8: Efecto 2:
A10: en COP (Pesos Colombianos)
C11: Totales | O11: COSUDE | V11: Fundación P | Y11: Otros | AB11: Comunidad
A12: No. | B12: RUBROS PRESUPUESTALES | C12: Total General Aprobado | D12: Total General Ejecutado | E12: %Ejec. Total | F12: Aprobado Total Admin. | G12: Ejecutado Acumulado Admin. | H12: %Ejec. Admin. | I12: Aprobado Total Efecto 1 | J12: Ejecutado Acumulado Efecto 1 | K12: %Ejec. Acum. Efecto 1 | L12: Aprobado Total Efecto 2 | M12: Ejecutado Acumulado Efecto 2 | N12: % Ejec. Acum. Efecto 2 | O12: Aprobado Total | P12: Ajustes Fecha 01.11.2021 | Q12: Nuevo Aprobado Total | R12: Ejecutado 1. período (09.12.201-31.03.2022) | S12: Ejecutado 2. período (01.04.2022-30.11.2022) | T12: Ejecutado Acumulado | U12: % Ejec. Acum. | V12: Aprobado Total | W12: Ejecutado Acumulado | X12: % Ejec. Acum. | Y12: Aprobado Total | Z12: Ejecutado Acumulado | AA12: % Ejec. Acum. | AB12: Aprobado Total | AC12: Ejecutado Acumulado | AD12: % Ejec. Acum.
A13: 1 | B13: GESTIONES / TOTAL | C13: =C15+C18+C21+C22+C25+C26+C27+C28 -> 56500000 | D13: =D15+D18+D21+D22+D25+D26+D27+D28 -> 25950000 | F13: =F15+F18+F21+F22+F25+F26+F27+F28 -> 23000000 | G13: =G15+G18+G21+G22+G25+G26+G27+G28 -> 11500000 | H13: =G123/F13 -> 0 | I13: =I15+I18+I21+I22+I25+I26+I27+I28 -> 16750000 | J13: =J15+J18+J21+J22+J25+J26+J27+J28 -> 7225000 | K13: =J123/I13 -> 0 | L13: =L15+L18+L21+L22+L25+L26+L27+L28 -> 16750000 | M13: =M15+M18+M21+M22+M25+M26+M27+M28 -> 7225000 | N13: =M123/L13 -> 0 | O13: =O15+O18+O21+O22+O25+O26+O27+O28 -> 12000000 | P13: =P15+P18+P21+P22+P25+P26+P27+P28 -> 1500000 | Q13: =Q15+Q18+Q21+Q22+Q25+Q26+Q27+Q28 -> 13500000 | R13: =R15+R18+R21+R22+R25+R26+R27+R28 -> 5152500 | T13: =T15+T18+T21+T22+T25+T26+T27+T28 -> 5152500 | U13: =T13/Q13 -> 0.38166667 | V13: =V15+V18+V21+V22+V25+V26+V27+V28 -> 43000000 | W13: =W15+W18+W21+W22+W25+W26+W27+W28 -> 20797500 | X13: =W13/V13 -> 0.48366279 | AA13: =Z13/Y13 -> #DIV/0! | AD13: =AC13/AB13 -> #DIV/0!
B14: Porcentaje sobre el total general | D14: =$D$13/$D$43 -> 0.43576826 | Q14: =Q13/$Q$43 -> 0.24590164
A15: 1.1 | B15: Personal operativo | C15: =C16+C17 -> 22500000 | D15: =D16+D17 -> 11250000 | E15: =D15/C15 -> 0.5 | I15: =I16+I17 -> 11250000 | J15: =J16+J17 -> 5625000 | K15: =J15/I15 -> 0.5 | L15: =L16+L17 -> 11250000 | M15: =M16+M17 -> 5625000 | N15: =M15/L15 -> 0.5 | O15: =O16+O17 -> 4000000 | P15: =P16+P17 -> 2000000 | Q15: =Q16+Q17 -> 6000000 | R15: =R16+R17 -> 2812500 | T15: =T16+T17 -> 2812500 | U15: =T15/Q15 -> 0.46875 | V15: =V16+V17 -> 16500000 | W15: =W16+W17 -> 8437500 | X15: =W15/V15 -> 0.51136364
A16: 1.1.1 | B16: Coordinador de proyecto (Dedicación 100%) | C16: 18000000 | D16: 9000000 | E16: =D16/C16 -> 0.5 | I16: =C16/2 -> 9000000 | J16: =D16/2 -> 4500000 | K16: =J16/I16 -> 0.5 | L16: =C16/2 -> 9000000 | M16: =L16/2 -> 4500000 | N16: =M16/L16 -> 0.5 | O16: 3000000 | P16: 1500000 | Q16: =O16+P16 -> 4500000 | R16: 2250000 | T16: =SUM(R16:S16) -> 2250000 | U16: =T16/Q16 -> 0.5 | V16: 13500000 | W16: 6750000 | X16: =W16/V16 -> 0.5
A17: 1.1.2 | B17: Asistente operacional (Dedicación 50%) | C17: 4500000 | D17: 2250000 | E17: =D17/C17 -> 0.5 | I17: =C17/2 -> 2250000 | J17: =D17/2 -> 1125000 | K17: =J17/I17 -> 0.5 | L17: =C17/2 -> 2250000 | M17: =D17/2 -> 1125000 | N17: =M17/L17 -> 0.5 | O17: 1000000 | P17: 500000 | Q17: =O17+P17 -> 1500000 | R17: 562500 | T17: =SUM(R17:S17) -> 562500 | U17: =T17/Q17 -> 0.375 | V17: 3000000 | W17: 1687500 | X17: =W17/V17 -> 0.5625
A18: 1.2 | B18: Personal administrativo | C18: =C19+C20 -> 23000000 | D18: =D19+D20 -> 11500000 | E18: =D18/C18 -> 0.5 | F18: =F19+F20 -> 23000000 | G18: =G19+G20 -> 11500000 | H18: =G18/F18 -> 0.5 | I18: =I19+I20 -> 0 | J18: =J19+J20 -> 0 | L18: =L19+L20 -> 0 | V18: =V19+V20 -> 23000000 | W18: =W19+W20 -> 11500000 | X18: =W18/V18 -> 0.5
A19: 1.2.1 | B19: Coordinadora administrativa y financiera (Dedicación 100%) | C19: 18000000 | D19: 9000000 | E19: =D19/C19 -> 0.5 | F19: =C19 -> 18000000 | G19: =D19 -> 9000000 | H19: =E19 -> 0.5 | V19: =C19 -> 18000000 | W19: =D19 -> 9000000 | X19: =W19/V19 -> 0.5
A20: 1.2.2 | B20: Contadora (Dedicación 40%) | C20: 5000000 | D20: 2500000 | E20: =D20/C20 -> 0.5 | F20: =C20 -> 5000000 | G20: =D20 -> 2500000 | H20: =E20 -> 0.5 | V20: =C20 -> 5000000 | W20: =D20 -> 2500000 | X20: =W20/V20 -> 0.5
A21: 1.3 | B21: Consultores
A22: 1.4 | B22: Gastos viaje del personal + consultores | C22: =C23+C24 -> 11000000 | D22: =D23+D24 -> 3200000 | E22: =D22/C22 -> 0.29090909 | I22: =I23+I24 -> 5500000 | J22: =J23+J24 -> 1600000 | K22: =J22/I22 -> 0.29090909 | L22: =L23+L24 -> 5500000 | M22: =M23+M24 -> 1600000 | N22: =M22/L22 -> 0.29090909 | O22: =O23+O24 -> 8000000 | P22: =P23+P24 -> -500000 | Q22: =Q23+Q24 -> 7500000 | R22: =R23+R24 -> 2340000 | T22: =T23+T24 -> 2340000 | U22: =T22/Q22 -> 0.312 | V22: =V23+V24 -> 3500000 | W22: =W23+W24 -> 860000 | X22: =W22/V22 -> 0.24571429
A23: 1.4.1 | B23: Tiquetes aéreos a terreno | C23: 6000000 | D23: 2000000 | E23: =D23/C23 -> 0.33333333 | I23: =C23/2 -> 3000000 | J23: =D23/2 -> 1000000 | K23: =J23/I23 -> 0.33333333 | L23: =C23/2 -> 3000000 | M23: =D23/2 -> 1000000 | N23: =M23/L23 -> 0.33333333 | O23: 4500000 | P23: -500000 | Q23: =O23+P23 -> 4000000 | R23: 1500000 | T23: =SUM(R23:S23) -> 1500000 | U23: =T23/Q23 -> 0.375 | V23: 2000000 | W23: 500000 | X23: =W23/V23 -> 0.25
A24: 1.4.2 | B24: Dietas y hospedaje | C24: 5000000 | D24: 1200000 | E24: =D24/C24 -> 0.24 | I24: =C24/2 -> 2500000 | J24: =D24/2 -> 600000 | K24: =J24/I24 -> 0.24 | L24: =C24/2 -> 2500000 | M24: =D24/2 -> 600000 | N24: =M24/L24 -> 0.24 | O24: 3500000 | P24: 0 | Q24: =O24+P24 -> 3500000 | R24: 840000 | T24: =SUM(R24:S24) -> 840000 | U24: =T24/Q24 -> 0.24 | V24: 1500000 | W24: 360000 | X24: =W24/V24 -> 0.24
A25: 1.5 | B25: Capacitaciones al personal
A26: 1.6 | B26: Visibilidad
A27: 1.7 | B27: Funcionamiento de la Oficina
A28: 1.8 | B28: Seguimiento, evaluación, sistematización
A30: 2 | B30: INVERSIONES / TOTAL | C30: =C32+C35+C37+C38 -> 57000000 | D30: =D32+D35+D37+D38 -> 33600000 | E30: =D30/C30 -> 0.58947368 | F30: =F32+F35+F37+F38 -> 0 | G30: =G32+G35+G37+G38 -> 0 | I30: =I32+I35+I37+I38 -> 22000000 | J30: =J32+J35+J37+J38 -> 15300000 | K30: =J30/I30 -> 0.69545455 | L30: =L32+L35+L37+L38 -> 35000000 | M30: =M32+M35+M37+M38 -> 18300000 | N30: =M30/L30 -> 0.52285714 | O30: =O32+O35+O37+O38 -> 39400000 | P30: =P32+P35+P37+P38 -> 0 | Q30: =Q32+Q35+Q37+Q38 -> 39400000 | R30: =R32+R35+R37+R38 -> 21200000 | S30: =S32+S35+S37+S38 -> 0 | T30: =T32+T35+T37+T38 -> 21200000 | U30: =T30/Q30 -> 0.53807107 | V30: =V32+V35+V37+V38 -> 17600000 | W30: =W32+W35+W37+W38 -> 12400000 | X30: =W30/V30 -> 0.70454545
B31: Porcentaje | D31: =$D$30/D43 -> 0.56423174
A32: 2.1 | B32: Infraestructura destinada a la pobl. meta | C32: =SUM(C33:C34) -> 44000000 | D32: =SUM(D33:D34) -> 30600000 | E32: =D32/C32 -> 0.69545455 | I32: =SUM(I33:I34) -> 22000000 | J32: =SUM(J33:J34) -> 15300000 | K32: =J32/I32 -> 0.69545455 | L32: =SUM(L33:L34) -> 22000000 | M32: =SUM(M33:M34) -> 15300000 | N32: =M32/L32 -> 0.69545455 | O32: =O33+O34 -> 26400000 | Q32: =Q33+Q34 -> 26400000 | R32: =R33+R34 -> 18200000 | T32: =T33+T34 -> 18200000 | U32: =T32/Q32 -> 0.68939394 | V32: =V33+V34 -> 17600000 | W32: =W33+W34 -> 12400000 | X32: =W32/V32 -> 0.70454545
A33: 2.1.1 | B33: Kits de primera necesidad | C33: 40000000 | D33: 28000000 | E33: =D33/C33 -> 0.7 | I33: =C33/2 -> 20000000 | J33: =D33/2 -> 14000000 | K33: =J33/I33 -> 0.7 | L33: =C33/2 -> 20000000 | M33: =D33/2 -> 14000000 | N33: =M33/L33 -> 0.7 | O33: =C33*0.6 -> 24000000 | P33: 0 | Q33: =O33+P33 -> 24000000 | R33: 16800000 | T33: =SUM(R33:S33) -> 16800000 | U33: =T33/Q33 -> 0.7 | V33: 16000000 | W33: 11200000 | X33: =W33/V33 -> 0.7
A34: 2.1.2 | B34: Transporte y entrega de kits | C34: 4000000 | D34: 2600000 | E34: =D34/C34 -> 0.65 | I34: =C34/2 -> 2000000 | J34: =D34/2 -> 1300000 | K34: =J34/I34 -> 0.65 | L34: =C34/2 -> 2000000 | M34: =D34/2 -> 1300000 | N34: =M34/L34 -> 0.65 | O34: =C34*0.6 -> 2400000 | P34: 0 | Q34: =O34+P34 -> 2400000 | R34: 1400000 | T34: =SUM(R34:S34) -> 1400000 | U34: =T34/Q34 -> 0.58333333 | V34: 1600000 | W34: 1200000 | X34: =W34/V34 -> 0.75
A35: 2.2 | B35: Capacitaciones destinadas a la pobl. meta | C35: =C36 -> 13000000 | D35: =D36 -> 3000000 | E35: =D35/C35 -> 0.23076923 | L35: =L36 -> 13000000 | M35: =M36 -> 3000000 | N35: =M35/L35 -> 0.23076923 | O35: =O36 -> 13000000 | P35: =P36 -> 0 | Q35: =Q36 -> 13000000 | R35: =R36 -> 3000000 | T35: =T36 -> 3000000 | U35: =U36 -> 0.23076923
A36: 2.2.1 | B36: Jornadas de autoprotección y defensa del territorio | C36: 13000000 | D36: 3000000 | E36: =D36/C36 -> 0.23076923 | L36: =C36 -> 13000000 | M36: =D36 -> 3000000 | N36: =M36/L36 -> 0.23076923 | O36: =L36 -> 13000000 | P36: 0 | Q36: =O36 -> 13000000 | R36: =M36 -> 3000000 | T36: =SUM(R36:S36) -> 3000000 | U36: =T36/Q36 -> 0.23076923
A37: 2.3 | B37: Generación de Ingresos
A38: 2.4 | B38: Levantamiento de la Línea Base
A41: 4 | B41: AUDITORIA EXTERNA / TOTAL | C41: 2000000 | D41: 0 | E41: =D41/C41 -> 0 | F41: =C41 -> 2000000 | G41: =D41 -> 0 | O41: 2000000 | Q41: 2000000
B42: Porcentaje ( % sobre suma TOTAL 1 y 2) | D42: =$D$41/$D$44 -> #DIV/0! | Q42: =Q41/$Q$43 -> 0.036429872
B43: TOTAL GENERAL | C43: =C13+C30+C41 -> 115500000 | D43: =D13+D30+D41 -> 59550000 | E43: =D43/C43 -> 0.51558442 | F43: =F13+F30+F41 -> 25000000 | G43: =G13+G30+G41 -> 11500000 | I43: =I13+I30+I41 -> 38750000 | J43: =J13+J30+J41 -> 22525000 | L43: =L13+L30+L41 -> 51750000 | M43: =M13+M30+M41 -> 25525000 | O43: =O13+O30+O41 -> 53400000 | P43: =P13+P30+P41 -> 1500000 | Q43: =Q13+Q30+Q41 -> 54900000 | R43: =R13+R30+R41 -> 26352500 | S43: =S13+S30+S41 -> 0 | T43: =T13+T30+T41 -> 26352500 | U43: =T43/Q43 -> 0.48000911 | V43: =V13+V30+V41 -> 60600000 | W43: =W13+W30+W41 -> 33197500 | X43: =W43/V43 -> 0.54781353
B44: Porcentaje (sobre el Total General) | C44: 1
B46: Resumen Fondos COSUDE | I46: Asignación de los gastos administrativos a los efectos
...

Sheet Estado de Resultados (Ejemplo)
A1: ESTADO DE RESULTADOS / CONCILIACION SALDOS
A4: Organización: Fundación P
A5: Proyecto: Asistencia Humanitaria
A6: No. 7F- COSUDE: 7F-55555.01.01
A7: Período: 01.09.2021-31.12.2021
A8: Moneda: Pesos Colombianos (COP)
A11: INGRESOS
A13: Aportes COSUDE a la fecha:
A14: 1. Desembolso | B14: ='Informe Financiero (Ejemplo)'!C49 -> 30000000
A15: 2. Desembolso
A16: 3. Desembolso
A17: 4. Desembolso
A18: etc.
A19: Otros Ingresos
A20: Total Aportes COSUDE a la fecha | B20: =SUM(B14:B19) -> 30000000
A22: Aportes Cofinanciación a la fecha:
A23: Cofinanciador 1 | B23: 33197500
A24: Cofinanciador 2
A25: Cofinanciador 3
A26: etc.
A27: Total Aportes Cofinanciación a la fecha | B27: =SUM($B$23:$B$26) -> 33197500
A29: Rendimientos Financieros COSUDE | B29: ='Informe Financiero (Ejemplo)'!C54 -> 11000
A30: Rendimientos Financieros Confinanciación | B30: 0
A31: Total Rendimientos Financieros a la fecha | B31: =$B$29+$B$30 -> 11000
A33: TOTAL INGRESOS | B33: =$B$20+$B$27+$B$31 -> 63208500
A35: EGRESOS
A36: Gastos con aportes COSUDE | B36: ='Informe Financiero (Ejemplo)'!C56 -> 26352500
A38: Gastos con aportes Cofinanciación | B38: ='Informe Financiero (Ejemplo)'!$W$43+'Informe Financiero (Ejemplo)'!$Z$43+'Informe Financiero (Ejemplo)'!$AC$43 -> 33197500
A40: TOTAL EGRESOS | B40: =$B$36+$B$38 -> 59550000
A42: SALDO DEL PROYECTO | B42: =$B$33-$B$40 -> 3658500
A44: CONCILIACION SALDO
A46: Efectivo en Bancos y Caja:
A47: Efectivo en Caja COSUDE
A48: Efectivo en Banco COSUDE | B48: ='Balance (Ejemplo)'!B15 -> 4458500
A49: Efectivo en Caja Cofinanciación
A50: Efectivo en Banco Confinanciación
A52: Cuentas por cobrar:
A53: a ser cargadas a COSUDE
A54: a ser cargadas a la Cofinanciación
A56: Cuentas por pagar:
...

Sheet Balance (Ejemplo)
A1: BALANCE
A4: Organización: Fundación P
A5: Proyecto: Asistencia Humanitaria
A6: No. 7F- COSUDE: 7F-55555.01.01
A7: Período: 01.09.2021-31.12.2021
A8: Moneda: Pesos Colombianos (COP)
A11: ACTIVOS
A13: COSUDE:
A14: Caja
A15: Banco XXX Cta. | B15: 4458500
A16: TOTAL EFECTIVO COSUDE | B16: =B14+B15 -> 4458500
A18: Cofinanciación:
A19: Caja | B19: ='Estado de Resultados (Ejemplo)'!$B$50 -> 0
A20: Bancos | B20: ='Estado de Resultados (Ejemplo)'!$B$49 -> 0
A21: TOTAL EFECTIVO COFINANCIACION | B21: =B19+B20 -> 0
A23: Cuentas por Cobrar:
A24: a ser cargadas a COSUDE
A25: a ser cargadas a la Cofinanciación
A27: TOTAL ACTIVOS | B27: =B16+B21+B24+B25 -> 4458500
A29: PASIVOS
A31: Saldo ingresos recibidos por:
A32: COSUDE | B32: 3658500
A33: Cofinanciación
A34: TOTAL SALDO INGRESOS RECIBIDOS | B34: =B32+B33 -> 3658500
A36: Cuentas por Pagar:
A37: cargadas a COSUDE | B37: 800000
A38: cargadas a la Cofinanciación | B38: ='Estado de Resultados'!$B$58 -> 0
A39: TOTAL CUENTAS POR PAGAR | B39: =B37+B38 -> 800000
A41: TOTAL PASIVOS | B41: =B34+B39 -> 4458500
