Workbook
Name \A: #REF!
Name \A: #REF!
Name \P: #REF!
Name \P: #REF!
Name \S: #REF!
Name \S: #REF!
Name _______sho1: '[3]Detailed Budget-SAVE'!#REF!
Name _______sho1: '[3]Detailed Budget-SAVE'!#REF!
Name __2DAI_1: #N/A
Name __3FEE: #N/A
Name __AFP1: #N/A
Name __AFP2: #N/A
Name __AFP3: #N/A
Name __AFP4: #N/A
Name __AMP1: #N/A
Name __AMP2: #N/A
Name __AMP3: #N/A
Name __AMP4: #N/A
Name __DAI4: #N/A
Name __EES1: #N/A
Name __EES2: #N/A
Name __EES3: #N/A
Name __EES4: #N/A
Name __EXT1: #N/A
Name __EXT2: #N/A
Name __EXT3: #N/A
Name __EXT4: #N/A
Name __FCP1: #N/A
Name __FCP2: #N/A
Name __FCP3: #N/A
Name __FCP4: #N/A
Name __FRI1: #N/A
Name __FRI4: #N/A
Name __HRA1: #N/A
Name __HRA2: #N/A
Name __HRA3: #N/A
Name __HRA4: #N/A
Name __inf1: #REF!
Name __LT4: [4]Parameters!$B$40
Name __ODC1: #N/A
Name __ODC2: #N/A
Name __POL1: #N/A
Name __POL2: #N/A
Name __POL3: #N/A
Name __POL4: #N/A
Name __TOT1: #N/A
Name __TOT2: #N/A
Name __TRV1: #N/A
Name __TRV2: #N/A
Name _060: #REF!
Name _1_1: #REF!
Name _13th_and_14th_month: [5]Parameters!$D$62
Name _2_1034: #REF!
Name _2DAI_1: #N/A
Name _3_1440: #REF!
Name _3FEE: #N/A
Name _4_2: #REF!
Name _5_3: #REF!
Name _AFP1: #N/A
Name _AFP2: #N/A

Sheet USDA Budget Summary
A1: Attachment 9
A2: Proposed Budget Summary
A4: Program (FFPr or MGD): | B4: FFPr
A5: Country of Operation: | B5: Tunisia
A6: Implementing Organization: | B6: Partners of the Americas Inc.
A7: Fiscal Year: | B7: 2024
A8: Agreement Number: | B8: USDA-FAS-10.606-0700-24(480)
A10: Total Amount of Federal Funds Requested
A11: Funding Source (FAS for MGD) (CCC for FFPr) | B11: Funding Year | C11: Commodity Cost | D11: Freight Cost | E11: Administrative Costs (cash portion) | F11: Total Federal Funding Obligated
B12: 2024 | C12: 19350000 | D12: 4000000 | E12: 1500000 | F12: =E12+D12+C12 -> 24850000
A14: Project Operating Budget
A15: Expense Type | B15: Monetization Proceeds (FFPr Only) | C15: FAS or CCC Funds (CCC is Admin Only) | D15: Cost Share | E15: Total w/out Cost Share | F15: Total w/Cost Share
A16: Administration
A17: Salaries/Personnel | B17: ='Program Budget'!V37-C17 -> 520668.29 | C17: 577000 | D17: ='Program Budget'!W37 -> 0 | E17: =B17+C17 -> 1097668.3 | F17: =B17+C17+D17 -> 1097668.3
A18: Benefits | B18: ='Program Budget'!V43-C18 -> 112887.37 | C18: 244128 | D18: ='Program Budget'!W43 -> 0 | E18: =B18+C18 -> 357015.37 | F18: =B18+C18+D18 -> 357015.37
A19: Travel | B19: ='Program Budget'!V60-C19 -> 297871 | C19: 20789.12 | D19: ='Program Budget'!W60 -> 0 | E19: =B19+C19 -> 318660.12 | F19: =B19+C19+D19 -> 318660.12
A20: Professional Services/Contractual | B20: ='Program Budget'!V86-C20 -> 1215333.8 | C20: 293800 | D20: ='Program Budget'!W86 -> 0 | E20: =B20+C20 -> 1509133.8 | F20: =B20+C20+D20 -> 1509133.8
A21: Equipment | B21: ='Program Budget'!V91-C21 -> 180000 | C21: 0 | D21: ='Program Budget'!W91 -> 0 | E21: =B21+C21 -> 180000 | F21: =B21+C21+D21 -> 180000
A22: Office | B22: ='Program Budget'!V110-C22 -> 438775.84 | C22: 12000 | D22: ='Program Budget'!W110 -> 0 | E22: =B22+C22 -> 450775.84 | F22: =B22+C22+D22 -> 450775.84
A23: Supplies | B23: ='Program Budget'!V125-C23 -> 64091.97 | C23: 18600 | D23: ='Program Budget'!W125 -> 0 | E23: =B23+C23 -> 82691.97 | F23: =B23+C23+D23 -> 82691.97
A24: Other | B24: ='Program Budget'!V135-C24 -> 57728.88 | C24: 3000 | D24: 0 | E24: =B24+C24 -> 60728.88 | F24: =B24+C24+D24 -> 60728.88
A25: Total Administration | B25: =SUM(B17:B24) -> 2887357.2 | C25: =SUM(C17:C24) -> 1169317.1 | D25: =SUM(D17:D24) -> 0 | E25: =SUM(E17:E24) -> 4056674.3 | F25: =SUM(F17:F24) -> 4056674.3
A27: Activities
A28: Activity 1: Increase Use of Climate Smart Agriculture and Water Management | B28: ='Program Budget'!V211 -> 3860925.1 | C28: 0 | D28: ='Program Budget'!W211 -> 96476 | E28: =B28+C28 -> 3860925.1 | F28: =B28+C28+D28 -> 3957401.1
A29: Activity 2: Increase Productivity of the Oasis Agricultural System | B29: ='Program Budget'!V282 -> 2395689.3 | C29: 0 | D29: ='Program Budget'!W282 -> 165000 | E29: =B29+C29 -> 2395689.3 | F29: =B29+C29+D29 -> 2560689.3
A30: Activity 3: Increase Use of Sustainable Oasis Agricultural System Business Models | B30: ='Program Budget'!V379 -> 2938971.9 | C30: 0 | D30: =ROUND('Program Budget'!W379,0) -> 43750 | E30: =B30+C30 -> 2938971.9 | F30: =B30+C30+D30 -> 2982721.9
A31: Total Activities | B31: =SUM(B28:B30) -> 9195586.4 | C31: =SUM(C28:C30) -> 0 | D31: =SUM(D28:D30) -> 305226 | E31: =SUM(E28:E30) -> 9195586.4 | F31: =SUM(F28:F30) -> 9500812.4
A33: Commodity and Food Purchases (N/A to FFPr)
A34: Commodity Procurement | B34: 0 | C34: 0 | D34: 0 | E34: =B34+C34 -> 0 | F34: =B34+C34+D34 -> 0
A35: Food Vouchers (N/A to MGD)
A36: Cash Transfers (N/A to MGD)
A37: Total Commodity Procurement | B37: =SUM(B34:B36) -> 0 | C37: =SUM(C34:C36) -> 0 | D37: =SUM(D34:D36) -> 0 | E37: =SUM(E34:E36) -> 0 | F37: =SUM(F34:F36) -> 0
A39: ITSH (N/A to FFPr)
A40: Salaries | B40: 0 | C40: 0 | D40: 0 | E40: =B40+C40 -> 0 | F40: =B40+C40+D40 -> 0
A41: Benefits | B41: 0 | C41: 0 | D41: 0 | E41: =B41+C41 -> 0 | F41: =B41+C41+D41 -> 0
A42: Transportation | B42: 0 | C42: 0 | D42: 0 | E42: =B42+C42 -> 0 | F42: =B42+C42+D42 -> 0
A43: Professional Services | B43: 0 | C43: 0 | D43: =0 -> 0 | E43: =B43+C43 -> 0 | F43: =B43+C43+D43 -> 0
A44: Warehouse | B44: 0 | C44: 0 | D44: 0 | E44: =B44+C44 -> 0 | F44: =B44+C44+D44 -> 0
A45: Supplies | B45: 0 | C45: 0 | D45: 0 | E45: =B45+C45 -> 0 | F45: =B45+C45+D45 -> 0
A46: Other | B46: 0 | C46: 0 | D46: 0 | E46: =B46+C46 -> 0 | F46: =B46+C46+D46 -> 0
...

Sheet Detailed Budget
A2: Item | B2: Type of Unit | C2: Year 1 | G2: Year 2 | K2: Year 3 | O2: Year 4 | S2: Year 5 | W2: Total
C3: Cost | D3: Quantity | E3: Percent Allocated | F3: Total | G3: Cost | H3: Quantity | I3: Percent Allocated | J3: Total | K3: Cost | L3: Quantity | M3: Percent Allocated | N3: Total | O3: Cost | P3: Quantity | Q3: Percent Allocated | R3: Total | S3: Cost | T3: Quantity | U3: Percent Allocated | V3: Total
A4: Direct Costs
A5: Salaries
A6: USN/TCN Staff
A7: None | F7: =C7*D7*E7 -> 0 | J7: =G7*H7*I7 -> 0 | N7: =K7*L7*M7 -> 0 | R7: =O7*P7*Q7 -> 0 | V7: =S7*T7*U7 -> 0 | W7: =F7+J7+N7+R7+V7 -> 0
A8: Total: Expatriate Salaries & Wages | F8: =SUM(F7:F7) -> 0 | J8: =SUM(J7:J7) -> 0 | N8: =SUM(N7:N7) -> 0 | R8: =SUM(R7:R7) -> 0 | V8: =SUM(V7:V7) -> 0 | W8: =+F8+J8+N8+R8+V8 -> 0
A9: CNN Staff
A10: ='Program Budget'!D12 -> Key Personnel: Chief of Party - Ms. Rym Ayari | B10: ='Program Budget'!F12 -> Month | C10: ='Program Budget'!H12 -> 13000 | D10: ='Program Budget'!G12 -> 12 | E10: =Admin!E10+'Activity 1'!E10+'Activity 2'!E10+'Activity 3'!E10 -> 1 | F10: =C10*D10*E10 -> 156000 | G10: =C10*1.05 -> 13650 | H10: ='Program Budget'!K12 -> 12 | I10: =Admin!I10+'Activity 1'!I10+'Activity 2'!I10+'Activity 3'!I10 -> 1 | J10: =G10*H10*I10 -> 163800 | K10: =G10*1.05 -> 14332.5 | L10: ='Program Budget'!N12 -> 12 | M10: =Admin!M10+'Activity 1'!M10+'Activity 2'!M10+'Activity 3'!M10 -> 1 | N10: =K10*L10*M10 -> 171990 | O10: =K10*1.05 -> 15049.125 | P10: ='Program Budget'!Q12 -> 12 | Q10: =Admin!Q10+'Activity 1'!Q10+'Activity 2'!Q10+'Activity 3'!Q10 -> 1 | R10: =O10*P10*Q10 -> 180589.5 | S10: =O10*1.05 -> 15801.581 | T10: ='Program Budget'!T12 -> 12 | U10: =Admin!U10+'Activity 1'!U10+'Activity 2'!U10+'Activity 3'!U10 -> 1 | V10: =S10*T10*U10 -> 189618.98 | W10: =F10+J10+N10+R10+V10 -> 861998.47
A11: ='Program Budget'!D13 -> Key Personnel: Technical Director | B11: ='Program Budget'!F13 -> Month | C11: ='Program Budget'!H13 -> 3916.6667 | D11: ='Program Budget'!G13 -> 9 | E11: =Admin!E11+'Activity 1'!E11+'Activity 2'!E11+'Activity 3'!E11 -> 1 | F11: =C11*D11*E11 -> 35250 | G11: =C11*1.05 -> 4112.5 | H11: ='Program Budget'!K13 -> 12 | I11: =Admin!I11+'Activity 1'!I11+'Activity 2'!I11+'Activity 3'!I11 -> 1 | J11: =G11*H11*I11 -> 49350 | K11: =G11*1.05 -> 4318.125 | L11: ='Program Budget'!N13 -> 12 | M11: =Admin!M11+'Activity 1'!M11+'Activity 2'!M11+'Activity 3'!M11 -> 1 | N11: =K11*L11*M11 -> 51817.5 | O11: =K11*1.05 -> 4534.0312 | P11: ='Program Budget'!Q13 -> 12 | Q11: =Admin!Q11+'Activity 1'!Q11+'Activity 2'!Q11+'Activity 3'!Q11 -> 1 | R11: =O11*P11*Q11 -> 54408.375 | S11: =O11*1.05 -> 4760.7328 | T11: ='Program Budget'!T13 -> 9 | U11: =Admin!U11+'Activity 1'!U11+'Activity 2'!U11+'Activity 3'!U11 -> 1 | V11: =S11*T11*U11 -> 42846.595 | W11: =F11+J11+N11+R11+V11 -> 233672.47
A12: ='Program Budget'!D14 -> Technical Lead Component 1 | B12: ='Program Budget'!F14 -> Month | C12: ='Program Budget'!H14 -> 2500 | D12: ='Program Budget'!G14 -> 6 | E12: =Admin!E12+'Activity 1'!E12+'Activity 2'!E12+'Activity 3'!E12 -> 1 | F12: =C12*D12*E12 -> 15000 | G12: =C12*1.05 -> 2625 | H12: ='Program Budget'!K14 -> 12 | I12: =Admin!I12+'Activity 1'!I12+'Activity 2'!I12+'Activity 3'!I12 -> 1 | J12: =G12*H12*I12 -> 31500 | K12: =G12*1.05 -> 2756.25 | L12: ='Program Budget'!N14 -> 12 | M12: =Admin!M12+'Activity 1'!M12+'Activity 2'!M12+'Activity 3'!M12 -> 1 | N12: =K12*L12*M12 -> 33075 | O12: =K12*1.05 -> 2894.0625 | P12: ='Program Budget'!Q14 -> 12 | Q12: =Admin!Q12+'Activity 1'!Q12+'Activity 2'!Q12+'Activity 3'!Q12 -> 1 | R12: =O12*P12*Q12 -> 34728.75 | S12: =O12*1.05 -> 3038.7656 | T12: ='Program Budget'!T14 -> 9 | U12: =Admin!U12+'Activity 1'!U12+'Activity 2'!U12+'Activity 3'!U12 -> 1 | V12: =S12*T12*U12 -> 27348.891 | W12: =F12+J12+N12+R12+V12 -> 141652.64
A13: ='Program Budget'!D15 -> Technical Lead Component 2 | B13: ='Program Budget'!F15 -> Month | C13: ='Program Budget'!H15 -> 2500 | D13: ='Program Budget'!G15 -> 6 | E13: =Admin!E13+'Activity 1'!E13+'Activity 2'!E13+'Activity 3'!E13 -> 1 | F13: =C13*D13*E13 -> 15000 | G13: =C13*1.05 -> 2625 | H13: ='Program Budget'!K15 -> 12 | I13: =Admin!I13+'Activity 1'!I13+'Activity 2'!I13+'Activity 3'!I13 -> 1 | J13: =G13*H13*I13 -> 31500 | K13: =G13*1.05 -> 2756.25 | L13: ='Program Budget'!N15 -> 12 | M13: =Admin!M13+'Activity 1'!M13+'Activity 2'!M13+'Activity 3'!M13 -> 1 | N13: =K13*L13*M13 -> 33075 | O13: =K13*1.05 -> 2894.0625 | P13: ='Program Budget'!Q15 -> 12 | Q13: =Admin!Q13+'Activity 1'!Q13+'Activity 2'!Q13+'Activity 3'!Q13 -> 1 | R13: =O13*P13*Q13 -> 34728.75 | S13: =O13*1.05 -> 3038.7656 | T13: ='Program Budget'!T15 -> 9 | U13: =Admin!U13+'Activity 1'!U13+'Activity 2'!U13+'Activity 3'!U13 -> 1 | V13: =S13*T13*U13 -> 27348.891 | W13: =F13+J13+N13+R13+V13 -> 141652.64
A14: ='Program Budget'!D16 -> Technical Lead Component 3 | B14: ='Program Budget'!F16 -> Month | C14: ='Program Budget'!H16 -> 2500 | D14: ='Program Budget'!G16 -> 6 | E14: =Admin!E14+'Activity 1'!E14+'Activity 2'!E14+'Activity 3'!E14 -> 1 | F14: =C14*D14*E14 -> 15000 | G14: =C14*1.05 -> 2625 | H14: ='Program Budget'!K16 -> 12 | I14: =Admin!I14+'Activity 1'!I14+'Activity 2'!I14+'Activity 3'!I14 -> 1 | J14: =G14*H14*I14 -> 31500 | K14: =G14*1.05 -> 2756.25 | L14: ='Program Budget'!N16 -> 12 | M14: =Admin!M14+'Activity 1'!M14+'Activity 2'!M14+'Activity 3'!M14 -> 1 | N14: =K14*L14*M14 -> 33075 | O14: =K14*1.05 -> 2894.0625 | P14: ='Program Budget'!Q16 -> 12 | Q14: =Admin!Q14+'Activity 1'!Q14+'Activity 2'!Q14+'Activity 3'!Q14 -> 1 | R14: =O14*P14*Q14 -> 34728.75 | S14: =O14*1.05 -> 3038.7656 | T14: ='Program Budget'!T16 -> 9 | U14: =Admin!U14+'Activity 1'!U14+'Activity 2'!U14+'Activity 3'!U14 -> 1 | V14: =S14*T14*U14 -> 27348.891 | W14: =F14+J14+N14+R14+V14 -> 141652.64
A15: ='Program Budget'!D17 -> Technical Specialist Component 1 | B15: ='Program Budget'!F17 -> Month | C15: ='Program Budget'!H17 -> 1833.3333 | D15: ='Program Budget'!G17 -> 6 | E15: =Admin!E15+'Activity 1'!E15+'Activity 2'!E15+'Activity 3'!E15 -> 1 | F15: =C15*D15*E15 -> 11000 | G15: =C15*1.05 -> 1925 | H15: ='Program Budget'!K17 -> 12 | I15: =Admin!I15+'Activity 1'!I15+'Activity 2'!I15+'Activity 3'!I15 -> 1 | J15: =G15*H15*I15 -> 23100 | K15: =G15*1.05 -> 2021.25 | L15: ='Program Budget'!N17 -> 12 | M15: =Admin!M15+'Activity 1'!M15+'Activity 2'!M15+'Activity 3'!M15 -> 1 | N15: =K15*L15*M15 -> 24255 | O15: =K15*1.05 -> 2122.3125 | P15: ='Program Budget'!Q17 -> 12 | Q15: =Admin!Q15+'Activity 1'!Q15+'Activity 2'!Q15+'Activity 3'!Q15 -> 1 | R15: =O15*P15*Q15 -> 25467.75 | S15: =O15*1.05 -> 2228.4281 | T15: ='Program Budget'!T17 -> 6 | U15: =Admin!U15+'Activity 1'!U15+'Activity 2'!U15+'Activity 3'!U15 -> 1 | V15: =S15*T15*U15 -> 13370.569 | W15: =F15+J15+N15+R15+V15 -> 97193.319
A16: ='Program Budget'!D18 -> Technical Specialist Component 2 | B16: ='Program Budget'!F18 -> Month | C16: ='Program Budget'!H18 -> 1833.3333 | D16: ='Program Budget'!G18 -> 6 | E16: =Admin!E16+'Activity 1'!E16+'Activity 2'!E16+'Activity 3'!E16 -> 1 | F16: =C16*D16*E16 -> 11000 | G16: =C16*1.05 -> 1925 | H16: ='Program Budget'!K18 -> 12 | I16: =Admin!I16+'Activity 1'!I16+'Activity 2'!I16+'Activity 3'!I16 -> 1 | J16: =G16*H16*I16 -> 23100 | K16: =G16*1.05 -> 2021.25 | L16: ='Program Budget'!N18 -> 12 | M16: =Admin!M16+'Activity 1'!M16+'Activity 2'!M16+'Activity 3'!M16 -> 1 | N16: =K16*L16*M16 -> 24255 | O16: =K16*1.05 -> 2122.3125 | P16: ='Program Budget'!Q18 -> 12 | Q16: =Admin!Q16+'Activity 1'!Q16+'Activity 2'!Q16+'Activity 3'!Q16 -> 1 | R16: =O16*P16*Q16 -> 25467.75 | S16: =O16*1.05 -> 2228.4281 | T16: ='Program Budget'!T18 -> 6 | U16: =Admin!U16+'Activity 1'!U16+'Activity 2'!U16+'Activity 3'!U16 -> 1 | V16: =S16*T16*U16 -> 13370.569 | W16: =F16+J16+N16+R16+V16 -> 97193.319
A17: ='Program Budget'!D19 -> Technical Specialist Component 3 | B17: ='Program Budget'!F19 -> Month | C17: ='Program Budget'!H19 -> 1833.3333 | D17: ='Program Budget'!G19 -> 6 | E17: =Admin!E17+'Activity 1'!E17+'Activity 2'!E17+'Activity 3'!E17 -> 1 | F17: =C17*D17*E17 -> 11000 | G17: =C17*1.05 -> 1925 | H17: ='Program Budget'!K19 -> 12 | I17: =Admin!I17+'Activity 1'!I17+'Activity 2'!I17+'Activity 3'!I17 -> 1 | J17: =G17*H17*I17 -> 23100 | K17: =G17*1.05 -> 2021.25 | L17: ='Program Budget'!N19 -> 12 | M17: =Admin!M17+'Activity 1'!M17+'Activity 2'!M17+'Activity 3'!M17 -> 1 | N17: =K17*L17*M17 -> 24255 | O17: =K17*1.05 -> 2122.3125 | P17: ='Program Budget'!Q19 -> 12 | Q17: =Admin!Q17+'Activity 1'!Q17+'Activity 2'!Q17+'Activity 3'!Q17 -> 1 | R17: =O17*P17*Q17 -> 25467.75 | S17: =O17*1.05 -> 2228.4281 | T17: ='Program Budget'!T19 -> 6 | U17: =Admin!U17+'Activity 1'!U17+'Activity 2'!U17+'Activity 3'!U17 -> 1 | V17: =S17*T17*U17 -> 13370.569 | W17: =F17+J17+N17+R17+V17 -> 97193.319
A18: ='Program Budget'!D20 -> Capacity Building Specialist (2) | B18: ='Program Budget'!F20 -> Month | C18: ='Program Budget'!H20 -> 3333.3333 | D18: ='Program Budget'!G20 -> 4 | E18: =Admin!E18+'Activity 1'!E18+'Activity 2'!E18+'Activity 3'!E18 -> 1 | F18: =C18*D18*E18 -> 13333.333 | G18: =C18*1.05 -> 3500 | H18: ='Program Budget'!K20 -> 12 | I18: =Admin!I18+'Activity 1'!I18+'Activity 2'!I18+'Activity 3'!I18 -> 1 | J18: =G18*H18*I18 -> 42000 | K18: =G18*1.05 -> 3675 | L18: ='Program Budget'!N20 -> 12 | M18: =Admin!M18+'Activity 1'!M18+'Activity 2'!M18+'Activity 3'!M18 -> 1 | N18: =K18*L18*M18 -> 44100 | O18: =K18*1.05 -> 3858.75 | P18: ='Program Budget'!Q20 -> 12 | Q18: =Admin!Q18+'Activity 1'!Q18+'Activity 2'!Q18+'Activity 3'!Q18 -> 1 | R18: =O18*P18*Q18 -> 46305 | S18: =O18*1.05 -> 4051.6875 | T18: ='Program Budget'!T20 -> 5 | U18: =Admin!U18+'Activity 1'!U18+'Activity 2'!U18+'Activity 3'!U18 -> 1 | V18: =S18*T18*U18 -> 20258.438 | W18: =F18+J18+N18+R18+V18 -> 165996.77
A19: ='Program Budget'!D21 -> Sociocultural and Gender Specialist | B19: ='Program Budget'!F21 -> Month | C19: ='Program Budget'!H21 -> 1833.3333 | D19: ='Program Budget'!G21 -> 7 | E19: =Admin!E19+'Activity 1'!E19+'Activity 2'!E19+'Activity 3'!E19 -> 1 | F19: =C19*D19*E19 -> 12833.333 | G19: =C19*1.05 -> 1925 | H19: ='Program Budget'!K21 -> 12 | I19: =Admin!I19+'Activity 1'!I19+'Activity 2'!I19+'Activity 3'!I19 -> 1 | J19: =G19*H19*I19 -> 23100 | K19: =G19*1.05 -> 2021.25 | L19: ='Program Budget'!N21 -> 12 | M19: =Admin!M19+'Activity 1'!M19+'Activity 2'!M19+'Activity 3'!M19 -> 1 | N19: =K19*L19*M19 -> 24255 | O19: =K19*1.05 -> 2122.3125 | P19: ='Program Budget'!Q21 -> 12 | Q19: =Admin!Q19+'Activity 1'!Q19+'Activity 2'!Q19+'Activity 3'!Q19 -> 1 | R19: =O19*P19*Q19 -> 25467.75 | S19: =O19*1.05 -> 2228.4281 | T19: ='Program Budget'!T21 -> 9 | U19: =Admin!U19+'Activity 1'!U19+'Activity 2'!U19+'Activity 3'!U19 -> 1 | V19: =S19*T19*U19 -> 20055.853 | W19: =F19+J19+N19+R19+V19 -> 105711.94
A20: ='Program Budget'!D22 -> Sociocultural and Gender Officers (3) | B20: ='Program Budget'!F22 -> Month | C20: ='Program Budget'!H22 -> 3750 | D20: ='Program Budget'!G22 -> 7 | E20: =Admin!E20+'Activity 1'!E20+'Activity 2'!E20+'Activity 3'!E20 -> 1 | F20: =C20*D20*E20 -> 26250 | G20: =C20*1.05 -> 3937.5 | H20: ='Program Budget'!K22 -> 12 | I20: =Admin!I20+'Activity 1'!I20+'Activity 2'!I20+'Activity 3'!I20 -> 1 | J20: =G20*H20*I20 -> 47250 | K20: =G20*1.05 -> 4134.375 | L20: ='Program Budget'!N22 -> 12 | M20: =Admin!M20+'Activity 1'!M20+'Activity 2'!M20+'Activity 3'!M20 -> 1 | N20: =K20*L20*M20 -> 49612.5 | O20: =K20*1.05 -> 4341.0938 | P20: ='Program Budget'!Q22 -> 12 | Q20: =Admin!Q20+'Activity 1'!Q20+'Activity 2'!Q20+'Activity 3'!Q20 -> 1 | R20: =O20*P20*Q20 -> 52093.125 | S20: =O20*1.05 -> 4558.1484 | T20: ='Program Budget'!T22 -> 9 | U20: =Admin!U20+'Activity 1'!U20+'Activity 2'!U20+'Activity 3'!U20 -> 1 | V20: =S20*T20*U20 -> 41023.336 | W20: =F20+J20+N20+R20+V20 -> 216228.96
A21: ='Program Budget'!D23 -> Communications Specialists | B21: ='Program Budget'!F23 -> Month | C21: ='Program Budget'!H23 -> 1500 | D21: ='Program Budget'!G23 -> 7 | E21: =Admin!E21+'Activity 1'!E21+'Activity 2'!E21+'Activity 3'!E21 -> 1 | F21: =C21*D21*E21 -> 10500 | G21: =C21*1.05 -> 1575 | H21: ='Program Budget'!K23 -> 12 | I21: =Admin!I21+'Activity 1'!I21+'Activity 2'!I21+'Activity 3'!I21 -> 1 | J21: =G21*H21*I21 -> 18900 | K21: =G21*1.05 -> 1653.75 | L21: ='Program Budget'!N23 -> 12 | M21: =Admin!M21+'Activity 1'!M21+'Activity 2'!M21+'Activity 3'!M21 -> 1 | N21: =K21*L21*M21 -> 19845 | O21: =K21*1.05 -> 1736.4375 | P21: ='Program Budget'!Q23 -> 12 | Q21: =Admin!Q21+'Activity 1'!Q21+'Activity 2'!Q21+'Activity 3'!Q21 -> 1 | R21: =O21*P21*Q21 -> 20837.25 | S21: =O21*1.05 -> 1823.2594 | T21: ='Program Budget'!T23 -> 10 | U21: =Admin!U21+'Activity 1'!U21+'Activity 2'!U21+'Activity 3'!U21 -> 1 | V21: =S21*T21*U21 -> 18232.594 | W21: =F21+J21+N21+R21+V21 -> 88314.844
... A30: ='Program Budget'!D32 -> Driver (3 Individuals) | B30: ='Program Budget'!F32 -> Month | C30: ='Program Budget'!H32 -> 2250 | D30: ='Program Budget'!G32 -> 3 | E30: =Admin!E30+'Activity 1'!E30+'Activity 2'!E30+'Activity 3'!E30 -> 1 | F30: =C30*D30*E30 -> 6750 | G30: =C30*1.05 -> 2362.5 | H30: ='Program Budget'!K32 -> 12 | I30: =Admin!I30+'Activity 1'!I30+'Activity 2'!I30+'Activity 3'!I30 -> 1 | J30: =G30*H30*I30 -> 28350 | K30: =G30*1.05 -> 2480.625 | L30: ='Program Budget'!N32 -> 12 | M30: =Admin!M30+'Activity 1'!M30+'Activity 2'!M30+'Activity 3'!M30 -> 1 | N30: =K30*L30*M30 -> 29767.5 | O30: =K30*1.05 -> 2604.6562 | P30: ='Program Budget'!Q32 -> 12 | Q30: =Admin!Q30+'Activity 1'!Q30+'Activity 2'!Q30+'Activity 3'!Q30 -> 1 | R30: =O30*P30*Q30 -> 31255.875 | S30: =O30*1.05 -> 2734.8891 | T30: ='Program Budget'!T32 -> 9 | U30: =Admin!U30+'Activity 1'!U30+'Activity 2'!U30+'Activity 3'!U30 -> 1 | V30: =S30*T30*U30 -> 24614.002 | W30: =F30+J30+N30+R30+V30 -> 120737.38
A31: Total Local Salary Cost | F31: =SUM(F10:F30) -> 522583.33 | J31: =SUM(J10:J30) -> 775950 | N31: =SUM(N10:N30) -> 814747.5 | R31: =SUM(R10:R30) -> 855484.88 | V31: =SUM(V10:V30) -> 747435.05 | W31: =F31+J31+N31+R31+V31 -> 3716200.8
A32: HQ Staff
A33: ='Program Budget'!D34 -> Senior Program Director | B33: ='Program Budget'!F34 -> Month | C33: ='Program Budget'!H34 -> 11250 | D33: ='Program Budget'!G34 -> 12 | E33: ='Program Budget'!E34 -> 0.2 | F33: =C33*D33*E33 -> 27000 | G33: =C33*1.05 -> 11812.5 | H33: ='Program Budget'!K34 -> 12 | I33: ='Program Budget'!J34 -> 0.2 | J33: =G33*H33*I33 -> 28350 | K33: =G33*1.05 -> 12403.125 | L33: ='Program Budget'!N34 -> 12 | M33: ='Program Budget'!M34 -> 0.2 | N33: =K33*L33*M33 -> 29767.5 | O33: =K33*1.05 -> 13023.281 | P33: ='Program Budget'!Q34 -> 12 | Q33: ='Program Budget'!P34 -> 0.2 | R33: =O33*P33*Q33 -> 31255.875 | S33: =O33*1.05 -> 13674.445 | T33: ='Program Budget'!T34 -> 12 | U33: ='Program Budget'!S34 -> 0.2 | V33: =S33*T33*U33 -> 32818.669 | W33: =F33+J33+N33+R33+V33 -> 149192.04
A34: ='Program Budget'!D35 -> Associate Director | B34: ='Program Budget'!F35 -> Month | C34: ='Program Budget'!H35 -> 7500 | D34: ='Program Budget'!G35 -> 12 | E34: ='Program Budget'!E35 -> 1 | F34: =C34*D34*E34 -> 90000 | G34: =C34*1.05 -> 7875 | H34: ='Program Budget'!K35 -> 12 | I34: ='Program Budget'!J35 -> 1 | J34: =G34*H34*I34 -> 94500 | K34: =G34*1.05 -> 8268.75 | L34: ='Program Budget'!N35 -> 12 | M34: ='Program Budget'!M35 -> 1 | N34: =K34*L34*M34 -> 99225 | O34: =K34*1.05 -> 8682.1875 | P34: ='Program Budget'!Q35 -> 12 | Q34: ='Program Budget'!P35 -> 1 | R34: =O34*P34*Q34 -> 104186.25 | S34: =O34*1.05 -> 9116.2969 | T34: ='Program Budget'!T35 -> 12 | U34: ='Program Budget'!S35 -> 1 | V34: =S34*T34*U34 -> 109395.56 | W34: =F34+J34+N34+R34+V34 -> 497306.81
A35: Total HQ Staff | F35: =SUM(F33:F34) -> 117000 | J35: =SUM(J33:J34) -> 122850 | N35: =SUM(N33:N34) -> 128992.5 | R35: =SUM(R33:R34) -> 135442.12 | V35: =SUM(V33:V34) -> 142214.23 | W35: =+F35+J35+N35+R35+V35 -> 646498.86
A37: Subtotal: Salaries & Wages | F37: =F35+F31+F8 -> 639583.33 | J37: =J35+J31+J8 -> 898800 | N37: =N35+N31+N8 -> 943740 | R37: =R35+R31+R8 -> 990927 | V37: =V35+V31+V8 -> 889649.28 | W37: =+F37+J37+N37+R37+V37 -> 4362699.6
A38: Fringe
A39: USN/TCN Staff | F39: =C39*D39*E39 -> 0 | J39: =G39*H39*I39 -> 0 | N39: =K39*L39*M39 -> 0 | R39: =O39*P39*Q39 -> 0 | V39: =S39*T39*U39 -> 0 | W39: =F39+J39+N39+R39+V39 -> 0
A40: CCN Staff | B40: ='Program Budget'!F41 -> % | C40: =F31 -> 522583.33 | D40: 1 | E40: ='Program Budget'!H40 -> 0.455 | F40: =C40*D40*E40 -> 237775.42 | G40: =J31 -> 775950 | H40: 1 | I40: =E40 -> 0.455 | J40: =G40*H40*I40 -> 353057.25 | K40: =N31 -> 814747.5 | L40: 1 | M40: =I40 -> 0.455 | N40: =K40*L40*M40 -> 370710.11 | O40: =R31 -> 855484.88 | P40: 1 | Q40: =M40 -> 0.455 | R40: =O40*P40*Q40 -> 389245.62 | S40: =V31 -> 747435.05 | T40: 1 | U40: =Q40 -> 0.455 | V40: =S40*T40*U40 -> 340082.95 | W40: =F40+J40+N40+R40+V40 -> 1690871.3
A41: HQ Staff | B41: ='Program Budget'!F41 -> % | C41: =F35 -> 117000 | D41: 1 | E41: ='Program Budget'!H41 -> 0.2347 | F41: =C41*D41*E41 -> 27459.9 | G41: =J35 -> 122850 | H41: 1 | I41: =E41 -> 0.2347 | J41: =G41*H41*I41 -> 28832.895 | K41: =N35 -> 128992.5 | L41: 1 | M41: =I41 -> 0.2347 | N41: =K41*L41*M41 -> 30274.54 | O41: =R35 -> 135442.12 | P41: 1 | Q41: =M41 -> 0.2347 | R41: =O41*P41*Q41 -> 31788.267 | S41: =V35 -> 142214.23 | T41: 1 | U41: =Q41 -> 0.2347 | V41: =S41*T41*U41 -> 33377.68 | W41: =F41+J41+N41+R41+V41 -> 151733.28
A42: Total: Fringe Benefits | F42: =+SUM(F39:F41) -> 265235.32 | J42: =+SUM(J39:J41) -> 381890.15 | N42: =+SUM(N39:N41) -> 400984.65 | R42: =+SUM(R39:R41) -> 421033.88 | V42: =+SUM(V39:V41) -> 373460.63 | W42: =+F42+J42+N42+R42+V42 -> 1842604.6
A43: Allowances
A44: USN/TCN Staff
A45: None | F45: =C45*D45*E45 -> 0 | J45: =G45*H45*I45 -> 0 | N45: =K45*L45*M45 -> 0 | R45: =O45*P45*Q45 -> 0 | V45: =S45*T45*U45 -> 0 | W45: =F45+J45+N45+R45+V45 -> 0
A46: Total: Allowances | F46: =SUM(F44:F45) -> 0 | J46: =SUM(J44:J45) -> 0 | N46: =SUM(N44:N45) -> 0 | R46: =SUM(R44:R45) -> 0 | V46: =SUM(V44:V45) -> 0 | W46: =F46+J46+N46+R46+V46 -> 0
A48: Subtotal: Benefits | F48: =F46+F42 -> 265235.32 | J48: =J46+J42 -> 381890.15 | N48: =N46+N42 -> 400984.65 | R48: =R46+R42 -> 421033.88 | V48: =V46+V42 -> 373460.63 | W48: =+F48+J48+N48+R48+V48 -> 1842604.6
A49: International Travel
A50: ='Program Budget'!D47 -> Airfare - DC-Tunisia - HQ Project Management Trip | B50: ='Program Budget'!F47 -> Trip | C50: ='Program Budget'!H47 -> 1400 | D50: ='Program Budget'!G47 -> 5 | E50: 1 | F50: =C50*D50*E50 -> 7000 | G50: =C50*1.07 -> 1498 | H50: ='Program Budget'!K47 -> 5 | I50: 1 | J50: =G50*H50*I50 -> 7490 | K50: =G50*1.07 -> 1602.86 | L50: ='Program Budget'!N47 -> 5 | M50: 1 | N50: =K50*L50*M50 -> 8014.3 | O50: =K50*1.07 -> 1715.0602 | P50: ='Program Budget'!Q47 -> 5 | Q50: 1 | R50: =O50*P50*Q50 -> 8575.301 | S50: =O50*1.07 -> 1835.1144 | T50: ='Program Budget'!T47 -> 5 | U50: 1 | V50: =S50*T50*U50 -> 9175.5721 | W50: =F50+J50+N50+R50+V50 -> 40255.173
A51: ='Program Budget'!D52 -> Airfare - Roundtrip - Tunisia to USA | B51: ='Program Budget'!F52 -> Trip | C51: ='Program Budget'!H52 -> 1400 | D51: ='Program Budget'!G52 -> 4 | E51: 1 | F51: =C51*D51*E51 -> 5600 | G51: =C51*1.07 -> 1498 | H51: ='Program Budget'!K52 -> 4 | I51: 1 | J51: =G51*H51*I51 -> 5992 | K51: =G51*1.07 -> 1602.86 | L51: ='Program Budget'!N52 -> 4 | M51: 1 | N51: =K51*L51*M51 -> 6411.44 | O51: =K51*1.07 -> 1715.0602 | P51: ='Program Budget'!Q52 -> 4 | Q51: 1 | R51: =O51*P51*Q51 -> 6860.2408 | S51: =O51*1.07 -> 1835.1144 | T51: ='Program Budget'!T52 -> 4 | U51: 1 | V51: =S51*T51*U51 -> 7340.4577 | W51: =F51+J51+N51+R51+V51 -> 32204.138
...

Sheet Sheet1

Sheet Admin
A2: Item | B2: Type of Unit | C2: Year 1 | G2: Year 2 | K2: Year 3 | O2: Year 4 | S2: Year 5 | W2: Total
C3: Cost | D3: Quantity | E3: Percent Allocated | F3: Total | G3: Cost | H3: Quantity | I3: Percent Allocated | J3: Total | K3: Cost | L3: Quantity | M3: Percent Allocated | N3: Total | O3: Cost | P3: Quantity | Q3: Percent Allocated | R3: Total | S3: Cost | T3: Quantity | U3: Percent Allocated | V3: Total | AF3: Chart of Accounts
A4: Direct Costs | AE4: Line# | AF4: Account | AG4: Account Name
A5: Salaries
A6: USN/TCN Staff
A7: None | F7: =C7*D7*E7 -> 0 | J7: =G7*H7*I7 -> 0 | N7: =K7*L7*M7 -> 0 | R7: =O7*P7*Q7 -> 0 | V7: =S7*T7*U7 -> 0 | W7: =F7+J7+N7+R7+V7 -> 0
A8: Total: Expatriate Salaries & Wages | F8: =SUM(F7:F7) -> 0 | J8: =SUM(J7:J7) -> 0 | N8: =SUM(N7:N7) -> 0 | R8: =SUM(R7:R7) -> 0 | V8: =SUM(V7:V7) -> 0 | W8: =+F8+J8+N8+R8+V8 -> 0
A9: CNN Staff
A10: ='Program Budget'!D12 -> Key Personnel: Chief of Party - Ms. Rym Ayari | B10: ='Program Budget'!F12 -> Month | C10: ='Program Budget'!H12 -> 13000 | D10: ='Program Budget'!G12 -> 12 | E10: ='Program Budget'!E12 -> 0.3 | F10: =C10*D10*E10 -> 46800 | G10: =C10*1.05 -> 13650 | H10: ='Program Budget'!K12 -> 12 | I10: ='Program Budget'!J12 -> 0.1 | J10: =G10*H10*I10 -> 16380 | K10: =G10*1.05 -> 14332.5 | L10: ='Program Budget'!N12 -> 12 | M10: ='Program Budget'!M12 -> 0.1 | N10: =K10*L10*M10 -> 17199 | O10: =K10*1.05 -> 15049.125 | P10: ='Program Budget'!Q12 -> 12 | Q10: ='Program Budget'!P12 -> 0.1 | R10: =O10*P10*Q10 -> 18058.95 | S10: =O10*1.05 -> 15801.581 | T10: ='Program Budget'!T12 -> 12 | U10: ='Program Budget'!S12 -> 0.1 | V10: =S10*T10*U10 -> 18961.898 | W10: =F10+J10+N10+R10+V10 -> 117399.85 | AE10: 180 | AF10: 50-01-2-020 | AG10: DIR-USN (Expat) Labor
A11: ='Program Budget'!D13 -> Key Personnel: Technical Director | B11: ='Program Budget'!F13 -> Month | C11: ='Program Budget'!H13 -> 3916.6667 | D11: ='Program Budget'!G13 -> 9 | E11: ='Program Budget'!E13 -> 0.3 | F11: =C11*D11*E11 -> 10575 | G11: =C11*1.05 -> 4112.5 | H11: ='Program Budget'!K13 -> 12 | I11: ='Program Budget'!J13 -> 0 | J11: =G11*H11*I11 -> 0 | K11: =G11*1.05 -> 4318.125 | L11: ='Program Budget'!N13 -> 12 | M11: ='Program Budget'!M13 -> 0 | N11: =K11*L11*M11 -> 0 | O11: =K11*1.05 -> 4534.0312 | P11: ='Program Budget'!Q13 -> 12 | Q11: ='Program Budget'!P13 -> 0 | R11: =O11*P11*Q11 -> 0 | S11: =O11*1.05 -> 4760.7328 | T11: ='Program Budget'!T13 -> 9 | U11: ='Program Budget'!S13 -> 0 | V11: =S11*T11*U11 -> 0 | W11: =F11+J11+N11+R11+V11 -> 10575 | AE11: 180 | AF11: 50-01-2-020 | AG11: DIR-USN (Expat) Labor
A12: ='Program Budget'!D14 -> Technical Lead Component 1 | B12: ='Program Budget'!F14 -> Month | C12: ='Program Budget'!H14 -> 2500 | D12: ='Program Budget'!G14 -> 6 | E12: ='Program Budget'!E14 -> 0.2 | F12: =C12*D12*E12 -> 3000 | G12: =C12*1.05 -> 2625 | H12: ='Program Budget'!K14 -> 12 | I12: ='Program Budget'!J14 -> 0 | J12: =G12*H12*I12 -> 0 | K12: =G12*1.05 -> 2756.25 | L12: ='Program Budget'!N14 -> 12 | M12: ='Program Budget'!M14 -> 0 | N12: =K12*L12*M12 -> 0 | O12: =K12*1.05 -> 2894.0625 | P12: ='Program Budget'!Q14 -> 12 | Q12: ='Program Budget'!P14 -> 0 | R12: =O12*P12*Q12 -> 0 | S12: =O12*1.05 -> 3038.7656 | T12: ='Program Budget'!T14 -> 9 | U12: ='Program Budget'!S14 -> 0 | V12: =S12*T12*U12 -> 0 | W12: =F12+J12+N12+R12+V12 -> 3000 | AE12: 180 | AF12: 50-01-2-020 | AG12: DIR-USN (Expat) Labor
A13: ='Program Budget'!D15 -> Technical Lead Component 2 | B13: ='Program Budget'!F15 -> Month | C13: ='Program Budget'!H15 -> 2500 | D13: ='Program Budget'!G15 -> 6 | E13: ='Program Budget'!E15 -> 0.2 | F13: =C13*D13*E13 -> 3000 | G13: =C13*1.05 -> 2625 | H13: ='Program Budget'!K15 -> 12 | I13: ='Program Budget'!J15 -> 0 | J13: =G13*H13*I13 -> 0 | K13: =G13*1.05 -> 2756.25 | L13: ='Program Budget'!N15 -> 12 | M13: ='Program Budget'!M15 -> 0 | N13: =K13*L13*M13 -> 0 | O13: =K13*1.05 -> 2894.0625 | P13: ='Program Budget'!Q15 -> 12 | Q13: ='Program Budget'!P15 -> 0 | R13: =O13*P13*Q13 -> 0 | S13: =O13*1.05 -> 3038.7656 | T13: ='Program Budget'!T15 -> 9 | U13: ='Program Budget'!S15 -> 0 | V13: =S13*T13*U13 -> 0 | W13: =F13+J13+N13+R13+V13 -> 3000 | AE13: 180 | AF13: 50-01-2-020 | AG13: DIR-USN (Expat) Labor
A14: ='Program Budget'!D16 -> Technical Lead Component 3 | B14: ='Program Budget'!F16 -> Month | C14: ='Program Budget'!H16 -> 2500 | D14: ='Program Budget'!G16 -> 6 | E14: ='Program Budget'!E16 -> 0.2 | F14: =C14*D14*E14 -> 3000 | G14: =C14*1.05 -> 2625 | H14: ='Program Budget'!K16 -> 12 | I14: ='Program Budget'!J16 -> 0 | J14: =G14*H14*I14 -> 0 | K14: =G14*1.05 -> 2756.25 | L14: ='Program Budget'!N16 -> 12 | M14: ='Program Budget'!M16 -> 0 | N14: =K14*L14*M14 -> 0 | O14: =K14*1.05 -> 2894.0625 | P14: ='Program Budget'!Q16 -> 12 | Q14: ='Program Budget'!P16 -> 0 | R14: =O14*P14*Q14 -> 0 | S14: =O14*1.05 -> 3038.7656 | T14: ='Program Budget'!T16 -> 9 | U14: ='Program Budget'!S16 -> 0 | V14: =S14*T14*U14 -> 0 | W14: =F14+J14+N14+R14+V14 -> 3000 | AE14: 180 | AF14: 50-01-2-020 | AG14: DIR-USN (Expat) Labor
A15: ='Program Budget'!D17 -> Technical Specialist Component 1 | B15: ='Program Budget'!F17 -> Month | C15: ='Program Budget'!H17 -> 1833.3333 | D15: ='Program Budget'!G17 -> 6 | E15: ='Program Budget'!E17 -> 0.2 | F15: =C15*D15*E15 -> 2200 | G15: =C15*1.05 -> 1925 | H15: ='Program Budget'!K17 -> 12 | I15: ='Program Budget'!J17 -> 0 | J15: =G15*H15*I15 -> 0 | K15: =G15*1.05 -> 2021.25 | L15: ='Program Budget'!N17 -> 12 | M15: ='Program Budget'!M17 -> 0 | N15: =K15*L15*M15 -> 0 | O15: =K15*1.05 -> 2122.3125 | P15: ='Program Budget'!Q17 -> 12 | Q15: ='Program Budget'!P17 -> 0 | R15: =O15*P15*Q15 -> 0 | S15: =O15*1.05 -> 2228.4281 | T15: ='Program Budget'!T17 -> 6 | U15: ='Program Budget'!S17 -> 0 | V15: =S15*T15*U15 -> 0 | W15: =F15+J15+N15+R15+V15 -> 2200
A16: ='Program Budget'!D18 -> Technical Specialist Component 2 | B16: ='Program Budget'!F18 -> Month | C16: ='Program Budget'!H18 -> 1833.3333 | D16: ='Program Budget'!G18 -> 6 | E16: ='Program Budget'!E18 -> 0.2 | F16: =C16*D16*E16 -> 2200 | G16: =C16*1.05 -> 1925 | H16: ='Program Budget'!K18 -> 12 | I16: ='Program Budget'!J18 -> 0 | J16: =G16*H16*I16 -> 0 | K16: =G16*1.05 -> 2021.25 | L16: ='Program Budget'!N18 -> 12 | M16: ='Program Budget'!M18 -> 0 | N16: =K16*L16*M16 -> 0 | O16: =K16*1.05 -> 2122.3125 | P16: ='Program Budget'!Q18 -> 12 | Q16: ='Program Budget'!P18 -> 0 | R16: =O16*P16*Q16 -> 0 | S16: =O16*1.05 -> 2228.4281 | T16: ='Program Budget'!T18 -> 6 | U16: ='Program Budget'!S18 -> 0 | V16: =S16*T16*U16 -> 0 | W16: =F16+J16+N16+R16+V16 -> 2200
A17: ='Program Budget'!D19 -> Technical Specialist Component 3 | B17: ='Program Budget'!F19 -> Month | C17: ='Program Budget'!H19 -> 1833.3333 | D17: ='Program Budget'!G19 -> 6 | E17: ='Program Budget'!E19 -> 0.2 | F17: =C17*D17*E17 -> 2200 | G17: =C17*1.05 -> 1925 | H17: ='Program Budget'!K19 -> 12 | I17: ='Program Budget'!J19 -> 0 | J17: =G17*H17*I17 -> 0 | K17: =G17*1.05 -> 2021.25 | L17: ='Program Budget'!N19 -> 12 | M17: ='Program Budget'!M19 -> 0 | N17: =K17*L17*M17 -> 0 | O17: =K17*1.05 -> 2122.3125 | P17: ='Program Budget'!Q19 -> 12 | Q17: ='Program Budget'!P19 -> 0 | R17: =O17*P17*Q17 -> 0 | S17: =O17*1.05 -> 2228.4281 | T17: ='Program Budget'!T19 -> 6 | U17: ='Program Budget'!S19 -> 0 | V17: =S17*T17*U17 -> 0 | W17: =F17+J17+N17+R17+V17 -> 2200 | AE17: 180 | AF17: 50-01-2-020 | AG17: DIR-USN (Expat) Labor
A18: ='Program Budget'!D20 -> Capacity Building Specialist (2) | B18: ='Program Budget'!F20 -> Month | C18: ='Program Budget'!H20 -> 3333.3333 | D18: ='Program Budget'!G20 -> 4 | E18: ='Program Budget'!E20 -> 0.2 | F18: =C18*D18*E18 -> 2666.6667 | G18: =C18*1.05 -> 3500 | H18: ='Program Budget'!K20 -> 12 | I18: ='Program Budget'!J20 -> 0 | J18: =G18*H18*I18 -> 0 | K18: =G18*1.05 -> 3675 | L18: ='Program Budget'!N20 -> 12 | M18: ='Program Budget'!M20 -> 0 | N18: =K18*L18*M18 -> 0 | O18: =K18*1.05 -> 3858.75 | P18: ='Program Budget'!Q20 -> 12 | Q18: ='Program Budget'!P20 -> 0 | R18: =O18*P18*Q18 -> 0 | S18: =O18*1.05 -> 4051.6875 | T18: ='Program Budget'!T20 -> 5 | U18: ='Program Budget'!S20 -> 0 | V18: =S18*T18*U18 -> 0 | W18: =F18+J18+N18+R18+V18 -> 2666.6667 | AE18: 180 | AF18: 50-01-2-020 | AG18: DIR-USN (Expat) Labor
A19: ='Program Budget'!D21 -> Sociocultural and Gender Specialist | B19: ='Program Budget'!F21 -> Month | C19: ='Program Budget'!H21 -> 1833.3333 | D19: ='Program Budget'!G21 -> 7 | E19: ='Program Budget'!E21 -> 0.25 | F19: =C19*D19*E19 -> 3208.3333 | G19: =C19*1.05 -> 1925 | H19: ='Program Budget'!K21 -> 12 | I19: ='Program Budget'!J21 -> 0 | J19: =G19*H19*I19 -> 0 | K19: =G19*1.05 -> 2021.25 | L19: ='Program Budget'!N21 -> 12 | M19: ='Program Budget'!M21 -> 0 | N19: =K19*L19*M19 -> 0 | O19: =K19*1.05 -> 2122.3125 | P19: ='Program Budget'!Q21 -> 12 | Q19: ='Program Budget'!P21 -> 0 | R19: =O19*P19*Q19 -> 0 | S19: =O19*1.05 -> 2228.4281 | T19: ='Program Budget'!T21 -> 9 | U19: ='Program Budget'!S21 -> 0 | V19: =S19*T19*U19 -> 0 | W19: =F19+J19+N19+R19+V19 -> 3208.3333
A20: ='Program Budget'!D22 -> Sociocultural and Gender Officers (3) | B20: ='Program Budget'!F22 -> Month | C20: ='Program Budget'!H22 -> 3750 | D20: ='Program Budget'!G22 -> 7 | E20: ='Program Budget'!E22 -> 0.25 | F20: =C20*D20*E20 -> 6562.5 | G20: =C20*1.05 -> 3937.5 | H20: ='Program Budget'!K22 -> 12 | I20: ='Program Budget'!J22 -> 0 | J20: =G20*H20*I20 -> 0 | K20: =G20*1.05 -> 4134.375 | L20: ='Program Budget'!N22 -> 12 | M20: ='Program Budget'!M22 -> 0 | N20: =K20*L20*M20 -> 0 | O20: =K20*1.05 -> 4341.0938 | P20: ='Program Budget'!Q22 -> 12 | Q20: ='Program Budget'!P22 -> 0 | R20: =O20*P20*Q20 -> 0 | S20: =O20*1.05 -> 4558.1484 | T20: ='Program Budget'!T22 -> 9 | U20: ='Program Budget'!S22 -> 0 | V20: =S20*T20*U20 -> 0 | W20: =F20+J20+N20+R20+V20 -> 6562.5
A21: ='Program Budget'!D23 -> Communications Specialists | B21: ='Program Budget'!F23 -> Month | C21: ='Program Budget'!H23 -> 1500 | D21: ='Program Budget'!G23 -> 7 | E21: ='Program Budget'!E23 -> 0.25 | F21: =C21*D21*E21 -> 2625 | G21: =C21*1.05 -> 1575 | H21: ='Program Budget'!K23 -> 12 | I21: ='Program Budget'!J23 -> 0.1 | J21: =G21*H21*I21 -> 1890 | K21: =G21*1.05 -> 1653.75 | L21: ='Program Budget'!N23 -> 12 | M21: ='Program Budget'!M23 -> 0.1 | N21: =K21*L21*M21 -> 1984.5 | O21: =K21*1.05 -> 1736.4375 | P21: ='Program Budget'!Q23 -> 12 | Q21: ='Program Budget'!P23 -> 0.1 | R21: =O21*P21*Q21 -> 2083.725 | S21: =O21*1.05 -> 1823.2594 | T21: ='Program Budget'!T23 -> 10 | U21: ='Program Budget'!S23 -> 0.1 | V21: =S21*T21*U21 -> 1823.2594 | W21: =F21+J21+N21+R21+V21 -> 10406.484
A22: ='Program Budget'!D24 -> M&E Director | B22: ='Program Budget'!F24 -> Month | C22: ='Program Budget'!H24 -> 3916.6667 | D22: ='Program Budget'!G24 -> 9 | E22: ='Program Budget'!E24 -> 0.25 | F22: =C22*D22*E22 -> 8812.5 | G22: =C22*1.05 -> 4112.5 | H22: ='Program Budget'!K24 -> 12 | I22: ='Program Budget'!J24 -> 0.1 | J22: =G22*H22*I22 -> 4935 | K22: =G22*1.05 -> 4318.125 | L22: ='Program Budget'!N24 -> 12 | M22: ='Program Budget'!M24 -> 0.1 | N22: =K22*L22*M22 -> 5181.75 | O22: =K22*1.05 -> 4534.0312 | P22: ='Program Budget'!Q24 -> 12 | Q22: ='Program Budget'!P24 -> 0.1 | R22: =O22*P22*Q22 -> 5440.8375 | S22: =O22*1.05 -> 4760.7328 | T22: ='Program Budget'!T24 -> 12 | U22: ='Program Budget'!S24 -> 0.1 | V22: =S22*T22*U22 -> 5712.8794 | W22: =F22+J22+N22+R22+V22 -> 30082.967 | AE22: 180 | AF22: 50-01-2-020 | AG22: DIR-USN (Expat) Labor
A23: ='Program Budget'!D25 -> M&E Specialist | B23: ='Program Budget'!F25 -> Month | C23: ='Program Budget'!H25 -> 1833.3333 | D23: ='Program Budget'!G25 -> 8 | E23: ='Program Budget'!E25 -> 0.25 | F23: =C23*D23*E23 -> 3666.6667 | G23: =C23*1.05 -> 1925 | H23: ='Program Budget'!K25 -> 12 | I23: ='Program Budget'!J25 -> 0.1 | J23: =G23*H23*I23 -> 2310 | K23: =G23*1.05 -> 2021.25 | L23: ='Program Budget'!N25 -> 12 | M23: ='Program Budget'!M25 -> 0.1 | N23: =K23*L23*M23 -> 2425.5 | O23: =K23*1.05 -> 2122.3125 | P23: ='Program Budget'!Q25 -> 12 | Q23: ='Program Budget'!P25 -> 0.1 | R23: =O23*P23*Q23 -> 2546.775 | S23: =O23*1.05 -> 2228.4281 | T23: ='Program Budget'!T25 -> 10 | U23: ='Program Budget'!S25 -> 0.1 | V23: =S23*T23*U23 -> 2228.4281 | W23: =F23+J23+N23+R23+V23 -> 13177.37 | AE23: 180 | AF23: 50-01-2-020 | AG23: DIR-USN (Expat) Labor
A24: ='Program Budget'!D26 -> Key Personnel: Finance Director | B24: ='Program Budget'!F26 -> Month | C24: ='Program Budget'!H26 -> 3916.6667 | D24: ='Program Budget'!G26 -> 11 | E24: ='Program Budget'!E26 -> 0.25 | F24: =C24*D24*E24 -> 10770.833 | G24: =C24*1.05 -> 4112.5 | H24: ='Program Budget'!K26 -> 12 | I24: ='Program Budget'!J26 -> 0.25 | J24: =G24*H24*I24 -> 12337.5 | K24: =G24*1.05 -> 4318.125 | L24: ='Program Budget'!N26 -> 12 | M24: ='Program Budget'!M26 -> 0.25 | N24: =K24*L24*M24 -> 12954.375 | O24: =K24*1.05 -> 4534.0312 | P24: ='Program Budget'!Q26 -> 12 | Q24: ='Program Budget'!P26 -> 0.25 | R24: =O24*P24*Q24 -> 13602.094 | S24: =O24*1.05 -> 4760.7328 | T24: ='Program Budget'!T26 -> 12 | U24: ='Program Budget'!S26 -> 0.25 | V24: =S24*T24*U24 -> 14282.198 | W24: =F24+J24+N24+R24+V24 -> 63947.001 | AE24: 180 | AF24: 50-01-2-020 | AG24: DIR-USN (Expat) Labor
A25: ='Program Budget'!D27 -> Contracts & Compliance Specialist | B25: ='Program Budget'!F27 -> Month | C25: ='Program Budget'!H27 -> 1833.3333 | D25: ='Program Budget'!G27 -> 9 | E25: ='Program Budget'!E27 -> 0.25 | F25: =C25*D25*E25 -> 4125 | G25: =C25*1.05 -> 1925 | H25: ='Program Budget'!K27 -> 12 | I25: ='Program Budget'!J27 -> 0.25 | J25: =G25*H25*I25 -> 5775 | K25: =G25*1.05 -> 2021.25 | L25: ='Program Budget'!N27 -> 12 | M25: ='Program Budget'!M27 -> 0.25 | N25: =K25*L25*M25 -> 6063.75 | O25: =K25*1.05 -> 2122.3125 | P25: ='Program Budget'!Q27 -> 12 | Q25: ='Program Budget'!P27 -> 0.25 | R25: =O25*P25*Q25 -> 6366.9375 | S25: =O25*1.05 -> 2228.4281 | T25: ='Program Budget'!T27 -> 12 | U25: ='Program Budget'!S27 -> 0.25 | V25: =S25*T25*U25 -> 6685.2844 | W25: =F25+J25+N25+R25+V25 -> 29015.972
A26: ='Program Budget'!D28 -> Grants & Procurement Officer (2) | B26: ='Program Budget'!F28 -> Month | C26: ='Program Budget'!H28 -> 2500 | D26: ='Program Budget'!G28 -> 9 | E26: ='Program Budget'!E28 -> 0.25 | F26: =C26*D26*E26 -> 5625 | G26: =C26*1.05 -> 2625 | H26: ='Program Budget'!K28 -> 12 | I26: ='Program Budget'!J28 -> 0.25 | J26: =G26*H26*I26 -> 7875 | K26: =G26*1.05 -> 2756.25 | L26: ='Program Budget'!N28 -> 12 | M26: ='Program Budget'!M28 -> 0.25 | N26: =K26*L26*M26 -> 8268.75 | O26: =K26*1.05 -> 2894.0625 | P26: ='Program Budget'!Q28 -> 12 | Q26: ='Program Budget'!P28 -> 0.25 | R26: =O26*P26*Q26 -> 8682.1875 | S26: =O26*1.05 -> 3038.7656 | T26: ='Program Budget'!T28 -> 12 | U26: ='Program Budget'!S28 -> 0.25 | V26: =S26*T26*U26 -> 9116.2969 | W26: =F26+J26+N26+R26+V26 -> 39567.234 | AE26: 180 | AF26: 50-01-2-020 | AG26: DIR-USN (Expat) Labor
A27: ='Program Budget'!D29 -> Accountant | B27: ='Program Budget'!F29 -> Month | C27: ='Program Budget'!H29 -> 1666.6667 | D27: ='Program Budget'!G29 -> 10 | E27: ='Program Budget'!E29 -> 0.25 | F27: =C27*D27*E27 -> 4166.6667 | G27: =C27*1.05 -> 1750 | H27: ='Program Budget'!K29 -> 12 | I27: ='Program Budget'!J29 -> 0.25 | J27: =G27*H27*I27 -> 5250 | K27: =G27*1.05 -> 1837.5 | L27: ='Program Budget'!N29 -> 12 | M27: ='Program Budget'!M29 -> 0.25 | N27: =K27*L27*M27 -> 5512.5 | O27: =K27*1.05 -> 1929.375 | P27: ='Program Budget'!Q29 -> 12 | Q27: ='Program Budget'!P29 -> 0.25 | R27: =O27*P27*Q27 -> 5788.125 | S27: =O27*1.05 -> 2025.8438 | T27: ='Program Budget'!T29 -> 11 | U27: ='Program Budget'!S29 -> 0.25 | V27: =S27*T27*U27 -> 5571.0703 | W27: =F27+J27+N27+R27+V27 -> 26288.362 | AE27: 180 | AF27: 50-01-2-020 | AG27: DIR-USN (Expat) Labor
A28: ='Program Budget'!D30 -> Administrative Officer | B28: ='Program Budget'!F30 -> Month | C28: ='Program Budget'!H30 -> 833.33333 | D28: ='Program Budget'!G30 -> 9 | E28: ='Program Budget'!E30 -> 0.25 | F28: =C28*D28*E28 -> 1875 | G28: =C28*1.05 -> 875 | H28: ='Program Budget'!K30 -> 12 | I28: ='Program Budget'!J30 -> 0.25 | J28: =G28*H28*I28 -> 2625 | K28: =G28*1.05 -> 918.75 | L28: ='Program Budget'!N30 -> 12 | M28: ='Program Budget'!M30 -> 0.25 | N28: =K28*L28*M28 -> 2756.25 | O28: =K28*1.05 -> 964.6875 | P28: ='Program Budget'!Q30 -> 12 | Q28: ='Program Budget'!P30 -> 0.25 | R28: =O28*P28*Q28 -> 2894.0625 | S28: =O28*1.05 -> 1012.9219 | T28: ='Program Budget'!T30 -> 10 | U28: ='Program Budget'!S30 -> 0.25 | V28: =S28*T28*U28 -> 2532.3047 | W28: =F28+J28+N28+R28+V28 -> 12682.617 | AE28: 180 | AF28: 50-01-2-020 | AG28: DIR-USN (Expat) Labor
A29: ='Program Budget'!D31 -> Human Resources Manager | B29: ='Program Budget'!F31 -> Month | C29: ='Program Budget'!H31 -> 2500 | D29: ='Program Budget'!G31 -> 11 | E29: ='Program Budget'!E31 -> 0.25 | F29: =C29*D29*E29 -> 6875 | G29: =C29*1.05 -> 2625 | H29: ='Program Budget'!K31 -> 12 | I29: ='Program Budget'!J31 -> 0.25 | J29: =G29*H29*I29 -> 7875 | K29: =G29*1.05 -> 2756.25 | L29: ='Program Budget'!N31 -> 12 | M29: ='Program Budget'!M31 -> 0.25 | N29: =K29*L29*M29 -> 8268.75 | O29: =K29*1.05 -> 2894.0625 | P29: ='Program Budget'!Q31 -> 12 | Q29: ='Program Budget'!P31 -> 0.25 | R29: =O29*P29*Q29 -> 8682.1875 | S29: =O29*1.05 -> 3038.7656 | T29: ='Program Budget'!T31 -> 12 | U29: ='Program Budget'!S31 -> 0.25 | V29: =S29*T29*U29 -> 9116.2969 | W29: =F29+J29+N29+R29+V29 -> 40817.234 | AE29: 180 | AF29: 50-01-2-020 | AG29: DIR-USN (Expat) Labor
A30: ='Program Budget'!D32 -> Driver (3 Individuals) | B30: ='Program Budget'!F32 -> Month | C30: ='Program Budget'!H32 -> 2250 | D30: ='Program Budget'!G32 -> 3 | E30: ='Program Budget'!E32 -> 0.1 | F30: =C30*D30*E30 -> 675 | G30: =C30*1.05 -> 2362.5 | H30: ='Program Budget'!K32 -> 12 | I30: ='Program Budget'!J32 -> 0.25 | J30: =G30*H30*I30 -> 7087.5 | K30: =G30*1.05 -> 2480.625 | L30: ='Program Budget'!N32 -> 12 | M30: ='Program Budget'!M32 -> 0.25 | N30: =K30*L30*M30 -> 7441.875 | O30: =K30*1.05 -> 2604.6562 | P30: ='Program Budget'!Q32 -> 12 | Q30: ='Program Budget'!P32 -> 0.25 | R30: =O30*P30*Q30 -> 7813.9688 | S30: =O30*1.05 -> 2734.8891 | T30: ='Program Budget'!T32 -> 9 | U30: ='Program Budget'!S32 -> 0.25 | V30: =S30*T30*U30 -> 6153.5004 | W30: =F30+J30+N30+R30+V30 -> 29171.844 | AE30: 180 | AF30: 50-01-2-020 | AG30: DIR-USN (Expat) Labor
A31: Total Local Salary Cost | F31: =SUM(F10:F30) -> 134629.17 | J31: =SUM(J10:J30) -> 74340 | N31: =SUM(N10:N30) -> 78057 | R31: =SUM(R10:R30) -> 81959.85 | V31: =SUM(V10:V30) -> 82183.416 | W31: =SUM(W10:W30) -> 451169.43
A32: HQ Staff
A33: ='Program Budget'!D34 -> Senior Program Director | B33: ='Program Budget'!F34 -> Month | C33: ='Program Budget'!H34 -> 11250 | D33: ='Program Budget'!G34 -> 12 | E33: ='Program Budget'!E34 -> 0.2 | F33: =C33*D33*E33 -> 27000 | G33: =C33*1.05 -> 11812.5 | H33: ='Program Budget'!K34 -> 12 | I33: ='Program Budget'!J34 -> 0.2 | J33: =G33*H33*I33 -> 28350 | K33: =G33*1.05 -> 12403.125 | L33: ='Program Budget'!N34 -> 12 | M33: ='Program Budget'!M34 -> 0.2 | N33: =K33*L33*M33 -> 29767.5 | O33: =K33*1.05 -> 13023.281 | P33: ='Program Budget'!Q34 -> 12 | Q33: ='Program Budget'!P34 -> 0.2 | R33: =O33*P33*Q33 -> 31255.875 | S33: =O33*1.05 -> 13674.445 | T33: ='Program Budget'!T34 -> 12 | U33: ='Program Budget'!S34 -> 0.2 | V33: =S33*T33*U33 -> 32818.669 | W33: =F33+J33+N33+R33+V33 -> 149192.04 | AE33: 180 | AF33: 50-01-2-020 | AG33: DIR-USN (Expat) Labor
A34: ='Program Budget'!D35 -> Associate Director | B34: ='Program Budget'!F35 -> Month | C34: ='Program Budget'!H35 -> 7500 | D34: ='Program Budget'!G35 -> 12 | E34: ='Program Budget'!E35 -> 1 | F34: =C34*D34*E34 -> 90000 | G34: =C34*1.05 -> 7875 | H34: ='Program Budget'!K35 -> 12 | I34: ='Program Budget'!J35 -> 1 | J34: =G34*H34*I34 -> 94500 | K34: =G34*1.05 -> 8268.75 | L34: ='Program Budget'!N35 -> 12 | M34: ='Program Budget'!M35 -> 1 | N34: =K34*L34*M34 -> 99225 | O34: =K34*1.05 -> 8682.1875 | P34: ='Program Budget'!Q35 -> 12 | Q34: ='Program Budget'!P35 -> 1 | R34: =O34*P34*Q34 -> 104186.25 | S34: =O34*1.05 -> 9116.2969 | T34: ='Program Budget'!T35 -> 12 | U34: ='Program Budget'!S35 -> 1 | V34: =S34*T34*U34 -> 109395.56 | W34: =F34+J34+N34+R34+V34 -> 497306.81 | AE34: 180 | AF34: 50-01-2-020 | AG34: DIR-USN (Expat) Labor
A35: Total HQ Staff | F35: =SUM(F33:F34) -> 117000 | J35: =SUM(J33:J34) -> 122850 | N35: =SUM(N33:N34) -> 128992.5 | R35: =SUM(R33:R34) -> 135442.12 | V35: =SUM(V33:V34) -> 142214.23 | W35: =+F35+J35+N35+R35+V35 -> 646498.86
A37: Subtotal: Salaries & Wages | F37: =F35+F31+F8 -> 251629.17 | J37: =J35+J31+J8 -> 197190 | N37: =N35+N31+N8 -> 207049.5 | R37: =R35+R31+R8 -> 217401.98 | V37: =V35+V31+V8 -> 224397.65 | W37: =+F37+J37+N37+R37+V37 -> 1097668.3
A38: Fringe
A39: USN/TCN Staff | F39: =C39*D39*E39 -> 0 | J39: =G39*H39*I39 -> 0 | N39: =K39*L39*M39 -> 0 | R39: =O39*P39*Q39 -> 0 | V39: =S39*T39*U39 -> 0 | W39: =F39+J39+N39+R39+V39 -> 0 | AE39: 194 | AF39: 50-03-0-020 | AG39: DIR-Allocated USN Fringe
A40: CCN Staff | B40: ='Program Budget'!F41 -> % | C40: =F31 -> 134629.17 | D40: 1 | E40: ='Program Budget'!H40 -> 0.455 | F40: =C40*D40*E40 -> 61256.271 | G40: =J31 -> 74340 | H40: 1 | I40: =E40 -> 0.455 | J40: =G40*H40*I40 -> 33824.7 | K40: =N31 -> 78057 | L40: 1 | M40: =I40 -> 0.455 | N40: =K40*L40*M40 -> 35515.935 | O40: =R31 -> 81959.85 | P40: 1 | Q40: =M40 -> 0.455 | R40: =O40*P40*Q40 -> 37291.732 | S40: =V31 -> 82183.416 | T40: 1 | U40: =Q40 -> 0.455 | V40: =S40*T40*U40 -> 37393.454 | W40: =F40+J40+N40+R40+V40 -> 205282.09 | AE40: 197 | AF40: 50-03-0-050 | AG40: DIR-CCN Fringe
A41: HQ Staff | B41: ='Program Budget'!#REF! -> #REF! | C41: =F35 -> 117000 | D41: 1 | E41: ='Program Budget'!H41 -> 0.2347 | F41: =C41*D41*E41 -> 27459.9 | G41: =J35 -> 122850 | H41: 1 | I41: =E41 -> 0.2347 | J41: =G41*H41*I41 -> 28832.895 | K41: =N35 -> 128992.5 | L41: 1 | M41: =I41 -> 0.2347 | N41: =K41*L41*M41 -> 30274.54 | O41: =R35 -> 135442.12 | P41: 1 | Q41: =M41 -> 0.2347 | R41: =O41*P41*Q41 -> 31788.267 | S41: =V35 -> 142214.23 | T41: 1 | U41: =Q41 -> 0.2347 | V41: =S41*T41*U41 -> 33377.68 | W41: =F41+J41+N41+R41+V41 -> 151733.28 | AE41: 193 | AF41: 50-03-0-010 | AG41: DIR-Allocated HQ Fringe
A42: Total: Fringe Benefits | F42: =+SUM(F39:F41) -> 88716.171 | J42: =+SUM(J39:J41) -> 62657.595 | N42: =+SUM(N39:N41) -> 65790.475 | R42: =+SUM(R39:R41) -> 69079.998 | V42: =+SUM(V39:V41) -> 70771.135 | W42: =+F42+J42+N42+R42+V42 -> 357015.37
...

Sheet Activity 1
A2: Item | B2: Type of Unit | C2: Year 1 | G2: Year 2 | K2: Year 3 | O2: Year 4 | S2: Year 5 | W2: Total
C3: Cost | D3: Quantity | E3: Percent Allocated | F3: Total | G3: Cost | H3: Quantity | I3: Percent Allocated | J3: Total | K3: Cost | L3: Quantity | M3: Percent Allocated | N3: Total | O3: Cost | P3: Quantity | Q3: Percent Allocated | R3: Total | S3: Cost | T3: Quantity | U3: Percent Allocated | V3: Total | AF3: Chart of Accounts
A4: Direct Costs | AE4: Line# | AF4: Account | AG4: Account Name
A5: Salaries
A6: USN/TCN Staff
A7: None | F7: =C7*D7*E7 -> 0 | J7: =G7*H7*I7 -> 0 | N7: =K7*L7*M7 -> 0 | R7: =O7*P7*Q7 -> 0 | V7: =S7*T7*U7 -> 0 | W7: =F7+J7+N7+R7+V7 -> 0
A8: Total: Expatriate Salaries & Wages | F8: =SUM(F7:F7) -> 0 | J8: =SUM(J7:J7) -> 0 | N8: =SUM(N7:N7) -> 0 | R8: =SUM(R7:R7) -> 0 | V8: =SUM(V7:V7) -> 0 | W8: =+F8+J8+N8+R8+V8 -> 0
A9: CCN Staff
A10: ='Program Budget'!D12 -> Key Personnel: Chief of Party - Ms. Rym Ayari | B10: ='Program Budget'!F140 -> Month | C10: ='Program Budget'!H12 -> 13000 | D10: ='Program Budget'!G12 -> 12 | E10: ='Program Budget'!E140 -> 0.25 | F10: =C10*D10*E10 -> 39000 | G10: =C10*1.05 -> 13650 | H10: ='Program Budget'!K12 -> 12 | I10: ='Program Budget'!J140 -> 0.3 | J10: =G10*H10*I10 -> 49140 | K10: =G10*1.05 -> 14332.5 | L10: ='Program Budget'!N12 -> 12 | M10: ='Program Budget'!M140 -> 0.3 | N10: =K10*L10*M10 -> 51597 | O10: =K10*1.05 -> 15049.125 | P10: ='Program Budget'!Q12 -> 12 | Q10: ='Program Budget'!P140 -> 0.3 | R10: =O10*P10*Q10 -> 54176.85 | S10: =O10*1.05 -> 15801.581 | T10: ='Program Budget'!T12 -> 12 | U10: ='Program Budget'!S140 -> 0.3 | V10: =S10*T10*U10 -> 56885.692 | W10: =F10+J10+N10+R10+V10 -> 250799.54
A11: ='Program Budget'!D13 -> Key Personnel: Technical Director | B11: ='Program Budget'!F141 -> Month | C11: ='Program Budget'!H13 -> 3916.6667 | D11: ='Program Budget'!G13 -> 9 | E11: ='Program Budget'!E141 -> 0.25 | F11: =C11*D11*E11 -> 8812.5 | G11: =C11*1.05 -> 4112.5 | H11: ='Program Budget'!K13 -> 12 | I11: ='Program Budget'!J141 -> 0.35 | J11: =G11*H11*I11 -> 17272.5 | K11: =G11*1.05 -> 4318.125 | L11: ='Program Budget'!N13 -> 12 | M11: ='Program Budget'!M141 -> 0.35 | N11: =K11*L11*M11 -> 18136.125 | O11: =K11*1.05 -> 4534.0312 | P11: ='Program Budget'!Q13 -> 12 | Q11: ='Program Budget'!P141 -> 0.35 | R11: =O11*P11*Q11 -> 19042.931 | S11: =O11*1.05 -> 4760.7328 | T11: ='Program Budget'!T13 -> 9 | U11: ='Program Budget'!S141 -> 0.35 | V11: =S11*T11*U11 -> 14996.308 | W11: =F11+J11+N11+R11+V11 -> 78260.365 | AE11: 180 | AF11: 50-01-2-020 | AG11: DIR-USN (Expat) Labor
A12: ='Program Budget'!D14 -> Technical Lead Component 1 | B12: ='Program Budget'!F142 -> Month | C12: ='Program Budget'!H14 -> 2500 | D12: ='Program Budget'!G14 -> 6 | E12: ='Program Budget'!E142 -> 0.8 | F12: =C12*D12*E12 -> 12000 | G12: =C12*1.05 -> 2625 | H12: ='Program Budget'!K14 -> 12 | I12: ='Program Budget'!J142 -> 1 | J12: =G12*H12*I12 -> 31500 | K12: =G12*1.05 -> 2756.25 | L12: ='Program Budget'!N14 -> 12 | M12: ='Program Budget'!M142 -> 1 | N12: =K12*L12*M12 -> 33075 | O12: =K12*1.05 -> 2894.0625 | P12: ='Program Budget'!Q14 -> 12 | Q12: ='Program Budget'!P142 -> 1 | R12: =O12*P12*Q12 -> 34728.75 | S12: =O12*1.05 -> 3038.7656 | T12: ='Program Budget'!T14 -> 9 | U12: ='Program Budget'!S142 -> 1 | V12: =S12*T12*U12 -> 27348.891 | W12: =F12+J12+N12+R12+V12 -> 138652.64 | AE12: 180 | AF12: 50-01-2-020 | AG12: DIR-USN (Expat) Labor
A13: ='Program Budget'!D15 -> Technical Lead Component 2 | B13: ='Program Budget'!F143 -> Month | C13: ='Program Budget'!H15 -> 2500 | D13: ='Program Budget'!G15 -> 6 | E13: ='Program Budget'!E143 -> 0 | F13: =C13*D13*E13 -> 0 | G13: =C13*1.05 -> 2625 | H13: ='Program Budget'!K15 -> 12 | I13: ='Program Budget'!J143 -> 0 | J13: =G13*H13*I13 -> 0 | K13: =G13*1.05 -> 2756.25 | L13: ='Program Budget'!N15 -> 12 | M13: ='Program Budget'!M143 -> 0 | N13: =K13*L13*M13 -> 0 | O13: =K13*1.05 -> 2894.0625 | P13: ='Program Budget'!Q15 -> 12 | Q13: ='Program Budget'!P143 -> 0 | R13: =O13*P13*Q13 -> 0 | S13: =O13*1.05 -> 3038.7656 | T13: ='Program Budget'!T15 -> 9 | U13: ='Program Budget'!S143 -> 0 | V13: =S13*T13*U13 -> 0 | W13: =F13+J13+N13+R13+V13 -> 0 | AE13: 180 | AF13: 50-01-2-020 | AG13: DIR-USN (Expat) Labor
A14: ='Program Budget'!D16 -> Technical Lead Component 3 | B14: ='Program Budget'!F144 -> Month | C14: ='Program Budget'!H16 -> 2500 | D14: ='Program Budget'!G16 -> 6 | E14: ='Program Budget'!E144 -> 0 | F14: =C14*D14*E14 -> 0 | G14: =C14*1.05 -> 2625 | H14: ='Program Budget'!K16 -> 12 | I14: ='Program Budget'!J144 -> 0 | J14: =G14*H14*I14 -> 0 | K14: =G14*1.05 -> 2756.25 | L14: ='Program Budget'!N16 -> 12 | M14: ='Program Budget'!M144 -> 0 | N14: =K14*L14*M14 -> 0 | O14: =K14*1.05 -> 2894.0625 | P14: ='Program Budget'!Q16 -> 12 | Q14: ='Program Budget'!P144 -> 0 | R14: =O14*P14*Q14 -> 0 | S14: =O14*1.05 -> 3038.7656 | T14: ='Program Budget'!T16 -> 9 | U14: ='Program Budget'!S144 -> 0 | V14: =S14*T14*U14 -> 0 | W14: =F14+J14+N14+R14+V14 -> 0 | AE14: 180 | AF14: 50-01-2-020 | AG14: DIR-USN (Expat) Labor
A15: ='Program Budget'!D17 -> Technical Specialist Component 1 | B15: ='Program Budget'!F145 -> Month | C15: ='Program Budget'!H17 -> 1833.3333 | D15: ='Program Budget'!G17 -> 6 | E15: ='Program Budget'!E145 -> 0.8 | F15: =C15*D15*E15 -> 8800 | G15: =C15*1.05 -> 1925 | H15: ='Program Budget'!K17 -> 12 | I15: ='Program Budget'!J145 -> 1 | J15: =G15*H15*I15 -> 23100 | K15: =G15*1.05 -> 2021.25 | L15: ='Program Budget'!N17 -> 12 | M15: ='Program Budget'!M145 -> 1 | N15: =K15*L15*M15 -> 24255 | O15: =K15*1.05 -> 2122.3125 | P15: ='Program Budget'!Q17 -> 12 | Q15: ='Program Budget'!P145 -> 1 | R15: =O15*P15*Q15 -> 25467.75 | S15: =O15*1.05 -> 2228.4281 | T15: ='Program Budget'!T17 -> 6 | U15: ='Program Budget'!S145 -> 1 | V15: =S15*T15*U15 -> 13370.569 | W15: =F15+J15+N15+R15+V15 -> 94993.319
A16: ='Program Budget'!D18 -> Technical Specialist Component 2 | B16: ='Program Budget'!F146 -> Month | C16: ='Program Budget'!H18 -> 1833.3333 | D16: ='Program Budget'!G18 -> 6 | E16: ='Program Budget'!E146 -> 0 | F16: =C16*D16*E16 -> 0 | G16: =C16*1.05 -> 1925 | H16: ='Program Budget'!K18 -> 12 | I16: ='Program Budget'!J146 -> 0 | J16: =G16*H16*I16 -> 0 | K16: =G16*1.05 -> 2021.25 | L16: ='Program Budget'!N18 -> 12 | M16: ='Program Budget'!M146 -> 0 | N16: =K16*L16*M16 -> 0 | O16: =K16*1.05 -> 2122.3125 | P16: ='Program Budget'!Q18 -> 12 | Q16: ='Program Budget'!P146 -> 0 | R16: =O16*P16*Q16 -> 0 | S16: =O16*1.05 -> 2228.4281 | T16: ='Program Budget'!T18 -> 6 | U16: ='Program Budget'!S146 -> 0 | V16: =S16*T16*U16 -> 0 | W16: =F16+J16+N16+R16+V16 -> 0
A17: ='Program Budget'!D19 -> Technical Specialist Component 3 | B17: ='Program Budget'!F147 -> Month | C17: ='Program Budget'!H19 -> 1833.3333 | D17: ='Program Budget'!G19 -> 6 | E17: ='Program Budget'!E147 -> 0 | F17: =C17*D17*E17 -> 0 | G17: =C17*1.05 -> 1925 | H17: ='Program Budget'!K19 -> 12 | I17: ='Program Budget'!J147 -> 0 | J17: =G17*H17*I17 -> 0 | K17: =G17*1.05 -> 2021.25 | L17: ='Program Budget'!N19 -> 12 | M17: ='Program Budget'!M147 -> 0 | N17: =K17*L17*M17 -> 0 | O17: =K17*1.05 -> 2122.3125 | P17: ='Program Budget'!Q19 -> 12 | Q17: ='Program Budget'!P147 -> 0 | R17: =O17*P17*Q17 -> 0 | S17: =O17*1.05 -> 2228.4281 | T17: ='Program Budget'!T19 -> 6 | U17: ='Program Budget'!S147 -> 0 | V17: =S17*T17*U17 -> 0 | W17: =F17+J17+N17+R17+V17 -> 0
A18: ='Program Budget'!D20 -> Capacity Building Specialist (2) | B18: ='Program Budget'!F148 -> Month | C18: ='Program Budget'!H20 -> 3333.3333 | D18: ='Program Budget'!G20 -> 4 | E18: ='Program Budget'!E148 -> 0 | F18: =C18*D18*E18 -> 0 | G18: =C18*1.05 -> 3500 | H18: ='Program Budget'!K20 -> 12 | I18: ='Program Budget'!J148 -> 0 | J18: =G18*H18*I18 -> 0 | K18: =G18*1.05 -> 3675 | L18: ='Program Budget'!N20 -> 12 | M18: ='Program Budget'!M148 -> 0 | N18: =K18*L18*M18 -> 0 | O18: =K18*1.05 -> 3858.75 | P18: ='Program Budget'!Q20 -> 12 | Q18: ='Program Budget'!P148 -> 0 | R18: =O18*P18*Q18 -> 0 | S18: =O18*1.05 -> 4051.6875 | T18: ='Program Budget'!T20 -> 5 | U18: ='Program Budget'!S148 -> 0 | V18: =S18*T18*U18 -> 0 | W18: =F18+J18+N18+R18+V18 -> 0
A19: ='Program Budget'!D21 -> Sociocultural and Gender Specialist | B19: ='Program Budget'!F149 -> Month | C19: ='Program Budget'!H21 -> 1833.3333 | D19: ='Program Budget'!G21 -> 7 | E19: ='Program Budget'!E149 -> 0.25 | F19: =C19*D19*E19 -> 3208.3333 | G19: =C19*1.05 -> 1925 | H19: ='Program Budget'!K21 -> 12 | I19: ='Program Budget'!J149 -> 0.35 | J19: =G19*H19*I19 -> 8085 | K19: =G19*1.05 -> 2021.25 | L19: ='Program Budget'!N21 -> 12 | M19: ='Program Budget'!M149 -> 0.3 | N19: =K19*L19*M19 -> 7276.5 | O19: =K19*1.05 -> 2122.3125 | P19: ='Program Budget'!Q21 -> 12 | Q19: ='Program Budget'!P149 -> 0.3 | R19: =O19*P19*Q19 -> 7640.325 | S19: =O19*1.05 -> 2228.4281 | T19: ='Program Budget'!T21 -> 9 | U19: ='Program Budget'!S149 -> 0.3 | V19: =S19*T19*U19 -> 6016.7559 | W19: =F19+J19+N19+R19+V19 -> 32226.914
A20: ='Program Budget'!D22 -> Sociocultural and Gender Officers (3) | B20: ='Program Budget'!F150 -> Month | C20: ='Program Budget'!H22 -> 3750 | D20: ='Program Budget'!G22 -> 7 | E20: ='Program Budget'!E150 -> 0.25 | F20: =C20*D20*E20 -> 6562.5 | G20: =C20*1.05 -> 3937.5 | H20: ='Program Budget'!K22 -> 12 | I20: ='Program Budget'!J150 -> 0.35 | J20: =G20*H20*I20 -> 16537.5 | K20: =G20*1.05 -> 4134.375 | L20: ='Program Budget'!N22 -> 12 | M20: ='Program Budget'!M150 -> 0.3 | N20: =K20*L20*M20 -> 14883.75 | O20: =K20*1.05 -> 4341.0938 | P20: ='Program Budget'!Q22 -> 12 | Q20: ='Program Budget'!P150 -> 0.3 | R20: =O20*P20*Q20 -> 15627.938 | S20: =O20*1.05 -> 4558.1484 | T20: ='Program Budget'!T22 -> 9 | U20: ='Program Budget'!S150 -> 0.3 | V20: =S20*T20*U20 -> 12307.001 | W20: =F20+J20+N20+R20+V20 -> 65918.688
A21: ='Program Budget'!D23 -> Communications Specialists | B21: ='Program Budget'!F151 -> Month | C21: ='Program Budget'!H23 -> 1500 | D21: ='Program Budget'!G23 -> 7 | E21: ='Program Budget'!E151 -> 0.25 | F21: =C21*D21*E21 -> 2625 | G21: =C21*1.05 -> 1575 | H21: ='Program Budget'!K23 -> 12 | I21: ='Program Budget'!J151 -> 0.3 | J21: =G21*H21*I21 -> 5670 | K21: =G21*1.05 -> 1653.75 | L21: ='Program Budget'!N23 -> 12 | M21: ='Program Budget'!M151 -> 0.3 | N21: =K21*L21*M21 -> 5953.5 | O21: =K21*1.05 -> 1736.4375 | P21: ='Program Budget'!Q23 -> 12 | Q21: ='Program Budget'!P151 -> 0.3 | R21: =O21*P21*Q21 -> 6251.175 | S21: =O21*1.05 -> 1823.2594 | T21: ='Program Budget'!T23 -> 10 | U21: ='Program Budget'!S151 -> 0.3 | V21: =S21*T21*U21 -> 5469.7781 | W21: =F21+J21+N21+R21+V21 -> 25969.453
A22: ='Program Budget'!D24 -> M&E Director | B22: ='Program Budget'!F152 -> Month | C22: ='Program Budget'!H24 -> 3916.6667 | D22: ='Program Budget'!G24 -> 9 | E22: ='Program Budget'!E152 -> 0.25 | F22: =C22*D22*E22 -> 8812.5 | G22: =C22*1.05 -> 4112.5 | H22: ='Program Budget'!K24 -> 12 | I22: ='Program Budget'!J152 -> 0.3 | J22: =G22*H22*I22 -> 14805 | K22: =G22*1.05 -> 4318.125 | L22: ='Program Budget'!N24 -> 12 | M22: ='Program Budget'!M152 -> 0.3 | N22: =K22*L22*M22 -> 15545.25 | O22: =K22*1.05 -> 4534.0312 | P22: ='Program Budget'!Q24 -> 12 | Q22: ='Program Budget'!P152 -> 0.3 | R22: =O22*P22*Q22 -> 16322.512 | S22: =O22*1.05 -> 4760.7328 | T22: ='Program Budget'!T24 -> 12 | U22: ='Program Budget'!S152 -> 0.3 | V22: =S22*T22*U22 -> 17138.638 | W22: =F22+J22+N22+R22+V22 -> 72623.901 | AE22: 180 | AF22: 50-01-2-020 | AG22: DIR-USN (Expat) Labor
A23: ='Program Budget'!D25 -> M&E Specialist | B23: ='Program Budget'!F153 -> Month | C23: ='Program Budget'!H25 -> 1833.3333 | D23: ='Program Budget'!G25 -> 8 | E23: ='Program Budget'!E153 -> 0.25 | F23: =C23*D23*E23 -> 3666.6667 | G23: =C23*1.05 -> 1925 | H23: ='Program Budget'!K25 -> 12 | I23: ='Program Budget'!J153 -> 0.3 | J23: =G23*H23*I23 -> 6930 | K23: =G23*1.05 -> 2021.25 | L23: ='Program Budget'!N25 -> 12 | M23: ='Program Budget'!M153 -> 0.3 | N23: =K23*L23*M23 -> 7276.5 | O23: =K23*1.05 -> 2122.3125 | P23: ='Program Budget'!Q25 -> 12 | Q23: ='Program Budget'!P153 -> 0.3 | R23: =O23*P23*Q23 -> 7640.325 | S23: =O23*1.05 -> 2228.4281 | T23: ='Program Budget'!T25 -> 10 | U23: ='Program Budget'!S153 -> 0.3 | V23: =S23*T23*U23 -> 6685.2844 | W23: =F23+J23+N23+R23+V23 -> 32198.776 | AE23: 180 | AF23: 50-01-2-020 | AG23: DIR-USN (Expat) Labor
