Workbook
Name __pd1: [1]Rates!$J$24
Name __pd6: [1]Rates!$J$30
Name __tix1: [1]Rates!$J$40
Name __tix2: [1]Rates!$J$41
Name __tix6: [1]Rates!$J$47
Name ANPDH: '[2]Salary & PR Tax'!#REF!
Name Board: '[3]Schedule E - Other'!$F$102
Name CEE_Consult: #REF!
Name CENIDH: #REF!
Name Consultants: #REF!
Name Equipment: '[4]Schedule D - Equipment'!$E$26
Name fg: #REF!
Name Housing: '[2]Salary & PR Tax'!#REF!
Name inf: [5]Assumptions!$C$75
Name Inflation: '[6]Detail-1'!$J$2
Name Interns: #REF!
Name jenn: #REF!
Name Local_Hire: #REF!
Name Local_Hires: #REF!
Name Merit: '[6]Detail-1'!$J$1
Name padf01: '[7]Level of Effort'!$C$14
Name padf02: '[7]Level of Effort'!$C$15
Name padf03: '[7]Level of Effort'!$C$16
Name padf04: '[7]Level of Effort'!$C$17
Name padf05: [7]Rates!$J$23
Name postdif01: [7]Rates!$J$34
Name postdif02: [7]Rates!$J$65
Name Print_Titles_MI: #REF!
Name sdf: #REF!
Name Travel_Regional: #REF!
Name Travel_WDC: #REF!

Sheet Summary Budget
A1: Partners of the Americas F2F Caribbean Basin Program Budget
A2: USAID NOFO #7200AA23RFA00006
A4: Line Items | B4: Year 1 | E4: Year 2 | H4: Year 3 | K4: Year 4 | N4: Year 5 | Q4: Total | R4: Total | S4: Grand
B5: USAID | C5: Leverage | D5: Total | E5: USAID | F5: Leverage | G5: Total | H5: USAID | I5: Leverage | J5: Total | K5: USAID | L5: Leverage | M5: Total | N5: USAID | O5: Leverage | P5: Total | Q5: USAID | R5: Leverage | S5: Total
A7: Salaries & Wages | B7: ='Detailed Budget'!I25 -> 534480 | C7: ='Detailed Budget'!J25 -> 511560 | D7: =SUM(B7:C7) -> 1046040 | E7: ='Detailed Budget'!O25 -> 614246.68 | F7: ='Detailed Budget'!P25 -> 589860 | G7: =SUM(E7:F7) -> 1204106.7 | H7: ='Detailed Budget'!U25 -> 632674.08 | I7: ='Detailed Budget'!V25 -> 582030 | J7: =SUM(H7:I7) -> 1214704.1 | K7: ='Detailed Budget'!AA25 -> 651654.3 | L7: ='Detailed Budget'!AB25 -> 574200 | M7: =SUM(K7:L7) -> 1225854.3 | N7: ='Detailed Budget'!AG25 -> 522138.54 | O7: ='Detailed Budget'!AH25 -> 477630 | P7: =SUM(N7:O7) -> 999768.54 | Q7: ='Detailed Budget'!AJ25 -> 2955193.6 | R7: ='Detailed Budget'!AK25 -> 2735280 | S7: ='Detailed Budget'!AL25 -> 5690473.6
A9: Fringe Benefits | B9: ='Detailed Budget'!I31 -> 128190.95 | C9: ='Detailed Budget'!J31 -> 0 | D9: ='Detailed Budget'!K31 -> 128190.95 | E9: ='Detailed Budget'!O31 -> 148739.99 | F9: ='Detailed Budget'!P31 -> 0 | G9: ='Detailed Budget'!Q31 -> 148739.99 | H9: ='Detailed Budget'!U31 -> 153202.19 | I9: ='Detailed Budget'!V31 -> 0 | J9: ='Detailed Budget'!W31 -> 153202.19 | K9: ='Detailed Budget'!AA31 -> 157798.25 | L9: ='Detailed Budget'!AB31 -> 0 | M9: ='Detailed Budget'!AC31 -> 157798.25 | N9: ='Detailed Budget'!AG31 -> 125392.85 | O9: ='Detailed Budget'!AH31 -> 0 | P9: ='Detailed Budget'!AI31 -> 125392.85 | Q9: ='Detailed Budget'!AJ31 -> 713324.22 | R9: ='Detailed Budget'!AK31 -> 0 | S9: ='Detailed Budget'!AL31 -> 713324.22
A11: Travel & Transportation | B11: ='Detailed Budget'!I80 -> 290955.13 | C11: ='Detailed Budget'!J80 -> 0 | D11: ='Detailed Budget'!K80 -> 290955.13 | E11: ='Detailed Budget'!O80 -> 324939.93 | F11: ='Detailed Budget'!P80 -> 0 | G11: ='Detailed Budget'!Q80 -> 324939.93 | H11: ='Detailed Budget'!U80 -> 340648.15 | I11: ='Detailed Budget'!V80 -> 0 | J11: ='Detailed Budget'!W80 -> 340648.15 | K11: ='Detailed Budget'!AA80 -> 332162.34 | L11: ='Detailed Budget'!AB80 -> 0 | M11: ='Detailed Budget'!AC80 -> 332162.34 | N11: ='Detailed Budget'!AG80 -> 294477.26 | O11: ='Detailed Budget'!AH80 -> 0 | P11: ='Detailed Budget'!AI80 -> 294477.26 | Q11: ='Detailed Budget'!AJ80 -> 1583182.8 | R11: ='Detailed Budget'!AK80 -> 0 | S11: ='Detailed Budget'!AL80 -> 1583182.8
A13: Equipment | B13: ='Detailed Budget'!I86 -> 43000 | C13: ='Detailed Budget'!J86 -> 0 | D13: ='Detailed Budget'!K86 -> 43000 | E13: ='Detailed Budget'!O86 -> 0 | F13: ='Detailed Budget'!P86 -> 0 | G13: ='Detailed Budget'!Q86 -> 0 | H13: ='Detailed Budget'!U86 -> 0 | I13: ='Detailed Budget'!V86 -> 0 | J13: ='Detailed Budget'!W86 -> 0 | K13: ='Detailed Budget'!AA86 -> 0 | L13: ='Detailed Budget'!AB86 -> 0 | M13: ='Detailed Budget'!AC86 -> 0 | N13: ='Detailed Budget'!AG86 -> 0 | O13: ='Detailed Budget'!AH86 -> 0 | P13: ='Detailed Budget'!AI86 -> 0 | Q13: ='Detailed Budget'!AJ86 -> 43000 | R13: ='Detailed Budget'!AK86 -> 0 | S13: ='Detailed Budget'!AL86 -> 43000
A15: Supplies | B15: ='Detailed Budget'!I99 -> 26514.3 | C15: ='Detailed Budget'!J99 -> 0 | D15: ='Detailed Budget'!K99 -> 26514.3 | E15: ='Detailed Budget'!O99 -> 2762.4 | F15: ='Detailed Budget'!P99 -> 0 | G15: ='Detailed Budget'!Q99 -> 2762.4 | H15: ='Detailed Budget'!U99 -> 2805.648 | I15: ='Detailed Budget'!V99 -> 0 | J15: ='Detailed Budget'!W99 -> 2805.648 | K15: ='Detailed Budget'!AA99 -> 2849.761 | L15: ='Detailed Budget'!AB99 -> 0 | M15: ='Detailed Budget'!AC99 -> 2849.761 | N15: ='Detailed Budget'!AG99 -> 2744.7562 | O15: ='Detailed Budget'!AH99 -> 0 | P15: ='Detailed Budget'!AI99 -> 2744.7562 | Q15: ='Detailed Budget'!AJ99 -> 37676.865 | R15: ='Detailed Budget'!AK99 -> 0 | S15: ='Detailed Budget'!AL99 -> 37676.865
A17: Contractual | B17: ='Detailed Budget'!I106 -> 9000 | C17: ='Detailed Budget'!J106 -> 0 | D17: ='Detailed Budget'!K106 -> 9000 | E17: ='Detailed Budget'!O106 -> 5000 | F17: ='Detailed Budget'!P106 -> 0 | G17: ='Detailed Budget'!Q106 -> 5000 | H17: ='Detailed Budget'!U106 -> 7000 | I17: ='Detailed Budget'!V106 -> 0 | J17: ='Detailed Budget'!W106 -> 7000 | K17: ='Detailed Budget'!AA106 -> 3000 | L17: ='Detailed Budget'!AB106 -> 0 | M17: ='Detailed Budget'!AC106 -> 3000 | N17: ='Detailed Budget'!AG106 -> 1000 | O17: ='Detailed Budget'!AH106 -> 0 | P17: ='Detailed Budget'!AI106 -> 1000 | Q17: ='Detailed Budget'!AJ106 -> 25000 | R17: ='Detailed Budget'!AK106 -> 0 | S17: ='Detailed Budget'!AL106 -> 25000
A19: Other Direct Costs | B19: ='Detailed Budget'!I122 -> 105761.26 | C19: ='Detailed Budget'!J122 -> 0 | D19: ='Detailed Budget'!K122 -> 105761.26 | E19: ='Detailed Budget'!O122 -> 90213.961 | F19: ='Detailed Budget'!P122 -> 0 | G19: ='Detailed Budget'!Q122 -> 90213.961 | H19: ='Detailed Budget'!U122 -> 115945.88 | I19: ='Detailed Budget'!V122 -> 0 | J19: ='Detailed Budget'!W122 -> 115945.88 | K19: ='Detailed Budget'!AA122 -> 93858.605 | L19: ='Detailed Budget'!AB122 -> 0 | M19: ='Detailed Budget'!AC122 -> 93858.605 | N19: ='Detailed Budget'!AG122 -> 83428.102 | O19: ='Detailed Budget'!AH122 -> 0 | P19: ='Detailed Budget'!AI122 -> 83428.102 | Q19: ='Detailed Budget'!AJ122 -> 489207.81 | R19: ='Detailed Budget'!AK122 -> 0 | S19: ='Detailed Budget'!AL122 -> 489207.81
A21: Total Direct Costs | B21: ='Detailed Budget'!I124 -> 1137901.6 | C21: ='Detailed Budget'!J124 -> 511560 | D21: ='Detailed Budget'!K124 -> 1649461.6 | E21: ='Detailed Budget'!O124 -> 1185903 | F21: ='Detailed Budget'!P124 -> 589860 | G21: ='Detailed Budget'!Q124 -> 1775763 | H21: ='Detailed Budget'!U124 -> 1252275.9 | I21: ='Detailed Budget'!V124 -> 582030 | J21: ='Detailed Budget'!W124 -> 1834305.9 | K21: ='Detailed Budget'!AA124 -> 1241323.3 | L21: ='Detailed Budget'!AB124 -> 574200 | M21: ='Detailed Budget'!AC124 -> 1815523.3 | N21: ='Detailed Budget'!AG124 -> 1029181.5 | O21: ='Detailed Budget'!AH124 -> 477630 | P21: ='Detailed Budget'!AI124 -> 1506811.5 | Q21: ='Detailed Budget'!AJ124 -> 5846585.3 | R21: ='Detailed Budget'!AK124 -> 2735280 | S21: ='Detailed Budget'!AL124 -> 8581865.3
A22: Indirect Costs | B22: ='Detailed Budget'!I125 -> 321798.58 | C22: ='Detailed Budget'!J125 -> 0 | D22: ='Detailed Budget'!K125 -> 321798.58 | E22: ='Detailed Budget'!O125 -> 335373.36 | F22: ='Detailed Budget'!P125 -> 0 | G22: ='Detailed Budget'!Q125 -> 335373.36 | H22: ='Detailed Budget'!U125 -> 354143.64 | I22: ='Detailed Budget'!V125 -> 0 | J22: ='Detailed Budget'!W125 -> 354143.64 | K22: ='Detailed Budget'!AA125 -> 351046.22 | L22: ='Detailed Budget'!AB125 -> 0 | M22: ='Detailed Budget'!AC125 -> 351046.22 | N22: ='Detailed Budget'!AG125 -> 291052.53 | O22: ='Detailed Budget'!AH125 -> 0 | P22: ='Detailed Budget'!AI125 -> 291052.53 | Q22: ='Detailed Budget'!AJ125 -> 1653414.3 | R22: ='Detailed Budget'!AK125 -> 0 | S22: ='Detailed Budget'!AL125 -> 1653414.3
A23: Buy-in | B23: ='Detailed Budget'!I126 -> 0 | C23: ='Detailed Budget'!J126 -> 0 | D23: ='Detailed Budget'!K126 -> 0 | E23: ='Detailed Budget'!O126 -> 0 | F23: ='Detailed Budget'!P126 -> 0 | G23: ='Detailed Budget'!Q126 -> 0 | H23: ='Detailed Budget'!U126 -> 1000000 | I23: ='Detailed Budget'!V126 -> 0 | J23: ='Detailed Budget'!W126 -> 0 | K23: ='Detailed Budget'!AA126 -> 0 | L23: ='Detailed Budget'!AB126 -> 0 | M23: ='Detailed Budget'!AC126 -> 0 | N23: ='Detailed Budget'!AG126 -> 0 | O23: ='Detailed Budget'!AH126 -> 0 | P23: ='Detailed Budget'!AI126 -> 0 | Q23: ='Detailed Budget'!AJ126 -> 1000000 | R23: ='Detailed Budget'!AK126 -> 0 | S23: ='Detailed Budget'!AL126 -> 1000000
A24: Total | B24: ='Detailed Budget'!I127 -> 1459700.2 | C24: ='Detailed Budget'!J127 -> 511560 | D24: ='Detailed Budget'!K127 -> 1971260.2 | E24: ='Detailed Budget'!O127 -> 1521276.3 | F24: ='Detailed Budget'!P127 -> 589860 | G24: ='Detailed Budget'!Q127 -> 2111136.3 | H24: ='Detailed Budget'!U127 -> 2606419.6 | I24: ='Detailed Budget'!V127 -> 582030 | J24: ='Detailed Budget'!W127 -> 2188449.6 | K24: ='Detailed Budget'!AA127 -> 1592369.5 | L24: ='Detailed Budget'!AB127 -> 574200 | M24: ='Detailed Budget'!AC127 -> 2166569.5 | N24: ='Detailed Budget'!AG127 -> 1320234 | O24: ='Detailed Budget'!AH127 -> 477630 | P24: ='Detailed Budget'!AI127 -> 1797864 | Q24: ='Detailed Budget'!AJ127 -> 8499999.7 | R24: ='Detailed Budget'!AK127 -> 2735280 | S24: ='Detailed Budget'!AL127 -> 11235280
Q25: =Q24-8500000 -> -0.34737351

Sheet Detailed Budget
A1: Entity: | B1: P | D1: Partners of the Americas F2F Caribbean Basin Program Budget
A2: Program-Dept.: | B2: 30100 | D2: USAID NOFO #7200AA23RFA00006
A3: Funder-Grant: | B3: USAID650
A4: Budget (Activity) Code | B4: Account Code | C4: Country Code | D4: Line Items | I4: Year 1 | O4: Year 2 | R4: Year 3 | AA4: Year 4 | AG4: Year 5 | AJ4: Total | AK4: Total | AL4: Grand
E5: Unit | F5: Cost | G5: Duration | H5: Type | I5: USAID | J5: Leverage | K5: Total | L5: Unit | M5: Cost | N5: Duration | O5: USAID | P5: Leverage | Q5: Total | R5: Unit | S5: Cost | T5: Duration | U5: USAID | V5: Leverage | W5: Total | X5: Unit | Y5: Cost | Z5: Duration | AA5: USAID | AB5: Leverage | AC5: Total | AD5: Unit | AE5: Cost | AF5: Duration | AG5: USAID | AH5: Leverage | AI5: Total | AJ5: USAID | AK5: Leverage | AL5: Total
D7: Personnel
D8: Headquarters | E8: LOE
A9: PERSNL | B9: 50000 | C9: USA | D9: Senior Director | E9: 0.05 | F9: =120000/12 -> 10000 | G9: 12 | H9: /months | I9: =G9*F9*E9 -> 6000 | J9: 0 | K9: =SUM(I9:J9) -> 6000 | L9: =E9 -> 0.05 | M9: =F9*1.03 -> 10300 | N9: 12 | O9: =L9*M9*N9 -> 6180 | P9: 0 | Q9: =SUM(O9:P9) -> 6180 | R9: =E9 -> 0.05 | S9: =M9*1.03 -> 10609 | T9: 12 | U9: =R9*S9*T9 -> 6365.4 | V9: 0 | W9: =SUM(U9:V9) -> 6365.4 | X9: =R9 -> 0.05 | Y9: =S9*1.03 -> 10927.27 | Z9: 12 | AA9: =X9*Y9*Z9 -> 6556.362 | AB9: 0 | AC9: =SUM(AA9:AB9) -> 6556.362 | AD9: =X9 -> 0.05 | AE9: =Y9*1.03 -> 11255.088 | AF9: 12 | AG9: =AD9*AE9*AF9 -> 6753.0529 | AH9: 0 | AI9: =SUM(AG9:AH9) -> 6753.0529 | AJ9: =I9+O9+U9+AA9+AG9 -> 31854.815 | AK9: =J9+P9+V9+AB9+AH9 -> 0 | AL9: =SUM(AJ9:AK9) -> 31854.815
A10: PERSNL | B10: 50000 | C10: USA | D10: Program Director* | E10: 0.75 | F10: =92000/12 -> 7666.6667 | G10: 12 | H10: /months | I10: =G10*F10*E10 -> 69000 | J10: 0 | K10: =SUM(I10:J10) -> 69000 | L10: =E10 -> 0.75 | M10: =F10*1.03 -> 7896.6667 | N10: 12 | O10: =L10*M10*N10 -> 71070 | P10: 0 | Q10: =SUM(O10:P10) -> 71070 | R10: =E10 -> 0.75 | S10: =M10*1.03 -> 8133.5667 | T10: 12 | U10: =R10*S10*T10 -> 73202.1 | V10: 0 | W10: =SUM(U10:V10) -> 73202.1 | X10: =R10 -> 0.75 | Y10: =S10*1.03 -> 8377.5737 | Z10: 12 | AA10: =X10*Y10*Z10 -> 75398.163 | AB10: 0 | AC10: =SUM(AA10:AB10) -> 75398.163 | AD10: =X10 -> 0.75 | AE10: =Y10*1.03 -> 8628.9009 | AF10: 12 | AG10: =AD10*AE10*AF10 -> 77660.108 | AH10: 0 | AI10: =SUM(AG10:AH10) -> 77660.108 | AJ10: =I10+O10+U10+AA10+AG10 -> 366330.37 | AK10: =J10+P10+V10+AB10+AH10 -> 0 | AL10: =SUM(AJ10:AK10) -> 366330.37
A11: PERSNL | B11: 50000 | C11: USA | D11: Program Manager | E11: 0.8 | F11: =80000/12 -> 6666.6667 | G11: 9 | H11: /months | I11: =G11*F11*E11 -> 48000 | J11: 0 | K11: =SUM(I11:J11) -> 48000 | L11: =E11 -> 0.8 | M11: =F11*1.03 -> 6866.6667 | N11: 12 | O11: =L11*M11*N11 -> 65920 | P11: 0 | Q11: =SUM(O11:P11) -> 65920 | R11: =L11 -> 0.8 | S11: =M11*1.03 -> 7072.6667 | T11: 12 | U11: =R11*S11*T11 -> 67897.6 | V11: 0 | W11: =SUM(U11:V11) -> 67897.6 | X11: =R11 -> 0.8 | Y11: =S11*1.03 -> 7284.8467 | Z11: 12 | AA11: =X11*Y11*Z11 -> 69934.528 | AB11: 0 | AC11: =SUM(AA11:AB11) -> 69934.528 | AD11: =X11 -> 0.8 | AE11: =Y11*1.03 -> 7503.3921 | AF11: 10 | AG11: =AD11*AE11*AF11 -> 60027.137 | AH11: 0 | AI11: =SUM(AG11:AH11) -> 60027.137 | AJ11: =I11+O11+U11+AA11+AG11 -> 311779.26 | AK11: =J11+P11+V11+AB11+AH11 -> 0 | AL11: =SUM(AJ11:AK11) -> 311779.26
A12: PERSNL | B12: 50000 | C12: USA | D12: Technical & M&E Officer | E12: 0.9 | F12: 4820 | G12: 10 | H12: /months | I12: =G12*F12*E12 -> 43380 | J12: 0 | K12: =SUM(I12:J12) -> 43380 | L12: =E12 -> 0.9 | M12: =F12*1.03 -> 4964.6 | N12: 12 | O12: =L12*M12*N12 -> 53617.68 | P12: 0 | Q12: =SUM(O12:P12) -> 53617.68 | R12: =L12 -> 0.9 | S12: =M12*1.03 -> 5113.538 | T12: 12 | U12: =R12*S12*T12 -> 55226.21 | V12: 0 | W12: =SUM(U12:V12) -> 55226.21 | X12: =R12 -> 0.9 | Y12: =S12*1.03 -> 5266.9441 | Z12: 12 | AA12: =X12*Y12*Z12 -> 56882.997 | AB12: 0 | AC12: =SUM(AA12:AB12) -> 56882.997 | AD12: =X12 -> 0.9 | AE12: =Y12*1.03 -> 5424.9525 | AF12: 10 | AG12: =AD12*AE12*AF12 -> 48824.572 | AH12: 0 | AI12: =SUM(AG12:AH12) -> 48824.572 | AJ12: =I12+O12+U12+AA12+AG12 -> 257931.46 | AK12: =J12+P12+V12+AB12+AH12 -> 0 | AL12: =SUM(AJ12:AK12) -> 257931.46
A13: PERSNL | B13: 50000 | C13: USA | D13: Recruiter | E13: 0.9 | F13: =51000/12 -> 4250 | G13: 10 | H13: /months | I13: =G13*F13*E13 -> 38250 | J13: 0 | K13: =SUM(I13:J13) -> 38250 | L13: =E13 -> 0.9 | M13: =F13*1.03 -> 4377.5 | N13: 12 | O13: =L13*M13*N13 -> 47277 | P13: 0 | Q13: =SUM(O13:P13) -> 47277 | R13: =L13 -> 0.9 | S13: =M13*1.03 -> 4508.825 | T13: 12 | U13: =R13*S13*T13 -> 48695.31 | V13: 0 | W13: =SUM(U13:V13) -> 48695.31 | X13: =R13 -> 0.9 | Y13: =S13*1.03 -> 4644.0898 | Z13: 12 | AA13: =X13*Y13*Z13 -> 50156.169 | AB13: 0 | AC13: =SUM(AA13:AB13) -> 50156.169 | AD13: =X13 -> 0.9 | AE13: =Y13*1.03 -> 4783.4124 | AF13: 8 | AG13: =AD13*AE13*AF13 -> 34440.57 | AH13: 0 | AI13: =SUM(AG13:AH13) -> 34440.57 | AJ13: =I13+O13+U13+AA13+AG13 -> 218819.05 | AK13: =J13+P13+V13+AB13+AH13 -> 0 | AL13: =SUM(AJ13:AK13) -> 218819.05
D14: Subtotal HQ Personnel | I14: =SUM(I9:I13) -> 204630 | J14: =SUM(J9:J13) -> 0 | K14: =SUM(K9:K13) -> 204630 | O14: =SUM(O9:O13) -> 244064.68 | P14: =SUM(P9:P13) -> 0 | Q14: =SUM(Q9:Q13) -> 244064.68 | U14: =SUM(U9:U13) -> 251386.62 | V14: =SUM(V9:V13) -> 0 | W14: =SUM(W9:W13) -> 251386.62 | AA14: =SUM(AA9:AA13) -> 258928.22 | AB14: =SUM(AB9:AB13) -> 0 | AC14: =SUM(AC9:AC13) -> 258928.22 | AG14: =SUM(AG9:AG13) -> 227705.44 | AH14: =SUM(AH9:AH13) -> 0 | AI14: =SUM(AI9:AI13) -> 227705.44 | AJ14: =SUM(AJ9:AJ13) -> 1186715 | AK14: =SUM(AK9:AK13) -> 0 | AL14: =SUM(AL9:AL13) -> 1186715
D15: *Key Personnel
D16: Field Personnel | E16: LOE
A17: PERSNL-GTM | B17: 70000 | C17: GTM | D17: Guatemala | E17: 1 | G17: 1 | H17: /year | I17: ='Guatemala '!I14 -> 94150 | J17: 0 | K17: =SUM(I17:J17) -> 94150 | O17: ='Guatemala '!N14 -> 108150 | P17: 0 | Q17: =SUM(O17:P17) -> 108150 | U17: ='Guatemala '!S14 -> 111394.5 | V17: 0 | W17: =SUM(U17:V17) -> 111394.5 | AA17: ='Guatemala '!X14 -> 114736.34 | AB17: 0 | AC17: =SUM(AA17:AB17) -> 114736.34 | AG17: ='Guatemala '!AC14 -> 84413.161 | AH17: 0 | AI17: =SUM(AG17:AH17) -> 84413.161 | AJ17: =I17+O17+U17+AA17+AG17 -> 512844 | AK17: =J17+P17+V17+AB17+AH17 -> 0 | AL17: =SUM(AJ17:AK17) -> 512844
A18: PERSNL-DOM | B18: 70000 | C18: DOM | D18: Dominican Republic | E18: 1 | G18: 1 | H18: /year | I18: ='Dominican Republic'!I14 -> 84700 | J18: 0 | K18: =SUM(I18:J18) -> 84700 | O18: ='Dominican Republic'!N14 -> 100116 | P18: 0 | Q18: =SUM(O18:P18) -> 100116 | U18: ='Dominican Republic'!S14 -> 103119.48 | V18: 0 | W18: =SUM(U18:V18) -> 103119.48 | AA18: ='Dominican Republic'!X14 -> 106213.06 | AB18: 0 | AC18: =SUM(AA18:AB18) -> 106213.06 | AG18: ='Dominican Republic'!AC14 -> 77322.455 | AH18: 0 | AI18: =SUM(AG18:AH18) -> 77322.455 | AJ18: =I18+O18+U18+AA18+AG18 -> 471471 | AK18: =J18+P18+V18+AB18+AH18 -> 0 | AL18: =SUM(AJ18:AK18) -> 471471
A19: PERSNL-GUY | B19: 70000 | C19: GUY | D19: Guyana | E19: 1 | G19: 1 | H19: /year | I19: =Guyana!I13 -> 68350 | J19: 0 | K19: =SUM(I19:J19) -> 68350 | O19: =Guyana!N13 -> 73542 | P19: 0 | Q19: =SUM(O19:P19) -> 73542 | U19: =Guyana!S13 -> 75748.26 | V19: 0 | W19: =SUM(U19:V19) -> 75748.26 | AA19: =Guyana!X13 -> 78020.708 | AB19: 0 | AC19: =SUM(AA19:AB19) -> 78020.708 | AG19: =Guyana!AC13 -> 60270.997 | AH19: 0 | AI19: =SUM(AG19:AH19) -> 60270.997 | AJ19: =I19+O19+U19+AA19+AG19 -> 355931.96 | AK19: =J19+P19+V19+AB19+AH19 -> 0 | AL19: =SUM(AJ19:AK19) -> 355931.96
A20: PERSNL-JAM | B20: 70000 | C20: JAM | D20: Jamaica | E20: 1 | G20: 1 | H20: /year | I20: =Jamaica!I13 -> 82650 | J20: 0 | K20: =SUM(I20:J20) -> 82650 | O20: =Jamaica!N13 -> 88374 | P20: 0 | Q20: =SUM(O20:P20) -> 88374 | U20: =Jamaica!S13 -> 91025.22 | V20: 0 | W20: =SUM(U20:V20) -> 91025.22 | AA20: =Jamaica!X13 -> 93755.977 | AB20: 0 | AC20: =SUM(AA20:AB20) -> 93755.977 | AG20: =Jamaica!AC13 -> 72426.492 | AH20: 0 | AI20: =SUM(AG20:AH20) -> 72426.492 | AJ20: =I20+O20+U20+AA20+AG20 -> 428231.69 | AK20: =J20+P20+V20+AB20+AH20 -> 0 | AL20: =SUM(AJ20:AK20) -> 428231.69
D21: Subtotal Field Personnel | I21: =SUM(I17:I20) -> 329850 | J21: =SUM(J17:J20) -> 0 | K21: =SUM(K17:K20) -> 329850 | O21: =SUM(O17:O20) -> 370182 | P21: =SUM(P17:P20) -> 0 | Q21: =SUM(Q17:Q20) -> 370182 | U21: =SUM(U17:U20) -> 381287.46 | V21: =SUM(V17:V20) -> 0 | W21: =SUM(W17:W20) -> 381287.46 | AA21: =SUM(AA17:AA20) -> 392726.08 | AB21: =SUM(AB17:AB20) -> 0 | AC21: =SUM(AC17:AC20) -> 392726.08 | AG21: =SUM(AG17:AG20) -> 294433.1 | AH21: =SUM(AH17:AH20) -> 0 | AI21: =SUM(AI17:AI20) -> 294433.1 | AJ21: =I21+O21+U21+AA21+AG21 -> 1768478.6 | AK21: =J21+P21+V21+AB21+AH21 -> 0 | AL21: =SUM(AJ21:AK21) -> 1768478.6
D23: F2F Volunteers | E23: =Leverage!F2 -> 980 | F23: 522 | G23: 1 | H23: /day | I23: 0 | J23: =F23*E23*G23 -> 511560 | K23: =SUM(I23:J23) -> 511560 | L23: =Leverage!F3 -> 1130 | M23: =F23 -> 522 | N23: 1 | O23: 0 | P23: =M23*L23*N23 -> 589860 | Q23: =SUM(O23:P23) -> 589860 | R23: =Leverage!F4 -> 1115 | S23: =F23 -> 522 | T23: 1 | U23: 0 | V23: =S23*R23*T23 -> 582030 | W23: =SUM(U23:V23) -> 582030 | X23: =Leverage!F5 -> 1100 | Y23: =F23 -> 522 | Z23: 1 | AA23: 0 | AB23: =Y23*X23*Z23 -> 574200 | AC23: =SUM(AA23:AB23) -> 574200 | AD23: =Leverage!F6 -> 915 | AE23: =F23 -> 522 | AF23: 1 | AG23: 0 | AH23: =AE23*AD23*AF23 -> 477630 | AI23: =SUM(AG23:AH23) -> 477630 | AJ23: =I23+O23+U23+AA23+AG23 -> 0 | AK23: =J23+P23+V23+AB23+AH23 -> 2735280 | AL23: =SUM(AJ23:AK23) -> 2735280
D25: Personnel Total | I25: =I21+I14+I23 -> 534480 | J25: =SUM(J23:J23) -> 511560 | K25: =K21+K14+K23 -> 1046040 | O25: =O21+O14+O23 -> 614246.68 | P25: =SUM(P23:P23) -> 589860 | Q25: =Q21+Q14+Q23 -> 1204106.7 | U25: =U21+U14+U23 -> 632674.08 | V25: =SUM(V23:V23) -> 582030 | W25: =W21+W14+W23 -> 1214704.1 | AA25: =AA21+AA14+AA23 -> 651654.3 | AB25: =SUM(AB23:AB23) -> 574200 | AC25: =AC21+AC14+AC23 -> 1225854.3 | AG25: =AG21+AG14+AG23 -> 522138.54 | AH25: =SUM(AH23:AH23) -> 477630 | AI25: =AI21+AI14+AI23 -> 999768.54 | AJ25: =AJ21+AJ14+AJ23 -> 2955193.6 | AK25: =SUM(AK23:AK23) -> 2735280 | AL25: =AL21+AL14+AL23 -> 5690473.6
D27: Fringe Benefits
A28: FRINGE | B28: 50900 | C28: USA | D28: Fringe Benefits - Headquarters | E28: 0.2347 | I28: =I14*E28 -> 48026.661 | J28: 0 | K28: =SUM(I28:J28) -> 48026.661 | O28: =O14*$E$28 -> 57281.98 | P28: 0 | Q28: =SUM(O28:P28) -> 57281.98 | U28: =U14*$E$28 -> 59000.44 | V28: 0 | W28: =SUM(U28:V28) -> 59000.44 | AA28: =AA14*$E$28 -> 60770.453 | AB28: 0 | AC28: =SUM(AA28:AB28) -> 60770.453 | AG28: =AG14*$E$28 -> 53442.467 | AH28: 0 | AI28: =SUM(AG28:AH28) -> 53442.467 | AJ28: =I28+O28+U28+AA28+AG28 -> 278522 | AK28: =J28+P28+V28+AB28+AH28 -> 0 | AL28: =SUM(AJ28:AK28) -> 278522
A29: VARIOUS SEE TAB | B29: 70015 | C29: VARIOUS SEE TAB | D29: Fringe Benefits - Field | I29: ='Guatemala '!I16+'Dominican Republic'!I16+Guyana!I15+Jamaica!I15 -> 80164.285 | J29: 0 | K29: =SUM(I29:J29) -> 80164.285 | O29: ='Guatemala '!N16+'Dominican Republic'!N16+Guyana!N15+Jamaica!N15 -> 91458.005 | P29: 0 | Q29: =SUM(O29:P29) -> 91458.005 | U29: ='Guatemala '!T16+'Dominican Republic'!T16+Guyana!T15+Jamaica!T15 -> 94201.746 | V29: 0 | W29: =SUM(U29:V29) -> 94201.746 | AA29: ='Guatemala '!X16+'Dominican Republic'!X16+Guyana!X15+Jamaica!X15 -> 97027.798 | AB29: 0 | AC29: =SUM(AA29:AB29) -> 97027.798 | AG29: ='Guatemala '!AC16+'Dominican Republic'!AC16+Guyana!AC15+Jamaica!AC15 -> 71950.385 | AH29: 0 | AI29: =SUM(AG29:AH29) -> 71950.385 | AJ29: =I29+O29+U29+AA29+AG29 -> 434802.22 | AK29: =J29+P29+V29+AB29+AH29 -> 0 | AL29: =SUM(AJ29:AK29) -> 434802.22
D31: Fringe Benefits Total | I31: =SUM(I28:I30) -> 128190.95 | J31: =SUM(J28:J30) -> 0 | K31: =SUM(K28:K30) -> 128190.95 | O31: =SUM(O28:O30) -> 148739.99 | P31: =SUM(P28:P30) -> 0 | Q31: =SUM(Q28:Q30) -> 148739.99 | U31: =SUM(U28:U30) -> 153202.19 | V31: =SUM(V28:V30) -> 0 | W31: =SUM(W28:W30) -> 153202.19 | AA31: =SUM(AA28:AA30) -> 157798.25 | AB31: =SUM(AB28:AB30) -> 0 | AC31: =SUM(AC28:AC30) -> 157798.25 | AG31: =SUM(AG28:AG30) -> 125392.85 | AH31: =SUM(AH28:AH30) -> 0 | AI31: =SUM(AI28:AI30) -> 125392.85 | AJ31: =SUM(AJ28:AJ30) -> 713324.22 | AK31: =SUM(AK28:AK30) -> 0 | AL31: =SUM(AL28:AL30) -> 713324.22
D33: Travel
D35: Volunteer Travel - International Airfare
A36: VFLYGTM | B36: 86040 | C36: GTM | D36: Guatemala | E36: ='Guatemala '!E26 -> 16 | F36: ='Guatemala '!F26 -> 650 | G36: 1 | H36: /RT | I36: =G36*F36*E36 -> 10400 | J36: 0 | K36: =SUM(I36:J36) -> 10400 | L36: ='Guatemala '!K26 -> 22 | M36: =F36*1.02 -> 663 | N36: 1 | O36: =L36*M36*N36 -> 14586 | P36: 0 | Q36: =SUM(O36:P36) -> 14586 | R36: ='Guatemala '!P26 -> 22 | S36: =M36*1.02 -> 676.26 | T36: 1 | U36: =R36*S36*T36 -> 14877.72 | V36: 0 | W36: =SUM(U36:V36) -> 14877.72 | X36: ='Guatemala '!U26 -> 22 | Y36: =S36*1.02 -> 689.7852 | Z36: 1 | AA36: =X36*Y36*Z36 -> 15175.274 | AB36: 0 | AC36: =SUM(AA36:AB36) -> 15175.274 | AD36: ='Guatemala '!Z26 -> 16 | AE36: =Y36*1.02 -> 703.5809 | AF36: 1 | AG36: =AD36*AE36*AF36 -> 11257.294 | AH36: 0 | AI36: =SUM(AG36:AH36) -> 11257.294 | AJ36: =I36+O36+U36+AA36+AG36 -> 66296.289 | AK36: =J36+P36+V36+AB36+AH36 -> 0 | AL36: =SUM(AJ36:AK36) -> 66296.289
A37: VFLYDOM | B37: 86040 | C37: DOM | D37: Dominican Republic | E37: ='Dominican Republic'!E26 -> 16 | F37: ='Dominican Republic'!F26 -> 750 | G37: 1 | H37: /RT | I37: =G37*F37*E37 -> 12000 | J37: 0 | K37: =SUM(I37:J37) -> 12000 | L37: ='Dominican Republic'!K26 -> 22 | M37: =F37*1.02 -> 765 | N37: 1 | O37: =L37*M37*N37 -> 16830 | P37: 0 | Q37: =SUM(O37:P37) -> 16830 | R37: ='Dominican Republic'!P26 -> 22 | S37: =M37*1.02 -> 780.3 | T37: 1 | U37: =R37*S37*T37 -> 17166.6 | V37: 0 | W37: =SUM(U37:V37) -> 17166.6 | X37: ='Dominican Republic'!U26 -> 22 | Y37: =S37*1.02 -> 795.906 | Z37: 1 | AA37: =X37*Y37*Z37 -> 17509.932 | AB37: 0 | AC37: =SUM(AA37:AB37) -> 17509.932 | AD37: ='Dominican Republic'!Z26 -> 16 | AE37: =Y37*1.02 -> 811.82412 | AF37: 1 | AG37: =AD37*AE37*AF37 -> 12989.186 | AH37: 0 | AI37: =SUM(AG37:AH37) -> 12989.186 | AJ37: =I37+O37+U37+AA37+AG37 -> 76495.718 | AK37: =J37+P37+V37+AB37+AH37 -> 0 | AL37: =SUM(AJ37:AK37) -> 76495.718
A38: VFLYGUY | B38: 86040 | C38: GUY | D38: Guyana | E38: =Guyana!E25 -> 14 | F38: =Guyana!F25 -> 850 | G38: 1 | H38: /RT | I38: =G38*F38*E38 -> 11900 | J38: 0 | K38: =SUM(I38:J38) -> 11900 | L38: =Guyana!K25 -> 13 | M38: =F38*1.02 -> 867 | N38: 1 | O38: =L38*M38*N38 -> 11271 | P38: 0 | Q38: =SUM(O38:P38) -> 11271 | R38: =Guyana!P25 -> 13 | S38: =M38*1.02 -> 884.34 | T38: 1 | U38: =R38*S38*T38 -> 11496.42 | V38: 0 | W38: =SUM(U38:V38) -> 11496.42 | X38: =Guyana!U25 -> 12 | Y38: =S38*1.02 -> 902.0268 | Z38: 1 | AA38: =X38*Y38*Z38 -> 10824.322 | AB38: 0 | AC38: =SUM(AA38:AB38) -> 10824.322 | AD38: =Guyana!Z25 -> 12 | AE38: =Y38*1.02 -> 920.06734 | AF38: 1 | AG38: =AD38*AE38*AF38 -> 11040.808 | AH38: 0 | AI38: =SUM(AG38:AH38) -> 11040.808 | AJ38: =I38+O38+U38+AA38+AG38 -> 56532.55 | AK38: =J38+P38+V38+AB38+AH38 -> 0 | AL38: =SUM(AJ38:AK38) -> 56532.55
A39: VFLYJAM | B39: 86040 | C39: JAM | D39: Jamaica | E39: =Jamaica!E25 -> 14 | F39: =Jamaica!F25 -> 800 | G39: 1 | H39: /RT | I39: =G39*F39*E39 -> 11200 | J39: 0 | K39: =SUM(I39:J39) -> 11200 | L39: =Jamaica!K25 -> 13 | M39: =F39*1.02 -> 816 | N39: 1 | O39: =L39*M39*N39 -> 10608 | P39: 0 | Q39: =SUM(O39:P39) -> 10608 | R39: =Jamaica!P25 -> 12 | S39: =M39*1.02 -> 832.32 | T39: 1 | U39: =R39*S39*T39 -> 9987.84 | V39: 0 | W39: =SUM(U39:V39) -> 9987.84 | X39: =Jamaica!U25 -> 12 | Y39: =S39*1.02 -> 848.9664 | Z39: 1 | AA39: =X39*Y39*Z39 -> 10187.597 | AB39: 0 | AC39: =SUM(AA39:AB39) -> 10187.597 | AD39: =Jamaica!Z25 -> 13 | AE39: =Y39*1.02 -> 865.94573 | AF39: 1 | AG39: =AD39*AE39*AF39 -> 11257.294 | AH39: 0 | AI39: =SUM(AG39:AH39) -> 11257.294 | AJ39: =I39+O39+U39+AA39+AG39 -> 53240.731 | AK39: =J39+P39+V39+AB39+AH39 -> 0 | AL39: =SUM(AJ39:AK39) -> 53240.731
A40: VOLTRAVEL | B40: 86040 | C40: FLX | D40: Flexible (Additional Countries) | E40: ='Volunteer Travel'!C12 -> 3 | F40: ='Volunteer Travel'!B31 -> 887 | G40: 1 | H40: /RT | I40: =G40*F40*E40 -> 2661 | J40: 0 | K40: =SUM(I40:J40) -> 2661 | L40: ='Volunteer Travel'!D12 -> 3 | M40: =F40*1.02 -> 904.74 | N40: 1 | O40: =L40*M40*N40 -> 2714.22 | P40: 0 | Q40: =SUM(O40:P40) -> 2714.22 | R40: ='Volunteer Travel'!E12 -> 4 | S40: =M40*1.02 -> 922.8348 | T40: 1 | U40: =R40*S40*T40 -> 3691.3392 | V40: 0 | W40: =SUM(U40:V40) -> 3691.3392 | X40: ='Volunteer Travel'!F12 -> 4 | Y40: =S40*1.02 -> 941.2915 | Z40: 1 | AA40: =X40*Y40*Z40 -> 3765.166 | AB40: 0 | AC40: =SUM(AA40:AB40) -> 3765.166 | AD40: ='Volunteer Travel'!G12 -> 4 | AE40: =Y40*1.02 -> 960.11733 | AF40: 1 | AG40: =AD40*AE40*AF40 -> 3840.4693 | AH40: 0 | AI40: =SUM(AG40:AH40) -> 3840.4693 | AJ40: =I40+O40+U40+AA40+AG40 -> 16672.194 | AK40: =J40+P40+V40+AB40+AH40 -> 0 | AL40: =SUM(AJ40:AK40) -> 16672.194
D41: Total Volunteer Airfare | E41: =SUM(E36:E40) -> 63 | I41: =SUM(I36:I40) -> 48161 | J41: =SUM(J36:J40) -> 0 | K41: =SUM(K36:K40) -> 48161 | L41: =SUM(L36:L40) -> 73 | O41: =SUM(O36:O40) -> 56009.22 | P41: =SUM(P36:P40) -> 0 | Q41: =SUM(Q36:Q40) -> 56009.22 | R41: =SUM(R36:R40) -> 73 | U41: =SUM(U36:U40) -> 57219.919 | V41: =SUM(V36:V40) -> 0 | W41: =SUM(W36:W40) -> 57219.919 | X41: =SUM(X36:X40) -> 72 | AA41: =SUM(AA36:AA40) -> 57462.291 | AB41: =SUM(AB36:AB40) -> 0 | AC41: =SUM(AC36:AC40) -> 57462.291 | AD41: =SUM(AD36:AD40) -> 61 | AG41: =SUM(AG36:AG40) -> 50385.052 | AH41: =SUM(AH36:AH40) -> 0 | AI41: =SUM(AI36:AI40) -> 50385.052 | AJ41: =SUM(AJ36:AJ40) -> 269237.48 | AK41: =SUM(AK36:AK40) -> 0 | AL41: =SUM(AL36:AL40) -> 269237.48
D43: Volunteer Travel-Related Costs (Traditional & Paired)
A44: VARIOUS SEE TAB | B44: 86000 (Transport)/ 86030 (Lodging)/ 86050 (M&IE) | C44: GTM | D44: Guatemala - Volunteer Travel Related Costs | E44: 1 | F44: =SUM('Guatemala '!I27:I35) -> 34108.665 | G44: 1 | H44: /year | I44: =G44*F44*E44 -> 34108.665 | J44: 0 | K44: =SUM(I44:J44) -> 34108.665 | L44: 1 | M44: =SUM('Guatemala '!O27:O35) -> 46333.839 | N44: 1 | O44: =L44*M44*N44 -> 46333.839 | P44: 0 | Q44: =SUM(O44:P44) -> 46333.839 | R44: 1 | S44: =SUM('Guatemala '!T27:T35) -> 47260.516 | T44: 1 | U44: =R44*S44*T44 -> 47260.516 | V44: 0 | W44: =SUM(U44:V44) -> 47260.516 | X44: 1 | Y44: =SUM('Guatemala '!Y27:Y35) -> 48205.726 | Z44: 1 | AA44: =X44*Y44*Z44 -> 48205.726 | AB44: 0 | AC44: =SUM(AA44:AB44) -> 48205.726 | AD44: 1 | AE44: =SUM('Guatemala '!AD27:AD35) -> 36008.548 | AF44: 1 | AG44: =AD44*AE44*AF44 -> 36008.548 | AH44: 0 | AI44: =SUM(AG44:AH44) -> 36008.548 | AJ44: =I44+O44+U44+AA44+AG44 -> 211917.29 | AK44: =J44+P44+V44+AB44+AH44 -> 0 | AL44: =SUM(AJ44:AK44) -> 211917.29
A45: VARIOUS SEE TAB | B45: 86000 (Transport)/ 86030 (Lodging)/ 86050 (M&IE) | C45: DOM | D45: Dominican Republic - Volunteer Travel Related Costs | E45: 1 | F45: =SUM('Dominican Republic'!I27:I35) -> 39000.27 | G45: 1 | H45: /year | I45: =G45*F45*E45 -> 39000.27 | J45: 0 | K45: =SUM(I45:J45) -> 39000.27 | L45: 1 | M45: =SUM('Dominican Republic'!O27:O35) -> 53251.074 | N45: 1 | O45: =L45*M45*N45 -> 53251.074 | P45: 0 | Q45: =SUM(O45:P45) -> 53251.074 | R45: 1 | S45: =SUM('Dominican Republic'!S27:S35) -> 54316.095 | T45: 1 | U45: =R45*S45*T45 -> 54316.095 | V45: 0 | W45: =SUM(U45:V45) -> 54316.095 | X45: 1 | Y45: =SUM('Dominican Republic'!Y27:Y35) -> 55402.417 | Z45: 1 | AA45: =X45*Y45*Z45 -> 55402.417 | AB45: 0 | AC45: =SUM(AA45:AB45) -> 55402.417 | AD45: 1 | AE45: =SUM('Dominican Republic'!AD27:AD35) -> 41337.797 | AF45: 1 | AG45: =AD45*AE45*AF45 -> 41337.797 | AH45: 0 | AI45: =SUM(AG45:AH45) -> 41337.797 | AJ45: =I45+O45+U45+AA45+AG45 -> 243307.65 | AK45: =J45+P45+V45+AB45+AH45 -> 0 | AL45: =SUM(AJ45:AK45) -> 243307.65
A46: VARIOUS SEE TAB | B46: 86000 (Transport)/ 86030 (Lodging)/ 86050 (M&IE) | C46: GUY | D46: Guyana - Volunteer Travel Related Costs | E46: 1 | F46: =SUM(Guyana!I26:I34) -> 37219.024 | G46: 1 | H46: /year | I46: =G46*F46*E46 -> 37219.024 | J46: 0 | K46: =SUM(I46:J46) -> 37219.024 | L46: 1 | M46: =SUM(Guyana!N26:N34) -> 36276.316 | N46: 1 | O46: =L46*M46*N46 -> 36276.316 | P46: 0 | Q46: =SUM(O46:P46) -> 36276.316 | R46: 1 | S46: =SUM(Guyana!S26:S34) -> 37001.843 | T46: 1 | U46: =R46*S46*T46 -> 37001.843 | V46: 0 | W46: =SUM(U46:V46) -> 37001.843 | X46: 1 | Y46: =SUM(Guyana!Y26:Y34) -> 35053.903 | Z46: 1 | AA46: =X46*Y46*Z46 -> 35053.903 | AB46: 0 | AC46: =SUM(AA46:AB46) -> 35053.903 | AD46: 1 | AE46: =SUM(Guyana!AD26:AD34) -> 34803.597 | AF46: 1 | AG46: =AD46*AE46*AF46 -> 34803.597 | AH46: 0 | AI46: =SUM(AG46:AH46) -> 34803.597 | AJ46: =I46+O46+U46+AA46+AG46 -> 180354.68 | AK46: =J46+P46+V46+AB46+AH46 -> 0 | AL46: =SUM(AJ46:AK46) -> 180354.68
A47: VARIOUS SEE TAB | B47: 86000 (Transport)/ 86030 (Lodging)/ 86050 (M&IE) | C47: JAM | D47: Jamaica - Volunteer Travel Related Costs | E47: 1 | F47: =SUM(Jamaica!I26:I34) -> 37878.62 | G47: 1 | H47: /year | I47: =G47*F47*E47 -> 37878.62 | J47: 0 | K47: =SUM(I47:J47) -> 37878.62 | L47: 1 | M47: =SUM(Jamaica!N26:N34) -> 36891.697 | N47: 1 | O47: =L47*M47*N47 -> 36891.697 | P47: 0 | Q47: =SUM(O47:P47) -> 36891.697 | R47: 1 | S47: =SUM(Jamaica!S26:S34) -> 34944.05 | T47: 1 | U47: =R47*S47*T47 -> 34944.05 | V47: 0 | W47: =SUM(U47:V47) -> 34944.05 | X47: 1 | Y47: =SUM(Jamaica!Y26:Y34) -> 35642.931 | Z47: 1 | AA47: =X47*Y47*Z47 -> 35642.931 | AB47: 0 | AC47: =SUM(AA47:AB47) -> 35642.931 | AD47: 1 | AE47: =SUM(Jamaica!AD26:AD34) -> 38207.063 | AF47: 1 | AG47: =AD47*AE47*AF47 -> 38207.063 | AH47: 0 | AI47: =SUM(AG47:AH47) -> 38207.063 | AJ47: =I47+O47+U47+AA47+AG47 -> 183564.36 | AK47: =J47+P47+V47+AB47+AH47 -> 0 | AL47: =SUM(AJ47:AK47) -> 183564.36
A48: VOLTRVCTS | B48: 86000 (Transport)/ 86030 (Lodging)/ 86050 (M&IE) | C48: FLX | D48: Flexible - Volunteer Travel Related Costs | E48: 1 | F48: ='Volunteer Travel'!B34*'Detailed Budget'!E40 -> 5571 | G48: 1 | H48: /year | I48: =G48*F48*E48 -> 5571 | J48: 0 | K48: =SUM(I48:J48) -> 5571 | L48: 1 | M48: ='Volunteer Travel'!C34*'Detailed Budget'!L40 -> 5739 | N48: 1 | O48: =L48*M48*N48 -> 5739 | P48: 0 | Q48: =SUM(O48:P48) -> 5739 | R48: 1 | S48: ='Volunteer Travel'!D34*'Detailed Budget'!R40 -> 7880 | T48: 1 | U48: =R48*S48*T48 -> 7880 | V48: 0 | W48: =SUM(U48:V48) -> 7880 | X48: 1 | Y48: ='Volunteer Travel'!F34*'Detailed Budget'!X40 -> 8116 | Z48: 1 | AA48: =X48*Y48*Z48 -> 8116 | AB48: 0 | AC48: =SUM(AA48:AB48) -> 8116 | AD48: 1 | AE48: ='Volunteer Travel'!G34*'Detailed Budget'!AD40 -> 8360 | AF48: 1 | AG48: =AD48*AE48*AF48 -> 8360 | AH48: 0 | AI48: =SUM(AG48:AH48) -> 8360 | AJ48: =I48+O48+U48+AA48+AG48 -> 35666 | AK48: =J48+P48+V48+AB48+AH48 -> 0 | AL48: =SUM(AJ48:AK48) -> 35666
...

Sheet Guatemala 
A1: Entity: | B1: P | D1: Partners of the Americas F2F Caribbean Basin Program Budget
A2: Program-Dept.: | B2: 30100 | D2: USAID NOFO #7200AA23RFA00006
A3: Funder-Grant: | B3: USAID650
A4: Budget (Activity) Code | B4: Account Code | C4: Country Code | D4: Guatemala | I4: Year 1 | K4: Year 2 | P4: Year 3 | U4: Year 4 | Z4: Year 5 | AE4: Total | AF4: Grand
E5: Units | F5: Cost | G5: Duration | H5: Type | I5: USAID | J5: Total | K5: Units | L5: Cost | M5: Duration | N5: USAID | O5: Total | P5: Units | Q5: Cost | R5: Duration | S5: USAID | T5: Total | U5: Units | V5: Cost | W5: Duration | X5: USAID | Y5: Total | Z5: Units | AA5: Cost | AB5: Duration | AC5: USAID | AD5: Total | AE5: USAID | AF5: Total
D7: Key Personnel
A8: PERSNL-GTM | B8: 70000 | C8: GTM | D8: Country Director* | E8: 1 | F8: 5400 | G8: 12 | H8: /months | I8: =G8*F8*E8 -> 64800 | J8: =SUM(I8:I8) -> 64800 | K8: 1 | L8: =F8*1.03 -> 5562 | M8: 12 | N8: =M8*L8*K8 -> 66744 | O8: =SUM(N8:N8) -> 66744 | P8: 1 | Q8: =L8*1.03 -> 5728.86 | R8: 12 | S8: =R8*Q8*P8 -> 68746.32 | T8: =SUM(S8:S8) -> 68746.32 | U8: 1 | V8: =Q8*1.03 -> 5900.7258 | W8: 12 | X8: =W8*V8*U8 -> 70808.71 | Y8: =SUM(X8:X8) -> 70808.71 | Z8: 1 | AA8: =V8*1.03 -> 6077.7476 | AB8: 9 | AC8: =AB8*AA8*Z8 -> 54699.728 | AD8: =SUM(AC8:AC8) -> 54699.728 | AE8: =I8+N8+S8+X8+AC8 -> 325798.76 | AF8: =SUM(AE8:AE8) -> 325798.76
D10: Other Personnel
A11: PERSNL-GTM | B11: 70000 | C11: GTM | D11: Field Officer 1 | E11: 1 | F11: 1250 | G11: 10 | H11: /months | I11: =G11*F11*E11 -> 12500 | J11: =SUM(I11:I11) -> 12500 | K11: =E11 -> 1 | L11: =F11*1.03 -> 1287.5 | M11: 12 | N11: =M11*L11*K11 -> 15450 | O11: =SUM(N11:N11) -> 15450 | P11: =E11 -> 1 | Q11: =L11*1.03 -> 1326.125 | R11: 12 | S11: =R11*Q11*P11 -> 15913.5 | T11: =SUM(S11:S11) -> 15913.5 | U11: =E11 -> 1 | V11: =Q11*1.03 -> 1365.9088 | W11: 12 | X11: =W11*V11*U11 -> 16390.905 | Y11: =SUM(X11:X11) -> 16390.905 | Z11: =E11 -> 1 | AA11: =V11*1.03 -> 1406.886 | AB11: 9 | AC11: =AB11*AA11*Z11 -> 12661.974 | AD11: =SUM(AC11:AC11) -> 12661.974 | AE11: =I11+N11+S11+X11+AC11 -> 72916.379 | AF11: =SUM(AE11:AE11) -> 72916.379 | AG11: =K11+P11+U11+Z11+AE11 -> 72920.379 | AH11: =SUM(AG11:AG11) -> 72920.379 | AI11: =M11+R11+W11+AB11+AG11 -> 72965.379
A12: PERSNL-GTM | B12: 70000 | C12: GTM | D12: Field Officer 2 | E12: 1 | F12: 1250 | G12: 6 | H12: /months | I12: =G12*F12*E12 -> 7500 | J12: =SUM(I12:I12) -> 7500 | K12: =E12 -> 1 | L12: =F12*1.03 -> 1287.5 | M12: 12 | N12: =M12*L12*K12 -> 15450 | O12: =SUM(N12:N12) -> 15450 | P12: =E12 -> 1 | Q12: =L12*1.03 -> 1326.125 | R12: 12 | S12: =R12*Q12*P12 -> 15913.5 | T12: =SUM(S12:S12) -> 15913.5 | U12: =E12 -> 1 | V12: =Q12*1.03 -> 1365.9088 | W12: 12 | X12: =W12*V12*U12 -> 16390.905 | Y12: =SUM(X12:X12) -> 16390.905 | Z12: =E12 -> 1 | AA12: =V12*1.03 -> 1406.886 | AB12: 6 | AC12: =AB12*AA12*Z12 -> 8441.3161 | AD12: =SUM(AC12:AC12) -> 8441.3161 | AE12: =I12+N12+S12+X12+AC12 -> 63695.721 | AF12: =SUM(AE12:AE12) -> 63695.721 | AG12: =K12+P12+U12+Z12+AE12 -> 63699.721 | AH12: =SUM(AG12:AG12) -> 63699.721 | AI12: =M12+R12+W12+AB12+AG12 -> 63741.721
A13: PERSNL-GTM | B13: 70000 | C13: GTM | D13: Administrative Assistant | E13: 1 | F13: 850 | G13: 11 | H13: /months | I13: =G13*F13*E13 -> 9350 | J13: =SUM(I13:I13) -> 9350 | K13: 1 | L13: =F13*1.03 -> 875.5 | M13: 12 | N13: =M13*L13*K13 -> 10506 | O13: =SUM(N13:N13) -> 10506 | P13: 1 | Q13: =L13*1.03 -> 901.765 | R13: 12 | S13: =R13*Q13*P13 -> 10821.18 | T13: =SUM(S13:S13) -> 10821.18 | U13: 1 | V13: =Q13*1.03 -> 928.81795 | W13: 12 | X13: =W13*V13*U13 -> 11145.815 | Y13: =SUM(X13:X13) -> 11145.815 | Z13: 1 | AA13: =V13*1.03 -> 956.68249 | AB13: 9 | AC13: =AB13*AA13*Z13 -> 8610.1424 | AD13: =SUM(AC13:AC13) -> 8610.1424 | AE13: =I13+N13+S13+X13+AC13 -> 50433.138 | AF13: =SUM(AE13:AE13) -> 50433.138 | AG13: =K13+P13+U13+Z13+AE13 -> 50437.138 | AH13: =SUM(AG13:AG13) -> 50437.138 | AI13: =M13+R13+W13+AB13+AG13 -> 50482.138
D14: Subtotal Field Salaries | I14: =SUM(I8:I13) -> 94150 | J14: =SUM(J8:J13) -> 94150 | N14: =SUM(N8:N13) -> 108150 | O14: =SUM(O8:O13) -> 108150 | S14: =SUM(S8:S13) -> 111394.5 | T14: =SUM(T8:T13) -> 111394.5 | X14: =SUM(X8:X13) -> 114736.34 | Y14: =SUM(Y8:Y13) -> 114736.34 | AC14: =SUM(AC8:AC13) -> 84413.161 | AD14: =SUM(AD8:AD13) -> 84413.161 | AE14: =I14+N14+S14+X14+AC14 -> 512844 | AF14: =SUM(AE14:AE14) -> 512844
A16: FRINGE-GTM | B16: 70015 | C16: GTM | D16: Benefits | E16: 0.3566 | F16: =I14 -> 94150 | I16: =F16*E16 -> 33573.89 | J16: =SUM(I16:I16) -> 33573.89 | L16: =N14 -> 108150 | N16: =L16*E16 -> 38566.29 | O16: =SUM(N16:N16) -> 38566.29 | Q16: =S14 -> 111394.5 | S16: =Q16*E16 -> 39723.279 | T16: =SUM(S16:S16) -> 39723.279 | V16: =X14 -> 114736.34 | X16: =V16*E16 -> 40914.977 | Y16: =SUM(X16:X16) -> 40914.977 | AA16: =AC14 -> 84413.161 | AC16: =AA16*E16 -> 30101.733 | AD16: =SUM(AC16:AC16) -> 30101.733 | AE16: =I16+N16+S16+X16+AC16 -> 182880.17 | AF16: =SUM(AE16:AE16) -> 182880.17
D18: Supplies
A19: SUPPLY-GTM | B19: 82401 | C19: GTM | D19: Laptops | E19: ='FO Expenses'!C12 -> 4 | F19: ='FO Expenses'!B12 -> 1100 | G19: 1 | H19: /year | I19: =E19*F19*G19 -> 4400 | J19: =SUM(I19:I19) -> 4400 | K19: 0 | L19: =F19*1.02 -> 1122 | M19: 1 | N19: =M19*L19*K19 -> 0 | O19: =SUM(N19:N19) -> 0 | P19: 0 | Q19: =L19*1.02 -> 1144.44 | R19: 1 | S19: =R19*Q19*P19 -> 0 | T19: =SUM(S19:S19) -> 0 | U19: 0 | V19: =Q19*1.02 -> 1167.3288 | W19: 1 | X19: =W19*V19*U19 -> 0 | Y19: =SUM(X19:X19) -> 0 | Z19: 0 | AA19: =V19*1.02 -> 1190.6754 | AB19: 1 | AC19: =AB19*AA19*Z19 -> 0 | AD19: =SUM(AC19:AC19) -> 0 | AE19: =I19+N19+S19+X19+AC19 -> 4400 | AF19: =SUM(AE19:AE19) -> 4400
A20: SUPPLY-GTM | B20: 82401 | C20: GTM | D20: Tablet | E20: ='FO Expenses'!C13 -> 2 | F20: ='FO Expenses'!B13 -> 260 | G20: 1 | H20: /year | I20: =E20*F20*G20 -> 520 | J20: =SUM(I20:I20) -> 520 | K20: 0 | L20: =F20*1.02 -> 265.2 | M20: 1 | N20: =M20*L20*K20 -> 0 | O20: =SUM(N20:N20) -> 0 | P20: 0 | Q20: =L20*1.02 -> 270.504 | R20: 1 | S20: =R20*Q20*P20 -> 0 | T20: =SUM(S20:S20) -> 0 | U20: 0 | V20: =Q20*1.02 -> 275.91408 | W20: 1 | X20: =W20*V20*U20 -> 0 | Y20: =SUM(X20:X20) -> 0 | Z20: 0 | AA20: =V20*1.02 -> 281.43236 | AB20: 1 | AC20: =AB20*AA20*Z20 -> 0 | AD20: =SUM(AC20:AC20) -> 0 | AE20: =I20+N20+S20+X20+AC20 -> 520 | AF20: =SUM(AE20:AE20) -> 520
A21: SUPPLY-GTM | B21: 82401 | C21: GTM | D21: Projector | E21: ='FO Expenses'!C14 -> 1 | F21: ='FO Expenses'!B14 -> 650 | G21: 1 | H21: /year | I21: =E21*F21*G21 -> 650 | J21: =SUM(I21:I21) -> 650 | K21: 0 | L21: =F21*1.02 -> 663 | M21: 1 | N21: =M21*L21*K21 -> 0 | O21: =SUM(N21:N21) -> 0 | P21: 0 | Q21: =L21*1.02 -> 676.26 | R21: 1 | S21: =R21*Q21*P21 -> 0 | T21: =SUM(S21:S21) -> 0 | U21: 0 | V21: =Q21*1.02 -> 689.7852 | W21: 1 | X21: =W21*V21*U21 -> 0 | Y21: =SUM(X21:X21) -> 0 | Z21: 0 | AA21: =V21*1.02 -> 703.5809 | AB21: 1 | AC21: =AB21*AA21*Z21 -> 0 | AD21: =SUM(AC21:AC21) -> 0 | AE21: =I21+N21+S21+X21+AC21 -> 650 | AF21: =SUM(AE21:AE21) -> 650
A22: SUPPLY-GTM | B22: 82401 | C22: GTM | D22: Miscellaneous Supplies | E22: ='FO Expenses'!C15 -> 1 | F22: =SUM('FO Expenses'!D15) -> 530 | G22: 1 | H22: /year | I22: =E22*F22*G22 -> 530 | J22: =SUM(I22:I22) -> 530 | K22: 1 | L22: =F22*1.02 -> 540.6 | M22: 1 | N22: =M22*L22*K22 -> 540.6 | O22: =SUM(N22:N22) -> 540.6 | P22: 1 | Q22: =L22*1.02 -> 551.412 | R22: 1 | S22: =R22*Q22*P22 -> 551.412 | T22: =SUM(S22:S22) -> 551.412 | U22: 1 | V22: =Q22*1.02 -> 562.44024 | W22: 1 | X22: =W22*V22*U22 -> 562.44024 | Y22: =SUM(X22:X22) -> 562.44024 | Z22: 1 | AA22: =V22*1.02 -> 573.68904 | AB22: 1 | AC22: =AB22*AA22*Z22 -> 573.68904 | AD22: =SUM(AC22:AC22) -> 573.68904 | AE22: =I22+N22+S22+X22+AC22 -> 2758.1413 | AF22: =SUM(AE22:AE22) -> 2758.1413
D23: Subtotal Supplies | I23: =SUM(I19:I22) -> 6100 | J23: =SUM(J19:J22) -> 6100 | N23: =SUM(N19:N22) -> 540.6 | O23: =SUM(O19:O22) -> 540.6 | S23: =SUM(S19:S22) -> 551.412 | T23: =SUM(T19:T22) -> 551.412 | X23: =SUM(X19:X22) -> 562.44024 | Y23: =SUM(Y19:Y22) -> 562.44024 | AC23: =SUM(AC19:AC22) -> 573.68904 | AD23: =SUM(AD19:AD22) -> 573.68904 | AE23: =I23+N23+S23+X23+AC23 -> 8328.1413 | AF23: =SUM(AE23:AE23) -> 8328.1413
D25: Volunteer Travel Related Costs (Traditional)
A26: VFLYGTM | B26: 86040 | C26: GTM | D26: Roundtrip Airfare | E26: ='Volunteer Travel'!C4 -> 16 | F26: ='Volunteer Travel'!B19 -> 650 | G26: 1 | H26: /trip | I26: =E26*F26*G26 -> 10400 | J26: =F26*G26*E26 -> 10400 | K26: ='Volunteer Travel'!D4 -> 22 | L26: =F26*1.02 -> 663 | M26: =G26 -> 1 | N26: =L26*M26*K26 -> 14586 | O26: =L26*M26*K26 -> 14586 | P26: ='Volunteer Travel'!E4 -> 22 | Q26: =L26*1.02 -> 676.26 | R26: =M26 -> 1 | S26: =Q26*R26*P26 -> 14877.72 | T26: =Q26*R26*P26 -> 14877.72 | U26: ='Volunteer Travel'!F4 -> 22 | V26: =Q26*1.02 -> 689.7852 | W26: =R26 -> 1 | X26: =V26*W26*U26 -> 15175.274 | Y26: =V26*W26*U26 -> 15175.274 | Z26: ='Volunteer Travel'!G4 -> 16 | AA26: =V26*1.02 -> 703.5809 | AB26: =W26 -> 1 | AC26: =AA26*AB26*Z26 -> 11257.294 | AD26: =AA26*AB26*Z26 -> 11257.294 | AE26: =SUM(AD26,Y26,T26,O26,J26) -> 66296.289 | AF26: =SUM(AE26:AE26) -> 66296.289 | AG26: =AF26*0.7 -> 46407.402 | AH26: =AG26/3 -> 15469.134 | AI26: =AH26/12 -> 1289.0945
A27: VTRADGTM | B27: 86030 | C27: GTM | D27: Lodging | E27: =E26 -> 16 | F27: ='Volunteer Travel'!C19 -> 85 | G27: 14 | H27: /night | I27: =E27*F27*G27 -> 19040 | J27: =F27*G27*E27 -> 19040 | K27: =K26 -> 22 | L27: =F27*1.02 -> 86.7 | M27: =G27 -> 14 | N27: =L27*M27*K27 -> 26703.6 | O27: =L27*M27*K27 -> 26703.6 | P27: =P26 -> 22 | Q27: =L27*1.02 -> 88.434 | R27: =M27 -> 14 | S27: =Q27*R27*P27 -> 27237.672 | T27: =Q27*R27*P27 -> 27237.672 | U27: =U26 -> 22 | V27: =Q27*1.02 -> 90.20268 | W27: =R27 -> 14 | X27: =V27*W27*U27 -> 27782.425 | Y27: =V27*W27*U27 -> 27782.425 | Z27: =Z26 -> 16 | AA27: =V27*1.02 -> 92.006734 | AB27: =W27 -> 14 | AC27: =AA27*AB27*Z27 -> 20609.508 | AD27: =AA27*AB27*Z27 -> 20609.508 | AE27: =SUM(AD27,Y27,T27,O27,J27) -> 121373.21 | AF27: =SUM(AE27:AE27) -> 121373.21 | AG27: =AF27*0.7 -> 84961.244 | AH27: =AG27/3 -> 28320.415 | AI27: =AH27/12 -> 2360.0346
A28: VTRADGTM | B28: 86050 | C28: GTM | D28: Meals and Incidentals | E28: =E26 -> 16 | F28: ='Volunteer Travel'!D19 -> 42.5 | G28: 15 | H28: /day | I28: =E28*F28*G28 -> 10200 | J28: =F28*G28*E28 -> 10200 | K28: =K26 -> 22 | L28: =F28*1.02 -> 43.35 | M28: =G28 -> 15 | N28: =L28*M28*K28 -> 14305.5 | O28: =L28*M28*K28 -> 14305.5 | P28: =P26 -> 22 | Q28: =L28*1.02 -> 44.217 | R28: =M28 -> 15 | S28: =Q28*R28*P28 -> 14591.61 | T28: =Q28*R28*P28 -> 14591.61 | U28: =U26 -> 22 | V28: =Q28*1.02 -> 45.10134 | W28: =R28 -> 15 | X28: =V28*W28*U28 -> 14883.442 | Y28: =V28*W28*U28 -> 14883.442 | Z28: =Z26 -> 16 | AA28: =V28*1.02 -> 46.003367 | AB28: =W28 -> 15 | AC28: =AA28*AB28*Z28 -> 11040.808 | AD28: =AA28*AB28*Z28 -> 11040.808 | AE28: =SUM(AD28,Y28,T28,O28,J28) -> 65021.36 | AF28: =SUM(AE28:AE28) -> 65021.36 | AG28: =AF28*0.7 -> 45514.952 | AH28: =AG28/3 -> 15171.651 | AI28: =AH28/12 -> 1264.3042
A29: VTRADGTM | B29: 86050 | C29: GTM | D29: Health Related | E29: =E26 -> 16 | F29: ='Volunteer Travel'!E19 -> 75 | G29: 1 | H29: /trip | I29: =E29*F29*G29 -> 1200 | J29: =F29*G29*E29 -> 1200 | K29: =K27 -> 22 | L29: =F29*1.02 -> 76.5 | M29: =G29 -> 1 | N29: =L29*M29*K29 -> 1683 | O29: =L29*M29*K29 -> 1683 | P29: =P27 -> 22 | Q29: =L29*1.02 -> 78.03 | R29: =M29 -> 1 | S29: =Q29*R29*P29 -> 1716.66 | T29: =Q29*R29*P29 -> 1716.66 | U29: =U27 -> 22 | V29: =Q29*1.02 -> 79.5906 | W29: =R29 -> 1 | X29: =V29*W29*U29 -> 1750.9932 | Y29: =V29*W29*U29 -> 1750.9932 | Z29: =Z27 -> 16 | AA29: =V29*1.02 -> 81.182412 | AB29: =W29 -> 1 | AC29: =AA29*AB29*Z29 -> 1298.9186 | AD29: =AA29*AB29*Z29 -> 1298.9186 | AE29: =SUM(AD29,Y29,T29,O29,J29) -> 7649.5718 | AF29: =SUM(AE29:AE29) -> 7649.5718
A30: VTRADGTM | B30: 86050 | C30: GTM | D30: Other Travel Related Costs | E30: =E26 -> 16 | F30: ='Volunteer Travel'!F19 -> 124 | G30: 1 | H30: /trip | I30: =E30*F30*G30 -> 1984 | J30: =F30*G30*E30 -> 1984 | K30: =K26 -> 22 | L30: =F30*1.02 -> 126.48 | M30: 1 | N30: =L30*M30*K30 -> 2782.56 | O30: =L30*M30*K30 -> 2782.56 | P30: =P26 -> 22 | Q30: =L30*1.02 -> 129.0096 | R30: 1 | S30: =Q30*R30*P30 -> 2838.2112 | T30: =Q30*R30*P30 -> 2838.2112 | U30: =U26 -> 22 | V30: =Q30*1.02 -> 131.58979 | W30: 1 | X30: =V30*W30*U30 -> 2894.9754 | Y30: =V30*W30*U30 -> 2894.9754 | Z30: =Z26 -> 16 | AA30: =V30*1.02 -> 134.22159 | AB30: 1 | AC30: =AA30*AB30*Z30 -> 2147.5454 | AD30: =AA30*AB30*Z30 -> 2147.5454 | AE30: =SUM(AD30,Y30,T30,O30,J30) -> 12647.292 | AF30: =SUM(AE30:AE30) -> 12647.292 | AG30: =AF30*0.7 -> 8853.1044 | AH30: =AG30/3 -> 2951.0348 | AI30: =AH30/12 -> 245.91957
D32: Volunteer Travel Related Costs (Paired)
A33: VPAIRGTM | B33: 86030 | C33: GTM | D33: Lodging | E33: ='Volunteer Travel'!C5 -> 2 | F33: ='Volunteer Travel'!G19 -> 59.5 | G33: 6 | H33: /night | I33: =E33*F33*G33 -> 714 | J33: =E33*F33*G33 -> 714 | K33: ='Volunteer Travel'!D5 -> 1 | L33: =F33*1.02 -> 60.69 | M33: =G33 -> 6 | N33: =M33*K33*L33 -> 364.14 | O33: =K33*L33*M33 -> 364.14 | P33: ='Volunteer Travel'!D5 -> 1 | Q33: =L33*1.02 -> 61.9038 | R33: =M33 -> 6 | S33: =R33*P33*Q33 -> 371.4228 | T33: =P33*Q33*R33 -> 371.4228 | U33: ='Volunteer Travel'!F5 -> 1 | V33: =Q33*1.02 -> 63.141876 | W33: =R33 -> 6 | X33: =W33*U33*V33 -> 378.85126 | Y33: =U33*V33*W33 -> 378.85126 | Z33: ='Volunteer Travel'!G5 -> 1 | AA33: =V33*1.02 -> 64.404714 | AB33: =W33 -> 6 | AC33: =AB33*Z33*AA33 -> 386.42828 | AD33: =Z33*AA33*AB33 -> 386.42828 | AE33: =SUM(AD33,Y33,T33,O33,J33) -> 2214.8423 | AF33: =SUM(AE33:AE33) -> 2214.8423 | AG33: =AF33*0.7 -> 1550.3896 | AH33: =AG33/3 -> 516.79655 | AI33: =AH33/12 -> 43.066379
A34: VPAIRGTM | B34: 86050 | C34: GTM | D34: Meals and Incidentals | E34: =E33 -> 2 | F34: ='Volunteer Travel'!G20 -> 65.0475 | G34: 7 | H34: /day | I34: =E34*F34*G34 -> 910.665 | J34: =E34*F34*G34 -> 910.665 | K34: =K33 -> 1 | L34: =F34*1.02 -> 66.34845 | M34: =G34 -> 7 | N34: =M34*K34*L34 -> 464.43915 | O34: =K34*L34*M34 -> 464.43915 | P34: =P33 -> 1 | Q34: =L34*1.02 -> 67.675419 | R34: =M34 -> 7 | S34: =R34*P34*Q34 -> 473.72793 | T34: =P34*Q34*R34 -> 473.72793 | U34: =U33 -> 1 | V34: =Q34*1.02 -> 69.028927 | W34: =R34 -> 7 | X34: =W34*U34*V34 -> 483.20249 | Y34: =U34*V34*W34 -> 483.20249 | Z34: =Z33 -> 1 | AA34: =V34*1.02 -> 70.409506 | AB34: =W34 -> 7 | AC34: =AB34*Z34*AA34 -> 492.86654 | AD34: =Z34*AA34*AB34 -> 492.86654 | AE34: =SUM(AD34,Y34,T34,O34,J34) -> 2824.9011 | AF34: =SUM(AE34:AE34) -> 2824.9011 | AG34: =AF34*0.7 -> 1977.4308 | AH34: =AG34/3 -> 659.14359 | AI34: =AH34/12 -> 54.928633
A35: VPAIRGTM | B35: 86050 | C35: GTM | D35: Other Travel Related Costs | E35: =E33 -> 2 | F35: ='Volunteer Travel'!I19 -> 30 | G35: 1 | H35: /trip | I35: =E35*F35*G35 -> 60 | J35: =E35*F35*G35 -> 60 | K35: =K33 -> 1 | L35: =F35*1.02 -> 30.6 | M35: =G35 -> 1 | N35: =M35*K35*L35 -> 30.6 | O35: =K35*L35*M35 -> 30.6 | P35: =P33 -> 1 | Q35: =L35*1.02 -> 31.212 | R35: =M35 -> 1 | S35: =R35*P35*Q35 -> 31.212 | T35: =P35*Q35*R35 -> 31.212 | U35: =U33 -> 1 | V35: =Q35*1.02 -> 31.83624 | W35: =R35 -> 1 | X35: =W35*U35*V35 -> 31.83624 | Y35: =U35*V35*W35 -> 31.83624 | Z35: =Z33 -> 1 | AA35: =V35*1.02 -> 32.472965 | AB35: =W35 -> 1 | AC35: =AB35*Z35*AA35 -> 32.472965 | AD35: =Z35*AA35*AB35 -> 32.472965 | AE35: =SUM(AD35,Y35,T35,O35,J35) -> 186.1212 | AF35: =SUM(AE35:AE35) -> 186.1212 | AG35: =AF35*0.7 -> 130.28484 | AH35: =AG35/3 -> 43.428281 | AI35: =AH35/12 -> 3.6190234
AG36: =AF30-AG30 -> 3794.1876 | AH36: =AG36/2 -> 1897.0938 | AI36: =AH36/9 -> 210.7882
D37: Local Travel Related Costs
A38: LOTRVL-GTM | B38: 86030 | C38: GTM | D38: Lodging | E38: 1 | F38: ='Field Travel'!B15 -> 59.5 | G38: ='Volunteer Travel'!K5 -> 150 | H38: /night | I38: =E38*F38*G38 -> 8925 | J38: =F38*G38 -> 8925 | K38: 1 | L38: =F38*1.02 -> 60.69 | M38: ='Volunteer Travel'!L5 -> 180 | N38: =L38*M38 -> 10924.2 | O38: =L38*M38 -> 10924.2 | P38: 1 | Q38: =L38*1.02 -> 61.9038 | R38: ='Volunteer Travel'!M5 -> 198 | S38: =Q38*R38 -> 12256.952 | T38: =Q38*R38 -> 12256.952 | U38: 1 | V38: =Q38*1.02 -> 63.141876 | W38: ='Volunteer Travel'!N5 -> 180 | X38: =V38*W38 -> 11365.538 | Y38: =V38*W38 -> 11365.538 | Z38: 1 | AA38: =V38*1.02 -> 64.404714 | AB38: ='Volunteer Travel'!O5 -> 144 | AC38: =AA38*AB38 -> 9274.2787 | AD38: =AA38*AB38 -> 9274.2787 | AE38: =SUM(AD38,Y38,T38,O38,J38) -> 52745.969 | AF38: =SUM(AE38:AE38) -> 52745.969 | AG38: =AF38*0.7 -> 36922.178 | AH38: =AG38/3 -> 12307.393 | AI38: =AH38/12 -> 1025.6161
A39: LOTRVL-GTM | B39: 86050 | C39: GTM | D39: Meals and Incidentals | E39: 1 | F39: ='Field Travel'!C15 -> 42.5 | G39: =G38 -> 150 | H39: /day | I39: =E39*F39*G39 -> 6375 | J39: =F39*G39 -> 6375 | K39: 1 | L39: =F39*1.02 -> 43.35 | M39: =M38 -> 180 | N39: =L39*M39 -> 7803 | O39: =L39*M39 -> 7803 | P39: 1 | Q39: =L39*1.02 -> 44.217 | R39: =R38 -> 198 | S39: =Q39*R39 -> 8754.966 | T39: =Q39*R39 -> 8754.966 | U39: 1 | V39: =Q39*1.02 -> 45.10134 | W39: =W38 -> 180 | X39: =V39*W39 -> 8118.2412 | Y39: =V39*W39 -> 8118.2412 | Z39: 1 | AA39: =V39*1.02 -> 46.003367 | AB39: =AB38 -> 144 | AC39: =AA39*AB39 -> 6624.4848 | AD39: =AA39*AB39 -> 6624.4848 | AE39: =SUM(AD39,Y39,T39,O39,J39) -> 37675.692 | AF39: =SUM(AE39:AE39) -> 37675.692 | AG39: =AF39*0.7 -> 26372.984 | AH39: =AG39/3 -> 8790.9948 | AI39: =AH39/12 -> 732.5829
A40: LOTRVL-GTM | B40: 86000 | C40: GTM | D40: Local Transportation Costs (fuel) | E40: 1 | F40: ='Field Travel'!D15 -> 56 | G40: =E26+E33+'Field Travel'!L15 -> 39 | H40: /trip | I40: =E40*F40*G40 -> 2184 | J40: =F40*G40 -> 2184 | K40: 1 | L40: =F40*1.02 -> 57.12 | M40: =K26+K33+'Field Travel'!L16 -> 44 | N40: =L40*M40 -> 2513.28 | O40: =L40*M40 -> 2513.28 | P40: 1 | Q40: =L40*1.02 -> 58.2624 | R40: =P26+P33+'Field Travel'!L17 -> 53 | S40: =Q40*R40 -> 3087.9072 | T40: =Q40*R40 -> 3087.9072 | U40: 1 | V40: =Q40*1.02 -> 59.427648 | W40: =U26+U33+'Field Travel'!L18 -> 44 | X40: =V40*W40 -> 2614.8165 | Y40: =V40*W40 -> 2614.8165 | Z40: 1 | AA40: =V40*1.02 -> 60.616201 | AB40: =Z26+Z33+'Field Travel'!L19 -> 38 | AC40: =AA40*AB40 -> 2303.4156 | AD40: =AA40*AB40 -> 2303.4156 | AE40: =SUM(AD40,Y40,T40,O40,J40) -> 12703.419 | AF40: =SUM(AE40:AE40) -> 12703.419 | AG40: =AF40*0.7 -> 8892.3935 | AH40: =AG40/3 -> 2964.1312 | AI40: =AH40/12 -> 247.01093
D42: Equipment | AI42: =AH36/10 -> 189.70938
A43: NONE | B43: NONE | C43: NONE | D43: Vehicles | E43: 1 | F43: 0 | G43: 1 | H43: /year | I43: =E43*F43*G43 -> 0 | J43: =SUM(I43:I43) -> 0 | K43: 0 | L43: 0 | M43: 0 | N43: =M43*L43*K43 -> 0 | O43: =SUM(N43:N43) -> 0 | P43: 0 | Q43: 0 | R43: 0 | S43: =R43*Q43*P43 -> 0 | T43: =SUM(S43:S43) -> 0 | U43: 0 | V43: 0 | W43: 0 | X43: =W43*V43*U43 -> 0 | Y43: =SUM(X43:X43) -> 0 | Z43: 0 | AA43: 0 | AB43: 0 | AC43: =AB43*AA43*Z43 -> 0 | AD43: =SUM(AC43:AC43) -> 0 | AE43: =I43+N43+S43+X43+AC43 -> 0 | AF43: =SUM(AE43:AE43) -> 0
D44: Subtotal Equipment | I44: =SUM(I42:I43) -> 0 | J44: =SUM(J42:J43) -> 0 | N44: =SUM(N42:N43) -> 0 | O44: =SUM(O42:O43) -> 0 | S44: =SUM(S42:S43) -> 0 | T44: =SUM(T42:T43) -> 0 | X44: =SUM(X42:X43) -> 0 | Y44: =SUM(Y42:Y43) -> 0 | AC44: =SUM(AC42:AC43) -> 0 | AD44: =SUM(AD42:AD43) -> 0 | AE44: =I44+N44+S44+X44+AC44 -> 0 | AF44: =SUM(AE44:AE44) -> 0
D46: Other Expenses
A47: MEETGTM | B47: 87010 | C47: GTM | D47: Meetings and Events | E47: 1 | F47: ='FO Expenses'!L12 -> 65 | G47: 11 | H47: /months | I47: =G47*F47*E47 -> 715 | J47: =SUM(I47:I47) -> 715 | K47: 1 | L47: =F47*1.02 -> 66.3 | M47: 12 | N47: =M47*L47*K47 -> 795.6 | O47: =SUM(N47:N47) -> 795.6 | P47: 1 | Q47: =L47*1.02 -> 67.626 | R47: 12 | S47: =R47*Q47*P47 -> 811.512 | T47: =SUM(S47:S47) -> 811.512 | U47: 1 | V47: =Q47*1.02 -> 68.97852 | W47: 12 | X47: =W47*V47*U47 -> 827.74224 | Y47: =SUM(X47:X47) -> 827.74224 | Z47: 1 | AA47: =V47*1.02 -> 70.35809 | AB47: 9 | AC47: =AB47*AA47*Z47 -> 633.22281 | AD47: =SUM(AC47:AC47) -> 633.22281 | AE47: =I47+N47+S47+X47+AC47 -> 3783.0771 | AF47: =SUM(AE47:AE47) -> 3783.0771
A48: TRANSGTM | B48: 85105 | C48: GTM | D48: Transportation | E48: 1 | F48: ='FO Expenses'!L13 -> 155 | G48: 11 | H48: /months | I48: =G48*F48*E48 -> 1705 | J48: =SUM(I48:I48) -> 1705 | K48: 1 | L48: =F48*1.02 -> 158.1 | M48: 12 | N48: =M48*L48*K48 -> 1897.2 | O48: =SUM(N48:N48) -> 1897.2 | P48: 1 | Q48: =L48*1.02 -> 161.262 | R48: 12 | S48: =R48*Q48*P48 -> 1935.144 | T48: =SUM(S48:S48) -> 1935.144 | U48: 1 | V48: =Q48*1.02 -> 164.48724 | W48: 12 | X48: =W48*V48*U48 -> 1973.8469 | Y48: =SUM(X48:X48) -> 1973.8469 | Z48: 1 | AA48: =V48*1.02 -> 167.77698 | AB48: 9 | AC48: =AB48*AA48*Z48 -> 1509.9929 | AD48: =SUM(AC48:AC48) -> 1509.9929 | AE48: =I48+N48+S48+X48+AC48 -> 9021.1837 | AF48: =SUM(AE48:AE48) -> 9021.1837
...

Sheet Guyana
A1: Entity: | B1: P | D1: Partners of the Americas F2F Caribbean Basin Program Budget
A2: Program-Dept.: | B2: 30100 | D2: USAID NOFO #7200AA23RFA00006
A3: Funder-Grant: | B3: USAID650
A4: Budget (Activity) Code | B4: Account Code | C4: Country Code | D4: Guyana | I4: Year 1 | K4: Year 2 | P4: Year 3 | U4: Year 4 | Z4: Year 5 | AE4: Total | AF4: Grand
E5: Units | F5: Cost | G5: Duration | H5: Type | I5: USAID | J5: Total | K5: Units | L5: Cost | M5: Duration | N5: USAID | O5: Total | P5: Units | Q5: Cost | R5: Duration | S5: USAID | T5: Total | U5: Units | V5: Cost | W5: Duration | X5: USAID | Y5: Total | Z5: Units | AA5: Cost | AB5: Duration | AC5: USAID | AD5: Total | AE5: USAID | AF5: Total
D7: Key Personnel
A8: PERSNL-GUY | B8: 70000 | C8: GUY | D8: Country Director* | E8: 1 | F8: 4000 | G8: 12 | H8: /months | I8: =G8*F8*E8 -> 48000 | J8: =SUM(I8:I8) -> 48000 | K8: 1 | L8: =F8*1.03 -> 4120 | M8: 12 | N8: =M8*L8*K8 -> 49440 | O8: =SUM(N8:N8) -> 49440 | P8: 1 | Q8: =L8*1.03 -> 4243.6 | R8: 12 | S8: =R8*Q8*P8 -> 50923.2 | T8: =SUM(S8:S8) -> 50923.2 | U8: 1 | V8: =Q8*1.03 -> 4370.908 | W8: 12 | X8: =W8*V8*U8 -> 52450.896 | Y8: =SUM(X8:X8) -> 52450.896 | Z8: 1 | AA8: =V8*1.03 -> 4502.0352 | AB8: 9 | AC8: =AB8*AA8*Z8 -> 40518.317 | AD8: =SUM(AC8:AC8) -> 40518.317 | AE8: =I8+N8+S8+X8+AC8 -> 241332.41 | AF8: =SUM(AE8:AE8) -> 241332.41
D10: Other Personnel
A11: PERSNL-GUY | B11: 70000 | C11: GUY | D11: Field Officer | E11: 1 | F11: 1100 | G11: 10 | H11: /months | I11: =G11*F11*E11 -> 11000 | J11: =SUM(I11:I11) -> 11000 | K11: =E11 -> 1 | L11: =F11*1.03 -> 1133 | M11: 12 | N11: =M11*L11*K11 -> 13596 | O11: =SUM(N11:N11) -> 13596 | P11: =E11 -> 1 | Q11: =L11*1.03 -> 1166.99 | R11: 12 | S11: =R11*Q11*P11 -> 14003.88 | T11: =SUM(S11:S11) -> 14003.88 | U11: =E11 -> 1 | V11: =Q11*1.03 -> 1201.9997 | W11: 12 | X11: =W11*V11*U11 -> 14423.996 | Y11: =SUM(X11:X11) -> 14423.996 | Z11: =E11 -> 1 | AA11: =V11*1.03 -> 1238.0597 | AB11: 9 | AC11: =AB11*AA11*Z11 -> 11142.537 | AD11: =SUM(AC11:AC11) -> 11142.537 | AE11: =I11+N11+S11+X11+AC11 -> 64166.414 | AF11: =SUM(AE11:AE11) -> 64166.414 | AG11: =K11+P11+U11+Z11+AE11 -> 64170.414 | AH11: =SUM(AG11:AG11) -> 64170.414 | AI11: =M11+R11+W11+AB11+AG11 -> 64215.414
A12: PERSNL-GUY | B12: 70000 | C12: GUY | D12: Administrative Assistant | E12: 1 | F12: 850 | G12: 11 | H12: /months | I12: =G12*F12*E12 -> 9350 | J12: =SUM(I12:I12) -> 9350 | K12: 1 | L12: =F12*1.03 -> 875.5 | M12: 12 | N12: =M12*L12*K12 -> 10506 | O12: =SUM(N12:N12) -> 10506 | P12: 1 | Q12: =L12*1.03 -> 901.765 | R12: 12 | S12: =R12*Q12*P12 -> 10821.18 | T12: =SUM(S12:S12) -> 10821.18 | U12: 1 | V12: =Q12*1.03 -> 928.81795 | W12: 12 | X12: =W12*V12*U12 -> 11145.815 | Y12: =SUM(X12:X12) -> 11145.815 | Z12: 1 | AA12: =V12*1.03 -> 956.68249 | AB12: 9 | AC12: =AB12*AA12*Z12 -> 8610.1424 | AD12: =SUM(AC12:AC12) -> 8610.1424 | AE12: =I12+N12+S12+X12+AC12 -> 50433.138 | AF12: =SUM(AE12:AE12) -> 50433.138 | AG12: =K12+P12+U12+Z12+AE12 -> 50437.138 | AH12: =SUM(AG12:AG12) -> 50437.138 | AI12: =M12+R12+W12+AB12+AG12 -> 50482.138
D13: Subtotal Field Salaries | I13: =SUM(I8:I12) -> 68350 | J13: =SUM(J8:J12) -> 68350 | N13: =SUM(N8:N12) -> 73542 | O13: =SUM(O8:O12) -> 73542 | S13: =SUM(S8:S12) -> 75748.26 | T13: =SUM(T8:T12) -> 75748.26 | X13: =SUM(X8:X12) -> 78020.708 | Y13: =SUM(Y8:Y12) -> 78020.708 | AC13: =SUM(AC8:AC12) -> 60270.997 | AD13: =SUM(AD8:AD12) -> 60270.997 | AE13: =I13+N13+S13+X13+AC13 -> 355931.96 | AF13: =SUM(AE13:AE13) -> 355931.96
A15: FRINGE-GUY | B15: 70015 | C15: GUY | D15: Benefits | E15: 0.1032 | F15: =I13 -> 68350 | I15: =F15*E15 -> 7053.72 | J15: =SUM(I15:I15) -> 7053.72 | L15: =N13 -> 73542 | N15: =L15*E15 -> 7589.5344 | O15: =SUM(N15:N15) -> 7589.5344 | Q15: =S13 -> 75748.26 | S15: =Q15*E15 -> 7817.2204 | T15: =SUM(S15:S15) -> 7817.2204 | V15: =X13 -> 78020.708 | X15: =V15*E15 -> 8051.737 | Y15: =SUM(X15:X15) -> 8051.737 | AA15: =AC13 -> 60270.997 | AC15: =AA15*E15 -> 6219.9669 | AD15: =SUM(AC15:AC15) -> 6219.9669 | AE15: =I15+N15+S15+X15+AC15 -> 36732.179 | AF15: =SUM(AE15:AE15) -> 36732.179
D17: Supplies
A18: SUPPLY-GUY | B18: 82401 | C18: GUY | D18: Laptops | E18: ='FO Expenses'!C19 -> 3 | F18: ='FO Expenses'!B19 -> 1100 | G18: 1 | H18: /year | I18: =E18*F18*G18 -> 3300 | J18: =SUM(I18:I18) -> 3300 | K18: 0 | L18: =F18*1.02 -> 1122 | M18: 1 | N18: =M18*L18*K18 -> 0 | O18: =SUM(N18:N18) -> 0 | P18: 0 | Q18: =L18*1.02 -> 1144.44 | R18: 1 | S18: =R18*Q18*P18 -> 0 | T18: =SUM(S18:S18) -> 0 | U18: 0 | V18: =Q18*1.02 -> 1167.3288 | W18: 1 | X18: =W18*V18*U18 -> 0 | Y18: =SUM(X18:X18) -> 0 | Z18: 0 | AA18: =V18*1.02 -> 1190.6754 | AB18: 1 | AC18: =AB18*AA18*Z18 -> 0 | AD18: =SUM(AC18:AC18) -> 0 | AE18: =I18+N18+S18+X18+AC18 -> 3300 | AF18: =SUM(AE18:AE18) -> 3300
A19: SUPPLY-GUY | B19: 82401 | C19: GUY | D19: Tablet | E19: ='FO Expenses'!C20 -> 2 | F19: ='FO Expenses'!B20 -> 190 | G19: 1 | H19: /year | I19: =E19*F19*G19 -> 380 | J19: =SUM(I19:I19) -> 380 | K19: 0 | L19: =F19*1.02 -> 193.8 | M19: 1 | N19: =M19*L19*K19 -> 0 | O19: =SUM(N19:N19) -> 0 | P19: 0 | Q19: =L19*1.02 -> 197.676 | R19: 1 | S19: =R19*Q19*P19 -> 0 | T19: =SUM(S19:S19) -> 0 | U19: 0 | V19: =Q19*1.02 -> 201.62952 | W19: 1 | X19: =W19*V19*U19 -> 0 | Y19: =SUM(X19:X19) -> 0 | Z19: 0 | AA19: =V19*1.02 -> 205.66211 | AB19: 1 | AC19: =AB19*AA19*Z19 -> 0 | AD19: =SUM(AC19:AC19) -> 0 | AE19: =I19+N19+S19+X19+AC19 -> 380 | AF19: =SUM(AE19:AE19) -> 380
A20: SUPPLY-GUY | B20: 82401 | C20: GUY | D20: Projector | E20: ='FO Expenses'!C21 -> 1 | F20: ='FO Expenses'!B21 -> 650 | G20: 1 | H20: /year | I20: =E20*F20*G20 -> 650 | J20: =SUM(I20:I20) -> 650 | K20: 0 | L20: =F20*1.02 -> 663 | M20: 1 | N20: =M20*L20*K20 -> 0 | O20: =SUM(N20:N20) -> 0 | P20: 0 | Q20: =L20*1.02 -> 676.26 | R20: 1 | S20: =R20*Q20*P20 -> 0 | T20: =SUM(S20:S20) -> 0 | U20: 0 | V20: =Q20*1.02 -> 689.7852 | W20: 1 | X20: =W20*V20*U20 -> 0 | Y20: =SUM(X20:X20) -> 0 | Z20: 0 | AA20: =V20*1.02 -> 703.5809 | AB20: 1 | AC20: =AB20*AA20*Z20 -> 0 | AD20: =SUM(AC20:AC20) -> 0 | AE20: =I20+N20+S20+X20+AC20 -> 650 | AF20: =SUM(AE20:AE20) -> 650
A21: SUPPLY-GUY | B21: 82401 | C21: GUY | D21: Miscellaneous Supplies | E21: =1 -> 1 | F21: ='FO Expenses'!B22 -> 530 | G21: 1 | H21: /year | I21: =E21*F21*G21 -> 530 | J21: =SUM(I21:I21) -> 530 | K21: 1 | L21: =F21*1.02 -> 540.6 | M21: 1 | N21: =M21*L21*K21 -> 540.6 | O21: =SUM(N21:N21) -> 540.6 | P21: 1 | Q21: =L21*1.02 -> 551.412 | R21: 1 | S21: =R21*Q21*P21 -> 551.412 | T21: =SUM(S21:S21) -> 551.412 | U21: 1 | V21: =Q21*1.02 -> 562.44024 | W21: 1 | X21: =W21*V21*U21 -> 562.44024 | Y21: =SUM(X21:X21) -> 562.44024 | Z21: 1 | AA21: =V21*1.02 -> 573.68904 | AB21: 1 | AC21: =AB21*AA21*Z21 -> 573.68904 | AD21: =SUM(AC21:AC21) -> 573.68904 | AE21: =I21+N21+S21+X21+AC21 -> 2758.1413 | AF21: =SUM(AE21:AE21) -> 2758.1413
D22: Subtotal Supplies | I22: =SUM(I18:I21) -> 4860 | J22: =SUM(J18:J21) -> 4860 | N22: =SUM(N18:N21) -> 540.6 | O22: =SUM(O18:O21) -> 540.6 | S22: =SUM(S18:S21) -> 551.412 | T22: =SUM(T18:T21) -> 551.412 | X22: =SUM(X18:X21) -> 562.44024 | Y22: =SUM(Y18:Y21) -> 562.44024 | AC22: =SUM(AC18:AC21) -> 573.68904 | AD22: =SUM(AD18:AD21) -> 573.68904 | AE22: =I22+N22+S22+X22+AC22 -> 7088.1413 | AF22: =SUM(AE22:AE22) -> 7088.1413
D24: Volunteer Travel Related Costs (Traditional)
