Workbook

Sheet Cover
A1: Shipley Capture Workbook
A2: Opportunity:
A3: Customer:
A4: Capture Manager:
A5: Capture plan start date:
A6: Expected RFP date:
A7: Latest Update:

Sheet TOC
A1: Table of Contents
A2: Section | B2: Tab
A4: Capture Plan Executive Overview | B4: Executive Overview
A6: Pwin | B6: Pwin Parameters
B7: Pwin Calculator
A9: External anaylsis | B9: Opportunity Description
B10: Customer Profile
B11: Hot Buttons
B12: Competitive Intelligence Part 1
B13: Competitive Intelligence Part 2
A15: Internal Analysis | B15: Our Competitive Position Part 1
B16: Our Competitive Position Part 2
B17: Estimate of Winning Price
B18: Internal Analysis: Pricing to Win Window
A20: Strategy Development | B20: Bidder Comparison Chart
B21: Leverage Our Strength
B22: Mitigate Our Weakness
B23: Exploit Competitor's Weakness
B24: Neutralize Competitor's Strength
B25: Teaming
B26: Integrated Solution Worksheet (ISW)
B27: Win Themes
B28: Benefits & Features
A30: Action Plans | B30: Customer Contact Plan
B31: Customer Stakeholders
B32: Intelligence Collection Plan
B33: Solution Development Plan
B34: Contingency Plan
B35: Risk Management Plan
A37: Preliminary Bid | B37: Preliminary Bid Checklist
B38: Preliminary Planning and Content
A40: Schedule | B40: 90-Day Action Plan Schedule

Sheet Executive Overview
A1: Executive Overview
A2: Program overview
A3: Customer overview
A4: Competitive position summary
A5: Our solution summary
A6: Capture strategy
A7: Status

Sheet Pwin Parameters
A1: Pwin Parameter Instructions:
A2: 1. Hover over column headings for pop-up help.
A3: 2. Modify or enter win factors only in gray-shaded cells.
A4: 3. Modify factor ratings to match organizational criteria, with most favorable rating on top, least favorable on bottom.
A5: 4. If other factors are entered, four ratings must be defined for each, with most favorable rating on top, least favorable on bottom.
A6: 5. The Points column cannot be modified.
A7: 6. Change breakpoint values based on organizational aggressiveness. Lowering breakpoint values will encourage pursuit of less favorable opportunities.
A9: Probability Parameters
A10: Win Factors | B10: Win Factor Ratings (Modify to Meet Organizational Criteria) | C10: Points | D10: Breakpoints | E10: Values
A11: Pre-RFP Marketing | B11: We had extensive pre-RFP contact and strongly influenced the requirements | C11: 4 | D11: Strong Pwin | E11: 3.5
B12: We provided background information for preparation of the RFP | C12: 3 | D12: Moderate Pwin | E12: 2.5
B13: We met with the customer prior to release of the RFP | C13: 2 | D13: Abandon pursuit | E13: 1.5
B14: We learned of the opportunity after the RFP was issued | C14: 1
A16: Customer's Preference | B16: The customer shows evidence of a strong preference for us | C16: 4
B17: The customer suggested we should bid | C17: 3
B18: The customer is unbiased, with no preference for any company | C18: 2
B19: The customer has a negative bias toward us which we must overcome | C19: 1
A21: Customer's Knowledge of Us | B21: The customer has contracted with our bidding business unit before | C21: 4
B22: The customer has contracted with business units other than our bidding unit | C22: 3
B23: The customer is familiar with us only through work we have done for others | C23: 2
B24: The customer is not familiar with us | C24: 1
A26: Technical | B26: We have a unique, proprietary solution | C26: 4
B27: We have a solution equivalent to other competitors | C27: 3
B28: Competitors have solution advantages we can overcome | C28: 2
B29: Competitors have unique, proprietary solutions that we may not be able to overcome | C29: 1
A31: Management | B31: We have a unique, proven management approach the customer will value | C31: 4
B32: We can offer a management solution better than most competitors | C32: 3
B33: Competitors have management advantages we can overcome | C33: 2
B34: Competitors have unique management solutions the customer will value | C34: 1
A36: Cost | B36: We know the budget and have a strong cost advantage | C36: 4
B37: We have a slight cost advantage | C37: 3
B38: Cost is equivalent for all competitors | C38: 2
B39: Competitors have cost advantages | C39: 1
A41: Incumbency | B41: We are a strong incumbent or can team with a strong incumbent | C41: 4
B42: We are an incumbent | C42: 3
B43: There is no incumbent | C43: 2
B44: A competitor is a strong incumbent | C44: 1
A46: Experience | B46: We have sold the same or similar product/service to this customer in the past | C46: 4
B47: We will be selling an existing product/service to a new customer | C47: 3
B48: We will be selling a new product/service to an existing customer | C48: 2
...

Sheet Pwin Calculator
A1: NOTICE: This Pwin Calculator is intended solely as an aid in evaluating the advisability of pursuing business opportunities and should be used in conjunction with other means of research and analysis. Use of this tool is subject to legal notices distributed with it or available from Shipley Associates. Shipley Associates expressly denies and user provides unconditional release from any liability for damages or loss of business purportedly arising from its use.
A3: Worksheet Instructions:
A4: 1. Enter information and view result in the Pwin Calculator on this worksheet.
A5: 2. Customize the tool for your organization's pipeline management preferences on the Pwin Parameters worksheet.
A6: 3. Hover over table headings to view pop-up help.
A7: 4. Completed chart may be printed or saved.
A8: 5. Worksheet Instructions will not print on completed chart.
A9: 6. Chart can be copied and pasted onto a PowerPoint slide.
A10: 7. Calculated scores appear in gray-shaded cells.
A11: 8. Strong Pwin indication will shade Result cell GREEN. Moderate indication will show YELLOW, recommended abandonment RED.
C13: Pwin Calculator
A14: Opportunity:
A15: Anticipated Value:
A16: Win Factor | B16: Wt. Inc. | C16: Win Factor Rating (Select one from drop-down list) | D16: Points | E16: Score
A17: ='Pwin Parameters'!$A$11 -> Pre-RFP Marketing | D17: =IF(C17>0,VLOOKUP($C17,'Pwin Parameters'!B11:C74,2,FALSE),0) -> 0 | E17: =IF(C17>0,(1+0.1*B17)*(D17-'Pwin Parameters'!$E$13),"")
A18: ='Pwin Parameters'!$A$16 -> Customer's Preference | D18: =IF(C18>0,VLOOKUP($C18,'Pwin Parameters'!B12:C75,2,FALSE),0) -> 0 | E18: =IF(C18>0,(1+0.1*B18)*(D18-'Pwin Parameters'!$E$13),"")
A19: ='Pwin Parameters'!$A$21 -> Customer's Knowledge of Us | D19: =IF(C19>0,VLOOKUP($C19,'Pwin Parameters'!B13:C76,2,FALSE),0) -> 0 | E19: =IF(C19>0,(1+0.1*B19)*(D19-'Pwin Parameters'!$E$13),"")
A20: ='Pwin Parameters'!$A$26 -> Technical | D20: =IF(C20>0,VLOOKUP($C20,'Pwin Parameters'!B14:C77,2,FALSE),0) -> 0 | E20: =IF(C20>0,(1+0.1*B20)*(D20-'Pwin Parameters'!$E$13),"")
A21: ='Pwin Parameters'!$A$31 -> Management | D21: =IF(C21>0,VLOOKUP($C21,'Pwin Parameters'!B15:C78,2,FALSE),0) -> 0 | E21: =IF(C21>0,(1+0.1*B21)*(D21-'Pwin Parameters'!$E$13),"")
A22: ='Pwin Parameters'!$A$36 -> Cost | D22: =IF(C22>0,VLOOKUP($C22,'Pwin Parameters'!B16:C79,2,FALSE),0) -> 0 | E22: =IF(C22>0,(1+0.1*B22)*(D22-'Pwin Parameters'!$E$13),"")
A23: ='Pwin Parameters'!$A$41 -> Incumbency | D23: =IF(C23>0,VLOOKUP($C23,'Pwin Parameters'!B17:C80,2,FALSE),0) -> 0 | E23: =IF(C23>0,(1+0.1*B23)*(D23-'Pwin Parameters'!$E$13),"")
A24: ='Pwin Parameters'!$A$46 -> Experience | D24: =IF(C24>0,VLOOKUP($C24,'Pwin Parameters'!B18:C81,2,FALSE),0) -> 0 | E24: =IF(C24>0,(1+0.1*B24)*(D24-'Pwin Parameters'!$E$13),"")
A25: ='Pwin Parameters'!$A$51 -> Past Performance | D25: =IF(C25>0,VLOOKUP($C25,'Pwin Parameters'!B19:C97,2,FALSE),0) -> 0 | E25: =IF(C25>0,(1+0.1*B25)*(D25-'Pwin Parameters'!$E$13),"")
A26: ='Pwin Parameters'!$A$56 -> Contract Risk | D26: =IF(C26>0,VLOOKUP($C26,'Pwin Parameters'!B20:C98,2,FALSE),0) -> 0 | E26: =IF(C26>0,(1+0.1*B26)*(D26-'Pwin Parameters'!$E$13),"")
A27: ='Pwin Parameters'!$A$61 -> Contract Size | D27: =IF(C27>0,VLOOKUP($C27,'Pwin Parameters'!B21:C99,2,FALSE),0) -> 0 | E27: =IF(C27>0,(1+0.1*B27)*(D27-'Pwin Parameters'!$E$13),"")
A28: ='Pwin Parameters'!$A$66 -> Competitor Rating | D28: =IF(C28>0,VLOOKUP($C28,'Pwin Parameters'!B22:C100,2,FALSE),0) -> 0 | E28: =IF(C28>0,(1+0.1*B28)*(D28-'Pwin Parameters'!$E$13),"")
A29: ='Pwin Parameters'!A71 -> Other | D29: =IF(C29>0,VLOOKUP($C29,'Pwin Parameters'!B23:C101,2,FALSE),0) -> 0 | E29: =IF(C29>0,(1+0.1*B29)*(D29-'Pwin Parameters'!$E$13),"")
D30: Result | E30: =AVERAGEIF(C17:C29,"<>""",E17:E29)+'Pwin Parameters'!$E$13 -> #DIV/0!
A31: Key: 4 = Strong Pwin 3 = Moderate Pwin 2 = Moderate Avoidance 1 = Strong Avoidance

Sheet Opp Description
A1: External Analysis: Opportunity Description
A2: Customer
A3: Program summary
A4: Key requirements
A5: Deliverables
A6: Budget and fiscal year funding profile
A7: Schedule
A8: Type of contract
A9: Other (as applicable to this offer)

Sheet Cust Profile
A1: External Analysis: Customer Profile
A2: Organization and key personnel
A3: Purchasing or buying process
A4: Evaluation process
A5: Buying history and trends

Sheet Hot Buttons
A1: External Analysis: Hot Button Issues
A2: Hot Button Owner | B2: Issues | C2: Objectives | D2: Hot Buttons | E2: Evidence | F2: Impact

Sheet Competitive Intel 1
A1: External Analysis: Competitive Intelligence Part 1— Competitor A [insert company name]
A2: Market approach and position | D2: NOTE: Repeat parts 1 and 2 for each major competitor
A3: Products and/or services
A4: Historical pricing patterns
A5: Business development
A6: Customer relationship
A7: Relevant experience
A8: Past performance

Sheet Competitive Intel 2
A1: External Analysis: Competitive Intelligence Part 2—Competitor A
A2: Customer perceptions | B2: Strengths | C2: Weaknesses
A11: Hot buttons | B11: Competitor's available solution | C11: Competitor's discriminator(s) | D11: Gap

Sheet Our Position Pt 1
A1: Internal Analysis: Our Competitive Position Part 1
A2: Market approach and position
A3: Products and/or services
A4: Historical pricing patterns
A5: Business development
A6: Customer relationship
A7: Relevant experience
A8: Past performance

Sheet Our Position Pt 2
A1: Internal Analysis: Our Competitive Position Part 2
A2: Customer perceptions | B2: Strengths | C2: Weaknesses
A10: Hot buttons | B10: Our solution | C10: Our discriminator(s) | D10: Gap

Sheet Winning Price
A1: Internal Analysis: Estimating Winning Price
A3: INTERNAL ANALYSIS
A4: Our Estimate of Winning Price
A6: Customer Budget | E6: Customer Expectations
A7: • Total available funds • Timing • Types and sources of funds | E7: • Independent cost estimates • Should cost models • Prior purchase prices
C17: Estimated Price to Win
C18: • Upper and lower limits on price and capability • Cost versus price • Acquisition, total installed, total life cycle, or annualized cost
A28: Low Cost | E28: Best Value
A29: • Minimally acceptable capability • Your organization's low cost approach • Credible competitors' approaches | C29: Winning Price Development • Fundamental relationship • Customer's perceived value ≥ customer's budget ≥ your price ≥ your price • Establish the target price early • Use target price to guide early solution development • Use "top down" then "bottom up" approach • Best value solutions • Balance value against price to maximize the difference | E29: • Capability satisfied solution • Optimal price capability tradeoff • Value proposition

Sheet PTW Window
A1: Internal Analysis: Pricing to Win Window
B2: Terminology • Maximum budget is the maximum amount the customer has budgeted • Addressable budget is the amount the customer has available for a purchase after deducting expenses associated with the purchase • Minimum credible budget is the amount below which the customer doubts the credibility of obtaining an acceptable solution • Minimum acceptable capability is the minimum capability acceptable to this customer • Maximum justifiable capability is the maximum capability that this customer can justify | C2: * NOTE: as you address capability with the customer, consider how this affects solutions, discriminators and PTW
A8: Minimum addressable budget | B8: Minimum capability* | C8: Maximum capability*

Sheet Bidder Comparison
A1: Strategy: Bidder Comparison Chart
K2: Use this worksheet when you wish to assign weighting factors to several issues and score bidders using a consistent 0-10 scale.
A3: Customer Issues | B3: Weight | C3: Us | E3: Competitor A | G3: Competitor B | I3: Competitor C
C4: Points | D4: Score | E4: Points | F4: Score | G4: Points | H4: Score | I4: Points | J4: Score
D5: =B5*C5 -> 0 | F5: =B5*E5 -> 0 | H5: =$B5*G5 -> 0 | J5: =$B5*I5 -> 0 | K5: Instructions:
D6: =B6*C6 -> 0 | F6: =B6*E6 -> 0 | H6: =$B6*G6 -> 0 | J6: =$B6*I6 -> 0 | K6: 1. Scroll over headings for pop-up instructions.
D7: =B7*C7 -> 0 | F7: =B7*E7 -> 0 | H7: =$B7*G7 -> 0 | J7: =$B7*I7 -> 0 | K7: 2. Enter competitors' names in header.
D8: =B8*C8 -> 0 | F8: =B8*E8 -> 0 | H8: =$B8*G8 -> 0 | J8: =$B8*I8 -> 0 | K8: 3. Calculated scores appear in gray-shaded cells.
D9: =B9*C9 -> 0 | F9: =B9*E9 -> 0 | H9: =$B9*G9 -> 0 | J9: =$B9*I9 -> 0 | K9: 4. Highest score will turn GREEN.
D10: =B10*C10 -> 0 | F10: =B10*E10 -> 0 | H10: =$B10*G10 -> 0 | J10: =$B10*I10 -> 0 | K10: 5. Unprotect worksheet to modify.
D11: =B11*C11 -> 0 | F11: =B11*E11 -> 0 | H11: =$B11*G11 -> 0 | J11: =$B11*I11 -> 0 | K11: 6. Completed chart may be printed or saved.
D12: =B12*C12 -> 0 | F12: =B12*E12 -> 0 | H12: =$B12*G12 -> 0 | J12: =$B12*I12 -> 0
D13: =B13*C13 -> 0 | F13: =B13*E13 -> 0 | H13: =$B13*G13 -> 0 | J13: =$B13*I13 -> 0
D14: =B14*C14 -> 0 | F14: =B14*E14 -> 0 | H14: =$B14*G14 -> 0 | J14: =$B14*I14 -> 0
D15: =B15*C15 -> 0 | F15: =B15*E15 -> 0 | H15: =$B15*G15 -> 0 | J15: =$B15*I15 -> 0
A16: Totals | D16: =SUM(D5:D15) -> 0 | F16: =SUM(F5:F15) -> 0 | H16: =SUM(H5:H15) -> 0 | J16: =SUM(J5:J15) -> 0

Sheet Leverage
A1: Strategy: Leverage Our Strengths
A2: We will leverage our strength in: | B2: By taking these actions: | C2: To achieve (what):

Sheet Mitigate
A1: Strategy: Mitigate Our Weaknesses
A2: We will mitigate our weakness in: | B2: By taking these actions: | C2: To achieve (what):

Sheet Exploit
A1: Strategy: Exploit Competitor's Weaknesses
A2: We will exploit our competitor's weakness in: | B2: By taking these actions: | C2: To achieve (what):

Sheet Neutralize
A1: Strategy: Neutralize Competitor's Strengths
A2: We will neutralize our competitor's strength in: | B2: By taking these actions: | C2: To achieve (what):

Sheet Teaming
A1: Strategy: Teaming (Partner) Insights
C2: Partner A | D2: Partner B | E2: Partner C | F2: Partner D | G2: Partner E
A3: Partner strategy | B3: Partner will be prime or subcontractor
B4: Partner's workstream or workshare on the opportunity
B5: Partner's strategic value
B6: (other)
A7: Partner selection criteria | B7: Customer alignment/relationship
B8: Partner's industry focus
B9: Partner's technology expertise
B10: Partner's value proposition
B11: How does the partner help increase our Pwin?
A12: Partner risks | B12: Is the partner vetted in the supplier management system?
B13: Is the partner involving any IP in this engagement?
B14: Is the partner bidding with others on this opportunity?
B15: (other)
A16: Partner contracts | B16: NDA in place
B17: Teaming agreement/MOU executed
B18: SOW
B19: Direct contract with customer
B20: Past performance documentation
B21: Other Contracts (e.g., enterprise agreement, software contracts, hardware)
B22: (other)

Sheet ISW
A1: Strategy: Integrated Solution Worksheet
A2: Customer issues (hot buttons) | B2: Customer requirements | C2: Discriminator | D2: Our solution | E2: Gap (Y or N) | F2: Competitor's solution | G2: Competitor Gap (Y or N) | H2: Competitor's discriminator (positive or negative) | I2: Strategy | J2: Action plan

Sheet Win Themes
A1: Strategy: Win Themes
A2: – Win themes are born out of strategy statements in the capture plan. They are messages we want to use to reinforce our standing and solution with the customer. – Maximum of three to four easy to understand statements explaining why you are optimum choice. – During proposal preparation, convert win themes into proposal theme statements. Include them in your Executive Summary and in major sections of the proposal.
A3: Win Theme Formula
A4: Acknowledge the concern, state the solution, discriminator, feature and benefit of solution, proof.
A5: The Snodgrass Corporation eliminates customer relationship management shortfalls by teaming with the only company providing CRM GAPSURE™ software that identifies and resolves issues as they occur. This was demonstrated successfully for three large box retailers in 2018 resulting in 25-33% increase in customer satisfaction.
A6: Develop Your Win Themes
A7: Acknowledge concern | B7: State solution | C7: Discriminator | D7: Benefit and feature | E7: Proof

Sheet Benefit-Feature
A1: Strategy: Benefits and Features
C2: Solution feature: what is it and how does it work: – Description of software – Implementation process – Project team – Core solution – Training plan – Support model
C3: Solution advantage: what the features does, how it performs: – Faster – Increased – Decreased – Improved – Reduced – Safer – Integrated
C4: Customer benefit is an advantage the customer wants/needs: – Increased cyber security – Improved employee productivity – Decreased operating costs
A5: Solution feature | B5: Advantage | C5: Benefit

Sheet Cust Contact
A1: Action Plans: Customer Contact Plan
A2: Contact objective (end in mind) | B2: Who will you meet with? | C2: Where/how (in person, call, virtual) | D2: When (date) | E2: Cost (if applicable) | F2: Action/status

Sheet Cust Stakeholders
A1: Action Plan: Customer Stakeholders
A2: Category | B2: Title/role | C2: Name | D2: Reports to | E2: Contact information | F2: Level of contact | G2: Level of support | H2: Role in decision | I2: Hot buttons | J2: Influenced by | K2: Team member assigned
A3: <Category> | B3: <Title> | C3: <Name> | E3: <Email or else when possible> | F3: L/M/H | G3: L/M/H/U/A | H3: Ultimate authority | I3: <Names> | J3: <Names> | K3: <Names>
B4: (program Manager) | C4: John Snodgrass | D4: Sue Snitherwick | E4: XXXX@XXXX.com | F4: Medium | G4: Medium | H4: Operations | I4: Transition, cost, schedule | J4: Sue Snitherwick | K4: Joe Boomerang
B5: CIO | F5: High | G5: High | H5: Legal
B6: CTO | G6: Unsure | H6: Operations
B7: LOB Manager(s) | G7: Adversary | H7: Technical
B8: Executive Project Sponsor | H8: Unsure
B9: Program Manager | H9: Sponsor
B10: Project Manager | H10: Power Sponsor

Sheet Intel Collection
A1: Action Plan: Intelligence Collection Plan
A2: Intelligence objective | B2: Assigned to | C2: Date required/ date received | D2: How (web research, 3rd party etc.) | E2: Cost | F2: Action/status

Sheet Solution Development
A1: Action Plan: Solution Development (if required)
A2: Solution element | B2: Assigned to | C2: Date required/ date received | D2: Cost | E2: Action/status

Sheet Contingency
A1: Action Plan: Contingency Plan
A2: Event | B2: Probablity | C2: Impact | D2: Area (personnel, solution, pricing etc.) | E2: Response actions | F2: Action/status

Sheet Risk
A1: Action Plan: Risk Management Plan (NOTE: Use DoD Risk Guide 2017)
A2: Risk area | B2: Probability | C2: Impact | D2: Likelihood | E2: Mitigation plan | F2: Status/actions

Sheet Preliminary Bid CL
A1: Preliminary Bid Checklist
A2: Checklist Item | B2: Yes | C2: No | D2: Action required (link to appropriate action plan) | E2: Who | F2: When
A3: Do we have a clear understanding of the deliverables and schedule?
A4: Are we sure of the evaluation process to be used?
A5: Do we know the customer’s perception of us and competitors?
A6: Has an objective bidder comparison been completed?
A7: Do we have firm commitments from needed teammates?
A8: Do we have strong, relevant past performance (proof)?
A9: Will our management approach provide added value (impact)?
A10: Will our technical solution provide added value (impact)?
A11: Are our discriminators unique and important to the customer?
A12: Can the customer justify selecting us based on our discriminators and cost?
A13: Has a price to win been determined, and is it acceptable to management?
A14: Is the customer adhering to the expected buying schedule?
... A24: Other

Sheet Preliminary Bid Planning
A1: Preliminary Bid Planning and Content
A2: Preliminary Bid Organization/Planning (HOW) | D2: Additional Decision Gate Topics
D4: Overview of Opportunity
D5: Overview of Customer
D6: Teaming
D7: Bidder Comparison Chart
D8: Integrated Solution Worksheet
D9: Risks and Mitigation
A25: Preliminary Bid Content (WHAT) | D25: STATUS (link to appropriate pages)

Sheet 90-Day Action Plan Schedule
A1: Schedule: 90-Day Action Plan Schedule
A2: Monitoring progress on improving our position
A3: Task | B3: Who | C3: 1 | D3: =C3+1 -> 2 | E3: =D3+1 -> 3 | F3: =E3+1 -> 4 | G3: =F3+1 -> 5 | H3: =G3+1 -> 6 | I3: =H3+1 -> 7 | J3: =I3+1 -> 8 | K3: =J3+1 -> 9 | ... AG3: =AF3+1 -> 31 | AH3: 1 | AI3: =AH3+1 -> 2 | AJ3: =AI3+1 -> 3 | AK3: =AJ3+1 -> 4 | AL3: =AK3+1 -> 5 | AM3: =AL3+1 -> 6 | AN3: =AM3+1 -> 7 | AO3: =AN3+1 -> 8 | AP3: =AO3+1 -> 9 | ... BL3: =BK3+1 -> 31 | BM3: 1 | BN3: =BM3+1 -> 2 | BO3: =BN3+1 -> 3 | BP3: =BO3+1 -> 4 | BQ3: =BP3+1 -> 5 | BR3: =BQ3+1 -> 6 | BS3: =BR3+1 -> 7 | BT3: =BS3+1 -> 8 | BU3: =BT3+1 -> 9 | ... CQ3: =CP3+1 -> 31
