Workbook
Name inf: #REF!
Name TRM: 'Activity 2 Sub Budget'!$B$1
Name TRM: 'Agrosavia Sub Budget'!$B$1

Sheet Project Funds Snapshots
B2: FFPR Program Budget Summary Sheet
C3: Total USDA Project | D3: Direct $ | E3: Direct % | F3: Indirect Costs $
B5: OVERALL PROJECT BUDGET | C5: =C6+C7 -> 25487876 | D5: ='Program Budget'!W534-'Activity 2 Sub Budget'!P46-'CIAT Sub Budget'!P71-'CIAT Sub Budget'!P116-'CIAT Sub Budget'!P152-'Agrosavia Sub Budget'!P43 -> 18689315 | E5: =D5/$C$5 -> 0.73326294 | F5: ='Program Budget'!W536+'Activity 2 Sub Budget'!P46+'CIAT Sub Budget'!P71+'CIAT Sub Budget'!P116+'CIAT Sub Budget'!P152+'Agrosavia Sub Budget'!P43 -> 4820633
B6: USDA | C6: ='USDA Budget Summary'!B65+'USDA Budget Summary'!C65 -> 23509948
B7: Cost Share | C7: ='USDA Budget Summary'!D65 -> 1977928 | D7: ='USDA Budget Summary'!D36 -> 1977928.1 | E7: =D7/$C$5 -> 0.077602703 | F7: 0
C9: Total USDA Project | D9: Direct $ | E9: Direct % | F9: Indirect Costs $ | G9: Cost Share $ | H9: % of Direct Funds by Partner | K9: =C9 -> Total USDA Project
B11: BUDGET BY PARTNER | J11: TOTAL | K11: =SUM(K12:K16)*-1 -> 25487876
B12: Prime | C12: =C5-SUM(C13:C16) -> 21850530 | D12: =C12-F12-G12 -> 15455142 | E12: =D12/SUM($C$12:$C$16) -> 0.60637229 | F12: ='Indirect Calculations'!I72 -> 4572464.1 | G12: ='USDA Budget Summary'!D65-SUM(G13:G16) -> 1822924 | H12: =(G12+D12)/SUM($C$12:$C$16) -> 0.67789351 | J12: POA | K12: =-C12 -> -21850530
B13: Sub 1 - CIAT | C13: ='CIAT Sub Budget'!P156+G13 -> 1776970.4 | D13: ='CIAT Sub Budget'!P69+'CIAT Sub Budget'!P114+'CIAT Sub Budget'!P150 -> 1474514.9 | E13: =D13/SUM($C$12:$C$16) -> 0.057851619 | F13: ='CIAT Sub Budget'!P71+'CIAT Sub Budget'!P116+'CIAT Sub Budget'!P152 -> 147451.49 | G13: ='Program Budget'!X160+'Program Budget'!X260 -> 155004 | H13: =(G13+D13)/SUM($C$12:$C$16) -> 0.063933098 | J13: CIAT | K13: =-C13 -> -1776970.4
B14: Sub 2 - TBD | C14: ='Activity 2 Sub Budget'!P50 -> 1000773.2 | D14: ='Activity 2 Sub Budget'!P44 -> 909793.81 | E14: =D14/SUM($C$12:$C$16) -> 0.03569516 | F14: ='Activity 2 Sub Budget'!P46 -> 90979.381 | G14: ='Activity 2 Sub Budget'!Q50 -> 0 | H14: =(G14+D14)/SUM($C$12:$C$16) -> 0.03569516 | J14: TBD | K14: =-C14 -> -1000773.2
B15: Sub 3 - Agrosavia | C15: ='Agrosavia Sub Budget'!P47 -> 334340.21 | D15: ='Agrosavia Sub Budget'!P41 -> 324602.14 | E15: =D15/SUM($C$12:$C$16) -> 0.012735551 | F15: ='Agrosavia Sub Budget'!P43 -> 9738.0643 | G15: ='Agrosavia Sub Budget'!Q47 -> 0 | H15: =(G15+D15)/SUM($C$12:$C$16) -> 0.012735551 | J15: Agrosavia | K15: =-C15 -> -334340.21
B16: Monetization Agent | C16: ='Program Budget'!Y66 -> 525262.5 | D16: ='Program Budget'!Y66 -> 525262.5 | E16: =D16/SUM($C$12:$C$16) -> 0.020608328 | F16: 0 | G16: 0 | H16: =(G16+D16)/SUM($C$12:$C$16) -> 0.020608328 | J16: Monetization | K16: =-C16 -> -525262.5
C18: Total USDA Project | D18: Direct $ | E18: Direct % | F18: Indirect Costs $ | G18: Cost Share $ | H18: % of Direct Funds by Activity | K18: =C18 -> Total USDA Project
B20: BUDGET BY ACTIVITY | K20: =SUM(K21:K29)*-1 -> 25487876
B21: Admin | C21: ='USDA Budget Summary'!F25+'USDA Budget Summary'!E57 -> 6605294.3 | D21: ='USDA Budget Summary'!E25-'CIAT Sub Budget'!P71 -> 5040229.9 | E21: =D21/SUM($C$21:$C$29) -> 0.1977501 | F21: ='USDA Budget Summary'!E57+'CIAT Sub Budget'!P71 -> 1565064.4 | G21: ='USDA Budget Summary'!D25 -> 0 | H21: =(G21+D21)/SUM($C$21:$C$29) -> 0.1977501 | J21: =B21 -> Admin | K21: =C21*-1 -> -6605294.3
B22: Activity 1 | C22: ='USDA Budget Summary'!F28+('USDA Budget Summary'!E28*0.2869) -> 303709.1 | D22: ='USDA Budget Summary'!B28 -> 154064.11 | E22: =D22/SUM($C$21:$C$29) -> 0.0060446038 | F22: =D22*0.2869 -> 44200.994 | G22: ='Program Budget'!X163 -> 105444 | H22: =(G22+D22)/SUM($C$21:$C$29) -> 0.01018163 | J22: =B22 -> Activity 1 | K22: =C22*-1 -> -303709.1
B23: Activity 2 | C23: ='USDA Budget Summary'!F29+('USDA Budget Summary'!E29*0.2869) -> 2142038.8 | D23: ='USDA Budget Summary'!B29-'Activity 2 Sub Budget'!P46 -> 1493538.2 | E23: =D23/SUM($C$21:$C$29) -> 0.058597988 | F23: =('USDA Budget Summary'!B29*0.2869)+'Activity 2 Sub Budget'!P46 -> 545577.49 | G23: ='Program Budget'!X206 -> 102923.08 | H23: =(G23+D23)/SUM($C$21:$C$29) -> 0.062636107 | J23: =B23 -> Activity 2 | K23: =C23*-1 -> -2142038.8
B24: Activity 3 | C24: ='USDA Budget Summary'!F30+('USDA Budget Summary'!E30*0.2869) -> 5815755.9 | D24: ='USDA Budget Summary'!B30-'CIAT Sub Budget'!P116-'CIAT Sub Budget'!P152 -> 4344411.4 | E24: =D24/SUM($C$21:$C$29) -> 0.17045012 | F24: =('USDA Budget Summary'!B30*0.2869)+'CIAT Sub Budget'!P116+'CIAT Sub Budget'!P152 -> 1317144.5 | G24: ='Program Budget'!X265 -> 154200 | H24: =(G24+D24)/SUM($C$21:$C$29) -> 0.17650005 | J24: =B24 -> Activity 3 | K24: =C24*-1 -> -5815755.9
B25: Activity 4 | C25: ='USDA Budget Summary'!F31+('USDA Budget Summary'!E31*0.2869) -> 2209425.6 | D25: ='USDA Budget Summary'!B31-'Agrosavia Sub Budget'!P43 -> 1698961.6 | E25: =D25/SUM($C$21:$C$29) -> 0.066657638 | F25: ='USDA Budget Summary'!B31*0.2869+'Agrosavia Sub Budget'!P43 -> 499964 | G25: ='USDA Budget Summary'!D31 -> 10500 | H25: =(G25+D25)/SUM($C$21:$C$29) -> 0.067069598 | J25: =B25 -> Activity 4 | K25: =C25*-1 -> -2209425.6
B26: Activity 5 | C26: ='USDA Budget Summary'!F32+('USDA Budget Summary'!E32*0.2869) -> 1440644.1 | D26: ='USDA Budget Summary'!B32 -> 618622.73 | E26: =D26/SUM($C$21:$C$29) -> 0.024271255 | F26: =D26*0.2869 -> 177482.86 | G26: ='Program Budget'!X367 -> 644538.46 | H26: =(G26+D26)/SUM($C$21:$C$29) -> 0.049559296 | J26: =B26 -> Activity 5 | K26: =C26*-1 -> -1440644.1
B27: Activity 6 | C27: ='USDA Budget Summary'!F33+('USDA Budget Summary'!E33*0.2869) -> 2135277.4 | D27: ='USDA Budget Summary'!B33 -> 1146739.4 | E27: =D27/SUM($C$21:$C$29) -> 0.044991565 | F27: =D27*0.2869 -> 328999.54 | G27: ='Program Budget'!X433 -> 659538.46 | H27: =(G27+D27)/SUM($C$21:$C$29) -> 0.070868122 | J27: =B27 -> Activity 6 | K27: =C27*-1 -> -2135277.4
B28: Activity 7 | C28: ='USDA Budget Summary'!F34+('USDA Budget Summary'!E34*0.2869) -> 1052406.8 | D28: ='USDA Budget Summary'!B34 -> 813122.07 | E28: =D28/SUM($C$21:$C$29) -> 0.031902308 | F28: =D28*0.2869 -> 233284.72 | G28: ='Program Budget'!X479 -> 6000 | H28: =(G28+D28)/SUM($C$21:$C$29) -> 0.032137714 | J28: =B28 -> Activity 7 | K28: =C28*-1 -> -1052406.8
B29: Activity 8 | C29: ='USDA Budget Summary'!F35+(('USDA Budget Summary'!E35-3000000)*0.2869) -> 3783323.9 | D29: ='USDA Budget Summary'!B35 -> 3379625.3 | E29: =D29/SUM($C$21:$C$29) -> 0.13259737 | F29: =(D29-3000000)*0.2869 -> 108914.5 | G29: ='Program Budget'!X526 -> 294784.07 | H29: =(G29+D29)/SUM($C$21:$C$29) -> 0.14416303 | J29: =B29 -> Activity 8 | K29: =C29*-1 -> -3783323.9
C31: Total USDA Project | D31: Direct $ | E31: Direct % | F31: Indirect Costs $ | G31: Cost Share $ | H31: % of Direct Funds by Activity
B32: DIRECT COST DETAILS BY ACTIVITY & PARTNER
B33: =CONCATENATE(B21," - ",B12) -> Admin - Prime | C33: ='USDA Budget Summary'!E25+'USDA Budget Summary'!E57-C34-C35 -> 5062667 | D33: ='USDA Budget Summary'!E25-D34-D35-F34-F35 -> 3590090.4 | E33: =D33/SUM($C$33:$C$46) -> 0.14085483 | F33: ='Indirect Calculations'!I46 -> 1472576.7 | G33: ='USDA Budget Summary'!D25 -> 0 | H33: =(G33+D33)/SUM($C$33:$C$46) -> 0.14085483
B34: Admin - Sub 1 - CIAT | C34: ='CIAT Sub Budget'!P73 -> 1017364.7 | D34: ='CIAT Sub Budget'!P69 -> 924877.04 | E34: =D34/SUM($C$33:$C$46) -> 0.036286941 | F34: ='CIAT Sub Budget'!P71 -> 92487.704 | G34: 0 | H34: =(G34+D34)/SUM($C$33:$C$46) -> 0.036286941
B35: =CONCATENATE(B21," - ",B16) -> Admin - Monetization Agent | C35: ='Program Budget'!Y66 -> 525262.5 | D35: ='Program Budget'!Y66 -> 525262.5 | E35: =D35/SUM($C$33:$C$46) -> 0.020608328 | F35: 0 | G35: 0 | H35: =(G35+D35)/SUM($C$33:$C$46) -> 0.020608328
B36: =CONCATENATE(B22," - ",B12) -> Activity 1 - Prime | C36: =('USDA Budget Summary'!F28+('USDA Budget Summary'!B28*0.2869)) -> 303709.1 | D36: ='USDA Budget Summary'!B28 -> 154064.11 | E36: =D36/SUM($C$33:$C$46) -> 0.0060446038 | F36: ='USDA Budget Summary'!B28*0.2869 -> 44200.994 | G36: ='Program Budget'!X163 -> 105444 | H36: =(G36+D36)/SUM($C$33:$C$46) -> 0.01018163
B37: =CONCATENATE(B23," - ",B12) -> Activity 2 - Prime | C37: ='USDA Budget Summary'!F29+('USDA Budget Summary'!B29*0.2869)-C38 -> 1141265.6 | D37: ='USDA Budget Summary'!B29-D38-F38 -> 583744.42 | E37: =D37/SUM($C$33:$C$46) -> 0.022902827 | F37: ='USDA Budget Summary'!B29*0.2869 -> 454598.1 | G37: ='Program Budget'!X206 -> 102923.08 | H37: =(G37+D37)/SUM($C$33:$C$46) -> 0.026940946
B38: Activity 2 - Sub 1 - TBD | C38: ='Activity 2 Sub Budget'!P48 -> 1000773.2 | D38: ='Activity 2 Sub Budget'!P44 -> 909793.81 | E38: =D38/SUM($C$33:$C$46) -> 0.03569516 | F38: ='Activity 2 Sub Budget'!P46 -> 90979.381 | G38: ='Activity 2 Sub Budget'!Q48 -> 0 | H38: =(G38+D38)/SUM($C$33:$C$46) -> 0.03569516
B39: =CONCATENATE(B24," - ",B12) -> Activity 3 - Prime | C39: =('USDA Budget Summary'!F30+('USDA Budget Summary'!B30*0.2869))-C40 -> 5151154.3 | D39: ='USDA Budget Summary'!B30-'Project Funds Snapshots'!D40-'Project Funds Snapshots'!F40 -> 3794773.6 | E39: =D39/SUM($C$33:$C$46) -> 0.14888544 | F39: ='USDA Budget Summary'!B30*0.2869 -> 1262180.7 | G39: ='Program Budget'!X265-G40 -> 94200 | H39: =(G39+D39)/SUM($C$33:$C$46) -> 0.15258131
B40: Activity 3 - Sub 1 - CIAT | C40: ='CIAT Sub Budget'!P118+'CIAT Sub Budget'!P154+'Program Budget'!X260 -> 664601.62 | D40: ='CIAT Sub Budget'!P150+'CIAT Sub Budget'!P114 -> 549637.84 | E40: =D40/SUM($C$33:$C$46) -> 0.021564678 | F40: ='CIAT Sub Budget'!P116+'CIAT Sub Budget'!P152 -> 54963.784 | G40: ='Program Budget'!X260 -> 60000 | H40: =(G40+D40)/SUM($C$33:$C$46) -> 0.023918738
B41: =CONCATENATE(B25," - ",B12) -> Activity 4 - Prime | C41: ='USDA Budget Summary'!F31+('USDA Budget Summary'!B31*0.2869)-C42 -> 1875085.4 | D41: ='USDA Budget Summary'!B31-D42-F42 -> 1374359.5 | E41: =D41/SUM($C$33:$C$46) -> 0.053922087 | F41: ='USDA Budget Summary'!B31*0.2869 -> 490225.93 | G41: ='Program Budget'!X313 -> 10500 | H41: =(G41+D41)/SUM($C$33:$C$46) -> 0.054334047
B42: Activity 4 - Sub 1 - Agrosavia | C42: ='Agrosavia Sub Budget'!P45 -> 334340.21 | D42: ='Agrosavia Sub Budget'!P41 -> 324602.14 | E42: =D42/SUM($C$33:$C$46) -> 0.012735551 | F42: ='Agrosavia Sub Budget'!P43 -> 9738.0643 | G42: ='Agrosavia Sub Budget'!Q45 -> 0 | H42: =(G42+D42)/SUM($C$33:$C$46) -> 0.012735551
B43: =CONCATENATE(B26," - ",B12) -> Activity 5 - Prime | C43: ='USDA Budget Summary'!F32+('USDA Budget Summary'!B32*0.2869) -> 1440644.1 | D43: ='USDA Budget Summary'!B32 -> 618622.73 | E43: =D43/SUM($C$33:$C$46) -> 0.024271255 | F43: =D43*0.2869 -> 177482.86 | G43: ='Program Budget'!X367 -> 644538.46 | H43: =(G43+D43)/SUM($C$33:$C$46) -> 0.049559296
B44: =CONCATENATE(B27," - ",B12) -> Activity 6 - Prime | C44: ='USDA Budget Summary'!F33+('USDA Budget Summary'!B33*0.2869) -> 2135277.4 | D44: ='USDA Budget Summary'!B33 -> 1146739.4 | E44: =D44/SUM($C$33:$C$46) -> 0.044991565 | F44: =D44*0.2869 -> 328999.54 | G44: ='Program Budget'!X433 -> 659538.46 | H44: =(G44+D44)/SUM($C$33:$C$46) -> 0.070868122
B45: =CONCATENATE(B28," - ",B12) -> Activity 7 - Prime | C45: ='USDA Budget Summary'!F34+('USDA Budget Summary'!B34*0.2869) -> 1052406.8 | D45: ='USDA Budget Summary'!B34 -> 813122.07 | E45: =D45/SUM($C$33:$C$46) -> 0.031902308 | F45: =D45*0.2869 -> 233284.72 | G45: ='Program Budget'!X479 -> 6000 | H45: =(G45+D45)/SUM($C$33:$C$46) -> 0.032137714
B46: =CONCATENATE(B29," - ",B12) -> Activity 8 - Prime | C46: ='USDA Budget Summary'!F35+(('USDA Budget Summary'!B35-3000000)*0.2869) -> 3783323.9 | D46: ='USDA Budget Summary'!B35 -> 3379625.3 | E46: =D46/SUM($C$33:$C$46) -> 0.13259737 | F46: =(D46-3000000)*0.2869 -> 108914.5 | G46: ='Program Budget'!X526 -> 294784.07 | H46: =(G46+D46)/SUM($C$33:$C$46) -> 0.14416303
C48: Total USDA Project | D48: Direct $ | E48: Direct % | F48: Indirect Costs $ | G48: Cost Share $ | H48: % of Direct Funds by Activity | L48: Column Labels
...

Sheet USDA Budget Summary
A1: ATTACHMENT C -1
A2: Proposed Budget Summary
A4: Program (FFPr or MGD): | B4: FFPr
A5: Country of Operation: | B5: Colombia
A6: Implementing Organization: | B6: Partners of the Americas Inc.
A7: Fiscal Year: | B7: 2020
A8: Agreement Number: | B8: USDA-FAS-10.606-0700-20-(514)
A10: Total Amount of Federal Funds Requested
A11: Funding Source (FAS for MGD) (CCC for FFPr) | B11: Funding Year | C11: Commodity Cost | D11: Freight Cost | E11: Administrative Costs (cash portion) | F11: Total Federal Funding Obligated
B12: 2020 | C12: 21924000 | D12: 9591750 | E12: 2280000 | F12: =E12+D12+C12 -> 33795750
A14: Project Operating Budget
A15: Expense Type | B15: Monetization Proceeds (FFPr Only) | C15: FAS or CCC Funds (CCC is Admin Only) | D15: Cost Share | E15: Total w/out Cost Share | F15: Total w/Cost Share
A16: Administration
A17: Salaries/Personnel | B17: ='Program Budget'!W32-C17 -> 843769.36 | C17: 430000 | D17: ='Program Budget'!X32 -> 0 | E17: =B17+C17 -> 1273769.4 | F17: =B17+C17+D17 -> 1273769.4
A18: Benefits | B18: ='Program Budget'!W44-C18 -> 499261.89 | C18: 225648 | D18: ='Program Budget'!X44 -> 0 | E18: =B18+C18 -> 724909.89 | F18: =B18+C18+D18 -> 724909.89
A19: Travel | B19: ='Program Budget'!W61-C19 -> 116709.46 | C19: 39104 | D19: ='Program Budget'!X61 -> 0 | E19: =B19+C19 -> 155813.46 | F19: =B19+C19+D19 -> 155813.46
A20: Professional Services/Contractual | B20: ='Program Budget'!W84-C20 -> 1619480 | C20: 862147.25 | D20: ='Program Budget'!X84 -> 0 | E20: =B20+C20 -> 2481627.2 | F20: =B20+C20+D20 -> 2481627.2
A21: Equipment | B21: ='Program Budget'!W89-C21 -> 0 | C21: 100000 | D21: ='Program Budget'!X89 -> 0 | E21: =B21+C21 -> 100000 | F21: =B21+C21+D21 -> 100000
A22: Office | B22: ='Program Budget'!W102-C22 -> 168021.71 | C22: 53944 | D22: ='Program Budget'!X102 -> 0 | E22: =B22+C22 -> 221965.71 | F22: =B22+C22+D22 -> 221965.71
A23: Supplies | B23: ='Program Budget'!W113-C23 -> 45495.646 | C23: 41096 | D23: ='Program Budget'!X113 -> 0 | E23: =B23+C23 -> 86591.646 | F23: =B23+C23+D23 -> 86591.646
A24: Other | B24: ='Program Budget'!W125-C24 -> 68280.29 | C24: ='Program Budget'!M125 -> 19760 | D24: 0 | E24: =B24+C24 -> 88040.29 | F24: =B24+C24+D24 -> 88040.29
A25: Total Administration | B25: =SUM(B17:B24) -> 3361018.4 | C25: =SUM(C17:C24) -> 1771699.2 | D25: =SUM(D17:D24) -> 0 | E25: =SUM(E17:E24) -> 5132717.6 | F25: =SUM(F17:F24) -> 5132717.6
A27: Activities
A28: Activity 1: Value Chain Development (Value Chain Analysis, Carbon Assessment, and Living Incomes) | B28: ='Program Budget'!W163 -> 154064.11 | C28: 0 | D28: ='Program Budget'!X163 -> 105444 | E28: =B28+C28 -> 154064.11 | F28: =B28+C28+D28 -> 259508.11 | G28: =B28/$B$36 -> 0.011160212
A29: Activity 2: Producer Organization Development & Commercialization | B29: ='Program Budget'!W206 -> 1584517.6 | C29: 0 | D29: ='Program Budget'!X206 -> 102923.08 | E29: =B29+C29 -> 1584517.6 | F29: =B29+C29+D29 -> 1687440.7 | G29: =B29/$B$36 -> 0.11478048
A30: Activity 3: Agriculture Extension and Production Support | B30: ='Program Budget'!W265 -> 4399375.2 | C30: 0 | D30: =ROUND('Program Budget'!X265,0) -> 154200 | E30: =B30+C30 -> 4399375.2 | F30: =B30+C30+D30 -> 4553575.2 | G30: =B30/$B$36 -> 0.31868524
A31: Activity 4: Post-Harvest Aggregation & Processing | B31: ='Program Budget'!W313 -> 1708699.7 | C31: 0 | D31: ='Program Budget'!X313 -> 10500 | E31: =B31+C31 -> 1708699.7 | F31: =B31+C31+D31 -> 1719199.7 | G31: =B31/$B$36 -> 0.12377607
A32: Activity 5: Ensure Financial Service/ Capital Access for Actors in the Value Chains | B32: ='Program Budget'!W367 -> 618622.73 | C32: 0 | D32: ='Program Budget'!X367 -> 644538.46 | E32: =B32+C32 -> 618622.73 | F32: =B32+C32+D32 -> 1263161.2 | G32: =B32/$B$36 -> 0.044812257
A33: Activity 6: Innovation and Job Creation Through Youth Engagement | B33: ='Program Budget'!W433 -> 1146739.4 | C33: 0 | D33: ='Program Budget'!X433 -> 659538.46 | E33: =B33+C33 -> 1146739.4 | F33: =B33+C33+D33 -> 1806277.9 | G33: =B33/$B$36 -> 0.08306837
A34: Activity 7: Establishment of Regional Community of Practice | B34: ='Program Budget'!W479 -> 813122.07 | C34: 0 | D34: ='Program Budget'!X479 -> 6000 | E34: =B34+C34 -> 813122.07 | F34: =B34+C34+D34 -> 819122.07 | G34: =B34/$B$36 -> 0.058901546
A35: Activity 8: Financial Services: Endowment Establishment, Fundraising and Management | B35: ='Program Budget'!W526 -> 3379625.3 | C35: 0 | D35: ='Program Budget'!X526 -> 294784.07 | E35: =B35+C35 -> 3379625.3 | F35: =B35+C35+D35 -> 3674409.4 | G35: =B35/$B$36 -> 0.24481583
A36: Total Activities | B36: =SUM(B28:B35) -> 13804766 | C36: =SUM(C28:C35) -> 0 | D36: =SUM(D28:D35) -> 1977928.1 | E36: =SUM(E28:E35) -> 13804766 | F36: =SUM(F28:F35) -> 15782694 | G36: =B36/$B$36 -> 1
A38: Commodity and Food Purchases (N/A to FFPr)
A39: Commodity Procurement | B39: 0 | C39: 0 | D39: 0 | E39: =B39+C39 -> 0 | F39: =B39+C39+D39 -> 0
A40: Food Vouchers (N/A to MGD)
A41: Cash Transfers (N/A to MGD)
A42: Total Commodity Procurement | B42: =SUM(B39:B41) -> 0 | C42: =SUM(C39:C41) -> 0 | D42: =SUM(D39:D41) -> 0 | E42: =SUM(E39:E41) -> 0 | F42: =SUM(F39:F41) -> 0
A44: ITSH (N/A to FFPr)
A45: Salaries | B45: 0 | C45: 0 | D45: 0 | E45: =B45+C45 -> 0 | F45: =B45+C45+D45 -> 0
A46: Benefits | B46: 0 | C46: 0 | D46: 0 | E46: =B46+C46 -> 0 | F46: =B46+C46+D46 -> 0
...

Sheet Indirect Calculations
B1: Partners of the Americas – FY 2020 FFPr Colombia
B2: NOFO: USDA-FAS-10.606-0700-20-(514)
B3: Duration: 5 Years
B4: Country: Colombia
B5: Summary of Indirect Cost Rates Applied
B7: BUDGET ITEM | C7: RATE/ UNIT | D7: YEAR 1 | E7: YEAR 2 | F7: YEAR 3 | G7: YEAR 4 | H7: YEAR 5 | I7: TOTAL USDA
B8: Administration Salaries/Personnel
B9: CCN Colombia National Staff (LOE)
B10: Key Personnel: Expat Chief of Party | C10: =141500/12 -> 11791.667 | D10: =#REF!*C10*#REF! -> #REF! | E10: =#REF!*C10*#REF!*#REF! -> #REF! | F10: =#REF!*C10*#REF!*#REF!*#REF! -> #REF! | G10: =#REF!*C10*#REF!*#REF!*#REF!*#REF! -> #REF! | H10: =#REF!*C10*#REF!*#REF!*#REF!*#REF!*#REF! -> #REF! | I10: =SUM(G10,F10,E10,D10,H10) -> #REF!
B11: Key Personnel: Deputy Chief of Party | C11: =110000/12 -> 9166.6667 | D11: =#REF!*C11*#REF! -> #REF! | E11: =#REF!*C11*#REF!*#REF! -> #REF! | F11: =#REF!*C11*#REF!*#REF!*#REF! -> #REF! | G11: =#REF!*C11*#REF!*#REF!*#REF!*#REF! -> #REF! | H11: =#REF!*C11*#REF!*#REF!*#REF!*#REF!*#REF! -> #REF! | I11: =SUM(G11,F11,E11,D11,H11) -> #REF!
B12: F&A Director | C12: =39000/12 -> 3250 | D12: =#REF!*C12*#REF! -> #REF! | E12: =#REF!*C12*#REF!*#REF! -> #REF! | F12: =#REF!*C12*#REF!*#REF!*#REF! -> #REF! | G12: =#REF!*C12*#REF!*#REF!*#REF!*#REF! -> #REF! | H12: =#REF!*C12*#REF!*#REF!*#REF!*#REF!*#REF! -> #REF! | I12: =SUM(G12,F12,E12,D12,H12) -> #REF!
B13: M&E Director | C13: =39000/12 -> 3250 | D13: =#REF!*C13*#REF! -> #REF! | E13: =#REF!*C13*#REF!*#REF! -> #REF! | F13: =#REF!*C13*#REF!*#REF!*#REF! -> #REF! | G13: =#REF!*C13*#REF!*#REF!*#REF!*#REF! -> #REF! | H13: =#REF!*C13*#REF!*#REF!*#REF!*#REF!*#REF! -> #REF! | I13: =SUM(G13,F13,E13,D13,H13) -> #REF!
B14: M&E Specialists | C14: =22000/12 -> 1833.3333 | D14: =#REF!*C14*#REF! -> #REF! | E14: =#REF!*C14*#REF!*#REF! -> #REF! | F14: =#REF!*C14*#REF!*#REF!*#REF! -> #REF! | G14: =#REF!*C14*#REF!*#REF!*#REF!*#REF! -> #REF! | H14: =#REF!*C14*#REF!*#REF!*#REF!*#REF!*#REF! -> #REF! | I14: =SUM(G14,F14,E14,D14,H14) -> #REF!
B15: M&E Specialists | C15: =22000/12 -> 1833.3333 | D15: =#REF!*C15*#REF! -> #REF! | E15: =#REF!*C15*#REF!*#REF! -> #REF! | F15: =#REF!*C15*#REF!*#REF!*#REF! -> #REF! | G15: =#REF!*C15*#REF!*#REF!*#REF!*#REF! -> #REF! | H15: =#REF!*C15*#REF!*#REF!*#REF!*#REF!*#REF! -> #REF! | I15: =SUM(G15,F15,E15,D15,H15) -> #REF!
B16: Activity Lead RCP Manager | C16: =22000/12 -> 1833.3333 | D16: =#REF!*C16*#REF! -> #REF! | E16: =#REF!*C16*#REF!*#REF! -> #REF! | F16: =#REF!*C16*#REF!*#REF!*#REF! -> #REF! | G16: =#REF!*C16*#REF!*#REF!*#REF!*#REF! -> #REF! | H16: =#REF!*C16*#REF!*#REF!*#REF!*#REF!*#REF! -> #REF! | I16: =SUM(G16,F16,E16,D16,H16) -> #REF!
B17: Activity Lead RCP Manager | C17: =18000/12 -> 1500 | D17: =#REF!*C17*#REF! -> #REF! | E17: =#REF!*C17*#REF!*#REF! -> #REF! | F17: =#REF!*C17*#REF!*#REF!*#REF! -> #REF! | G17: =#REF!*C17*#REF!*#REF!*#REF!*#REF! -> #REF! | H17: =#REF!*C17*#REF!*#REF!*#REF!*#REF!*#REF! -> #REF! | I17: =SUM(G17,F17,E17,D17,H17) -> #REF!
B18: Activity Lead Agribusiness Specialist | C18: =22000/12 -> 1833.3333 | D18: =#REF!*C18*#REF! -> #REF! | E18: =#REF!*C18*#REF!*#REF! -> #REF! | F18: =#REF!*C18*#REF!*#REF!*#REF! -> #REF! | G18: =#REF!*C18*#REF!*#REF!*#REF!*#REF! -> #REF! | H18: =#REF!*C18*#REF!*#REF!*#REF!*#REF!*#REF! -> #REF! | I18: =SUM(G18,F18,E18,D18,H18) -> #REF!
B19: Activity Lead Agribusiness Specialist | C19: =22000/12 -> 1833.3333 | D19: =#REF!*C19*#REF! -> #REF! | E19: =#REF!*C19*#REF!*#REF! -> #REF! | F19: =#REF!*C19*#REF!*#REF!*#REF! -> #REF! | G19: =#REF!*C19*#REF!*#REF!*#REF!*#REF! -> #REF! | H19: =#REF!*C19*#REF!*#REF!*#REF!*#REF!*#REF! -> #REF! | I19: =SUM(G19,F19,E19,D19,H19) -> #REF!
B20: Activity Lead Agribusiness Specialist | C20: =18000/12 -> 1500 | D20: =#REF!*C20*#REF! -> #REF! | E20: =#REF!*C20*#REF!*#REF! -> #REF! | F20: =#REF!*C20*#REF!*#REF!*#REF! -> #REF! | G20: =#REF!*C20*#REF!*#REF!*#REF!*#REF! -> #REF! | H20: =#REF!*C20*#REF!*#REF!*#REF!*#REF!*#REF! -> #REF! | I20: =SUM(G20,F20,E20,D20,H20) -> #REF!
B21: Activity Lead Agribusiness Specialist | C21: =18000/12 -> 1500 | D21: =#REF!*C21*#REF! -> #REF! | E21: =#REF!*C21*#REF!*#REF! -> #REF! | F21: =#REF!*C21*#REF!*#REF!*#REF! -> #REF! | G21: =#REF!*C21*#REF!*#REF!*#REF!*#REF! -> #REF! | H21: =#REF!*C21*#REF!*#REF!*#REF!*#REF!*#REF! -> #REF! | I21: =SUM(G21,F21,E21,D21,H21) -> #REF!
B22: Compliance Officer | C22: =22000/12 -> 1833.3333 | D22: =#REF!*C22*#REF! -> #REF! | E22: =#REF!*C22*#REF!*#REF! -> #REF! | F22: =#REF!*C22*#REF!*#REF!*#REF! -> #REF! | G22: =#REF!*C22*#REF!*#REF!*#REF!*#REF! -> #REF! | H22: =#REF!*C22*#REF!*#REF!*#REF!*#REF!*#REF! -> #REF! | I22: =SUM(G22,F22,E22,D22,H22) -> #REF!
B23: Accountant | C23: =18000/12 -> 1500 | D23: =#REF!*C23*#REF! -> #REF! | E23: =#REF!*C23*#REF!*#REF! -> #REF! | F23: =#REF!*C23*#REF!*#REF!*#REF! -> #REF! | G23: =#REF!*C23*#REF!*#REF!*#REF!*#REF! -> #REF! | H23: =#REF!*C23*#REF!*#REF!*#REF!*#REF!*#REF! -> #REF! | I23: =SUM(G23,F23,E23,D23,H23) -> #REF!
B24: Administrative Assistant | C24: =15000/12 -> 1250 | D24: =#REF!*C24*#REF! -> #REF! | E24: =#REF!*C24*#REF!*#REF! -> #REF! | F24: =#REF!*C24*#REF!*#REF!*#REF! -> #REF! | G24: =#REF!*C24*#REF!*#REF!*#REF!*#REF! -> #REF! | H24: =#REF!*C24*#REF!*#REF!*#REF!*#REF!*#REF! -> #REF! | I24: =SUM(G24,F24,E24,D24,H24) -> #REF!
B26: Home Office Support (LOE)
B27: HQ Senior Program Officer | C27: =55000/12 -> 4583.3333 | D27: =#REF!*C27*#REF! -> #REF! | E27: =#REF!*C27*#REF!*#REF! -> #REF! | F27: =#REF!*C27*#REF!*#REF!*#REF! -> #REF! | G27: =#REF!*C27*#REF!*#REF!*#REF!*#REF! -> #REF! | H27: =#REF!*C27*#REF!*#REF!*#REF!*#REF!*#REF! -> #REF! | I27: =SUM(G27,F27,E27,D27,H27) -> #REF!
B29: Total Personnel | D29: ='Program Budget'!J32 -> 188172.22 | E29: ='Program Budget'!M32 -> 268458.67 | F29: ='Program Budget'!P32 -> 279197.01 | G29: ='Program Budget'!S32 -> 267080.21 | H29: ='Program Budget'!V32 -> 270861.25 | I29: =SUM(D29:H29) -> 1273769.4
B30: Administration Fringe Benefits
B31: Total Fringe Benefits | D31: ='Program Budget'!J44 -> 112358.33 | E31: ='Program Budget'!M44 -> 144568.98 | F31: ='Program Budget'!P44 -> 150026.26 | G31: ='Program Budget'!S44 -> 143150 | H31: ='Program Budget'!V44 -> 174806.32 | I31: =SUM(D31:H31) -> 724909.89
B32: Administration Travel
B33: Total Travel | D33: ='Program Budget'!J61 -> 20120 | E33: ='Program Budget'!M61 -> 32458.8 | F33: ='Program Budget'!P61 -> 33639.732 | G33: ='Program Budget'!S61 -> 34864.379 | H33: ='Program Budget'!V61 -> 34730.553 | I33: =SUM(D33:H33) -> 155813.46
B34: Administration Professional Services/Contractual
B35: Total Professional Services/Contractual | D35: ='Program Budget'!J84 -> 1570061.2 | E35: ='Program Budget'!M84 -> 385066.02 | F35: ='Program Budget'!P84 -> 245500 | G35: ='Program Budget'!S84 -> 60500 | H35: ='Program Budget'!V84 -> 220500 | I35: =SUM(D35:H35) -> 2481627.2
B36: Administration Equipment
B37: Total Equipment | D37: ='Program Budget'!J89 -> 100000 | E37: ='Program Budget'!M89 -> 0 | F37: ='Program Budget'!P89 -> 0 | G37: ='Program Budget'!S89 -> 0 | H37: ='Program Budget'!V89 -> 0 | I37: =SUM(D37:H37) -> 100000
B38: Administration Office Expenses
B39: Total Office Expenses | D39: ='Program Budget'!J102 -> 13910.8 | E39: ='Program Budget'!M102 -> 56400.032 | F39: ='Program Budget'!P102 -> 58656.033 | G39: ='Program Budget'!S102 -> 61002.275 | H39: ='Program Budget'!V102 -> 31996.568 | I39: =SUM(D39:H39) -> 221965.71
B40: Administration Office Supplies
B41: Total Office Supplies | D41: ='Program Budget'!J113 -> 72798.63 | E41: ='Program Budget'!M113 -> 3744 | F41: ='Program Budget'!P113 -> 3893.76 | G41: ='Program Budget'!S113 -> 4049.5104 | H41: ='Program Budget'!V113 -> 2105.7454 | I41: =SUM(D41:H41) -> 86591.646
B42: Administration Other
B43: Total Other | D43: ='Program Budget'!J125 -> 13525 | E43: ='Program Budget'!M125 -> 19760 | F43: ='Program Budget'!P125 -> 19926.4 | G43: ='Program Budget'!S125 -> 20099.456 | H43: ='Program Budget'!V125 -> 14729.434 | I43: =SUM(D43:H43) -> 88040.29
...

Sheet Program Budget
E1: Partners of the Americas – FY 2020 FFPr Colombia
E2: NOFO: USDA-FAS-10.606-0700-20-(514)
E3: Duration: 5 Years
E4: Country: Colombia
E5: Budget Assumptions:
A6: Entity: | B6: P | E6: Inflation - US Based Goods/Services | F6: 1.03
A7: Program-Dept.: | B7: FTF | E7: Inflation - Locally Purchased Goods/Services | F7: 1.04
A8: Funder-Grant: | B8: USDA700 | E8: Merit Based Increases for HQ & Field Staff | F8: 1.04
A10: Activity (Budget Code) | B10: Account Code | C10: Country Code (USA or COL2) | D10: Subcontract Code | E10: BUDGET ITEM | F10: Level of Effort (LOE) Year 1 | G10: UNIT | H10: # of Units | I10: RATE/ UNIT | J10: YEAR 1 | K10: Level of Effort (LOE) Year 2 | L10: # of Units | M10: YEAR 2 | N10: Level of Effort (LOE) Year 3 | O10: # of Units | P10: YEAR 3 | Q10: Level of Effort (LOE) Year 4 | R10: # of Units | S10: YEAR 4 | T10: Level of Effort (LOE) Year 5 | U10: # of Units | V10: YEAR 5 | W10: TOTAL USDA | X10: TOTAL COST SHARE | Y10: PROJECT GRAND TOTAL | AA10: Cacao Focus | AB10: Complementary Crop Focus
E11: Salaries/Personnel (Administration)
E12: CCN Colombia National Field Staff (LOE) | AA12: Cacao Focus | AB12: Complementary Crop Focus
A13: PERSNL | B13: 50000 | C13: USA | D13: 0 | E13: Key Personnel: Chief of Party | F13: ='LOE Breakdown by Year'!D11 -> 0.15 | G13: Month | H13: 12 | I13: =150000/12 -> 12500 | J13: =H13*I13*F13 -> 22500 | K13: ='LOE Breakdown by Year'!D35 -> 0.1 | L13: 12 | M13: =L13*I13*$F$8*$K13 -> 15600 | N13: ='LOE Breakdown by Year'!D59 -> 0.1 | O13: 12 | P13: =O13*I13*$N13*$F$8*$F$8 -> 16224 | Q13: ='LOE Breakdown by Year'!D83 -> 0.1 | R13: 12 | S13: =R13*I13*$Q13*$F$8*$F$8*$F$8 -> 16872.96 | T13: ='LOE Breakdown by Year'!D107 -> 0.1 | U13: 12 | V13: =U13*I13*$T13*$F$8*$F$8*$F$8*$F$8 -> 17547.878 | W13: =SUM(S13,P13,M13,J13,V13) -> 88744.838 | X13: 0 | Y13: =SUM(W13:X13) -> 88744.838 | AA13: 0.5 | AB13: 0.5
A14: PERSNL | B14: 70000 | C14: COL2 | D14: 0 | E14: Key Personnel: Technical Director | F14: ='LOE Breakdown by Year'!D12 -> 0.1 | G14: Month | H14: 8 | I14: =70000/12 -> 5833.3333 | J14: =H14*I14*F14 -> 4666.6667 | K14: ='LOE Breakdown by Year'!D36 -> 0.1 | L14: 12 | M14: =L14*I14*$F$8*$K14 -> 7280 | N14: ='LOE Breakdown by Year'!D60 -> 0.1 | O14: 12 | P14: =O14*I14*$N14*$F$8*$F$8 -> 7571.2 | Q14: ='LOE Breakdown by Year'!D84 -> 0.1 | R14: 12 | S14: =R14*I14*$Q14*$F$8*$F$8*$F$8 -> 7874.048 | T14: ='LOE Breakdown by Year'!D108 -> 0.1 | U14: 12 | V14: =U14*I14*$T14*$F$8*$F$8*$F$8*$F$8 -> 8189.0099 | W14: =SUM(S14,P14,M14,J14,V14) -> 35580.925 | X14: 0 | Y14: =SUM(W14:X14) -> 35580.925 | AA14: 0.5 | AB14: 0.5
A15: PERSNL | B15: 70000 | C15: COL2 | D15: 0 | E15: F&A Director | F15: ='LOE Breakdown by Year'!D13 -> 1 | G15: Month | H15: 8 | I15: =46000/12 -> 3833.3333 | J15: =H15*I15*F15 -> 30666.667 | K15: ='LOE Breakdown by Year'!D37 -> 0.95 | L15: 12 | M15: =L15*I15*$F$8*$K15 -> 45448 | N15: ='LOE Breakdown by Year'!D61 -> 0.95 | O15: 12 | P15: =O15*I15*$N15*$F$8*$F$8 -> 47265.92 | Q15: ='LOE Breakdown by Year'!D85 -> 0.5 | R15: 12 | S15: =R15*I15*$Q15*$F$8*$F$8*$F$8 -> 25871.872 | T15: ='LOE Breakdown by Year'!D109 -> 0.75 | U15: 12 | V15: =U15*I15*$T15*$F$8*$F$8*$F$8*$F$8 -> 40360.12 | W15: =SUM(S15,P15,M15,J15,V15) -> 189612.58 | X15: 0 | Y15: =SUM(W15:X15) -> 189612.58 | AA15: 0.5 | AB15: 0.5
A16: PERSNL | B16: 70000 | C16: COL2 | D16: 0 | E16: M&E Director | F16: ='LOE Breakdown by Year'!D14 -> 0.25 | G16: Month | H16: 8 | I16: =46000/12 -> 3833.3333 | J16: =H16*I16*F16 -> 7666.6667 | K16: ='LOE Breakdown by Year'!D38 -> 0.25 | L16: 12 | M16: =L16*I16*$F$8*$K16 -> 11960 | N16: ='LOE Breakdown by Year'!D62 -> 0.25 | O16: 12 | P16: =O16*I16*$N16*$F$8*$F$8 -> 12438.4 | Q16: ='LOE Breakdown by Year'!D86 -> 0.25 | R16: 12 | S16: =R16*I16*$Q16*$F$8*$F$8*$F$8 -> 12935.936 | T16: ='LOE Breakdown by Year'!D110 -> 0.25 | U16: 12 | V16: =U16*I16*$T16*$F$8*$F$8*$F$8*$F$8 -> 13453.373 | W16: =SUM(S16,P16,M16,J16,V16) -> 58454.376 | X16: 0 | Y16: =SUM(W16:X16) -> 58454.376 | AA16: 0.5 | AB16: 0.5
A17: PERSNL | B17: 70000 | C17: COL2 | D17: 0 | E17: M&E Mid-level Specialist | F17: ='LOE Breakdown by Year'!D15 -> 0.25 | G17: Month | H17: 7 | I17: =32000/12 -> 2666.6667 | J17: =H17*I17*F17 -> 4666.6667 | K17: ='LOE Breakdown by Year'!D39 -> 0.25 | L17: 12 | M17: =L17*I17*$F$8*$K17 -> 8320 | N17: ='LOE Breakdown by Year'!D63 -> 0.25 | O17: 12 | P17: =O17*I17*$N17*$F$8*$F$8 -> 8652.8 | Q17: ='LOE Breakdown by Year'!D87 -> 0.25 | R17: 12 | S17: =R17*I17*$Q17*$F$8*$F$8*$F$8 -> 8998.912 | T17: ='LOE Breakdown by Year'!D111 -> 0.25 | U17: 9 | V17: =U17*I17*$T17*$F$8*$F$8*$F$8*$F$8 -> 7019.1514 | W17: =SUM(S17,P17,M17,J17,V17) -> 37657.53 | X17: 0 | Y17: =SUM(W17:X17) -> 37657.53 | AA17: 0.5 | AB17: 0.5
A18: PERSNL | B18: 70000 | C18: COL2 | D18: 0 | E18: M&E Specialist | F18: ='LOE Breakdown by Year'!D16 -> 0.25 | G18: Month | H18: 3 | I18: =26000/12 -> 2166.6667 | J18: =H18*I18*F18 -> 1625 | K18: ='LOE Breakdown by Year'!D40 -> 0.25 | L18: 12 | M18: =L18*I18*$F$8*$K18 -> 6760 | N18: ='LOE Breakdown by Year'!D64 -> 0.25 | O18: 12 | P18: =O18*I18*$N18*$F$8*$F$8 -> 7030.4 | Q18: ='LOE Breakdown by Year'!D88 -> 0.25 | R18: 12 | S18: =R18*I18*$Q18*$F$8*$F$8*$F$8 -> 7311.616 | T18: ='LOE Breakdown by Year'!D112 -> 0.25 | U18: 9 | V18: =U18*I18*$T18*$F$8*$F$8*$F$8*$F$8 -> 5703.0605 | W18: =SUM(S18,P18,M18,J18,V18) -> 28430.076 | X18: 0 | Y18: =SUM(W18:X18) -> 28430.076 | AA18: 0.5 | AB18: 0.5
A19: PERSNL | B19: 70000 | C19: COL2 | D19: 0 | E19: Partnerships and Investment Director | F19: ='LOE Breakdown by Year'!D17 -> 0.05 | G19: Month | H19: 8 | I19: =46000/12 -> 3833.3333 | J19: =H19*I19*F19 -> 1533.3333 | K19: ='LOE Breakdown by Year'!D41 -> 0.1 | L19: 12 | M19: =L19*I19*$F$8*$K19 -> 4784 | N19: ='LOE Breakdown by Year'!D65 -> 0.1 | O19: 12 | P19: =O19*I19*$N19*$F$8*$F$8 -> 4975.36 | Q19: ='LOE Breakdown by Year'!D89 -> 0.1 | R19: 12 | S19: =R19*I19*$Q19*$F$8*$F$8*$F$8 -> 5174.3744 | T19: ='LOE Breakdown by Year'!D113 -> 0.1 | U19: 9 | V19: =U19*I19*$T19*$F$8*$F$8*$F$8*$F$8 -> 4036.012 | W19: =SUM(S19,P19,M19,J19,V19) -> 20503.08 | X19: 0 | Y19: =SUM(W19:X19) -> 20503.08 | AA19: 0.5 | AB19: 0.5
A20: PERSNL | B20: 70000 | C20: COL2 | D20: 0 | E20: Extension Agents (15) | F20: ='LOE Breakdown by Year'!D18 -> 0 | G20: Month | H20: 3 | I20: =(21000/12)*15 -> 26250 | J20: =H20*I20*F20 -> 0 | K20: ='LOE Breakdown by Year'!D42 -> 0 | L20: 12 | M20: =L20*I20*$F$8*$K20 -> 0 | N20: ='LOE Breakdown by Year'!D66 -> 0 | O20: 12 | P20: =O20*I20*$N20*$F$8*$F$8 -> 0 | Q20: ='LOE Breakdown by Year'!D90 -> 0 | R20: 12 | S20: =R20*I20*$Q20*$F$8*$F$8*$F$8 -> 0 | T20: ='LOE Breakdown by Year'!D114 -> 0 | U20: 9 | V20: =U20*I20*$T20*$F$8*$F$8*$F$8*$F$8 -> 0 | W20: =SUM(S20,P20,M20,J20,V20) -> 0 | X20: 0 | Y20: =SUM(W20:X20) -> 0 | AA20: 0.5 | AB20: 0.5
A21: PERSNL | B21: 70000 | C21: COL2 | D21: 0 | E21: Activity Lead Agribusiness Senior Specialist (Cacao) | F21: ='LOE Breakdown by Year'!D19 -> 0.1 | G21: Month | H21: 3 | I21: =34000/12 -> 2833.3333 | J21: =H21*I21*F21 -> 850 | K21: ='LOE Breakdown by Year'!D43 -> 0.1 | L21: 12 | M21: =L21*I21*$F$8*$K21 -> 3536 | N21: ='LOE Breakdown by Year'!D67 -> 0.1 | O21: 12 | P21: =O21*I21*$N21*$F$8*$F$8 -> 3677.44 | Q21: ='LOE Breakdown by Year'!D91 -> 0.1 | R21: 12 | S21: =R21*I21*$Q21*$F$8*$F$8*$F$8 -> 3824.5376 | T21: ='LOE Breakdown by Year'!D115 -> 0.1 | U21: 9 | V21: =U21*I21*$T21*$F$8*$F$8*$F$8*$F$8 -> 2983.1393 | W21: =SUM(S21,P21,M21,J21,V21) -> 14871.117 | X21: 0 | Y21: =SUM(W21:X21) -> 14871.117 | AA21: 1 | AB21: 0
A22: PERSNL | B22: 70000 | C22: COL2 | D22: 0 | E22: Activity Lead Agribusiness Senior Specialist (Complementary Crop) | F22: ='LOE Breakdown by Year'!D20 -> 0.1 | G22: Month | H22: 3 | I22: =34000/12 -> 2833.3333 | J22: =H22*I22*F22 -> 850 | K22: ='LOE Breakdown by Year'!D44 -> 0.1 | L22: 12 | M22: =L22*I22*$F$8*$K22 -> 3536 | N22: ='LOE Breakdown by Year'!D68 -> 0.1 | O22: 12 | P22: =O22*I22*$N22*$F$8*$F$8 -> 3677.44 | Q22: ='LOE Breakdown by Year'!D92 -> 0.1 | R22: 12 | S22: =R22*I22*$Q22*$F$8*$F$8*$F$8 -> 3824.5376 | T22: ='LOE Breakdown by Year'!D116 -> 0.1 | U22: 9 | V22: =U22*I22*$T22*$F$8*$F$8*$F$8*$F$8 -> 2983.1393 | W22: =SUM(S22,P22,M22,J22,V22) -> 14871.117 | X22: 0 | Y22: =SUM(W22:X22) -> 14871.117 | AA22: 0 | AB22: 1
A23: PERSNL | B23: 70000 | C23: COL2 | D23: 0 | E23: Food Safety Mid-Specialist | F23: ='LOE Breakdown by Year'!D21 -> 0.1 | G23: Month | H23: 3 | I23: =32000/12 -> 2666.6667 | J23: =H23*I23*F23 -> 800 | K23: ='LOE Breakdown by Year'!D45 -> 0.1 | L23: 12 | M23: =L23*I23*$F$8*$K23 -> 3328 | N23: ='LOE Breakdown by Year'!D69 -> 0.1 | O23: 12 | P23: =O23*I23*$N23*$F$8*$F$8 -> 3461.12 | Q23: ='LOE Breakdown by Year'!D93 -> 0.1 | R23: 12 | S23: =R23*I23*$Q23*$F$8*$F$8*$F$8 -> 3599.5648 | T23: ='LOE Breakdown by Year'!D117 -> 0.1 | U23: 9 | V23: =U23*I23*$T23*$F$8*$F$8*$F$8*$F$8 -> 2807.6605 | W23: =SUM(S23,P23,M23,J23,V23) -> 13996.345 | X23: 0 | Y23: =SUM(W23:X23) -> 13996.345 | AA23: 0.5 | AB23: 0.5
A24: PERSNL | B24: 70000 | C24: COL2 | D24: 0 | E24: Compliance Director | F24: ='LOE Breakdown by Year'!D22 -> 0.33333333 | G24: Month | H24: 8 | I24: =82000/12 -> 6833.3333 | J24: =H24*I24*F24 -> 18222.222 | K24: ='LOE Breakdown by Year'!D46 -> 0.33333333 | L24: 12 | M24: =L24*I24*$F$8*$K24 -> 28426.667 | N24: ='LOE Breakdown by Year'!D70 -> 0.33333333 | O24: 12 | P24: =O24*I24*$N24*$F$8*$F$8 -> 29563.733 | Q24: ='LOE Breakdown by Year'!D94 -> 0.33333333 | R24: 12 | S24: =R24*I24*$Q24*$F$8*$F$8*$F$8 -> 30746.283 | T24: ='LOE Breakdown by Year'!D118 -> 0.33333333 | U24: 12 | V24: =U24*I24*$T24*$F$8*$F$8*$F$8*$F$8 -> 31976.134 | W24: =SUM(S24,P24,M24,J24,V24) -> 138935.04 | X24: 0 | Y24: =SUM(W24:X24) -> 138935.04 | AA24: 0.5 | AB24: 0.5
A25: PERSNL | B25: 70000 | C25: COL2 | D25: 0 | E25: Accountant | F25: ='LOE Breakdown by Year'!D23 -> 1 | G25: Month | H25: 3 | I25: =21000/12 -> 1750 | J25: =H25*I25*F25 -> 5250 | K25: ='LOE Breakdown by Year'!D47 -> 1 | L25: 12 | M25: =L25*I25*$F$8*$K25 -> 21840 | N25: ='LOE Breakdown by Year'!D71 -> 1 | O25: 12 | P25: =O25*I25*$N25*$F$8*$F$8 -> 22713.6 | Q25: ='LOE Breakdown by Year'!D95 -> 1 | R25: 12 | S25: =R25*I25*$Q25*$F$8*$F$8*$F$8 -> 23622.144 | T25: ='LOE Breakdown by Year'!D119 -> 1 | U25: 9 | V25: =U25*I25*$T25*$F$8*$F$8*$F$8*$F$8 -> 18425.272 | W25: =SUM(S25,P25,M25,J25,V25) -> 91851.016 | X25: 0 | Y25: =SUM(W25:X25) -> 91851.016 | AA25: 0.5 | AB25: 0.5
A26: PERSNL | B26: 70000 | C26: COL2 | D26: 0 | E26: Administrative Assistant | F26: ='LOE Breakdown by Year'!D24 -> 0.5 | G26: Month | H26: 3 | I26: =15000/12 -> 1250 | J26: =H26*I26*F26 -> 1875 | K26: ='LOE Breakdown by Year'!D48 -> 0.5 | L26: 12 | M26: =L26*I26*$F$8*$K26 -> 7800 | N26: ='LOE Breakdown by Year'!D72 -> 0.5 | O26: 12 | P26: =O26*I26*$N26*$F$8*$F$8 -> 8112 | Q26: ='LOE Breakdown by Year'!D96 -> 0.5 | R26: 12 | S26: =R26*I26*$Q26*$F$8*$F$8*$F$8 -> 8436.48 | T26: ='LOE Breakdown by Year'!D120 -> 0.5 | U26: 9 | V26: =U26*I26*$T26*$F$8*$F$8*$F$8*$F$8 -> 6580.4544 | W26: =SUM(S26,P26,M26,J26,V26) -> 32803.934 | X26: 0 | Y26: =SUM(W26:X26) -> 32803.934 | AA26: 0.5 | AB26: 0.5
A27: PERSNL | B27: 70000 | C27: COL2 | D27: 0 | E27: Driver | F27: ='LOE Breakdown by Year'!D25 -> 1 | G27: Month | H27: 3 | I27: =12000/12 -> 1000 | J27: =H27*I27*F27 -> 3000 | K27: ='LOE Breakdown by Year'!D49 -> 1 | L27: 12 | M27: =L27*I27*$F$8*$K27 -> 12480 | N27: ='LOE Breakdown by Year'!D73 -> 1 | O27: 12 | P27: =O27*I27*$N27*$F$8*$F$8 -> 12979.2 | Q27: ='LOE Breakdown by Year'!D97 -> 1 | R27: 12 | S27: =R27*I27*$Q27*$F$8*$F$8*$F$8 -> 13498.368 | T27: ='LOE Breakdown by Year'!D121 -> 1 | U27: 9 | V27: =U27*I27*$T27*$F$8*$F$8*$F$8*$F$8 -> 10528.727 | W27: =SUM(S27,P27,M27,J27,V27) -> 52486.295 | X27: 0 | Y27: =SUM(W27:X27) -> 52486.295 | AA27: 0.5 | AB27: 0.5
E28: Headquarters (HQ) Support (LOE)
A29: PERSNL | B29: 50000 | C29: USA | D29: 0 | E29: Senior Director | F29: 0.2 | G29: Month | H29: 12 | I29: =120000/12 -> 10000 | J29: =H29*I29*F29 -> 24000 | K29: 0.2 | L29: 12 | M29: =L29*I29*$F$8*$K29 -> 24960 | N29: 0.2 | O29: 12 | P29: =O29*I29*$N29*$F$8*$F$8 -> 25958.4 | Q29: 0.2 | R29: 12 | S29: =R29*I29*$Q29*$F$8*$F$8*$F$8 -> 26996.736 | T29: 0.2 | U29: 12 | V29: =U29*I29*$T29*$F$8*$F$8*$F$8*$F$8 -> 28076.605 | W29: =SUM(S29,P29,M29,J29,V29) -> 129991.74 | X29: 0 | Y29: =SUM(W29:X29) -> 129991.74 | AA29: 0.5 | AB29: 0.5
A30: PERSNL | B30: 50000 | C30: USA | D30: 0 | E30: HQ Senior Program Officer | F30: ='LOE Breakdown by Year'!D28 -> 1 | G30: Month | H30: 12 | I30: =60000/12 -> 5000 | J30: =H30*I30*F30 -> 60000 | K30: ='LOE Breakdown by Year'!D52 -> 1 | L30: 12 | M30: =L30*I30*$F$8*$K30 -> 62400 | N30: ='LOE Breakdown by Year'!D76 -> 1 | O30: 12 | P30: =O30*I30*$N30*$F$8*$F$8 -> 64896 | Q30: ='LOE Breakdown by Year'!D100 -> 1 | R30: 12 | S30: =R30*I30*$Q30*$F$8*$F$8*$F$8 -> 67491.84 | T30: ='LOE Breakdown by Year'!D124 -> 1 | U30: 12 | V30: =U30*I30*$T30*$F$8*$F$8*$F$8*$F$8 -> 70191.514 | W30: =SUM(S30,P30,M30,J30,V30) -> 324979.35 | X30: 0 | Y30: =SUM(W30:X30) -> 324979.35 | AA30: 0.5 | AB30: 0.5
E32: Total Personnel | J32: =SUM(J13:J30) -> 188172.22 | M32: =SUM(M13:M30) -> 268458.67 | P32: =SUM(P13:P30) -> 279197.01 | S32: =SUM(S13:S30) -> 267080.21 | V32: =SUM(V13:V30) -> 270861.25 | W32: =SUM(W13:W30) -> 1273769.4 | X32: =SUM(X13:X30) -> 0 | Y32: =SUM(Y13:Y30) -> 1273769.4 | AA32: =SUMPRODUCT(Y13:Y27,AA13:AA27)+SUMPRODUCT(Y29:Y30,AA29:AA30) -> 636884.68 | AB32: =+SUMPRODUCT(Y13:Y27,AB13:AB27)+SUMPRODUCT(Y29:Y30,AB29:AB30) -> 636884.68
E34: Fringe Benefits
A35: FRINGE | B35: 70015 | C35: COL2 | D35: 0 | E35: Fringe Benefits CCN - Colombia (above $2,600 monthly) | G35: % | I35: 0.53864 | J35: =(J14+J15+J16+J24+J19+J17+J21+J22+J23)*$I$35 -> 37662.906 | M35: =(M14+M15+M16+M24+M19+M17+M21+M22+M23)*$I$35 -> 62815.479 | P35: =(P14+P15+P16+P24+P19+P17+P21+P22+P23)*$I$35 -> 65328.098 | S35: =(S14+S15+S16+S24+S19+S17+S21+S22+S23)*$I$35 -> 55399.159 | V35: =(V14+V15+V16+V24+V19+V17+V21+V22+V23)*$I$35 -> 61301.401 | W35: =SUM(S35,P35,M35,J35,V35) -> 282507.04 | X35: 0 | Y35: =SUM(W35:X35) -> 282507.04 | AA35: 0.5 | AB35: 0.5
A36: FRINGE | B36: 70015 | C36: COL2 | D36: 0 | E36: Fringe Benefits CCN - Colombia (below $2,600 monthly) | G36: % | I36: 0.40364 | J36: =(J18+J20+J25+J26+J27)*$I$36 -> 4742.77 | M36: =(M18+M20+M25+M26+M27)*$I$36 -> 19729.923 | P36: =(P18+P20+P25+P26+P27)*$I$36 -> 20519.12 | S36: =(S18+S20+S25+S26+S27)*$I$36 -> 21339.885 | V36: =(V18+V20+V25+V26+V27)*$I$36 -> 16645.11 | W36: =SUM(S36,P36,M36,J36,V36) -> 82976.809 | X36: 0 | Y36: =SUM(W36:X36) -> 82976.809 | AA36: 0.5 | AB36: 0.5
A37: FRINGE | B37: 50900 | C37: USA | D37: 0 | E37: Fringe Benefits - HQ (21.81%) | G37: % | I37: 0.2181 | J37: =(J30+J29)*$I$37 -> 18320.4 | M37: =(M30+M29)*$I$37 -> 19053.216 | P37: =(P30+P29)*$I$37 -> 19815.345 | S37: =(S30+S29)*$I$37 -> 20607.958 | V37: =(V30+V29)*$I$37 -> 21432.277 | W37: =SUM(S37,P37,M37,J37,V37) -> 99229.196 | X37: 0 | Y37: =SUM(W37:X37) -> 99229.196 | AA37: 0.5 | AB37: 0.5
A38: POST DIFF | B38: 50202 | C38: COL2 | D38: 0 | E38: Post (Hardship) Differential for Chief of Party | G38: % | I38: 0.1 | J38: =J13*$I$38 -> 2250 | M38: =M13*$I$38 -> 1560 | P38: =P13*$I$38 -> 1622.4 | S38: =S13*$I$38 -> 1687.296 | V38: =V13*$I$38 -> 1754.7878 | W38: =SUM(S38,P38,M38,J38,V38) -> 8874.4838 | X38: - | Y38: =SUM(W38:X38) -> 8874.4838 | AA38: 0.5 | AB38: 0.5
A39: FRINGE | B39: 50900 | C39: USA | D39: 0 | E39: Fringe Benefits Package for Chief of Party | G39: % | I39: 0.5681 | J39: =J13*$I$39 -> 12782.25 | M39: =M13*$I$39 -> 8862.36 | P39: =P13*$I$39 -> 9216.8544 | S39: =S13*$I$39 -> 9585.5286 | V39: =V13*$I$39 -> 9968.9497 | W39: =SUM(S39,P39,M39,J39,V39) -> 50415.943 | X39: - | Y39: =SUM(W39:X39) -> 50415.943 | AA39: 0.5 | AB39: 0.5
A40: HOUSE. ALL | B40: 50203 | C40: COL2 | D40: 0 | E40: Housing Allowance for Chief of Party | G40: Month | H40: 4 | I40: 2500 | J40: =H40*I40 -> 10000 | L40: 12 | M40: =I40*L40*$F$6 -> 30900 | O40: 12 | P40: =I40*O40*$F$6*$F$6 -> 31827 | R40: 12 | S40: =I40*R40*$F$6*$F$6*$F$6 -> 32781.81 | U40: 12 | V40: =U40*I40*$F$6*$F$6*$F$6*$F$6 -> 33765.264 | W40: =SUM(S40,P40,M40,J40,V40) -> 139274.07 | X40: - | Y40: =SUM(W40:X40) -> 139274.07 | AA40: 0.5 | AB40: 0.5
A41: REALLOC | B41: 50205 | C41: COL2 | D41: 0 | E41: Reallocation & Demobilization Allowance for Chief of Party | G41: Year | H41: 1 | I41: 25000 | J41: =H41*I41 -> 25000 | L41: 0 | M41: =I41*L41*$F$6 -> 0 | O41: 0 | P41: =I41*O41*$F$6*$F$6 -> 0 | R41: 0 | S41: =I41*R41*$F$6*$F$6*$F$6 -> 0 | U41: 1 | V41: =U41*I41*$F$6*$F$6*$F$6*$F$6 -> 28137.72 | W41: =SUM(S41,P41,M41,J41,V41) -> 53137.72 | X41: - | Y41: =SUM(W41:X41) -> 53137.72 | AA41: 0.5 | AB41: 0.5
A42: R&RTRIP | B42: 50206 | C42: COL2 | D42: 0 | E42: Annual Home of Record for Chief of Party | G42: Year | H42: 2 | I42: 800 | J42: =H42*I42 -> 1600 | L42: 2 | M42: =I42*L42*$F$6 -> 1648 | O42: 2 | P42: =I42*O42*$F$6*$F$6 -> 1697.44 | R42: 2 | S42: =I42*R42*$F$6*$F$6*$F$6 -> 1748.3632 | U42: 2 | V42: =U42*I42*$F$6*$F$6*$F$6*$F$6 -> 1800.8141 | W42: =SUM(S42,P42,M42,J42,V42) -> 8494.6173 | X42: - | Y42: =SUM(W42:X42) -> 8494.6173 | AA42: 0.5 | AB42: 0.5
E44: Total Fringe Benefits | J44: =SUM(J35:J43) -> 112358.33 | M44: =SUM(M35:M43) -> 144568.98 | P44: =SUM(P35:P43) -> 150026.26 | S44: =SUM(S35:S43) -> 143150 | V44: =SUM(V35:V43) -> 174806.32 | W44: =SUM(W35:W43) -> 724909.89 | X44: =SUM(X35:X43) -> 0 | Y44: =SUM(Y35:Y43) -> 724909.89 | AA44: =SUMPRODUCT(Y35:Y42,AA35:AA42) -> 362454.94 | AB44: =SUMPRODUCT(Y35:Y42,AB35:AB42) -> 362454.94
...

Sheet Partners by Activity
C1: Admin | D1: Activity 1. Value Chain Development (VC Study, Living Income, Carbon) | E1: Activity 2. Producer Organization Development & Commercialization | F1: Activity 3. Agriculture Extension and Production Support | G1: Activity 4. Post-Harvest Aggregation & Processing . Seedstock/Nurseries | H1: Activity 5. Ensure Financial Service/ Capital Access for Actors in the Value Chains | I1: Activity 6. Innovation and Job Creation Through Youth Engagement | J1: Activity 7. Establishment of Regional Community of Practice | K1: Activity 8. Financial Services: Endowment Establishment, Fundraising and Management
A2: In-Country Partners | B2: Partners of the Americas | C2: ● | D2: ● | E2: ● | F2: ● | G2: ● | H2: ● | I2: ● | J2: ● | K2: ● | L2: Prime Awardee with Regional Expertise
B3: CIAT | D3: ● | F3: ● | J3: ○ | L3: Major in-country research institution
B4: Agrosavia | G4: ● | J4: ○ | L4: Major in-country research institution
B5: Activity 2 partnership | E5: ● | J5: ○
B6: Fedecacao | D6: ○ | E6: ○ | F6: ○ | H6: ○ | I6: ○ | J6: ○ | L6: Colombian university with regional and research expertise
B7: Red Nacional Cacaotera | D7: ○ | E7: ○ | F7: ○ | H7: ○ | I7: ○ | J7: ○
B8: Sena | E8: ○ | H8: ○ | I8: ○ | J8: ○
B9: Office of the Vice President of Colombia | H9: ○ | I9: ○ | J9: ○ | K9: ○
B10: Nacional de Chocolates | D10: ○ | F10: ○ | I10: ○ | J10: ○ | K10: ○ | L10: Major in-country purchaser of Colombian cacao
B11: Luker Chocolates | D11: ○ | F11: ○ | G11: ○ | I11: ○ | J11: ○ | K11: ○ | L11: Major in-country purchaser of Colombian cacao
B12: Cacao Hunters | D12: ○ | F12: ○ | G12: ○ | I12: ○ | J12: ○ | K12: ○
B13: Other Colombian cacao companies | D13: ○ | F13: ○ | G13: ○ | I13: ○ | J13: ○ | K13: ○
B14: Other Colombian Complementary crops companies | D14: ○ | G14: ○ | I14: ○ | J14: ○ | L14: Colombian exporters of tropical fruit (pulp, juice concentrate, frozen) including soursop, guava, mango, papaya, and passion fruit, etc
B15: Digital training partnerships | F15: ● | J15: ○
B16: Carbon Partnerships | D16: ○ | F16: ● | J16: ○
B17: Food Safety, Traceability and Risk Management partnerships | F17: ● | J17: ○
B18: Other Extension-Producer support partnerships (Agromovil) | F18: ●
B19: Post harvest and aggregation partnerships | G19: ● | J19: ○
B20: Incubator/Accelerator partnerships | H20: ● | J20: ○
B21: ANDEAN* | I21: ○ | J21: ○ | K21: ○ | L21: Major in-country network for impact investors
B22: The National Fruit and Vegetable Association (ASOHOFRUCOL) | D22: ○ | E22: ○ | F22: ○ | G22: ○ | J22: ○ | L22: In-country association for commercialization of Colombian fruits and vegetables, administers the National Fund for Fruit and Vegetable Development
B23: Finanfuturo | G23: ○ | H23: ○ | J23: ○ | K23: ○ | L23: Impact investment arm of Citi Bank working in Cacao/illicit crop substitution
B24: Acumen, Alter-eco Foundation, InterAmerican Foundation & others | H24: ○ | J24: ○ | K24: ○ | L24: International Impact Investment firm with Bogota office
A25: Grants | B25: Multiple grant recipients | F25: ● | G25: ● | H25: ● | I25: ● | J25: ●
A26: International Partners | B26: World Cocoa Foundation | J26: ○ | K26: ○ | L26: Major international cacao sector development support organization
B27: American Retailer Chains | E27: ○ | G27: ○ | J27: ○ | L27: Global trader of tropical fruits sourced from Latin America, based in U.S. with offices across the region
L28: US-based market chain that sources from Latin America
L29: US-based market chain that sources from Latin America
A30: International Research Partners | B30: CATIE | J30: ○ | L30: Major International Agriculture Research Institution
B31: USDA ARS Tropical Crops and Germplasm Research (PR) | J31: ○ | L31: Major US Tropical Agriculture Research Institution
B32: Regional University Center of the Atlantic Coast (CURLA) | J32: ○ | L32: Major International Agriculture Research Institution
B33: Peruvian Amazon Research Institute | J33: ○ | L33: Tropical and Amazonian agriculture research station with cacao expertise
B34: Instituto Nacional de Investigaciones Agropecuarias (INIAP) | J34: ○ | L34: Major Ecuadorian agriculture research institution with cacao expertise
A36: ● | B36: Receives funding from C4D
A37: ○ | B37: Does not receive funding
S52: RACI for Activity 1 (Summarized Sample)
S53: Partners of the Americas | T53: CIAT | U53: USDA | V53: Fedecacao | W53: Red Cacaotera | X53: Sector Privado
R54: Questionnaire brainstorm | S54: A | T54: R | U54: A | V54: I | W54: I | X54: I
R55: Questionnaire Design/Validat | S55: A | T55: R | U55: I | V55: I | W55: I | X55: I
...

Sheet Personnel & LOE Summary
B1: Partners of the Americas – FY 2020 FFPr Colombia
B2: NOFO: USDA-FAS-10.606-0700-20-(514)
B3: Duration: 5 Years
B4: Country: Colombia
B5: Level of Effort (LOE) Breakdown by Activity
C7: Months in Year 1 | D7: Year 1 LOE | E7: Total Salary Amount Year 1 | F7: Months in Year 2 | G7: Year 2 LOE | H7: Total Salary Amount Year 2 | I7: Months in Year 3 | J7: Year 3 LOE | K7: Total Salary Amount Year 3 | L7: Months in Year 4 | M7: Year 4 LOE | N7: Total Salary Amount Year 4 | O7: Months in Year 5 | P7: Year 5 LOE | Q7: Total Salary Amount Year 5 | R7: Total Amount LOP
C8: LOE | D8: LOE | E8: LOE | F8: LOE | G8: LOE | H8: LOE | I8: LOE | J8: LOE | K8: LOE | L8: LOE | M8: LOE | N8: LOE | O8: LOE | P8: LOE | Q8: LOE | R8: LOE
B9: Personnel (Administration)
B10: Colombia National Staff
B11: ='Program Budget'!E13 -> Key Personnel: Chief of Party | C11: ='Program Budget'!H13 -> 12 | D11: ='Program Budget'!F13+'Program Budget'!F130+'Program Budget'!F168+'Program Budget'!F211+'Program Budget'!F270+'Program Budget'!F318+'Program Budget'!F372+'Program Budget'!F438+'Program Budget'!F484 -> 1 | E11: ='Program Budget'!J13+'Program Budget'!J130+'Program Budget'!J168+'Program Budget'!J211+'Program Budget'!J270+'Program Budget'!J318+'Program Budget'!J372+'Program Budget'!J438+'Program Budget'!J484 -> 150000 | F11: ='Program Budget'!L13 -> 12 | G11: ='Program Budget'!K13+'Program Budget'!K130+'Program Budget'!K168+'Program Budget'!K211+'Program Budget'!K270+'Program Budget'!K318+'Program Budget'!K372+'Program Budget'!K438+'Program Budget'!K484 -> 1 | H11: ='Program Budget'!M13+'Program Budget'!M130+'Program Budget'!M168+'Program Budget'!M211+'Program Budget'!M270+'Program Budget'!M318+'Program Budget'!M372+'Program Budget'!M438+'Program Budget'!M484 -> 156000 | I11: ='Program Budget'!O13 -> 12 | J11: ='Program Budget'!N13+'Program Budget'!N130+'Program Budget'!N168+'Program Budget'!N211+'Program Budget'!N270+'Program Budget'!N318+'Program Budget'!N372+'Program Budget'!N438+'Program Budget'!N484 -> 1 | K11: ='Program Budget'!P13+'Program Budget'!P130+'Program Budget'!P168+'Program Budget'!P211+'Program Budget'!P270+'Program Budget'!P318+'Program Budget'!P372+'Program Budget'!P438+'Program Budget'!P484 -> 162240 | L11: ='Program Budget'!R13 -> 12 | M11: ='Program Budget'!Q13+'Program Budget'!Q130+'Program Budget'!Q168+'Program Budget'!Q211+'Program Budget'!Q270+'Program Budget'!Q318+'Program Budget'!Q372+'Program Budget'!Q438+'Program Budget'!Q484 -> 1 | N11: ='Program Budget'!S13+'Program Budget'!S130+'Program Budget'!S168+'Program Budget'!S211+'Program Budget'!S270+'Program Budget'!S318+'Program Budget'!S372+'Program Budget'!S438+'Program Budget'!S484 -> 168729.6 | O11: ='Program Budget'!U13 -> 12 | P11: ='Program Budget'!T13+'Program Budget'!T130+'Program Budget'!T168+'Program Budget'!T211+'Program Budget'!T270+'Program Budget'!T318+'Program Budget'!T372+'Program Budget'!T438+'Program Budget'!T484 -> 1 | Q11: ='Program Budget'!V13+'Program Budget'!V130+'Program Budget'!V168+'Program Budget'!V211+'Program Budget'!V270+'Program Budget'!V318+'Program Budget'!V372+'Program Budget'!V438+'Program Budget'!V484 -> 175478.78 | R11: =E11+H11+K11+N11+Q11 -> 812448.38
B12: ='Program Budget'!E14 -> Key Personnel: Technical Director | C12: ='Program Budget'!H14 -> 8 | D12: ='Program Budget'!F14+'Program Budget'!F131+'Program Budget'!F169+'Program Budget'!F212+'Program Budget'!F271+'Program Budget'!F319+'Program Budget'!F373+'Program Budget'!F439+'Program Budget'!F485 -> 1 | E12: ='Program Budget'!J14+'Program Budget'!J131+'Program Budget'!J169+'Program Budget'!J212+'Program Budget'!J271+'Program Budget'!J319+'Program Budget'!J373+'Program Budget'!J439+'Program Budget'!J485 -> 46666.667 | F12: ='Program Budget'!L14 -> 12 | G12: ='Program Budget'!K14+'Program Budget'!K131+'Program Budget'!K169+'Program Budget'!K212+'Program Budget'!K271+'Program Budget'!K319+'Program Budget'!K373+'Program Budget'!K439+'Program Budget'!K485 -> 1 | H12: ='Program Budget'!M14+'Program Budget'!M131+'Program Budget'!M169+'Program Budget'!M212+'Program Budget'!M271+'Program Budget'!M319+'Program Budget'!M373+'Program Budget'!M439+'Program Budget'!M485 -> 72800 | I12: ='Program Budget'!O14 -> 12 | J12: ='Program Budget'!N14+'Program Budget'!N131+'Program Budget'!N169+'Program Budget'!N212+'Program Budget'!N271+'Program Budget'!N319+'Program Budget'!N373+'Program Budget'!N439+'Program Budget'!N485 -> 1 | K12: ='Program Budget'!P14+'Program Budget'!P131+'Program Budget'!P169+'Program Budget'!P212+'Program Budget'!P271+'Program Budget'!P319+'Program Budget'!P373+'Program Budget'!P439+'Program Budget'!P485 -> 75712 | L12: ='Program Budget'!R14 -> 12 | M12: ='Program Budget'!Q14+'Program Budget'!Q131+'Program Budget'!Q169+'Program Budget'!Q212+'Program Budget'!Q271+'Program Budget'!Q319+'Program Budget'!Q373+'Program Budget'!Q439+'Program Budget'!Q485 -> 1 | N12: ='Program Budget'!S14+'Program Budget'!S131+'Program Budget'!S169+'Program Budget'!S212+'Program Budget'!S271+'Program Budget'!S319+'Program Budget'!S373+'Program Budget'!S439+'Program Budget'!S485 -> 78740.48 | O12: ='Program Budget'!U14 -> 12 | P12: ='Program Budget'!T14+'Program Budget'!T131+'Program Budget'!T169+'Program Budget'!T212+'Program Budget'!T271+'Program Budget'!T319+'Program Budget'!T373+'Program Budget'!T439+'Program Budget'!T485 -> 1 | Q12: ='Program Budget'!V14+'Program Budget'!V131+'Program Budget'!V169+'Program Budget'!V212+'Program Budget'!V271+'Program Budget'!V319+'Program Budget'!V373+'Program Budget'!V439+'Program Budget'!V485 -> 81890.099 | R12: =E12+H12+K12+N12+Q12 -> 355809.25
B13: ='Program Budget'!E15 -> F&A Director | C13: ='Program Budget'!H15 -> 8 | D13: ='Program Budget'!F15+'Program Budget'!F132+'Program Budget'!F170+'Program Budget'!F213+'Program Budget'!F272+'Program Budget'!F320+'Program Budget'!F374+'Program Budget'!F440+'Program Budget'!F486 -> 1 | E13: ='Program Budget'!J15+'Program Budget'!J132+'Program Budget'!J170+'Program Budget'!J213+'Program Budget'!J272+'Program Budget'!J320+'Program Budget'!J374+'Program Budget'!J440+'Program Budget'!J486 -> 30666.667 | F13: ='Program Budget'!L15 -> 12 | G13: ='Program Budget'!K15+'Program Budget'!K132+'Program Budget'!K170+'Program Budget'!K213+'Program Budget'!K272+'Program Budget'!K320+'Program Budget'!K374+'Program Budget'!K440+'Program Budget'!K486 -> 1 | H13: ='Program Budget'!M15+'Program Budget'!M132+'Program Budget'!M170+'Program Budget'!M213+'Program Budget'!M272+'Program Budget'!M320+'Program Budget'!M374+'Program Budget'!M440+'Program Budget'!M486 -> 47840 | I13: ='Program Budget'!O15 -> 12 | J13: ='Program Budget'!N15+'Program Budget'!N132+'Program Budget'!N170+'Program Budget'!N213+'Program Budget'!N272+'Program Budget'!N320+'Program Budget'!N374+'Program Budget'!N440+'Program Budget'!N486 -> 1 | K13: ='Program Budget'!P15+'Program Budget'!P132+'Program Budget'!P170+'Program Budget'!P213+'Program Budget'!P272+'Program Budget'!P320+'Program Budget'!P374+'Program Budget'!P440+'Program Budget'!P486 -> 49753.6 | L13: ='Program Budget'!R15 -> 12 | M13: ='Program Budget'!Q15+'Program Budget'!Q132+'Program Budget'!Q170+'Program Budget'!Q213+'Program Budget'!Q272+'Program Budget'!Q320+'Program Budget'!Q374+'Program Budget'!Q440+'Program Budget'!Q486 -> 1 | N13: ='Program Budget'!S15+'Program Budget'!S132+'Program Budget'!S170+'Program Budget'!S213+'Program Budget'!S272+'Program Budget'!S320+'Program Budget'!S374+'Program Budget'!S440+'Program Budget'!S486 -> 51743.744 | O13: ='Program Budget'!U15 -> 12 | P13: ='Program Budget'!T15+'Program Budget'!T132+'Program Budget'!T170+'Program Budget'!T213+'Program Budget'!T272+'Program Budget'!T320+'Program Budget'!T374+'Program Budget'!T440+'Program Budget'!T486 -> 1 | Q13: ='Program Budget'!V15+'Program Budget'!V132+'Program Budget'!V170+'Program Budget'!V213+'Program Budget'!V272+'Program Budget'!V320+'Program Budget'!V374+'Program Budget'!V440+'Program Budget'!V486 -> 53813.494 | R13: =E13+H13+K13+N13+Q13 -> 233817.5
B14: ='Program Budget'!E16 -> M&E Director | C14: ='Program Budget'!H16 -> 8 | D14: ='Program Budget'!F16+'Program Budget'!F133+'Program Budget'!F171+'Program Budget'!F214+'Program Budget'!F273+'Program Budget'!F321+'Program Budget'!F375+'Program Budget'!F441+'Program Budget'!F487 -> 1 | E14: ='Program Budget'!J16+'Program Budget'!J133+'Program Budget'!J171+'Program Budget'!J214+'Program Budget'!J273+'Program Budget'!J321+'Program Budget'!J375+'Program Budget'!J441+'Program Budget'!J487 -> 30666.667 | F14: ='Program Budget'!L16 -> 12 | G14: ='Program Budget'!K16+'Program Budget'!K133+'Program Budget'!K171+'Program Budget'!K214+'Program Budget'!K273+'Program Budget'!K321+'Program Budget'!K375+'Program Budget'!K441+'Program Budget'!K487 -> 1 | H14: ='Program Budget'!M16+'Program Budget'!M133+'Program Budget'!M171+'Program Budget'!M214+'Program Budget'!M273+'Program Budget'!M321+'Program Budget'!M375+'Program Budget'!M441+'Program Budget'!M487 -> 47840 | I14: ='Program Budget'!O16 -> 12 | J14: ='Program Budget'!N16+'Program Budget'!N133+'Program Budget'!N171+'Program Budget'!N214+'Program Budget'!N273+'Program Budget'!N321+'Program Budget'!N375+'Program Budget'!N441+'Program Budget'!N487 -> 1 | K14: ='Program Budget'!P16+'Program Budget'!P133+'Program Budget'!P171+'Program Budget'!P214+'Program Budget'!P273+'Program Budget'!P321+'Program Budget'!P375+'Program Budget'!P441+'Program Budget'!P487 -> 49753.6 | L14: ='Program Budget'!R16 -> 12 | M14: ='Program Budget'!Q16+'Program Budget'!Q133+'Program Budget'!Q171+'Program Budget'!Q214+'Program Budget'!Q273+'Program Budget'!Q321+'Program Budget'!Q375+'Program Budget'!Q441+'Program Budget'!Q487 -> 1 | N14: ='Program Budget'!S16+'Program Budget'!S133+'Program Budget'!S171+'Program Budget'!S214+'Program Budget'!S273+'Program Budget'!S321+'Program Budget'!S375+'Program Budget'!S441+'Program Budget'!S487 -> 51743.744 | O14: ='Program Budget'!U16 -> 12 | P14: ='Program Budget'!T16+'Program Budget'!T133+'Program Budget'!T171+'Program Budget'!T214+'Program Budget'!T273+'Program Budget'!T321+'Program Budget'!T375+'Program Budget'!T441+'Program Budget'!T487 -> 1 | Q14: ='Program Budget'!V16+'Program Budget'!V133+'Program Budget'!V171+'Program Budget'!V214+'Program Budget'!V273+'Program Budget'!V321+'Program Budget'!V375+'Program Budget'!V441+'Program Budget'!V487 -> 53813.494 | R14: =E14+H14+K14+N14+Q14 -> 233817.5
