Workbook
Name Category: #N/A
Name Category: #N/A
Name Category: #N/A
Name Category: 'Project Budget'!$G$15:$G$181
Name DL_Country: #N/A
Name DL_Country: #N/A
Name DL_Country: #N/A
Name DL_Country: 'Project Budget'!#REF!
Name DL_TotalDOL: #N/A
Name DL_TotalDOL: #N/A
Name DL_TotalDOL: #N/A
Name DL_TotalDOL: 'Project Budget'!$T$14:$T$31
Name EQ_Country: #N/A
Name EQ_Country: #N/A
Name EQ_Country: #N/A
Name EQ_Country: 'Project Budget'!#REF!
Name EQ_TotalDOL: #N/A
Name EQ_TotalDOL: #N/A
Name EQ_TotalDOL: #N/A
Name EQ_TotalDOL: 'Project Budget'!#REF!
Name inf: #N/A
Name inf: #N/A
Name inf: #N/A
Name inf: #REF!
Name JEA_Country: #N/A
Name JEA_Country: #N/A
Name JEA_Country: #N/A
Name JEA_Country: #REF!
Name JEA_Year1: #N/A
Name JEA_Year1: #N/A
Name JEA_Year1: #N/A
Name JEA_Year1: #REF!
Name ME_Country: #N/A
Name ME_Country: #N/A
Name ME_Country: #N/A
Name ME_Country: 'Project Budget'!#REF!
Name ME_TotalDOL: #N/A
Name ME_TotalDOL: #N/A
Name ME_TotalDOL: #N/A
Name ME_TotalDOL: 'Project Budget'!$T$156:$T$167
Name O1_Country: #N/A
Name O1_Country: #N/A
Name O1_Country: #N/A
Name O1_Country: 'Project Budget'!#REF!
Name O1_TotalDOL: #N/A
Name O1_TotalDOL: #N/A
Name O1_TotalDOL: #N/A
Name O1_TotalDOL: 'Project Budget'!$T$75:$T$75
Name O2_Country: #N/A
Name O2_Country: #N/A
Name O2_Country: #N/A
Name O2_Country: 'Project Budget'!#REF!
Name O2_TotalDOL: #N/A
Name O2_TotalDOL: #N/A
Name O2_TotalDOL: #N/A
Name O2_TotalDOL: 'Project Budget'!#REF!
Name SU_Country: #N/A
Name SU_Country: #N/A
Name SU_Country: #N/A
Name SU_Country: 'Project Budget'!#REF!

Sheet Budget Summary
B1: Mexico Awareness Raising Project
B2: FOA-ILAB-20-10
B3: Partners of the Americas
B4: BUDGET ITEM | C4: TOTAL DOL | D4: TOTAL COST SHARING | E4: PROJECT GRAND TOTAL
B5: Direct Labor | C5: ='Project Budget'!T33 -> 2303880.4 | D5: ='Project Budget'!U33 -> 0 | E5: =SUM(C5:D5) -> 2303880.4
B6: Travel | C6: ='Project Budget'!T53 -> 204415.3 | D6: ='Project Budget'!U53 -> 0 | E6: =SUM(C6:D6) -> 204415.3
B7: Equipment | C7: 0 | D7: 0 | E7: =SUM(C7:D7) -> 0
B8: Supplies and Office Expenses | C8: ='Project Budget'!T71 -> 259904.78 | D8: ='Project Budget'!U71 -> 0 | E8: =SUM(C8:D8) -> 259904.78
B9: Outcome 1 | C9: ='Project Budget'!T129 -> 3659294.1 | D9: ='Project Budget'!U129 -> 0 | E9: =SUM(C9:D9) -> 3659294.1
B10: Outcome 2 | C10: ='Project Budget'!T152 -> 1019816.1 | D10: ='Project Budget'!U152 -> 0 | E10: =SUM(C10:D10) -> 1019816.1
B11: Monitoring, Evaluation, and Collection of Reliable Data | C11: ='Project Budget'!T177 -> 323301.23 | D11: ='Project Budget'!U177 -> 0 | E11: =SUM(C11:D11) -> 323301.23
B12: Total Direct Costs | C12: =SUM(C5:C11) -> 7770611.9 | D12: =SUM(D5:D11) -> 0 | E12: =SUM(E5:E11) -> 7770611.9
B13: Indirect Costs (NICRA) | C13: ='Project Budget'!T181 -> 2229388.6 | D13: ='Project Budget'!U181 -> 0 | E13: =SUM(C13:D13) -> 2229388.6
B14: TOTAL COSTS | C14: =C13+C12 -> 10000000 | D14: =D13+D12 -> 0 | E14: =E13+E12 -> 10000000
B16: ADMINISTRATIVE COSTS (Direct Labor, Equipment, Supplies, Indirect Costs) | C16: =C5+C7+C8+C13 -> 4793173.7
B17: PROGRAM COSTS (Travel, Contractual, Other Direct Costs) | C17: =C6+C9+C10+C11 -> 5206826.8

Sheet Project Budget
F1: Equal Access to Quality Jobs for Women and Girls in Agriculture (EQUAL)
F2: FOA-ILAB-19-02
F3: Partners of the Americas
A4: Entity: | B4: P | F4: Partners of the Americas
A5: Program-Dept.: | B5: 20200 | F5: NOFO: FOA-ILAB-20-10
A6: Funder-Grant: | B6: DOL423 | F6: Country: Mexico
F7: Budget Assumptions:
F8: Inflation - US Based Goods/Services | G8: 1.03
F9: Inflation - Locally Purchased Goods/Services | G9: 1.04
F10: Merit Based Increases for HQ & Field Staff | G10: 1.035
A12: Sage Activity | B12: Sage Object Code/ Line Item | C12: Country Code (DC=0 or MX) | D12: Office Code (DC=0 or MX) | E12: Subcontract Code | F12: BUDGET ITEM | G12: CATEGORY | H12: UNIT | I12: # of Units | J12: RATE / UNIT | K12: YEAR 1 | L12: # of Units | M12: YEAR 2 | N12: # of Units | O12: YEAR 3 | P12: # of Units | Q12: YEAR 4 | R12: # of Units | S12: YEAR 5 | T12: TOTAL DOL | U12: TOTAL COST SHARING | V12: PROJECT GRAND TOTAL
F13: Direct Labor
F14: Key Personnel
A15: PERSNL-PD | B15: 70000 | C15: MEX | D15: MEX | E15: 0 | F15: Project Director (100%) | G15: Salaries | H15: Month | I15: 12 | J15: 12916 | K15: =I15*J15 -> 154992 | L15: 12 | M15: =L15*J15*$G$10 -> 160416.72 | N15: 12 | O15: =(J15*3*$G$10*$G$10)+(N15*7000*$G$10*$G$10) -> 131490.73 | P15: 12 | Q15: =P15*7000*1.015*$G$10*$G$10*$G$10 -> 94529.286 | R15: 6 | S15: =R15*7000*$G$10*$G$10*$G$10*$G$10 -> 48195.966 | T15: =SUM(K15+M15+O15+Q15+S15) -> 589624.7 | U15: 0 | V15: =SUM(T15:U15) -> 589624.7
A16: PERSNL-M&E | B16: 70000 | C16: MEX | D16: MEX | E16: 0 | F16: Monitoring and Evaluation (M&E) Officer (100%) | G16: Salaries | H16: Month | I16: 12 | J16: 4200 | K16: =I16*J16 -> 50400 | L16: 12 | M16: =L16*J16*$G$10 -> 52164 | N16: 12 | O16: =N16*J16*$G$10*$G$10 -> 53989.74 | P16: 12 | Q16: =P16*J16*1.015*$G$10*$G$10*$G$10 -> 56717.572 | R16: 6 | S16: =J16*R16*$G$10*$G$10*$G$10*$G$10 -> 28917.58 | T16: =SUM(K16+M16+O16+Q16+S16) -> 242188.89 | U16: 0 | V16: =SUM(T16:U16) -> 242188.89
F18: Other Professional Personnel
A19: PERSNL-CBS | B19: 70000 | C19: MEX | D19: MEX | E19: 0 | F19: Capacity Building Specialist (100%) | G19: Salaries | H19: Month | I19: 11 | J19: 3600 | K19: =I19*J19 -> 39600 | L19: 12 | M19: =L19*J19*$G$10 -> 44712 | N19: 12 | O19: =N19*J19*$G$10*$G$10 -> 46276.92 | P19: 12 | Q19: =P19*J19*1.015*$G$10*$G$10*$G$10 -> 48615.061 | R19: 5 | S19: =J19*R19*$G$10*$G$10*$G$10*$G$10 -> 20655.414 | T19: =SUM(K19+M19+O19+Q19+S19) -> 199859.4 | U19: 0 | V19: =SUM(T19:U19) -> 199859.4
A20: PERSNL-COM | B20: 70000 | C20: MEX | D20: MEX | E20: 0 | F20: Communications Specialist (100%) | G20: Salaries | H20: Month | I20: 11 | J20: 2800 | K20: =I20*J20 -> 30800 | L20: 12 | M20: =L20*J20*$G$10 -> 34776 | N20: 12 | O20: =N20*J20*$G$10*$G$10 -> 35993.16 | P20: 12 | Q20: =P20*J20*1.015*$G$10*$G$10*$G$10 -> 37811.714 | R20: 5 | S20: =J20*R20*$G$10*$G$10*$G$10*$G$10 -> 16065.322 | T20: =SUM(K20+M20+O20+Q20+S20) -> 155446.2 | U20: 0 | V20: =SUM(T20:U20) -> 155446.2
A21: PERSNL-F&A | B21: 70000 | C21: MEX | D21: MEX | E21: 0 | F21: Finance and Administration Manager (100%) | G21: Salaries | H21: Month | I21: 11 | J21: 3200 | K21: =I21*J21 -> 35200 | L21: 12 | M21: =L21*J21*$G$10 -> 39744 | N21: 12 | O21: =N21*J21*$G$10*$G$10 -> 41135.04 | P21: 12 | Q21: =P21*J21*1.015*$G$10*$G$10*$G$10 -> 43213.388 | R21: 6 | S21: =J21*R21*$G$10*$G$10*$G$10*$G$10 -> 22032.442 | T21: =SUM(K21+M21+O21+Q21+S21) -> 181324.87 | U21: 0 | V21: =SUM(T21:U21) -> 181324.87
F23: Home Office Support
A24: PERSNL-PM | B24: Timesheets | C24: 0 | D24: 0 | E24: 0 | F24: Project Manager (20%) | G24: Salaries | H24: Month | I24: 12 | J24: =9832*0.2 -> 1966.4 | K24: =I24*J24 -> 23596.8 | L24: 12 | M24: =L24*J24*$G$10 -> 24422.688 | N24: 12 | O24: =N24*J24*$G$10*$G$10 -> 25277.482 | P24: 12 | Q24: =P24*J24*1.015*$G$10*$G$10*$G$10 -> 26554.627 | R24: 6 | S24: =J24*R24*$G$10*$G$10*$G$10*$G$10 -> 13538.935 | T24: =SUM(K24+M24+O24+Q24+S24) -> 113390.53 | U24: 0 | V24: =SUM(T24:U24) -> 113390.53
A25: PERSNL-PO | B25: Timesheets | C25: 0 | D25: 0 | E25: 0 | F25: Program Officer (50%) | G25: Salaries | H25: Month | I25: 12 | J25: =5500*0.5 -> 2750 | K25: =I25*J25 -> 33000 | L25: 12 | M25: =L25*J25*$G$10 -> 34155 | N25: 12 | O25: =N25*J25*$G$10*$G$10 -> 35350.425 | P25: 12 | Q25: =P25*J25*1.015*$G$10*$G$10*$G$10 -> 37136.505 | R25: 6 | S25: =J25*R25*$G$10*$G$10*$G$10*$G$10 -> 18934.13 | T25: =SUM(K25+M25+O25+Q25+S25) -> 158576.06 | U25: 0 | V25: =SUM(T25:U25) -> 158576.06
F27: Subtotal | K27: =SUM(K15:K25) -> 367588.8 | M27: =SUM(M15:M25) -> 390390.41 | O27: =SUM(O15:O25) -> 369513.49 | Q27: =SUM(Q15:Q25) -> 344578.15 | S27: =SUM(S15:S25) -> 168339.79 | T27: =SUM(K27+M27+O27+Q27+S27) -> 1640410.6 | U27: 0 | V27: =SUM(T27:U27) -> 1640410.6
F29: Fringe Benefits
A30: FRINGE-MX | B30: 70015 | C30: MEX | D30: MEX | E30: 0 | F30: Fringe benefits - Mexico Staff | G30: Fringe Benefits | J30: 0.5084 | K30: =SUM(K16,K19,K20,K21)*J30 -> 79310.4 | M30: =SUM(M16,M19,M20,M21)*J30 -> 87137.726 | O30: =SUM(O15,O16,O19,O20,O21)*J30 -> 157037.43 | Q30: =SUM(Q15,Q16,Q19,Q20,Q21)*J30 -> 142802.96 | S30: =SUM(S15,S16,S19,S20,S21)*J30 -> 69074.642 | T30: =SUM(K30+M30+O30+Q30+S30) -> 535363.16 | U30: 0 | V30: =SUM(T30:U30) -> 535363.16
A31: FRINGE | B31: Timesheets | C31: 0 | D31: 0 | E31: 0 | F31: Fringe benefits - Home Office Support | G31: Fringe Benefits | J31: 0.2181 | K31: =SUM(K15,K24:K25)*$J$31 -> 46147.517 | M31: =SUM(M15,M24:M25)*$J$31 -> 47762.68 | O31: =SUM(O24:O25)*$J$31 -> 13222.947 | Q31: =SUM(Q24:Q25)*$J$31 -> 13891.036 | S31: =SUM(S24:S25)*$J$31 -> 7082.3755 | T31: =SUM(K31+M31+O31+Q31+S31) -> 128106.56 | U31: 0 | V31: =SUM(T31:U31) -> 128106.56
F33: Subtotal Direct Labor | K33: =SUM(K27:K31) -> 493046.72 | M33: =SUM(M27:M31) -> 525290.81 | O33: =SUM(O27:O31) -> 539773.87 | Q33: =SUM(Q27:Q31) -> 501272.15 | S33: =SUM(S27:S31) -> 244496.81 | T33: =K33+M33+O33+Q33+S33 -> 2303880.4 | U33: =SUM(U27:U31) -> 0 | V33: =SUM(T33:U33) -> 2303880.4
F34: Travel
F35: T1: Post-award Meeting with ILAB
A36: MX.T1.A | B36: 86040 | C36: MEX | D36: MEX | E36: 0 | F36: Airfare - Mexico-DC | G36: Travel | H36: Trip | I36: 2 | J36: 750 | K36: =I36*J36 -> 1500 | L36: 0 | M36: =L36*J36 -> 0 | N36: 0 | O36: =N36*J36 -> 0 | P36: 0 | Q36: =P36*J36 -> 0 | R36: 0 | S36: =R36*J36 -> 0 | T36: =K36+M36+O36+Q36+S36 -> 1500 | U36: - | V36: =SUM(T36:U36) -> 1500
A37: MX.T1.B | B37: 86030 (Lodging)/ 86050 (M&IE) | C37: MEX | D37: MEX | E37: 0 | F37: Lodging and M&IE in DC | G37: Travel | H37: Day | I37: =5*2 -> 10 | J37: =68.4+210 -> 278.4 | K37: =I37*J37 -> 2784 | L37: 0 | M37: =L37*J37 -> 0 | N37: 0 | O37: =N37*J37 -> 0 | P37: 0 | Q37: =P37*J37 -> 0 | R37: 0 | S37: =R37*J37 -> 0 | T37: =K37+M37+O37+Q37+S37 -> 2784 | U37: - | V37: =SUM(T37:U37) -> 2784
A38: MX.T1.C | B38: 86000 | C38: MEX | D38: MEX | E38: 0 | F38: Local transportation in DC | G38: Travel | H38: Day | I38: 5 | J38: 30 | K38: =I38*J38 -> 150 | L38: 0 | M38: =L38*J38 -> 0 | N38: 0 | O38: =N38*J38 -> 0 | P38: 0 | Q38: =P38*J38 -> 0 | R38: 0 | S38: =R38*J38 -> 0 | T38: =K38+M38+O38+Q38+S38 -> 150 | U38: - | V38: =SUM(T38:U38) -> 150
A39: MX.T1.D | B39: 86050 | C39: MEX | D39: MEX | E39: 0 | F39: U.S. Visa Fees | G39: Travel | H39: Trip | I39: 2 | J39: 160 | K39: =I39*J39 -> 320 | L39: 0 | M39: =L39*J39 -> 0 | N39: 0 | O39: =N39*J39 -> 0 | P39: 0 | Q39: =P39*J39 -> 0 | R39: 0 | S39: =R39*J39 -> 0 | T39: =K39+M39+O39+Q39+S39 -> 320 | U39: - | V39: =SUM(T39:U39) -> 320
F40: T2: Field Personnel Annual Visits with ILAB
A41: MX.T2.A | B41: 86040 | C41: MEX | D41: MEX | E41: 0 | F41: Airfare - Mexico-DC | G41: Travel | H41: Trip | I41: 0 | J41: 750 | K41: =I41*J41 -> 0 | L41: 1 | M41: =L41*J41*$G$9 -> 780 | N41: 2 | O41: =N41*J41*$G$9*$G$9 -> 1622.4 | P41: 1 | Q41: =P41*J41*$G$9*$G$9*$G$9 -> 843.648 | R41: 1 | S41: =R41*J41*$G$9*$G$9*$G$9*$G$9 -> 877.39392 | T41: =K41+M41+O41+Q41+S41 -> 4123.4419 | U41: - | V41: =SUM(T41:U41) -> 4123.4419
A42: MX.T2.B | B42: 86030 (Lodging)/ 86050 (M&IE) | C42: MEX | D42: MEX | E42: 0 | F42: Lodging and M&IE in DC | G42: Travel | H42: Day | I42: 0 | J42: =68.4+210 -> 278.4 | K42: =I42*J42 -> 0 | L42: 8 | M42: =L42*J42*$G$9 -> 2316.288 | N42: 16 | O42: =N42*J42*$G$9*$G$9 -> 4817.879 | P42: 8 | Q42: =P42*J42*$G$9*$G$9*$G$9 -> 2505.2971 | R42: 8 | S42: =R42*J42*$G$9*$G$9*$G$9*$G$9 -> 2605.509 | T42: =K42+M42+O42+Q42+S42 -> 12244.973 | U42: - | V42: =SUM(T42:U42) -> 12244.973
A43: MX.T2.C | B43: 86000 | C43: MEX | D43: MEX | E43: 0 | F43: Local transportation in DC | G43: Travel | H43: Day | I43: 0 | J43: 30 | K43: =I43*J43 -> 0 | L43: 8 | M43: =L43*J43*$G$9 -> 249.6 | N43: 8 | O43: =N43*J43*$G$9*$G$9 -> 259.584 | P43: 8 | Q43: =P43*J43*$G$9*$G$9*$G$9 -> 269.96736 | R43: 8 | S43: =R43*J43*$G$9*$G$9*$G$9*$G$9 -> 280.76605 | T43: =K43+M43+O43+Q43+S43 -> 1059.9174 | U43: - | V43: =SUM(T43:U43) -> 1059.9174
F44: T3: Project Management Travel to Field
A45: MX.T3.A | B45: 86040 | C45: 0 | D45: 0 | E45: 0 | F45: Airfare - DC-Mexico | G45: Travel | H45: Trip | I45: 1 | J45: 750 | K45: =I45*J45 -> 750 | L45: 2 | M45: =L45*J45*$G$9 -> 1560 | N45: 2 | O45: =N45*J45*$G$9*$G$9 -> 1622.4 | P45: 2 | Q45: =P45*J45*$G$9*$G$9*$G$9 -> 1687.296 | R45: 1 | S45: =R45*J45*$G$9*$G$9*$G$9*$G$9 -> 877.39392 | T45: =K45+M45+O45+Q45+S45 -> 6497.0899 | U45: - | V45: =SUM(T45:U45) -> 6497.0899
A46: MX.T3.B | B46: 86030 (Lodging)/ 86050 (M&IE) | C46: 0 | D46: 0 | E46: 0 | F46: Lodging and M&IE | G46: Travel | H46: Day | I46: 5 | J46: =106.2+210 -> 316.2 | K46: =I46*J46 -> 1581 | L46: 10 | M46: =L46*J46*$G$9 -> 3288.48 | N46: 10 | O46: =N46*J46*$G$9*$G$9 -> 3420.0192 | P46: 10 | Q46: =P46*J46*$G$9*$G$9*$G$9 -> 3556.82 | R46: 5 | S46: =R46*J46*$G$9*$G$9*$G$9*$G$9 -> 1849.5464 | T46: =K46+M46+O46+Q46+S46 -> 13695.866 | U46: - | V46: =SUM(T46:U46) -> 13695.866
...

Sheet CFO
A1: Entity: | B1: P | G1: Name of Project: Mexico Awareness Raising Project
A2: Program-Dept.: | B2: CCL | G2: Name of Subawardee: Comité Fronterizo de Obreros (CFO)
A3: Funder-Grant: | B3: DOL423 | G3: Subaward Budget
G4: Budget Assumptions:
G5: Inflation - Locally Purchased Goods/Services | H5: 1.05
G6: Merit Based Increases for Field Staff | H6: 1.035
A7: Sage Activity | B7: Sage Object Code/ Line Item | C7: Country Code (DC=0 or MX) | D7: Office Code (DC=0 or MX) | E7: Subcontract Code | F7: Open1 Code | G7: BUDGET ITEM | H7: CATEGORY | I7: UNIT | J7: # of Units | K7: RATE/ UNIT | L7: YEAR 1 | M7: # of Units | N7: YEAR 2 | O7: # of Units | P7: YEAR 3 | Q7: # of Units | R7: YEAR 4 | S7: # of Units | T7: YEAR 5 | U7: TOTAL CFO | V7: TOTAL COST SHARING | W7: PROJECT GRAND TOTAL | X7: Percentage 95% to Outcome 1 | Y7: Percentage 5% to Outcome 3
G8: Direct Labor
G9: Personnel
A10: MX.1.1.A (Outcome 1)/ MX.3.7.A (M&E) | B10: 89050 | C10: MX | D10: MX | E10: CFO | F10: CFOPERSLLC | G10: Lead Coordinator for the Project (50%) | H10: Salaries | I10: Month | J10: 3 | K10: 1200 | L10: =J10*K10 -> 3600 | M10: 12 | N10: =M10*K10*$H$6 -> 14904 | O10: 12 | P10: =O10*K10*$H$6*$H$6 -> 15425.64 | Q10: 12 | R10: =Q10*K10*$H$6*$H$6*$H$6 -> 15965.537 | S10: 0 | T10: =S10*K10*$H$6*$H$6*$H$6*$H$6 -> 0 | U10: =SUM(L10+N10+P10+R10+T10) -> 49895.177 | V10: 0 | W10: =SUM(U10:V10) -> 49895.177 | X10: =W10*0.95 -> 47400.419 | Y10: =W10-X10 -> 2494.7589
A11: MX.1.1.A (Outcome 1)/ MX.3.7.A (M&E) | B11: 89050 | C11: MX | D11: MX | E11: CFO | F11: CFOPERSLGC | G11: Gender Coordinator (50%) | H11: Salaries | I11: Month | J11: 3 | K11: 800 | L11: =J11*K11 -> 2400 | M11: 12 | N11: =M11*K11*$H$6 -> 9936 | O11: 12 | P11: =O11*K11*$H$6*$H$6 -> 10283.76 | Q11: 12 | R11: =Q11*K11*$H$6*$H$6*$H$6 -> 10643.692 | S11: 0 | T11: =S11*K11*$H$6*$H$6*$H$6*$H$6 -> 0 | U11: =SUM(L11+N11+P11+R11+T11) -> 33263.452 | V11: 0 | W11: =SUM(U11:V11) -> 33263.452 | X11: =W11*0.95 -> 31600.279 | Y11: =W11-X11 -> 1663.1726
A12: MX.1.1.A (Outcome 1)/ MX.3.7.A (M&E) | B12: 89050 | C12: MX | D12: MX | E12: CFO | F12: CFOPERSLAA | G12: Administrative Assistant (50%) | H12: Salaries | I12: Month | J12: 3 | K12: 400 | L12: =J12*K12 -> 1200 | M12: 12 | N12: =M12*K12*$H$6 -> 4968 | O12: 12 | P12: =O12*K12*$H$6*$H$6 -> 5141.88 | Q12: 12 | R12: =Q12*K12*$H$6*$H$6*$H$6 -> 5321.8458 | S12: 0 | T12: =S12*K12*$H$6*$H$6*$H$6*$H$6 -> 0 | U12: =SUM(L12+N12+P12+R12+T12) -> 16631.726 | V12: 0 | W12: =SUM(U12:V12) -> 16631.726 | X12: =W12*0.95 -> 15800.14 | Y12: =W12-X12 -> 831.58629
A13: MX.1.1.A (Outcome 1)/ MX.3.7.A (M&E) | B13: 89050 | C13: MX | D13: MX | E13: CFO | F13: CFOPERSLP1 | G13: Promoter 1 (100%) | H13: Salaries | I13: Month | J13: 3 | K13: 200 | L13: =J13*K13 -> 600 | M13: 12 | N13: =M13*K13*$H$6 -> 2484 | O13: 12 | P13: =O13*K13*$H$6*$H$6 -> 2570.94 | Q13: 12 | R13: =Q13*K13*$H$6*$H$6*$H$6 -> 2660.9229 | S13: 0 | T13: =S13*K13*$H$6*$H$6*$H$6*$H$6 -> 0 | U13: =SUM(L13+N13+P13+R13+T13) -> 8315.8629 | V13: 0 | W13: =SUM(U13:V13) -> 8315.8629 | X13: =W13*0.95 -> 7900.0698 | Y13: =W13-X13 -> 415.79315
A14: MX.1.1.A (Outcome 1)/ MX.3.7.A (M&E) | B14: 89050 | C14: MX | D14: MX | E14: CFO | F14: CFOPERSLP2 | G14: Promoter 2 (100%) | H14: Salaries | I14: Month | J14: 3 | K14: 200 | L14: =J14*K14 -> 600 | M14: 12 | N14: =M14*K14*$H$6 -> 2484 | O14: 12 | P14: =O14*K14*$H$6*$H$6 -> 2570.94 | Q14: 12 | R14: =Q14*K14*$H$6*$H$6*$H$6 -> 2660.9229 | S14: 0 | T14: =S14*K14*$H$6*$H$6*$H$6*$H$6 -> 0 | U14: =SUM(L14+N14+P14+R14+T14) -> 8315.8629 | V14: 0 | W14: =SUM(U14:V14) -> 8315.8629 | X14: =W14*0.95 -> 7900.0698 | Y14: =W14-X14 -> 415.79315
A15: MX.1.1.A (Outcome 1)/ MX.3.7.A (M&E) | B15: 89050 | C15: MX | D15: MX | E15: CFO | F15: CFOPERSLP3 | G15: Promoter 3 (100%) | H15: Salaries | I15: Month | J15: 3 | K15: 200 | L15: =J15*K15 -> 600 | M15: 12 | N15: =M15*K15*$H$6 -> 2484 | O15: 12 | P15: =O15*K15*$H$6*$H$6 -> 2570.94 | Q15: 12 | R15: =Q15*K15*$H$6*$H$6*$H$6 -> 2660.9229 | S15: 0 | T15: =S15*K15*$H$6*$H$6*$H$6*$H$6 -> 0 | U15: =SUM(L15+N15+P15+R15+T15) -> 8315.8629 | V15: 0 | W15: =SUM(U15:V15) -> 8315.8629 | X15: =W15*0.95 -> 7900.0698 | Y15: =W15-X15 -> 415.79315
G17: Subtotal | L17: =SUM(L10:L15) -> 9000 | N17: =SUM(N10:N15) -> 37260 | P17: =SUM(P10:P15) -> 38564.1 | R17: =SUM(R10:R15) -> 39913.843 | T17: =SUM(T10:T15) -> 0 | U17: =SUM(L17+N17+P17+R17+T17) -> 124737.94 | V17: =SUM(V10:V15) -> 0 | W17: =SUM(U17:V17) -> 124737.94
G19: Fringe Benefits
A20: MX.1.1.A (Outcome 1)/ MX.3.7.A (M&E) | B20: 89050 | C20: MX | D20: MX | E20: CFO | F20: CFOFRINGE | G20: Fringe benefits | H20: Fringe benefits | K20: 0.5 | L20: =K20*L17 -> 4500 | N20: =K20*N17 -> 18630 | P20: =K20*P17 -> 19282.05 | R20: =R17*K20 -> 19956.922 | T20: =K20*T17 -> 0 | U20: =SUM(T20,R20,P20,N20,L20) -> 62368.972 | V20: 0 | W20: =SUM(U20:V20) -> 62368.972 | X20: =W20*0.95 -> 59250.523 | Y20: =W20-X20 -> 3118.4486
G22: Subtotal Direct Labor | L22: =SUM(L17:L20) -> 13500 | N22: =SUM(N17:N20) -> 55890 | P22: =SUM(P17:P20) -> 57846.15 | R22: =SUM(R17:R20) -> 59870.765 | T22: =SUM(T17:T20) -> 0 | U22: =L22+N22+P22+R22+T22 -> 187106.92 | V22: =SUM(V9:V20) -> 0 | W22: =SUM(U22:V22) -> 187106.92
G24: Travel
G25: T1. Meetings with POA in Mexico City
A26: MX.1.1.A (Outcome 1)/ MX.3.7.A (M&E) | B26: 89050 | C26: MX | D26: MX | E26: CFO | F26: CFOT1AIR | G26: Project Staff - Airfare | H26: Travel | I26: Trip | J26: 1 | K26: 375 | L26: =J26*K26 -> 375 | M26: 2 | N26: =M26*K26*$H$5 -> 787.5 | O26: 2 | P26: =O26*K26*$H$5*$H$5 -> 826.875 | Q26: 2 | R26: =Q26*K26*$H$5*$H$5*$H$5 -> 868.21875 | S26: 0 | T26: =S26*K26*$H$5*$H$5*$H$5*$H$5 -> 0 | U26: =L26+N26+P26+R26+T26 -> 2857.5938 | V26: - | W26: =SUM(U26:V26) -> 2857.5938 | X26: =W26*0.95 -> 2714.7141 | Y26: =W26-X26 -> 142.87969
A27: MX.1.1.A (Outcome 1)/ MX.3.7.A (M&E) | B27: 89050 | C27: MX | D27: MX | E27: CFO | F27: CFOT1LODME | G27: Project Staff - Lodging and M&IE | H27: Travel | I27: Day | J27: 7 | K27: 110 | L27: =J27*K27 -> 770 | M27: 14 | N27: =M27*K27*$H$5 -> 1617 | O27: 14 | P27: =O27*K27*$H$5*$H$5 -> 1697.85 | Q27: 14 | R27: =Q27*K27*$H$5*$H$5*$H$5 -> 1782.7425 | S27: 0 | T27: =S27*K27*$H$5*$H$5*$H$5*$H$5 -> 0 | U27: =L27+N27+P27+R27+T27 -> 5867.5925 | V27: - | W27: =SUM(U27:V27) -> 5867.5925 | X27: =W27*0.95 -> 5574.2129 | Y27: =W27-X27 -> 293.37963
A28: MX.1.1.A (Outcome 1)/ MX.3.7.A (M&E) | B28: 89050 | C28: MX | D28: MX | E28: CFO | F28: CFOT1TRANS | G28: Project Staff - Ground Transportation | H28: Travel | I28: Day | J28: 7 | K28: 25 | L28: =J28*K28 -> 175 | M28: 14 | N28: =M28*K28*$H$5 -> 367.5 | O28: 14 | P28: =O28*K28*$H$5*$H$5 -> 385.875 | Q28: 14 | R28: =Q28*K28*$H$5*$H$5*$H$5 -> 405.16875 | S28: 0 | T28: =S28*K28*$H$5*$H$5*$H$5*$H$5 -> 0 | U28: =L28+N28+P28+R28+T28 -> 1333.5438 | V28: - | W28: =SUM(U28:V28) -> 1333.5438 | X28: =W28*0.95 -> 1266.8666 | Y28: =W28-X28 -> 66.677188
G30: Subtotal Travel | L30: =SUM(L26:L28) -> 1320 | N30: =SUM(N26:N28) -> 2772 | P30: =SUM(P26:P28) -> 2910.6 | R30: =SUM(R26:R28) -> 3056.13 | T30: =SUM(T26:T28) -> 0 | U30: =L30+N30+P30+R30+T30 -> 10058.73 | V30: =SUM(V26:V28) -> 0 | W30: =SUM(U30:V30) -> 10058.73
G31: Supplies
A32: MX.1.1.A (Outcome 1)/ MX.3.7.A (M&E) | B32: 89050 | C32: MX | D32: MX | E32: CFO | F32: CFOLAPTOP | G32: Laptops and software | H32: Supplies | I32: Unit | J32: 4 | K32: 650 | L32: =J32*K32 -> 2600 | M32: 0 | N32: =M32*K32*$H$5 -> 0 | O32: 0 | P32: =O32*K32*$H$5*$H$5 -> 0 | Q32: 0 | R32: =Q32*K32*$H$5*$H$5*$H$5 -> 0 | S32: 0 | T32: =S32*K32*$H$5*$H$5*$H$5*$H$5 -> 0 | U32: =L32+N32+P32+R32+T32 -> 2600 | V32: 0 | W32: =SUM(U32:V32) -> 2600 | X32: =W32*0.95 -> 2470 | Y32: =W32-X32 -> 130
A33: MX.1.1.A (Outcome 1)/ MX.3.7.A (M&E) | B33: 89050 | C33: MX | D33: MX | E33: CFO | F33: CFOPHONE | G33: Cellphone | H33: Supplies | I33: Unit | J33: 2 | K33: 600 | L33: =J33*K33 -> 1200 | M33: 0 | N33: =M33*K33*$H$5 -> 0 | O33: 0 | P33: =O33*K33*$H$5*$H$5 -> 0 | Q33: 0 | R33: =Q33*K33*$H$5*$H$5*$H$5 -> 0 | S33: 0 | T33: =S33*K33*$H$5*$H$5*$H$5*$H$5 -> 0 | U33: =L33+N33+P33+R33+T33 -> 1200 | V33: 0 | W33: =SUM(U33:V33) -> 1200 | X33: =W33*0.95 -> 1140 | Y33: =W33-X33 -> 60
A34: MX.1.1.A (Outcome 1)/ MX.3.7.A (M&E) | B34: 89050 | C34: MX | D34: MX | E34: CFO | F34: CFOPRINT | G34: Printer and copier | H34: Supplies | I34: Unit | J34: 1 | K34: 300 | L34: =J34*K34 -> 300 | M34: 0 | N34: =M34*K34*$H$5 -> 0 | O34: 0 | P34: =O34*K34*$H$5*$H$5 -> 0 | Q34: 0 | R34: =Q34*K34*$H$5*$H$5*$H$5 -> 0 | S34: 0 | T34: =S34*K34*$H$5*$H$5*$H$5*$H$5 -> 0 | U34: =L34+N34+P34+R34+T34 -> 300 | V34: 0 | W34: =SUM(U34:V34) -> 300 | X34: =W34*0.95 -> 285 | Y34: =W34-X34 -> 15
G36: Subtotal Supplies | L36: =SUM(L32:L34) -> 4100 | N36: =SUM(N32:N34) -> 0 | P36: =SUM(P32:P34) -> 0 | R36: =SUM(R32:R34) -> 0 | T36: =SUM(T32:T34) -> 0 | U36: =L36+N36+P36+R36+T36 -> 4100 | V36: =SUM(V32:V34) -> 0 | W36: =SUM(U36:V36) -> 4100
G37: Office Expenses
A38: MX.1.1.A (Outcome 1)/ MX.3.7.A (M&E) | B38: 89050 | C38: MX | D38: MX | E38: CFO | F38: CFOBANKFEE | G38: Banking and cash handling fees | H38: Office Expenses | I38: Month | J38: 1 | K38: 30 | L38: =J38*K38 -> 30 | M38: 12 | N38: =M38*K38*$H$5 -> 378 | O38: 12 | P38: =O38*K38*$H$5*$H$5 -> 396.9 | Q38: 12 | R38: =Q38*K38*$H$5*$H$5*$H$5 -> 416.745 | S38: 0 | T38: =S38*K38*$H$5*$H$5*$H$5*$H$5 -> 0 | U38: =L38+N38+P38+R38+T38 -> 1221.645 | V38: 0 | W38: =SUM(U38:V38) -> 1221.645 | X38: =W38*0.95 -> 1160.5628 | Y38: =W38-X38 -> 61.08225
A39: MX.1.1.A (Outcome 1)/ MX.3.7.A (M&E) | B39: 89050 | C39: MX | D39: MX | E39: CFO | F39: CFOPOSTAGE | G39: Courier fees/services/postage | H39: Office Expenses | I39: Year | J39: 0 | K39: 50 | L39: =J39*K39 -> 0 | M39: 1 | N39: =M39*K39*$H$5 -> 52.5 | O39: 1 | P39: =O39*K39*$H$5*$H$5 -> 55.125 | Q39: 1 | R39: =Q39*K39*$H$5*$H$5*$H$5 -> 57.88125 | S39: 0 | T39: =S39*K39*$H$5*$H$5*$H$5*$H$5 -> 0 | U39: =L39+N39+P39+R39+T39 -> 165.50625 | V39: 0 | W39: =SUM(U39:V39) -> 165.50625 | X39: =W39*0.95 -> 157.23094 | Y39: =W39-X39 -> 8.2753125
A40: MX.1.1.A (Outcome 1)/ MX.3.7.A (M&E) | B40: 89050 | C40: MX | D40: MX | E40: CFO | F40: CFOEMAIL | G40: Email/Internet | H40: Office Expenses | I40: Month | J40: 3 | K40: 40 | L40: =J40*K40 -> 120 | M40: 12 | N40: =M40*K40*$H$5 -> 504 | O40: 12 | P40: =O40*K40*$H$5*$H$5 -> 529.2 | Q40: 12 | R40: =Q40*K40*$H$5*$H$5*$H$5 -> 555.66 | S40: 0 | T40: =S40*K40*$H$5*$H$5*$H$5*$H$5 -> 0 | U40: =L40+N40+P40+R40+T40 -> 1708.86 | V40: 0 | W40: =SUM(U40:V40) -> 1708.86 | X40: =W40*0.95 -> 1623.417 | Y40: =W40-X40 -> 85.443
A41: MX.1.1.A (Outcome 1)/ MX.3.7.A (M&E) | B41: 89050 | C41: MX | D41: MX | E41: CFO | F41: CFORENT | G41: Office Rent | H41: Office Expenses | I41: Month | J41: 3 | K41: 435 | L41: =J41*K41 -> 1305 | M41: 12 | N41: =M41*K41*$H$5 -> 5481 | O41: 12 | P41: =O41*K41*$H$5*$H$5 -> 5755.05 | Q41: 12 | R41: =Q41*K41*$H$5*$H$5*$H$5 -> 6042.8025 | S41: 0 | T41: =S41*K41*$H$5*$H$5*$H$5*$H$5 -> 0 | U41: =L41+N41+P41+R41+T41 -> 18583.853 | V41: 0 | W41: =SUM(U41:V41) -> 18583.853 | X41: =W41*0.95 -> 17654.66 | Y41: =W41-X41 -> 929.19262
A42: MX.1.1.A (Outcome 1)/ MX.3.7.A (M&E) | B42: 89050 | C42: MX | D42: MX | E42: CFO | F42: CFOUTILITY | G42: Office Utilities | H42: Office Expenses | I42: Month | J42: 3 | K42: 60 | L42: =J42*K42 -> 180 | M42: 12 | N42: =M42*K42*$H$5 -> 756 | O42: 12 | P42: =O42*K42*$H$5*$H$5 -> 793.8 | Q42: 12 | R42: =Q42*K42*$H$5*$H$5*$H$5 -> 833.49 | S42: 0 | T42: =S42*K42*$H$5*$H$5*$H$5*$H$5 -> 0 | U42: =L42+N42+P42+R42+T42 -> 2563.29 | V42: 0 | W42: =SUM(U42:V42) -> 2563.29 | X42: =W42*0.95 -> 2435.1255 | Y42: =W42-X42 -> 128.1645
A43: MX.1.1.A (Outcome 1)/ MX.3.7.A (M&E) | B43: 89050 | C43: MX | D43: MX | E43: CFO | F43: CFOMAINT | G43: Equipment and office repairs and maintenance | H43: Office Expenses | I43: Year | J43: 0 | K43: 250 | L43: =J43*K43 -> 0 | M43: 1 | N43: =M43*K43*$H$5 -> 262.5 | O43: 1 | P43: =O43*K43*$H$5*$H$5 -> 275.625 | Q43: 1 | R43: =Q43*K43*$H$5*$H$5*$H$5 -> 289.40625 | S43: 0 | T43: =S43*K43*$H$5*$H$5*$H$5*$H$5 -> 0 | U43: =L43+N43+P43+R43+T43 -> 827.53125 | V43: 0 | W43: =SUM(U43:V43) -> 827.53125 | X43: =W43*0.95 -> 786.15469 | Y43: =W43-X43 -> 41.376563
A44: MX.1.1.A (Outcome 1)/ MX.3.7.A (M&E) | B44: 89050 | C44: MX | D44: MX | E44: CFO | F44: CFOTRANS | G44: Translation Costs | H44: Office Expenses | I44: Month | J44: 0 | K44: 100 | L44: =J44*K44 -> 0 | M44: 12 | N44: =M44*K44*$H$5 -> 1260 | O44: 12 | P44: =O44*K44*$H$5*$H$5 -> 1323 | Q44: 12 | R44: =Q44*K44*$H$5*$H$5*$H$5 -> 1389.15 | S44: 0 | T44: =S44*K44*$H$5*$H$5*$H$5*$H$5 -> 0 | U44: =L44+N44+P44+R44+T44 -> 3972.15 | V44: 0 | W44: =SUM(U44:V44) -> 3972.15 | X44: =W44*0.95 -> 3773.5425 | Y44: =W44-X44 -> 198.6075
G46: Subtotal Office Expenses | L46: =SUM(L38:L44) -> 1635 | N46: =SUM(N38:N44) -> 8694 | P46: =SUM(P38:P44) -> 9128.7 | R46: =SUM(R38:R44) -> 9585.135 | T46: =SUM(T38:T44) -> 0 | U46: =L46+N46+P46+R46+T46 -> 29042.835 | V46: =SUM(V38:V44) -> 0 | W46: =SUM(U46:V46) -> 29042.835
G47: The above is only for percentage calculations for the below outcomes
...

Sheet CDM
A1: Entity: | B1: P | G1: Name of Project: Mexico Awareness Raising Project
A2: Program-Dept.: | B2: 20200 | G2: Name of Subawardee: Centro de los Derechos del Migrante (CDM)
A3: Funder-Grant: | B3: DOL423 | G3: Subaward Budget
G4: Budget Assumptions:
G5: Inflation - Locally Purchased Goods/Services | H5: 1.05
G6: Merit Based Increases for Staff | H6: 1.035
A7: Sage Activity | B7: Account Code | C7: Country Code | D7: Office Code | E7: Subcontract Code | F7: Sub Activity | G7: BUDGET ITEM | H7: CATEGORY | I7: UNIT | J7: # of Units | K7: RATE/ UNIT | L7: YEAR 1 | M7: # of Units | N7: YEAR 2 | O7: # of Units | P7: YEAR 3 | Q7: # of Units | R7: YEAR 4 | S7: # of Units | T7: YEAR 5 | U7: TOTAL CDM | V7: TOTAL COST SHARING | W7: PROJECT GRAND TOTAL | X7: Percentage 95% to Outcome 1 | Y7: Percentage 5% to Outcome 3
G8: Direct Labor
G9: Personnel
A10: MX.1.1.B (Outcome 1) / MX.3.7.B (M&E) | B10: 89050 | C10: MEX | D10: MEX | E10: CDM | F10: CDMPERSCDC | G10: Communications Director/Coordinator (100%) | H10: Salaries | I10: Month | J10: 6 | K10: =3500 -> 3500 | L10: =J10*K10 -> 21000 | M10: 12 | N10: =M10*K10*$H$6 -> 43470 | O10: 12 | P10: =O10*K10*$H$6*$H$6 -> 44991.45 | Q10: 12 | R10: =Q10*K10*$H$6*$H$6*$H$6 -> 46566.151 | S10: 0 | T10: =S10*K10*$H$6*$H$6*$H$6*$H$6 -> 0 | U10: =SUM(L10+N10+P10+R10+T10) -> 156027.6 | V10: 0 | W10: =SUM(U10:V10) -> 156027.6 | X10: =W10*0.95 -> 148226.22 | Y10: =W10-X10 -> 7801.38
A11: MX.1.1.B (Outcome 1) / MX.3.7.B (M&E) | B11: 89050 | C11: MEX | D11: MEX | E11: CDM | F11: CDMPERSSMS | G11: Social Media Strategist (100%) | H11: Salaries | I11: Month | J11: 6 | K11: =2800 -> 2800 | L11: =J11*K11 -> 16800 | M11: 12 | N11: =M11*K11*$H$6 -> 34776 | O11: 12 | P11: =O11*K11*$H$6*$H$6 -> 35993.16 | Q11: 12 | R11: =Q11*K11*$H$6*$H$6*$H$6 -> 37252.921 | S11: 0 | T11: =S11*K11*$H$6*$H$6*$H$6*$H$6 -> 0 | U11: =SUM(L11+N11+P11+R11+T11) -> 124822.08 | V11: 0 | W11: =SUM(U11:V11) -> 124822.08 | X11: =W11*0.95 -> 118580.98 | Y11: =W11-X11 -> 6241.104
A12: MX.1.1.B (Outcome 1) / MX.3.7.B (M&E) | B12: 89050 | C12: MEX | D12: MEX | E12: CDM | F12: CDMPERSAA | G12: Administration Assistant (100%) | H12: Salaries | I12: Month | J12: 6 | K12: =2200 -> 2200 | L12: =J12*K12 -> 13200 | M12: 12 | N12: =M12*K12*$H$6 -> 27324 | O12: 12 | P12: =O12*K12*$H$6*$H$6 -> 28280.34 | Q12: 12 | R12: =Q12*K12*$H$6*$H$6*$H$6 -> 29270.152 | S12: 0 | T12: =S12*K12*$H$6*$H$6*$H$6*$H$6 -> 0 | U12: =SUM(L12+N12+P12+R12+T12) -> 98074.492 | V12: 0 | W12: =SUM(U12:V12) -> 98074.492 | X12: =W12*0.95 -> 93170.767 | Y12: =W12-X12 -> 4903.7246
A13: MX.1.1.B (Outcome 1) / MX.3.7.B (M&E) | B13: 89050 | C13: MEX | D13: MEX | E13: CDM | F13: CDMPERSPM | G13: Partnerships Manager (50%) | H13: Salaries | I13: Month | J13: 6 | K13: =2300*50% -> 1150 | L13: =J13*K13 -> 6900 | M13: 12 | N13: =M13*K13*$H$6 -> 14283 | O13: 12 | P13: =O13*K13*$H$6*$H$6 -> 14782.905 | Q13: 12 | R13: =Q13*K13*$H$6*$H$6*$H$6 -> 15300.307 | S13: 0 | T13: =S13*K13*$H$6*$H$6*$H$6*$H$6 -> 0 | U13: =SUM(L13+N13+P13+R13+T13) -> 51266.212 | V13: 0 | W13: =SUM(U13:V13) -> 51266.212 | X13: =W13*0.95 -> 48702.901 | Y13: =W13-X13 -> 2563.3106
G15: Subtotal | L15: =SUM(L10:L13) -> 57900 | N15: =SUM(N10:N13) -> 119853 | P15: =SUM(P10:P13) -> 124047.85 | R15: =SUM(R10:R13) -> 128389.53 | T15: =SUM(T10:T13) -> 0 | U15: =SUM(L15+N15+P15+R15+T15) -> 430190.38 | V15: =SUM(V10:V13) -> 0 | W15: =SUM(U15:V15) -> 430190.38
G17: Fringe Benefits
A18: MX.1.1.B (Outcome 1) / MX.3.7.B (M&E) | B18: 89050 | C18: MEX | D18: MEX | E18: CDM | F18: CDMFRINGE | G18: Fringe benefits | H18: Fringe benefits | K18: 0.304 | L18: =K18*L15 -> 17601.6 | N18: =K18*N15 -> 36435.312 | P18: =K18*P15 -> 37710.548 | R18: =R15*K18 -> 39030.417 | T18: =K18*T15 -> 0 | U18: =SUM(T18,R18,P18,N18,L18) -> 130777.88 | V18: 0 | W18: =SUM(U18:V18) -> 130777.88 | X18: =W18*0.95 -> 124238.98 | Y18: =W18-X18 -> 6538.8939
G20: Subtotal Direct Labor | L20: =SUM(L15:L18) -> 75501.6 | N20: =SUM(N15:N18) -> 156288.31 | P20: =SUM(P15:P18) -> 161758.4 | R20: =SUM(R15:R18) -> 167419.95 | T20: =SUM(T15:T18) -> 0 | U20: =L20+N20+P20+R20+T20 -> 560968.26 | V20: =SUM(V9:V18) -> 0 | W20: =SUM(U20:V20) -> 560968.26
G21: T1. Meetings with POA
A22: MX.1.1.B (Outcome 1) / MX.3.7.B (M&E) | B22: 89050 | C22: MEX | D22: MEX | E22: CDM | F22: CDMGROUND | G22: Project Staff - Ground Transportation | H22: Travel | I22: Day | J22: 6 | K22: 30 | L22: =J22*K22 -> 180 | M22: 6 | N22: =M22*K22*$H$5 -> 189 | O22: 6 | P22: =O22*K22*$H$5*$H$5 -> 198.45 | Q22: 6 | R22: =Q22*K22*$H$5*$H$5*$H$5 -> 208.3725 | S22: 0 | T22: =S22*K22*$H$5*$H$5*$H$5*$H$5 -> 0 | U22: =L22+N22+P22+R22+T22 -> 775.8225 | V22: - | W22: =SUM(U22:V22) -> 775.8225 | X22: =W22*0.95 -> 737.03138 | Y22: =W22-X22 -> 38.791125
G24: Subtotal Travel | L24: =SUM(L22:L22) -> 180 | N24: =SUM(N22:N22) -> 189 | P24: =SUM(P22:P22) -> 198.45 | R24: =SUM(R22:R22) -> 208.3725 | T24: =SUM(T22:T22) -> 0 | U24: =L24+N24+P24+R24+T24 -> 775.8225 | V24: =SUM(V22:V22) -> 0 | W24: =SUM(U24:V24) -> 775.8225
G25: Supplies - Under $5,000 USD
A26: MX.1.1.B (Outcome 1) / MX.3.7.B (M&E) | B26: 89050 | C26: MEX | D26: MEX | E26: CDM | F26: CDMLAPTOP | G26: Laptops and software | H26: Supplies | I26: Device | J26: 4 | K26: 800 | L26: =J26*K26 -> 3200 | M26: 0 | N26: =M26*K26*$H$5 -> 0 | O26: 0 | P26: =O26*K26*$H$5*$H$5 -> 0 | Q26: 0 | R26: =Q26*K26*$H$5*$H$5*$H$5 -> 0 | S26: 0 | T26: =S26*K26*$H$5*$H$5*$H$5*$H$5 -> 0 | U26: =L26+N26+P26+R26+T26 -> 3200 | V26: 0 | W26: =SUM(U26:V26) -> 3200 | X26: =W26*0.95 -> 3040 | Y26: =W26-X26 -> 160
A27: MX.1.1.B (Outcome 1) / MX.3.7.B (M&E) | B27: 89050 | C27: MEX | D27: MEX | E27: CDM | F27: CDMPHONE | G27: Cellphone | H27: Supplies | I27: Device | J27: 1 | K27: 550 | L27: =J27*K27 -> 550 | M27: 0 | N27: =M27*K27*$H$5 -> 0 | O27: 0 | P27: =O27*K27*$H$5*$H$5 -> 0 | Q27: 0 | R27: =Q27*K27*$H$5*$H$5*$H$5 -> 0 | S27: 0 | T27: =S27*K27*$H$5*$H$5*$H$5*$H$5 -> 0 | U27: =L27+N27+P27+R27+T27 -> 550 | V27: 0 | W27: =SUM(U27:V27) -> 550 | X27: =W27*0.95 -> 522.5 | Y27: =W27-X27 -> 27.5
A28: MX.1.1.B (Outcome 1) / MX.3.7.B (M&E) | B28: 89050 | C28: MEX | D28: MEX | E28: CDM | F28: CDMSUPPLY | G28: Office Supplies | H28: Supplies | I28: Month | J28: 6 | K28: 125 | L28: =J28*K28 -> 750 | M28: 12 | N28: =M28*K28*$H$5 -> 1575 | O28: 12 | P28: =O28*K28*$H$5*$H$5 -> 1653.75 | Q28: 12 | R28: =Q28*K28*$H$5*$H$5*$H$5 -> 1736.4375 | S28: 0 | T28: =S28*K28*$H$5*$H$5*$H$5*$H$5 -> 0 | U28: =L28+N28+P28+R28+T28 -> 5715.1875 | V28: 0 | W28: =SUM(U28:V28) -> 5715.1875 | X28: =W28*0.95 -> 5429.4281 | Y28: =W28-X28 -> 285.75938
G30: Subtotal Supplies | L30: =SUM(L26:L28) -> 4500 | N30: =SUM(N26:N28) -> 1575 | P30: =SUM(P26:P28) -> 1653.75 | R30: =SUM(R26:R28) -> 1736.4375 | T30: =SUM(T26:T28) -> 0 | U30: =L30+N30+P30+R30+T30 -> 9465.1875 | V30: =SUM(V26:V28) -> 0 | W30: =SUM(U30:V30) -> 9465.1875
G31: Office Expenses
A32: MX.1.1.B (Outcome 1) / MX.3.7.B (M&E) | B32: 89050 | C32: MEX | D32: MEX | E32: CDM | F32: CDMBANKFEE | G32: Banking and cash handling fees | H32: Office Expenses | I32: Month | J32: 5 | K32: 30 | L32: =J32*K32 -> 150 | M32: 12 | N32: =M32*K32*$H$5 -> 378 | O32: 12 | P32: =O32*K32*$H$5*$H$5 -> 396.9 | Q32: 12 | R32: =Q32*K32*$H$5*$H$5*$H$5 -> 416.745 | S32: 0 | T32: =S32*K32*$H$5*$H$5*$H$5*$H$5 -> 0 | U32: =L32+N32+P32+R32+T32 -> 1341.645 | V32: 0 | W32: =SUM(U32:V32) -> 1341.645 | X32: =W32*0.95 -> 1274.5628 | Y32: =W32-X32 -> 67.08225
A33: MX.1.1.B (Outcome 1) / MX.3.7.B (M&E) | B33: 89050 | C33: MEX | D33: MEX | E33: CDM | F33: CDMPOSTAGE | G33: Courier fees/services/postage | H33: Office Expenses | I33: Year | J33: 0 | K33: 50 | L33: =J33*K33 -> 0 | M33: 1 | N33: =M33*K33*$H$5 -> 52.5 | O33: 1 | P33: =O33*K33*$H$5*$H$5 -> 55.125 | Q33: 1 | R33: =Q33*K33*$H$5*$H$5*$H$5 -> 57.88125 | S33: 0 | T33: =S33*K33*$H$5*$H$5*$H$5*$H$5 -> 0 | U33: =L33+N33+P33+R33+T33 -> 165.50625 | V33: 0 | W33: =SUM(U33:V33) -> 165.50625 | X33: =W33*0.95 -> 157.23094 | Y33: =W33-X33 -> 8.2753125
A34: MX.1.1.B (Outcome 1) / MX.3.7.B (M&E) | B34: 89050 | C34: MEX | D34: MEX | E34: CDM | F34: CDMADVERT | G34: Recruitment/Procurement Advertising | H34: Office Expenses | I34: Year | J34: 3 | K34: 300 | L34: =J34*K34 -> 900 | M34: 0 | N34: =M34*K34*$H$5 -> 0 | O34: 0 | P34: =O34*K34*$H$5*$H$5 -> 0 | Q34: 0 | R34: =Q34*K34*$H$5*$H$5*$H$5 -> 0 | S34: 0 | T34: =S34*K34*$H$5*$H$5*$H$5*$H$5 -> 0 | U34: =L34+N34+P34+R34+T34 -> 900 | V34: 0 | W34: =SUM(U34:V34) -> 900 | X34: =W34*0.95 -> 855 | Y34: =W34-X34 -> 45
A35: MX.1.1.B (Outcome 1) / MX.3.7.B (M&E) | B35: 89050 | C35: MEX | D35: MEX | E35: CDM | F35: CDMEMAIL | G35: Email/Internet | H35: Office Expenses | I35: Month | J35: 6 | K35: 200 | L35: =J35*K35 -> 1200 | M35: 12 | N35: =M35*K35*$H$5 -> 2520 | O35: 12 | P35: =O35*K35*$H$5*$H$5 -> 2646 | Q35: 12 | R35: =Q35*K35*$H$5*$H$5*$H$5 -> 2778.3 | S35: 0 | T35: =S35*K35*$H$5*$H$5*$H$5*$H$5 -> 0 | U35: =L35+N35+P35+R35+T35 -> 9144.3 | V35: 0 | W35: =SUM(U35:V35) -> 9144.3 | X35: =W35*0.95 -> 8687.085 | Y35: =W35-X35 -> 457.215
A36: MX.1.1.B (Outcome 1) / MX.3.7.B (M&E) | B36: 89050 | C36: MEX | D36: MEX | E36: CDM | F36: CDMCELL | G36: Cellphone plan | H36: Office Expenses | I36: Month | J36: 6 | K36: 150 | L36: =J36*K36 -> 900 | M36: 12 | N36: =M36*K36*$H$5 -> 1890 | O36: 12 | P36: =O36*K36*$H$5*$H$5 -> 1984.5 | Q36: 12 | R36: =Q36*K36*$H$5*$H$5*$H$5 -> 2083.725 | S36: 0 | T36: =S36*K36*$H$5*$H$5*$H$5*$H$5 -> 0 | U36: =L36+N36+P36+R36+T36 -> 6858.225 | V36: 0 | W36: =SUM(U36:V36) -> 6858.225 | X36: =W36*0.95 -> 6515.3138 | Y36: =W36-X36 -> 342.91125
A37: MX.1.1.B (Outcome 1) / MX.3.7.B (M&E) | B37: 89050 | C37: MEX | D37: MEX | E37: CDM | F37: CDMRENT | G37: Office Rent | H37: Office Expenses | I37: Month | J37: 6 | K37: 900 | L37: =J37*K37 -> 5400 | M37: 12 | N37: =M37*K37*$H$5 -> 11340 | O37: 12 | P37: =O37*K37*$H$5*$H$5 -> 11907 | Q37: 12 | R37: =Q37*K37*$H$5*$H$5*$H$5 -> 12502.35 | S37: 0 | T37: =S37*K37*$H$5*$H$5*$H$5*$H$5 -> 0 | U37: =L37+N37+P37+R37+T37 -> 41149.35 | V37: 0 | W37: =SUM(U37:V37) -> 41149.35 | X37: =W37*0.95 -> 39091.882 | Y37: =W37-X37 -> 2057.4675
A38: MX.1.1.B (Outcome 1) / MX.3.7.B (M&E) | B38: 89050 | C38: MEX | D38: MEX | E38: CDM | F38: CDMMAINT | G38: Equipment and office repairs and maintenance | H38: Office Expenses | I38: Year | J38: 1 | K38: 250 | L38: =J38*K38 -> 250 | M38: 1 | N38: =M38*K38*$H$5 -> 262.5 | O38: 1 | P38: =O38*K38*$H$5*$H$5 -> 275.625 | Q38: 1 | R38: =Q38*K38*$H$5*$H$5*$H$5 -> 289.40625 | S38: 0 | T38: =S38*K38*$H$5*$H$5*$H$5*$H$5 -> 0 | U38: =L38+N38+P38+R38+T38 -> 1077.5312 | V38: 0 | W38: =SUM(U38:V38) -> 1077.5312 | X38: =W38*0.95 -> 1023.6547 | Y38: =W38-X38 -> 53.876563
G40: Subtotal Office Expenses | L40: =SUM(L32:L38) -> 8800 | N40: =SUM(N32:N38) -> 16443 | P40: =SUM(P32:P38) -> 17265.15 | R40: =SUM(R32:R38) -> 18128.408 | T40: =SUM(T32:T38) -> 0 | U40: =L40+N40+P40+R40+T40 -> 60636.558 | V40: =SUM(V32:V38) -> 0 | W40: =SUM(U40:V40) -> 60636.558
G41: The above is only for percentage calculations for the below outcomes
G42: Outcome 1: Increase understanding by workers, employers, and union leaders on how to utilize Mexico’s new labor systems to protect labor rights and effectively address labor disputes.
G43: Activities/Costs
A44: MX.1.1.B | B44: 89050 | C44: MEX | D44: MEX | E44: CDM | F44: See breakdown column X, Y | G44: Personnel & Fringe (95% of Direct Labor line item) | H44: Outcome1 | I44: Unit | J44: =$L$20 -> 75501.6 | K44: 0.95 | L44: =J44*K44 -> 71726.52 | M44: =$N$20 -> 156288.31 | N44: =M44*K44 -> 148473.9 | O44: =$P$20 -> 161758.4 | P44: =O44*K44 -> 153670.48 | Q44: =$R$20 -> 167419.95 | R44: =Q44*K44 -> 159048.95 | S44: =$T$20 -> 0 | T44: =S44*K44 -> 0 | U44: =L44+N44+P44+R44+T44 -> 532919.85 | V44: 0 | W44: =SUM(U44:V44) -> 532919.85
A45: MX.1.1.B | B45: 89050 | C45: MEX | D45: MEX | E45: CDM | F45: See breakdown column X, Y | G45: Travel 95% | H45: Outcome1 | I45: Unit | J45: =L24 -> 180 | K45: 0.95 | L45: =J45*K45 -> 171 | M45: =N24 -> 189 | N45: =M45*K45 -> 179.55 | O45: =P24 -> 198.45 | P45: =O45*K45 -> 188.5275 | Q45: =R24 -> 208.3725 | R45: =Q45*K45 -> 197.95388 | S45: =$T$30 -> 0 | T45: =S45*K45 -> 0 | U45: =L45+N45+P45+R45+T45 -> 737.03138 | V45: 0 | W45: =SUM(U45:V45) -> 737.03138
A46: MX.1.1.B | B46: 89050 | C46: MEX | D46: MEX | E46: CDM | F46: See breakdown column X, Y | G46: Supplies 95% | H46: Outcome1 | I46: Unit | J46: =$L$30 -> 4500 | K46: 0.95 | L46: =J46*K46 -> 4275 | M46: =$N$30 -> 1575 | N46: =M46*K46 -> 1496.25 | O46: =$P$30 -> 1653.75 | P46: =O46*K46 -> 1571.0625 | Q46: =$R$30 -> 1736.4375 | R46: =Q46*K46 -> 1649.6156 | S46: 0 | T46: =S46*K46 -> 0 | U46: =L46+N46+P46+R46+T46 -> 8991.9281 | V46: 0 | W46: =SUM(U46:V46) -> 8991.9281
...

Sheet SAI
A1: Name of Project: Mexico Awareness Raising Project
A2: Name of Subawardee: Social Accountability International (SAI)
A3: Subaward Budget
A4: Budget Assumptions:
A5: Inflation - US Based Goods/Services | B5: 1.03
A6: Inflation - Locally Purchased Goods/Services | B6: 1.05
A7: Merit Based Increases for Staff | B7: 1.035
A9: BUDGET ITEM | B9: CATEGORY | C9: UNIT | D9: # of Units | E9: RATE/ UNIT | F9: YEAR 1 | G9: # of Units | H9: YEAR 2 | I9: # of Units | J9: YEAR 3 | K9: # of Units | L9: YEAR 4 | M9: # of Units | N9: YEAR 5 | O9: TOTALSAI | P9: TOTAL COST SHARING | Q9: PROJECT GRAND TOTAL | R9: Percentage 60% to Outcome 1 | S9: Percentage 35% to Outcome 2 | T9: Percentage 5% to Outcome 3
A11: Direct Labor
A12: Field Personnel
A13: Assessor, Trainer & Facilitator 1 | B13: Salaries | C13: Day | D13: =(6*15)+(3*10) -> 120 | E13: 325 | F13: =D13*E13 -> 39000 | G13: =10*12 -> 120 | H13: =G13*E13*$B$7 -> 40365 | I13: =10*12 -> 120 | J13: =I13*E13*$B$7*$B$7 -> 41777.775 | K13: =10*12 -> 120 | L13: =K13*E13*$B$7*$B$7*$B$7 -> 43239.997 | M13: =3*10 -> 30 | N13: =M13*E13*$B$7*$B$7*$B$7*$B$7 -> 11188.349 | O13: =SUM(F13+H13+J13+L13+N13) -> 175571.12 | P13: 0 | Q13: =SUM(O13:P13) -> 175571.12 | R13: =Q13*0.6 -> 105342.67 | S13: =Q13*0.35 -> 61449.892 | T13: =Q13-R13-S13 -> 8778.5561
A14: Assessor, Trainer & Facilitator 2 | B14: Salaries | C14: Day | D14: =(6*15)+(3*10) -> 120 | E14: 325 | F14: =D14*E14 -> 39000 | G14: =10*12 -> 120 | H14: =G14*E14*$B$7 -> 40365 | I14: =10*12 -> 120 | J14: =I14*E14*$B$7*$B$7 -> 41777.775 | K14: =10*12 -> 120 | L14: =K14*E14*$B$7*$B$7*$B$7 -> 43239.997 | M14: =3*10 -> 30 | N14: =M14*E14*$B$7*$B$7*$B$7*$B$7 -> 11188.349 | O14: =SUM(F14+H14+J14+L14+N14) -> 175571.12 | P14: 0 | Q14: =SUM(O14:P14) -> 175571.12 | R14: =Q14*0.6 -> 105342.67 | S14: =Q14*0.35 -> 61449.892 | T14: =Q14-R14-S14 -> 8778.5561
A15: Assessor, Trainer & Facilitator 3 | B15: Salaries | C15: Day | D15: 10 | E15: 350 | F15: =D15*E15 -> 3500 | G15: 10 | H15: =G15*E15*$B$7 -> 3622.5 | I15: 10 | J15: =I15*E15*$B$7*$B$7 -> 3749.2875 | K15: 0 | L15: =K15*E15*$B$7*$B$7*$B$7 -> 0 | M15: 0 | N15: =M15*E15*$B$7*$B$7*$B$7*$B$7 -> 0 | O15: =SUM(F15+H15+J15+L15+N15) -> 10871.787 | P15: 0 | Q15: =SUM(O15:P15) -> 10871.787 | R15: =Q15*0.6 -> 6523.0725 | S15: =Q15*0.35 -> 3805.1256 | T15: =Q15-R15-S15 -> 543.58938
A16: Assessor, Trainer & Facilitator 4 | B16: Salaries | C16: Day | D16: 10 | E16: 350 | F16: =D16*E16 -> 3500 | G16: 10 | H16: =G16*E16*$B$7 -> 3622.5 | I16: 10 | J16: =I16*E16*$B$7*$B$7 -> 3749.2875 | K16: 0 | L16: =K16*E16*$B$7*$B$7*$B$7 -> 0 | M16: 0 | N16: =M16*E16*$B$7*$B$7*$B$7*$B$7 -> 0 | O16: =SUM(F16+H16+J16+L16+N16) -> 10871.787 | P16: 0 | Q16: =SUM(O16:P16) -> 10871.787
A17: HQ Personnel
A18: Senior Director, Innovations and Capacity Building | B18: Salaries | C18: Day | D18: =4*12 -> 48 | E18: =125000/222 -> 563.06306 | F18: =D18*E18 -> 27027.027 | G18: =4*12 -> 48 | H18: =G18*E18*$B$7 -> 27972.973 | I18: =3*12 -> 36 | J18: =I18*E18*$B$7*$B$7 -> 21714.02 | K18: =2*12 -> 24 | L18: =K18*E18*$B$7*$B$7*$B$7 -> 14982.674 | M18: =2*6 -> 12 | N18: =M18*E18*$B$7*$B$7*$B$7*$B$7 -> 7753.5338 | O18: =SUM(F18+H18+J18+L18+N18) -> 99450.228 | P18: 0 | Q18: =SUM(O18:P18) -> 99450.228 | R18: =Q18*0.6 -> 59670.137 | S18: =Q18*0.35 -> 34807.58 | T18: =Q18-R18-S18 -> 4972.5114
A19: Associate Director, Innovations and Partnerships | B19: Salaries | C19: Day | D19: =2*12 -> 24 | E19: =100000/218 -> 458.7156 | F19: =D19*E19 -> 11009.174 | G19: =3*12 -> 36 | H19: =G19*E19*$B$7 -> 17091.743 | I19: =3*12 -> 36 | J19: =I19*E19*$B$7*$B$7 -> 17689.954 | K19: =2*12 -> 24 | L19: =K19*E19*$B$7*$B$7*$B$7 -> 12206.068 | M19: =2*6 -> 12 | N19: =M19*E19*$B$7*$B$7*$B$7*$B$7 -> 6316.6404 | O19: =SUM(F19+H19+J19+L19+N19) -> 64313.58 | P19: 0 | Q19: =SUM(O19:P19) -> 64313.58 | R19: =Q19*0.6 -> 38588.148 | S19: =Q19*0.35 -> 22509.753 | T19: =Q19-R19-S19 -> 3215.679
A20: Manager, Policy & Stakeholder Engagement | B20: Salaries | C20: Day | D20: =2*12 -> 24 | E20: =75000/218 -> 344.0367 | F20: =D20*E20 -> 8256.8807 | G20: =2*12 -> 24 | H20: =G20*E20*$B$7 -> 8545.8716 | I20: =2*12 -> 24 | J20: =I20*E20*$B$7*$B$7 -> 8844.9771 | K20: =1*12 -> 12 | L20: =K20*E20*$B$7*$B$7*$B$7 -> 4577.2756 | M20: =1*6 -> 6 | N20: =M20*E20*$B$7*$B$7*$B$7*$B$7 -> 2368.7401 | O20: =SUM(F20+H20+J20+L20+N20) -> 32593.745 | P20: 0 | Q20: =SUM(O20:P20) -> 32593.745 | R20: =Q20*0.6 -> 19556.247 | S20: =Q20*0.35 -> 11407.811 | T20: =Q20-R20-S20 -> 1629.6873
A21: Manager, Communications & Marketing | B21: Salaries | C21: Day | D21: =4*12 -> 48 | E21: =75000/222 -> 337.83784 | F21: =D21*E21 -> 16216.216 | G21: =5*12 -> 60 | H21: =G21*E21*$B$7 -> 20979.73 | I21: =5*12 -> 60 | J21: =I21*E21*$B$7*$B$7 -> 21714.02 | K21: =4*12 -> 48 | L21: =K21*E21*$B$7*$B$7*$B$7 -> 17979.209 | M21: 8 | N21: =M21*E21*$B$7*$B$7*$B$7*$B$7 -> 3101.4135 | O21: =SUM(F21+H21+J21+L21+N21) -> 79990.589 | P21: 0 | Q21: =SUM(O21:P21) -> 79990.589 | R21: =Q21*0.6 -> 47994.353 | S21: =Q21*0.35 -> 27996.706 | T21: =Q21-R21-S21 -> 3999.5294
A22: Subtotal | F22: =SUM(F13:F21) -> 147509.3 | H22: =SUM(H13:H21) -> 162565.32 | J22: =SUM(J13:J21) -> 161017.1 | L22: =SUM(L13:L21) -> 136225.22 | N22: =SUM(N13:N21) -> 41917.026 | O22: =SUM(F22+H22+J22+L22+N22) -> 649233.96 | P22: =SUM(P13:P21) -> 0 | Q22: =SUM(O22:P22) -> 649233.96 | R22: =Q22*0.6 -> 389540.38 | S22: =Q22*0.35 -> 227231.89 | T22: =Q22-R22-S22 -> 32461.698
R23: =Q23*0.6 -> 0 | S23: =Q23*0.35 -> 0 | T23: =Q23-R23-S23 -> 0
A24: Fringe Benefits | R24: =Q24*0.6 -> 0 | S24: =Q24*0.35 -> 0 | T24: =Q24-R24-S24 -> 0
A25: Fringe benefits HQ Support | B25: Fringe Benefits | E25: 0.29 | F25: =E25*SUM(F18:F21) -> 18127.697 | H25: =E25*SUM(H18:H21) -> 21631.192 | J25: =E25*SUM(J18:J21) -> 20289.262 | L25: =E25*SUM(L18:L21) -> 14426.116 | N25: =E25*SUM(N18:N21) -> 5666.6951 | O25: =SUM(F25+H25+J25+L25+N25) -> 80140.961 | P25: 0 | Q25: =SUM(O25:P25) -> 80140.961 | R25: =Q25*0.6 -> 48084.577 | S25: =Q25*0.35 -> 28049.336 | T25: =Q25-R25-S25 -> 4007.0481
R26: =Q26*0.6 -> 0 | S26: =Q26*0.35 -> 0 | T26: =Q26-R26-S26 -> 0
A27: Subtotal Direct Labor | F27: =SUM(F22:F25) -> 165636.99 | H27: =SUM(H22:H25) -> 184196.51 | J27: =SUM(J22:J25) -> 181306.36 | L27: =SUM(L22:L25) -> 150651.34 | N27: =SUM(N22:N25) -> 47583.721 | O27: =F27+H27+J27+L27+N27 -> 729374.92 | P27: =SUM(P12:P25) -> 0 | Q27: =SUM(O27:P27) -> 729374.92 | R27: =Q27*0.6 -> 437624.95 | S27: =Q27*0.35 -> 255281.22 | T27: =Q27-R27-S27 -> 36468.746
R28: =Q28*0.6 -> 0 | S28: =Q28*0.35 -> 0 | T28: =Q28-R28-S28 -> 0
A29: Travel
A30: T1. Meetings with Partners and USDOL
A31: HQ Staff - Train NYC<>DC | B31: Travel | C31: Trip | D31: =2*2 -> 4 | E31: 250 | F31: =D31*E31 -> 1000 | G31: 0 | H31: =G31*E31*$B$5 -> 0 | I31: 0 | J31: =I31*E31*$B$5*$B$5 -> 0 | K31: 0 | L31: =K31*E31*$B$5*$B$5*$B$5 -> 0 | M31: 0 | N31: =M31*E31*$B$5*$B$5*$B$5*$B$5 -> 0 | O31: =F31+H31+J31+L31+N31 -> 1000 | P31: - | Q31: =SUM(O31:P31) -> 1000
A32: HQ Staff - Lodging in DC | B32: Travel | C32: Day | D32: =2*2*1 -> 4 | E32: 200 | F32: =D32*E32 -> 800 | G32: 0 | H32: =G32*E32*$B$5 -> 0 | I32: 0 | J32: =I32*E32*$B$5*$B$5 -> 0 | K32: 0 | L32: =K32*E32*$B$5*$B$5*$B$5 -> 0 | M32: 0 | N32: =M32*E32*$B$5*$B$5*$B$5*$B$5 -> 0 | O32: =F32+H32+J32+L32+N32 -> 800 | P32: - | Q32: =SUM(O32:P32) -> 800
A33: HQ Staff - Local Transportation in DC | B33: Travel | C33: Day | D33: =2*2 -> 4 | E33: 50 | F33: =D33*E33 -> 200 | G33: 0 | H33: =G33*E33*$B$5 -> 0 | I33: 0 | J33: =I33*E33*$B$5*$B$5 -> 0 | K33: 0 | L33: =K33*E33*$B$5*$B$5*$B$5 -> 0 | M33: 0 | N33: =M33*E33*$B$5*$B$5*$B$5*$B$5 -> 0 | O33: =F33+H33+J33+L33+N33 -> 200 | P33: - | Q33: =SUM(O33:P33) -> 200 | R33: =Q33*0.6 -> 120 | S33: =Q33*0.35 -> 70 | T33: =Q33-R33-S33 -> 10
A34: HQ Staff - M&IE in DC | B34: Travel | C34: Day | D34: =2*2 -> 4 | E34: 50 | F34: =D34*E34 -> 200 | G34: 0 | H34: =G34*E34*$B$5 -> 0 | I34: 0 | J34: =I34*E34*$B$5*$B$5 -> 0 | K34: 0 | L34: =K34*E34*$B$5*$B$5*$B$5 -> 0 | M34: 0 | N34: =M34*E34*$B$5*$B$5*$B$5*$B$5 -> 0 | O34: =F34+H34+J34+L34+N34 -> 200 | P34: - | Q34: =SUM(O34:P34) -> 200
A35: T2. HQ Trips to Mexico
A36: Airfare for: NYC<>Mexico City | B36: Travel | C36: Trip | D36: 1 | E36: 600 | F36: =D36*E36 -> 600 | G36: 1 | H36: =G36*E36*$B$5 -> 618 | I36: 1 | J36: =I36*E36*$B$5*$B$5 -> 636.54 | K36: 1 | L36: =K36*E36*$B$5*$B$5*$B$5 -> 655.6362 | M36: 1 | N36: =M36*E36*$B$5*$B$5*$B$5*$B$5 -> 675.30529 | O36: =F36+H36+J36+L36+N36 -> 3185.4815 | P36: - | Q36: =SUM(O36:P36) -> 3185.4815
A37: Airfare within Mexico | B37: Travel | C37: Trip | D37: 1 | E37: 125 | F37: =D37*E37 -> 125 | G37: 1 | H37: =G37*E37*$B$6 -> 131.25 | I37: 1 | J37: =I37*E37*$B$6*$B$6 -> 137.8125 | K37: 1 | L37: =K37*E37*$B$6*$B$6*$B$6 -> 144.70312 | M37: 1 | N37: =M37*E37*$B$6*$B$6*$B$6*$B$6 -> 151.93828 | O37: =F37+H37+J37+L37+N37 -> 690.70391 | P37: - | Q37: =SUM(O37:P37) -> 690.70391
A38: Lodging and M&IE | B38: Travel | C38: Day | D38: 20 | E38: 110 | F38: =D38*E38 -> 2200 | G38: 7 | H38: =G38*E38*$B$6 -> 808.5 | I38: 7 | J38: =I38*E38*$B$6*$B$6 -> 848.925 | K38: 7 | L38: =K38*E38*$B$6*$B$6*$B$6 -> 891.37125 | M38: 7 | N38: =M38*E38*$B$6*$B$6*$B$6*$B$6 -> 935.93981 | O38: =F38+H38+J38+L38+N38 -> 5684.7361 | P38: - | Q38: =SUM(O38:P38) -> 5684.7361
A39: Transportation (to and from home airports) | B39: Travel | C39: Day | D39: 20 | E39: 50 | F39: =D39*E39 -> 1000 | G39: 7 | H39: =G39*E39*$B$6 -> 367.5 | I39: 7 | J39: =I39*E39*$B$6*$B$6 -> 385.875 | K39: 7 | L39: =K39*E39*$B$6*$B$6*$B$6 -> 405.16875 | M39: 7 | N39: =M39*E39*$B$6*$B$6*$B$6*$B$6 -> 425.42719 | O39: =F39+H39+J39+L39+N39 -> 2583.9709 | P39: - | Q39: =SUM(O39:P39) -> 2583.9709 | R39: =Q39*0.6 -> 1550.3826 | S39: =Q39*0.35 -> 904.38983 | T39: =Q39-R39-S39 -> 129.19855
A40: Local transportation | B40: Travel | C40: Day | D40: 20 | E40: 30 | F40: =D40*E40 -> 600 | G40: 7 | H40: =G40*E40*$B$6 -> 220.5 | I40: 7 | J40: =I40*E40*$B$6*$B$6 -> 231.525 | K40: 7 | L40: =K40*E40*$B$6*$B$6*$B$6 -> 243.10125 | M40: 7 | N40: =M40*E40*$B$6*$B$6*$B$6*$B$6 -> 255.25631 | O40: =F40+H40+J40+L40+N40 -> 1550.3826 | P40: - | Q40: =SUM(O40:P40) -> 1550.3826 | R40: =Q40*0.6 -> 930.22954 | S40: =Q40*0.35 -> 542.6339 | T40: =Q40-R40-S40 -> 77.519128
A41: T3. Field Personnel Trips in Mexico | R41: =Q41*0.6 -> 0 | S41: =Q41*0.35 -> 0 | T41: =Q41-R41-S41 -> 0
A42: Airfare within Mexico | B42: Travel | C42: Trip | D42: =2*6 -> 12 | E42: 125 | F42: =D42*E42 -> 1500 | G42: =2*6 -> 12 | H42: =G42*E42*$B$6 -> 1575 | I42: =2*6 -> 12 | J42: =I42*E42*$B$6*$B$6 -> 1653.75 | K42: =2*6 -> 12 | L42: =K42*E42*$B$6*$B$6*$B$6 -> 1736.4375 | M42: 2 | N42: =M42*E42*$B$6*$B$6*$B$6*$B$6 -> 303.87656 | O42: =F42+H42+J42+L42+N42 -> 6769.0641 | P42: - | Q42: =SUM(O42:P42) -> 6769.0641 | R42: =Q42*0.6 -> 4061.4384 | S42: =Q42*0.35 -> 2369.1724 | T42: =Q42-R42-S42 -> 338.4532
...

Sheet SF-424 Cost Categories
B2: Category | C2: TOTAL USDOL
B3: Salaries | C3: =SUMIF(Category,B3,TotalDOL) -> 1640410.6
B4: Fringe Benefits | C4: =SUMIF(Category,"Fringe Benefits",TotalDOL) -> 663469.72
B5: Travel | C5: =SUMIF(Category,"Travel",TotalDOL) -> 265175.3
B6: Equipment | C6: =SUMIF(Category,"Equipment",TotalDOL) -> 4500
B7: Supplies | C7: =SUMIF(Category,"Supplies",TotalDOL) -> 255404.78
B8: Contractual | C8: =SUMIF(Category,"Contractual",TotalDOL) -> 3441032.7
B9: Other Direct Charges | C9: =SUMIF(Category,"Other",TotalDOL) -> 1429218.7
B10: Indirect Charges | C10: =SUMIF(Category,"Indirect Charges",TotalDOL) -> 2229388.6
B12: TOTAL | C12: =SUM(C3:C10) -> 9928600.5
