Workbook
Name \a: '[1]CUADRO No 4'!#REF!
Name \c: #REF!
Name \i: #REF!
Name \P: #REF!
Name \r: #REF!
Name __pd1: [2]Rates!$J$24
Name __pd6: [2]Rates!$J$30
Name __tix1: [2]Rates!$J$40
Name __tix2: [2]Rates!$J$41
Name __tix6: [2]Rates!$J$47
Name _1: #REF!
Name _1998: #REF!
Name _1999: #REF!
Name _2: #REF!
Name _2000: #REF!
Name _2001: #REF!
Name _2002: #REF!
Name _3: #REF!
Name _4: #REF!
Name _5: #REF!
Name _6: #REF!
Name _7: #REF!
Name _8: #REF!
Name _fmi1: [3]PAGOFMI!$A$1:$L$51
Name _fmi2: [3]PAGOFMI!$P$1:$AA$51
Name _fmi3: [3]PAGORES!$AC$1:$AN$43
Name _fmi4: [3]PAGORES!$AP$1:$BA$44
Name _PIB01: [4]SUPUESTOS!#REF!
Name _PIB02: [5]SUPUESTOS!#REF!
Name _PIB95: [4]SUPUESTOS!$J$47
Name _PIB96: [4]SUPUESTOS!$K$47
Name _PIB97: [6]SUPUESTOS!$L$47
Name _PIB98: [6]SUPUESTOS!$M$47
Name _PIB99: [6]SUPUESTOS!$N$47
Name _RES9397: #REF!
Name _rez2: '[3]PAGOS VIGENCIA t'!$A$57:$AH$108
Name _rez3: [3]PAGORES!$A$1:$M$37
Name _rez4: [3]PAGORES!$O$1:$AN$43
Name a: #REF!
Name A_2002: #REF!
Name A_CAPITAL: [9]Hoja4!$B$3:$O$34
Name A_DEPTOS: [9]Hoja4!$B$76:$N$108
Name A_impresión_IM: #REF!
Name A_MUNPIOS: [9]Hoja4!$B$39:$N$71
Name AAA: [10]proyecINGRESOS99!$L$1:$T$97
Name AEFormar: [11]Variables!$C$5
Name Ajustado: #REF!
Name almuerzo: [11]Variables!$C$18
Name alquilertableta: [11]Variables!$C$21
Name ANEXO_No.: #REF!
Name ANEXO_No._5: #REF!
Name ANPDH: '[12]Salary & PR Tax'!#REF!
Name aprnac: [13]GASTOS!#REF!
Name APROPIACIONES_PAC_Y_REZAGO_1999___2000: #REF!
Name aprprp: [13]GASTOS!#REF!
Name asigbas: #REF!
Name asigbasempu: #REF!
Name asigbasisten: #REF!
Name asigmen: #REF!
Name auxalm: #REF!

Sheet 800-FC - Detailed Changes
G1: ESTOY REUBICANDO LA LÍNEA | I1: Letra en rojo, significa cambiar la denominación del ítem
G2: LÍNEA NUEVA | I2: LÍNEA QUE SE VA
A4: Entity: | B4: P
A5: Program-Dept.: | B5: 20300 | G5: Initial Budget Assumptions | L5: Modification 7 - Budget Assumptions
A6: Funder-Grant: | B6: USAID800 | G6: Inflation - Locally Purchased Goods/Services - 3% | H6: 1.03 | L6: Inflation - Locally Purchased Goods/Services | M6: 0.08
G7: Merit Based Increases for HQ & Field Staff - 4% | H7: 1.04 | L7: Merit Based Increases for HQ & Field Staff | M7: 0.1
G9: *Key Personnel | J9: Actuals/Estimates Year 1 and 2 and 3 (January 1, 2023 - December 31, 2023) | P9: Projections for Year 3 (January 1, 2024 - December 31, 2024) - 6 | AO9: New Proposed Budget Total
A10: Sage Activity | B10: Sage Object Code/ Line Item | C10: Country Code (DC=0 or CO) | D10: Office Code (DC=0 or CO) | E10: Subcontract Code | F10: Open 1 Code | G10: Line Items | J10: USAID Year 1 -Actuals August 16, 2021 - December 31, 2021 | K10: Leverage Year 1 - Actuals August 16, 2021 - December 31, 2021 | L10: USAID Year 2 - Actuals January 1, 2022 - December 31, 2022 | M10: Leverage Year 2 - Actuals January 1, 2022 - December 31, 2022 | N10: USAID Year 3 - Actuals January 1, 2023 - December 31, 2023 | O10: Leverage Year 3 - Actuals January 1, 2023 - July 31, 2023 | P10: Year 4 - January 1, 2024 - December 31, 2024 | V10: Year 5 - January 1, 2025 - December 31, 2025 | AB10: Year 6 - January 1, 2026 - Agosto 31, 2026 | AH10: Actuals Year 1- 3 | AI10: Actuals Year 1- 3 | AJ10: Actuals Year 1- 3 | AK10: Year 4- 6 | AL10: Year 4- 6 | AM10: Year 4- 6 | AO10: Total | AP10: Total | AQ10: Grand
P11: Unit LOE | Q11: Cost | R11: Duration | S11: USAID | T11: Leverage | U11: Total | V11: Unit LOE | W11: Cost | X11: Duration | Y11: USAID | Z11: Leverage | AA11: Total | AB11: Unit | AC11: Cost | AD11: Duration | AE11: USAID | AF11: Leverage | AG11: Total | AH11: Total USAID | AI11: Total Leverage | AJ11: Grand Total | AK11: Total USAID | AL11: Total Leverage | AM11: Grand Total | AO11: USAID | AP11: Leverage | AQ11: Total
G12: Personnel | H12: 1. Personnel
G13: Headquarters Personnel (include Level of Effort) | H13: Headquarters Personnel (include Level of Effort)
G14: Fundación Carvajal Office (Cali) | H14: Fundación Carvajal Management Team
A15: SUBFCARVA | B15: 89050 | C15: COL2 | D15: COL2 | E15: CARVAJAL | F15: FCPERSNL/ FCPERSNLEV | G15: Program Director | H15: Program Director | I15: David Gironza | J15: 9207.63 | K15: 1087.7 | L15: 21864.25 | M15: 0 | N15: 16983.86 | O15: 8197.2 | P15: 0 | Q15: 0 | R15: 0 | S15: 0 | T15: 0 | U15: 0 | V15: 0 | W15: =+Q15*10%+Q15 -> 0 | X15: 0 | Y15: 0 | Z15: 0 | AA15: 0 | AB15: 0 | AC15: 0 | AD15: 0 | AE15: 0 | AF15: 0 | AG15: =+AE15+AF15 -> 0 | AH15: =+J15+L15+N15 -> 48055.74 | AI15: =+K15+M15+O15 -> 9284.9 | AJ15: =+AH15+AI15 -> 57340.64 | AK15: =+S15+Y15+AE15 -> 0 | AL15: =+T15+Z15+AF15 -> 0 | AM15: =+AK15+AL15 -> 0 | AO15: =+AH15+AK15 -> 48055.74 | AP15: =+AI15+AL15 -> 9284.9 | AQ15: =+AO15+AP15 -> 57340.64
H16: Management Team | I16: TBD (Marcela Astudillo, Erika Acevedo, Aura Aydé García) | J16: 0 | K16: 0 | L16: 0 | M16: 0 | N16: 0 | O16: 0 | P16: 0.26 | Q16: 1641.45 | R16: 10.5 | S16: =Q16*R16 -> 17235.225 | T16: =704.89*R16 -> 7401.345 | U16: =SUM(S16:T16) -> 24636.57 | V16: 0.5 | W16: =+Q16*10%+Q16 -> 1805.595 | X16: 12 | Y16: =+W16*X16 -> 21667.14 | Z16: =+T16*1.1 -> 8141.4795 | AA16: =SUM(Y16:Z16) -> 29808.62 | AB16: 0.5 | AC16: =+W16*1.1 -> 1986.1545 | AD16: 8 | AE16: =AB16*AC16*AD16 -> 7944.618 | AF16: =+(Z16*1.1)/12*8 -> 5970.4183 | AG16: =SUM(AE16:AF16) -> 13915.036 | AH16: =+J16+L16+N16 -> 0 | AI16: =+K16+M16+O16 -> 0 | AJ16: =+AH16+AI16 -> 0 | AK16: =+S16+Y16+AE16 -> 46846.983 | AL16: =+T16+Z16+AF16 -> 21513.243 | AM16: =+AK16+AL16 -> 68360.226 | AO16: =+AH16+AK16 -> 46846.983 | AP16: =+AI16+AL16 -> 21513.243 | AQ16: =+AO16+AP16 -> 68360.226
A17: SUBFCARVA | B17: 89050 | C17: COL2 | D17: COL2 | E17: CARVAJAL | F17: FCPERSNL | G17: Education Director* | H17: Education Director* | I17: Paola Trujillo | J17: 4793.31 | K17: 0 | L17: 37385.23 | M17: 0 | N17: 0 | O17: 0 | P17: 0 | Q17: 0 | R17: 0 | S17: =Q17*R17 -> 0 | T17: 0 | U17: =SUM(S17:T17) -> 0 | V17: 0 | W17: =+Q17*10%+Q17 -> 0 | X17: 0 | Y17: =+W17*X17 -> 0 | Z17: 0 | AA17: =SUM(Y17:Z17) -> 0 | AB17: 0 | AC17: 0 | AD17: 0 | AE17: =AB17*AC17*AD17 -> 0 | AF17: 0 | AG17: =SUM(AE17:AF17) -> 0 | AH17: =+J17+L17+N17 -> 42178.54 | AI17: =+K17+M17+O17 -> 0 | AJ17: =+AH17+AI17 -> 42178.54 | AK17: =+S17+Y17+AE17 -> 0 | AL17: =+T17+Z17+AF17 -> 0 | AM17: =+AK17+AL17 -> 0 | AO17: =+AH17+AK17 -> 42178.54 | AP17: =+AI17+AL17 -> 0 | AQ17: =+AO17+AP17 -> 42178.54
G18: Education Director* | H18: Education Director* | I18: Catalina Prada | J18: 0 | K18: 0 | L18: 0 | M18: 0 | N18: 41755.1 | O18: 0 | P18: 1 | Q18: 4172.84 | R18: 12 | S18: =Q18*R18 -> 50074.08 | T18: 0 | U18: =SUM(S18:T18) -> 50074.08 | V18: 1 | W18: =+Q18*10%+Q18 -> 4590.124 | X18: 12 | Y18: =+W18*X18 -> 55081.488 | Z18: 0 | AA18: =SUM(Y18:Z18) -> 55081.488 | AB18: 1 | AC18: =+W18*10%+W18 -> 5049.1364 | AD18: 8 | AE18: =AB18*AC18*AD18 -> 40393.091 | AF18: 0 | AG18: =SUM(AE18:AF18) -> 40393.091 | AH18: =+J18+L18+N18 -> 41755.1 | AI18: =+K18+M18+O18 -> 0 | AJ18: =+AH18+AI18 -> 41755.1 | AK18: =+S18+Y18+AE18 -> 145548.66 | AL18: =+T18+Z18+AF18 -> 0 | AM18: =+AK18+AL18 -> 145548.66 | AO18: =+AH18+AK18 -> 187303.76 | AP18: =+AI18+AL18 -> 0 | AQ18: =+AO18+AP18 -> 187303.76
G19: Project Office (Bogotá) | H19: Core Technical Team | AH19: =+J19+L19+N19 -> 0 | AI19: =+K19+M19+O19 -> 0 | AJ19: =+AH19+AI19 -> 0 | AK19: =+S19+Y19+AE19 -> 0 | AL19: =+T19+Z19+AF19 -> 0 | AM19: =+AK19+AL19 -> 0 | AO19: =+AH19+AK19 -> 0 | AP19: =+AI19+AL19 -> 0 | AQ19: =+AO19+AP19 -> 0
A20: SUBFCARVA | B20: 89050 | C20: COL2 | D20: COL2 | E20: CARVAJAL | F20: FCPERSNL | G20: Education Manager | H20: Education Manager | I20: Catalina Prada | J20: 8591.19 | K20: 0 | L20: 21376.46 | M20: 0 | N20: 0 | O20: 0 | P20: 0 | Q20: 0 | R20: 0 | S20: =+Q20*R20 -> 0 | T20: 0 | U20: =SUM(S20:T20) -> 0 | V20: 0 | W20: 0 | X20: 0 | Y20: =+W20*X20 -> 0 | Z20: 0 | AA20: =SUM(Y20:Z20) -> 0 | AB20: 0 | AC20: 0 | AD20: 0 | AE20: =AB20*AC20*AD20 -> 0 | AF20: 0 | AG20: =SUM(AE20:AF20) -> 0 | AH20: =+J20+L20+N20 -> 29967.65 | AI20: =+K20+M20+O20 -> 0 | AJ20: =+AH20+AI20 -> 29967.65 | AK20: =+S20+Y20+AE20 -> 0 | AL20: =+T20+Z20+AF20 -> 0 | AM20: =+AK20+AL20 -> 0 | AO20: =+AH20+AK20 -> 29967.65 | AP20: =+AI20+AL20 -> 0 | AQ20: =+AO20+AP20 -> 29967.65
H21: Education Coordinator | I21: Lisep Castillo | J21: 0 | K21: 0 | L21: 0 | M21: 0 | N21: 14944.37 | O21: 0 | P21: 1 | Q21: 1678.7 | R21: 12 | S21: =+Q21*R21 -> 20144.4 | T21: 0 | U21: =SUM(S21:T21) -> 20144.4 | V21: 1 | W21: =+Q21*10%+Q21 -> 1846.57 | X21: 12 | Y21: =+W21*X21 -> 22158.84 | Z21: 0 | AA21: =SUM(Y21:Z21) -> 22158.84 | AB21: 1 | AC21: =+W21*10%+W21 -> 2031.227 | AD21: 8 | AE21: =AB21*AC21*AD21 -> 16249.816 | AF21: 0 | AG21: =SUM(AE21:AF21) -> 16249.816 | AH21: =+J21+L21+N21 -> 14944.37 | AI21: =+K21+M21+O21 -> 0 | AJ21: =+AH21+AI21 -> 14944.37 | AK21: =+S21+Y21+AE21 -> 58553.056 | AL21: =+T21+Z21+AF21 -> 0 | AM21: =+AK21+AL21 -> 58553.056 | AO21: =+AH21+AK21 -> 73497.426 | AP21: =+AI21+AL21 -> 0 | AQ21: =+AO21+AP21 -> 73497.426
G22: Pre-Primary Education Specialist | H22: Pre-Primary Education Specialist | I22: Lisep Castillo | J22: 1992.97 | K22: 0 | L22: 5558.49 | M22: 0 | N22: 0 | O22: 0 | P22: 0 | Q22: 0 | R22: 0 | S22: =+Q22*R22 -> 0 | T22: 0 | U22: =SUM(S22:T22) -> 0 | V22: 0 | W22: 0 | X22: 0 | Y22: =+W22*X22 -> 0 | Z22: 0 | AA22: =SUM(Y22:Z22) -> 0 | AB22: 0 | AC22: 0 | AD22: 0 | AE22: =AB22*AC22*AD22 -> 0 | AF22: 0 | AG22: =SUM(AE22:AF22) -> 0 | AH22: =+J22+L22+N22 -> 7551.46 | AI22: =+K22+M22+O22 -> 0 | AJ22: =+AH22+AI22 -> 7551.46 | AK22: =+S22+Y22+AE22 -> 0 | AL22: =+T22+Z22+AF22 -> 0 | AM22: =+AK22+AL22 -> 0 | AO22: =+AH22+AK22 -> 7551.46 | AP22: =+AI22+AL22 -> 0 | AQ22: =+AO22+AP22 -> 7551.46
A23: SUBFCARVA | B23: 89050 | C23: COL2 | D23: COL2 | E23: CARVAJAL | F23: FCPERSNL | G23: Pre-Primary Education Specialist | H23: Pre-Primary Education Specialist | I23: Luz Doris Gallego Jiménez | J23: 0 | K23: 0 | L23: 11429.4 | M23: 0 | N23: 16923 | O23: 0 | P23: 1 | Q23: 1645.65 | R23: 12 | S23: =+Q23*R23 -> 19747.8 | T23: 0 | U23: =SUM(S23:T23) -> 19747.8 | V23: 1 | W23: =+Q23*10%+Q23 -> 1810.215 | X23: 12 | Y23: =+W23*X23 -> 21722.58 | Z23: 0 | AA23: =SUM(Y23:Z23) -> 21722.58 | AB23: 1 | AC23: =+W23*10%+W23 -> 1991.2365 | AD23: 6 | AE23: =AB23*AC23*AD23 -> 11947.419 | AF23: 0 | AG23: =SUM(AE23:AF23) -> 11947.419 | AH23: =+J23+L23+N23 -> 28352.4 | AI23: =+K23+M23+O23 -> 0 | AJ23: =+AH23+AI23 -> 28352.4 | AK23: =+S23+Y23+AE23 -> 53417.799 | AL23: =+T23+Z23+AF23 -> 0 | AM23: =+AK23+AL23 -> 53417.799 | AO23: =+AH23+AK23 -> 81770.199 | AP23: =+AI23+AL23 -> 0 | AQ23: =+AO23+AP23 -> 81770.199
A24: SUBFCARVA | B24: 89050 | C24: COL2 | D24: COL2 | E24: CARVAJAL | F24: FCPERSNL | G24: Primary Education Specialist | H24: Primary Education Specialist | I24: Marta Milena Tulcán Tapia | J24: 5796.13 | K24: 0 | L24: 14394.25 | M24: 0 | N24: 15856.88 | O24: 0 | P24: 1 | Q24: 1557.95 | R24: 12 | S24: =+Q24*R24 -> 18695.4 | T24: 0 | U24: =SUM(S24:T24) -> 18695.4 | V24: 1 | W24: =+Q24*10%+Q24 -> 1713.745 | X24: 12 | Y24: =+W24*X24 -> 20564.94 | Z24: 0 | AA24: =SUM(Y24:Z24) -> 20564.94 | AB24: 1 | AC24: =+W24*10%+W24 -> 1885.1195 | AD24: 6 | AE24: =AB24*AC24*AD24 -> 11310.717 | AF24: 0 | AG24: =SUM(AE24:AF24) -> 11310.717 | AH24: =+J24+L24+N24 -> 36047.26 | AI24: =+K24+M24+O24 -> 0 | AJ24: =+AH24+AI24 -> 36047.26 | AK24: =+S24+Y24+AE24 -> 50571.057 | AL24: =+T24+Z24+AF24 -> 0 | AM24: =+AK24+AL24 -> 50571.057 | AO24: =+AH24+AK24 -> 86618.317 | AP24: =+AI24+AL24 -> 0 | AQ24: =+AO24+AP24 -> 86618.317
A25: SUBFCARVA | B25: 89050 | C25: COL2 | D25: COL2 | E25: CARVAJAL | F25: FCPERSNL | G25: Secondary Education Specialist | H25: Secondary Education Specialist | I25: Natalia Suaza | J25: 0 | K25: 0 | L25: 12249.75 | M25: 0 | N25: 17074.28 | O25: 0 | P25: 1 | Q25: 1657.81 | R25: 12 | S25: =+Q25*R25 -> 19893.72 | T25: 0 | U25: =SUM(S25:T25) -> 19893.72 | V25: 1 | W25: =+Q25*10%+Q25 -> 1823.591 | X25: 12 | Y25: =+W25*X25 -> 21883.092 | Z25: 0 | AA25: =SUM(Y25:Z25) -> 21883.092 | AB25: 1 | AC25: =+W25*10%+W25 -> 2005.9501 | AD25: 6 | AE25: =AB25*AC25*AD25 -> 12035.701 | AF25: 0 | AG25: =SUM(AE25:AF25) -> 12035.701 | AH25: =+J25+L25+N25 -> 29324.03 | AI25: =+K25+M25+O25 -> 0 | AJ25: =+AH25+AI25 -> 29324.03 | AK25: =+S25+Y25+AE25 -> 53812.513 | AL25: =+T25+Z25+AF25 -> 0 | AM25: =+AK25+AL25 -> 53812.513 | AO25: =+AH25+AK25 -> 83136.543 | AP25: =+AI25+AL25 -> 0 | AQ25: =+AO25+AP25 -> 83136.543
A26: SUBFCARVA | B26: 89050 | C26: COL2 | D26: COL2 | E26: CARVAJAL | F26: FCPERSNL | G26: Alternative Education Specialist | H26: Alternative Education Specialist | I26: Rufina González | J26: 0 | K26: 0 | L26: 14276.65 | M26: 0 | N26: 11067.62 | O26: 0 | P26: 1 | Q26: 1555.4 | R26: 0 | S26: =+Q26*R26 -> 0 | T26: 0 | U26: =SUM(S26:T26) -> 0 | V26: 1 | W26: =+Q26*10%+Q26 -> 1710.94 | X26: 12 | Y26: =+W26*X26 -> 20531.28 | Z26: 0 | AA26: =SUM(Y26:Z26) -> 20531.28 | AB26: 1 | AC26: =+W26*10%+W26 -> 1882.034 | AD26: 6 | AE26: =AB26*AC26*AD26 -> 11292.204 | AF26: 0 | AG26: =SUM(AE26:AF26) -> 11292.204 | AH26: =+J26+L26+N26 -> 25344.27 | AI26: =+K26+M26+O26 -> 0 | AJ26: =+AH26+AI26 -> 25344.27 | AK26: =+S26+Y26+AE26 -> 31823.484 | AL26: =+T26+Z26+AF26 -> 0 | AM26: =+AK26+AL26 -> 31823.484 | AO26: =+AH26+AK26 -> 57167.754 | AP26: =+AI26+AL26 -> 0 | AQ26: =+AO26+AP26 -> 57167.754
A27: SUBFCARVA | B27: 89050 | C27: COL2 | D27: COL2 | E27: CARVAJAL | F27: FCPERSNL/ FCPERSNLEV | G27: Methodological Coordinator - Flexible Learning Models | H27: Methodological Coordinator/Specialist - MEF | I27: María Eugenia López Maya | J27: 4573.43 | K27: 0 | L27: 12040.88 | M27: 0 | N27: 13903.73 | O27: 0 | P27: 1 | Q27: 1536.1 | R27: 12 | S27: =+Q27*R27 -> 18433.2 | T27: 0 | U27: =SUM(S27:T27) -> 18433.2 | V27: 1 | W27: =+Q27*10%+Q27 -> 1689.71 | X27: 12 | Y27: =+W27*X27 -> 20276.52 | Z27: 0 | AA27: =SUM(Y27:Z27) -> 20276.52 | AB27: 1 | AC27: =+W27*10%+W27 -> 1858.681 | AD27: 6 | AE27: =AB27*AC27*AD27 -> 11152.086 | AF27: 0 | AG27: =SUM(AE27:AF27) -> 11152.086 | AH27: =+J27+L27+N27 -> 30518.04 | AI27: =+K27+M27+O27 -> 0 | AJ27: =+AH27+AI27 -> 30518.04 | AK27: =+S27+Y27+AE27 -> 49861.806 | AL27: =+T27+Z27+AF27 -> 0 | AM27: =+AK27+AL27 -> 49861.806 | AO27: =+AH27+AK27 -> 80379.846 | AP27: =+AI27+AL27 -> 0 | AQ27: =+AO27+AP27 -> 80379.846
H28: Learning Trajectories Manager | I28: Jorge Alberto Riveros | J28: 0 | K28: 0 | L28: 17164.83 | M28: 0 | N28: 23283.11 | O28: 0 | P28: 1 | Q28: 2269.38 | R28: 12 | S28: =+Q28*R28 -> 27232.56 | T28: 0 | U28: =SUM(S28:T28) -> 27232.56 | V28: 1 | W28: =+Q28*10%+Q28 -> 2496.318 | X28: 12 | Y28: =+W28*X28 -> 29955.816 | Z28: 0 | AA28: =SUM(Y28:Z28) -> 29955.816 | AB28: 1 | AC28: =+W28*10%+W28 -> 2745.9498 | AD28: 6 | AE28: =AB28*AC28*AD28 -> 16475.699 | AF28: 0 | AG28: =SUM(AE28:AF28) -> 16475.699 | AH28: =+J28+L28+N28 -> 40447.94 | AI28: =+K28+M28+O28 -> 0 | AJ28: =+AH28+AI28 -> 40447.94 | AK28: =+S28+Y28+AE28 -> 73664.075 | AL28: =+T28+Z28+AF28 -> 0 | AM28: =+AK28+AL28 -> 73664.075 | AO28: =+AH28+AK28 -> 114112.01 | AP28: =+AI28+AL28 -> 0 | AQ28: =+AO28+AP28 -> 114112.01
H29: Migration Officer | I29: Lecsy Bibiana Avendaño | J29: 0 | K29: 0 | L29: 0 | M29: 0 | N29: 0 | O29: 0 | P29: 1 | Q29: 993.99 | R29: 10 | S29: =+Q29*R29 -> 9939.9 | T29: 0 | U29: =SUM(S29:T29) -> 9939.9 | V29: 1 | W29: =+Q29*10%+Q29 -> 1093.389 | X29: 12 | Y29: =+W29*X29 -> 13120.668 | Z29: 0 | AA29: =SUM(Y29:Z29) -> 13120.668 | AB29: 1 | AC29: =+W29*10%+W29 -> 1202.7279 | AD29: 6 | AE29: =AB29*AC29*AD29 -> 7216.3674 | AF29: 0 | AG29: =SUM(AE29:AF29) -> 7216.3674 | AH29: =+J29+L29+N29 -> 0 | AI29: =+K29+M29+O29 -> 0 | AJ29: =+AH29+AI29 -> 0 | AK29: =+S29+Y29+AE29 -> 30276.935 | AL29: =+T29+Z29+AF29 -> 0 | AM29: =+AK29+AL29 -> 30276.935 | AO29: =+AH29+AK29 -> 30276.935 | AP29: =+AI29+AL29 -> 0 | AQ29: =+AO29+AP29 -> 30276.935
G30: Subtotal HQ Personnel | H30: Subtotal HQ + Core Technical Team Personnel | J30: =+SUM(J15:J29) -> 34954.66 | K30: =+SUM(K15:K29) -> 1087.7 | L30: =+SUM(L15:L29) -> 167740.19 | M30: =+SUM(M15:M29) -> 0 | N30: =+SUM(N15:N29) -> 171791.95 | O30: =+SUM(O15:O29) -> 8197.2 | Q30: =+SUM(Q15:Q29) -> 18709.27 | S30: =+SUM(S15:S29) -> 201396.29 | T30: =+SUM(T15:T29) -> 7401.345 | U30: =+SUM(U15:U29) -> 208797.63 | W30: =+SUM(W15:W29) -> 20580.197 | Y30: =+SUM(Y15:Y29) -> 246962.36 | Z30: =+SUM(Z15:Z29) -> 8141.4795 | AA30: =+SUM(AA15:AA29) -> 255103.84 | AC30: =+SUM(AC15:AC29) -> 22638.217 | AE30: =+SUM(AE15:AE29) -> 146017.72 | AF30: =+SUM(AF15:AF29) -> 5970.4183 | AG30: =+SUM(AG15:AG29) -> 151988.14 | AH30: =+SUM(AH15:AH29) -> 374486.8 | AI30: =+SUM(AI15:AI29) -> 9284.9 | AJ30: =+SUM(AJ15:AJ29) -> 383771.7 | AK30: =+SUM(AK15:AK29) -> 594376.37 | AL30: =+SUM(AL15:AL29) -> 21513.243 | AM30: =+SUM(AM15:AM29) -> 615889.61 | AO30: =+SUM(AO15:AO29) -> 968863.17 | AP30: =+SUM(AP15:AP29) -> 30798.143 | AQ30: =+SUM(AQ15:AQ29) -> 999661.31
G31: Field Personnel (include Level of Effort) | H31: Field Personnel
H32: M&E Team | I32: M&E Team
A33: SUBFCARVA | B33: 89050 | C33: COL2 | D33: COL2 | E33: CARVAJAL | F33: FCPERSNL | G33: Monitoring and Evaluation Specialist | H33: Monitoring and Evaluation Specialist | I33: Ángela Patricia Bedoya Valdés | J33: 5221.52 | K33: 0 | L33: 13894.7 | M33: 0 | N33: 15216.99 | O33: 0 | P33: 1 | Q33: 1495.08 | R33: 12 | S33: =+Q33*R33 -> 17940.96 | T33: 0 | U33: =SUM(S33:T33) -> 17940.96 | V33: 1 | W33: =+Q33*10%+Q33 -> 1644.588 | X33: 12 | Y33: =+W33*X33 -> 19735.056 | Z33: 0 | AA33: =SUM(Y33:Z33) -> 19735.056 | AB33: 1 | AC33: =+W33*10%+W33 -> 1809.0468 | AD33: 8 | AE33: =AB33*AC33*AD33 -> 14472.374 | AF33: 0 | AG33: =SUM(AE33:AF33) -> 14472.374 | AH33: =+J33+L33+N33 -> 34333.21 | AI33: =+K33+M33+O33 -> 0 | AJ33: =+AH33+AI33 -> 34333.21 | AK33: =+S33+Y33+AE33 -> 52148.39 | AL33: =+T33+Z33+AF33 -> 0 | AM33: =+AK33+AL33 -> 52148.39 | AO33: =+AH33+AK33 -> 86481.6 | AP33: =+AI33+AL33 -> 0 | AQ33: =+AO33+AP33 -> 86481.6
A34: SUBFCARVA | B34: 89050 | C34: COL2 | D34: COL2 | E34: CARVAJAL | F34: FCPERSNL | G34: Information System Professional | H34: Information System Professional | I34: Isabella Ríos | J34: 3794.35 | K34: 0 | L34: 9100.49 | M34: 0 | N34: 1087.16 | O34: 0 | P34: 0 | Q34: 0 | R34: 0 | S34: =+Q34*R34 -> 0 | T34: 0 | U34: =SUM(S34:T34) -> 0 | V34: 0 | W34: 0 | X34: 0 | Y34: =+W34*X34 -> 0 | Z34: 0 | AA34: =SUM(Y34:Z34) -> 0 | AB34: 0 | AC34: 0 | AD34: 0 | AE34: =AB34*AC34*AD34 -> 0 | AF34: 0 | AG34: =SUM(AE34:AF34) -> 0 | AH34: =+J34+L34+N34 -> 13982 | AI34: =+K34+M34+O34 -> 0 | AJ34: =+AH34+AI34 -> 13982 | AK34: =+S34+Y34+AE34 -> 0 | AL34: =+T34+Z34+AF34 -> 0 | AM34: =+AK34+AL34 -> 0 | AO34: =+AH34+AK34 -> 13982 | AP34: =+AI34+AL34 -> 0 | AQ34: =+AO34+AP34 -> 13982
H35: Information System Professional | I35: Carolina Rojas Sánchez | J35: 0 | K35: 0 | L35: 8194.5 | M35: 0 | N35: 10865.45 | O35: 0 | P35: 1 | Q35: 1054.97 | R35: 12 | S35: =+Q35*R35 -> 12659.64 | T35: 0 | U35: =SUM(S35:T35) -> 12659.64 | V35: 1 | W35: =+Q35*10%+Q35 -> 1160.467 | X35: 12 | Y35: =+W35*X35 -> 13925.604 | Z35: 0 | AA35: =SUM(Y35:Z35) -> 13925.604 | AB35: 1 | AC35: =+W35*10%+W35 -> 1276.5137 | AD35: 6 | AE35: =AB35*AC35*AD35 -> 7659.0822 | AF35: 0 | AG35: =SUM(AE35:AF35) -> 7659.0822 | AH35: =+J35+L35+N35 -> 19059.95 | AI35: =+K35+M35+O35 -> 0 | AJ35: =+AH35+AI35 -> 19059.95 | AK35: =+S35+Y35+AE35 -> 34244.326 | AL35: =+T35+Z35+AF35 -> 0 | AM35: =+AK35+AL35 -> 34244.326 | AO35: =+AH35+AK35 -> 53304.276 | AP35: =+AI35+AL35 -> 0 | AQ35: =+AO35+AP35 -> 53304.276
H36: Information System Professional | I36: Daniela Alejandra Mendieta | J36: 0 | K36: 0 | L36: 0 | M36: 0 | N36: 8985.85 | O36: 0 | P36: 1 | Q36: 878.7 | R36: 12 | S36: =+Q36*R36 -> 10544.4 | T36: 0 | U36: =SUM(S36:T36) -> 10544.4 | V36: 1 | W36: =+Q36*10%+Q36 -> 966.57 | X36: 12 | Y36: =+W36*X36 -> 11598.84 | Z36: 0 | AA36: =SUM(Y36:Z36) -> 11598.84 | AB36: 1 | AC36: =+W36*10%+W36 -> 1063.227 | AD36: 6 | AE36: =AB36*AC36*AD36 -> 6379.362 | AF36: 0 | AG36: =SUM(AE36:AF36) -> 6379.362 | AH36: =+J36+L36+N36 -> 8985.85 | AI36: =+K36+M36+O36 -> 0 | AJ36: =+AH36+AI36 -> 8985.85 | AK36: =+S36+Y36+AE36 -> 28522.602 | AL36: =+T36+Z36+AF36 -> 0 | AM36: =+AK36+AL36 -> 28522.602 | AO36: =+AH36+AK36 -> 37508.452 | AP36: =+AI36+AL36 -> 0 | AQ36: =+AO36+AP36 -> 37508.452
H37: Information System Professional | I37: Juan Guillermo Salguero Astudillo | J37: 0 | K37: 0 | L37: 0 | M37: 0 | N37: 8663.78 | O37: 0 | P37: 1 | Q37: 878.7 | R37: 12 | S37: =+Q37*R37 -> 10544.4 | T37: 0 | U37: =SUM(S37:T37) -> 10544.4 | V37: 1 | W37: =+Q37*10%+Q37 -> 966.57 | X37: 12 | Y37: =+W37*X37 -> 11598.84 | Z37: 0 | AA37: =SUM(Y37:Z37) -> 11598.84 | AB37: 1 | AC37: =+W37*10%+W37 -> 1063.227 | AD37: 6 | AE37: =AB37*AC37*AD37 -> 6379.362 | AF37: 0 | AG37: =SUM(AE37:AF37) -> 6379.362 | AH37: =+J37+L37+N37 -> 8663.78 | AI37: =+K37+M37+O37 -> 0 | AJ37: =+AH37+AI37 -> 8663.78 | AK37: =+S37+Y37+AE37 -> 28522.602 | AL37: =+T37+Z37+AF37 -> 0 | AM37: =+AK37+AL37 -> 28522.602 | AO37: =+AH37+AK37 -> 37186.382 | AP37: =+AI37+AL37 -> 0 | AQ37: =+AO37+AP37 -> 37186.382
H38: Information System Professional | I38: Ma. Alejandra Pinzón | J38: 0 | K38: 0 | L38: 0 | M38: 0 | N38: 8065.44 | O38: 0 | P38: 1 | Q38: 1062.71 | R38: 12 | S38: =+Q38*R38 -> 12752.52 | T38: 0 | U38: =SUM(S38:T38) -> 12752.52 | V38: 1 | W38: =+Q38*10%+Q38 -> 1168.981 | X38: 12 | Y38: =+W38*X38 -> 14027.772 | Z38: 0 | AA38: =SUM(Y38:Z38) -> 14027.772 | AB38: 1 | AC38: =+W38*10%+W38 -> 1285.8791 | AD38: 6 | AE38: =AB38*AC38*AD38 -> 7715.2746 | AF38: 0 | AG38: =SUM(AE38:AF38) -> 7715.2746 | AH38: =+J38+L38+N38 -> 8065.44 | AI38: =+K38+M38+O38 -> 0 | AJ38: =+AH38+AI38 -> 8065.44 | AK38: =+S38+Y38+AE38 -> 34495.567 | AL38: =+T38+Z38+AF38 -> 0 | AM38: =+AK38+AL38 -> 34495.567 | AO38: =+AH38+AK38 -> 42561.007 | AP38: =+AI38+AL38 -> 0 | AQ38: =+AO38+AP38 -> 42561.007
H39: Grants Team
A40: SUBFCARVA | B40: 89050 | C40: COL2 | D40: COL2 | E40: CARVAJAL | F40: FCPERSNL | G40: Grants & Compliance Coordinator | H40: Grants Specialist | I40: Adriana Rodríguez | J40: 4459.29 | K40: 0 | L40: 18701.01 | M40: 0 | N40: 19770.92 | O40: 0 | P40: 1 | Q40: 1748.82 | R40: 12 | S40: =+Q40*R40 -> 20985.84 | T40: 0 | U40: =SUM(S40:T40) -> 20985.84 | V40: 1 | W40: =+Q40*10%+Q40 -> 1923.702 | X40: 12 | Y40: =V40*W40*X40 -> 23084.424 | Z40: 0 | AA40: =SUM(Y40:Z40) -> 23084.424 | AB40: 1 | AC40: =+W40*10%+W40 -> 2116.0722 | AD40: 6 | AE40: =AB40*AC40*AD40 -> 12696.433 | AF40: 0 | AG40: =SUM(AE40:AF40) -> 12696.433 | AH40: =+J40+L40+N40 -> 42931.22 | AI40: =+K40+M40+O40 -> 0 | AJ40: =+AH40+AI40 -> 42931.22 | AK40: =+S40+Y40+AE40 -> 56766.697 | AL40: =+T40+Z40+AF40 -> 0 | AM40: =+AK40+AL40 -> 56766.697 | AO40: =+AH40+AK40 -> 99697.917 | AP40: =+AI40+AL40 -> 0 | AQ40: =+AO40+AP40 -> 99697.917
H41: 2nd Tier Subawardess Technical Supervisor | I41: José García | J41: 0 | K41: 0 | L41: 7199.58 | M41: 0 | N41: 12801.36 | O41: 0 | P41: 1 | Q41: 1284.54 | R41: 6 | S41: =+Q41*R41 -> 7707.24 | T41: 0 | U41: =SUM(S41:T41) -> 7707.24 | V41: 1 | W41: =+Q41*10%+Q41 -> 1412.994 | X41: 12 | Y41: =V41*W41*X41 -> 16955.928 | Z41: 0 | AA41: =SUM(Y41:Z41) -> 16955.928 | AB41: 1 | AC41: =+W41*10%+W41 -> 1554.2934 | AD41: 6 | AE41: =AB41*AC41*AD41 -> 9325.7604 | AF41: 0 | AG41: =SUM(AE41:AF41) -> 9325.7604 | AH41: =+J41+L41+N41 -> 20000.94 | AI41: =+K41+M41+O41 -> 0 | AJ41: =+AH41+AI41 -> 20000.94 | AK41: =+S41+Y41+AE41 -> 33988.928 | AL41: =+T41+Z41+AF41 -> 0 | AM41: =+AK41+AL41 -> 33988.928 | AO41: =+AH41+AK41 -> 53989.868 | AP41: =+AI41+AL41 -> 0 | AQ41: =+AO41+AP41 -> 53989.868
H42: F&A Team
...

Sheet 800-FC - Consolidated Details
A4: Entity: | B4: P
A5: Program-Dept.: | B5: 20300 | G5: Modification 7 - Budget Assumptions
A6: Funder-Grant: | B6: USAID800 | G6: Inflation - Locally Purchased Goods/Services - 8%
G7: Merit Based Increases for HQ & Field Staff - 10%
H9: Actuals/Estimates Year 1 and 2 and 3 (January 1, 2023 - December 31, 2023) | N9: Projections for Year 3 (January 1, 2024 - December 31, 2024) - 6 | AM9: New Proposed Budget Total
A10: Sage Activity | B10: Sage Object Code/ Line Item | C10: Country Code (DC=0 or CO) | D10: Office Code (DC=0 or CO) | E10: Subcontract Code | F10: Open 1 Code | H10: USAID Year 1 -Actuals August 16, 2021 - December 31, 2021 | I10: Leverage Year 1 - Actuals August 16, 2021 - December 31, 2021 | J10: USAID Year 2 - Actuals January 1, 2022 - December 31, 2022 | K10: Leverage Year 2 - Actuals January 1, 2022 - December 31, 2022 | L10: USAID Year 3 - Actuals January 1, 2023 - December 31, 2023 | M10: Leverage Year 3 - Actuals January 1, 2023 - July 31, 2023 | N10: Year 4 - January 1, 2024 - December 31, 2024 | T10: Year 5 - January 1, 2025 - December 31, 2025 | Z10: Year 6 - January 1, 2026 - Agosto 31, 2026 | AF10: Actuals Year 1- 3 | AG10: Actuals Year 1- 3 | AH10: Actuals Year 1- 3 | AI10: Year 4- 6 | AJ10: Year 4- 6 | AK10: Year 4- 6 | AM10: Total | AN10: Total | AO10: Grand
N11: Unit LOE | O11: Cost | P11: Duration | Q11: USAID | R11: Leverage | S11: Total | T11: Unit LOE | U11: Cost | V11: Duration | W11: USAID | X11: Leverage | Y11: Total | Z11: Unit | AA11: Cost | AB11: Duration | AC11: USAID | AD11: Leverage | AE11: Total | AF11: Total USAID | AG11: Total Leverage | AH11: Grand Total | AI11: Total USAID | AJ11: Total Leverage | AK11: Grand Total | AM11: USAID | AN11: Leverage | AO11: Total
G12: 1. Personnel
G13: Headquarters Personnel (include Level of Effort)
G14: Fundación Carvajal Management Team
A15: SUBFCARVA | B15: 89050 | C15: COL2 | D15: COL2 | E15: CARVAJAL | F15: FCPERSNL/ FCPERSNLEV | G15: Program Director/Management Team | H15: 9207.63 | I15: 1087.7 | J15: 21864.25 | K15: 0 | L15: 16983.86 | M15: 8197.2 | N15: 0.26 | O15: 1641.45 | P15: 10.5 | Q15: =+O15*P15 -> 17235.225 | R15: =704.89*10.5 -> 7401.345 | S15: =SUM(Q15:R15) -> 24636.57 | T15: 0.5 | U15: =+O15*10%+O15 -> 1805.595 | V15: 12 | W15: =+U15*V15 -> 21667.14 | X15: =+R15*1.1 -> 8141.4795 | Y15: =SUM(W15:X15) -> 29808.62 | Z15: 0.5 | AA15: =+U15*1.1 -> 1986.1545 | AB15: 8 | AC15: =Z15*AA15*AB15 -> 7944.618 | AD15: =+(X15*1.1)/12*AB15 -> 5970.4183 | AE15: =SUM(AC15:AD15) -> 13915.036 | AF15: =+H15+J15+L15 -> 48055.74 | AG15: =+I15+K15+M15 -> 9284.9 | AH15: =+AF15+AG15 -> 57340.64 | AI15: =+Q15+W15+AC15 -> 46846.983 | AJ15: =+R15+X15+AD15 -> 21513.243 | AK15: =+AI15+AJ15 -> 68360.226 | AM15: =+AF15+AI15 -> 94902.723 | AN15: =+AG15+AJ15 -> 30798.143 | AO15: =+AM15+AN15 -> 125700.87
A16: SUBFCARVA | B16: 89050 | C16: COL2 | D16: COL2 | E16: CARVAJAL | F16: FCPERSNL | G16: Education Director* | H16: 4793.31 | I16: 0 | J16: 37385.23 | K16: 0 | L16: 41755.1 | M16: 0 | N16: 1 | O16: 4172.84 | P16: 12 | Q16: =O16*P16 -> 50074.08 | R16: 0 | S16: =SUM(Q16:R16) -> 50074.08 | T16: 1 | U16: =+O16*10%+O16 -> 4590.124 | V16: 12 | W16: =+U16*V16 -> 55081.488 | X16: 0 | Y16: =SUM(W16:X16) -> 55081.488 | Z16: 1 | AA16: =+U16*10%+U16 -> 5049.1364 | AB16: 8 | AC16: =Z16*AA16*AB16 -> 40393.091 | AD16: 0 | AE16: =SUM(AC16:AD16) -> 40393.091 | AF16: =+H16+J16+L16 -> 83933.64 | AG16: =+I16+K16+M16 -> 0 | AH16: =+AF16+AG16 -> 83933.64 | AI16: =+Q16+W16+AC16 -> 145548.66 | AJ16: =+R16+X16+AD16 -> 0 | AK16: =+AI16+AJ16 -> 145548.66 | AM16: =+AF16+AI16 -> 229482.3 | AN16: =+AG16+AJ16 -> 0 | AO16: =+AM16+AN16 -> 229482.3
G17: Core Technical Team | AO17: =+AM17+AN17 -> 0
A18: SUBFCARVA | B18: 89050 | C18: COL2 | D18: COL2 | E18: CARVAJAL | F18: FCPERSNL | G18: Education Manager | H18: 8591.19 | I18: 0 | J18: 21376.46 | K18: 0 | L18: 0 | M18: 0 | N18: 0 | O18: 0 | P18: 0 | Q18: =+O18*P18 -> 0 | R18: 0 | S18: =SUM(Q18:R18) -> 0 | T18: 0 | U18: 0 | V18: 0 | W18: =+U18*V18 -> 0 | X18: 0 | Y18: =SUM(W18:X18) -> 0 | Z18: 0 | AA18: 0 | AB18: 0 | AC18: =Z18*AA18*AB18 -> 0 | AD18: 0 | AE18: =SUM(AC18:AD18) -> 0 | AF18: =+H18+J18+L18 -> 29967.65 | AG18: =+I18+K18+M18 -> 0 | AH18: =+AF18+AG18 -> 29967.65 | AI18: =+Q18+W18+AC18 -> 0 | AJ18: =+R18+X18+AD18 -> 0 | AK18: =+AI18+AJ18 -> 0 | AM18: =+AF18+AI18 -> 29967.65 | AN18: =+AG18+AJ18 -> 0 | AO18: =+AM18+AN18 -> 29967.65
G19: Education Coordinator | H19: 0 | I19: 0 | J19: 0 | K19: 0 | L19: 14944.37 | M19: 0 | N19: 1 | O19: 1678.7 | P19: 12 | Q19: =+O19*P19 -> 20144.4 | R19: 0 | S19: =SUM(Q19:R19) -> 20144.4 | T19: 1 | U19: =+O19*10%+O19 -> 1846.57 | V19: 12 | W19: =+U19*V19 -> 22158.84 | X19: 0 | Y19: =SUM(W19:X19) -> 22158.84 | Z19: 1 | AA19: =+U19*10%+U19 -> 2031.227 | AB19: 8 | AC19: =Z19*AA19*AB19 -> 16249.816 | AD19: 0 | AE19: =SUM(AC19:AD19) -> 16249.816 | AF19: =+H19+J19+L19 -> 14944.37 | AG19: =+I19+K19+M19 -> 0 | AH19: =+AF19+AG19 -> 14944.37 | AI19: =+Q19+W19+AC19 -> 58553.056 | AJ19: =+R19+X19+AD19 -> 0 | AK19: =+AI19+AJ19 -> 58553.056 | AM19: =+AF19+AI19 -> 73497.426 | AN19: =+AG19+AJ19 -> 0 | AO19: =+AM19+AN19 -> 73497.426
A20: SUBFCARVA | B20: 89050 | C20: COL2 | D20: COL2 | E20: CARVAJAL | F20: FCPERSNL | G20: Pre-Primary Education Specialist | H20: 1992.97 | I20: 0 | J20: 16987.89 | K20: 0 | L20: 16923 | M20: 0 | N20: 1 | O20: 1645.65 | P20: 12 | Q20: =+O20*P20 -> 19747.8 | R20: 0 | S20: =SUM(Q20:R20) -> 19747.8 | T20: 1 | U20: =+O20*10%+O20 -> 1810.215 | V20: 12 | W20: =+U20*V20 -> 21722.58 | X20: 0 | Y20: =SUM(W20:X20) -> 21722.58 | Z20: 1 | AA20: =+U20*10%+U20 -> 1991.2365 | AB20: 6 | AC20: =Z20*AA20*AB20 -> 11947.419 | AD20: 0 | AE20: =SUM(AC20:AD20) -> 11947.419 | AF20: =+H20+J20+L20 -> 35903.86 | AG20: =+I20+K20+M20 -> 0 | AH20: =+AF20+AG20 -> 35903.86 | AI20: =+Q20+W20+AC20 -> 53417.799 | AJ20: =+R20+X20+AD20 -> 0 | AK20: =+AI20+AJ20 -> 53417.799 | AM20: =+AF20+AI20 -> 89321.659 | AN20: =+AG20+AJ20 -> 0 | AO20: =+AM20+AN20 -> 89321.659
A21: SUBFCARVA | B21: 89050 | C21: COL2 | D21: COL2 | E21: CARVAJAL | F21: FCPERSNL | G21: Primary Education Specialist | H21: 5796.13 | I21: 0 | J21: 14394.25 | K21: 0 | L21: 15856.88 | M21: 0 | N21: 1 | O21: 1557.95 | P21: 12 | Q21: =+O21*P21 -> 18695.4 | R21: 0 | S21: =SUM(Q21:R21) -> 18695.4 | T21: 1 | U21: =+O21*10%+O21 -> 1713.745 | V21: 12 | W21: =+U21*V21 -> 20564.94 | X21: 0 | Y21: =SUM(W21:X21) -> 20564.94 | Z21: 1 | AA21: =+U21*10%+U21 -> 1885.1195 | AB21: 6 | AC21: =Z21*AA21*AB21 -> 11310.717 | AD21: 0 | AE21: =SUM(AC21:AD21) -> 11310.717 | AF21: =+H21+J21+L21 -> 36047.26 | AG21: =+I21+K21+M21 -> 0 | AH21: =+AF21+AG21 -> 36047.26 | AI21: =+Q21+W21+AC21 -> 50571.057 | AJ21: =+R21+X21+AD21 -> 0 | AK21: =+AI21+AJ21 -> 50571.057 | AM21: =+AF21+AI21 -> 86618.317 | AN21: =+AG21+AJ21 -> 0 | AO21: =+AM21+AN21 -> 86618.317
A22: SUBFCARVA | B22: 89050 | C22: COL2 | D22: COL2 | E22: CARVAJAL | F22: FCPERSNL | G22: Secondary Education Specialist | H22: 0 | I22: 0 | J22: 12249.75 | K22: 0 | L22: 17074.28 | M22: 0 | N22: 1 | O22: 1657.81 | P22: 12 | Q22: =+O22*P22 -> 19893.72 | R22: 0 | S22: =SUM(Q22:R22) -> 19893.72 | T22: 1 | U22: =+O22*10%+O22 -> 1823.591 | V22: 12 | W22: =+U22*V22 -> 21883.092 | X22: 0 | Y22: =SUM(W22:X22) -> 21883.092 | Z22: 1 | AA22: =+U22*10%+U22 -> 2005.9501 | AB22: 6 | AC22: =Z22*AA22*AB22 -> 12035.701 | AD22: 0 | AE22: =SUM(AC22:AD22) -> 12035.701 | AF22: =+H22+J22+L22 -> 29324.03 | AG22: =+I22+K22+M22 -> 0 | AH22: =+AF22+AG22 -> 29324.03 | AI22: =+Q22+W22+AC22 -> 53812.513 | AJ22: =+R22+X22+AD22 -> 0 | AK22: =+AI22+AJ22 -> 53812.513 | AM22: =+AF22+AI22 -> 83136.543 | AN22: =+AG22+AJ22 -> 0 | AO22: =+AM22+AN22 -> 83136.543
A23: SUBFCARVA | B23: 89050 | C23: COL2 | D23: COL2 | E23: CARVAJAL | F23: FCPERSNL | G23: Alternative Education Specialist | H23: 0 | I23: 0 | J23: 14276.65 | K23: 0 | L23: 11067.62 | M23: 0 | N23: 1 | O23: 1555.4 | P23: 0 | Q23: =+O23*P23 -> 0 | R23: 0 | S23: =SUM(Q23:R23) -> 0 | T23: 1 | U23: =+O23*10%+O23 -> 1710.94 | V23: 12 | W23: =+U23*V23 -> 20531.28 | X23: 0 | Y23: =SUM(W23:X23) -> 20531.28 | Z23: 1 | AA23: =+U23*10%+U23 -> 1882.034 | AB23: 6 | AC23: =Z23*AA23*AB23 -> 11292.204 | AD23: 0 | AE23: =SUM(AC23:AD23) -> 11292.204 | AF23: =+H23+J23+L23 -> 25344.27 | AG23: =+I23+K23+M23 -> 0 | AH23: =+AF23+AG23 -> 25344.27 | AI23: =+Q23+W23+AC23 -> 31823.484 | AJ23: =+R23+X23+AD23 -> 0 | AK23: =+AI23+AJ23 -> 31823.484 | AM23: =+AF23+AI23 -> 57167.754 | AN23: =+AG23+AJ23 -> 0 | AO23: =+AM23+AN23 -> 57167.754
A24: SUBFCARVA | B24: 89050 | C24: COL2 | D24: COL2 | E24: CARVAJAL | F24: FCPERSNL | G24: Methodological Coordinator/Specialist - MEF | H24: 4573.43 | I24: 0 | J24: 12040.88 | K24: 0 | L24: 13903.73 | M24: 0 | N24: 1 | O24: 1536.1 | P24: 12 | Q24: =+O24*P24 -> 18433.2 | R24: 0 | S24: =SUM(Q24:R24) -> 18433.2 | T24: 1 | U24: =+O24*10%+O24 -> 1689.71 | V24: 12 | W24: =+U24*V24 -> 20276.52 | X24: 0 | Y24: =SUM(W24:X24) -> 20276.52 | Z24: 1 | AA24: =+U24*10%+U24 -> 1858.681 | AB24: 6 | AC24: =Z24*AA24*AB24 -> 11152.086 | AD24: 0 | AE24: =SUM(AC24:AD24) -> 11152.086 | AF24: =+H24+J24+L24 -> 30518.04 | AG24: =+I24+K24+M24 -> 0 | AH24: =+AF24+AG24 -> 30518.04 | AI24: =+Q24+W24+AC24 -> 49861.806 | AJ24: =+R24+X24+AD24 -> 0 | AK24: =+AI24+AJ24 -> 49861.806 | AM24: =+AF24+AI24 -> 80379.846 | AN24: =+AG24+AJ24 -> 0 | AO24: =+AM24+AN24 -> 80379.846
A25: SUBFCARVA | B25: 89050 | C25: COL2 | D25: COL2 | E25: CARVAJAL | F25: FCPERSNL | G25: Learning Trajectories Manager | H25: 0 | I25: 0 | J25: 17164.83 | K25: 0 | L25: 23283.11 | M25: 0 | N25: 1 | O25: 2269.38 | P25: 12 | Q25: =+O25*P25 -> 27232.56 | R25: 0 | S25: =SUM(Q25:R25) -> 27232.56 | T25: 1 | U25: =+O25*10%+O25 -> 2496.318 | V25: 12 | W25: =+U25*V25 -> 29955.816 | X25: 0 | Y25: =SUM(W25:X25) -> 29955.816 | Z25: 1 | AA25: =+U25*10%+U25 -> 2745.9498 | AB25: 6 | AC25: =Z25*AA25*AB25 -> 16475.699 | AD25: 0 | AE25: =SUM(AC25:AD25) -> 16475.699 | AF25: =+H25+J25+L25 -> 40447.94 | AG25: =+I25+K25+M25 -> 0 | AH25: =+AF25+AG25 -> 40447.94 | AI25: =+Q25+W25+AC25 -> 73664.075 | AJ25: =+R25+X25+AD25 -> 0 | AK25: =+AI25+AJ25 -> 73664.075 | AM25: =+AF25+AI25 -> 114112.01 | AN25: =+AG25+AJ25 -> 0 | AO25: =+AM25+AN25 -> 114112.01
A26: SUBFCARVA | B26: 89050 | C26: COL2 | D26: COL2 | E26: CARVAJAL | F26: FCPERSNL | G26: Migration Officer | H26: 0 | I26: 0 | J26: 0 | K26: 0 | L26: 0 | M26: 0 | N26: 1 | O26: 993.99 | P26: 10 | Q26: =+O26*P26 -> 9939.9 | R26: 0 | S26: =SUM(Q26:R26) -> 9939.9 | T26: 1 | U26: =+O26*10%+O26 -> 1093.389 | V26: 12 | W26: =+U26*V26 -> 13120.668 | X26: 0 | Y26: =SUM(W26:X26) -> 13120.668 | Z26: 1 | AA26: =+U26*10%+U26 -> 1202.7279 | AB26: 6 | AC26: =Z26*AA26*AB26 -> 7216.3674 | AD26: 0 | AE26: =SUM(AC26:AD26) -> 7216.3674 | AF26: =+H26+J26+L26 -> 0 | AG26: =+I26+K26+M26 -> 0 | AH26: =+AF26+AG26 -> 0 | AI26: =+Q26+W26+AC26 -> 30276.935 | AJ26: =+R26+X26+AD26 -> 0 | AK26: =+AI26+AJ26 -> 30276.935 | AM26: =+AF26+AI26 -> 30276.935 | AN26: =+AG26+AJ26 -> 0 | AO26: =+AM26+AN26 -> 30276.935
G27: Subtotal HQ + Core Technical Team Personnel | H27: =+SUM(H15:H26) -> 34954.66 | I27: =+SUM(I15:I26) -> 1087.7 | J27: =+SUM(J15:J26) -> 167740.19 | K27: =+SUM(K15:K26) -> 0 | L27: =+SUM(L15:L26) -> 171791.95 | M27: =+SUM(M15:M26) -> 8197.2 | O27: =+SUM(O15:O26) -> 18709.27 | Q27: =+SUM(Q15:Q26) -> 201396.29 | R27: =+SUM(R15:R26) -> 7401.345 | S27: =+SUM(S15:S26) -> 208797.63 | U27: =+SUM(U15:U26) -> 20580.197 | W27: =+SUM(W15:W26) -> 246962.36 | X27: =+SUM(X15:X26) -> 8141.4795 | Y27: =+SUM(Y15:Y26) -> 255103.84 | AA27: =+SUM(AA15:AA26) -> 22638.217 | AC27: =+SUM(AC15:AC26) -> 146017.72 | AD27: =+SUM(AD15:AD26) -> 5970.4183 | AE27: =+SUM(AE15:AE26) -> 151988.14 | AF27: =+SUM(AF15:AF26) -> 374486.8 | AG27: =+SUM(AG15:AG26) -> 9284.9 | AH27: =+SUM(AH15:AH26) -> 383771.7 | AI27: =+SUM(AI15:AI26) -> 594376.37 | AJ27: =+SUM(AJ15:AJ26) -> 21513.243 | AK27: =+SUM(AK15:AK26) -> 615889.61 | AM27: =+SUM(AM15:AM26) -> 968863.17 | AN27: =+SUM(AN15:AN26) -> 30798.143 | AO27: =+SUM(AO15:AO26) -> 999661.31
G28: Field Personnel
G29: M&E Team
A30: SUBFCARVA | B30: 89050 | C30: COL2 | D30: COL2 | E30: CARVAJAL | F30: FCPERSNL | G30: Monitoring and Evaluation Specialist | H30: 5221.52 | I30: 0 | J30: 13894.7 | K30: 0 | L30: 15216.99 | M30: 0 | N30: 1 | O30: 1495.08 | P30: 12 | Q30: =+O30*P30 -> 17940.96 | R30: 0 | S30: =SUM(Q30:R30) -> 17940.96 | T30: 1 | U30: =+O30*10%+O30 -> 1644.588 | V30: 12 | W30: =+U30*V30 -> 19735.056 | X30: 0 | Y30: =SUM(W30:X30) -> 19735.056 | Z30: 1 | AA30: =+U30*10%+U30 -> 1809.0468 | AB30: 8 | AC30: =Z30*AA30*AB30 -> 14472.374 | AD30: 0 | AE30: =SUM(AC30:AD30) -> 14472.374 | AF30: =+H30+J30+L30 -> 34333.21 | AG30: =+I30+K30+M30 -> 0 | AH30: =+AF30+AG30 -> 34333.21 | AI30: =+Q30+W30+AC30 -> 52148.39 | AJ30: =+R30+X30+AD30 -> 0 | AK30: =+AI30+AJ30 -> 52148.39 | AM30: =+AF30+AI30 -> 86481.6 | AN30: =+AG30+AJ30 -> 0 | AO30: =+AM30+AN30 -> 86481.6
A31: SUBFCARVA | B31: 89050 | C31: COL2 | D31: COL2 | E31: CARVAJAL | F31: FCPERSNL | G31: Information System Professionals | H31: 3794.35 | I31: 0 | J31: 17294.99 | K31: 0 | L31: 20018.05 | M31: 0 | N31: 1 | O31: 2117.68 | P31: 12 | Q31: =+O31*P31 -> 25412.16 | R31: 0 | S31: =SUM(Q31:R31) -> 25412.16 | T31: 1 | U31: =+O31*10%+O31 -> 2329.448 | V31: 12 | W31: =+U31*V31 -> 27953.376 | X31: 0 | Y31: =SUM(W31:X31) -> 27953.376 | Z31: 1 | AA31: =+U31*10%+U31 -> 2562.3928 | AB31: 6 | AC31: =Z31*AA31*AB31 -> 15374.357 | AD31: 0 | AE31: =SUM(AC31:AD31) -> 15374.357 | AF31: =+H31+J31+L31 -> 41107.39 | AG31: =+I31+K31+M31 -> 0 | AH31: =+AF31+AG31 -> 41107.39 | AI31: =+Q31+W31+AC31 -> 68739.893 | AJ31: =+R31+X31+AD31 -> 0 | AK31: =+AI31+AJ31 -> 68739.893 | AM31: =+AF31+AI31 -> 109847.28 | AN31: =+AG31+AJ31 -> 0 | AO31: =+AM31+AN31 -> 109847.28
G32: Information Systems Analysts | H32: 0 | I32: 0 | J32: 0 | K32: 0 | L32: 17649.63 | M32: 0 | N32: 1 | O32: 1757.4 | P32: 12 | Q32: =+O32*P32 -> 21088.8 | R32: 0 | S32: =SUM(Q32:R32) -> 21088.8 | T32: 1 | U32: =+O32*10%+O32 -> 1933.14 | V32: 12 | W32: =+U32*V32 -> 23197.68 | X32: 0 | Y32: =SUM(W32:X32) -> 23197.68 | Z32: 1 | AA32: =+U32*10%+U32 -> 2126.454 | AB32: 6 | AC32: =Z32*AA32*AB32 -> 12758.724 | AD32: 0 | AE32: =SUM(AC32:AD32) -> 12758.724 | AF32: =+H32+J32+L32 -> 17649.63 | AG32: =+I32+K32+M32 -> 0 | AH32: =+AF32+AG32 -> 17649.63 | AI32: =+Q32+W32+AC32 -> 57045.204 | AJ32: =+R32+X32+AD32 -> 0 | AK32: =+AI32+AJ32 -> 57045.204 | AM32: =+AF32+AI32 -> 74694.834 | AN32: =+AG32+AJ32 -> 0 | AO32: =+AM32+AN32 -> 74694.834
G33: Grants Team
A34: SUBFCARVA | B34: 89050 | C34: COL2 | D34: COL2 | E34: CARVAJAL | F34: FCPERSNL | G34: Grants Specialist | H34: 4459.29 | I34: 0 | J34: 18701.01 | K34: 0 | L34: 19770.92 | M34: 0 | N34: 1 | O34: 1748.82 | P34: 12 | Q34: =+O34*P34 -> 20985.84 | R34: 0 | S34: =SUM(Q34:R34) -> 20985.84 | T34: 1 | U34: =+O34*10%+O34 -> 1923.702 | V34: 12 | W34: =T34*U34*V34 -> 23084.424 | X34: 0 | Y34: =SUM(W34:X34) -> 23084.424 | Z34: 1 | AA34: =+U34*10%+U34 -> 2116.0722 | AB34: 6 | AC34: =Z34*AA34*AB34 -> 12696.433 | AD34: 0 | AE34: =SUM(AC34:AD34) -> 12696.433 | AF34: =+H34+J34+L34 -> 42931.22 | AG34: =+I34+K34+M34 -> 0 | AH34: =+AF34+AG34 -> 42931.22 | AI34: =+Q34+W34+AC34 -> 56766.697 | AJ34: =+R34+X34+AD34 -> 0 | AK34: =+AI34+AJ34 -> 56766.697 | AM34: =+AF34+AI34 -> 99697.917 | AN34: =+AG34+AJ34 -> 0 | AO34: =+AM34+AN34 -> 99697.917
A35: SUBFCARVA | B35: 89050 | C35: COL2 | D35: COL2 | E35: CARVAJAL | F35: FCPERSNL | G35: 2nd Tier Subawardess Technical Supervisor | H35: 0 | I35: 0 | J35: 7199.58 | K35: 0 | L35: 12801.36 | M35: 0 | N35: 1 | O35: 1284.54 | P35: 6 | Q35: =+O35*P35 -> 7707.24 | R35: 0 | S35: =SUM(Q35:R35) -> 7707.24 | T35: 1 | U35: =+O35*10%+O35 -> 1412.994 | V35: 12 | W35: =T35*U35*V35 -> 16955.928 | X35: 0 | Y35: =SUM(W35:X35) -> 16955.928 | Z35: 1 | AA35: =+U35*10%+U35 -> 1554.2934 | AB35: 6 | AC35: =Z35*AA35*AB35 -> 9325.7604 | AD35: 0 | AE35: =SUM(AC35:AD35) -> 9325.7604 | AF35: =+H35+J35+L35 -> 20000.94 | AG35: =+I35+K35+M35 -> 0 | AH35: =+AF35+AG35 -> 20000.94 | AI35: =+Q35+W35+AC35 -> 33988.928 | AJ35: =+R35+X35+AD35 -> 0 | AK35: =+AI35+AJ35 -> 33988.928 | AM35: =+AF35+AI35 -> 53989.868 | AN35: =+AG35+AJ35 -> 0 | AO35: =+AM35+AN35 -> 53989.868
G36: F&A Team
A37: SUBFCARVA | B37: 89050 | C37: COL2 | D37: COL2 | E37: CARVAJAL | F37: FCPERSNL | G37: Finance & Admin Coordinator | H37: 5716.37 | I37: 0 | J37: 14334.38 | K37: 0 | L37: 15607.17 | M37: 0 | N37: 1 | O37: 1660.21 | P37: 12 | Q37: =+O37*P37 -> 19922.52 | R37: 0 | S37: =SUM(Q37:R37) -> 19922.52 | T37: 1 | U37: 1866.98 | V37: 12 | W37: =T37*U37*V37 -> 22403.76 | X37: 0 | Y37: =SUM(W37:X37) -> 22403.76 | Z37: 1 | AA37: =+U37*10%+U37 -> 2053.678 | AB37: 8 | AC37: =Z37*AA37*AB37 -> 16429.424 | AD37: 0 | AE37: =SUM(AC37:AD37) -> 16429.424 | AF37: =+H37+J37+L37 -> 35657.92 | AG37: =+I37+K37+M37 -> 0 | AH37: =+AF37+AG37 -> 35657.92 | AI37: =+Q37+W37+AC37 -> 58755.704 | AJ37: =+R37+X37+AD37 -> 0 | AK37: =+AI37+AJ37 -> 58755.704 | AM37: =+AF37+AI37 -> 94413.624 | AN37: =+AG37+AJ37 -> 0 | AO37: =+AM37+AN37 -> 94413.624
A38: SUBFCARVA | B38: 89050 | C38: COL2 | D38: COL2 | E38: CARVAJAL | F38: FCPERSNL | G38: Accounting Analyst | H38: 2058.13 | I38: 0 | J38: 8631.23 | K38: 0 | L38: 5714.67 | M38: 0 | N38: 1 | O38: 758.33 | P38: 12 | Q38: =+O38*P38 -> 9099.96 | R38: 0 | S38: =SUM(Q38:R38) -> 9099.96 | T38: 1 | U38: =+O38*10%+O38 -> 834.163 | V38: 12 | W38: =T38*U38*V38 -> 10009.956 | X38: 0 | Y38: =SUM(W38:X38) -> 10009.956 | Z38: 1 | AA38: =+U38*10%+U38 -> 917.5793 | AB38: 8 | AC38: =Z38*AA38*AB38 -> 7340.6344 | AD38: 0 | AE38: =SUM(AC38:AD38) -> 7340.6344 | AF38: =+H38+J38+L38 -> 16404.03 | AG38: =+I38+K38+M38 -> 0 | AH38: =+AF38+AG38 -> 16404.03 | AI38: =+Q38+W38+AC38 -> 26450.55 | AJ38: =+R38+X38+AD38 -> 0 | AK38: =+AI38+AJ38 -> 26450.55 | AM38: =+AF38+AI38 -> 42854.58 | AN38: =+AG38+AJ38 -> 0 | AO38: =+AM38+AN38 -> 42854.58
A39: SUBFCARVA | B39: 89050 | C39: COL2 | D39: COL2 | E39: CARVAJAL | F39: FCPERSNL | G39: Accounting Analyst (Maternity Leave) | H39: 0 | I39: 0 | J39: 0 | K39: 0 | L39: 3288.75 | M39: 0 | N39: 1 | O39: 864.2 | P39: 2 | Q39: =+O39*P39 -> 1728.4 | R39: 0 | S39: =SUM(Q39:R39) -> 1728.4 | T39: 1 | U39: =+O39*10%+O39 -> 950.62 | V39: 0 | W39: =T39*U39*V39 -> 0 | X39: 0 | Y39: =SUM(W39:X39) -> 0 | Z39: 0 | AA39: 0 | AB39: 0 | AC39: =Z39*AA39*AB39 -> 0 | AD39: 0 | AE39: =SUM(AC39:AD39) -> 0 | AF39: =+H39+J39+L39 -> 3288.75 | AG39: =+I39+K39+M39 -> 0 | AH39: =+AF39+AG39 -> 3288.75 | AI39: =+Q39+W39+AC39 -> 1728.4 | AJ39: =+R39+X39+AD39 -> 0 | AK39: =+AI39+AJ39 -> 1728.4 | AM39: =+AF39+AI39 -> 5017.15 | AN39: =+AG39+AJ39 -> 0 | AO39: =+AM39+AN39 -> 5017.15
A40: SUBFCARVA | B40: 89050 | C40: COL2 | D40: COL2 | E40: CARVAJAL | F40: FCPERSNL | G40: Project Assistant | H40: 1828.58 | I40: 0 | J40: 5691.93 | K40: 0 | L40: 6142.27 | M40: 0 | N40: 1 | O40: 608.7 | P40: 12 | Q40: =+O40*P40 -> 7304.4 | R40: 0 | S40: =SUM(Q40:R40) -> 7304.4 | T40: 1 | U40: =+O40*10%+O40 -> 669.57 | V40: 12 | W40: =T40*U40*V40 -> 8034.84 | X40: 0 | Y40: =SUM(W40:X40) -> 8034.84 | Z40: 1 | AA40: =+U40*10%+U40 -> 736.527 | AB40: 8 | AC40: =Z40*AA40*AB40 -> 5892.216 | AD40: 0 | AE40: =SUM(AC40:AD40) -> 5892.216 | AF40: =+H40+J40+L40 -> 13662.78 | AG40: =+I40+K40+M40 -> 0 | AH40: =+AF40+AG40 -> 13662.78 | AI40: =+Q40+W40+AC40 -> 21231.456 | AJ40: =+R40+X40+AD40 -> 0 | AK40: =+AI40+AJ40 -> 21231.456 | AM40: =+AF40+AI40 -> 34894.236 | AN40: =+AG40+AJ40 -> 0 | AO40: =+AM40+AN40 -> 34894.236
A41: SUBFCARVA | B41: 89050 | C41: COL2 | D41: COL2 | E41: CARVAJAL | F41: FCPERSNL | G41: File Clerk Assistant | H41: 0 | I41: 0 | J41: 2930.08 | K41: 0 | L41: 4338.44 | M41: 0 | N41: 1 | O41: 421.89 | P41: 12 | Q41: =+O41*P41 -> 5062.68 | R41: 0 | S41: =SUM(Q41:R41) -> 5062.68 | T41: 1 | U41: =+O41*10%+O41 -> 464.079 | V41: 2 | W41: =T41*U41*V41 -> 928.158 | X41: 0 | Y41: =SUM(W41:X41) -> 928.158 | Z41: 1 | AA41: =+U41*10%+U41 -> 510.4869 | AB41: 8 | AC41: =Z41*AA41*AB41 -> 4083.8952 | AD41: 0 | AE41: =SUM(AC41:AD41) -> 4083.8952 | AF41: =+H41+J41+L41 -> 7268.52 | AG41: =+I41+K41+M41 -> 0 | AH41: =+AF41+AG41 -> 7268.52 | AI41: =+Q41+W41+AC41 -> 10074.733 | AJ41: =+R41+X41+AD41 -> 0 | AK41: =+AI41+AJ41 -> 10074.733 | AM41: =+AF41+AI41 -> 17343.253 | AN41: =+AG41+AJ41 -> 0 | AO41: =+AM41+AN41 -> 17343.253
A42: SUBFCARVA | B42: 89050 | C42: COL2 | D42: COL2 | E42: CARVAJAL | F42: FCPERSNL/ FCPERSNLEV | G42: Promotions Professional (Applies for Cali) | H42: 114.87 | I42: 125.51 | J42: 741.04 | K42: 814.45 | L42: 821.51 | M42: 889.09 | N42: 0.13 | O42: 79.52 | P42: 12 | Q42: =+O42*P42 -> 954.24 | R42: =+O42*P42 -> 954.24 | S42: =SUM(Q42:R42) -> 1908.48 | T42: 0.26 | U42: =+O42*10%+O42 -> 87.472 | V42: 12 | W42: =T42*U42*V42 -> 272.91264 | X42: 252.35 | Y42: =SUM(W42:X42) -> 525.26264 | Z42: 0.26 | AA42: =+U42*10%+U42 -> 96.2192 | AB42: 8 | AC42: =Z42*AA42*AB42 -> 200.13594 | AD42: 277.59 | AE42: =SUM(AC42:AD42) -> 477.72594 | AF42: =+H42+J42+L42 -> 1677.42 | AG42: =+I42+K42+M42 -> 1829.05 | AH42: =+AF42+AG42 -> 3506.47 | AI42: =+Q42+W42+AC42 -> 1427.2886 | AJ42: =+R42+X42+AD42 -> 1484.18 | AK42: =+AI42+AJ42 -> 2911.4686 | AM42: =+AF42+AI42 -> 3104.7086 | AN42: =+AG42+AJ42 -> 3313.23 | AO42: =+AM42+AN42 -> 6417.9386
A43: SUBFCARVA | B43: 89050 | C43: COL2 | D43: COL2 | E43: CARVAJAL | F43: FCPERSNL | G43: Legal Assistant | H43: 952.12 | I43: 0 | J43: 4385.81 | K43: 0 | L43: 5005.85 | M43: 0 | N43: 0.5 | O43: 290.73 | P43: 12 | Q43: =+O43*P43 -> 3488.76 | R43: 0 | S43: =SUM(Q43:R43) -> 3488.76 | T43: 0.5 | U43: =+O43*10%+O43 -> 319.803 | V43: 2 | W43: =T43*U43*V43 -> 319.803 | X43: 0 | Y43: =SUM(W43:X43) -> 319.803 | Z43: 0.5 | AA43: =+U43*10%+U43 -> 351.7833 | AB43: 8 | AC43: =Z43*AA43*AB43 -> 1407.1332 | AD43: 0 | AE43: =SUM(AC43:AD43) -> 1407.1332 | AF43: =+H43+J43+L43 -> 10343.78 | AG43: =+I43+K43+M43 -> 0 | AH43: =+AF43+AG43 -> 10343.78 | AI43: =+Q43+W43+AC43 -> 5215.6962 | AJ43: =+R43+X43+AD43 -> 0 | AK43: =+AI43+AJ43 -> 5215.6962 | AM43: =+AF43+AI43 -> 15559.476 | AN43: =+AG43+AJ43 -> 0 | AO43: =+AM43+AN43 -> 15559.476
A44: SUBFCARVA | B44: 89050 | C44: COL2 | D44: COL2 | E44: CARVAJAL | F44: FCPERSNL | G44: Procurement Assistant | H44: 0 | I44: 0 | J44: 0 | K44: 0 | L44: 0 | M44: 0 | N44: 1 | O44: 608.7 | P44: 10 | Q44: =+O44*P44 -> 6087 | R44: 0 | S44: =SUM(Q44:R44) -> 6087 | T44: 1 | U44: =+O44*10%+O44 -> 669.57 | V44: 12 | W44: =T44*U44*V44 -> 8034.84 | X44: 0 | Y44: =SUM(W44:X44) -> 8034.84 | Z44: 1 | AA44: =+U44*10%+U44 -> 736.527 | AB44: 6 | AC44: =Z44*AA44*AB44 -> 4419.162 | AD44: 0 | AE44: =SUM(AC44:AD44) -> 4419.162 | AF44: =+H44+J44+L44 -> 0 | AG44: =+I44+K44+M44 -> 0 | AH44: =+AF44+AG44 -> 0 | AI44: =+Q44+W44+AC44 -> 18541.002 | AJ44: =+R44+X44+AD44 -> 0 | AK44: =+AI44+AJ44 -> 18541.002 | AM44: =+AF44+AI44 -> 18541.002 | AN44: =+AG44+AJ44 -> 0 | AO44: =+AM44+AN44 -> 18541.002
...

Sheet 800-FC - Mod7
A2: 800-FUNDACION CARVAJAL | F2: 800-FUNDACION CARVAJAL - Modification No. 7 - Cost Extension and Budget Realignment
B3: Categories | C3: Amount | D3: Leverage | E3: Total | G3: Categories | H3: Amount | I3: Leverage | J3: Total | L3: % representativo sobre el total del subacuerdo (USAID Funds) | N3: % representativo sobre el total del subacuerdo (Leverage Funds) | P3: % representativo sobre el total del subacuerdo (TOTAL)
B4: Categorías | C4: Monto | D4: Apalancamiento | G4: Categorías | H4: Monto | I4: Apalancamiento | L4: Inicial | M4: Mod.7 | N4: Inicial | O4: Mod.7 | P4: Inicial | Q4: Mod.7
A5: 1. | B5: Personnel | C5: 2847676 | D5: 66152 | E5: =+C5+D5 -> 2913828 | F5: 1. | G5: Personnel | H5: ='800-FC - Consolidated Details'!AM77 -> 2858976.9 | I5: ='800-FC - Consolidated Details'!AN77 -> 65374.663 | J5: ='800-FC - Consolidated Details'!AO77 -> 2924351.5 | K5: =IF(J5>=E5,"SUBE","BAJA") -> SUBE | L5: =+$C5*100/$C$23 -> 32.783661 | M5: =+$H5*100/$H$23 -> 31.395712 | N5: =+$D5*100/$D$23 -> 20.936496 | O5: =+$I5*100/$I$23 -> 13.841655 | P5: =+$E5*100/$E$23 -> 32.367839 | Q5: =+$J5*100/$J$23 -> 30.530146
B6: Personal | G6: Personal
A7: 2. | B7: Fringe Benefits | C7: 1310790 | D7: 29095 | E7: =+C7+D7 -> 1339885 | F7: 2. | G7: Fringe Benefits | H7: ='800-FC - Consolidated Details'!AM81 -> 1383962.7 | I7: ='800-FC - Consolidated Details'!AN81 -> 24339.97 | J7: ='800-FC - Consolidated Details'!AO81 -> 1408302.7 | K7: =IF(J7>=E7,"SUBE","BAJA") -> SUBE | L7: =+$C7*100/$C$23 -> 15.090374 | M7: =+$H7*100/$H$23 -> 15.197917 | N7: =+$D7*100/$D$23 -> 9.2082984 | O7: =+$I7*100/$I$23 -> 5.1534564 | P7: =+$E7*100/$E$23 -> 14.88392 | Q7: =+$J7*100/$J$23 -> 14.702639
B8: Beneficios | G8: Beneficios
A9: 3. | B9: Travel | C9: 188410 | D9: 0 | E9: =+C9+D9 -> 188410 | F9: 3. | G9: Travel | H9: ='800-FC - Consolidated Details'!AM104 -> 322692 | I9: ='800-FC - Consolidated Details'!AN104 -> 3999.26 | J9: ='800-FC - Consolidated Details'!AO104 -> 326691.26 | K9: =IF(J9>=E9,"SUBE","BAJA") -> SUBE | L9: =+$C9*100/$C$23 -> 2.1690563 | M9: =+$H9*100/$H$23 -> 3.5436261 | N9: =+$D9*100/$D$23 -> 0 | O9: =+$I9*100/$I$23 -> 0.84675585 | P9: =+$E9*100/$E$23 -> 2.0929254 | Q9: =+$J9*100/$J$23 -> 3.4106473
B10: Viajes | G10: Viajes
A11: 4. | B11: Equipment | C11: 50000 | D11: 0 | E11: =+C11+D11 -> 50000 | F11: 4. | G11: Equipment | H11: ='800-FC - Consolidated Details'!AM106 -> 0 | I11: ='800-FC - Consolidated Details'!AN106 -> 0 | J11: ='800-FC - Consolidated Details'!AO106 -> 0 | K11: =IF(J11>=E11,"SUBE","BAJA") -> BAJA | L11: =+$C11*100/$C$23 -> 0.57562133 | M11: =+$H11*100/$H$23 -> 0 | N11: =+$D11*100/$D$23 -> 0 | O11: =+$I11*100/$I$23 -> 0 | P11: =+$E11*100/$E$23 -> 0.55541781 | Q11: =+$J11*100/$J$23 -> 0
B12: Equipo | G12: Equipo
A13: 5. | B13: Supplies | C13: 69389 | D13: 0 | E13: =+C13+D13 -> 69389 | F13: 5. | G13: Supplies | H13: ='800-FC - Consolidated Details'!AM111 -> 67039.9 | I13: ='800-FC - Consolidated Details'!AN111 -> 2639.18 | J13: ='800-FC - Consolidated Details'!AO111 -> 69679.08 | K13: =IF(J13>=E13,"SUBE","BAJA") -> SUBE | L13: =+$C13*100/$C$23 -> 0.79883577 | M13: =+$H13*100/$H$23 -> 0.73619531 | N13: =+$D13*100/$D$23 -> 0 | O13: =+$I13*100/$I$23 -> 0.55878865 | P13: =+$E13*100/$E$23 -> 0.77079773 | Q13: =+$J13*100/$J$23 -> 0.72744759
B14: Suministros | G14: Suministros
A15: 6. | B15: Contractual | C15: 3113105 | D15: 0 | E15: =+C15+D15 -> 3113105 | F15: 6. | G15: Contractual | H15: ='800-FC - Consolidated Details'!AM132 -> 2753313.3 | I15: ='800-FC - Consolidated Details'!AN132 -> 230324.4 | J15: ='800-FC - Consolidated Details'!AO132 -> 2983637.7 | K15: =IF(J15>=E15,"SUBE","BAJA") -> BAJA | L15: =+$C15*100/$C$23 -> 35.839393 | M15: =+$H15*100/$H$23 -> 30.235372 | N15: =+$D15*100/$D$23 -> 0 | O15: =+$I15*100/$I$23 -> 48.766155 | P15: =+$E15*100/$E$23 -> 34.581479 | Q15: =+$J15*100/$J$23 -> 31.149092
B16: Contractual | G16: Contractual
A17: 7. | B17: Other Direct Costs | C17: 594509 | D17: 191995 | E17: =+C17+D17 -> 786504 | F17: 7. | G17: Other Direct Costs | H17: ='800-FC - Consolidated Details'!AM170 -> 1064583.8 | I17: ='800-FC - Consolidated Details'!AN170 -> 114460.72 | J17: ='800-FC - Consolidated Details'!AO170 -> 1179044.6 | K17: =IF(J17>=E17,"SUBE","BAJA") -> SUBE | L17: =+$C17*100/$C$23 -> 6.8442412 | M17: =+$H17*100/$H$23 -> 11.690674 | N17: =+$D17*100/$D$23 -> 60.764642 | O17: =+$I17*100/$I$23 -> 24.234554 | P17: =+$E17*100/$E$23 -> 8.7367666 | Q17: =+$J17*100/$J$23 -> 12.309191
B18: Otros Costos Directos | G18: Otros Costos Directos
A19: 8. | B19: Total Direct Costs | C19: =+SUM(C5:C18) -> 8173879 | D19: =+SUM(D5:D18) -> 287242 | E19: =+SUM(E5:E18) -> 8461121 | F19: 8. | G19: Total Direct Costs | H19: =+SUM(H5:H18) -> 8450568.6 | I19: =+SUM(I5:I18) -> 441138.19 | J19: =+SUM(J5:J18) -> 8891706.8 | K19: =IF(J19>=E19,"SUBE","BAJA") -> SUBE | L19: =+$C19*100/$C$23 -> 94.101182 | M19: =+$H19*100/$H$23 -> 92.799497 | N19: =+$D19*100/$D$23 -> 90.909436 | O19: =+$I19*100/$I$23 -> 93.401365 | P19: =+$E19*100/$E$23 -> 93.989146 | Q19: =+$J19*100/$J$23 -> 92.829163
B20: Valor Total Costos Directos | G20: Valor Total Costos Directos
A21: 9. | B21: Indirect Costs | C21: 512388 | D21: 28724 | E21: =+C21+D21 -> 541112 | F21: 9. | G21: Indirect Costs | H21: ='800-FC - Consolidated Details'!AM172 -> 655696.94 | I21: ='800-FC - Consolidated Details'!AN172 -> 31165.602 | J21: ='800-FC - Consolidated Details'!AO172 -> 686863.66 | K21: =IF(J21>=E21,"SUBE","BAJA") -> SUBE | L21: =+$C21*100/$C$23 -> 5.8988293 | M21: =+$H21*100/$H$23 -> 7.2005032 | N21: =+$D21*100/$D$23 -> 9.0908803 | O21: =+$I21*100/$I$23 -> 6.5986347 | P21: =+$E21*100/$E$23 -> 6.0108649 | Q21: =+$J21*100/$J$23 -> 7.1708369
B22: Costos Indirectos | G22: Costos Indirectos
A23: 10. | B23: Total Costs | C23: =+C19+C21-1 -> 8686266 | D23: =+D19+D21-1 -> 315965 | E23: =+E19+E21-1 -> 9002232 | F23: 10. | G23: Total Costs | H23: =+H19+H21 -> 9106265.6 | I23: =+I19+I21 -> 472303.8 | J23: =+J19+J21 -> 9578570.5 | K23: =IF(J23>=E23,"SUBE","BAJA") -> SUBE | L23: =+$C23*100/$C$23 -> 100 | M23: =+$H23*100/$H$23 -> 100 | N23: =+$D23*100/$D$23 -> 100 | O23: =+$I23*100/$I$23 -> 100 | P23: =+$E23*100/$E$23 -> 100 | Q23: =+$J23*100/$J$23 -> 100
B24: Valor Total | G24: Valor Total
A28: 800-FUNDACION CARVAJAL - INITIAL BUDGET
B29: Categories | C29: Amount | D29: Leverage | E29: Total | F29: Expenditures Amount up to Dec/23 | G29: Expenditures Leverage up to Dec/23 | H29: Total Expenditures up to Dec/23 | I29: Remaining USAID | J29: Remaining Leverage | K29: Total Remaining
B30: Categorías | C30: Monto | D30: Apalancamiento | F30: Monto Ejecutado | G30: Apalancamiento Reportado | H30: Apalancamiento Reportado | I30: Saldo USAID | J30: Saldo Apalancamiento | K30: Saldo Total
A31: 1. | B31: Personnel | C31: 2847676 | D31: 66152 | E31: =+C31+D31 -> 2913828 | F31: ='800-FC - Consolidated Details'!AF77 -> 1107253.8 | G31: ='800-FC - Consolidated Details'!AG77 -> 32437.34 | H31: =+F31+G31 -> 1139691.1 | I31: =+C31-F31 -> 1740422.2 | J31: =+D31-G31 -> 33714.66 | K31: =+E31-H31 -> 1774136.9
B32: Personal
A33: 2. | B33: Fringe Benefits | C33: 1310790 | D33: 29095 | E33: =+C33+D33 -> 1339885 | F33: ='800-FC - Consolidated Details'!AF81 -> 492962.7 | G33: ='800-FC - Consolidated Details'!AG81 -> 8339.97 | H33: =+F33+G33 -> 501302.67 | I33: =+C33-F33 -> 817827.3 | J33: =+D33-G33 -> 20755.03 | K33: =+E33-H33 -> 838582.33
B34: Beneficios
A35: 3. | B35: Travel | C35: 188410 | D35: 0 | E35: =+C35+D35 -> 188410 | F35: ='800-FC - Consolidated Details'!AF104 -> 132644 | G35: ='800-FC - Consolidated Details'!AG104 -> 3549.26 | H35: =+F35+G35 -> 136193.26 | I35: =+C35-F35 -> 55766 | J35: =+D35-G35 -> -3549.26 | K35: =+E35-H35 -> 52216.74
B36: Viajes
A37: 4. | B37: Equipment | C37: 50000 | D37: 0 | E37: =+C37+D37 -> 50000 | F37: ='800-FC - Consolidated Details'!AF107 -> 0 | G37: ='800-FC - Consolidated Details'!AG107 -> 0 | H37: =+F37+G37 -> 0 | I37: =+C37-F37 -> 50000 | J37: =+D37-G37 -> 0 | K37: =+E37-H37 -> 50000
B38: Equipo
A39: 5. | B39: Supplies | C39: 69389 | D39: 0 | E39: =+C39+D39 -> 69389 | F39: ='800-FC - Consolidated Details'!AF111 -> 59050.3 | G39: ='800-FC - Consolidated Details'!AG111 -> 2639.18 | H39: =+F39+G39 -> 61689.48 | I39: =+C39-F39 -> 10338.7 | J39: =+D39-G39 -> -2639.18 | K39: =+E39-H39 -> 7699.52
B40: Suministros
A41: 6. | B41: Contractual | C41: 3113105 | D41: 0 | E41: =+C41+D41 -> 3113105 | F41: ='800-FC - Consolidated Details'!AF132 -> 1272971.5 | G41: ='800-FC - Consolidated Details'!AG132 -> 151747.4 | H41: =+F41+G41 -> 1424718.9 | I41: =+C41-F41 -> 1840133.5 | J41: =+D41-G41 -> -151747.4 | K41: =+E41-H41 -> 1688386.1
B42: Contractual
A43: 7. | B43: Other Direct Costs | C43: 594509 | D43: 191995 | E43: =+C43+D43 -> 786504 | F43: ='800-FC - Consolidated Details'!AF170 -> 345033.98 | G43: ='800-FC - Consolidated Details'!AG170 -> 60695.72 | H43: ='800-FC - Consolidated Details'!AG170 -> 60695.72 | I43: =+C43-F43 -> 249475.02 | J43: =+D43-G43 -> 131299.28 | K43: =+E43-H43 -> 725808.28
B44: Otros Costos Directos
...

Sheet 800-FC - Summary - Annex B
B1: Name of Subawardee: Fundación Carvajal
B2: 800-FUNDACION CARVAJAL - MODIFICATION No. 7
A4: Line Items | B4: Year 1 | E4: Year 2 | H4: Year 3 | K4: Year 4 | N4: Year 5 | Q4: Year 6 | T4: Total | U4: Total | V4: Grand
B5: USAID | C5: Leverage | D5: Total | E5: USAID | F5: Leverage | G5: Total | H5: USAID | I5: Leverage | J5: Total | K5: USAID | L5: Leverage | M5: Total | N5: USAID | O5: Leverage | P5: Total | Q5: USAID | R5: Leverage | S5: Total | T5: USAID | U5: Leverage | V5: Total
A7: Personnel | B7: 75200 | C7: 1213 | D7: =+B7+C7 -> 76413 | E7: 471135 | F7: 3225 | G7: =+E7+F7 -> 474360 | H7: 560919 | I7: 27999 | J7: =+H7+I7 -> 588918 | K7: 673740 | L7: 18295 | M7: =+K7+L7 -> 692035 | N7: 695259 | O7: 8394 | P7: =+N7+O7 -> 703653 | Q7: 382724 | R7: 6248 | S7: =+Q7+R7 -> 388972 | T7: =+B7+E7+H7+K7+N7+Q7 -> 2858977 | U7: =+C7+F7+I7+L7+O7+R7+1 -> 65375 | V7: =+T7+U7 -> 2924352
A9: Fringe Benefits | B9: 27002 | C9: 428 | D9: =+B9+C9 -> 27430 | E9: 194200 | F9: 955 | G9: =+E9+F9 -> 195155 | H9: 271761 | I9: 6958 | J9: =+H9+I9 -> 278719 | K9: 340000 | L9: 9200 | M9: =+K9+L9 -> 349200 | N9: 351000 | O9: 4600 | P9: =+N9+O9 -> 355600 | Q9: 200000 | R9: 2200 | S9: =+Q9+R9 -> 202200 | T9: =+B9+E9+H9+K9+N9+Q9 -> 1383963 | U9: =+C9+F9+I9+L9+O9+R9-1 -> 24340 | V9: =+T9+U9 -> 1408303
A11: Travel | B11: 10059 | C11: 0 | D11: =+B11+C11 -> 10059 | E11: 66634 | F11: 576 | G11: =+E11+F11 -> 67210 | H11: 55951 | I11: 2974 | J11: =+H11+I11 -> 58925 | K11: 80050 | L11: =450-1 -> 449 | M11: =+K11+L11 -> 80499 | N11: 79380 | O11: 0 | P11: =+N11+O11 -> 79380 | Q11: 30618 | R11: 0 | S11: =+Q11+R11 -> 30618 | T11: =+B11+E11+H11+K11+N11+Q11 -> 322692 | U11: =+C11+F11+I11+L11+O11+R11 -> 3999 | V11: =+T11+U11 -> 326691
A13: Equipment | B13: 0 | C13: 0 | D13: =+B13+C13 -> 0 | E13: 0 | F13: 0 | G13: =+E13+F13 -> 0 | H13: 0 | I13: 0 | J13: =+H13+I13 -> 0 | K13: 0 | L13: 0 | M13: =+K13+L13 -> 0 | N13: 0 | O13: 0 | P13: =+N13+O13 -> 0 | Q13: 0 | R13: 0 | S13: =+Q13+R13 -> 0 | T13: =+B13+E13+H13+K13+N13+Q13 -> 0 | U13: =+C13+F13+I13+L13+O13+R13 -> 0 | V13: =+T13+U13 -> 0
A15: Supplies | B15: 42723 | C15: 0 | D15: =+B15+C15 -> 42723 | E15: 10551 | F15: 0 | G15: =+E15+F15 -> 10551 | H15: 5776 | I15: 2639 | J15: =+H15+I15 -> 8415 | K15: 3000 | L15: 0 | M15: =+K15+L15 -> 3000 | N15: 3240 | O15: 0 | P15: =+N15+O15 -> 3240 | Q15: 1750 | R15: 0 | S15: =+Q15+R15 -> 1750 | T15: =+B15+E15+H15+K15+N15+Q15 -> 67040 | U15: =+C15+F15+I15+L15+O15+R15 -> 2639 | V15: =+T15+U15 -> 69679
A17: Contractual | B17: 46712 | C17: 0 | D17: =+B17+C17 -> 46712 | E17: 565429 | F17: 13314 | G17: =+E17+F17 -> 578743 | H17: 660830 | I17: 138433 | J17: =+H17+I17 -> 799263 | K17: 291619 | L17: 78577 | M17: =+K17+L17 -> 370196 | N17: 932661 | O17: 0 | P17: =+N17+O17 -> 932661 | Q17: 256063 | R17: 0 | S17: =+Q17+R17 -> 256063 | T17: =+B17+E17+H17+K17+N17+Q17 -> 2753314 | U17: =+C17+F17+I17+L17+O17+R17 -> 230324 | V17: =+T17+U17 -> 2983638
A19: Other Direct Costs | B19: 2301 | C19: 7005 | D19: =+B19+C19 -> 9306 | E19: 176624 | F19: 24982 | G19: =+E19+F19 -> 201606 | H19: 166108 | I19: 28709 | J19: =+H19+I19 -> 194817 | K19: 291558 | L19: 53765 | M19: =+K19+L19 -> 345323 | N19: 247029 | O19: 0 | P19: =+N19+O19 -> 247029 | Q19: 180963 | R19: 0 | S19: =+Q19+R19 -> 180963 | T19: =+B19+E19+H19+K19+N19+Q19 -> 1064583 | U19: =+C19+F19+I19+L19+O19+R19 -> 114461 | V19: =+T19+U19 -> 1179044
A21: Total Direct Costs | B21: =SUM(B7:B19) -> 203997 | C21: =SUM(C7:C19) -> 8646 | D21: =SUM(D7:D19) -> 212643 | E21: =SUM(E7:E19) -> 1484573 | F21: =SUM(F7:F19)-1 -> 43051 | G21: =SUM(G7:G19) -> 1527625 | H21: =SUM(H7:H19)+1 -> 1721346 | I21: =SUM(I7:I19) -> 207712 | J21: =SUM(J7:J19) -> 1929057 | K21: =SUM(K7:K19)-1 -> 1679966 | L21: =SUM(L7:L19) -> 160286 | M21: =SUM(M7:M19) -> 1840253 | N21: =SUM(N7:N19) -> 2308569 | O21: =SUM(O7:O19) -> 12994 | P21: =SUM(P7:P19)-1 -> 2321562 | Q21: =SUM(Q7:Q19) -> 1052118 | R21: =SUM(R7:R19) -> 8448 | S21: =SUM(S7:S19) -> 1060566 | T21: =SUM(T7:T19) -> 8450569 | U21: =SUM(U7:U19) -> 441138 | V21: =SUM(V7:V19) -> 8891707
A22: Indirect Costs | B22: 20400 | C22: 0 | D22: =+B22+C22 -> 20400 | E22: 111259 | F22: 0 | G22: =+E22+F22 -> 111259 | H22: 125832 | I22: 12993 | J22: =+H22+I22 -> 138825 | K22: 161497 | L22: 16029 | M22: =+K22+L22-1 -> 177525 | N22: 154196 | O22: 1299 | P22: 155495 | Q22: 82515 | R22: 845 | S22: 83140 | T22: 655698 | U22: 31166 | V22: =+T22+U22 -> 686864
