Workbook
Name \a: #REF!
Name \A1: #REF!
Name \A10: #REF!
Name \A2: #REF!
Name \A4: #REF!
Name \A7: #REF!
Name \A8: #REF!
Name \A9: #REF!
Name \b: #REF!
Name \B1: #REF!
Name \B10: #REF!
Name \B3: #REF!
Name \B4: #REF!
Name \B7: #REF!
Name \B8: #REF!
Name \B9: #REF!
Name \c: #REF!
Name \C1: #REF!
Name \C10: #REF!
Name \C2: #REF!
Name \C3: #REF!
Name \C5: #REF!
Name \C7: #REF!
Name \C8: #REF!
Name \C9: #REF!
Name \d: #REF!
Name \D1: #REF!
Name \D10: #REF!
Name \D2: #REF!
Name \D3: #REF!
Name \D7: #REF!
Name \D8: #REF!
Name \D9: #REF!
Name \g: #N/A
Name \h: #REF!
Name \P: [4]InputData!#REF!
Name \q: '[5]COMPTRFC Page8'!#REF!
Name \R: [4]InputData!#REF!
Name \s: #REF!
Name \T: [4]InputData!#REF!
Name \U: [4]InputData!#REF!
Name \V: [4]InputData!#REF!
Name \W: [4]InputData!#REF!
Name _.: #REF!
Name ___ASO1: #REF!
Name ___MOS6: #REF!
Name ___PUL1: #REF!
Name ___PUL2: #REF!
Name __1_0REV: '[6]Age Sheet'!#REF!
Name __ASO1: #REF!
Name __MOS6: #REF!
Name __PUL1: #REF!
Name __PUL2: #REF!
Name _1_0REV: '[6]Age Sheet'!#REF!
Name _2_0REV: '[6]Age Sheet'!#REF!
Name _219: #REF!
Name _2REV: '[6]Age Sheet'!#REF!
Name _3_0REV: '[6]Age Sheet'!#REF!
Name _4_0REV: '[6]Age Sheet'!#REF!
Name _7: #N/A

Sheet Premium History
A1: Partners of the Americas
E2: 2017 | G2: 2018 | I2: 2019 | K2: 2020 | M2: 2021 | O2: 2022 | Q2: 2023
A3: Partners Estimated Monthly Premium | E3: 9822.01 | G3: 10080.74 | I3: 12149.07 | K3: 15991.23 | M3: 28401.84 | O3: 21338.82 | Q3: ='Partners 23-24 No Change'!M79 -> 33947.246
A4: Renewal Change at 8/1 based on enrollment at that time | G4: =(G3-E3)/E3 -> 0.026341859 | I4: -0.0644 | K4: 0.0264 | M4: 0.0367 | O4: -0.0129 | Q4: ='Partners 23-24 No Change'!M81 -> 0.16077017
A5: Employees Covered | E5: 15 | G5: 15 | I5: 18 | K5: 22 | M5: 27 | O5: 36 | Q5: 30
A6: Percentage Change in Headcount | G6: =(G5-E5)/E5 -> 0 | I6: =(I5-G5)/G5 -> 0.2 | K6: =(K5-I5)/I5 -> 0.22222222 | M6: =(M5-K5)/K5 -> 0.22727273 | O6: =(O5-M5)/M5 -> 0.33333333 | Q6: =(Q5-O5)/O5 -> -0.16666667
A7: ER/EE Breakout | E7: 80/20 | G7: 80/20 | I7: 80/20 | K7: 80/20 | M7: 80/20 | O7: 80/20 | Q7: 80/20
A8: Reference Plan | E8: BlueChoice Plus Platinum | G8: BlueChoice Plus Platinum | I8: BlueChoice Plus Platinum | K8: BlueChoice Plus Platinum | M8: BlueChoice Plus Platinum | O8: BlueChoice Plus Platinum | Q8: BlueChoice Plus Platinum
B10: Paul Notes: there is some variance in the Partners Estimated Monthly Premium due to enrollment types, some years had more families or younger/older employees. Bearing this in mind, I pulled the actual renewal change based on our review from the spreadsheets dating back to 2017. Overall, Partners has had tremendous employee growth and this is the first major increase since 2017. As the next tabs lay out, a severe change in plan may not be needed at this time nor will it do much to relieve the premium increase based on the idea of funding a portion of a deductible for employees. However, it may be the year to change the employer/employee split and encourage employees to look closely at their choices and how they are spending their portion of Partners premium contribution.

Sheet Totals
A1: Partners of the Americas
A4: Rates vary based on option selected
A5: DC Health Link
A6: Total Premium Monthly for DC Health Link*
E7: Employer Costs | G7: Employee Costs
A8: Current June 2023 DC Health Link Premium | E8: ='Partners 23-24 No Change'!M78 -> 29245.45 | G8: =SUM('Partners 23-24 No Change'!F6:F76) -> 5330.16
A9: Current Reference Plan POS BCCS Base 80/20 Split (80% of the cost of the base plan covered by employer, remaining 20% employee) | E9: ='Partners 23-24 No Change'!M79 -> 33947.246 | G9: =SUM('Partners 23-24 No Change'!M6:M75) -> 5237.764 | I9: Option 1
A10: Percentage Change | E10: =(E9-$E$8)/$E$8 -> 0.16077017 | G10: =(G9-$G$8)/$E$8 -> -0.0031593291
A11: Difference Total Dollar Monthly | E11: =E9-$E$8 -> 4701.796 | G11: =G9-$G$8 -> -92.396
A12: Difference Total Dollar Annual | E12: =E11*12 -> 56421.552 | G12: =G11*12 -> -1108.752
A13: Current Reference Plan POS BCCS Base 75/25 Split (75% of the cost of the base plan covered by employer, remaining 25% employee) | E13: ='Partners 23-24 75%'!M79 -> 32236.463 | G13: =SUM('Partners 23-24 75%'!M6:M76) -> 7496.8375 | I13: Option 2 | J13: Recommended
A14: Percentage Change | E14: =(E13-$E$8)/$E$8 -> 0.10227275 | G14: =(G13-$G$8)/$E$8 -> 0.074085969
A15: Difference Total Dollar Monthly | E15: =E13-$E$8 -> 2991.0125 | G15: =G13-$G$8 -> 2166.6775
A16: Difference Total Dollar Annual | E16: =E15*12 -> 35892.15 | G16: =G15*12 -> 26000.13
A17: Change Reference to BlueChoice Advantage Gold HRA 80/20 Split and 100% HRA Funding (80% of the cost of the base plan covered by employer, remaining 20% employee) | E17: ='Prtnrs Change Ref to Gold HRA'!M79+('Prtnrs Change Ref to Gold HRA'!M83/12) -> 38074.68 | G17: =SUM('Prtnrs Change Ref to Gold HRA'!M6:M75) -> 7737.42 | I17: Option 3
A18: Percentage Change | E18: =(E17-$E$8)/$E$8 -> 0.30190098 | G18: =(G17-$G$8)/$E$8 -> 0.082312291
A19: Difference Total Dollar Monthly | E19: =E17-$E$8 -> 8829.23 | G19: =G17-$G$8 -> 2407.26
A20: Difference Total Dollar Annual | E20: =E19*12 -> 105950.76 | G20: =G19*12 -> 28887.12
A21: Change Reference to BlueChoice Advantage Silver HRA 80/20 Split and 100% HRA Funding (80% of the cost of the base plan covered by employer, remaining 20% employee) | E21: ='Prtnrs Change Ref to Silver HRA'!M79+('Prtnrs Change Ref to Silver HRA'!M83/12) -> 34915.888 | G21: =SUM('Prtnrs Change Ref to Silver HRA'!M6:M75) -> 6828.972 | I21: Option 4
A22: Percentage Change | E22: =(E21-$E$8)/$E$8 -> 0.19389129 | G22: =(G21-$G$8)/$E$8 -> 0.051249408
A23: Difference Total Dollar Monthly | E23: =E21-$E$8 -> 5670.438 | G23: =G21-$G$8 -> 1498.812
A24: Difference Total Dollar Annual | E24: =E23*12 -> 68045.256 | G24: =G23*12 -> 17985.744
A25: *Assumptions are based on current enrollment rates
A26: Notes:
A27: PPO - preferred provider organization (usually most expensive)
A28: POS - point-of-service plan (usually mid range costs)
A29: HMO - health maintenance organization (always cheapest option)

Sheet Partners 23-24 No Change
A1: 2023 Benefits Worksheet | M1: Partners Covers | N1: 0.8 | O1: Employee | P1: 0.8 | Q1: Dependents
A2: 1 | N2: No Changes Employees Actual Choices on DCHL
A3: Renewal Date | B3: 45139
A4: Basic Demographic Data | E4: Current Premiums | H4: Renewal Information | K4: Plan Info
A5: Employee | B5: Covered Dependents | C5: DOB | D5: Renewal Age | E5: Partners Current Premium | F5: Employee Current Monthly Premium based on May Invoice | G5: Total Cost Current Premium | H5: Renewal Premium BlueChoice Plus Opt-Out Platinum 0 | I5: Renewal Cost Employee's Actual Plan | J5: Percentage Change on Actual Plan | K5: Employee's Actual Plan Choice | L5: Maximum Renewal Cost for Partners BlueChoice Plus Platinum 0 | M5: Employee Premium On Renewal | N5: Percentage Change for Partners | O5: Percentage Change for Employee | P5: Employee's % Cost of Premium
A6: Alexandra Lishansky | B6: 1 | C6: 34087 | D6: =($B$3-C6)/365 -> 30.279452 | E6: 650.85 | F6: 257.39 | G6: 908.24 | H6: ='[2]MEDICAL-Table Rates'!$S$42 -> 513.4 | I6: 1055.95 | J6: =(I6-G6)/G6 -> 0.16263322 | K6: BlueChoice Advantage Platinum 0 | L6: =IF($N$1*H6+$P$1*H7>=I6,I6,$N$1*H6+$P$1*H7) -> 755.536 | M6: =I6-L6 -> 300.414 | N6: =(L6-E6)/E6 -> 0.16084505 | O6: =(M6-F6)/F6 -> 0.1671549 | P6: =M6/I6 -> 0.28449643
D7: 1 | H7: ='[2]MEDICAL-Table Rates'!$S$16 -> 431.02
A8: Marcio Nascimento | B8: 0 | C8: 26679 | D8: =($B$3-C8)/365 -> 50.575342 | E8: 633.82 | F8: 112.9 | G8: 746.72 | H8: ='[2]MEDICAL-Table Rates'!$S$75 -> 943.1 | I8: 887.51 | J8: =(I8-G8)/G8 -> 0.18854457 | K8: BlueChoice HMO Referral Platinum 0 | L8: =IF($N$1*H8>=I8,I8,$N$1*H8) -> 754.48 | M8: =I8-L8 -> 133.03 | N8: =(L8-E8)/E8 -> 0.19036951 | O8: =(M8-F8)/F8 -> 0.17829938 | P8: =M8/I8 -> 0.14989127
A9: Penelope Kim | B9: 2 | C9: 31381 | D9: =($B$3-C9)/365 -> 37.693151 | E9: 1055.91 | F9: 263.97 | G9: 1319.88 | H9: ='[2]MEDICAL-Table Rates'!$S$54 -> 603.69 | I9: 1535.59 | J9: =(I9-G9)/G9 -> 0.16343152 | K9: BlueChoice Plus Opt-Out Platinum 0 | L9: =IF($N$1*H9+$P$1*SUM(H10:H11)>=I9,I9,$N$1*H9+$P$1*SUM(H10:H11)) -> 1228.472 | M9: =I9-L9 -> 307.118 | N9: =(L9-E9)/E9 -> 0.16342491 | O9: =(M9-F9)/F9 -> 0.16345797 | P9: =M9/I9 -> 0.2
D10: 29 | H10: ='[2]MEDICAL-Table Rates'!$S$41 -> 500.88
D11: 0 | H11: ='[2]MEDICAL-Table Rates'!$S$16 -> 431.02
A12: Michael B Moscarelli | B12: 4 | C12: 30749 | D12: =($B$3-C12)/365 -> 39.424658 | E12: 1733 | F12: 433.25 | G12: 2166.25 | H12: ='[2]MEDICAL-Table Rates'!$S$57 -> 618.19 | I12: 2501.76 | J12: =(I12-G12)/G12 -> 0.15488055 | K12: BlueChoice Plus Opt-Out Platinum 0 | L12: =IF($N$1*H12+$P$1*SUM(H13:H16)>=I12,I12,$N$1*H12+$P$1*SUM(H13:H16)) -> 2001.408 | M12: =I12-L12 -> 500.352 | N12: =(L12-E12)/E12 -> 0.15488055 | O12: =(M12-F12)/F12 -> 0.15488055 | P12: =M12/I12 -> 0.2
D13: 36 | H13: ='[2]MEDICAL-Table Rates'!$S$52 -> 590.51
D14: 6 | H14: ='[2]MEDICAL-Table Rates'!$S$16 -> 431.02
D15: 3 | H15: ='[2]MEDICAL-Table Rates'!$S$16 -> 431.02
D16: 0 | H16: ='[2]MEDICAL-Table Rates'!$S$16 -> 431.02
A17: Ana Aslan | B17: 1 | C17: 24458 | D17: =($B$3-C17)/365 -> 56.660274 | E17: 1758.76 | F17: 439.69 | G17: 2198.45 | H17: 1186.95 | I17: 2518.23 | J17: =(I17-G17)/G17 -> 0.14545703 | K17: BlueChoice Plus Opt-Out Platinum 0 | L17: =IF($N$1*H17+$P$1*H18>=I17,I17,$N$1*H17+$P$1*H18) -> 2014.584 | M17: =I17-L17 -> 503.646 | N17: =(L17-E17)/E17 -> 0.14545703 | O17: =(M17-F17)/F17 -> 0.14545703 | P17: =M17/I17 -> 0.2
D18: 59 | H18: ='[2]MEDICAL-Table Rates'!$S$89 -> 1331.28
A19: Lesly Yohana Rubio | B19: 0 | C19: 31552 | D19: =($B$3-C19)/365 -> 37.224658 | E19: 412.42 | F19: 249.96 | G19: 662.38 | H19: ='[2]MEDICAL-Table Rates'!$S$54 -> 603.69 | I19: 765.65 | J19: =(I19-G19)/G19 -> 0.15590749 | K19: BluePreferred PPO Platinum 0 | L19: =IF($N$1*H19>=I19,I19,$N$1*H19) -> 482.952 | M19: =I19-L19 -> 282.698 | N19: =(L19-E19)/E19 -> 0.17101983 | O19: =(M19-F19)/F19 -> 0.13097296 | P19: =M19/I19 -> 0.36922615
A20: Carmen Pena | B20: 2 | C20: 31899 | D20: =($B$3-C20)/365 -> 36.273973 | E20: 1116.67 | F20: 676.78 | G20: 1793.45 | H20: ='[2]MEDICAL-Table Rates'!$S$52 -> 590.51 | I20: 2061.23 | J20: =(I20-G20)/G20 -> 0.14930999 | K20: BluePreferred PPO Platinum 0 | L20: =IF($N$1*H20+$P$1*SUM(H21:H22)>=I20,I20,$N$1*H20+$P$1*SUM(H21:H22)) -> 1300.176 | M20: =I20-L20 -> 761.054 | N20: =(L20-E20)/E20 -> 0.16433324 | O20: =(M20-F20)/F20 -> 0.124522 | P20: =M20/I20 -> 0.36922323
D21: 37 | H21: ='[2]MEDICAL-Table Rates'!$S$54 -> 603.69
D22: 5 | H22: ='[2]MEDICAL-Table Rates'!$S$16 -> 431.02
A23: Kelly M McNally | B23: 0 | C23: 34588 | D23: =($B$3-C23)/365 -> 28.906849 | E23: 334.63 | F23: 117.07 | G23: 451.7 | H23: ='[2]MEDICAL-Table Rates'!$S$39 -> 490.33 | I23: 534.96 | J23: =(I23-G23)/G23 -> 0.18432588 | K23: HealthyBlue Advantage Platinum 500 | L23: =IF($N$1*H23>=I23,I23,$N$1*H23) -> 392.264 | M23: =I23-L23 -> 142.696 | N23: =(L23-E23)/E23 -> 0.17223202 | O23: =(M23-F23)/F23 -> 0.21889468 | P23: =M23/I23 -> 0.26674144
A24: Susanna J Meyer | B24: 0 | C24: 33900 | D24: =($B$3-C24)/365 -> 30.791781 | E24: 349.82 | F24: 122.38 | G24: 472.2 | H24: ='[2]MEDICAL-Table Rates'!$S$42 -> 513.4 | I24: 560.12 | J24: =(I24-G24)/G24 -> 0.18619229 | K24: HealthyBlue Advantage Platinum 500 | L24: =IF($N$1*H24>=I24,I24,$N$1*H24) -> 410.72 | M24: =I24-L24 -> 149.4 | N24: =(L24-E24)/E24 -> 0.17408953 | O24: =(M24-F24)/F24 -> 0.22078771 | P24: =M24/I24 -> 0.26672856
A25: Madeline Rae Steiner | B25: 0 | C25: 33765 | D25: =($B$3-C25)/365 -> 31.161644 | E25: 358.57 | F25: 125.44 | G25: 484.01 | H25: ='[2]MEDICAL-Table Rates'!$S$44 -> 526.58 | I25: 574.5 | J25: =(I25-G25)/G25 -> 0.18695895 | K25: HealthyBlue Advantage Platinum 500 | L25: =IF($N$1*H25>=I25,I25,$N$1*H25) -> 421.264 | M25: =I25-L25 -> 153.236 | N25: =(L25-E25)/E25 -> 0.17484452 | O25: =(M25-F25)/F25 -> 0.22158801 | P25: =M25/I25 -> 0.26672933
A26: Stephanie Monroy | B26: 0 | C26: 31116 | D26: =($B$3-C26)/365 -> 38.419178 | E26: 426.69 | F26: 149.27 | G26: 575.96 | H26: ='[2]MEDICAL-Table Rates'!$S$55 -> 610.94 | I26: 666.54 | J26: =(I26-G26)/G26 -> 0.15726787 | K26: HealthyBlue Advantage Platinum 500 | L26: =IF($N$1*H26>=I26,I26,$N$1*H26) -> 488.752 | M26: =I26-L26 -> 177.788 | N26: =(L26-E26)/E26 -> 0.14544986 | O26: =(M26-F26)/F26 -> 0.19104978 | P26: =M26/I26 -> 0.26673268
A27: Kirk Amper Del Rosario | B27: 0 | C27: 33886 | D27: =($B$3-C27)/365 -> 30.830137 | E27: 349.82 | F27: 75.87 | G27: 425.69 | H27: ='[2]MEDICAL-Table Rates'!$S$42 -> 513.4 | I27: 504.65 | J27: =(I27-G27)/G27 -> 0.18548709 | K27: HealthyBlue Plus Platinum 500 | L27: =IF($N$1*H27>=I27,I27,$N$1*H27) -> 410.72 | M27: =I27-L27 -> 93.93 | N27: =(L27-E27)/E27 -> 0.17408953 | O27: =(M27-F27)/F27 -> 0.23803875 | P27: =M27/I27 -> 0.186129
A28: Sara Jebena | B28: 0 | C28: 29996 | D28: =($B$3-C28)/365 -> 41.487671 | E28: 448.78 | F28: 97.34 | G28: 546.12 | H28: ='[2]MEDICAL-Table Rates'!$S$60 -> 667.62 | I28: 656.24 | J28: =(I28-G28)/G28 -> 0.20164067 | K28: HealthyBlue Plus Platinum 500 | L28: =IF($N$1*H28>=I28,I28,$N$1*H28) -> 534.096 | M28: =I28-L28 -> 122.144 | N28: =(L28-E28)/E28 -> 0.19010651 | O28: =(M28-F28)/F28 -> 0.25481816 | P28: =M28/I28 -> 0.18612703
A29: Summar T Lyons | B29: 1 | C29: 31217 | D29: =($B$3-C29)/365 -> 38.142466 | E29: 887.89 | F29: 192.58 | G29: 1080.47 | H29: ='[2]MEDICAL-Table Rates'!$S$55 -> 610.94 | I29: 1282.68 | J29: =(I29-G29)/G29 -> 0.18715004 | K29: HealthyBlue Plus Platinum 500 | L29: =IF($N$1*H29+$P$1*H30>=I29,I29,$N$1*H29+$P$1*H30) -> 1043.936 | M29: =I29-L29 -> 238.744 | N29: =(L29-E29)/E29 -> 0.17574925 | O29: =(M29-F29)/F29 -> 0.23971337 | P29: =M29/I29 -> 0.18612904
D30: 42 | H30: ='[2]MEDICAL-Table Rates'!$S$62 -> 693.98
A31: Armin Cordova | B31: 0 | C31: 35369 | D31: =($B$3-C31)/365 -> 26.767123 | E31: 324.42 | F31: 0 | G31: 324.42 | H31: ='[2]MEDICAL-Table Rates'!$S$28 -> 479.13 | I31: 374.63 | J31: =(I31-G31)/G31 -> 0.15476851 | K31: KP DC Platinum 0/10/Vision | L31: =IF($N$1*H31>=I31,I31,$N$1*H31) -> 374.63 | M31: =I31-L31 -> 0 | N31: =(L31-E31)/E31 -> 0.15476851 | O31: =(M31-F31)/F31 -> #DIV/0! | P31: =M31/I31 -> 0
A32: Megan Michelle Ash | B32: 0 | C32: 34295 | D32: =($B$3-C32)/365 -> 29.709589 | E32: 332 | F32: 0 | G32: 332 | H32: 500.88 | I32: 391.63 | J32: =(I32-G32)/G32 -> 0.17960843 | K32: KP DC Platinum 0/10/Vision | L32: =IF($N$1*H32>=I32,I32,$N$1*H32) -> 391.63 | M32: =I32-L32 -> 0 | N32: =(L32-E32)/E32 -> 0.17960843 | O32: =(M32-F32)/F32 -> #DIV/0! | P32: =M32/I32 -> 0
A33: Stephanie Verganza | B33: 0 | C33: 33576 | D33: =($B$3-C33)/365 -> 31.679452 | E33: 347.62 | F33: 0 | G33: 347.62 | H33: 526.58 | I33: 411.73 | J33: =(I33-G33)/G33 -> 0.18442552 | K33: KP DC Platinum 0/10/Vision | L33: =IF($N$1*H33>=I33,I33,$N$1*H33) -> 411.73 | M33: =I33-L33 -> 0 | N33: =(L33-E33)/E33 -> 0.18442552 | O33: =(M33-F33)/F33 -> #DIV/0! | P33: =M33/I33 -> 0
A34: Anh H Nguyen | B34: 1 | C34: 33338 | D34: =($B$3-C34)/365 -> 32.331507 | E34: 680.97 | F34: 0 | G34: 680.97 | H34: ='[2]MEDICAL-Table Rates'!$S$45 -> 538.44 | I34: =421.01+383.39 -> 804.4 | J34: =(I34-G34)/G34 -> 0.18125615 | K34: KP DC Platinum 0/10/Vision | L34: =IF($N$1*H34+$P$1*H35>=I34,I34,$N$1*H34+$P$1*H35) -> 804.4 | M34: =I34-L34 -> 0 | N34: =(L34-E34)/E34 -> 0.18125615 | O34: =(M34-F34)/F34 -> #DIV/0! | P34: =M34/I34 -> 0
D35: 28 | H35: ='[2]MEDICAL-Table Rates'!$S$39 -> 490.33
A36: Janira J Romero Reyes | B36: 1 | C36: 31561 | D36: =($B$3-C36)/365 -> 37.2 | E36: 691.67 | F36: 0 | G36: 691.67 | H36: 603.69 | I36: =472.02+337.01 -> 809.03 | J36: =(I36-G36)/G36 -> 0.16967629 | K36: KP DC Platinum 0/10/Vision | L36: =IF($N$1*H36+$P$1*H37>=I36,I36,$N$1*H36+$P$1*H37) -> 809.03 | M36: =I36-L36 -> 0 | N36: =(L36-E36)/E36 -> 0.16967629 | O36: =(M36-F36)/F36 -> #DIV/0! | P36: =M36/I36 -> 0
D37: 0 | H37: ='[2]MEDICAL-Table Rates'!$S$16 -> 431.02
A38: Danielle R Martin | B38: 1 | C38: 33497 | D38: =($B$3-C38)/365 -> 31.89589 | E38: 695.24 | F38: 0 | G38: 695.24 | H38: ='[2]MEDICAL-Table Rates'!$S$44 -> 526.58 | I38: =395.9*2 -> 791.8 | J38: =(I38-G38)/G38 -> 0.13888729 | K38: KP DC Platinum 0/10/Vision | L38: =IF($N$1*H38+$P$1*H39>=I38,I38,$N$1*H38+$P$1*H39) -> 791.8 | M38: =I38-L38 -> 0 | N38: =(L38-E38)/E38 -> 0.13888729 | O38: =(M38-F38)/F38 -> #DIV/0! | P38: =M38/I38 -> 0
D39: 31 | H39: ='[2]MEDICAL-Table Rates'!$S$44 -> 526.58
A40: William D Webber | B40: 1 | C40: 34122 | D40: =($B$3-C40)/365 -> 30.183562 | E40: 738.97 | F40: 0 | G40: 738.97 | H40: ='[2]MEDICAL-Table Rates'!$S$42 -> 513.4 | I40: =453.87+385.99 -> 839.86 | J40: =(I40-G40)/G40 -> 0.13652787 | K40: KP DC Platinum 0/10/Vision | L40: =IF($N$1*H40+$P$1*H41>=I40,I40,$N$1*H40+$P$1*H41) -> 839.86 | M40: =I40-L40 -> 0 | N40: =(L40-E40)/E40 -> 0.13652787 | O40: =(M40-F40)/F40 -> #DIV/0! | P40: =M40/I40 -> 0
...

Sheet Partners 23-24 75%
A1: 2023 Benefits Worksheet | M1: Partners Covers | N1: 0.75 | O1: Employee | P1: 0.75 | Q1: Dependents
A2: 1 | N2: No Changes Employees Actual Choices on DCHL
A3: Renewal Date | B3: 45139
A4: Basic Demographic Data | E4: Current Premiums | H4: Renewal Information | K4: Plan Info
A5: Employee | B5: Covered Dependents | C5: DOB | D5: Renewal Age | E5: Partners Current Premium | F5: Employee Current Monthly Premium based on May Invoice | G5: Total Cost Current Premium | H5: Renewal Premium BlueChoice Plus Opt-Out Platinum 0 | I5: Renewal Cost Employee's Actual Plan | J5: Percentage Change on Actual Plan | K5: Employee's Actual Plan Choice | L5: Maximum Renewal Cost for Partners BlueChoice Plus Platinum 0 | M5: Employee Premium On Renewal | N5: Percentage Change for Partners | O5: Percentage Change for Employee | P5: Employee's % Cost of Premium
A6: Alexandra Lishansky | B6: 1 | C6: 34087 | D6: =($B$3-C6)/365 -> 30.279452 | E6: 650.85 | F6: 257.39 | G6: 908.24 | H6: ='[2]MEDICAL-Table Rates'!$S$42 -> 513.4 | I6: 1055.95 | J6: =(I6-G6)/G6 -> 0.16263322 | K6: BlueChoice Advantage Platinum 0 | L6: =IF($N$1*H6+$P$1*H7>=I6,I6,$N$1*H6+$P$1*H7) -> 708.315 | M6: =I6-L6 -> 347.635 | N6: =(L6-E6)/E6 -> 0.088292233 | O6: =(M6-F6)/F6 -> 0.3506158 | P6: =M6/I6 -> 0.3292154
D7: 1 | H7: ='[2]MEDICAL-Table Rates'!$S$16 -> 431.02
A8: Marcio Nascimento | B8: 0 | C8: 26679 | D8: =($B$3-C8)/365 -> 50.575342 | E8: 633.82 | F8: 112.9 | G8: 746.72 | H8: ='[2]MEDICAL-Table Rates'!$S$75 -> 943.1 | I8: 887.51 | J8: =(I8-G8)/G8 -> 0.18854457 | K8: BlueChoice HMO Referral Platinum 0 | L8: =IF($N$1*H8>=I8,I8,$N$1*H8) -> 707.325 | M8: =I8-L8 -> 180.185 | N8: =(L8-E8)/E8 -> 0.11597141 | O8: =(M8-F8)/F8 -> 0.59596988 | P8: =M8/I8 -> 0.20302306
A9: Penelope Kim | B9: 2 | C9: 31381 | D9: =($B$3-C9)/365 -> 37.693151 | E9: 1055.91 | F9: 263.97 | G9: 1319.88 | H9: ='[2]MEDICAL-Table Rates'!$S$54 -> 603.69 | I9: 1535.59 | J9: =(I9-G9)/G9 -> 0.16343152 | K9: BlueChoice Plus Opt-Out Platinum 0 | L9: =IF($N$1*H9+$P$1*SUM(H10:H11)>=I9,I9,$N$1*H9+$P$1*SUM(H10:H11)) -> 1151.6925 | M9: =I9-L9 -> 383.8975 | N9: =(L9-E9)/E9 -> 0.090710856 | O9: =(M9-F9)/F9 -> 0.45432246 | P9: =M9/I9 -> 0.25
D10: 29 | H10: ='[2]MEDICAL-Table Rates'!$S$41 -> 500.88
D11: 0 | H11: ='[2]MEDICAL-Table Rates'!$S$16 -> 431.02
A12: Michael B Moscarelli | B12: 4 | C12: 30749 | D12: =($B$3-C12)/365 -> 39.424658 | E12: 1733 | F12: 433.25 | G12: 2166.25 | H12: ='[2]MEDICAL-Table Rates'!$S$57 -> 618.19 | I12: 2501.76 | J12: =(I12-G12)/G12 -> 0.15488055 | K12: BlueChoice Plus Opt-Out Platinum 0 | L12: =IF($N$1*H12+$P$1*SUM(H13:H16)>=I12,I12,$N$1*H12+$P$1*SUM(H13:H16)) -> 1876.32 | M12: =I12-L12 -> 625.44 | N12: =(L12-E12)/E12 -> 0.082700519 | O12: =(M12-F12)/F12 -> 0.44360069 | P12: =M12/I12 -> 0.25
D13: 36 | H13: ='[2]MEDICAL-Table Rates'!$S$52 -> 590.51
D14: 6 | H14: ='[2]MEDICAL-Table Rates'!$S$16 -> 431.02
D15: 3 | H15: ='[2]MEDICAL-Table Rates'!$S$16 -> 431.02
D16: 0 | H16: ='[2]MEDICAL-Table Rates'!$S$16 -> 431.02
A17: Ana Aslan | B17: 1 | C17: 24458 | D17: =($B$3-C17)/365 -> 56.660274 | E17: 1758.76 | F17: 439.69 | G17: 2198.45 | H17: 1186.95 | I17: 2518.23 | J17: =(I17-G17)/G17 -> 0.14545703 | K17: BlueChoice Plus Opt-Out Platinum 0 | L17: =IF($N$1*H17+$P$1*H18>=I17,I17,$N$1*H17+$P$1*H18) -> 1888.6725 | M17: =I17-L17 -> 629.5575 | N17: =(L17-E17)/E17 -> 0.073865962 | O17: =(M17-F17)/F17 -> 0.43182128 | P17: =M17/I17 -> 0.25
D18: 59 | H18: ='[2]MEDICAL-Table Rates'!$S$89 -> 1331.28
A19: Lesly Yohana Rubio | B19: 0 | C19: 31552 | D19: =($B$3-C19)/365 -> 37.224658 | E19: 412.42 | F19: 249.96 | G19: 662.38 | H19: ='[2]MEDICAL-Table Rates'!$S$54 -> 603.69 | I19: 765.65 | J19: =(I19-G19)/G19 -> 0.15590749 | K19: BluePreferred PPO Platinum 0 | L19: =IF($N$1*H19>=I19,I19,$N$1*H19) -> 452.7675 | M19: =I19-L19 -> 312.8825 | N19: =(L19-E19)/E19 -> 0.097831095 | O19: =(M19-F19)/F19 -> 0.25173028 | P19: =M19/I19 -> 0.40864951
A20: Carmen Pena | B20: 2 | C20: 31899 | D20: =($B$3-C20)/365 -> 36.273973 | E20: 1116.67 | F20: 676.78 | G20: 1793.45 | H20: ='[2]MEDICAL-Table Rates'!$S$52 -> 590.51 | I20: 2061.23 | J20: =(I20-G20)/G20 -> 0.14930999 | K20: BluePreferred PPO Platinum 0 | L20: =IF($N$1*H20+$P$1*SUM(H21:H22)>=I20,I20,$N$1*H20+$P$1*SUM(H21:H22)) -> 1218.915 | M20: =I20-L20 -> 842.315 | N20: =(L20-E20)/E20 -> 0.091562413 | O20: =(M20-F20)/F20 -> 0.24459204 | P20: =M20/I20 -> 0.40864678
D21: 37 | H21: ='[2]MEDICAL-Table Rates'!$S$54 -> 603.69
D22: 5 | H22: ='[2]MEDICAL-Table Rates'!$S$16 -> 431.02
A23: Kelly M McNally | B23: 0 | C23: 34588 | D23: =($B$3-C23)/365 -> 28.906849 | E23: 334.63 | F23: 117.07 | G23: 451.7 | H23: ='[2]MEDICAL-Table Rates'!$S$39 -> 490.33 | I23: 534.96 | J23: =(I23-G23)/G23 -> 0.18432588 | K23: HealthyBlue Advantage Platinum 500 | L23: =IF($N$1*H23>=I23,I23,$N$1*H23) -> 367.7475 | M23: =I23-L23 -> 167.2125 | N23: =(L23-E23)/E23 -> 0.098967516 | O23: =(M23-F23)/F23 -> 0.42831212 | P23: =M23/I23 -> 0.3125701
A24: Susanna J Meyer | B24: 0 | C24: 33900 | D24: =($B$3-C24)/365 -> 30.791781 | E24: 349.82 | F24: 122.38 | G24: 472.2 | H24: ='[2]MEDICAL-Table Rates'!$S$42 -> 513.4 | I24: 560.12 | J24: =(I24-G24)/G24 -> 0.18619229 | K24: HealthyBlue Advantage Platinum 500 | L24: =IF($N$1*H24>=I24,I24,$N$1*H24) -> 385.05 | M24: =I24-L24 -> 175.07 | N24: =(L24-E24)/E24 -> 0.10070894 | O24: =(M24-F24)/F24 -> 0.43054421 | P24: =M24/I24 -> 0.31255802
A25: Madeline Rae Steiner | B25: 0 | C25: 33765 | D25: =($B$3-C25)/365 -> 31.161644 | E25: 358.57 | F25: 125.44 | G25: 484.01 | H25: ='[2]MEDICAL-Table Rates'!$S$44 -> 526.58 | I25: 574.5 | J25: =(I25-G25)/G25 -> 0.18695895 | K25: HealthyBlue Advantage Platinum 500 | L25: =IF($N$1*H25>=I25,I25,$N$1*H25) -> 394.935 | M25: =I25-L25 -> 179.565 | N25: =(L25-E25)/E25 -> 0.10141674 | O25: =(M25-F25)/F25 -> 0.43148119 | P25: =M25/I25 -> 0.31255875
A26: Stephanie Monroy | B26: 0 | C26: 31116 | D26: =($B$3-C26)/365 -> 38.419178 | E26: 426.69 | F26: 149.27 | G26: 575.96 | H26: ='[2]MEDICAL-Table Rates'!$S$55 -> 610.94 | I26: 666.54 | J26: =(I26-G26)/G26 -> 0.15726787 | K26: HealthyBlue Advantage Platinum 500 | L26: =IF($N$1*H26>=I26,I26,$N$1*H26) -> 458.205 | M26: =I26-L26 -> 208.335 | N26: =(L26-E26)/E26 -> 0.073859242 | O26: =(M26-F26)/F26 -> 0.39569237 | P26: =M26/I26 -> 0.31256189
A27: Kirk Amper Del Rosario | B27: 0 | C27: 33886 | D27: =($B$3-C27)/365 -> 30.830137 | E27: 349.82 | F27: 75.87 | G27: 425.69 | H27: ='[2]MEDICAL-Table Rates'!$S$42 -> 513.4 | I27: 504.65 | J27: =(I27-G27)/G27 -> 0.18548709 | K27: HealthyBlue Plus Platinum 500 | L27: =IF($N$1*H27>=I27,I27,$N$1*H27) -> 385.05 | M27: =I27-L27 -> 119.6 | N27: =(L27-E27)/E27 -> 0.10070894 | O27: =(M27-F27)/F27 -> 0.57638065 | P27: =M27/I27 -> 0.23699594
A28: Sara Jebena | B28: 0 | C28: 29996 | D28: =($B$3-C28)/365 -> 41.487671 | E28: 448.78 | F28: 97.34 | G28: 546.12 | H28: ='[2]MEDICAL-Table Rates'!$S$60 -> 667.62 | I28: 656.24 | J28: =(I28-G28)/G28 -> 0.20164067 | K28: HealthyBlue Plus Platinum 500 | L28: =IF($N$1*H28>=I28,I28,$N$1*H28) -> 500.715 | M28: =I28-L28 -> 155.525 | N28: =(L28-E28)/E28 -> 0.11572485 | O28: =(M28-F28)/F28 -> 0.59775015 | P28: =M28/I28 -> 0.23699409
A29: Summar T Lyons | B29: 1 | C29: 31217 | D29: =($B$3-C29)/365 -> 38.142466 | E29: 887.89 | F29: 192.58 | G29: 1080.47 | H29: ='[2]MEDICAL-Table Rates'!$S$55 -> 610.94 | I29: 1282.68 | J29: =(I29-G29)/G29 -> 0.18715004 | K29: HealthyBlue Plus Platinum 500 | L29: =IF($N$1*H29+$P$1*H30>=I29,I29,$N$1*H29+$P$1*H30) -> 978.69 | M29: =I29-L29 -> 303.99 | N29: =(L29-E29)/E29 -> 0.10226492 | O29: =(M29-F29)/F29 -> 0.57851283 | P29: =M29/I29 -> 0.23699598
D30: 42 | H30: ='[2]MEDICAL-Table Rates'!$S$62 -> 693.98
A31: Armin Cordova | B31: 0 | C31: 35369 | D31: =($B$3-C31)/365 -> 26.767123 | E31: 324.42 | F31: 0 | G31: 324.42 | H31: ='[2]MEDICAL-Table Rates'!$S$28 -> 479.13 | I31: 374.63 | J31: =(I31-G31)/G31 -> 0.15476851 | K31: KP DC Platinum 0/10/Vision | L31: =IF($N$1*H31>=I31,I31,$N$1*H31) -> 359.3475 | M31: =I31-L31 -> 15.2825 | N31: =(L31-E31)/E31 -> 0.10766136 | O31: =(M31-F31)/F31 -> #DIV/0! | P31: =M31/I31 -> 0.040793583
A32: Megan Michelle Ash | B32: 0 | C32: 34295 | D32: =($B$3-C32)/365 -> 29.709589 | E32: 332 | F32: 0 | G32: 332 | H32: 500.88 | I32: 391.63 | J32: =(I32-G32)/G32 -> 0.17960843 | K32: KP DC Platinum 0/10/Vision | L32: =IF($N$1*H32>=I32,I32,$N$1*H32) -> 375.66 | M32: =I32-L32 -> 15.97 | N32: =(L32-E32)/E32 -> 0.13150602 | O32: =(M32-F32)/F32 -> #DIV/0! | P32: =M32/I32 -> 0.040778286
A33: Stephanie Verganza | B33: 0 | C33: 33576 | D33: =($B$3-C33)/365 -> 31.679452 | E33: 347.62 | F33: 0 | G33: 347.62 | H33: 526.58 | I33: 411.73 | J33: =(I33-G33)/G33 -> 0.18442552 | K33: KP DC Platinum 0/10/Vision | L33: =IF($N$1*H33>=I33,I33,$N$1*H33) -> 394.935 | M33: =I33-L33 -> 16.795 | N33: =(L33-E33)/E33 -> 0.13611127 | O33: =(M33-F33)/F33 -> #DIV/0! | P33: =M33/I33 -> 0.040791295
A34: Anh H Nguyen | B34: 1 | C34: 33338 | D34: =($B$3-C34)/365 -> 32.331507 | E34: 680.97 | F34: 0 | G34: 680.97 | H34: ='[2]MEDICAL-Table Rates'!$S$45 -> 538.44 | I34: =421.01+383.39 -> 804.4 | J34: =(I34-G34)/G34 -> 0.18125615 | K34: KP DC Platinum 0/10/Vision | L34: =IF($N$1*H34+$P$1*H35>=I34,I34,$N$1*H34+$P$1*H35) -> 771.5775 | M34: =I34-L34 -> 32.8225 | N34: =(L34-E34)/E34 -> 0.13305652 | O34: =(M34-F34)/F34 -> #DIV/0! | P34: =M34/I34 -> 0.040803705
D35: 28 | H35: ='[2]MEDICAL-Table Rates'!$S$39 -> 490.33
A36: Janira J Romero Reyes | B36: 1 | C36: 31561 | D36: =($B$3-C36)/365 -> 37.2 | E36: 691.67 | F36: 0 | G36: 691.67 | H36: 603.69 | I36: =472.02+337.01 -> 809.03 | J36: =(I36-G36)/G36 -> 0.16967629 | K36: KP DC Platinum 0/10/Vision | L36: =IF($N$1*H36+$P$1*H37>=I36,I36,$N$1*H36+$P$1*H37) -> 776.0325 | M36: =I36-L36 -> 32.9975 | N36: =(L36-E36)/E36 -> 0.12196929 | O36: =(M36-F36)/F36 -> #DIV/0! | P36: =M36/I36 -> 0.040786497
D37: 0 | H37: ='[2]MEDICAL-Table Rates'!$S$16 -> 431.02
A38: Danielle R Martin | B38: 1 | C38: 33497 | D38: =($B$3-C38)/365 -> 31.89589 | E38: 695.24 | F38: 0 | G38: 695.24 | H38: ='[2]MEDICAL-Table Rates'!$S$44 -> 526.58 | I38: =395.9*2 -> 791.8 | J38: =(I38-G38)/G38 -> 0.13888729 | K38: KP DC Platinum 0/10/Vision | L38: =IF($N$1*H38+$P$1*H39>=I38,I38,$N$1*H38+$P$1*H39) -> 789.87 | M38: =I38-L38 -> 1.93 | N38: =(L38-E38)/E38 -> 0.13611127 | O38: =(M38-F38)/F38 -> #DIV/0! | P38: =M38/I38 -> 0.0024374842
D39: 31 | H39: ='[2]MEDICAL-Table Rates'!$S$44 -> 526.58
A40: William D Webber | B40: 1 | C40: 34122 | D40: =($B$3-C40)/365 -> 30.183562 | E40: 738.97 | F40: 0 | G40: 738.97 | H40: ='[2]MEDICAL-Table Rates'!$S$42 -> 513.4 | I40: =453.87+385.99 -> 839.86 | J40: =(I40-G40)/G40 -> 0.13652787 | K40: KP DC Platinum 0/10/Vision | L40: =IF($N$1*H40+$P$1*H41>=I40,I40,$N$1*H40+$P$1*H41) -> 837.8175 | M40: =I40-L40 -> 2.0425 | N40: =(L40-E40)/E40 -> 0.13376389 | O40: =(M40-F40)/F40 -> #DIV/0! | P40: =M40/I40 -> 0.0024319529
...

Sheet Prtnrs Change Ref to Gold HRA
A1: 2023 Benefits Worksheet | M1: Partners Covers | N1: 0.8 | O1: Employee | P1: 0.8 | Q1: Dependents
A2: 1 | N2: No Changes Employees Actual Choices on DCHL
A3: Renewal Date | B3: 45139
A4: Basic Demographic Data | E4: Current Premiums | H4: Renewal Information | K4: Plan Info
A5: Employee | B5: Covered Dependents | C5: DOB | D5: Renewal Age | E5: Partners Current Premium | F5: Employee Current Monthly Premium based on May Invoice | G5: Total Cost Current Premium | H5: Renewal Premium BlueChoice Advantage HDHP/HSA/HRA Gold Plan - $1,500 | I5: Renewal Cost Employee's Actual Plan | J5: Percentage Change on Actual Plan | K5: Employee's Actual Plan Choice | L5: Maximum Renewal Cost for Partners BlueChoice Advantage HDHP/HSA/HRA Gold Plan - $1,500 | M5: Employee Premium On Renewal | N5: Percentage Change for Partners | O5: Percentage Change for Employee | P5: Employee's % Cost of Premium
A6: Alexandra Lishansky | B6: 1 | C6: 34087 | D6: =($B$3-C6)/365 -> 30.279452 | E6: 650.85 | F6: 257.39 | G6: 908.24 | H6: 461.62 | I6: =SUM(H6:H7) -> 849.17 | J6: =(I6-G6)/G6 -> -0.065037875 | K6: BlueChoice Advantage HDHP/HSA/HRA Gold Plan - $1,500 | L6: =IF($N$1*H6+$P$1*H7>=I6,I6,$N$1*H6+$P$1*H7) -> 679.336 | M6: =I6-L6 -> 169.834 | N6: =(L6-E6)/E6 -> 0.043767381 | O6: =(M6-F6)/F6 -> -0.34016862 | P6: =M6/I6 -> 0.2
D7: 1 | H7: 387.55
A8: Marcio Nascimento | B8: 0 | C8: 26679 | D8: =($B$3-C8)/365 -> 50.575342 | E8: 633.82 | F8: 112.9 | G8: 746.72 | H8: 847.98 | I8: =H8 -> 847.98 | J8: =(I8-G8)/G8 -> 0.13560639 | K8: BlueChoice Advantage HDHP/HSA/HRA Gold Plan - $1,500 | L8: =IF($N$1*H8>=I8,I8,$N$1*H8) -> 678.384 | M8: =I8-L8 -> 169.596 | N8: =(L8-E8)/E8 -> 0.070310183 | O8: =(M8-F8)/F8 -> 0.50217892 | P8: =M8/I8 -> 0.2
A9: Penelope Kim | B9: 2 | C9: 31381 | D9: =($B$3-C9)/365 -> 37.693151 | E9: 1055.91 | F9: 263.97 | G9: 1319.88 | H9: 542.8 | I9: =SUM(H9:H11) -> 1380.71 | J9: =(I9-G9)/G9 -> 0.046087523 | K9: BlueChoice Advantage HDHP/HSA/HRA Gold Plan - $1,500 | L9: =IF($N$1*H9+$P$1*SUM(H10:H11)>=I9,I9,$N$1*H9+$P$1*SUM(H10:H11)) -> 1104.568 | M9: =I9-L9 -> 276.142 | N9: =(L9-E9)/E9 -> 0.046081579 | O9: =(M9-F9)/F9 -> 0.046111301 | P9: =M9/I9 -> 0.2
D10: 29 | H10: 450.36
D11: 0 | H11: 387.55
A12: Michael B Moscarelli | B12: 4 | C12: 30749 | D12: =($B$3-C12)/365 -> 39.424658 | E12: 1733 | F12: 433.25 | G12: 2166.25 | H12: 555.84 | I12: =SUM(H12:H16) -> 2249.44 | J12: =(I12-G12)/G12 -> 0.03840277 | K12: BlueChoice Advantage HDHP/HSA/HRA Gold Plan - $1,500 | L12: =IF($N$1*H12+$P$1*SUM(H13:H16)>=I12,I12,$N$1*H12+$P$1*SUM(H13:H16)) -> 1799.552 | M12: =I12-L12 -> 449.888 | N12: =(L12-E12)/E12 -> 0.03840277 | O12: =(M12-F12)/F12 -> 0.03840277 | P12: =M12/I12 -> 0.2
D13: 36 | H13: 530.95
D14: 6 | H14: 387.55
D15: 3 | H15: 387.55
D16: 0 | H16: 387.55
A17: Ana Aslan | B17: 1 | C17: 24458 | D17: =($B$3-C17)/365 -> 56.660274 | E17: 1758.76 | F17: 439.69 | G17: 2198.45 | H17: 1067.24 | I17: =SUM(H17:H18) -> 2264.25 | J17: =(I17-G17)/G17 -> 0.029930178 | K17: BlueChoice Advantage HDHP/HSA/HRA Gold Plan - $1,500 | L17: =IF($N$1*H17+$P$1*H18>=I17,I17,$N$1*H17+$P$1*H18) -> 1811.4 | M17: =I17-L17 -> 452.85 | N17: =(L17-E17)/E17 -> 0.029930178 | O17: =(M17-F17)/F17 -> 0.029930178 | P17: =M17/I17 -> 0.2
D18: 59 | H18: 1197.01
A19: Lesly Yohana Rubio | B19: 0 | C19: 31552 | D19: =($B$3-C19)/365 -> 37.224658 | E19: 412.42 | F19: 249.96 | G19: 662.38 | H19: 542.8 | I19: =H19 -> 542.8 | J19: =(I19-G19)/G19 -> -0.18053081 | K19: BlueChoice Advantage HDHP/HSA/HRA Gold Plan - $1,500 | L19: =IF($N$1*H19>=I19,I19,$N$1*H19) -> 434.24 | M19: =I19-L19 -> 108.56 | N19: =(L19-E19)/E19 -> 0.05290723 | O19: =(M19-F19)/F19 -> -0.56569051 | P19: =M19/I19 -> 0.2
A20: Carmen Pena | B20: 2 | C20: 31899 | D20: =($B$3-C20)/365 -> 36.273973 | E20: 1116.67 | F20: 676.78 | G20: 1793.45 | H20: 530.95 | I20: =SUM(H20:H22) -> 1461.3 | J20: =(I20-G20)/G20 -> -0.18520171 | K20: BlueChoice Advantage HDHP/HSA/HRA Gold Plan - $1,500 | L20: =IF($N$1*H20+$P$1*SUM(H21:H22)>=I20,I20,$N$1*H20+$P$1*SUM(H21:H22)) -> 1169.04 | M20: =I20-L20 -> 292.26 | N20: =(L20-E20)/E20 -> 0.046898367 | O20: =(M20-F20)/F20 -> -0.568161 | P20: =M20/I20 -> 0.2
D21: 37 | H21: 542.8
D22: 5 | H22: 387.55
A23: Kelly M McNally | B23: 0 | C23: 34588 | D23: =($B$3-C23)/365 -> 28.906849 | E23: 334.63 | F23: 117.07 | G23: 451.7 | H23: 440.88 | I23: =H23 -> 440.88 | J23: =(I23-G23)/G23 -> -0.023953952 | K23: BlueChoice Advantage HDHP/HSA/HRA Gold Plan - $1,500 | L23: =IF($N$1*H23>=I23,I23,$N$1*H23) -> 352.704 | M23: =I23-L23 -> 88.176 | N23: =(L23-E23)/E23 -> 0.054011894 | O23: =(M23-F23)/F23 -> -0.2468096 | P23: =M23/I23 -> 0.2
A24: Susanna J Meyer | B24: 0 | C24: 33900 | D24: =($B$3-C24)/365 -> 30.791781 | E24: 349.82 | F24: 122.38 | G24: 472.2 | H24: 461.62 | I24: =H24 -> 461.62 | J24: =(I24-G24)/G24 -> -0.02240576 | K24: BlueChoice Advantage HDHP/HSA/HRA Gold Plan - $1,500 | L24: =IF($N$1*H24>=I24,I24,$N$1*H24) -> 369.296 | M24: =I24-L24 -> 92.324 | N24: =(L24-E24)/E24 -> 0.055674347 | O24: =(M24-F24)/F24 -> -0.24559569 | P24: =M24/I24 -> 0.2
A25: Madeline Rae Steiner | B25: 0 | C25: 33765 | D25: =($B$3-C25)/365 -> 31.161644 | E25: 358.57 | F25: 125.44 | G25: 484.01 | H25: 473.47 | I25: =H25 -> 473.47 | J25: =(I25-G25)/G25 -> -0.02177641 | K25: BlueChoice Advantage HDHP/HSA/HRA Gold Plan - $1,500 | L25: =IF($N$1*H25>=I25,I25,$N$1*H25) -> 378.776 | M25: =I25-L25 -> 94.694 | N25: =(L25-E25)/E25 -> 0.056351619 | O25: =(M25-F25)/F25 -> -0.24510523 | P25: =M25/I25 -> 0.2
A26: Stephanie Monroy | B26: 0 | C26: 31116 | D26: =($B$3-C26)/365 -> 38.419178 | E26: 426.69 | F26: 149.27 | G26: 575.96 | H26: 549.32 | I26: =H26 -> 549.32 | J26: =(I26-G26)/G26 -> -0.046253212 | K26: BlueChoice Advantage HDHP/HSA/HRA Gold Plan - $1,500 | L26: =IF($N$1*H26>=I26,I26,$N$1*H26) -> 439.456 | M26: =I26-L26 -> 109.864 | N26: =(L26-E26)/E26 -> 0.029918676 | O26: =(M26-F26)/F26 -> -0.26399142 | P26: =M26/I26 -> 0.2
A27: Kirk Amper Del Rosario | B27: 0 | C27: 33886 | D27: =($B$3-C27)/365 -> 30.830137 | E27: 349.82 | F27: 75.87 | G27: 425.69 | H27: 461.62 | I27: =H27 -> 461.62 | J27: =(I27-G27)/G27 -> 0.084404144 | K27: BlueChoice Advantage HDHP/HSA/HRA Gold Plan - $1,500 | L27: =IF($N$1*H27>=I27,I27,$N$1*H27) -> 369.296 | M27: =I27-L27 -> 92.324 | N27: =(L27-E27)/E27 -> 0.055674347 | O27: =(M27-F27)/F27 -> 0.21687096 | P27: =M27/I27 -> 0.2
A28: Sara Jebena | B28: 0 | C28: 29996 | D28: =($B$3-C28)/365 -> 41.487671 | E28: 448.78 | F28: 97.34 | G28: 546.12 | H28: 600.28 | I28: =H28 -> 600.28 | J28: =(I28-G28)/G28 -> 0.099172343 | K28: BlueChoice Advantage HDHP/HSA/HRA Gold Plan - $1,500 | L28: =IF($N$1*H28>=I28,I28,$N$1*H28) -> 480.224 | M28: =I28-L28 -> 120.056 | N28: =(L28-E28)/E28 -> 0.070065511 | O28: =(M28-F28)/F28 -> 0.23336758 | P28: =M28/I28 -> 0.2
A29: Summar T Lyons | B29: 1 | C29: 31217 | D29: =($B$3-C29)/365 -> 38.142466 | E29: 887.89 | F29: 192.58 | G29: 1080.47 | H29: 549.32 | I29: =SUM(H29:H30) -> 1173.31 | J29: =(I29-G29)/G29 -> 0.085925569 | K29: BlueChoice Advantage HDHP/HSA/HRA Gold Plan - $1,500 | L29: =IF($N$1*H29+$P$1*H30>=I29,I29,$N$1*H29+$P$1*H30) -> 938.648 | M29: =I29-L29 -> 234.662 | N29: =(L29-E29)/E29 -> 0.057166991 | O29: =(M29-F29)/F29 -> 0.21851698 | P29: =M29/I29 -> 0.2
D30: 42 | H30: 623.99
A31: Armin Cordova | B31: 0 | C31: 35369 | D31: =($B$3-C31)/365 -> 26.767123 | E31: 324.42 | F31: 0 | G31: 324.42 | H31: 430.81 | I31: =H31 -> 430.81 | J31: =(I31-G31)/G31 -> 0.32793909 | K31: BlueChoice Advantage HDHP/HSA/HRA Gold Plan - $1,500 | L31: =IF($N$1*H31>=I31,I31,$N$1*H31) -> 344.648 | M31: =I31-L31 -> 86.162 | N31: =(L31-E31)/E31 -> 0.062351273 | O31: =(M31-F31)/F31 -> #DIV/0! | P31: =M31/I31 -> 0.2
A32: Megan Michelle Ash | B32: 0 | C32: 34295 | D32: =($B$3-C32)/365 -> 29.709589 | E32: 332 | F32: 0 | G32: 332 | H32: 450.36 | I32: =H32 -> 450.36 | J32: =(I32-G32)/G32 -> 0.35650602 | K32: BlueChoice Advantage HDHP/HSA/HRA Gold Plan - $1,500 | L32: =IF($N$1*H32>=I32,I32,$N$1*H32) -> 360.288 | M32: =I32-L32 -> 90.072 | N32: =(L32-E32)/E32 -> 0.085204819 | O32: =(M32-F32)/F32 -> #DIV/0! | P32: =M32/I32 -> 0.2
A33: Stephanie Verganza | B33: 0 | C33: 33576 | D33: =($B$3-C33)/365 -> 31.679452 | E33: 347.62 | F33: 0 | G33: 347.62 | H33: 473.47 | I33: =H33 -> 473.47 | J33: =(I33-G33)/G33 -> 0.36203325 | K33: BlueChoice Advantage HDHP/HSA/HRA Gold Plan - $1,500 | L33: =IF($N$1*H33>=I33,I33,$N$1*H33) -> 378.776 | M33: =I33-L33 -> 94.694 | N33: =(L33-E33)/E33 -> 0.089626604 | O33: =(M33-F33)/F33 -> #DIV/0! | P33: =M33/I33 -> 0.2
A34: Anh H Nguyen | B34: 1 | C34: 33338 | D34: =($B$3-C34)/365 -> 32.331507 | E34: 680.97 | F34: 0 | G34: 680.97 | H34: 484.14 | I34: =SUM(H34:H35) -> 925.02 | J34: =(I34-G34)/G34 -> 0.35838583 | K34: BlueChoice Advantage HDHP/HSA/HRA Gold Plan - $1,500 | L34: =IF($N$1*H34+$P$1*H35>=I34,I34,$N$1*H34+$P$1*H35) -> 740.016 | M34: =I34-L34 -> 185.004 | N34: =(L34-E34)/E34 -> 0.086708666 | O34: =(M34-F34)/F34 -> #DIV/0! | P34: =M34/I34 -> 0.2
D35: 28 | H35: 440.88
A36: Janira J Romero Reyes | B36: 1 | C36: 31561 | D36: =($B$3-C36)/365 -> 37.2 | E36: 691.67 | F36: 0 | G36: 691.67 | H36: 542.8 | I36: =SUM(H36:H37) -> 930.35 | J36: =(I36-G36)/G36 -> 0.34507786 | K36: BlueChoice Advantage HDHP/HSA/HRA Gold Plan - $1,500 | L36: =IF($N$1*H36+$P$1*H37>=I36,I36,$N$1*H36+$P$1*H37) -> 744.28 | M36: =I36-L36 -> 186.07 | N36: =(L36-E36)/E36 -> 0.076062284 | O36: =(M36-F36)/F36 -> #DIV/0! | P36: =M36/I36 -> 0.2
D37: 0 | H37: 387.55
A38: Danielle R Martin | B38: 1 | C38: 33497 | D38: =($B$3-C38)/365 -> 31.89589 | E38: 695.24 | F38: 0 | G38: 695.24 | H38: 473.47 | I38: =SUM(H38:H39) -> 946.94 | J38: =(I38-G38)/G38 -> 0.36203325 | K38: BlueChoice Advantage HDHP/HSA/HRA Gold Plan - $1,500 | L38: =IF($N$1*H38+$P$1*H39>=I38,I38,$N$1*H38+$P$1*H39) -> 757.552 | M38: =I38-L38 -> 189.388 | N38: =(L38-E38)/E38 -> 0.089626604 | O38: =(M38-F38)/F38 -> #DIV/0! | P38: =M38/I38 -> 0.2
D39: 31 | H39: 473.47
A40: William D Webber | B40: 1 | C40: 34122 | D40: =($B$3-C40)/365 -> 30.183562 | E40: 738.97 | F40: 0 | G40: 738.97 | H40: 461.62 | I40: =SUM(H40:H41) -> 1004.42 | J40: =(I40-G40)/G40 -> 0.35921621 | K40: BlueChoice Advantage HDHP/HSA/HRA Gold Plan - $1,500 | L40: =IF($N$1*H40+$P$1*H41>=I40,I40,$N$1*H40+$P$1*H41) -> 803.536 | M40: =I40-L40 -> 200.884 | N40: =(L40-E40)/E40 -> 0.087372965 | O40: =(M40-F40)/F40 -> #DIV/0! | P40: =M40/I40 -> 0.2
...

Sheet Prtnrs Change Ref to Silver HRA
A1: 2023 Benefits Worksheet | M1: Partners Covers | N1: 0.8 | O1: Employee | P1: 0.8 | Q1: Dependents
A2: 1 | N2: No Changes Employees Actual Choices on DCHL
A3: Renewal Date | B3: 45139
A4: Basic Demographic Data | E4: Current Premiums | H4: Renewal Information | K4: Plan Info
A5: Employee | B5: Covered Dependents | C5: DOB | D5: Renewal Age | E5: Partners Current Premium | F5: Employee Current Monthly Premium based on May Invoice | G5: Total Cost Current Premium | H5: Renewal Premium BlueChoice Advantage HSA BlueFund Silver Plan - $1,600 | I5: Renewal Cost Employee's Actual Plan | J5: Percentage Change on Actual Plan | K5: Employee's Actual Plan Choice | L5: Maximum Renewal Cost for Partners BlueChoice Advantage HSA BlueFund Silver Plan - $1,600 | M5: Employee Premium On Renewal | N5: Percentage Change for Partners | O5: Percentage Change for Employee | P5: Employee's % Cost of Premium
A6: Alexandra Lishansky | B6: 1 | C6: 34087 | D6: =($B$3-C6)/365 -> 30.279452 | E6: 650.85 | F6: 257.39 | G6: 908.24 | H6: 407.85 | I6: =SUM(H6:H7) -> 750.25 | J6: =(I6-G6)/G6 -> -0.17395182 | K6: BlueChoice Advantage HSA BlueFund Silver Plan - $1,600 | L6: =IF($N$1*H6+$P$1*H7>=I6,I6,$N$1*H6+$P$1*H7) -> 600.2 | M6: =I6-L6 -> 150.05 | N6: =(L6-E6)/E6 -> -0.077821311 | O6: =(M6-F6)/F6 -> -0.41703252 | P6: =M6/I6 -> 0.2
D7: 1 | H7: 342.4
A8: Marcio Nascimento | B8: 0 | C8: 26679 | D8: =($B$3-C8)/365 -> 50.575342 | E8: 633.82 | F8: 112.9 | G8: 746.72 | H8: 749.2 | I8: =H8 -> 749.2 | J8: =(I8-G8)/G8 -> 0.0033211913 | K8: BlueChoice Advantage HSA BlueFund Silver Plan - $1,600 | L8: =IF($N$1*H8>=I8,I8,$N$1*H8) -> 599.36 | M8: =I8-L8 -> 149.84 | N8: =(L8-E8)/E8 -> -0.054368748 | O8: =(M8-F8)/F8 -> 0.32719221 | P8: =M8/I8 -> 0.2
A9: Penelope Kim | B9: 2 | C9: 31381 | D9: =($B$3-C9)/365 -> 37.693151 | E9: 1055.91 | F9: 263.97 | G9: 1319.88 | H9: 479.57 | I9: =SUM(H9:H11) -> 1219.87 | J9: =(I9-G9)/G9 -> -0.07577204 | K9: BlueChoice Advantage HSA BlueFund Silver Plan - $1,600 | L9: =IF($N$1*H9+$P$1*SUM(H10:H11)>=I9,I9,$N$1*H9+$P$1*SUM(H10:H11)) -> 975.896 | M9: =I9-L9 -> 243.974 | N9: =(L9-E9)/E9 -> -0.075777292 | O9: =(M9-F9)/F9 -> -0.075751032 | P9: =M9/I9 -> 0.2
D10: 29 | H10: 397.9
D11: 0 | H11: 342.4
A12: Michael B Moscarelli | B12: 4 | C12: 30749 | D12: =($B$3-C12)/365 -> 39.424658 | E12: 1733 | F12: 433.25 | G12: 2166.25 | H12: 491.09 | I12: =SUM(H12:H16) -> 1987.39 | J12: =(I12-G12)/G12 -> -0.082566647 | K12: BlueChoice Advantage HSA BlueFund Silver Plan - $1,600 | L12: =IF($N$1*H12+$P$1*SUM(H13:H16)>=I12,I12,$N$1*H12+$P$1*SUM(H13:H16)) -> 1589.912 | M12: =I12-L12 -> 397.478 | N12: =(L12-E12)/E12 -> -0.082566647 | O12: =(M12-F12)/F12 -> -0.082566647 | P12: =M12/I12 -> 0.2
D13: 36 | H13: 469.1
D14: 6 | H14: 342.4
D15: 3 | H15: 342.4
D16: 0 | H16: 342.4
A17: Ana Aslan | B17: 1 | C17: 24458 | D17: =($B$3-C17)/365 -> 56.660274 | E17: 1758.76 | F17: 439.69 | G17: 2198.45 | H17: 942.91 | I17: =SUM(H17:H18) -> 2000.48 | J17: =(I17-G17)/G17 -> -0.090049808 | K17: BlueChoice Advantage HSA BlueFund Silver Plan - $1,600 | L17: =IF($N$1*H17+$P$1*H18>=I17,I17,$N$1*H17+$P$1*H18) -> 1600.384 | M17: =I17-L17 -> 400.096 | N17: =(L17-E17)/E17 -> -0.090049808 | O17: =(M17-F17)/F17 -> -0.090049808 | P17: =M17/I17 -> 0.2
D18: 59 | H18: 1057.57
A19: Lesly Yohana Rubio | B19: 0 | C19: 31552 | D19: =($B$3-C19)/365 -> 37.224658 | E19: 412.42 | F19: 249.96 | G19: 662.38 | H19: 479.57 | I19: =H19 -> 479.57 | J19: =(I19-G19)/G19 -> -0.27598961 | K19: BlueChoice Advantage HSA BlueFund Silver Plan - $1,600 | L19: =IF($N$1*H19>=I19,I19,$N$1*H19) -> 383.656 | M19: =I19-L19 -> 95.914 | N19: =(L19-E19)/E19 -> -0.069744435 | O19: =(M19-F19)/F19 -> -0.61628261 | P19: =M19/I19 -> 0.2
A20: Carmen Pena | B20: 2 | C20: 31899 | D20: =($B$3-C20)/365 -> 36.273973 | E20: 1116.67 | F20: 676.78 | G20: 1793.45 | H20: 469.1 | I20: =SUM(H20:H22) -> 1291.07 | J20: =(I20-G20)/G20 -> -0.28011932 | K20: BlueChoice Advantage HSA BlueFund Silver Plan - $1,600 | L20: =IF($N$1*H20+$P$1*SUM(H21:H22)>=I20,I20,$N$1*H20+$P$1*SUM(H21:H22)) -> 1032.856 | M20: =I20-L20 -> 258.214 | N20: =(L20-E20)/E20 -> -0.075057089 | O20: =(M20-F20)/F20 -> -0.61846686 | P20: =M20/I20 -> 0.2
D21: 37 | H21: 479.57
D22: 5 | H22: 342.4
A23: Kelly M McNally | B23: 0 | C23: 34588 | D23: =($B$3-C23)/365 -> 28.906849 | E23: 334.63 | F23: 117.07 | G23: 451.7 | H23: 389.52 | I23: =H23 -> 389.52 | J23: =(I23-G23)/G23 -> -0.13765774 | K23: BlueChoice Advantage HSA BlueFund Silver Plan - $1,600 | L23: =IF($N$1*H23>=I23,I23,$N$1*H23) -> 311.616 | M23: =I23-L23 -> 77.904 | N23: =(L23-E23)/E23 -> -0.068774467 | O23: =(M23-F23)/F23 -> -0.33455198 | P23: =M23/I23 -> 0.2
A24: Susanna J Meyer | B24: 0 | C24: 33900 | D24: =($B$3-C24)/365 -> 30.791781 | E24: 349.82 | F24: 122.38 | G24: 472.2 | H24: 407.85 | I24: =H24 -> 407.85 | J24: =(I24-G24)/G24 -> -0.136277 | K24: BlueChoice Advantage HSA BlueFund Silver Plan - $1,600 | L24: =IF($N$1*H24>=I24,I24,$N$1*H24) -> 326.28 | M24: =I24-L24 -> 81.57 | N24: =(L24-E24)/E24 -> -0.06729175 | O24: =(M24-F24)/F24 -> -0.33346952 | P24: =M24/I24 -> 0.2
A25: Madeline Rae Steiner | B25: 0 | C25: 33765 | D25: =($B$3-C25)/365 -> 31.161644 | E25: 358.57 | F25: 125.44 | G25: 484.01 | H25: 418.32 | I25: =H25 -> 418.32 | J25: =(I25-G25)/G25 -> -0.13572034 | K25: BlueChoice Advantage HSA BlueFund Silver Plan - $1,600 | L25: =IF($N$1*H25>=I25,I25,$N$1*H25) -> 334.656 | M25: =I25-L25 -> 83.664 | N25: =(L25-E25)/E25 -> -0.066692696 | O25: =(M25-F25)/F25 -> -0.33303571 | P25: =M25/I25 -> 0.2
A26: Stephanie Monroy | B26: 0 | C26: 31116 | D26: =($B$3-C26)/365 -> 38.419178 | E26: 426.69 | F26: 149.27 | G26: 575.96 | H26: 485.33 | I26: =H26 -> 485.33 | J26: =(I26-G26)/G26 -> -0.15735468 | K26: BlueChoice Advantage HSA BlueFund Silver Plan - $1,600 | L26: =IF($N$1*H26>=I26,I26,$N$1*H26) -> 388.264 | M26: =I26-L26 -> 97.066 | N26: =(L26-E26)/E26 -> -0.090056013 | O26: =(M26-F26)/F26 -> -0.34972868 | P26: =M26/I26 -> 0.2
A27: Kirk Amper Del Rosario | B27: 0 | C27: 33886 | D27: =($B$3-C27)/365 -> 30.830137 | E27: 349.82 | F27: 75.87 | G27: 425.69 | H27: 407.85 | I27: =H27 -> 407.85 | J27: =(I27-G27)/G27 -> -0.041908431 | K27: BlueChoice Advantage HSA BlueFund Silver Plan - $1,600 | L27: =IF($N$1*H27>=I27,I27,$N$1*H27) -> 326.28 | M27: =I27-L27 -> 81.57 | N27: =(L27-E27)/E27 -> -0.06729175 | O27: =(M27-F27)/F27 -> 0.075128509 | P27: =M27/I27 -> 0.2
A28: Sara Jebena | B28: 0 | C28: 29996 | D28: =($B$3-C28)/365 -> 41.487671 | E28: 448.78 | F28: 97.34 | G28: 546.12 | H28: 530.36 | I28: =H28 -> 530.36 | J28: =(I28-G28)/G28 -> -0.028858126 | K28: BlueChoice Advantage HSA BlueFund Silver Plan - $1,600 | L28: =IF($N$1*H28>=I28,I28,$N$1*H28) -> 424.288 | M28: =I28-L28 -> 106.072 | N28: =(L28-E28)/E28 -> -0.054574625 | O28: =(M28-F28)/F28 -> 0.089706185 | P28: =M28/I28 -> 0.2
A29: Summar T Lyons | B29: 1 | C29: 31217 | D29: =($B$3-C29)/365 -> 38.142466 | E29: 887.89 | F29: 192.58 | G29: 1080.47 | H29: 485.33 | I29: =SUM(H29:H30) -> 1036.63 | J29: =(I29-G29)/G29 -> -0.040574935 | K29: BlueChoice Advantage HSA BlueFund Silver Plan - $1,600 | L29: =IF($N$1*H29+$P$1*H30>=I29,I29,$N$1*H29+$P$1*H30) -> 829.304 | M29: =I29-L29 -> 207.326 | N29: =(L29-E29)/E29 -> -0.065983399 | O29: =(M29-F29)/F29 -> 0.076570776 | P29: =M29/I29 -> 0.2
D30: 42 | H30: 551.3
A31: Armin Cordova | B31: 0 | C31: 35369 | D31: =($B$3-C31)/365 -> 26.767123 | E31: 324.42 | F31: 0 | G31: 324.42 | H31: 380.62 | I31: =H31 -> 380.62 | J31: =(I31-G31)/G31 -> 0.17323223 | K31: BlueChoice Advantage HSA BlueFund Silver Plan - $1,600 | L31: =IF($N$1*H31>=I31,I31,$N$1*H31) -> 304.496 | M31: =I31-L31 -> 76.124 | N31: =(L31-E31)/E31 -> -0.061414216 | O31: =(M31-F31)/F31 -> #DIV/0! | P31: =M31/I31 -> 0.2
A32: Megan Michelle Ash | B32: 0 | C32: 34295 | D32: =($B$3-C32)/365 -> 29.709589 | E32: 332 | F32: 0 | G32: 332 | H32: 397.9 | I32: =H32 -> 397.9 | J32: =(I32-G32)/G32 -> 0.19849398 | K32: BlueChoice Advantage HSA BlueFund Silver Plan - $1,600 | L32: =IF($N$1*H32>=I32,I32,$N$1*H32) -> 318.32 | M32: =I32-L32 -> 79.58 | N32: =(L32-E32)/E32 -> -0.041204819 | O32: =(M32-F32)/F32 -> #DIV/0! | P32: =M32/I32 -> 0.2
A33: Stephanie Verganza | B33: 0 | C33: 33576 | D33: =($B$3-C33)/365 -> 31.679452 | E33: 347.62 | F33: 0 | G33: 347.62 | H33: 418.32 | I33: =H33 -> 418.32 | J33: =(I33-G33)/G33 -> 0.203383 | K33: BlueChoice Advantage HSA BlueFund Silver Plan - $1,600 | L33: =IF($N$1*H33>=I33,I33,$N$1*H33) -> 334.656 | M33: =I33-L33 -> 83.664 | N33: =(L33-E33)/E33 -> -0.037293596 | O33: =(M33-F33)/F33 -> #DIV/0! | P33: =M33/I33 -> 0.2
A34: Anh H Nguyen | B34: 1 | C34: 33338 | D34: =($B$3-C34)/365 -> 32.331507 | E34: 680.97 | F34: 0 | G34: 680.97 | H34: 427.74 | I34: =SUM(H34:H35) -> 817.26 | J34: =(I34-G34)/G34 -> 0.20014098 | K34: BlueChoice Advantage HSA BlueFund Silver Plan - $1,600 | L34: =IF($N$1*H34+$P$1*H35>=I34,I34,$N$1*H34+$P$1*H35) -> 653.808 | M34: =I34-L34 -> 163.452 | N34: =(L34-E34)/E34 -> -0.03988722 | O34: =(M34-F34)/F34 -> #DIV/0! | P34: =M34/I34 -> 0.2
D35: 28 | H35: 389.52
A36: Janira J Romero Reyes | B36: 1 | C36: 31561 | D36: =($B$3-C36)/365 -> 37.2 | E36: 691.67 | F36: 0 | G36: 691.67 | H36: 479.57 | I36: =SUM(H36:H37) -> 821.97 | J36: =(I36-G36)/G36 -> 0.18838463 | K36: BlueChoice Advantage HSA BlueFund Silver Plan - $1,600 | L36: =IF($N$1*H36+$P$1*H37>=I36,I36,$N$1*H36+$P$1*H37) -> 657.576 | M36: =I36-L36 -> 164.394 | N36: =(L36-E36)/E36 -> -0.049292293 | O36: =(M36-F36)/F36 -> #DIV/0! | P36: =M36/I36 -> 0.2
D37: 0 | H37: 342.4
A38: Danielle R Martin | B38: 1 | C38: 33497 | D38: =($B$3-C38)/365 -> 31.89589 | E38: 695.24 | F38: 0 | G38: 695.24 | H38: 418.32 | I38: =SUM(H38:H39) -> 836.64 | J38: =(I38-G38)/G38 -> 0.203383 | K38: BlueChoice Advantage HSA BlueFund Silver Plan - $1,600 | L38: =IF($N$1*H38+$P$1*H39>=I38,I38,$N$1*H38+$P$1*H39) -> 669.312 | M38: =I38-L38 -> 167.328 | N38: =(L38-E38)/E38 -> -0.037293596 | O38: =(M38-F38)/F38 -> #DIV/0! | P38: =M38/I38 -> 0.2
D39: 31 | H39: 418.32
A40: William D Webber | B40: 1 | C40: 34122 | D40: =($B$3-C40)/365 -> 30.183562 | E40: 738.97 | F40: 0 | G40: 738.97 | H40: 407.85 | I40: =SUM(H40:H41) -> 887.42 | J40: =(I40-G40)/G40 -> 0.20088772 | K40: BlueChoice Advantage HSA BlueFund Silver Plan - $1,600 | L40: =IF($N$1*H40+$P$1*H41>=I40,I40,$N$1*H40+$P$1*H41) -> 709.936 | M40: =I40-L40 -> 177.484 | N40: =(L40-E40)/E40 -> -0.039289822 | O40: =(M40-F40)/F40 -> #DIV/0! | P40: =M40/I40 -> 0.2
...
