Workbook
Name \a: #REF!
Name \c: #REF!
Name \i: #REF!
Name \P: #REF!
Name \r: #REF!
Name __pd1: #REF!
Name __pd6: #REF!
Name __tix1: #REF!
Name __tix2: #REF!
Name __tix6: #REF!
Name _1: #REF!
Name _1998: #REF!
Name _1999: #REF!
Name _2: #REF!
Name _2000: #REF!
Name _2001: #REF!
Name _2002: #REF!
Name _3: #REF!
Name _4: #REF!
Name _5: #REF!
Name _6: #REF!
Name _7: #REF!
Name _8: #REF!
Name _fmi1: #REF!
Name _fmi2: #REF!
Name _fmi3: #REF!
Name _fmi4: #REF!
Name _PIB01: #REF!
Name _PIB02: #REF!
Name _PIB95: #REF!
Name _PIB96: #REF!
Name _PIB97: #REF!
Name _PIB98: #REF!
Name _PIB99: #REF!
Name _RES9397: #REF!
Name _rez2: #REF!
Name _rez3: #REF!
Name _rez4: #REF!
Name a: #REF!
Name A_2002: #REF!
Name A_CAPITAL: #REF!
Name A_DEPTOS: #REF!
Name A_impresión_IM: #REF!
Name A_MUNPIOS: #REF!
Name AAA: #REF!
Name AEFormar: #REF!
Name Ajustado: #REF!
Name almuerzo: #REF!
Name alquilertableta: #REF!
Name ANEXO_No.: #REF!
Name ANEXO_No._5: #REF!
Name ANPDH: #REF!
Name aprnac: #REF!
Name APROPIACIONES_PAC_Y_REZAGO_1999___2000: #REF!
Name aprprp: #REF!
Name asigbas: #REF!
Name asigbasempu: #REF!
Name asigbasisten: #REF!
Name asigmen: #REF!
Name auxalm: #REF!

Sheet OrigBudget Summary ProAntioquia
B1: Name of Subawardee: ProAntioquia
B2: USAID RFA No. 7200AA21RFA00001
A4: Line Items | B4: Year 1 | E4: Year 2 | H4: Year 3 | K4: Year 4 | N4: Year 5 | Q4: Total | R4: Total | S4: Grand
B5: USAID | C5: Leverage | D5: Total | E5: USAID | F5: Leverage | G5: Total | H5: USAID | I5: Leverage | J5: Total | K5: USAID | L5: Leverage | M5: Total | N5: USAID | O5: Leverage | P5: Total | Q5: USAID | R5: Leverage | S5: Total
A7: Personnel | B7: 146525 | C7: 29706.9 | D7: =SUM(B7:C7) -> 176231.9 | E7: 180648 | F7: 33006.272 | G7: =SUM(E7:F7) -> 213654.27 | H7: 187873.92 | I7: 34326.523 | J7: =SUM(H7:I7) -> 222200.44 | K7: 195388.88 | L7: 35699.584 | M7: =SUM(K7:L7) -> 231088.46 | N7: 175186.32 | O7: 35922.73 | P7: =SUM(N7:O7) -> 211109.05 | Q7: 885622.12 | R7: 168662.01 | S7: 1054284.1
A9: Fringe Benefits | B9: 68799.226 | C9: 13520.295 | D9: 82319.521 | E9: 84668.239 | F9: 15057.827 | G9: 99726.066 | H9: 88054.968 | I9: 15660.14 | J9: 103715.11 | K9: 91577.167 | L9: 16286.546 | M9: 107863.71 | N9: 83109.782 | O9: 16289.034 | P9: 99398.816 | Q9: 416209.38 | R9: 76813.842 | S9: 493023.22
A11: Travel | B11: 18570 | C11: 0 | D11: 18570 | E11: 19700.7 | F11: 0 | G11: 19700.7 | H11: 21801.801 | I11: 0 | J11: 21801.801 | K11: 21847.131 | L11: 0 | M11: 21847.131 | N11: 21546.523 | O11: 0 | P11: 21546.523 | Q11: 103466.15 | R11: 0 | S11: 103466.15
A13: Equipment | B13: 50000 | C13: 0 | D13: 50000 | E13: 0 | F13: 0 | G13: 0 | H13: 0 | I13: 0 | J13: 0 | K13: 0 | L13: 0 | M13: 0 | N13: 0 | O13: 0 | P13: 0 | Q13: 50000 | R13: 0 | S13: 50000
A15: Supplies | B15: 15344.91 | C15: 3336 | D15: 18680.91 | E15: 9270 | F15: 4466.904 | G15: 13736.904 | H15: 9548.1 | I15: 4600.9111 | J15: 14149.011 | K15: 4917.2715 | L15: 4738.9385 | M15: 9656.21 | N15: 3798.5922 | O15: 4881.1066 | P15: 8679.6988 | Q15: 42878.874 | R15: 22023.86 | S15: 64902.734
A17: Contractual | B17: 42850 | C17: 0 | D17: 42850 | E17: 47050 | F17: 0 | G17: 47050 | H17: 22050 | I17: 0 | J17: 22050 | K17: 22050 | L17: 0 | M17: 22050 | N17: 19950 | O17: 0 | P17: 19950 | Q17: 153950 | R17: 0 | S17: 153950
A19: Other Direct Costs | B19: 105566 | C19: 33306 | D19: 138872 | E19: 176388.48 | F19: 0 | G19: 176388.48 | H19: 85222.354 | I19: 0 | J19: 85222.354 | K19: 94155.779 | L19: 0 | M19: 94155.779 | N19: 20519.592 | O19: 0 | P19: 20519.592 | Q19: 481852.2 | R19: 33306 | S19: 515158.2
A21: Total Direct Costs | B21: =SUM(B7:B20) -> 447655.14 | C21: =SUM(C7:C20) -> 79869.195 | D21: =SUM(D7:D20) -> 527524.33 | E21: =SUM(E7:E20) -> 517725.42 | F21: =SUM(F7:F20) -> 52531.003 | G21: =SUM(G7:G20) -> 570256.42 | H21: =SUM(H7:H20) -> 414551.14 | I21: =SUM(I7:I20) -> 54587.574 | ... S21: =SUM(S7:S20) -> 2434784.4
A22: Indirect Costs | B22: 0 | C22: 0 | D22: 0 | E22: 0 | F22: 0 | G22: 0 | H22: 0 | I22: 0 | J22: 0 | K22: 0 | L22: 0 | M22: 0 | N22: 0 | O22: 0 | P22: 0 | Q22: 0 | R22: 0 | S22: 0
A23: Total | B23: =B22+B21 -> 447655.14 | C23: =C22+C21 -> 79869.195 | D23: =D22+D21 -> 527524.33 | E23: =E22+E21 -> 517725.42 | F23: =F22+F21 -> 52531.003 | G23: =G22+G21 -> 570256.42 | H23: =H22+H21 -> 414551.14 | I23: =I22+I21 -> 54587.574 | ... S23: =S22+S21 -> 2434784.4

Sheet Budget ProAntioquia
J1: USAID Juntos Aprendemos
J2: ProAntioquia
J3: Subaward Budget
J4: Country: Colombia
F5: Budget Assumptions
F6: Inflation - Locally Purchased Goods/Services - 6% | J6: 1.03
F7: Merit Based Increases for HQ & Field Staff - 4% | J7: 1.04
F8: *Key Personnel | J8: Original Budget | AR8: Actuals/Estimates Year 1 and 2 | BB8: Projections for Year 3 -5 | CE8: New Proposed Budget Total | CH8: DEFICIT/SURPLUS | CK8: SALDO | CL8: BALANCE | CM8: 4 | CN8: 5 | CO8: 7 | CP8: 10 | CQ8: 14 | CR8: 15 | CS8: 16 | CT8: 27 USAID | CU8: 27 LEVERAGE | CV8: 37 | CW8: 38 | CX8: 39 | CY8: 40 | CZ8: 45 | DA8: 46 | DB8: 47 | DC8: 49 | DD8: 51 | DE8: 52 | DF8: 53 | DG8: 54 | DH8: 56 | DI8: 57 | DJ8: 58 | DK8: 59 | DL8: 61 | DM8: 62 | DN8: 63 | DO8: 64 | DP8: 66 | DQ8: 67 | DR8: 68 | DS8: 69 | DT8: 73 | DU8: 85 | DV8: 90 | DW8: 91 | DX8: 92 | DY8: 97 | DZ8: 102 | EA8: 103 | EB8: 104 | EC8: 110 | ED8: 111 | EE8: 112 | EF8: 113 | EG8: 115 | EH8: 116 | EI8: 117 | EJ8: 120 | EK8: 122 | EL8: 123 | EM8: 124 | EN8: 129 | EO8: 131 | EP8: 132 | EQ8: 134 | ER8: 135 | ES8: 137
A9: Sage Activity | B9: Account Code | C9: Country Code | D9: Sub Activity | F9: Line Items | J9: Year 1 | Q9: Year 2 | W9: Year 3 | AC9: Year 4 | AI9: Year 5 | AO9: Total | AP9: Total | AQ9: Grand | AR9: Year 1 | AT9: Year 2 | AV9: Total | BB9: Year 3 | BI9: Year 4 | BO9: Year 5 | BU9: Year 6 | CA9: Year 3- 6 | CB9: Year 3- 6 | CC9: Year 3- 6 | CE9: Total | CF9: Total | CG9: Grand | CM9: BUDGET REALIGNEMENT
E10: LINE NUMBER | F10: Line Items | G10: SECTION | H10: SUB-SCTION | I10: SOURCE | J10: Unit | K10: Cost | L10: Duration | M10: Type | N10: USAID | O10: Leverage | P10: Total | Q10: Unit | R10: Cost | S10: Duration | T10: USAID | U10: Leverage | V10: Total | W10: Unit | X10: Cost | Y10: Duration | Z10: USAID | AA10: Leverage | AB10: Total | AC10: Unit | AD10: Cost | AE10: Duration | AF10: USAID | AG10: Leverage | AH10: Total | AI10: Unit | AJ10: Cost | AK10: Duration | AL10: USAID | AM10: Leverage | AN10: Total | AO10: USAID | AP10: Leverage | AQ10: Total | AR10: USAID Year 1 -Actuals August 16, 2021 - December 31, 2021 | AS10: Leverage Year 1 -Actuals August 16, 2021 - December 31, 2021 | AT10: USAID Year 2 -Actuals/Estimate January 1, 2022 - December 31, 2022 | AU10: Leverage Year 2 -Actuals/Estimate January 1, 2022 - December 31, 2022 | AV10: USAID EXECUTED | AW10: LEVERAGE EXECUTED | AX10: TOTAL EXECUTED | AY10: Balance remaining | AZ10: Balance Remaining | BA10: Control | BB10: Unit | BC10: Cost | BD10: Duration | BE10: USAID | BF10: Leverage | BG10: Total | BH10: NOTAS | BI10: Unit | BJ10: Cost | BK10: Duration | BL10: USAID | BM10: Leverage | BN10: Total | BO10: Unit | BP10: Cost | BQ10: Duration | BR10: USAID | BS10: Leverage | BT10: Total | BU10: Unit | BV10: Cost | BW10: Duration | BX10: USAID | BY10: Leverage | BZ10: Total | CA10: Total USAID | CB10: Total Leverage | CC10: Grand Total | CE10: USAID | CF10: Leverage | CG10: Total | CH10: USAID DEFICIT/SURPLUS | CI10: LEVERAGE DEFICIT/SURPLUS | CJ10: TOTAL DEFICIT/SURPLUS | CM10: Partnerships and Alliances Director* | CN10: Partnerships and Alliances Coordinator | CO10: Education Director (HQ-ProAntioquia) | CP10: Teacher Training Specialist (2) | CQ10: Visual Documentation Communications Professional | CR10: Content Development Professional | CS10: Finance & Admin Coordinator Project Analyst | CT10: Fringe Benefits – Colombia HQ and Field Staff (above $2,600 monthly) | CU10: Fringe Benefits – Colombia HQ and Field Staff (above $2,600 monthly) | CV10: Local Transportation (Airfare, Taxis, & Rental Car/Driver) for Directors | CW10: Meals and Incidentals for Directors | CX10: Lodging for Directors | CY10: Other Travel Related Expenses for Directors | CZ10: Meals and Incidentals for Site Visits and M&E | DA10: Lodging for Site Visits and M&E | DB10: Other Travel Related Expenses for Site Visits and M&E | DC10: Vehicle Fuel Expense | DD10: Local Transportation for Advisory Board Meetings | DE10: Meals and Incidentals for Advisory Board Meetings | DF10: Lodging for Advisory Board Meetings | DG10: Other Travel Related Expenses for Advisory Board Meetings | DH10: Local Transportation for Annual Forums | DI10: Meals and Incidentals for Annual Forums | DJ10: Lodging for Annual Forums | DK10: Other Travel Related Expenses for Annual Forums | DL10: Local Transportation for SMT Meetings | DM10: Meals and Incidentals for SMT Meetings | DN10: Lodging for SMT Meetings | DO10: Other Travel Related Expenses for SMT Meetings | DP10: Local Transportation for Steering Committee Meeting | DQ10: Meals and Incidentals for Steering Committee Meeting | DR10: Lodging for Steering Committee Meeting | DS10: Other Travel Related Expenses for Steering Committee Meeting | DT10: Vehicle for Field Office | DU10: Personal Protective Equipment (Gloves, Masks, Hand Sanitizer, Antibacterial Wipes etc.) | DV10: Consultant for data analysis to build public policy guidelines | DW10: Consultant for technical advice for advocacy on public policy | DX10: Entrena-QL methodology for development of educational materials | DY10: Local Office Security Contractor (Local Hire) | DZ10: Prototypes and pilots of educational materials | EA10: Adaptation of existing content and methodologies for educational materials | EB10: Content for school campaigns | EC10: Translation costs | ED10: Courier fees/services/postage | EE10: Banking and cash handling fees | EF10: Vehicle Insurance & Maintenance | EG10: Development of teacher training books for Replica Workshops | EH10: Graphic and operational design of digital courses | EI10: Graphic design for teachers training materials | EJ10: Transport of books for children | EK10: Process systematization book | EL10: Videos for teacher training | EM10: Books for children (Collection of NEXO literary) | EN10: Printing of informational materials | EO10: Round table with local private sector to build public policy guidelines | EP10: Regional workshops about strategic themes of public policy guidelines | EQ10: M&E Database Platform Access | ER10: Data Collection Tools | ES10: On-going Training Workshops for Data Collection Staff
E11: 1 | F11: PERSONNEL | CL11: =SUM(CM12:ES152) -> 0
E12: 2 | F12: Headquarters Personnel | J12: LOE | CK12: =SUM(CM12:ES12) -> 0 | CL12: =CJ12+CK12 -> 0
E13: 3 | F13: Project Office (Bogota) | CK13: =SUM(CM13:ES13) -> 0 | CL13: =CJ13+CK13 -> 0
A14: SUBPROANT | B14: 89050 | C14: COL2 | D14: PAPERSNL | E14: 4 | F14: Partnerships and Alliances Director* | G14: PERSONNEL | H14: Project Office (Bogota) | I14: USAID | J14: 1 | K14: =52500/12 -> 4375 | L14: 11 | M14: /months | N14: =L14*K14*J14 -> 48125 | O14: 0 | P14: =SUM(N14:O14) -> 48125 | Q14: =J14 -> 1 | R14: =K14*$J$7 -> 4550 | S14: 12 | T14: =Q14*R14*S14 -> 54600 | U14: 0 | V14: =SUM(T14:U14) -> 54600 | W14: =J14 -> 1 | X14: =+K14*$J$7*$J$7 -> 4732 | Y14: 12 | Z14: =W14*X14*Y14 -> 56784 | AA14: 0 | AB14: =SUM(Z14:AA14) -> 56784 | AC14: =W14 -> 1 | AD14: =+K14*$J$7*$J$7*$J$7 -> 4921.28 | AE14: 12 | AF14: =AC14*AD14*AE14 -> 59055.36 | AG14: 0 | AH14: =SUM(AF14:AG14) -> 59055.36 | AI14: =AC14 -> 1 | AJ14: =+K14*$J$7*$J$7*$J$7*$J$7 -> 5118.1312 | AK14: 12 | AL14: =AI14*AJ14*AK14 -> 61417.574 | AM14: 0 | AN14: =SUM(AL14:AM14) -> 61417.574 | AO14: =N14+T14+Z14+AF14+AL14 -> 279981.93 | AP14: =O14+U14+AA14+AG14+AM14 -> 0 | AQ14: =SUM(AO14:AP14) -> 279981.93 | AR14: 0 | AS14: 0 | AT14: =3252.77+3817.03+3948.19+3962.6+3739.26+3813.47+3433.22+3475.34+3384.44+3177.56+3047.83+3137.35 -> 42189.06 | AU14: 0 | AV14: =AR14+AT14 -> 42189.06 | AW14: =AS14+AU14 -> 0 | AX14: =AV14+AW14 -> 42189.06 | AY14: =AQ14-AX14 -> 237792.87 | AZ14: =AQ14-AR14-AS14-AT14-AU14 -> 237792.87 | BA14: =AY14-AZ14 -> 0 | BB14: 1 | BC14: 2923.08 | BD14: 7.9483 | BE14: =BB14*BC14*BD14 -> 23233.517 | BF14: =AA14 -> 0 | BG14: =SUM(BE14:BF14) -> 23233.517 | BH14: Key Personnel responsable de liderar la implementación de procesos y actividades de formalización de Alianzas. Se contrata la nueva persona en este rol el 8 de mayo de 2023 por el tiempo del proyecto. | BI14: 1 | BJ14: =BC14*1.04 -> 3040.0032 | BK14: 12 | BL14: =BI14*BJ14*BK14 -> 36480.038 | BM14: 0 | BN14: =SUM(BL14:BM14) -> 36480.038 | BO14: 1 | BP14: =BJ14*1.04 -> 3161.6033 | BQ14: 12 | BR14: =BO14*BP14*BQ14 -> 37939.24 | BS14: 0 | BT14: =SUM(BR14:BS14) -> 37939.24 | BU14: 1 | BV14: =BP14*1.04 -> 3288.0675 | BW14: 6 | BX14: =BW14*BV14 -> 19728.405 | BY14: 0 | BZ14: =BY14+BX14 -> 19728.405 | CA14: =BR14+BL14+BE14+BX14 -> 117381.2 | CB14: =BY14+BS14+BM14+BF14 -> 0 | CC14: =CA14+CB14 -> 117381.2 | CE14: =AV14+CA14 -> 159570.26 | CF14: =AW14+CB14 -> 0 | CG14: =CE14+CF14 -> 159570.26 | CH14: =AO14-CE14 -> 120411.67 | CI14: =AP14-CF14 -> 0 | CJ14: =AQ14-CG14 -> 120411.67 | CK14: =SUM(CM14:ES14) -> -120412 | CL14: =CJ14+CK14 -> -0.32546672 | CM14: -120412
A15: SUBPROANT | B15: 89050 | C15: COL2 | D15: PAPERSNL | E15: 5 | F15: Partnerships and Alliances Coordinator | G15: PERSONNEL | H15: Project Office (Bogota) | I15: USAID | J15: 1 | K15: =22500/12 -> 1875 | L15: 9 | M15: /months | N15: =L15*K15*J15 -> 16875 | O15: 0 | P15: =SUM(N15:O15) -> 16875 | Q15: =J15 -> 1 | R15: =K15*$J$7 -> 1950 | S15: 12 | T15: =Q15*R15*S15 -> 23400 | U15: 0 | V15: =SUM(T15:U15) -> 23400 | W15: =J15 -> 1 | X15: =+K15*$J$7*$J$7 -> 2028 | Y15: 12 | Z15: =W15*X15*Y15 -> 24336 | AA15: 0 | AB15: =SUM(Z15:AA15) -> 24336 | AC15: =W15 -> 1 | AD15: =+K15*$J$7*$J$7*$J$7 -> 2109.12 | AE15: 12 | AF15: =AC15*AD15*AE15 -> 25309.44 | AG15: 0 | AH15: =SUM(AF15:AG15) -> 25309.44 | AI15: =AC15 -> 1 | AJ15: =+K15*$J$7*$J$7*$J$7*$J$7 -> 2193.4848 | AK15: 10 | AL15: =AI15*AJ15*AK15 -> 21934.848 | AM15: 0 | AN15: =SUM(AL15:AM15) -> 21934.848 | AO15: =N15+T15+Z15+AF15+AL15 -> 111855.29 | AP15: =O15+U15+AA15+AG15+AM15 -> 0 | AQ15: =SUM(AO15:AP15) -> 111855.29 | AR15: 0 | AS15: 0 | AT15: =1144.41+1737.67+1692.22+1588.78+1523.92+1568.68 -> 9255.68 | AU15: 0 | AV15: =AR15+AT15 -> 9255.68 | AW15: =AS15+AU15 -> 0 | AX15: =AV15+AW15 -> 9255.68 | AY15: =AQ15-AX15 -> 102599.61 | AZ15: =AQ15-AR15-AS15-AT15-AU15 -> 102599.61 | BA15: =AY15-AZ15 -> 0 | BB15: 1 | BC15: 1861.4 | BD15: 12 | BE15: =BC15*BD15 -> 22336.8 | BF15: =AA15 -> 0 | BG15: =SUM(BE15:BF15) -> 22336.8 | BH15: Responsable de coordinar la implementación de procesos y actividades de formalización de alianzas en el marco del programa Juntos Aprendemos . | BI15: 1 | BJ15: =BC15*1.04 -> 1935.856 | BK15: 12 | BL15: =BK15*BJ15*BI15 -> 23230.272 | BM15: 0 | BN15: =SUM(BL15:BM15) -> 23230.272 | BO15: 1 | BP15: =BJ15*1.04 -> 2013.2902 | BQ15: 10 | BR15: =BQ15*BP15*BO15 -> 20132.902 | BS15: 0 | BT15: =SUM(BR15:BS15) -> 20132.902 | BU15: 0 | BV15: 0 | BW15: 0 | BX15: =BW15*BV15 -> 0 | BY15: 0 | BZ15: =BY15+BX15 -> 0 | CA15: =BR15+BL15+BE15+BX15 -> 65699.974 | CB15: =BY15+BS15+BM15+BF15 -> 0 | CC15: =CA15+CB15 -> 65699.974 | CE15: =AV15+CA15 -> 74955.654 | CF15: =AW15+CB15 -> 0 | CG15: =CE15+CF15 -> 74955.654 | CH15: =AO15-CE15 -> 36899.634 | CI15: =AP15-CF15 -> 0 | CJ15: =AQ15-CG15 -> 36899.634 | CK15: =SUM(CM15:ES15) -> -36900 | CL15: =CJ15+CK15 -> -0.3664 | CN15: -36900
E16: 6 | F16: ProAntioquia Office | CG16: =CE16+CF16 -> 0 | CJ16: =AQ16-CG16 -> 0 | CK16: =SUM(CM16:ES16) -> 0 | CL16: =CJ16+CK16 -> 0
E17: 7 | F17: Education Director (HQ-ProAntioquia) | G17: PERSONNEL | H17: ProAntioquia Office | I17: LEVERAGE | J17: 0.3 | K17: 3433 | L17: 11 | M17: /months | N17: 0 | O17: =+J17*K17*L17 -> 11328.9 | P17: =SUM(N17:O17) -> 11328.9 | Q17: =J17 -> 0.3 | R17: =K17*$J$7 -> 3570.32 | S17: 12 | T17: 0 | U17: =+Q17*R17*S17 -> 12853.152 | V17: =SUM(T17:U17) -> 12853.152 | W17: =J17 -> 0.3 | X17: =+K17*$J$7*$J$7 -> 3713.1328 | Y17: 12 | Z17: 0 | AA17: =+W17*X17*Y17 -> 13367.278 | AB17: =SUM(Z17:AA17) -> 13367.278 | AC17: =W17 -> 0.3 | AD17: =+K17*$J$7*$J$7*$J$7 -> 3861.6581 | AE17: 12 | AF17: 0 | AG17: =+AC17*AD17*AE17 -> 13901.969 | AH17: =SUM(AF17:AG17) -> 13901.969 | AI17: =AC17 -> 0.3 | AJ17: =+K17*$J$7*$J$7*$J$7*$J$7 -> 4016.1244 | AK17: 11 | AL17: 0 | AM17: =+AI17*AJ17*AK17 -> 13253.211 | AN17: =SUM(AL17:AM17) -> 13253.211 | AO17: =N17+T17+Z17+AF17+AL17 -> 0 | AP17: =O17+U17+AA17+AG17+AM17 -> 64704.51 | AQ17: =SUM(AO17:AP17) -> 64704.51 | AR17: 0 | AS17: 0 | AT17: 0 | AU17: =464.15+480.1+481.85+454.69+463.72 -> 2344.51 | AV17: =AR17+AT17 -> 0 | AW17: =AS17+AU17 -> 2344.51 | AX17: =AV17+AW17 -> 2344.51 | AY17: =AQ17-AX17 -> 62360 | AZ17: =AQ17-AR17-AS17-AT17-AU17 -> 62360 | BA17: =AY17-AZ17 -> 0 | BB17: 0.2 | BC17: 13367 | BE17: =BB17*BC17*BD17 -> 0 | BF17: =BC17 -> 13367 | BG17: =SUM(BE17:BF17) -> 13367 | BH17: Tiempos de dedicación al programa de la dirección del area de Educación de la fundación Proantioquia. (Leverage). | BI17: 0 | BJ17: 0 | BK17: 0 | BL17: =BK17*BJ17*BI17 -> 0 | BM17: =13901.9692032 -> 13901.969 | BN17: =SUM(BL17:BM17) -> 13901.969 | BO17: 0 | BP17: 0 | BQ17: 0 | BR17: =BQ17*BP17*BO17 -> 0 | BS17: =13253.210640384 -> 13253.211 | BT17: =SUM(BR17:BS17) -> 13253.211 | BU17: 0 | BV17: 0 | BW17: 0 | BX17: 0 | BY17: =(BS17/12)*2 -> 2208.8684 | BZ17: =BY17+BX17 -> 2208.8684 | CA17: =BR17+BL17+BE17+BX17 -> 0 | CB17: =BY17+BS17+BM17+BF17 -> 42731.048 | CC17: =CA17+CB17 -> 42731.048 | CE17: =AV17+CA17 -> 0 | CF17: =AW17+CB17 -> 45075.558 | CG17: =CE17+CF17 -> 45075.558 | CH17: =AO17-CE17 -> 0 | CI17: =AP17-CF17 -> 19628.952 | CJ17: =AQ17-CG17 -> 19628.952 | CK17: =SUM(CM17:ES17) -> -19629 | CL17: =CJ17+CK17 -> -0.048360064 | CO17: -19629
E18: 8 | F18: Subtotal HQ Personnel | N18: =SUM(N14:N17) -> 65000 | O18: =SUM(O14:O17) -> 11328.9 | P18: =SUM(P14:P17) -> 76328.9 | T18: =SUM(T14:T17) -> 78000 | U18: =SUM(U14:U17) -> 12853.152 | V18: =SUM(V14:V17) -> 90853.152 | Z18: =SUM(Z14:Z17) -> 81120 | AA18: =SUM(AA14:AA17) -> 13367.278 | AB18: =SUM(AB14:AB17) -> 94487.278 | AD18: =+K18*$J$7*$J$7*$J$7 -> 0 | AF18: =SUM(AF14:AF17) -> 84364.8 | AG18: =SUM(AG14:AG17) -> 13901.969 | AH18: =SUM(AH14:AH17) -> 98266.769 | AL18: =SUM(AL14:AL17) -> 83352.422 | AM18: =SUM(AM14:AM17) -> 13253.211 | AN18: =SUM(AN14:AN17) -> 96605.633 | AO18: =SUM(AO14:AO17) -> 391837.22 | AP18: =SUM(AP14:AP17) -> 64704.51 | AQ18: =SUM(AQ14:AQ17) -> 456541.73 | AR18: =SUM(AR14:AR17) -> 0 | AS18: =SUM(AS14:AS17) -> 0 | AT18: =SUM(AT14:AT17) -> 51444.74 | AU18: =AU17+AU15+AU14 -> 2344.51 | AZ18: =AQ18-AR18-AS18-AT18-AU18 -> 402752.48 | BC18: =BC14+BC15+BC17 -> 18151.48 | BE18: =BE14+BE15 -> 45570.317 | BF18: =BF17 -> 13367 | BG18: =SUM(BE18:BF18) -> 58937.317 | BJ18: =BJ14+BJ15 -> 4975.8592 | BL18: =BL14+BL15 -> 59710.31 | BM18: =BM17 -> 13901.969 | BN18: =SUM(BL18:BM18) -> 73612.28 | BP18: =BP14+BP15 -> 5174.8936 | BR18: =BR14+BR15 -> 58072.142 | BS18: =BS17 -> 13253.211 | BT18: =SUM(BR18:BS18) -> 71325.353 | BV18: =SUM(BV14:BV15) -> 3288.0675 | BX18: =SUM(BX14:BX15) -> 19728.405 | BY18: =BY17 -> 2208.8684 | BZ18: =BY18+BX18 -> 21937.273 | CA18: =SUM(CA14:CA17) -> 183081.17 | CB18: =SUM(CB14:CB17) -> 42731.048 | CC18: =SUM(CC14:CC17) -> 225812.22 | CE18: =SUM(CE14:CE17) -> 234525.91 | CF18: =SUM(CF14:CF17) -> 45075.558 | CG18: =SUM(CG14:CG17) -> 279601.47 | CK18: =SUM(CM18:ES18) -> 0 | CL18: =CJ18+CK18 -> 0
E19: 9 | F19: Field Personnel | J19: LOE | AD19: =+K19*$J$7*$J$7*$J$7 -> 0 | CK19: =SUM(CM19:ES19) -> 0 | CL19: =CJ19+CK19 -> 0
A20: SUBPROANT | B20: 89050 | C20: COL2 | D20: PAPERSNL | E20: 10 | F20: Teacher Training Specialist (2) | G20: PERSONNEL | H20: Field Personnel | I20: USAID | J20: 1 | K20: =31200/12 -> 2600 | L20: 9 | M20: /months | N20: =L20*K20*J20 -> 23400 | O20: 0 | P20: =SUM(N20:O20) -> 23400 | Q20: =J20 -> 1 | R20: =K20*$J$7 -> 2704 | S20: 12 | T20: =Q20*R20*S20 -> 32448 | U20: 0 | V20: =SUM(T20:U20) -> 32448 | W20: =Q20 -> 1 | X20: =+K20*$J$7*$J$7 -> 2812.16 | Y20: 12 | Z20: =W20*X20*Y20 -> 33745.92 | AA20: 0 | AB20: =SUM(Z20:AA20) -> 33745.92 | AC20: =W20 -> 1 | AD20: =+K20*$J$7*$J$7*$J$7 -> 2924.6464 | AE20: 12 | AF20: =AC20*AD20*AE20 -> 35095.757 | AG20: 0 | AH20: =SUM(AF20:AG20) -> 35095.757 | AI20: =AC20 -> 1 | AJ20: =+K20*$J$7*$J$7*$J$7*$J$7 -> 3041.6323 | AK20: 10 | AL20: =AI20*AJ20*AK20 -> 30416.323 | AM20: 0 | AN20: =SUM(AL20:AM20) -> 30416.323 | AO20: =N20+T20+Z20+AF20+AL20 -> 155106 | AP20: =O20+U20+AA20+AG20+AM20 -> 0 | AQ20: =SUM(AO20:AP20) -> 155106 | AR20: 8888 | AS20: 0 | AT20: =(1074.78+1289.74)+970.84+916.12+622.87+(841.14+1121.52)+(567.64+851.46)+(1105.58+829.19)+(1038+778.5)+(995.63+746.72)+(1024.87+281.84)+24822 -> 39878.44 | AU20: 0 | AV20: =AR20+AT20 -> 48766.44 | AW20: =AS20+AU20 -> 0 | AX20: =AV20+AW20 -> 48766.44 | AY20: =AQ20-AX20 -> 106339.56 | AZ20: =AQ20-AR20-AS20-AT20-AU20 -> 106339.56 | BA20: =AY20-AZ20 -> 0 | BB20: 1 | BC20: 2433.44 | BD20: 11.7625 | BE20: =BC20*BD20*BB20 -> 28623.338 | BF20: =AA20 -> 0 | BG20: =SUM(BE20:BF20) -> 28623.338 | BH20: Especialistas responsables de acompañar los procesos de diseño, ejecución y evaluación de programas educativos desde la creación de escenarios que favorezcan la consolidación de prácticas de mediación de maestros/ambientes de aprendizaje incluyentes o con enfoque GESI. Son 2 personas, cargadas al 100%. | BI20: 1 | BJ20: =2347.92*1.04 -> 2441.8368 | BK20: 12 | BL20: =BI20*BJ20*BK20 -> 29302.042 | BM20: 0 | BN20: =SUM(BL20:BM20) -> 29302.042 | BO20: 1 | BP20: =BJ20*1.04 -> 2539.5103 | BQ20: 10 | BR20: =BQ20*BP20*BO20 -> 25395.103 | BS20: 0 | BT20: =SUM(BR20:BS20) -> 25395.103 | BU20: 1 | BV20: =BP20*1.04 -> 2641.0907 | BW20: 6 | BX20: =BW20*BV20 -> 15846.544 | BY20: 0 | BZ20: =BY20+BX20 -> 15846.544 | CA20: =BR20+BL20+BE20+BX20 -> 99167.026 | CB20: =+BY20+BS20+BM20+BF20 -> 0 | CC20: =CA20+CB20 -> 99167.026 | CE20: =AV20+CA20 -> 147933.47 | CF20: =AW20+CB20 -> 0 | CG20: =CE20+CF20 -> 147933.47 | CH20: =AO20-CE20 -> 7172.5329 | CI20: =AP20-CF20 -> 0 | CJ20: =AQ20-CG20 -> 7172.5329 | CK20: =SUM(CM20:ES20) -> -7173 | CL20: =CJ20+CK20 -> -0.46705728 | CP20: -7173
A21: SUBPROANT | B21: 89050 | C21: COL2 | D21: PAPERSNL | E21: 11 | F21: Teacher Training Professionals (4) | G21: PERSONNEL | H21: Field Personnel | I21: USAID | J21: 1 | K21: =(15000/12)*3 -> 3750 | L21: 9 | M21: /months | N21: =L21*K21*J21 -> 33750 | O21: 0 | P21: =SUM(N21:O21) -> 33750 | Q21: 1 | R21: =K21*$J$7 -> 3900 | S21: 12 | T21: =R21*S21*Q21 -> 46800 | U21: 0 | V21: =SUM(T21:U21) -> 46800 | W21: 1 | X21: =+K21*$J$7*$J$7 -> 4056 | Y21: 12 | Z21: =Y21*X21*W21 -> 48672 | AA21: 0 | AB21: =SUM(Z21:AA21) -> 48672 | AC21: 1 | AD21: =+K21*$J$7*$J$7*$J$7 -> 4218.24 | AE21: 12 | AF21: =AE21*AD21*AC21 -> 50618.88 | AG21: 0 | AH21: =SUM(AF21:AG21) -> 50618.88 | AI21: 1 | AJ21: =+K21*$J$7*$J$7*$J$7*$J$7 -> 4386.9696 | AK21: 9 | AL21: =AK21*AJ21*AI21 -> 39482.726 | AM21: 0 | AN21: =SUM(AL21:AM21) -> 39482.726 | AO21: =N21+T21+Z21+AF21+AL21 -> 219323.61 | AP21: =O21+U21+AA21+AG21+AM21 -> 0 | AQ21: =SUM(AO21:AP21) -> 219323.61 | AR21: =(276.67+592.87+592.87)+(1203.86*3)+(2016.17+976.69+976.69+212.51)+(943.07+943.07+1025.97)+(928.26+928.26+1009.85) -> 15034.53 | AS21: 0 | AT21: =(919.98+919.98+1000.85)+(1246.9+1246.9+542.65+67.43+433.66)+(336.78+336.78+1316.06)+((1126.7*2)+1320.87)+(1063.2*2)+(1084.3*3)+((976.18*3)+650.79)+((988.16*4)+922.28)+(962.31*5)+(903.49*5)+(866.6*4)+(892.05*4)+6247+3242 -> 51628.39 | AU21: 0 | AV21: =AR21+AT21 -> 66662.92 | AW21: =AS21+AU21 -> 0 | AX21: =AV21+AW21 -> 66662.92 | AY21: =AQ21-AX21 -> 152660.69 | AZ21: =AQ21-AR21-AS21-AT21-AU21 -> 152660.69 | BA21: =AY21-AZ21 -> 0 | BB21: 1 | BC21: 4233.87 | BD21: 12 | BE21: =BC21*BD21 -> 50806.44 | BF21: =AA21 -> 0 | BG21: =SUM(BE21:BF21) -> 50806.44 | BH21: Profesionales responsables de acompañar los procesos de planeación, diseño, ejecución y evaluación de programas educativos desde la creación de escenarios que favorezcan la consolidación de prácticas de mediación de maestros/ambientes de aprendizaje incluyentes o con enfoque GESI. Son 4 personas, cargadas al 100%. | BI21: 1 | BJ21: =4087.29*1.04 -> 4250.7816 | BK21: 12 | BL21: =BI21*BJ21*BK21 -> 51009.379 | BM21: 0 | BN21: =SUM(BL21:BM21) -> 51009.379 | BO21: 1 | BP21: =BJ21*1.04 -> 4420.8129 | BQ21: 10 | BR21: =BQ21*BP21*BO21 -> 44208.129 | BS21: 0 | BT21: =SUM(BR21:BS21) -> 44208.129 | BU21: 2 | BV21: =(BP21/2)*1.04 -> 2298.8227 | BW21: 6 | BX21: =BW21*BV21 -> 13792.936 | BY21: 0 | BZ21: =BY21+BX21 -> 13792.936 | CA21: =BR21+BL21+BE21+BX21 -> 159816.88 | CB21: =+BY21+BS21+BM21+BF21 -> 0 | CC21: =CA21+CB21 -> 159816.88 | CE21: =AV21+CA21 -> 226479.8 | CF21: =AW21+CB21 -> 0 | CG21: =CE21+CF21 -> 226479.8 | CH21: =AO21-CE21 -> -7156.1976 | CI21: =AP21-CF21 -> 0 | CJ21: =AQ21-CG21 -> -7156.1976 | CK21: =SUM(CM21:ES21) -> 7156 | CL21: =CJ21+CK21 -> -0.19757568 | CP21: 7156
A22: SUBPROANT | B22: 89050 | C22: COL2 | E22: 12 | F22: Administrative Coordinator Administrative and Organizational Cultural Leader | G22: PERSONNEL | H22: Field Personnel | I22: LEVERAGE | J22: 1 | K22: 2000 | L22: 4 | M22: /months | N22: 0 | O22: =+J22*K22*L22 -> 8000 | P22: =SUM(N22:O22) -> 8000 | Q22: 1 | R22: =K22*$J$7 -> 2080 | S22: 4 | T22: 0 | U22: =+Q22*R22*S22 -> 8320 | V22: =SUM(T22:U22) -> 8320 | W22: 1 | X22: =+K22*$J$7*$J$7 -> 2163.2 | Y22: 4 | Z22: 0 | AA22: =+W22*X22*Y22 -> 8652.8 | AB22: =SUM(Z22:AA22) -> 8652.8 | AC22: 1 | AD22: =+K22*$J$7*$J$7*$J$7 -> 2249.728 | AE22: 4 | AF22: 0 | AG22: =+AC22*AD22*AE22 -> 8998.912 | AH22: =SUM(AF22:AG22) -> 8998.912 | AI22: 1 | AJ22: =+K22*$J$7*$J$7*$J$7*$J$7 -> 2339.7171 | AK22: 4 | AL22: 0 | AM22: =+AI22*AJ22*AK22 -> 9358.8685 | AN22: =SUM(AL22:AM22) -> 9358.8685 | AO22: =N22+T22+Z22+AF22+AL22 -> 0 | AP22: =O22+U22+AA22+AG22+AM22 -> 43330.58 | AQ22: =SUM(AO22:AP22) -> 43330.58 | AR22: 0 | AS22: =2000+2000+2000+637.52 -> 6637.52 | AT22: 0 | AU22: =640.29+651.19+673.56+676.02+637.92+650.58+585.71+592.89+577.39+577.39+519.96+535.23 -> 7318.13 | AV22: =AR22+AT22 -> 0 | AW22: =AS22+AU22 -> 13955.65 | AX22: =AV22+AW22 -> 13955.65 | AY22: =AQ22-AX22 -> 29374.93 | AZ22: =AQ22-AR22-AS22-AT22-AU22 -> 29374.93 | BA22: =AY22-AZ22 -> 0 | BB22: 0.3 | BC22: 0 | BD22: 0 | BE22: =BB22*BC22*BD22 -> 0 | BF22: =AA22*0.92 -> 7960.576 | BG22: =SUM(BE22:BF22) -> 7960.576 | BH22: Tiempos de dedicación de la lider administrativa y de cultura organizacional de la fundación Proantioquia al proyecto, en especifico en la coordinación y manejo de temas administrativos propios de movimientos contables y de personal adscritos al programa desde lo que comprende la operación de Proantioquia en el programa Juntos Aprendemos. (Leverage). | BI22: 0.3 | BJ22: 0 | BK22: 12 | BL22: =BI22*BJ22*BK22 -> 0 | BM22: =8998.912 -> 8998.912 | BN22: =SUM(BL22:BM22) -> 8998.912 | BO22: 0.3 | BP22: =BJ22*1.04 -> 0 | BQ22: 8 | BR22: =BQ22*BP22*BO22 -> 0 | BS22: =BM22*1.04 -> 9358.8685 | BT22: =SUM(BR22:BS22) -> 9358.8685 | BU22: 0 | BV22: 0 | BW22: 0 | BX22: =BW22*BV22 -> 0 | BY22: =((BS22/12)*6)-1100+36 -> 3615.4342 | BZ22: =BY22+BX22 -> 3615.4342 | CA22: =BR22+BL22+BE22+BX22 -> 0 | CB22: =+BY22+BS22+BM22+BF22 -> 29933.791 | CC22: =CA22+CB22 -> 29933.791 | CE22: =AV22+CA22 -> 0 | CF22: =AW22+CB22 -> 43889.441 | CG22: =CE22+CF22 -> 43889.441 | CH22: =AO22-CE22 -> 0 | CI22: =AP22-CF22 -> -558.86024 | CJ22: =AQ22-CG22 -> -558.86024 | CK22: =SUM(CM22:ES22) -> 559 | CL22: =CJ22+CK22 -> 0.13976 | CQ22: 559
A23: SUBPROANT | B23: 89050 | C23: COL2 | E23: 13 | F23: Professional Accountant | G23: PERSONNEL | H23: Field Personnel | I23: LEVERAGE | J23: 1 | K23: 1030 | L23: 3 | M23: /months | N23: 0 | O23: =+J23*K23*L23 -> 3090 | P23: =SUM(N23:O23) -> 3090 | Q23: 1 | R23: =K23*$J$7 -> 1071.2 | S23: 3 | T23: 0 | U23: =+Q23*R23*S23 -> 3213.6 | V23: =SUM(T23:U23) -> 3213.6 | W23: 1 | X23: =+K23*$J$7*$J$7 -> 1114.048 | Y23: 3 | Z23: 0 | AA23: =+W23*X23*Y23 -> 3342.144 | AB23: =SUM(Z23:AA23) -> 3342.144 | AC23: 1 | AD23: =+K23*$J$7*$J$7*$J$7 -> 1158.6099 | AE23: 3 | AF23: 0 | AG23: =+AC23*AD23*AE23 -> 3475.8298 | AH23: =SUM(AF23:AG23) -> 3475.8298 | AI23: 1 | AJ23: =+K23*$J$7*$J$7*$J$7*$J$7 -> 1204.9543 | AK23: 3 | AL23: 0 | AM23: =+AI23*AJ23*AK23 -> 3614.863 | AN23: =SUM(AL23:AM23) -> 3614.863 | AO23: =N23+T23+Z23+AF23+AL23 -> 0 | AP23: =O23+U23+AA23+AG23+AM23 -> 16736.437 | AQ23: =SUM(AO23:AP23) -> 16736.437 | AR23: 0 | AS23: =772.5+772.5+772.5+318.76 -> 2636.26 | AT23: 0 | AU23: =319.02+324.45+335.6+336.82+317.84+324.15+291.82+295.4+287.68+287.68+259.07+266.67 -> 3646.2 | AV23: =AR23+AT23 -> 0 | AW23: =AS23+AU23 -> 6282.46 | AX23: =AV23+AW23 -> 6282.46 | AY23: =AQ23-AX23 -> 10453.977 | AZ23: =AQ23-AR23-AS23-AT23-AU23 -> 10453.977 | BA23: =AY23-AZ23 -> 0 | BB23: 0.3 | BC23: 0 | BD23: 0 | BE23: =BB23*BC23*BD23 -> 0 | BF23: =AA23*0.92 -> 3074.7725 | BG23: =SUM(BE23:BF23) -> 3074.7725 | BH23: Tiempos de dedicación de la profesional contable de la fundación Proantioquia al proyecto, en especifico en la coordinación y manejo de temas contables desde lo que comprende la operación de Proantioquia en el programa Juntos Aprendemos. (Leverage). | BI23: 0.3 | BJ23: 0 | BK23: 12 | BL23: =BI23*BJ23*BK23 -> 0 | BM23: =3475.82976 -> 3475.8298 | BN23: =SUM(BL23:BM23) -> 3475.8298 | BO23: 0.3 | BP23: =BJ23*1.04 -> 0 | BQ23: 8 | BR23: =BQ23*BP23*BO23 -> 0 | BS23: =3766.8629504 -> 3766.863 | BT23: =SUM(BR23:BS23) -> 3766.863 | BU23: 0 | BV23: 0 | BW23: 0 | BX23: =BW23*BV23 -> 0 | BY23: =(BS23/12)*6 -> 1883.4315 | BZ23: =BY23+BX23 -> 1883.4315 | CA23: =BR23+BL23+BE23+BX23 -> 0 | CB23: =+BY23+BS23+BM23+BF23 -> 12200.897 | CC23: =CA23+CB23 -> 12200.897 | CE23: =AV23+CA23 -> 0 | CF23: =AW23+CB23 -> 18483.357 | CG23: =CE23+CF23 -> 18483.357 | CH23: =AO23-CE23 -> 0 | CI23: =AP23-CF23 -> -1746.92 | CJ23: =AQ23-CG23 -> -1746.92 | CK23: =SUM(CM23:ES23) -> 1747 | CL23: =CJ23+CK23 -> 0.0800448 | CQ23: 1747
A24: SUBPROANT | B24: 89050 | C24: COL2 | E24: 14 | F24: Visual Documentation Communications Professional | G24: PERSONNEL | H24: Field Personnel | I24: LEVERAGE | J24: 1 | K24: 1144 | L24: 2 | M24: /months | N24: 0 | O24: =+J24*K24*L24 -> 2288 | P24: =SUM(N24:O24) -> 2288 | Q24: 1 | R24: =K24*$J$7 -> 1189.76 | S24: 2 | T24: 0 | U24: =+Q24*R24*S24 -> 2379.52 | V24: =SUM(T24:U24) -> 2379.52 | W24: 1 | X24: =+K24*$J$7*$J$7 -> 1237.3504 | Y24: 2 | Z24: 0 | AA24: =+W24*X24*Y24 -> 2474.7008 | AB24: =SUM(Z24:AA24) -> 2474.7008 | AC24: 1 | AD24: =+K24*$J$7*$J$7*$J$7 -> 1286.8444 | AE24: 2 | AF24: 0 | AG24: =+AC24*AD24*AE24 -> 2573.6888 | AH24: =SUM(AF24:AG24) -> 2573.6888 | AI24: 1 | AJ24: =+K24*$J$7*$J$7*$J$7*$J$7 -> 1338.3182 | AK24: 2 | AL24: 0 | AM24: =+AI24*AJ24*AK24 -> 2676.6364 | AN24: =SUM(AL24:AM24) -> 2676.6364 | AO24: =N24+T24+Z24+AF24+AL24 -> 0 | AP24: =O24+U24+AA24+AG24+AM24 -> 12392.546 | AQ24: =SUM(AO24:AP24) -> 12392.546 | AR24: 0 | AS24: =572+572+572 -> 1716 | AT24: 0 | AU24: 0 | AV24: =AR24+AT24 -> 0 | AW24: =AS24+AU24 -> 1716 | AX24: =AV24+AW24 -> 1716 | AY24: =AQ24-AX24 -> 10676.546 | AZ24: =AQ24-AR24-AS24-AT24-AU24 -> 10676.546 | BA24: =AY24-AZ24 -> 0 | BB24: 0.3 | BC24: 0 | BD24: 0 | BE24: =BB24*BC24*BD24 -> 0 | BF24: =AA24*0.92 -> 2276.7247 | BG24: =SUM(BE24:BF24) -> 2276.7247 | BH24: Tiempos de dedicación del area de comunicaciones de la fundación Proantioquia en el programa Juntos Aprendemos. (Leverage). | BI24: 0.3 | BJ24: 0 | BK24: 12 | BL24: =BI24*BJ24*BK24 -> 0 | BM24: =2573.688832 -> 2573.6888 | BN24: =SUM(BL24:BM24) -> 2573.6888 | BO24: 0.3 | BP24: =BJ24*1.04 -> 0 | BQ24: 0 | BR24: =BQ24*BP24*BO24 -> 0 | BS24: 0 | BT24: =SUM(BR24:BS24) -> 0 | BU24: 0 | BV24: 0 | BW24: 0 | BX24: =BW24*BV24 -> 0 | BY24: 0 | BZ24: =BY24+BX24 -> 0 | CA24: =BR24+BL24+BE24+BX24 -> 0 | CB24: =+BY24+BS24+BM24+BF24 -> 4850.4136 | CC24: =CA24+CB24 -> 4850.4136 | CE24: =AV24+CA24 -> 0 | CF24: =AW24+CB24 -> 6566.4136 | CG24: =CE24+CF24 -> 6566.4136 | CH24: =AO24-CE24 -> 0 | CI24: =AP24-CF24 -> 5826.1324 | CJ24: =AQ24-CG24 -> 5826.1324 | CK24: =SUM(CM24:ES24) -> -5826 | CL24: =CJ24+CK24 -> 0.13244928 | CQ24: -5826
A25: SUBPROANT | B25: 89050 | C25: COL2 | E25: 15 | F25: Content Development Professional | G25: PERSONNEL | H25: Field Personnel | I25: USAID | J25: 1 | K25: =15000/12 -> 1250 | L25: 6 | M25: /months | N25: =L25*K25*J25 -> 7500 | O25: 0 | P25: =SUM(N25:O25) -> 7500 | Q25: 1 | R25: =K25*$J$7 -> 1300 | S25: 0 | T25: =R25*S25*Q25 -> 0 | U25: 0 | V25: =SUM(T25:U25) -> 0 | W25: 1 | X25: =+K25*$J$7*$J$7 -> 1352 | Y25: 0 | Z25: =Y25*X25*W25 -> 0 | AA25: 0 | AB25: =SUM(Z25:AA25) -> 0 | AC25: 1 | AD25: =+K25*$J$7*$J$7*$J$7 -> 1406.08 | AE25: 0 | AF25: =AE25*AD25*AC25 -> 0 | AG25: 0 | AH25: =SUM(AF25:AG25) -> 0 | AI25: 1 | AJ25: =+K25*$J$7*$J$7*$J$7*$J$7 -> 1462.3232 | AK25: 0 | AL25: =AK25*AJ25*AI25 -> 0 | AM25: 0 | AN25: =SUM(AL25:AM25) -> 0 | AO25: =N25+T25+Z25+AF25+AL25 -> 7500 | AP25: =O25+U25+AA25+AG25+AM25 -> 0 | AQ25: =SUM(AO25:AP25) -> 7500 | AR25: 0 | AS25: 0 | AT25: 0 | AU25: 0 | AV25: =AR25+AT25 -> 0 | AW25: =AS25+AU25 -> 0 | AX25: =AV25+AW25 -> 0 | AY25: =AQ25-AX25 -> 7500 | AZ25: =AQ25-AR25-AS25-AT25-AU25 -> 7500 | BA25: =AY25-AZ25 -> 0 | BB25: 0 | BC25: =AI25*$P$7*$P$7 -> 0 | BD25: 0 | BE25: =BB25*BC25*BD25 -> 0 | BF25: =AA25 -> 0 | BG25: =SUM(BE25:BF25) -> 0 | BH25: Tiempos de dedicación del area de educación de la fundación Proantioquia al proyecto, en especifico en temas vinculados a la generación de contenidos y gestión del conocimiento. (Leverage).Esta linea no se requiere. | BI25: 0 | BJ25: =AO25*$P$7*$P$7 -> 0 | BK25: 0 | BL25: =BI25*BJ25*BK25 -> 0 | BM25: 0 | BN25: =SUM(BL25:BM25) -> 0 | BO25: 0 | BP25: =BJ25*1.04 -> 0 | BQ25: 0 | BR25: =BQ25*BP25*BO25 -> 0 | BS25: 0 | BT25: =SUM(BR25:BS25) -> 0 | BU25: 0 | BV25: 0 | BW25: 0 | BX25: =BW25*BV25 -> 0 | BY25: 0 | BZ25: =BY25+BX25 -> 0 | CA25: =BR25+BL25+BE25+BX25 -> 0 | CB25: =+BY25+BS25+BM25+BF25 -> 0 | CC25: =CA25+CB25 -> 0 | CE25: =AV25+CA25 -> 0 | CF25: =AW25+CB25 -> 0 | CG25: =CE25+CF25 -> 0 | CH25: =AO25-CE25 -> 7500 | CI25: =AP25-CF25 -> 0 | CJ25: =AQ25-CG25 -> 7500 | CK25: =SUM(CM25:ES25) -> -7500 | CL25: =CJ25+CK25 -> 0 | CR25: -7500
A26: SUBPROANT | B26: 89050 | C26: COL2 | D26: PAPERSNL | E26: 16 | F26: Finance & Admin Coordinator Project Analyst | G26: PERSONNEL | H26: Field Personnel | I26: USAID | J26: 1 | K26: =22500/12 -> 1875 | L26: 9 | M26: /months | N26: =L26*K26*J26 -> 16875 | O26: 0 | P26: =SUM(N26:O26) -> 16875 | Q26: =J26 -> 1 | R26: =K26*$J$7 -> 1950 | S26: 12 | T26: =Q26*R26*S26 -> 23400 | U26: 0 | V26: =SUM(T26:U26) -> 23400 | W26: =Q26 -> 1 | X26: =+K26*$J$7*$J$7 -> 2028 | Y26: 12 | Z26: =W26*X26*Y26 -> 24336 | AA26: 0 | AB26: =SUM(Z26:AA26) -> 24336 | AC26: =W26 -> 1 | AD26: =+K26*$J$7*$J$7*$J$7 -> 2109.12 | AE26: 12 | AF26: =AC26*AD26*AE26 -> 25309.44 | AG26: 0 | AH26: =SUM(AF26:AG26) -> 25309.44 | AI26: =AC26 -> 1 | AJ26: =+K26*$J$7*$J$7*$J$7*$J$7 -> 2193.4848 | AK26: 10 | AL26: =AI26*AJ26*AK26 -> 21934.848 | AM26: 0 | AN26: =SUM(AL26:AM26) -> 21934.848 | AO26: =N26+T26+Z26+AF26+AL26 -> 111855.29 | AP26: =O26+U26+AA26+AG26+AM26 -> 0 | AQ26: =SUM(AO26:AP26) -> 111855.29 | AR26: =222.73+969.16+982.85+949.02+934.11+3510 -> 7567.87 | AS26: 0 | AT26: =925.79+(1003.88+62.34)+1122.6+1126.7+1063.2+1084.3+976.18+988.16+962.31+903.49+866.6+892.05+8843+2243+10776 -> 33839.6 | AU26: 0 | AV26: =AR26+AT26 -> 41407.47 | AW26: =AS26+AU26 -> 0 | AX26: =AV26+AW26 -> 41407.47 | AY26: =AQ26-AX26 -> 70447.818 | AZ26: =AQ26-AR26-AS26-AT26-AU26 -> 70447.818 | BA26: =AY26-AZ26 -> 0 | BB26: 1 | BC26: 1058.47 | BD26: 12 | BE26: =BB26*BC26*BD26 -> 12701.64 | BF26: =AA26 -> 0 | BG26: =SUM(BE26:BF26) -> 12701.64 | BH26: Responsable de realizar los reportes financieros al cooperante, dar tramite administrativo a las solicitudes de fondos, accruals y demas requerimientos que desde POA sean solicitados para dar cumplimiento a las responsabilidades contractuales adquiridas con el subacuerdo y da cuenta de la operación de la fundación Proantioquia sobre la ejecución de las subactividades y demas información que pueda ser solicitada, se espera que esta persona esté activa hasta el final de proyecto. | BI26: 1 | BJ26: 1062.69 | BK26: 12 | BL26: =BI26*BJ26*BK26 -> 12752.28 | BM26: 0 | BN26: =SUM(BL26:BM26) -> 12752.28 | BO26: 1 | BP26: =BJ26*1.04 -> 1105.1976 | BQ26: 12 | BR26: =BQ26*BP26*BO26 -> 13262.371 | BS26: 0 | BT26: =SUM(BR26:BS26) -> 13262.371 | BU26: 1 | BV26: =BP26*1.04 -> 1149.4055 | BW26: 6 | BX26: =BW26*BV26 -> 6896.433 | BY26: 0 | BZ26: =BY26+BX26 -> 6896.433 | CA26: =BR26+BL26+BE26+BX26 -> 45612.724 | CB26: =+BY26+BS26+BM26+BF26 -> 0 | CC26: =CA26+CB26 -> 45612.724 | CE26: =AV26+CA26 -> 87020.194 | CF26: =AW26+CB26 -> 0 | CG26: =CE26+CF26 -> 87020.194 | CH26: =AO26-CE26 -> 24835.094 | CI26: =AP26-CF26 -> 0 | CJ26: =AQ26-CG26 -> 24835.094 | CK26: =SUM(CM26:ES26) -> -24835 | CL26: =CJ26+CK26 -> 0.093776 | CS26: -24835
A27: SUBPROANT | B27: 89050 | C27: COL2 | D27: PAPERSNL | E27: 17 | F27: Operations and Planning Professional Human Resources Professional | G27: PERSONNEL | H27: Field Personnel | I27: LEVERAGE | J27: 1 | K27: 1000 | L27: 5 | M27: /months | N27: 0 | O27: =+K27*L27 -> 5000 | P27: =SUM(N27:O27) -> 5000 | Q27: 1 | R27: =K27*$J$7 -> 1040 | S27: 6 | T27: 0 | U27: =+R27*S27 -> 6240 | V27: =SUM(T27:U27) -> 6240 | W27: 1 | X27: =+K27*$J$7*$J$7 -> 1081.6 | Y27: 6 | Z27: 0 | AA27: =+X27*Y27 -> 6489.6 | AB27: =SUM(Z27:AA27) -> 6489.6 | AC27: 1 | AD27: =+K27*$J$7*$J$7*$J$7 -> 1124.864 | AE27: 6 | AF27: 0 | AG27: =+AD27*AE27 -> 6749.184 | AH27: =SUM(AF27:AG27) -> 6749.184 | AI27: 1 | AJ27: =+K27*$J$7*$J$7*$J$7*$J$7 -> 1169.8586 | AK27: 6 | AL27: 0 | AM27: =+AJ27*AK27 -> 7019.1514 | AN27: =SUM(AL27:AM27) -> 7019.1514 | AO27: =N27+T27+Z27+AF27+AL27 -> 0 | AP27: =O27+U27+AA27+AG27+AM27 -> 31497.935 | AQ27: =SUM(AO27:AP27) -> 31497.935 | AR27: 0 | AS27: =1250+1250+1250+314.38 -> 4064.38 | AT27: 0 | AU27: =296.13+301.16+311.51+312.65+295.03+300.88+270.88+274.2+267.03+267.03+240.47+247.54 -> 3384.51 | AV27: =AR27+AT27 -> 0 | AW27: =AS27+AU27 -> 7448.89 | AX27: =AV27+AW27 -> 7448.89 | AY27: =AQ27-AX27 -> 24049.045 | AZ27: =AQ27-AR27-AS27-AT27-AU27 -> 24049.045 | BA27: =AY27-AZ27 -> 0 | BB27: 0.3 | BC27: =AI27*$P$7*$P$7 -> 0 | BD27: 0 | BE27: =BB27*BC27*BD27 -> 0 | BF27: 5970.43 | BG27: =SUM(BE27:BF27) -> 5970.43 | BH27: Tiempos de dedicación del area de gestion humana de la fundación Proantioquia al proyecto, en especifico en la coordinación y manejo de manejo de personal adscritos al programa desde lo que comprende la operación de Proantioquia en el programa Juntos Aprendemos. (Leverage). | BI27: 0.3 | BJ27: =AO27*$P$7*$P$7 -> 0 | BK27: 12 | BL27: =BI27*BJ27*BK27 -> 0 | BM27: =6749.184 -> 6749.184 | BN27: =SUM(BL27:BM27) -> 6749.184 | BO27: 0.3 | BP27: =BJ27*1.04 -> 0 | BQ27: 12 | BR27: =BQ27*BP27*BO27 -> 0 | BS27: =BM27*1.04 -> 7019.1514 | BT27: =SUM(BR27:BS27) -> 7019.1514 | BU27: 0 | BV27: 5443.1 | BW27: 0 | BX27: =BW27*BV27 -> 0 | BY27: =BV27 -> 5443.1 | BZ27: =BY27+BX27 -> 5443.1 | CA27: =BR27+BL27+BE27+BX27 -> 0 | CB27: =+BY27+BS27+BM27+BF27 -> 25181.865 | CC27: =CA27+CB27 -> 25181.865 | CE27: =AV27+CA27 -> 0 | CF27: =AW27+CB27 -> 32630.755 | CG27: =CE27+CF27 -> 32630.755 | CH27: =AO27-CE27 -> 0 | CI27: =AP27-CF27 -> -1132.82 | CJ27: =AQ27-CG27 -> -1132.82 | CK27: =SUM(CM27:ES27) -> 1133 | CL27: =CJ27+CK27 -> 0.18 | CQ27: 1133
A28: SUBPROANT | B28: 89050 | C28: COL2 | D28: PAPERSNL | E28: 18 | F28: Juntos Aprendemos Project Leader | G28: PERSONNEL | H28: Field Personnel | I28: USAID | M28: /months | AQ28: 0 | AR28: 0 | AS28: 0 | AT28: 0 | AU28: 0 | AV28: =AR28+AT28 -> 0 | AW28: =AS28+AU28 -> 0 | AX28: =AV28+AW28 -> 0 | AY28: =AQ28-AX28 -> 0 | AZ28: =AQ28-AR28-AS28-AT28-AU28 -> 0 | BA28: =AY28-AZ28 -> 0 | BB28: 1 | BC28: 2209.36 | BD28: 12 | BE28: =BC28*BD28 -> 26512.32 | BF28: =AA28 -> 0 | BG28: =SUM(BE28:BF28) -> 26512.32 | BH28: Responsable de coordinar la implementación de procesos y actividades de formación de maestros en el marco del programa Juntos Aprendemos, se espera que esta persona esté activa hasta el final de proyecto. | BI28: 1 | BJ28: =2132.77*1.04 -> 2218.0808 | BK28: 12 | BL28: =BI28*BJ28*BK28 -> 26616.97 | BM28: 0 | BN28: =SUM(BL28:BM28) -> 26616.97 | BO28: 1 | BP28: =BJ28*1.04 -> 2306.804 | BQ28: 12 | BR28: =BQ28*BP28*BO28 -> 27681.648 | BS28: 0 | BT28: =SUM(BR28:BS28) -> 27681.648 | BU28: 1 | BV28: =BP28*1.04 -> 2399.0762 | BW28: 6 | BX28: =BW28*BV28 -> 14394.457 | BY28: 0 | BZ28: =BY28+BX28 -> 14394.457 | CA28: =BR28+BL28+BE28+BX28 -> 95205.395 | CB28: =+BY28+BS28+BM28+BF28 -> 0 | CC28: =CA28+CB28 -> 95205.395 | CE28: =AV28+CA28 -> 95205.395 | CF28: =AW28+CB28 -> 0 | CG28: =CE28+CF28 -> 95205.395 | CH28: =AO28-CE28 -> -95205.395 | CI28: =AP28-CF28 -> 0 | CJ28: =AQ28-CG28 -> -95205.395 | CK28: =SUM(CM28:ES28) -> 95205 | CL28: =CJ28+CK28 -> -0.39514368 | CM28: 95205
A29: SUBPROANT | B29: 89050 | C29: COL2 | D29: PAPERSNL | E29: 19 | F29: Logistics professional | G29: PERSONNEL | H29: Field Personnel | I29: USAID | M29: /months | AQ29: 0 | AR29: 0 | AS29: 0 | AT29: 0 | AU29: 0 | AV29: =AR29+AT29 -> 0 | AW29: =AS29+AU29 -> 0 | AX29: =AV29+AW29 -> 0 | AY29: =AQ29-AX29 -> 0 | AZ29: =AQ29-AR29-AS29-AT29-AU29 -> 0 | BA29: =AY29-AZ29 -> 0 | BB29: 1 | BC29: 880.49 | BD29: 12 | BE29: =BC29*BD29 -> 10565.88 | BF29: =AA29 -> 0 | BG29: =SUM(BE29:BF29) -> 10565.88 | BH29: Responsable de asistir, acompañar y soportar los procesos logísticos del proyecto Juntos Aprendemos, se espera que esta persona esté activa hasta el final de proyecto. | BI29: 1 | BJ29: =817.46*1.04 -> 850.1584 | BK29: 12 | BL29: =BI29*BJ29*BK29 -> 10201.901 | BM29: 0 | BN29: =SUM(BL29:BM29) -> 10201.901 | BO29: 1 | BP29: =BJ29*1.04 -> 884.16474 | BQ29: 12 | BR29: =BQ29*BP29*BO29 -> 10609.977 | BS29: 0 | BT29: =SUM(BR29:BS29) -> 10609.977 | BU29: 1 | BV29: =BP29*1.04 -> 919.53133 | BW29: 6 | BX29: =BW29*BV29 -> 5517.188 | BY29: 0 | BZ29: =BY29+BX29 -> 5517.188 | CA29: =BR29+BL29+BE29+BX29 -> 36894.946 | CB29: =+BY29+BS29+BM29+BF29 -> 0 | CC29: =CA29+CB29 -> 36894.946 | CE29: =AV29+CA29 -> 36894.946 | CF29: =AW29+CB29 -> 0 | CG29: =CE29+CF29 -> 36894.946 | CH29: =AO29-CE29 -> -36894.946 | CI29: =AP29-CF29 -> 0 | CJ29: =AQ29-CG29 -> -36894.946 | CK29: =SUM(CM29:ES29) -> 36895 | CL29: =CJ29+CK29 -> 0.05441536 | CN29: 36895
A30: SUBPROANT | B30: 89050 | C30: COL2 | D30: PAPERSNL | E30: 20 | F30: Monitoring, evaluation and Learning (MEL) professional | G30: PERSONNEL | H30: Field Personnel | I30: USAID | M30: /months | AQ30: 0 | AR30: 0 | AS30: 0 | AT30: 0 | AU30: 0 | AV30: =AR30+AT30 -> 0 | AW30: =AS30+AU30 -> 0 | AX30: =AV30+AW30 -> 0 | AY30: =AQ30-AX30 -> 0 | AZ30: =AQ30-AR30-AS30-AT30-AU30 -> 0 | BA30: =AY30-AZ30 -> 0 | BB30: 1 | BC30: 979.78 | BD30: 11.7164 | BE30: =BC30*BD30 -> 11479.494 | BF30: =AA30 -> 0 | BG30: =SUM(BE30:BF30) -> 11479.494 | BH30: Responsable de participar y dar el manejo objetivo de los datos según requerimientos de la mesa de monitoreo y evaluación del programa Juntos Aprendemos, se espera que esta persona esté activa hasta el final de proyecto. | BI30: 1 | BJ30: 982.97 | BK30: 12 | BL30: =BI30*BJ30*BK30 -> 11795.64 | BM30: 0 | BN30: =SUM(BL30:BM30) -> 11795.64 | BO30: 1 | BP30: =BJ30*1.04 -> 1022.2888 | BQ30: 12 | BR30: =BQ30*BP30*BO30 -> 12267.466 | BS30: 0 | BT30: =SUM(BR30:BS30) -> 12267.466 | BU30: 0 | BV30: 0 | BW30: 0 | BX30: 0 | BY30: 0 | BZ30: =BY30+BX30 -> 0 | CA30: =BR30+BL30+BE30+BX30 -> 35542.6 | CB30: =+BY30+BS30+BM30+BF30 -> 0 | CC30: =CA30+CB30 -> 35542.6 | CE30: =AV30+CA30 -> 35542.6 | CF30: =AW30+CB30 -> 0 | CG30: =CE30+CF30 -> 35542.6 | CH30: =AO30-CE30 -> -35542.6 | CI30: =AP30-CF30 -> 0 | CJ30: =AQ30-CG30 -> -35542.6 | CK30: =SUM(CM30:ES30) -> 35543 | CL30: =CJ30+CK30 -> 0.400008 | CM30: 25207 | CS30: 10336
A31: SUBPROANT | B31: 89050 | C31: COL2 | D31: PAPERSNL | E31: 21 | F31: Metrics Analyst | G31: PERSONNEL | H31: Field Personnel | I31: USAID | M31: /months | AQ31: 0 | AR31: 0 | AS31: 0 | AT31: 0 | AU31: 0 | AV31: =AR31+AT31 -> 0 | AW31: =AS31+AU31 -> 0 | AX31: =AV31+AW31 -> 0 | AY31: =AQ31-AX31 -> 0 | AZ31: =AQ31-AR31-AS31-AT31-AU31 -> 0 | BA31: =AY31-AZ31 -> 0 | BB31: 1 | BC31: 826.91 | BD31: 1 | BE31: =BB31*BC31*BD31 -> 826.91 | BF31: =AA31 -> 0 | BG31: =SUM(BE31:BF31) -> 826.91 | BH31: Responsable de centralizar y acompañar los procesos de manejo y reporte de datos del programa Juntos Aprendemos desde lo comprendido en la operación de Proantioquia ademas de brindar apoyo al profesional de monitoreo y evaluación según las solicitudes que tenga desde su participación dentro del proyecto. | BI31: 1 | BJ31: 850.16 | BK31: 12 | BL31: =BI31*BJ31*BK31 -> 10201.92 | BM31: 0 | BN31: =SUM(BL31:BM31) -> 10201.92 | BO31: 1 | BP31: =BJ31*1.04 -> 884.1664 | BQ31: 0 | BR31: =BQ31*BP31*BO31 -> 0 | BS31: 0 | BT31: =SUM(BR31:BS31) -> 0 | BU31: 0 | BV31: 0 | BW31: 0 | BX31: 0 | BY31: 0 | BZ31: =BY31+BX31 -> 0 | CA31: =BR31+BL31+BE31+BX31 -> 11028.83 | CB31: =+BY31+BS31+BM31+BF31 -> 0 | CC31: =CA31+CB31 -> 11028.83 | CE31: =AV31+CA31 -> 11028.83 | CF31: =AW31+CB31 -> 0 | CG31: =CE31+CF31 -> 11028.83 | CH31: =AO31-CE31 -> -11028.83 | CI31: =AP31-CF31 -> 0 | CJ31: =AQ31-CG31 -> -11028.83 | CK31: =SUM(CM31:ES31) -> 11029 | CL31: =CJ31+CK31 -> 0.17 | CR31: 7500 | CS31: 3529
A32: SUBPROANT | B32: 89050 | C32: COL2 | D32: PAPERSNL | E32: 22 | F32: Administrative Assistant | G32: PERSONNEL | H32: Field Personnel | I32: USAID | M32: /months | AQ32: 0 | AR32: 0 | AS32: 0 | AT32: 0 | AU32: 0 | AV32: =AR32+AT32 -> 0 | AW32: =AS32+AU32 -> 0 | AX32: =AV32+AW32 -> 0 | AY32: =AQ32-AX32 -> 0 | AZ32: =AQ32-AR32-AS32-AT32-AU32 -> 0 | BA32: =AY32-AZ32 -> 0 | BB32: 1 | BC32: 555.01 | BD32: 12 | BE32: =BB32*BC32*BD32 -> 6660.12 | BF32: =AA32 -> 0 | BG32: =SUM(BE32:BF32) -> 6660.12 | BH32: Responsable de registrar los movimientos contables del proyecto, preparar los pagos de seguridad social, nómina y obligaciones de los colaboradores del proyecto, se espera que esta persona esté activa hasta el final de proyecto. | BI32: 1 | BJ32: 548.16 | BK32: 12 | BL32: =BI32*BJ32*BK32 -> 6577.92 | BM32: 0 | BN32: =SUM(BL32:BM32) -> 6577.92 | BO32: 1 | BP32: =BJ32*1.04 -> 570.0864 | BQ32: 10 | BR32: =BQ32*BP32*BO32 -> 5700.864 | BS32: 0 | BT32: =SUM(BR32:BS32) -> 5700.864 | BU32: 0 | BV32: 0 | BW32: 0 | BX32: 0 | BY32: 0 | BZ32: =BY32+BX32 -> 0 | CA32: =BR32+BL32+BE32+BX32 -> 18938.904 | CB32: =+BY32+BS32+BM32+BF32 -> 0 | CC32: =CA32+CB32 -> 18938.904 | CE32: =AV32+CA32 -> 18938.904 | CF32: =AW32+CB32 -> 0 | CG32: =CE32+CF32 -> 18938.904 | CH32: =AO32-CE32 -> -18938.904 | CI32: =AP32-CF32 -> 0 | CJ32: =AQ32-CG32 -> -18938.904 | CK32: =SUM(CM32:ES32) -> 18939 | CL32: =CJ32+CK32 -> 0.096 | CN32: 5 | CP32: 17 | CS32: 10970 | DU32: 7947
A33: SUBPROANT | B33: 89050 | C33: COL2 | D33: PAPERSNL | E33: 23 | F33: Operations Assistant | G33: PERSONNEL | H33: Field Personnel | I33: USAID | M33: /months | AQ33: 0 | AR33: 0 | AS33: 0 | AT33: 0 | AU33: 0 | AV33: =AR33+AT33 -> 0 | AW33: =AS33+AU33 -> 0 | AX33: =AV33+AW33 -> 0 | AY33: =AQ33-AX33 -> 0 | AZ33: =AQ33-AR33-AS33-AT33-AU33 -> 0 | BA33: =AY33-AZ33 -> 0 | BB33: 1 | BC33: 556.8 | BD33: 10.733 | BE33: =BB33*BC33*BD33 -> 5976.1344 | BF33: =AA33 -> 0 | BG33: =SUM(BE33:BF33) -> 5976.1344 | BH33: Responsable de apoyar las tareas operativas, documentales, logísticas y la sistematización de datos del programa Juntos Aprendemos desde la fundación Proantioquia, se espera que esta persona esté activa hasta el final de proyecto. | BI33: 1 | BJ33: 476.66 | BK33: 12 | BL33: =BI33*BJ33*BK33 -> 5719.92 | BM33: 0 | BN33: =SUM(BL33:BM33) -> 5719.92 | BO33: 1 | BP33: =BJ33*1.04 -> 495.7264 | BQ33: 10 | BR33: =BQ33*BP33*BO33 -> 4957.264 | BS33: 0 | BT33: =SUM(BR33:BS33) -> 4957.264 | BU33: 0 | BV33: 0 | BW33: 0 | BX33: 0 | BY33: 0 | BZ33: =BY33+BX33 -> 0 | CA33: =BR33+BL33+BE33+BX33 -> 16653.318 | CB33: =+BY33+BS33+BM33+BF33 -> 0 | CC33: =CA33+CB33 -> 16653.318 | CE33: =AV33+CA33 -> 16653.318 | CF33: =AW33+CB33 -> 0 | CG33: =CE33+CF33 -> 16653.318 | CH33: =AO33-CE33 -> -16653.318 | CI33: =AP33-CF33 -> 0 | CJ33: =AQ33-CG33 -> -16653.318 | CK33: =SUM(CM33:ES33) -> 16653 | CL33: =CJ33+CK33 -> -0.3184 | DU33: 13922 | DV33: 2731
E34: 24 | F34: Subtotal Field Personnel | N34: =SUM(N20:N27) -> 81525 | O34: =SUM(O20:O27) -> 18378 | P34: =SUM(P20:P27) -> 99903 | T34: =SUM(T20:T27) -> 102648 | U34: =SUM(U20:U27) -> 20153.12 | V34: =SUM(V20:V27) -> 122801.12 | Z34: =SUM(Z20:Z27) -> 106753.92 | AA34: =SUM(AA20:AA27) -> 20959.245 | AB34: =SUM(AB20:AB27) -> 127713.16 | AF34: =SUM(AF20:AF27) -> 111024.08 | AG34: =SUM(AG20:AG27) -> 21797.615 | AH34: =SUM(AH20:AH27) -> 132821.69 | AL34: =SUM(AL20:AL27) -> 91833.897 | AM34: =SUM(AM20:AM27) -> 22669.519 | AN34: =SUM(AN20:AN27) -> 114503.42 | AO34: =SUM(AO20:AO27) -> 493784.89 | AP34: =SUM(AP20:AP27) -> 103957.5 | AQ34: =SUM(AQ20:AQ27) -> 597742.39 | AR34: =SUM(AR20:AR33) -> 31490.4 | AS34: =SUM(AS20:AS33) -> 15054.16 | AT34: =SUM(AT20:AT33) -> 125346.43 | AU34: =SUM(AU20:AU33) -> 14348.84 | AV34: =SUM(AV20:AV33) -> 156836.83 | AW34: =SUM(AW20:AW33) -> 29403 | AX34: =SUM(AX20:AX33) -> 186239.83 | AY34: =SUM(AY20:AY33) -> 411502.56 | AZ34: =AQ34-AR34-AS34-AT34-AU34 -> 411502.56 | BE34: =SUM(BE20:BE33) -> 154152.28 | BF34: =SUM(BF20:BF33) -> 19282.503 | BG34: =SUM(BE34:BF34) -> 173434.78 | BJ34: =SUM(BJ20:BJ33) -> 13681.498 | BL34: =SUM(BL20:BL33) -> 164177.97 | BM34: =SUM(BM20:BM33) -> 21797.615 | BN34: =SUM(BL34:BM34) -> 185975.59 | BP34: =SUM(BP20:BP33) -> 14228.758 | BR34: =SUM(BR20:BR33) -> 144082.82 | BS34: =SUM(BS20:BS33) -> 20144.883 | BT34: =SUM(BR34:BS34) -> 164227.7 | BV34: =SUM(BV20:BV33) -> 14851.026 | BX34: =SUM(BX20:BX33) -> 56447.558 | BY34: =SUM(BY20:BY33) -> 10941.966 | BZ34: =SUM(BZ20:BZ33) -> 67389.524 | CA34: =SUM(CA20:CA33) -> 518860.63 | CB34: =SUM(CB20:CB33) -> 72166.966 | CC34: =SUM(CC20:CC33) -> 591027.59 | CE34: =SUM(CE20:CE33) -> 675697.46 | CF34: =SUM(CF20:CF33) -> 101569.97 | CG34: =SUM(CG20:CG33) -> 777267.42 | CK34: =SUM(CM34:ES34) -> 0 | CL34: =CJ34+CK34 -> 0
E35: 25 | F35: Personnel Total | N35: =N34+N18 -> 146525 | O35: =O34+O18 -> 29706.9 | P35: =P34+P18 -> 176231.9 | T35: =T34+T18 -> 180648 | U35: =U34+U18 -> 33006.272 | V35: =V34+V18 -> 213654.27 | Z35: =Z34+Z18 -> 187873.92 | AA35: =AA34+AA18 -> 34326.523 | AB35: =AB34+AB18 -> 222200.44 | AF35: =AF34+AF18 -> 195388.88 | AG35: =AG34+AG18 -> 35699.584 | AH35: =AH34+AH18 -> 231088.46 | AL35: =AL34+AL18 -> 175186.32 | AM35: =AM34+AM18 -> 35922.73 | AN35: =AN34+AN18 -> 211109.05 | AO35: =AO34+AO18 -> 885622.12 | AP35: =AP34+AP18 -> 168662.01 | AQ35: =AQ34+AQ18 -> 1054284.1 | AR35: =AR34+AR18 -> 31490.4 | AS35: =AS34+AS18 -> 15054.16 | ... AY35: =AY34+AY18 -> 411502.56 | AZ35: =AQ35-AR35-AS35-AT35-AU35 -> 814255.04 | BE35: =BE34+BE18 -> 199722.59 | BF35: =BF34+BF18 -> 32649.503 | BG35: =SUM(BE35:BF35) -> 232372.1 | BJ35: =BJ34+BJ18 -> 18657.357 | BL35: =BL34+BL18 -> 223888.28 | BM35: =BM34+BM18 -> 35699.584 | BN35: =SUM(BL35:BM35) -> 259587.87 | BP35: =BP34+BP18 -> 19403.651 | BR35: =BR34+BR18 -> 202154.96 | BS35: =BS34+BS18 -> 33398.093 | BT35: =SUM(BR35:BS35) -> 235553.06 | BV35: =BV34+BV18 -> 18139.094 | BX35: =BX34+BX18 -> 76175.963 | BY35: =BY34+BY18 -> 13150.834 | BZ35: =BZ34+BZ18 -> 89326.797 | CA35: =CA18+CA34 -> 701941.8 | CB35: =CB18+CB34 -> 114898.01 | CC35: =CC34+CC18 -> 816839.82 | CE35: =CE34+CE18 -> 910223.37 | CF35: =CF34+CF18 -> 146645.52 | CG35: =CG34+CG18 -> 1056868.9 | CK35: =SUM(CM35:ES35) -> 0 | CL35: =CJ35+CK35 -> 0
E36: 26 | F36: FRINGE BENEFITS | CK36: =SUM(CM36:ES36) -> 0 | CL36: =CJ36+CK36 -> 0
A37: SUBPROANT | B37: 89050 | C37: COL2 | D37: PAFRINGE | E37: 27 | F37: Fringe Benefits – Colombia HQ and Field Staff (above $2,600 monthly) | G37: PERSONNEL | H37: Fringe Benefits | I37: MIXED | J37: 0.53864 | N37: =$J$37*(N14+N17+N20) -> 38526.226 | O37: =$J$37*(O14+O17+O20) -> 6102.1987 | P37: =SUM(N37:O37) -> 44628.425 | Q37: =J37 -> 0.53864 | T37: =$J$37*(T14+T17+T20) -> 46887.535 | U37: =$J$37*(U14+U17+U20) -> 6923.2218 | V37: =+T37+U37 -> 53810.757 | W37: =J37 -> 0.53864 | Z37: =$J$37*(Z14+Z17+Z20) -> 48763.036 | AA37: =$J$37*(AA14+AA17+AA20) -> 7200.1507 | AB37: =SUM(Z37:AA37) -> 55963.187 | AC37: =J37 -> 0.53864 | AF37: =$J$37*(AF14+AF17+AF20) -> 50713.558 | AG37: =$J$37*(AG14+AG17+AG20) -> 7488.1567 | AH37: =SUM(AF37:AG37) -> 58201.714 | AI37: =J37 -> 0.53864 | AL37: =$J$37*(AL14+AL17+AL20) -> 49465.41 | AM37: =$J$37*(AM14+AM17+AM20) -> 7138.7094 | AN37: =SUM(AL37:AM37) -> 56604.12 | AO37: =+AL37+AF37+Z37+T37+N37 -> 234355.76 | AP37: =+AM37+AG37+AA37+U37+O37 -> 34852.437 | AQ37: =+SUM(AO37:AP37) -> 269208.2 | AR37: 0 | AS37: 0 | AT37: =(1146.22-152.83)+1165.72+1205.78+1210.18+1141.97+(1164.63+1864.79)+1048.51+1061.37+1033.6+970.42+930.8+(958.14+1602.38)+162.13 -> 16513.81 | AU37: 0 | AV37: =AR37+AT37 -> 16513.81 | AW37: =AS37+AU37 -> 0 | AX37: =AV37+AW37 -> 16513.81 | AY37: =AQ37-AX37 -> 252694.39 | AZ37: =AQ37-AR37-AS37-AT37-AU37 -> 252694.39 | BA37: =AY37-AZ37 -> 0 | BB37: 0 | BC37: 0 | BD37: 0 | BE37: 0 | BF37: 0 | BG37: =SUM(BB37:BF37) -> 0 | BH37: Seguridad social (sobre $2,600), se dejará todo en una sola línea dado que el calculo porcentual a cargar es el mismo para todo el personal | BI37: 0 | BJ37: 0 | BK37: 0 | BL37: 0 | BM37: 0 | BN37: =SUM(BI37:BM37) -> 0 | BO37: 0 | BP37: 0 | BQ37: 0 | BR37: 0 | BS37: 0 | BT37: =SUM(BO37:BS37) -> 0 | CA37: =BR37+BL37+BE37 -> 0 | CB37: =BS37+BM37+BF37 -> 0 | CC37: =CA37+CB37 -> 0 | CE37: =AV37+CA37 -> 16513.81 | CF37: =AW37+CB37 -> 0 | CG37: =CE37+CF37 -> 16513.81 | CH37: =AO37-CE37 -> 217841.95 | CI37: =AP37-CF37 -> 34852.437 | CJ37: =AQ37-CG37 -> 252694.39 | CK37: =SUM(CM37:ES37) -> -252694 | CL37: =CJ37+CK37 -> 0.39186573 | CT37: -217842 | CU37: -34852
A38: SUBPROANT | B38: 89050 | C38: COL2 | D38: PAFRINGE | E38: 28 | F38: Fringe Benefits - Colombia HQ and Field Staff (below $2,600 monthly) | G38: PERSONNEL | H38: Fringe Benefits | I38: MIXED | J38: 0.40364 | N38: =$J$38*(N15+N21+N22+N23+N24+N25+N26+N27) -> 30273 | O38: =$J$38*(O15+O21+O22+O23+O24+O25+O26+O27) -> 7418.0959 | P38: =SUM(N38:O38) -> 37691.096 | Q38: =J38 -> 0.40364 | T38: =$J$38*(T15+T21+T22+T23+T24+T25+T26+T27) -> 37780.704 | U38: =$J$38*(U15+U21+U22+U23+U24+U25+U26+U27) -> 8134.6054 | V38: =+T38+U38 -> 45915.309 | W38: =J38 -> 0.40364 | Z38: =$J$38*(Z15+Z21+Z22+Z23+Z24+Z25+Z26+Z27) -> 39291.932 | AA38: =$J$38*(AA15+AA21+AA22+AA23+AA24+AA25+AA26+AA27) -> 8459.9896 | AB38: =SUM(Z38:AA38) -> 47751.922 | AC38: =J38 -> 0.40364 | AF38: =$J$38*(AF15+AF21+AF22+AF23+AF24+AF25+AF26+AF27) -> 40863.609 | AG38: =$J$38*(AG15+AG21+AG22+AG23+AG24+AG25+AG26+AG27) -> 8798.3892 | AH38: =SUM(AF38:AG38) -> 49661.999 | AI38: =J38 -> 0.40364 | AL38: =$J$38*(AL15+AL21+AL22+AL23+AL24+AL25+AL26+AL27) -> 33644.372 | AM38: =$J$38*(AM15+AM21+AM22+AM23+AM24+AM25+AM26+AM27) -> 9150.3247 | AN38: =SUM(AL38:AM38) -> 42794.696 | AO38: =+AL38+AF38+Z38+T38+N38 -> 181853.62 | AP38: =+AM38+AG38+AA38+U38+O38 -> 41961.405 | AQ38: =+SUM(AO38:AP38) -> 223815.02 | AR38: =1004.62+2384.5+1984.94+2167.27+4452.1 -> 11993.43 | AS38: =610.8+235.92+174.69+381.75+610.8+235.92+174.69+381.75+610.8+235.92+174.69+381.75+194.7+97.35+96.01 -> 4597.54 | AT38: =5666.77+3395+3401.2+3467.08+3271.67+8962.85+5296.53+4925.25+5608.71+8084.1+5733.3+11946.72-AT37 -> 53245.37 | AU38: =195.42+97.37+90.38+141.66+198.74+99.02+91.92+146.53+205.57+102.42+95.07+147.06+206.32+102.8+95.42+138.77+194.69+97+90.04+141.53+198.56+98.93+91.83+178.76+89.06+82.67+180.95+90.16+83.69+176.22+87.8+81.5+176.22+87.8+81.5+158.69+79.07+73.39+163.35+81.39+75.55 -> 5094.82 | AV38: =AR38+AT38 -> 65238.8 | AW38: =AS38+AU38 -> 9692.36 | AX38: =AV38+AW38 -> 74931.16 | AY38: =AQ38-AX38 -> 148883.86 | AZ38: =AQ38-AR38-AS38-AT38-AU38 -> 148883.86 | BA38: =AY38-AZ38 -> 0 | BB38: =52.374% -> 0.52374 | BE38: 96121.16 | BF38: =BF35*BB38 -> 17099.851 | BG38: =SUM(BE38:BF38) -> 113221.01 | BH38: Seguridad social: para lo reportado mes a mes se registra lo efectivamente pagado (30,54%) sobre el salario mensual percibido por los colaboradores (Salud 8,5%, Pensión 12%, Caja de compensación familiar 4%, ARL 1,044%, Sena 2%, ICBF 3%), el restante exigido por ley se reporta en los periodos en que sea efectivamente pagado (provision de vacaciones (4,17%), provision de prima (8,33%), de ello el valor a cargar mes a mes es de 52,4% sobre el salario mensual percibido, para un total cargado a seguridad social de 52,4%. El valor relacionado comprende las provisiones del año 2022 efectivamente pagado en el año 2023. El valor presentado para el año 2023 incluye provision de cesantias (8,33%), provision de int ces (1%) del año 2022 los cuales fueron efectivamente pagados en el mes de enero de 2023. El valor presentado para el 2023 corresponde a lo efectivamente pagado (30,54%) sobre el salario mas los pagos correspondientes a primas legales , se excluyen los pagos de cesantias e intereses a cesantias para ser sumados en el año 2024 dada la limitación del monto obligado actual | BI38: 0.52374 | BL38: =BL35*BI38 -> 117259.25 | BM38: =BM35*BI38 -> 18697.3 | BN38: =SUM(BL38:BM38) -> 135956.55 | BO38: 0.52374 | BR38: =BR35*BO38 -> 105876.64 | BS38: =BS35*BO38 -> 17491.917 | BT38: =BS38+BR38 -> 123368.56 | BU38: 0.52374 | BX38: =BX35*BU38 -> 39896.399 | BY38: =BY35*BU38 -> 6887.6179 | BZ38: =BY38+BX38 -> 46784.017 | CA38: =BR38+BL38+BE38+BX38 -> 359153.45 | CB38: =BF38+BM38+BS38+BY38 -> 60176.686 | CC38: =CA38+CB38 -> 419330.13 | CE38: =AV38+CA38 -> 424392.25 | CF38: =AW38+CB38 -> 69869.046 | CG38: =CE38+CF38 -> 494261.29 | CH38: =AO38-CE38 -> -242538.63 | CI38: =AP38-CF38 -> -27907.641 | CJ38: =AQ38-CG38 -> -270446.27 | CK38: =SUM(CM38:ES38) -> 270446 | CL38: =CJ38+CK38 -> -0.27229192 | CT38: 217842 | CU38: 27908 | EG38: 24696
E39: 29 | F39: Fringe Benefits Total | N39: =SUM(N37:N38) -> 68799.226 | O39: =SUM(O37:O38) -> 13520.295 | P39: =SUM(P37:P38) -> 82319.521 | T39: =SUM(T37:T38) -> 84668.239 | U39: =SUM(U37:U38) -> 15057.827 | V39: =SUM(V37:V38) -> 99726.066 | Z39: =SUM(Z37:Z38) -> 88054.968 | AA39: =SUM(AA37:AA38) -> 15660.14 | AB39: =SUM(AB37:AB38) -> 103715.11 | AF39: =SUM(AF37:AF38) -> 91577.167 | AG39: =SUM(AG37:AG38) -> 16286.546 | AH39: =SUM(AH37:AH38) -> 107863.71 | AL39: =SUM(AL37:AL38) -> 83109.782 | AM39: =SUM(AM37:AM38) -> 16289.034 | AN39: =SUM(AN37:AN38) -> 99398.816 | AO39: =SUM(AO37:AO38) -> 416209.38 | AP39: =SUM(AP37:AP38) -> 76813.842 | AQ39: =SUM(AO39:AP39) -> 493023.22 | AR39: =AR38+AR37 -> 11993.43 | AS39: =AS38+AS37 -> 4597.54 | AT39: =SUM(AT37:AT38) -> 69759.18 | AU39: =SUM(AU37:AU38) -> 5094.82 | AV39: =SUM(AV37:AV38) -> 81752.61 | AW39: =SUM(AW37:AW38) -> 9692.36 | AX39: =SUM(AX37:AX38) -> 91444.97 | AY39: =SUM(AY37:AY38) -> 401578.25 | AZ39: =AQ39-AR39-AS39-AT39-AU39 -> 401578.25 | BC39: =BC38+BC37 -> 0 | BD39: 0 | BE39: =SUM(BE37:BE38) -> 96121.16 | BF39: =SUM(BF37:BF38) -> 17099.851 | BG39: =SUM(BE39:BF39) -> 113221.01 | BJ39: =BJ38+BJ37 -> 0 | BL39: =SUM(BL37:BL38) -> 117259.25 | BM39: =SUM(BM37:BM38) -> 18697.3 | BN39: =SUM(BL39:BM39) -> 135956.55 | BP39: =BP38+BP37 -> 0 | BR39: =SUM(BR37:BR38) -> 105876.64 | BS39: =BS38+BS37 -> 17491.917 | BT39: =SUM(BR39:BS39) -> 123368.56 | BV39: =BV38 -> 0 | BX39: =BX38 -> 39896.399 | BY39: =BY38 -> 6887.6179 | BZ39: =BZ38 -> 46784.017 | CA39: =BR39+BL39+BE39+BX39 -> 359153.45 | CB39: =BY39+BS39+BM39+BF39 -> 60176.686 | CC39: =BZ39+BT39+BN39+BG39 -> 419330.13 | CE39: =CA39+AT39+AR39 -> 440906.06 | CF39: =CF38+CF37 -> 69869.046 | CG39: =CE39+CF39 -> 510775.1 | CK39: =SUM(CM39:ES39) -> 0 | CL39: =CJ39+CK39 -> 0
E40: 30 | F40: TRAVEL | CK40: =SUM(CM40:ES40) -> 0 | CL40: =CJ40+CK40 -> 0
...

Sheet Hoja1
