Workbook
Name ColumnTitle1: #REF!

Sheet Checklist
A1: Partners of the Americas - Project Closeout Checklist
A2: Award Number and Grant: | C2: Country Office:
A3: Award End Date: | C3: Award Closeout Date:
A4: All projects must follow closeout procedure in accordance to 2 CFR 200.344 and terms of the specific award.
A5: ACTIONS | C5: Complete by Date | D5: Person Responsible | E5: Reviewer/Approver | F5: Status | G5: Remark
A6: Human Resources | B6: Develop staffing plan with termination dates
B7: Amend employee contracts to end by project closing date (or process paperwork for internal transfer)
B8: Pay or accrue final leave balances, severance (if applicable), other fringe benefits (as applicable), & salary payments
B9: Contract termination notice (letter)
B10: Work certification letter
B11: Closure of fringe benefits (social security, pensions, etc.)
B12: End of service Checklist and follow termination process
B13: Exit interview
B14: Final timesheet submitted
B15: Terminate employee contracts
A16: Operation | B16: Compile list of vendors (service, utilities, other) - see utilities checklist tab
B17: Notify vendors of contract/service termination and amend contracts as necessary to close by project end date
B18: Terminate service/vendor/utilities contracts (including electricity, water, gas, phone, Internet, fuel, mobile phones, security, shipping, cleaning, banks). Settle any obligations related to closing your office or other program facilities
B19: Terminate insurance policies
B20: Close petty cash and return funds to bank account
B21: Ensure all payments and refunds are cleared before the bank account is closed
B22: Close bank accounts and send remaining account balance to Home Office
B23: Terminate leases (if appropriate) on rented office space that you do not plan to use after the award. Settle any obligations related to closing your office or other program facilities
B24: Receive refund of security deposit
B25: Receive release letter from landlord
B26: If applicable, determine operational requirements to keep the POA registration open (i.e. annual board meetings, registrations, fees, etc.)
B27: Pay annual operational fees, taxes and registration and send registration documentation to Compliance Team
B28: Review Board of Directors for local office
... B30: Send thank you notes to key contacts in final project week
A31: Finance | B31: Budget for final 12-month project expenses
B32: Update budget for final 6-month project expenses and adjust spending as necessary
B33: Update budget for final 3-month project expenses and adjust spending as necessary
B34: Update budget for final 2-month project expenses and adjust spending as necessary
B35: Update budget for final 1-month project expenses and adjust spending as necessary
B36: Final request for funds submitted to F&A (ensure full amount of award funds are drawn, unless returning funds to USG)
B37: Review expenditures for allowability
B38: Verify that all costs charged to the project are appropriate and in line with the outcomes and/or deliverables
B39: Confirm all expenses have posted and post closeout expenses are accrued
B40: Identify and resolve all outstanding invoices (Accounts Receivable and Accounts Payable), reconcile outstanding advances/payments
B41: Ensure all journal entries and accruals have been completed and processed
...

Sheet Staff Plan
A1: Staff Transition Plan
A2: Name | B2: Position | C2: Termination Date from Project | D2: Notice Required (Y/N) | E2: Notice Date | F2: Transition Plan | G2: Closeout Duties

Sheet Utilities Checklist
A1: Partners of the Americas - Utilities Checklist
A2: Award Number :
A3: Award End Date:
A4: Grant Name: USAID649
A6: Utility or Service | B6: Company name | C6: Last day | D6: Final | E6: Amount paid | F6: Date paid | G6: Deposits | H6: Refund of deposit | I6: Expected | J6: Comments
C7: of service | D7: Invoice Amt | G7: on account | H7: amount | I7: refund date
A8: E.g. Water | B8: Nairobi Water Company | C8: August 31 | D8: KES 50,000 | E8: KES 30,000 | F8: March 31 | G8: KES 20,000 | H8: KES 20,000 | I8: August 15 | J8: Deposit used to offset final bill
A9: Electricity | B9: Guyana Power & Light | C9: 45199 | D9: 45199
A10: Water | B10: Guyana Water Authority | C10: 45199 | D10: 45199
A11: Gas | B11: Nil | C11: Nil | D11: Nil
A12: Telephone | B12: Guyana Telephone & Telegraph | C12: 45199 | D12: 45230
A13: Internet Service Provider | B13: Guyana Telephone & Telegraph | C13: 45199 | D13: 45230
A14: Copier maintenance | C14: 45169 | D14: 45170
A15: Other equip maintenance | C15: Nil | D15: Nil
A16: Fuel - vehicles | B16: Chands Service Station | C16: 45199 | D16: 45206
A17: Fuel - generators | B17: Nil | C17: Nil | D17: Nil
A18: Vehicle maintenance | B18: Patrick Chung | C18: 45169 | D18: 45184
A19: Generator maintenance | B19: Nil | C19: Nil | D19: Nil
A20: Office supplies | B20: Regal Stationery & Computer | C20: 45169 | D20: 45169
A21: Newspaper/magazine | C21: Nil
A22: Bottled water Service | B22: Banks DIH Ltd. | C22: 45199
A23: Kitchen supplies | C23: 45169
A24: Security | C24: NIl
A25: Office Cleaning | B25: Fentola Belgrave | C25: 45199
A26: Garbage collection | C26: Nil
A27: Building maintenance | B27: Vibert Lord | C27: 45199 | D27: 45200

Sheet Inventory Listing
A1: Inventory & Equipment Listing Report
A3: Inventory as of: | C3: 44865
A4: # | B4: Photo | C4: Description of Inventory & Equipment | D4: Condition | E4: Brand | F4: Model | G4: Serial # | H4: Method of Acquisition | I4: Acquisition/ Purchase Date | J4: Purchase Price | K4: % Charged to Grant | L4: Amount Charged to Grant | M4: Current Price | N4: Useful Life in Days | O4: Current Price Charged to Grant | P4: Grant | Q4: Type of Equipment/ Supply | R4: Useful Life | S4: City & Physical Location | T4: Responsible Person | U4: Notes
A5: Equipment (over $5,000 USD)
A6: 1 | L6: =IF(J6="","",(K6*J6)) | M6: =IF(J6="","",((_xlfn.DAYS($C$3,I6))/N6)*J6) | N6: =(IF(J6="","",((VLOOKUP(R6,Sheet1!$B$9:$C$15,2)))*365)) | O6: =IF(J6="","",(K6*M6)) | R6: =IF(Q6="","",(VLOOKUP(Q6,Sheet1!$A$9:$B$15,2)))
A7: 2 | L7: =IF(J7="","",(K7*J7)) | M7: =IF(J7="","",((_xlfn.DAYS($C$3,I7))/N7)*J7) | N7: =(IF(J7="","",((VLOOKUP(R7,Sheet1!$B$9:$C$15,2)))*365)) | O7: =IF(J7="","",(K7*M7)) | R7: =IF(Q7="","",(VLOOKUP(Q7,Sheet1!$A$9:$B$15,2)))
A8: 3 | L8: =IF(J8="","",(K8*J8)) | M8: =IF(J8="","",((_xlfn.DAYS($C$3,I8))/N8)*J8) | N8: =(IF(J8="","",((VLOOKUP(R8,Sheet1!$B$9:$C$15,2)))*365)) | O8: =IF(J8="","",(K8*M8)) | R8: =IF(Q8="","",(VLOOKUP(Q8,Sheet1!$A$9:$B$15,2)))
A9: 4 | L9: =IF(J9="","",(K9*J9)) | M9: =IF(J9="","",((_xlfn.DAYS($C$3,I9))/N9)*J9) | N9: =(IF(J9="","",((VLOOKUP(R9,Sheet1!$B$9:$C$15,2)))*365)) | O9: =IF(J9="","",(K9*M9)) | R9: =IF(Q9="","",(VLOOKUP(Q9,Sheet1!$A$9:$B$15,2)))
A10: 5 | L10: =IF(J10="","",(K10*J10)) | M10: =IF(J10="","",((_xlfn.DAYS($C$3,I10))/N10)*J10) | N10: =(IF(J10="","",((VLOOKUP(R10,Sheet1!$B$9:$C$15,2)))*365)) | O10: =IF(J10="","",(K10*M10)) | R10: =IF(Q10="","",(VLOOKUP(Q10,Sheet1!$A$9:$B$15,2)))
A11: 6 | L11: =IF(J11="","",(K11*J11)) | M11: =IF(J11="","",((_xlfn.DAYS($C$3,I11))/N11)*J11) | N11: =(IF(J11="","",((VLOOKUP(R11,Sheet1!$B$9:$C$15,2)))*365)) | O11: =IF(J11="","",(K11*M11)) | R11: =IF(Q11="","",(VLOOKUP(Q11,Sheet1!$A$9:$B$15,2)))
A12: 7 | L12: =IF(J12="","",(K12*J12)) | M12: =IF(J12="","",((_xlfn.DAYS($C$3,I12))/N12)*J12) | N12: =(IF(J12="","",((VLOOKUP(R12,Sheet1!$B$9:$C$15,2)))*365)) | O12: =IF(J12="","",(K12*M12)) | R12: =IF(Q12="","",(VLOOKUP(Q12,Sheet1!$A$9:$B$15,2)))
A13: 8 | L13: =IF(J13="","",(K13*J13)) | M13: =IF(J13="","",((_xlfn.DAYS($C$3,I13))/N13)*J13) | N13: =(IF(J13="","",((VLOOKUP(R13,Sheet1!$B$9:$C$15,2)))*365)) | O13: =IF(J13="","",(K13*M13)) | R13: =IF(Q13="","",(VLOOKUP(Q13,Sheet1!$A$9:$B$15,2)))
A14: 9 | L14: =IF(J14="","",(K14*J14)) | M14: =IF(J14="","",((_xlfn.DAYS($C$3,I14))/N14)*J14) | N14: =(IF(J14="","",((VLOOKUP(R14,Sheet1!$B$9:$C$15,2)))*365)) | O14: =IF(J14="","",(K14*M14)) | R14: =IF(Q14="","",(VLOOKUP(Q14,Sheet1!$A$9:$B$15,2)))
A15: 10 | L15: =IF(J15="","",(K15*J15)) | M15: =IF(J15="","",((_xlfn.DAYS($C$3,I15))/N15)*J15) | N15: =(IF(J15="","",((VLOOKUP(R15,Sheet1!$B$9:$C$15,2)))*365)) | O15: =IF(J15="","",(K15*M15)) | R15: =IF(Q15="","",(VLOOKUP(Q15,Sheet1!$A$9:$B$15,2)))
A16: Inventory & Supplies (under $5,000 USD)
A17: 1 | L17: =IF(J17="","",(K17*J17)) | M17: =IF(J17="","",((_xlfn.DAYS($C$3,I17))/N17)*J17) | N17: =(IF(J17="","",((VLOOKUP(R17,Sheet1!$B$9:$C$15,2)))*365)) | O17: =IF(J17="","",(K17*M17)) | R17: =IF(Q17="","",(VLOOKUP(Q17,Sheet1!$A$9:$B$15,2)))
A18: 2 | L18: =IF(J18="","",(K18*J18)) | M18: =IF(J18="","",((_xlfn.DAYS($C$3,I18))/N18)*J18) | N18: =(IF(J18="","",((VLOOKUP(R18,Sheet1!$B$9:$C$15,2)))*365)) | O18: =IF(J18="","",(K18*M18)) | R18: =IF(Q18="","",(VLOOKUP(Q18,Sheet1!$A$9:$B$15,2)))
A19: 3 | L19: =IF(J19="","",(K19*J19)) | M19: =IF(J19="","",((_xlfn.DAYS($C$3,I19))/N19)*J19) | N19: =(IF(J19="","",((VLOOKUP(R19,Sheet1!$B$9:$C$15,2)))*365)) | O19: =IF(J19="","",(K19*M19)) | R19: =IF(Q19="","",(VLOOKUP(Q19,Sheet1!$A$9:$B$15,2)))
A20: 4 | L20: =IF(J20="","",(K20*J20)) | M20: =IF(J20="","",((_xlfn.DAYS($C$3,I20))/N20)*J20) | N20: =(IF(J20="","",((VLOOKUP(R20,Sheet1!$B$9:$C$15,2)))*365)) | O20: =IF(J20="","",(K20*M20)) | R20: =IF(Q20="","",(VLOOKUP(Q20,Sheet1!$A$9:$B$15,2)))
A21: 5 | L21: =IF(J21="","",(K21*J21)) | M21: =IF(J21="","",((_xlfn.DAYS($C$3,I21))/N21)*J21) | N21: =(IF(J21="","",((VLOOKUP(R21,Sheet1!$B$9:$C$15,2)))*365)) | O21: =IF(J21="","",(K21*M21)) | R21: =IF(Q21="","",(VLOOKUP(Q21,Sheet1!$A$9:$B$15,2)))
A22: 6 | L22: =IF(J22="","",(K22*J22)) | M22: =IF(J22="","",((_xlfn.DAYS($C$3,I22))/N22)*J22) | N22: =(IF(J22="","",((VLOOKUP(R22,Sheet1!$B$9:$C$15,2)))*365)) | O22: =IF(J22="","",(K22*M22)) | R22: =IF(Q22="","",(VLOOKUP(Q22,Sheet1!$A$9:$B$15,2)))
A23: 7 | L23: =IF(J23="","",(K23*J23)) | M23: =IF(J23="","",((_xlfn.DAYS($C$3,I23))/N23)*J23) | N23: =(IF(J23="","",((VLOOKUP(R23,Sheet1!$B$9:$C$15,2)))*365)) | O23: =IF(J23="","",(K23*M23)) | R23: =IF(Q23="","",(VLOOKUP(Q23,Sheet1!$A$9:$B$15,2)))
A24: 8 | L24: =IF(J24="","",(K24*J24)) | M24: =IF(J24="","",((_xlfn.DAYS($C$3,I24))/N24)*J24) | N24: =(IF(J24="","",((VLOOKUP(R24,Sheet1!$B$9:$C$15,2)))*365)) | O24: =IF(J24="","",(K24*M24)) | R24: =IF(Q24="","",(VLOOKUP(Q24,Sheet1!$A$9:$B$15,2)))
A25: 9 | L25: =IF(J25="","",(K25*J25)) | M25: =IF(J25="","",((_xlfn.DAYS($C$3,I25))/N25)*J25) | N25: =(IF(J25="","",((VLOOKUP(R25,Sheet1!$B$9:$C$15,2)))*365)) | O25: =IF(J25="","",(K25*M25)) | R25: =IF(Q25="","",(VLOOKUP(Q25,Sheet1!$A$9:$B$15,2)))
A26: 10 | L26: =IF(J26="","",(K26*J26)) | M26: =IF(J26="","",((_xlfn.DAYS($C$3,I26))/N26)*J26) | N26: =(IF(J26="","",((VLOOKUP(R26,Sheet1!$B$9:$C$15,2)))*365)) | O26: =IF(J26="","",(K26*M26)) | R26: =IF(Q26="","",(VLOOKUP(Q26,Sheet1!$A$9:$B$15,2)))
A27: 11 | L27: =IF(J27="","",(K27*J27)) | M27: =IF(J27="","",((_xlfn.DAYS($C$3,I27))/N27)*J27) | N27: =(IF(J27="","",((VLOOKUP(R27,Sheet1!$B$9:$C$15,2)))*365)) | O27: =IF(J27="","",(K27*M27)) | R27: =IF(Q27="","",(VLOOKUP(Q27,Sheet1!$A$9:$B$15,2)))
A28: 12 | L28: =IF(J28="","",(K28*J28)) | M28: =IF(J28="","",((_xlfn.DAYS($C$3,I28))/N28)*J28) | N28: =(IF(J28="","",((VLOOKUP(R28,Sheet1!$B$9:$C$15,2)))*365)) | O28: =IF(J28="","",(K28*M28)) | R28: =IF(Q28="","",(VLOOKUP(Q28,Sheet1!$A$9:$B$15,2)))
... A36: 20 | L36: =IF(J36="","",(K36*J36)) | M36: =IF(J36="","",((_xlfn.DAYS($C$3,I36))/N36)*J36) | N36: =(IF(J36="","",((VLOOKUP(R36,Sheet1!$B$9:$C$15,2)))*365)) | O36: =IF(J36="","",(K36*M36)) | R36: =IF(Q36="","",(VLOOKUP(Q36,Sheet1!$A$9:$B$15,2)))
A37: Total | J37: =SUM(J6:J15,J17:J36) -> 0 | L37: =SUM(L6:L15,L17:L36) -> 0 | M37: =SUM(M6:M15,M17:M36) -> 0 | O37: =SUM(O6:O15,O17:O36) -> 0 | R37: =IF(Q37="","",(VLOOKUP(Q37,Sheet1!$A$9:$B$15,2)))
A40: Submitted by: | D40: Date:
A43: Signature:

Sheet Sheet1
A2: New
A3: Good
A4: Bad
A5: Damaged
A6: Lost
A9: Computer/LaptopTablet | B9: 4 Years | C9: 4
A10: Furniture | B10: 8 Years | C10: 8
A11: General Supplies | B11: 1 Year | C11: 1
A12: Other Equipment ($5K+) | B12: 10 Years | C12: 10
A13: Printer/Projector/Camera, etc. | B13: 4 Years | C13: 4
A14: Telecommunications/Phone | B14: 4 Years | C14: 4
A15: Vehicle | B15: 5 Years | C15: 5
A18: Purchased
A19: Donated
