Workbook
Name \A: #REF!
Name \A: #REF!
Name \P: #REF!
Name \P: #REF!
Name \S: #REF!
Name \S: #REF!
Name _______sho1: '[3]Detailed Budget-SAVE'!#REF!
Name _______sho1: #REF!
Name __2DAI_1: #N/A
Name __3FEE: #N/A
Name __AFP1: #N/A
Name __AFP2: #N/A
Name __AFP3: #N/A
Name __AFP4: #N/A
Name __AMP1: #N/A
Name __AMP2: #N/A
Name __AMP3: #N/A
Name __AMP4: #N/A
Name __DAI4: #N/A
Name __EES1: #N/A
Name __EES2: #N/A
Name __EES3: #N/A
Name __EES4: #N/A
Name __EXT1: #N/A
Name __EXT2: #N/A
Name __EXT3: #N/A
Name __EXT4: #N/A
Name __FCP1: #N/A
Name __FCP2: #N/A
Name __FCP3: #N/A
Name __FCP4: #N/A
Name __FRI1: #N/A
Name __FRI4: #N/A
Name __HRA1: #N/A
Name __HRA2: #N/A
Name __HRA3: #N/A
Name __HRA4: #N/A
Name __inf1: #REF!
Name __inf1: #REF!
Name __LT4: [4]Parameters!$B$40
Name __LT4: #REF!
Name __ODC1: #N/A
Name __ODC2: #N/A
Name __POL1: #N/A
Name __POL2: #N/A
Name __POL3: #N/A
Name __POL4: #N/A
Name __TOT1: #N/A
Name __TOT2: #N/A
Name __TRV1: #N/A
Name __TRV2: #N/A
Name _060: #REF!
Name _060: #REF!
Name _1_1: #REF!
Name _1_1: #REF!
Name _13th_and_14th_month: [5]Parameters!$D$62
Name _13th_and_14th_month: #REF!
Name _2_1034: #REF!
Name _2_1034: #REF!
Name _2DAI_1: #N/A

Sheet USDA Budget Summary
A1: Attachment C-1
A2: Budget Summary
A4: Program (FFPr or MGD): | B4: MGD
A5: Country of Operation: | B5: Honduras
A6: Implementing Organization: | B6: Partners of the Americas Inc.
A7: Fiscal Year: | B7: 2025
A8: Agreement Number: | B8: USDA-FAS-10.608-0700-25-(522)
A10: Total Amount of Federal Funds Requested
A11: Funding Source (FAS for MGD) (CCC for FFPr) | B11: Funding Year | C11: Commodity Cost | D11: Freight Cost | E11: Project Operating Cost | F11: Total Federal Funding Obligated | G11: Original Agreement Total | H11: Difference
B12: 2025 | C12: 9958720 | D12: 2511080 | E12: =E68 -> 27530200 | F12: =E12+D12+C12 -> 40000000
A14: Project Operating Budget
A15: Expense Type | B15: Monetization Proceeds (FFPr Only) | C15: FAS or CCC Funds (CCC is Admin Only) | D15: Cost Share | E15: Total w/out Cost Share | F15: Total w/Cost Share
A16: Administration
A17: Salaries/Personnel | B17: 0 | C17: ='Program Budget'!Y53 -> 5286497.8 | D17: ='Program Budget'!Z53 -> 0 | E17: =B17+C17 -> 5286497.8 | F17: =B17+C17+D17 -> 5286497.8 | G17: 2402720.4 | H17: =F17-G17 -> 2883777.4
A18: Benefits | B18: 0 | C18: ='Program Budget'!Y59 -> 2027171 | D18: ='Program Budget'!Z59 -> 0 | E18: =B18+C18 -> 2027171 | F18: =B18+C18+D18 -> 2027171 | G18: 659056.67 | H18: =F18-G18 -> 1368114.3
A19: Travel | B19: 0 | C19: ='Program Budget'!Y80 -> 368758.3 | D19: ='Program Budget'!Z80 -> 0 | E19: =B19+C19 -> 368758.3 | F19: =B19+C19+D19 -> 368758.3 | G19: 368758.3 | H19: =F19-G19 -> 0.0027323751
A20: Professional Services/Contractual | B20: 0 | C20: ='Program Budget'!Y101 -> 1116800 | D20: ='Program Budget'!Z101 -> 0 | E20: =B20+C20 -> 1116800 | F20: =B20+C20+D20 -> 1116800 | G20: 1082000 | H20: =F20-G20 -> 34800
A21: Equipment | B21: 0 | C21: ='Program Budget'!Y106 -> 53000 | D21: ='Program Budget'!Z106 -> 0 | E21: =B21+C21 -> 53000 | F21: =B21+C21+D21 -> 53000 | G21: 159000 | H21: =F21-G21 -> -106000
A22: Supplies | B22: 0 | C22: ='Program Budget'!Y121 -> 82190.637 | D22: ='Program Budget'!Z121 -> 0 | E22: =B22+C22 -> 82190.637 | F22: =B22+C22+D22 -> 82190.637 | G22: 91027.43 | H22: =F22-G22 -> -8836.7925
A23: Other | B23: 0 | C23: ='Program Budget'!Y148 -> 646819.51 | D23: ='Program Budget'!Z148 -> 0 | E23: =B23+C23 -> 646819.51 | F23: =B23+C23+D23 -> 646819.51 | G23: 640169.34 | H23: =F23-G23 -> 6650.1702
A24: Total Administration | B24: =SUM(B17:B23) -> 0 | C24: =SUM(C17:C23) -> 9581237.2 | D24: =SUM(D17:D23) -> 0 | E24: =SUM(E17:E23) -> 9581237.2 | F24: =SUM(F17:F23) -> 9581237.2 | G24: 5402732.1 | H24: =F24-G24 -> 4178505.1 | J24: 9715046.9 | K24: =J24-F24 -> 133809.69
A26: Activities
A27: Activity 1: Provide School Meals | B27: 0 | C27: ='Program Budget'!Y210 -> 658976.11 | D27: ='Program Budget'!Z210 -> 187000 | E27: =B27+C27 -> 658976.11 | F27: =B27+C27+D27 -> 845976.11 | G27: 1161155.5 | H27: =F27-G27 -> -315179.41
A28: Activity 2: Distribution: School Supplies and Materials | B28: 0 | C28: ='Program Budget'!Y269 -> 407143.18 | D28: ='Program Budget'!Z269 -> 0 | E28: =B28+C28 -> 407143.18 | F28: =B28+C28+D28 -> 407143.18 | G28: 750076.07 | H28: =F28-G28 -> -342932.89
A29: Activity 3: Training: Teacher and Administrators | B29: 0 | C29: ='Program Budget'!Y338 -> 2400715.2 | D29: ='Program Budget'!Z338 -> 0 | E29: =B29+C29 -> 2400715.2 | F29: =B29+C29+D29 -> 2400715.2 | G29: 2723500.9 | H29: =F29-G29 -> -322785.68
A30: Activity 4: Enrollment Campaigns | B30: 0 | C30: ='Program Budget'!Y405 -> 629594.49 | D30: ='Program Budget'!Z405 -> 0 | E30: =B30+C30 -> 629594.49 | F30: =B30+C30+D30 -> 629594.49 | G30: 935164.19 | H30: =F30-G30 -> -305569.7
A31: Activity 5: Building/Rehabilitation: Wells and Water Stations/Systems | B31: 0 | C31: ='Program Budget'!Y477 -> 520716.18 | D31: ='Program Budget'!Z477 -> 182500 | E31: =B31+C31 -> 520716.18 | F31: =B31+C31+D31 -> 703216.18 | G31: 1011819.9 | H31: =F31-G31 -> -308603.68
A32: Activity 6: Training: Good Health and Nutrition Practices | B32: 0 | C32: ='Program Budget'!Y552 -> 1056867.1 | D32: ='Program Budget'!Z552 -> 0 | E32: =B32+C32 -> 1056867.1 | F32: =B32+C32+D32 -> 1056867.1 | G32: 1251376.6 | H32: =F32-G32 -> -194509.49
A33: Activity 7: Training: Commodity Management | B33: 0 | C33: ='Program Budget'!Y607 -> 357568.95 | D33: ='Program Budget'!Z607 -> 0 | E33: =B33+C33 -> 357568.95 | F33: =B33+C33+D33 -> 357568.95 | G33: 951532.38 | H33: =F33-G33 -> -593963.43
A34: Activity 8: Capacity Building: Local and Regional Level | B34: 0 | C34: ='Program Budget'!Y681 -> 365869.91 | D34: ='Program Budget'!Z681 -> 11500 | E34: =B34+C34 -> 365869.91 | F34: =B34+C34+D34 -> 377369.91 | G34: 689004.77 | H34: =F34-G34 -> -311634.86
A35: Activity 9: Capacity Building: National Level | B35: 0 | C35: ='Program Budget'!Y755 -> 425854.9 | D35: ='Program Budget'!Z755 -> 0 | E35: =B35+C35 -> 425854.9 | F35: =B35+C35+D35 -> 425854.9 | G35: 632635.61 | H35: =F35-G35 -> -206780.71
A36: Activity 10: Develop Public-Private Partnerships to Support School Feeding Sustainability | B36: 0 | C36: ='Program Budget'!Y827 -> 462935.92 | D36: ='Program Budget'!Z827 -> 21000 | E36: =B36+C36 -> 462935.92 | F36: =B36+C36+D36 -> 483935.92 | G36: 807880.29 | H36: =F36-G36 -> -323944.37
A37: Activity 11: Expand Use of US Commodities in Honduras School Feeding Program | B37: 0 | C37: ='Program Budget'!Y886 -> 89328.663 | D37: ='Program Budget'!Z886 -> 4980 | E37: =B37+C37 -> 89328.663 | F37: =B37+C37+D37 -> 94308.663 | G37: 424932.75 | H37: =F37-G37 -> -330624.09
A38: Total Activities | B38: =SUM(B27:B37) -> 0 | C38: =SUM(C27:C37) -> 7375570.6 | D38: =SUM(D27:D37) -> 406980 | E38: =SUM(E27:E37) -> 7375570.6 | F38: =SUM(F27:F37) -> 7782550.6 | G38: 11339079 | H38: =F38-G38 -> -3556528.3
A40: Commodity and Food Purchases (N/A to FFPr)
A41: Commodity Procurement | B41: 0 | C41: ='Program Budget'!Y978 -> 3282393.1 | D41: ='Program Budget'!Z978 -> 0 | E41: =B41+C41 -> 3282393.1 | F41: =B41+C41+D41 -> 3282393.1
A42: Food Vouchers (N/A to MGD)
A43: Cash Transfers (N/A to MGD)
A44: Total Commodity Procurement | B44: =SUM(B41:B43) -> 0 | C44: =SUM(C41:C43) -> 3282393.1 | D44: =SUM(D41:D43) -> 0 | E44: =SUM(E41:E43) -> 3282393.1 | F44: =SUM(F41:F43) -> 3282393.1 | G44: 3136470 | H44: =F44-G44 -> 145923.11 | I44: =F44/C68 -> 0.11922881 | J44: =C44+C55 -> 5985025.6
J45: =J44*20% -> 1197005.1
...

Sheet Program Budget
D1: Partners of the Americas – FY 2025 McGovern-Dole Honduras
D2: NOFO: USDA-FAS-10.608-0700-25-(522)
D3: Duration: 6 Years
D4: Country: Honduras
D5: Budget Assumptions:
A6: Program/Dept.: | B6: 20300 | D6: Inflation Increases- 5% | E6: 1.05
A7: Funder Grant: | B7: USDA801 | D7: Merit Based Increases for HQ & Field Staff | E7: 1.05
A9: Activity Code | B9: Account Code | C9: Country Code | D9: BUDGET ITEM | E9: Level of Effort (LOE) Year 1 | F9: UNIT | G9: # of Units | H9: RATE/ UNIT | I9: YEAR 1 | J9: Level of Effort (LOE) Year 2 | K9: # of Units | L9: YEAR 2 | M9: Level of Effort (LOE) Year 3 | N9: # of Units | O9: YEAR 3 | P9: Level of Effort (LOE) Year 4 | Q9: # of Units | R9: YEAR 4 | S9: Level of Effort (LOE) Year 5 | T9: # of Units | U9: YEAR 5 | V9: Level of Effort (LOE) Year 6 | W9: # of Units | X9: YEAR 6 | Y9: TOTAL USDA | Z9: TOTAL COST SHARE | AA9: PROJECT GRAND TOTAL
D10: Salaries/Personnel (Administration)
D11: CCN Honduran Field Staff (LOE)
A12: PERADMNCOP | B12: 70000 | C12: HND | D12: Key Personnel: Chief of Party - Roger Sanchez O’Neill | E12: ='LOE Breakdown by Year'!D11 -> 1 | F12: Month | G12: 11 | H12: =115000/12 -> 9583.3333 | I12: =G12*H12*E12 -> 105416.67 | J12: ='LOE Breakdown by Year'!D57 -> 1 | K12: 12 | L12: =K12*H12*$E$7*$J12 -> 120750 | M12: ='LOE Breakdown by Year'!D103 -> 1 | N12: 12 | O12: =N12*H12*$M12*$E$7*$E$7 -> 126787.5 | P12: ='LOE Breakdown by Year'!D149 -> 1 | Q12: 12 | R12: =Q12*H12*$P12*$E$7*$E$7*$E$7 -> 133126.88 | S12: ='LOE Breakdown by Year'!D195 -> 1 | T12: 12 | U12: =T12*H12*$S12*$E$7*$E$7*$E$7*$E$7 -> 139783.22 | V12: ='LOE Breakdown by Year'!D241 -> 1 | W12: 12 | X12: =W12*H12*$V12*$E$7*$E$7*$E$7*$E$7*$E$7 -> 146772.38 | Y12: =SUM(R12,O12,L12,I12,U12,X12) -> 772636.64 | Z12: 0 | AA12: =SUM(Y12:Z12) -> 772636.64
A13: PERADMNDOP | B13: 70000 | C13: HND | D13: Key Personnel: Deputy Chief of Party - David Medina Mayo | E13: ='LOE Breakdown by Year'!D12 -> 1 | F13: Month | G13: 11 | H13: =78000/12 -> 6500 | I13: =G13*H13*E13 -> 71500 | J13: ='LOE Breakdown by Year'!D58 -> 1 | K13: 12 | L13: =K13*H13*$E$7*$J13 -> 81900 | M13: ='LOE Breakdown by Year'!D104 -> 1 | N13: 12 | O13: =N13*H13*$M13*$E$7*$E$7 -> 85995 | P13: ='LOE Breakdown by Year'!D150 -> 1 | Q13: 12 | R13: =Q13*H13*$P13*$E$7*$E$7*$E$7 -> 90294.75 | S13: ='LOE Breakdown by Year'!D196 -> 1 | T13: 12 | U13: =T13*H13*$S13*$E$7*$E$7*$E$7*$E$7 -> 94809.488 | V13: ='LOE Breakdown by Year'!D242 -> 1 | W13: 12 | X13: =W13*H13*$V13*$E$7*$E$7*$E$7*$E$7*$E$7 -> 99549.962 | Y13: =SUM(R13,O13,L13,I13,U13,X13) -> 524049.2 | Z13: 0 | AA13: =SUM(Y13:Z13) -> 524049.2
A14: PERADMNPOL | B14: 70000 | C14: HND | D14: Policy & Sustainability Specialist | E14: ='LOE Breakdown by Year'!D13 -> 0 | F14: Month | G14: 0 | H14: =18000/12 -> 1500 | I14: =G14*H14*E14 -> 0 | J14: ='LOE Breakdown by Year'!D59 -> 0 | K14: 0 | L14: =K14*H14*$E$7*$J14 -> 0 | M14: ='LOE Breakdown by Year'!D105 -> 0 | N14: 7 | O14: =N14*H14*$M14*$E$7*$E$7 -> 0 | P14: ='LOE Breakdown by Year'!D151 -> 0 | Q14: 12 | R14: =Q14*H14*$P14*$E$7*$E$7*$E$7 -> 0 | S14: ='LOE Breakdown by Year'!D197 -> 0 | T14: 12 | U14: =T14*H14*$S14*$E$7*$E$7*$E$7*$E$7 -> 0 | V14: ='LOE Breakdown by Year'!D243 -> 0 | W14: 6 | X14: =W14*H14*$V14*$E$7*$E$7*$E$7*$E$7*$E$7 -> 0 | Y14: =SUM(R14,O14,L14,I14,U14,X14) -> 0 | Z14: 0 | AA14: =SUM(Y14:Z14) -> 0
A15: PERADMNEDD | B15: 70000 | C15: HND | D15: Education Director | E15: ='LOE Breakdown by Year'!D14 -> 0 | F15: Month | G15: 9 | H15: =55000/12 -> 4583.3333 | I15: =G15*H15*E15 -> 0 | J15: ='LOE Breakdown by Year'!D60 -> 0 | K15: 12 | L15: =K15*H15*$E$7*$J15 -> 0 | M15: ='LOE Breakdown by Year'!D106 -> 0 | N15: 12 | O15: =N15*H15*$M15*$E$7*$E$7 -> 0 | P15: ='LOE Breakdown by Year'!D152 -> 0 | Q15: 12 | R15: =Q15*H15*$P15*$E$7*$E$7*$E$7 -> 0 | S15: ='LOE Breakdown by Year'!D198 -> 0 | T15: 12 | U15: =T15*H15*$S15*$E$7*$E$7*$E$7*$E$7 -> 0 | V15: ='LOE Breakdown by Year'!D244 -> 0 | W15: 8 | X15: =W15*H15*$V15*$E$7*$E$7*$E$7*$E$7*$E$7 -> 0 | Y15: =SUM(R15,O15,L15,I15,U15,X15) -> 0 | Z15: 0 | AA15: =SUM(Y15:Z15) -> 0
A16: PERADMNEDS | B16: 70000 | C16: HND | D16: Education Specialist | E16: ='LOE Breakdown by Year'!D15 -> 0 | F16: Month | G16: 8 | H16: =30000/12 -> 2500 | I16: =G16*H16*E16 -> 0 | J16: ='LOE Breakdown by Year'!D61 -> 0 | K16: 12 | L16: =K16*H16*$E$7*$J16 -> 0 | M16: ='LOE Breakdown by Year'!D107 -> 0 | N16: 12 | O16: =N16*H16*$M16*$E$7*$E$7 -> 0 | P16: ='LOE Breakdown by Year'!D153 -> 0 | Q16: 12 | R16: =Q16*H16*$P16*$E$7*$E$7*$E$7 -> 0 | S16: ='LOE Breakdown by Year'!D199 -> 0 | T16: 12 | U16: =T16*H16*$S16*$E$7*$E$7*$E$7*$E$7 -> 0 | V16: ='LOE Breakdown by Year'!D245 -> 0 | W16: 3 | X16: =W16*H16*$V16*$E$7*$E$7*$E$7*$E$7*$E$7 -> 0 | Y16: =SUM(R16,O16,L16,I16,U16,X16) -> 0 | Z16: 0 | AA16: =SUM(Y16:Z16) -> 0
A17: PERADMNEDO | B17: 70000 | C17: HND | D17: Education Officer | E17: ='LOE Breakdown by Year'!D16 -> 0 | F17: Month | G17: =6 -> 6 | H17: =(12000/12) -> 1000 | I17: =G17*H17*E17 -> 0 | J17: ='LOE Breakdown by Year'!D62 -> 0 | K17: =12 -> 12 | L17: =K17*H17*$E$7*$J17 -> 0 | M17: ='LOE Breakdown by Year'!D108 -> 0 | N17: =12 -> 12 | O17: =N17*H17*$M17*$E$7*$E$7 -> 0 | P17: ='LOE Breakdown by Year'!D154 -> 0 | Q17: =12 -> 12 | R17: =Q17*H17*$P17*$E$7*$E$7*$E$7 -> 0 | S17: ='LOE Breakdown by Year'!D200 -> 0 | T17: =12 -> 12 | U17: =T17*H17*$S17*$E$7*$E$7*$E$7*$E$7 -> 0 | V17: ='LOE Breakdown by Year'!D246 -> 0 | W17: 3 | X17: =W17*H17*$V17*$E$7*$E$7*$E$7*$E$7*$E$7 -> 0 | Y17: =SUM(R17,O17,L17,I17,U17,X17) -> 0 | Z17: 0 | AA17: =SUM(Y17:Z17) -> 0
A18: PERADMNNHS | B18: 70000 | C18: HND | D18: Nutrition and Health Specialist | E18: ='LOE Breakdown by Year'!D17 -> 0 | F18: Month | G18: 9 | H18: =18000/12 -> 1500 | I18: =G18*H18*E18 -> 0 | J18: ='LOE Breakdown by Year'!D63 -> 0 | K18: 12 | L18: =K18*H18*$E$7*$J18 -> 0 | M18: ='LOE Breakdown by Year'!D109 -> 0 | N18: 12 | O18: =N18*H18*$M18*$E$7*$E$7 -> 0 | P18: ='LOE Breakdown by Year'!D155 -> 0 | Q18: 12 | R18: =Q18*H18*$P18*$E$7*$E$7*$E$7 -> 0 | S18: ='LOE Breakdown by Year'!D201 -> 0 | T18: 12 | U18: =T18*H18*$S18*$E$7*$E$7*$E$7*$E$7 -> 0 | V18: ='LOE Breakdown by Year'!D247 -> 0 | W18: 6 | X18: =W18*H18*$V18*$E$7*$E$7*$E$7*$E$7*$E$7 -> 0 | Y18: =SUM(R18,O18,L18,I18,U18,X18) -> 0 | Z18: 0 | AA18: =SUM(Y18:Z18) -> 0
A19: PERADMNNOF | B19: 70000 | C19: HND | D19: Nutrition Officer - (2 Individuals) | E19: ='LOE Breakdown by Year'!D18 -> 0 | F19: Month | G19: =2*3 -> 6 | H19: =(12000/12) -> 1000 | I19: =G19*H19*E19 -> 0 | J19: ='LOE Breakdown by Year'!D64 -> 0 | K19: =2*12 -> 24 | L19: =K19*H19*$E$7*$J19 -> 0 | M19: ='LOE Breakdown by Year'!D110 -> 0 | N19: =2*12 -> 24 | O19: =N19*H19*$M19*$E$7*$E$7 -> 0 | P19: ='LOE Breakdown by Year'!D156 -> 0 | Q19: =2*12 -> 24 | R19: =Q19*H19*$P19*$E$7*$E$7*$E$7 -> 0 | S19: ='LOE Breakdown by Year'!D202 -> 0 | T19: =2*12 -> 24 | U19: =T19*H19*$S19*$E$7*$E$7*$E$7*$E$7 -> 0 | V19: ='LOE Breakdown by Year'!D248 -> 0 | W19: =2*3 -> 6 | X19: =W19*H19*$V19*$E$7*$E$7*$E$7*$E$7*$E$7 -> 0 | Y19: =SUM(R19,O19,L19,I19,U19,X19) -> 0 | Z19: 0 | AA19: =SUM(Y19:Z19) -> 0
A20: PERADMNSFS | B20: 70000 | C20: HND | D20: School Feeding Specialist | E20: ='LOE Breakdown by Year'!D19 -> 0 | F20: Month | G20: 9 | H20: =18000/12 -> 1500 | I20: =G20*H20*E20 -> 0 | J20: ='LOE Breakdown by Year'!D65 -> 0 | K20: 12 | L20: =K20*H20*$E$7*$J20 -> 0 | M20: ='LOE Breakdown by Year'!D111 -> 0 | N20: 12 | O20: =N20*H20*$M20*$E$7*$E$7 -> 0 | P20: ='LOE Breakdown by Year'!D157 -> 0 | Q20: 12 | R20: =Q20*H20*$P20*$E$7*$E$7*$E$7 -> 0 | S20: ='LOE Breakdown by Year'!D203 -> 0 | T20: 6 | U20: =T20*H20*$S20*$E$7*$E$7*$E$7*$E$7 -> 0 | V20: ='LOE Breakdown by Year'!D249 -> 0 | W20: 6 | X20: =W20*H20*$V20*$E$7*$E$7*$E$7*$E$7*$E$7 -> 0 | Y20: =SUM(R20,O20,L20,I20,U20,X20) -> 0 | Z20: 0 | AA20: =SUM(Y20:Z20) -> 0
A21: PERADMNFAM | B21: 70000 | C21: HND | D21: Food Aid Monitors - (2 Individuals) | E21: ='LOE Breakdown by Year'!D20 -> 0 | F21: Month | G21: =2*3 -> 6 | H21: =(12000/12) -> 1000 | I21: =G21*H21*E21 -> 0 | J21: ='LOE Breakdown by Year'!D66 -> 0 | K21: =2*12 -> 24 | L21: =K21*H21*$E$7*$J21 -> 0 | M21: ='LOE Breakdown by Year'!D112 -> 0 | N21: =2*12 -> 24 | O21: =N21*H21*$M21*$E$7*$E$7 -> 0 | P21: ='LOE Breakdown by Year'!D158 -> 0 | Q21: =2*12 -> 24 | R21: =Q21*H21*$P21*$E$7*$E$7*$E$7 -> 0 | S21: ='LOE Breakdown by Year'!D204 -> 0 | T21: =2*12 -> 24 | U21: =T21*H21*$S21*$E$7*$E$7*$E$7*$E$7 -> 0 | V21: ='LOE Breakdown by Year'!D250 -> 0 | W21: =2*6 -> 12 | X21: =W21*H21*$V21*$E$7*$E$7*$E$7*$E$7*$E$7 -> 0 | Y21: =SUM(R21,O21,L21,I21,U21,X21) -> 0 | Z21: 0 | AA21: =SUM(Y21:Z21) -> 0
A22: PERADMNWAS | B22: 70000 | C22: HND | D22: WASH Officer | E22: ='LOE Breakdown by Year'!D21 -> 0 | F22: Month | G22: 6 | H22: =(12000/12) -> 1000 | I22: =G22*H22*E22 -> 0 | J22: ='LOE Breakdown by Year'!D67 -> 0 | K22: 12 | L22: =K22*H22*$E$7*$J22 -> 0 | M22: ='LOE Breakdown by Year'!D113 -> 0 | N22: 12 | O22: =N22*H22*$M22*$E$7*$E$7 -> 0 | P22: ='LOE Breakdown by Year'!D159 -> 0 | Q22: 12 | R22: =Q22*H22*$P22*$E$7*$E$7*$E$7 -> 0 | S22: ='LOE Breakdown by Year'!D205 -> 0 | T22: 12 | U22: =T22*H22*$S22*$E$7*$E$7*$E$7*$E$7 -> 0 | V22: ='LOE Breakdown by Year'!D251 -> 0 | W22: 3 | X22: =W22*H22*$V22*$E$7*$E$7*$E$7*$E$7*$E$7 -> 0 | Y22: =SUM(R22,O22,L22,I22,U22,X22) -> 0 | Z22: 0 | AA22: =SUM(Y22:Z22) -> 0
A23: PERADMNCMS | B23: 70000 | C23: HND | D23: Communications Specialist | E23: ='LOE Breakdown by Year'!D22 -> 0.5 | F23: Month | G23: 8 | H23: 1500 | I23: =G23*H23*E23 -> 6000 | J23: ='LOE Breakdown by Year'!D68 -> 0.5 | K23: 12 | L23: =K23*H23*$E$7*$J23 -> 9450 | M23: ='LOE Breakdown by Year'!D114 -> 0.5 | N23: 12 | O23: =N23*H23*$M23*$E$7*$E$7 -> 9922.5 | P23: ='LOE Breakdown by Year'!D160 -> 0.5 | Q23: 12 | R23: =Q23*H23*$P23*$E$7*$E$7*$E$7 -> 10418.625 | S23: ='LOE Breakdown by Year'!D206 -> 0.5 | T23: 12 | U23: =T23*H23*$S23*$E$7*$E$7*$E$7*$E$7 -> 10939.556 | V23: ='LOE Breakdown by Year'!D252 -> 0.5 | W23: 8 | X23: =W23*H23*$V23*$E$7*$E$7*$E$7*$E$7*$E$7 -> 7657.6894 | Y23: =SUM(R23,O23,L23,I23,U23,X23) -> 54388.371 | Z23: 0 | AA23: =SUM(Y23:Z23) -> 54388.371
A24: PERADMNCMO | B24: 70000 | C24: HND | D24: Communications Officer | E24: ='LOE Breakdown by Year'!D23 -> 0 | F24: Month | G24: 0 | H24: =12000/12 -> 1000 | I24: =G24*H24*E24 -> 0 | J24: ='LOE Breakdown by Year'!D69 -> 0 | K24: 12 | L24: =K24*H24*$E$7*$J24 -> 0 | M24: ='LOE Breakdown by Year'!D115 -> 0 | N24: 12 | O24: =N24*H24*$M24*$E$7*$E$7 -> 0 | P24: ='LOE Breakdown by Year'!D161 -> 0 | Q24: 12 | R24: =Q24*H24*$P24*$E$7*$E$7*$E$7 -> 0 | S24: ='LOE Breakdown by Year'!D207 -> 0 | T24: 12 | U24: =T24*H24*$S24*$E$7*$E$7*$E$7*$E$7 -> 0 | V24: ='LOE Breakdown by Year'!D253 -> 0 | W24: 0 | X24: =W24*H24*$V24*$E$7*$E$7*$E$7*$E$7*$E$7 -> 0 | Y24: =SUM(R24,O24,L24,I24,U24,X24) -> 0 | Z24: 0 | AA24: =SUM(Y24:Z24) -> 0
A25: PERADMNECS | B25: 70000 | C25: HND | D25: Education & Community Engagement Specialist | E25: ='LOE Breakdown by Year'!D24 -> 0 | F25: Month | G25: 6 | H25: =18000/12 -> 1500 | I25: =G25*H25*E25 -> 0 | J25: ='LOE Breakdown by Year'!D70 -> 0 | K25: 12 | L25: =K25*H25*$E$7*$J25 -> 0 | M25: ='LOE Breakdown by Year'!D116 -> 0 | N25: 12 | O25: =N25*H25*$M25*$E$7*$E$7 -> 0 | P25: ='LOE Breakdown by Year'!D162 -> 0 | Q25: 12 | R25: =Q25*H25*$P25*$E$7*$E$7*$E$7 -> 0 | S25: ='LOE Breakdown by Year'!D208 -> 0 | T25: 12 | U25: =T25*H25*$S25*$E$7*$E$7*$E$7*$E$7 -> 0 | V25: ='LOE Breakdown by Year'!D254 -> 0 | W25: 8 | X25: =W25*H25*$V25*$E$7*$E$7*$E$7*$E$7*$E$7 -> 0 | Y25: =SUM(R25,O25,L25,I25,U25,X25) -> 0 | Z25: 0 | AA25: =SUM(Y25:Z25) -> 0
A26: PERADMNECO | B26: 70000 | C26: HND | D26: Education & Community Engagement Officer | E26: ='LOE Breakdown by Year'!D25 -> 0 | F26: Month | G26: 3 | H26: =12000/12 -> 1000 | I26: =G26*H26*E26 -> 0 | J26: ='LOE Breakdown by Year'!D71 -> 0 | K26: 12 | L26: =K26*H26*$E$7*$J26 -> 0 | M26: ='LOE Breakdown by Year'!D117 -> 0 | N26: 12 | O26: =N26*H26*$M26*$E$7*$E$7 -> 0 | P26: ='LOE Breakdown by Year'!D163 -> 0 | Q26: 12 | R26: =Q26*H26*$P26*$E$7*$E$7*$E$7 -> 0 | S26: ='LOE Breakdown by Year'!D209 -> 0 | T26: 12 | U26: =T26*H26*$S26*$E$7*$E$7*$E$7*$E$7 -> 0 | V26: ='LOE Breakdown by Year'!D255 -> 0 | W26: 0 | X26: =W26*H26*$V26*$E$7*$E$7*$E$7*$E$7*$E$7 -> 0 | Y26: =SUM(R26,O26,L26,I26,U26,X26) -> 0 | Z26: 0 | AA26: =SUM(Y26:Z26) -> 0
A27: PERADMNPSS | B27: 70000 | C27: HND | D27: Private Sector Specialist | E27: ='LOE Breakdown by Year'!D26 -> 0 | F27: Month | G27: 9 | H27: =24000/12 -> 2000 | I27: =G27*H27*E27 -> 0 | J27: ='LOE Breakdown by Year'!D72 -> 0 | K27: 12 | L27: =K27*H27*$E$7*$J27 -> 0 | M27: ='LOE Breakdown by Year'!D118 -> 0 | N27: 12 | O27: =N27*H27*$M27*$E$7*$E$7 -> 0 | P27: ='LOE Breakdown by Year'!D164 -> 0 | Q27: 12 | R27: =Q27*H27*$P27*$E$7*$E$7*$E$7 -> 0 | S27: ='LOE Breakdown by Year'!D210 -> 0 | T27: 12 | U27: =T27*H27*$S27*$E$7*$E$7*$E$7*$E$7 -> 0 | V27: ='LOE Breakdown by Year'!D256 -> 0 | W27: 6 | X27: =W27*H27*$V27*$E$7*$E$7*$E$7*$E$7*$E$7 -> 0 | Y27: =SUM(R27,O27,L27,I27,U27,X27) -> 0 | Z27: 0 | AA27: =SUM(Y27:Z27) -> 0
A28: PERADMNMED | B28: 70000 | C28: HND | D28: Key Personnel: M&E Director | E28: ='LOE Breakdown by Year'!D27 -> 1 | F28: Month | G28: 11 | H28: =55000/12 -> 4583.3333 | I28: =G28*H28*E28 -> 50416.667 | J28: ='LOE Breakdown by Year'!D73 -> 1 | K28: 12 | L28: =K28*H28*$E$7*$J28 -> 57750 | M28: ='LOE Breakdown by Year'!D119 -> 1 | N28: 12 | O28: =N28*H28*$M28*$E$7*$E$7 -> 60637.5 | P28: ='LOE Breakdown by Year'!D165 -> 1 | Q28: 12 | R28: =Q28*H28*$P28*$E$7*$E$7*$E$7 -> 63669.375 | S28: ='LOE Breakdown by Year'!D211 -> 1 | T28: 12 | U28: =T28*H28*$S28*$E$7*$E$7*$E$7*$E$7 -> 66852.844 | V28: ='LOE Breakdown by Year'!D257 -> 1 | W28: 12 | X28: =W28*H28*$V28*$E$7*$E$7*$E$7*$E$7*$E$7 -> 70195.486 | Y28: =SUM(R28,O28,L28,I28,U28,X28) -> 369521.87 | Z28: 0 | AA28: =SUM(Y28:Z28) -> 369521.87
A29: PERADMNMES | B29: 70000 | C29: HND | D29: M&E Specialist | E29: ='LOE Breakdown by Year'!D28 -> 1 | F29: Month | G29: 6 | H29: =(24000/12) -> 2000 | I29: =G29*H29*E29 -> 12000 | J29: ='LOE Breakdown by Year'!D74 -> 1 | K29: 12 | L29: =K29*H29*$E$7*$J29 -> 25200 | M29: ='LOE Breakdown by Year'!D120 -> 1 | N29: 12 | O29: =N29*H29*$M29*$E$7*$E$7 -> 26460 | P29: ='LOE Breakdown by Year'!D166 -> 1 | Q29: 12 | R29: =Q29*H29*$P29*$E$7*$E$7*$E$7 -> 27783 | S29: ='LOE Breakdown by Year'!D212 -> 1 | T29: 12 | U29: =T29*H29*$S29*$E$7*$E$7*$E$7*$E$7 -> 29172.15 | V29: ='LOE Breakdown by Year'!D258 -> 1 | W29: 11 | X29: =W29*H29*$V29*$E$7*$E$7*$E$7*$E$7*$E$7 -> 28078.194 | Y29: =SUM(R29,O29,L29,I29,U29,X29) -> 148693.34 | Z29: 0 | AA29: =SUM(Y29:Z29) -> 148693.34
A30: PERADMNMEO | B30: 70000 | C30: HND | D30: M&E Officer | E30: ='LOE Breakdown by Year'!D29 -> 1 | F30: Month | G30: 2 | H30: =15000/12 -> 1250 | I30: =G30*H30*E30 -> 2500 | J30: ='LOE Breakdown by Year'!D75 -> 1 | K30: =12 -> 12 | L30: =K30*H30*$E$7*$J30 -> 15750 | M30: ='LOE Breakdown by Year'!D121 -> 1 | N30: =12 -> 12 | O30: =N30*H30*$M30*$E$7*$E$7 -> 16537.5 | P30: ='LOE Breakdown by Year'!D167 -> 1 | Q30: =12 -> 12 | R30: =Q30*H30*$P30*$E$7*$E$7*$E$7 -> 17364.375 | S30: ='LOE Breakdown by Year'!D213 -> 1 | T30: =12 -> 12 | U30: =T30*H30*$S30*$E$7*$E$7*$E$7*$E$7 -> 18232.594 | V30: ='LOE Breakdown by Year'!D259 -> 1 | W30: 3 | X30: =W30*H30*$V30*$E$7*$E$7*$E$7*$E$7*$E$7 -> 4786.0559 | Y30: =SUM(R30,O30,L30,I30,U30,X30) -> 75170.525 | Z30: 0 | AA30: =SUM(Y30:Z30) -> 75170.525
A31: PERADMNSCM | B31: 70000 | C31: HND | D31: Supply Chain Manager | E31: ='LOE Breakdown by Year'!D30 -> 0 | F31: Month | G31: 11 | H31: =60000/12 -> 5000 | I31: =G31*H31*E31 -> 0 | J31: ='LOE Breakdown by Year'!D76 -> 0 | K31: 12 | L31: =K31*H31*$E$7*$J31 -> 0 | M31: ='LOE Breakdown by Year'!D122 -> 0 | N31: 12 | O31: =N31*H31*$M31*$E$7*$E$7 -> 0 | P31: ='LOE Breakdown by Year'!D168 -> 0 | Q31: 12 | R31: =Q31*H31*$P31*$E$7*$E$7*$E$7 -> 0 | S31: ='LOE Breakdown by Year'!D214 -> 0 | T31: 12 | U31: =T31*H31*$S31*$E$7*$E$7*$E$7*$E$7 -> 0 | V31: ='LOE Breakdown by Year'!D260 -> 0 | W31: 8 | X31: =W31*H31*$V31*$E$7*$E$7*$E$7*$E$7*$E$7 -> 0 | Y31: =SUM(R31,O31,L31,I31,U31,X31) -> 0 | Z31: 0 | AA31: =SUM(Y31:Z31) -> 0
A32: PERADMNCLO | B32: 70000 | C32: HND | D32: In-Country Logistics Specialist | E32: ='LOE Breakdown by Year'!D31 -> 0 | F32: Month | G32: 9 | H32: =24000/12 -> 2000 | I32: =G32*H32*E32 -> 0 | J32: ='LOE Breakdown by Year'!D77 -> 0 | K32: 12 | L32: =K32*H32*$E$7*$J32 -> 0 | M32: ='LOE Breakdown by Year'!D123 -> 0 | N32: 12 | O32: =N32*H32*$M32*$E$7*$E$7 -> 0 | P32: ='LOE Breakdown by Year'!D169 -> 0 | Q32: 12 | R32: =Q32*H32*$P32*$E$7*$E$7*$E$7 -> 0 | S32: ='LOE Breakdown by Year'!D215 -> 0 | T32: 12 | U32: =T32*H32*$S32*$E$7*$E$7*$E$7*$E$7 -> 0 | V32: ='LOE Breakdown by Year'!D261 -> 0 | W32: 8 | X32: =W32*H32*$V32*$E$7*$E$7*$E$7*$E$7*$E$7 -> 0 | Y32: =SUM(R32,O32,L32,I32,U32,X32) -> 0 | Z32: 0 | AA32: =SUM(Y32:Z32) -> 0
A33: PERADMNULO | B33: 70000 | C33: HND | D33: US Commodity Logistics Specialist | E33: ='LOE Breakdown by Year'!D32 -> 0 | F33: Month | G33: 9 | H33: =24000/12 -> 2000 | I33: =G33*H33*E33 -> 0 | J33: ='LOE Breakdown by Year'!D78 -> 0 | K33: 12 | L33: =K33*H33*$E$7*$J33 -> 0 | M33: ='LOE Breakdown by Year'!D124 -> 0 | N33: 12 | O33: =N33*H33*$M33*$E$7*$E$7 -> 0 | P33: ='LOE Breakdown by Year'!D170 -> 0 | Q33: 12 | R33: =Q33*H33*$P33*$E$7*$E$7*$E$7 -> 0 | S33: ='LOE Breakdown by Year'!D216 -> 0 | T33: 12 | U33: =T33*H33*$S33*$E$7*$E$7*$E$7*$E$7 -> 0 | V33: ='LOE Breakdown by Year'!D262 -> 0 | W33: 8 | X33: =W33*H33*$V33*$E$7*$E$7*$E$7*$E$7*$E$7 -> 0 | Y33: =SUM(R33,O33,L33,I33,U33,X33) -> 0 | Z33: 0 | AA33: =SUM(Y33:Z33) -> 0
A34: PERADMNWHM | B34: 70000 | C34: HND | D34: Warehouse Manager | E34: ='LOE Breakdown by Year'!D33 -> 0 | F34: Month | G34: 8 | H34: 1250 | I34: =G34*H34*E34 -> 0 | J34: ='LOE Breakdown by Year'!D79 -> 0 | K34: 12 | L34: =K34*H34*$E$7*$J34 -> 0 | M34: ='LOE Breakdown by Year'!D125 -> 0 | N34: 12 | O34: =N34*H34*$M34*$E$7*$E$7 -> 0 | P34: ='LOE Breakdown by Year'!D171 -> 0 | Q34: 12 | R34: =Q34*H34*$P34*$E$7*$E$7*$E$7 -> 0 | S34: ='LOE Breakdown by Year'!D217 -> 0 | T34: 12 | U34: =T34*H34*$S34*$E$7*$E$7*$E$7*$E$7 -> 0 | V34: ='LOE Breakdown by Year'!D263 -> 0 | W34: 8 | X34: =W34*H34*$V34*$E$7*$E$7*$E$7*$E$7*$E$7 -> 0 | Y34: =SUM(R34,O34,L34,I34,U34,X34) -> 0 | Z34: 0 | AA34: =SUM(Y34:Z34) -> 0
A35: PERADMNWHO | B35: 70000 | C35: HND | D35: Warehouse Officer - (2 Individuals) | E35: ='LOE Breakdown by Year'!D34 -> 0 | F35: Month | G35: =2*4 -> 8 | H35: =(12000/12) -> 1000 | I35: =G35*H35*E35 -> 0 | J35: ='LOE Breakdown by Year'!D80 -> 0 | K35: =2*12 -> 24 | L35: =K35*H35*$E$7*$J35 -> 0 | M35: ='LOE Breakdown by Year'!D126 -> 0 | N35: =2*12 -> 24 | O35: =N35*H35*$M35*$E$7*$E$7 -> 0 | P35: ='LOE Breakdown by Year'!D172 -> 0 | Q35: =2*12 -> 24 | R35: =Q35*H35*$P35*$E$7*$E$7*$E$7 -> 0 | S35: ='LOE Breakdown by Year'!D218 -> 0 | T35: =2*12 -> 24 | U35: =T35*H35*$S35*$E$7*$E$7*$E$7*$E$7 -> 0 | V35: ='LOE Breakdown by Year'!D264 -> 0 | W35: =2*4 -> 8 | X35: =W35*H35*$V35*$E$7*$E$7*$E$7*$E$7*$E$7 -> 0 | Y35: =SUM(R35,O35,L35,I35,U35,X35) -> 0 | Z35: 0 | AA35: =SUM(Y35:Z35) -> 0
A36: PERADMNLRP | B36: 70000 | C36: HND | D36: LRP Technical Specialist | E36: ='LOE Breakdown by Year'!D35 -> 0 | F36: Month | G36: 8 | H36: =18000/12 -> 1500 | I36: =G36*H36*E36 -> 0 | J36: ='LOE Breakdown by Year'!D81 -> 0 | K36: 12 | L36: =K36*H36*$E$7*$J36 -> 0 | M36: ='LOE Breakdown by Year'!D127 -> 0 | N36: 12 | O36: =N36*H36*$M36*$E$7*$E$7 -> 0 | P36: ='LOE Breakdown by Year'!D173 -> 0 | Q36: 12 | R36: =Q36*H36*$P36*$E$7*$E$7*$E$7 -> 0 | S36: ='LOE Breakdown by Year'!D219 -> 0 | T36: 12 | U36: =T36*H36*$S36*$E$7*$E$7*$E$7*$E$7 -> 0 | V36: ='LOE Breakdown by Year'!D265 -> 0 | W36: 0 | X36: =W36*H36*$V36*$E$7*$E$7*$E$7*$E$7*$E$7 -> 0 | Y36: =SUM(R36,O36,L36,I36,U36,X36) -> 0 | Z36: 0 | AA36: =SUM(Y36:Z36) -> 0
A37: PERADMNFAD | B37: 70000 | C37: HND | D37: Finance & Administration Director | E37: ='LOE Breakdown by Year'!D36 -> 1 | F37: Month | G37: 9 | H37: =60000/12 -> 5000 | I37: =G37*H37*E37 -> 45000 | J37: ='LOE Breakdown by Year'!D82 -> 1 | K37: 12 | L37: =K37*H37*$E$7*$J37 -> 63000 | M37: ='LOE Breakdown by Year'!D128 -> 1 | N37: 12 | O37: =N37*H37*$M37*$E$7*$E$7 -> 66150 | P37: ='LOE Breakdown by Year'!D174 -> 1 | Q37: 12 | R37: =Q37*H37*$P37*$E$7*$E$7*$E$7 -> 69457.5 | S37: ='LOE Breakdown by Year'!D220 -> 1 | T37: 12 | U37: =T37*H37*$S37*$E$7*$E$7*$E$7*$E$7 -> 72930.375 | V37: ='LOE Breakdown by Year'!D266 -> 1 | W37: 12 | X37: =W37*H37*$V37*$E$7*$E$7*$E$7*$E$7*$E$7 -> 76576.894 | Y37: =SUM(R37,O37,L37,I37,U37,X37) -> 393114.77 | Z37: 0 | AA37: =SUM(Y37:Z37) -> 393114.77
A38: PERADMNCCM | B38: 70000 | C38: HND | D38: Contracts & Compliance Manager | E38: ='LOE Breakdown by Year'!D37 -> 1 | F38: Month | G38: 9 | H38: =31600/12 -> 2633.3333 | I38: =G38*H38*E38 -> 23700 | J38: ='LOE Breakdown by Year'!D83 -> 1 | K38: 12 | L38: =K38*H38*$E$7*$J38 -> 33180 | M38: ='LOE Breakdown by Year'!D129 -> 1 | N38: 12 | O38: =N38*H38*$M38*$E$7*$E$7 -> 34839 | P38: ='LOE Breakdown by Year'!D175 -> 1 | Q38: 12 | R38: =Q38*H38*$P38*$E$7*$E$7*$E$7 -> 36580.95 | S38: ='LOE Breakdown by Year'!D221 -> 1 | T38: 12 | U38: =T38*H38*$S38*$E$7*$E$7*$E$7*$E$7 -> 38409.998 | V38: ='LOE Breakdown by Year'!D267 -> 1 | W38: 11 | X38: =W38*H38*$V38*$E$7*$E$7*$E$7*$E$7*$E$7 -> 36969.623 | Y38: =SUM(R38,O38,L38,I38,U38,X38) -> 203679.57 | Z38: 0 | AA38: =SUM(Y38:Z38) -> 203679.57
A39: PERADMNGPS | B39: 70000 | C39: HND | D39: Grants & Procurement Specialist | E39: ='LOE Breakdown by Year'!D38 -> 1 | F39: Month | G39: 6 | H39: 1500 | I39: =G39*H39*E39 -> 9000 | J39: ='LOE Breakdown by Year'!D84 -> 1 | K39: 12 | L39: =K39*H39*$E$7*$J39 -> 18900 | M39: ='LOE Breakdown by Year'!D130 -> 1 | N39: 12 | O39: =N39*H39*$M39*$E$7*$E$7 -> 19845 | P39: ='LOE Breakdown by Year'!D176 -> 1 | Q39: 12 | R39: =Q39*H39*$P39*$E$7*$E$7*$E$7 -> 20837.25 | S39: ='LOE Breakdown by Year'!D222 -> 1 | T39: 12 | U39: =T39*H39*$S39*$E$7*$E$7*$E$7*$E$7 -> 21879.112 | V39: ='LOE Breakdown by Year'!D268 -> 1 | W39: 6 | X39: =W39*H39*$V39*$E$7*$E$7*$E$7*$E$7*$E$7 -> 11486.534 | Y39: =SUM(R39,O39,L39,I39,U39,X39) -> 101947.9 | Z39: 0 | AA39: =SUM(Y39:Z39) -> 101947.9
A40: PERADMNGPO | B40: 70000 | C40: HND | D40: Grants & Procurement Officer | E40: ='LOE Breakdown by Year'!D39 -> 1 | F40: Month | G40: 2 | H40: =12000/12 -> 1000 | I40: =G40*H40*E40 -> 2000 | J40: ='LOE Breakdown by Year'!D85 -> 1 | K40: 12 | L40: =K40*H40*$E$7*$J40 -> 12600 | M40: ='LOE Breakdown by Year'!D131 -> 1 | N40: 12 | O40: =N40*H40*$M40*$E$7*$E$7 -> 13230 | P40: ='LOE Breakdown by Year'!D177 -> 1 | Q40: 12 | R40: =Q40*H40*$P40*$E$7*$E$7*$E$7 -> 13891.5 | S40: ='LOE Breakdown by Year'!D223 -> 1 | T40: 12 | U40: =T40*H40*$S40*$E$7*$E$7*$E$7*$E$7 -> 14586.075 | V40: ='LOE Breakdown by Year'!D269 -> 1 | W40: 3 | X40: =W40*H40*$V40*$E$7*$E$7*$E$7*$E$7*$E$7 -> 3828.8447 | Y40: =SUM(R40,O40,L40,I40,U40,X40) -> 60136.42 | Z40: 0 | AA40: =SUM(Y40:Z40) -> 60136.42
A41: PERADMNFNO | B41: 70000 | C41: HND | D41: Finance Officer | E41: ='LOE Breakdown by Year'!D40 -> 1 | F41: Month | G41: 9 | H41: =15000/12 -> 1250 | I41: =G41*H41*E41 -> 11250 | J41: ='LOE Breakdown by Year'!D86 -> 1 | K41: 12 | L41: =K41*H41*$E$7*$J41 -> 15750 | M41: ='LOE Breakdown by Year'!D132 -> 1 | N41: 12 | O41: =N41*H41*$M41*$E$7*$E$7 -> 16537.5 | P41: ='LOE Breakdown by Year'!D178 -> 1 | Q41: 12 | R41: =Q41*H41*$P41*$E$7*$E$7*$E$7 -> 17364.375 | S41: ='LOE Breakdown by Year'!D224 -> 1 | T41: 12 | U41: =T41*H41*$S41*$E$7*$E$7*$E$7*$E$7 -> 18232.594 | V41: ='LOE Breakdown by Year'!D270 -> 1 | W41: 11 | X41: =W41*H41*$V41*$E$7*$E$7*$E$7*$E$7*$E$7 -> 17548.871 | Y41: =SUM(R41,O41,L41,I41,U41,X41) -> 96683.34 | Z41: 0 | AA41: =SUM(Y41:Z41) -> 96683.34
...

Sheet FEREMA Sub Budget
C2: Subrecipient Budget MGD
C3: Country of Operation: HONDURAS
C4: Implementing Organization: FEREMA
A5: Budget Assumptions
A6: Merit Based Increases for Staff - 5% | B6: 1.05
A7: Inflation rate - 5% | B7: 1.05
A9: Item | B9: Type of Unit | C9: Year 1 | G9: Year 2 | K9: Year 3 | O9: Year 4 | S9: Year 5 | W9: Total | AA9: Activity 3 | AB9: Activity 4 | AC9: Activity 6
C10: Cost | D10: Quantity | E10: Percent Allocated | F10: Total | G10: Cost | H10: Quantity | I10: Percent Allocated | J10: Total | K10: Cost | L10: Quantity | M10: Percent Allocated | N10: Total | O10: Cost | P10: Quantity | Q10: Percent Allocated | R10: Total | S10: Cost | T10: Quantity | U10: Percent Allocated | V10: Total | AA10: 0.73024993 | AB10: 0.080106447 | AC10: 0.18964362
A11: Direct Costs | X11: A3 | Y11: A4 | Z11: A6
A12: Salaries | X12: 0.8 | Y12: 0.1 | Z12: 0.1
A13: CCN Staff
A14: Project Coordinator | B14: Month | C14: 2900 | D14: 3 | E14: 1 | F14: =C14*D14*E14 -> 8700 | G14: =C14*$B$6 -> 3045 | H14: 12 | I14: 1 | J14: =G14*H14*I14 -> 36540 | K14: =G14*$B$6 -> 3197.25 | L14: 12 | M14: 1 | N14: =K14*L14*M14 -> 38367 | O14: =K14*$B$6 -> 3357.1125 | P14: 12 | Q14: 1 | R14: =O14*P14*Q14 -> 40285.35 | S14: =O14*$B$6 -> 3524.9681 | T14: 3 | U14: 1 | V14: =S14*T14*U14 -> 10574.904 | W14: =F14+J14+N14+V14+R14 -> 134467.25 | X14: =+W14*$X$12 -> 107573.8 | Y14: =+W14*$Y$12 -> 13446.725 | Z14: =+W14*$Z$12 -> 13446.725
A15: Education Officer (3 officers) | B15: Month | C15: 950 | D15: =3*1 -> 3 | E15: 1 | F15: =C15*D15*E15 -> 2850 | G15: =C15*$B$6 -> 997.5 | H15: =12*3 -> 36 | I15: 1 | J15: =G15*H15*I15 -> 35910 | K15: =G15*$B$6 -> 1047.375 | L15: =12*3 -> 36 | M15: 1 | N15: =K15*L15*M15 -> 37705.5 | O15: =K15*$B$6 -> 1099.7438 | P15: =12*3 -> 36 | Q15: 1 | R15: =O15*P15*Q15 -> 39590.775 | S15: =O15*$B$6 -> 1154.7309 | T15: =3*2 -> 6 | U15: 1 | V15: =S15*T15*U15 -> 6928.3856 | W15: =F15+J15+N15+V15+R15 -> 122984.66 | X15: =+W15 -> 122984.66
A16: Preschool Specialist | B16: Month | C16: 1900 | D16: 0 | E16: 1 | F16: =C16*D16*E16 -> 0 | G16: =C16*$B$6 -> 1995 | H16: 12 | I16: 1 | J16: =G16*H16*I16 -> 23940 | K16: =G16*$B$6 -> 2094.75 | L16: 12 | M16: 1 | N16: =K16*L16*M16 -> 25137 | O16: =K16*$B$6 -> 2199.4875 | P16: 12 | Q16: 1 | R16: =O16*P16*Q16 -> 26393.85 | S16: =O16*$B$6 -> 2309.4619 | T16: 0 | U16: 1 | V16: =S16*T16*U16 -> 0 | W16: =F16+J16+N16+V16+R16 -> 75470.85 | Y16: =+W16 -> 75470.85
A17: Logistics Officer | B17: Month | C17: 950 | D17: 0 | E17: 1 | F17: =C17*D17*E17 -> 0 | G17: =C17*$B$6 -> 997.5 | H17: 12 | I17: 1 | J17: =G17*H17*I17 -> 11970 | K17: =G17*$B$6 -> 1047.375 | L17: 12 | M17: 1 | N17: =K17*L17*M17 -> 12568.5 | O17: =K17*$B$6 -> 1099.7438 | P17: 12 | Q17: 1 | R17: =O17*P17*Q17 -> 13196.925 | S17: =O17*$B$6 -> 1154.7309 | T17: 0 | U17: 1 | V17: =S17*T17*U17 -> 0 | W17: =F17+J17+N17+V17+R17 -> 37735.425 | Y17: =+W17 -> 37735.425
A18: Financial Specialist | B18: Month | C18: 1900 | D18: 3 | E18: 1 | F18: =C18*D18*E18 -> 5700 | G18: =C18*$B$6 -> 1995 | H18: 12 | I18: 1 | J18: =G18*H18*I18 -> 23940 | K18: =G18*$B$6 -> 2094.75 | L18: 12 | M18: 1 | N18: =K18*L18*M18 -> 25137 | O18: =K18*$B$6 -> 2199.4875 | P18: 12 | Q18: 1 | R18: =O18*P18*Q18 -> 26393.85 | S18: =O18*$B$6 -> 2309.4619 | T18: 3 | U18: 1 | V18: =S18*T18*U18 -> 6928.3856 | W18: =F18+J18+N18+V18+R18 -> 88099.236 | X18: =+W18*$X$12 -> 70479.389 | Y18: =+W18*$Y$12 -> 8809.9236 | Z18: =+W18*$Z$12 -> 8809.9236
A19: Financial, Accounting, and Logistics Assistant | B19: Month | C19: 950 | D19: 3 | E19: 0.5 | F19: =C19*D19*E19 -> 1425 | G19: =C19*$B$6 -> 997.5 | H19: 12 | I19: 1 | J19: =G19*H19*I19 -> 11970 | K19: =G19*$B$6 -> 1047.375 | L19: 12 | M19: 1 | N19: =K19*L19*M19 -> 12568.5 | O19: =K19*$B$6 -> 1099.7438 | P19: 12 | Q19: 1 | R19: =O19*P19*Q19 -> 13196.925 | S19: =O19*$B$6 -> 1154.7309 | T19: 3 | U19: 1 | V19: =S19*T19*U19 -> 3464.1928 | W19: =F19+J19+N19+V19+R19 -> 42624.618 | X19: =+W19*$X$12 -> 34099.694 | Y19: =+W19*$Y$12 -> 4262.4618 | Z19: =+W19*$Z$12 -> 4262.4618
A21: Subtotal: Salaries & Wages | F21: =SUM(F14:F19) -> 18675 | J21: =SUM(J14:J19) -> 144270 | N21: =SUM(N14:N19) -> 151483.5 | R21: =SUM(R14:R19) -> 159057.67 | V21: =SUM(V14:V19) -> 27895.868 | W21: =SUM(W14:W19) -> 501382.04 | AA21: =W21*$AA$10 -> 366134.2 | AB21: =W21*$AB$10 -> 40163.934 | AC21: =W21*$AC$10 -> 95083.906
A22: Fringe
A23: CCN Staff | B23: 0.37 | C23: =(SUM(F14:F19))*$B$23 -> 6909.75 | E23: 1 | F23: =C23*E23 -> 6909.75 | G23: =(SUM(J14:J19))*$B$23 -> 53379.9 | I23: 1 | J23: =G23*I23 -> 53379.9 | K23: =(SUM(N14:N19))*$B$23 -> 56048.895 | M23: 1 | N23: =K23*M23 -> 56048.895 | O23: =(SUM(R14:R19))*$B$23 -> 58851.34 | Q23: 1 | R23: =O23*Q23 -> 58851.34 | S23: =(SUM(V14:V19))*$B$23 -> 10321.471 | U23: 1 | V23: =S23*U23 -> 10321.471 | W23: =F23+J23+N23+V23+R23 -> 185511.36
A25: Subtotal: Benefits | F25: =F23 -> 6909.75 | J25: =J23 -> 53379.9 | N25: =N23 -> 56048.895 | R25: =R23 -> 58851.34 | V25: =V23 -> 10321.471 | W25: =W23 -> 185511.36 | X25: =+W25*$X$12 -> 148409.08 | Y25: =+W25*$Y$12 -> 18551.136 | Z25: =+W25*$Z$12 -> 18551.136 | AA25: =W25*$AA$10 -> 135469.66 | AB25: =W25*$AB$10 -> 14860.656 | AC25: =W25*$AC$10 -> 35181.045
A26: Local Travel
A27: Local Transportation for Trainings and Field Activities - Staff | B27: Daily | C27: 10 | D27: =((1*10)*2)+((2*10)*2)+((0*10)*2)+((1*5)*2)+((1*5)*2) -> 80 | E27: 1 | F27: =C27*D27*E27 -> 800 | G27: =C27*$B$6 -> 10.5 | H27: =((1*10)*12)+((2*10)*12)+((1*10)*12)+((1*5)*12)+((1*5)*12) -> 600 | I27: 1 | J27: =G27*H27*I27 -> 6300 | K27: =G27*$B$6 -> 11.025 | L27: =((1*10)*12)+((2*10)*12)+((1*10)*12)+((1*5)*12)+((1*5)*12) -> 600 | M27: 1 | N27: =K27*L27*M27 -> 6615 | O27: =K27*$B$6 -> 11.57625 | P27: =((1*10)*12)+((2*10)*12)+((1*10)*12)+((1*5)*12)+((1*5)*12) -> 600 | Q27: 1 | R27: =O27*P27*Q27 -> 6945.75 | S27: =O27*$B$6 -> 12.155063 | T27: =((1*10)*2)+((2*10)*2)+((0*10)*2)+((1*5)*2)+((1*5)*2) -> 80 | U27: 1 | V27: =S27*T27*U27 -> 972.405 | W27: =F27+J27+N27+V27+R27 -> 21633.155 | X27: =+W27*$X$12 -> 17306.524 | Y27: =+W27*$Y$12 -> 2163.3155 | Z27: =+W27*$Z$12 -> 2163.3155
A28: Local Transportation for Trainings and Field Activities - Consultants Activity 3.1 (Strengthen Teaching Using Targeted Instruction and GANE Guides) | B28: Daily | C28: 10 | D28: =+(10*5)+(0*10) -> 50 | E28: 1 | F28: =C28*D28*E28 -> 500 | G28: =C28*$B$6 -> 10.5 | H28: =+(10*5)+(35*10) -> 400 | I28: 1 | J28: =G28*H28*I28 -> 4200 | K28: =G28*$B$6 -> 11.025 | L28: =+(10*5)+(35*10) -> 400 | M28: 1 | N28: =K28*L28*M28 -> 4410 | O28: =K28*$B$6 -> 11.57625 | P28: =+(10*5)+(35*10) -> 400 | Q28: 1 | R28: =O28*P28*Q28 -> 4630.5 | S28: =O28*$B$6 -> 12.155063 | T28: 0 | U28: 1 | V28: =S28*T28*U28 -> 0 | W28: =F28+J28+N28+V28+R28 -> 13740.5 | X28: =+W28 -> 13740.5
A29: Local Transportation for Trainings and Field Activities - Consultants Activity 6.2 Deliver Nutrition for Early Learners and Caregivers | B29: Daily | C29: 10 | D29: =8*10 -> 80 | E29: 1 | F29: =C29*D29*E29 -> 800 | G29: =C29*$B$6 -> 10.5 | H29: =8*10*12 -> 960 | I29: 1 | J29: =G29*H29*I29 -> 10080 | K29: =G29*$B$6 -> 11.025 | L29: =8*10*12 -> 960 | M29: 1 | N29: =K29*L29*M29 -> 10584 | O29: =K29*$B$6 -> 11.57625 | P29: =8*10*12 -> 960 | Q29: 1 | R29: =O29*P29*Q29 -> 11113.2 | S29: =O29*$B$6 -> 12.155063 | T29: 0 | U29: 1 | V29: =S29*T29*U29 -> 0 | W29: =F29+J29+N29+V29+R29 -> 32577.2 | Z29: =+W29 -> 32577.2
A30: Per Diem | W30: =F30+J30+N30+V30+R30 -> 0
A31: Per Diem - Staff | B31: Daily | C31: 20 | D31: =+D27 -> 80 | E31: 1 | F31: =C31*D31*E31 -> 1600 | G31: =C31*$B$6 -> 21 | H31: =+H27 -> 600 | I31: 1 | J31: =G31*H31*I31 -> 12600 | K31: =G31*$B$6 -> 22.05 | L31: =+L27 -> 600 | M31: 1 | N31: =K31*L31*M31 -> 13230 | O31: =K31*$B$6 -> 23.1525 | P31: =+P27 -> 600 | Q31: 1 | R31: =O31*P31*Q31 -> 13891.5 | S31: =O31*$B$6 -> 24.310125 | T31: =+T27 -> 80 | U31: 1 | V31: =S31*T31*U31 -> 1944.81 | W31: =F31+J31+N31+V31+R31 -> 43266.31 | X31: =+W31*$X$12 -> 34613.048 | Y31: =+W31*$Y$12 -> 4326.631 | Z31: =+W31*$Z$12 -> 4326.631
A32: Per Diem - - Consultants Activity 3.1 (Strengthen Teaching Using Targeted Instruction and GANE Guides) | B32: Daily | C32: 20 | D32: =+D28 -> 50 | E32: 1 | F32: =C32*D32*E32 -> 1000 | G32: =C32*$B$6 -> 21 | H32: =+H28 -> 400 | I32: 1 | J32: =G32*H32*I32 -> 8400 | K32: =G32*$B$6 -> 22.05 | L32: =+L28 -> 400 | M32: 1 | N32: =K32*L32*M32 -> 8820 | O32: =K32*$B$6 -> 23.1525 | P32: =+P28 -> 400 | Q32: 1 | R32: =O32*P32*Q32 -> 9261 | S32: =O32*$B$6 -> 24.310125 | T32: 0 | U32: 1 | V32: =S32*T32*U32 -> 0 | W32: =F32+J32+N32+V32+R32 -> 27481 | X32: =+W32 -> 27481
A33: Per Diem -Consultants Activity 6.2 Deliver Nutrition for Early Learners and Caregivers | B33: Daily | C33: 20 | D33: =+D29 -> 80 | E33: 1 | F33: =C33*D33*E33 -> 1600 | G33: =C33*$B$6 -> 21 | H33: =+H29 -> 960 | I33: 1 | J33: =G33*H33*I33 -> 20160 | K33: =G33*$B$6 -> 22.05 | L33: =+L29 -> 960 | M33: 1 | N33: =K33*L33*M33 -> 21168 | O33: =K33*$B$6 -> 23.1525 | P33: =+P29 -> 960 | Q33: 1 | R33: =O33*P33*Q33 -> 22226.4 | S33: =O33*$B$6 -> 24.310125 | T33: 0 | U33: 1 | V33: =S33*T33*U33 -> 0 | W33: =F33+J33+N33+V33+R33 -> 65154.4 | Z33: =+W33 -> 65154.4
A34: Lodging and M&IE for Trainings | W34: =F34+J34+N34+V34+R34 -> 0
A35: Lodging and M&IE for Trainings - Staff | B35: Daily | C35: 45 | D35: 80 | E35: 1 | F35: =C35*D35*E35 -> 3600 | G35: =C35*$B$6 -> 47.25 | H35: 450 | I35: 1 | J35: =G35*H35*I35 -> 21262.5 | K35: =G35*$B$6 -> 49.6125 | L35: 450 | M35: 1 | N35: =K35*L35*M35 -> 22325.625 | O35: =K35*$B$6 -> 52.093125 | P35: 450 | Q35: 1 | R35: =O35*P35*Q35 -> 23441.906 | S35: =O35*$B$6 -> 54.697781 | T35: 80 | U35: 1 | V35: =S35*T35*U35 -> 4375.8225 | W35: =F35+J35+N35+V35+R35 -> 75005.854 | X35: =+W35*$X$12 -> 60004.683 | Y35: =+W35*$Y$12 -> 7500.5854 | Z35: =+W35*$Z$12 -> 7500.5854
A36: Lodging and M&IE for Trainings - Consultants Activity 3.1 (Strengthen Teaching Using Targeted Instruction and GANE Guides) | B36: Daily | C36: 45 | D36: 50 | E36: 1 | F36: =C36*D36*E36 -> 2250 | G36: =C36*$B$6 -> 47.25 | H36: 300 | I36: 1 | J36: =G36*H36*I36 -> 14175 | K36: =G36*$B$6 -> 49.6125 | L36: 300 | M36: 1 | N36: =K36*L36*M36 -> 14883.75 | O36: =K36*$B$6 -> 52.093125 | P36: 300 | Q36: 1 | R36: =O36*P36*Q36 -> 15627.938 | S36: =O36*$B$6 -> 54.697781 | T36: 0 | U36: 1 | V36: =S36*T36*U36 -> 0 | W36: =F36+J36+N36+V36+R36 -> 46936.688 | X36: =+W36 -> 46936.688
A37: Lodging and M&IE for Trainings - Consultants Activity 6.2 Deliver Nutrition for Early Learners and Caregivers | B37: Daily | C37: 45 | D37: 80 | E37: 1 | F37: =C37*D37*E37 -> 3600 | G37: =C37*$B$6 -> 47.25 | H37: 800 | I37: 1 | J37: =G37*H37*I37 -> 37800 | K37: =G37*$B$6 -> 49.6125 | L37: 800 | M37: 1 | N37: =K37*L37*M37 -> 39690 | O37: =K37*$B$6 -> 52.093125 | P37: 800 | Q37: 1 | R37: =O37*P37*Q37 -> 41674.5 | S37: =O37*$B$6 -> 54.697781 | T37: 0 | U37: 1 | V37: =S37*T37*U37 -> 0 | W37: =F37+J37+N37+V37+R37 -> 122764.5 | Z37: =+W37 -> 122764.5
A38: Rent and Full transportation | B38: Daily | C38: 120 | D38: =3*5*4 -> 60 | E38: 1 | F38: =C38*D38*E38 -> 7200 | G38: =C38*$B$6 -> 126 | H38: =9*5*4 -> 180 | I38: 1 | J38: =G38*H38*I38 -> 22680 | K38: =G38*$B$6 -> 132.3 | L38: =9*5*4 -> 180 | M38: 1 | N38: =K38*L38*M38 -> 23814 | O38: =K38*$B$6 -> 138.915 | P38: =9*5*4 -> 180 | Q38: 1 | R38: =O38*P38*Q38 -> 25004.7 | S38: =O38*$B$6 -> 145.86075 | T38: =3*5*4 -> 60 | U38: 1 | V38: =S38*T38*U38 -> 8751.645 | W38: =F38+J38+N38+V38+R38 -> 87450.345 | X38: =+W38*$X$12 -> 69960.276 | Y38: =+W38*$Y$12 -> 8745.0345 | Z38: =+W38*$Z$12 -> 8745.0345
A39: Subtotal: Travel | F39: =SUM(F26:F38) -> 22950 | J39: =SUM(J26:J38) -> 157657.5 | N39: =SUM(N26:N38) -> 165540.38 | R39: =SUM(R26:R38) -> 173817.39 | V39: =SUM(V26:V38) -> 16044.683 | W39: =SUM(W26:W38) -> 536009.95 | AA39: =W39*$AA$10 -> 391421.23 | AB39: =W39*$AB$10 -> 42937.853 | AC39: =W39*$AC$10 -> 101650.87
A40: Professional Services
A41: Master Trainers | B41: Daily | C41: 40 | D41: =10*10*1 -> 100 | E41: 1 | F41: =C41*D41*E41 -> 4000 | G41: =C41*$B$6 -> 42 | H41: =10*10*11 -> 1100 | I41: 1 | J41: =G41*H41*I41 -> 46200 | K41: =G41*$B$6 -> 44.1 | L41: =10*10*11 -> 1100 | M41: 1 | N41: =K41*L41*M41 -> 48510 | O41: =K41*$B$6 -> 46.305 | P41: =10*10*11 -> 1100 | Q41: 1 | R41: =O41*P41*Q41 -> 50935.5 | S41: =O41*$B$6 -> 48.62025 | T41: 0 | U41: 1 | V41: =S41*T41*U41 -> 0 | W41: =F41+J41+N41+V41+R41 -> 149645.5 | X41: =+W41 -> 149645.5
A42: Teacher Coaches | B42: Daily | C42: 35 | D42: 0 | E42: 1 | F42: =C42*D42*E42 -> 0 | G42: =C42*$B$6 -> 36.75 | H42: =35*10*11 -> 3850 | I42: 1 | J42: =G42*H42*I42 -> 141487.5 | K42: =G42*$B$6 -> 38.5875 | L42: =35*10*11 -> 3850 | M42: 1 | N42: =K42*L42*M42 -> 148561.88 | O42: =K42*$B$6 -> 40.516875 | P42: =35*10*11 -> 3850 | Q42: 1 | R42: =O42*P42*Q42 -> 155989.97 | S42: =O42*$B$6 -> 42.542719 | T42: 0 | U42: 1 | V42: =S42*T42*U42 -> 0 | W42: =F42+J42+N42+V42+R42 -> 446039.34 | X42: =+W42 -> 446039.34
A43: Literacy Specialist | B43: Daily | C43: 55 | D43: =5*1 -> 5 | E43: 1 | F43: =C43*D43*E43 -> 275 | G43: =C43*$B$6 -> 57.75 | H43: =5*11 -> 55 | I43: 1 | J43: =G43*H43*I43 -> 3176.25 | K43: =G43*$B$6 -> 60.6375 | L43: =5*11 -> 55 | M43: 1 | N43: =K43*L43*M43 -> 3335.0625 | O43: =K43*$B$6 -> 63.669375 | P43: =5*11 -> 55 | Q43: 1 | R43: =O43*P43*Q43 -> 3501.8156 | S43: =O43*$B$6 -> 66.852844 | T43: 0 | U43: 1 | V43: =S43*T43*U43 -> 0 | W43: =F43+J43+N43+V43+R43 -> 10288.128 | X43: =+W43 -> 10288.128
A44: Math Specialist | B44: Daily | C44: 55 | D44: =5*1 -> 5 | E44: 1 | F44: =C44*D44*E44 -> 275 | G44: =C44*$B$6 -> 57.75 | H44: =5*11 -> 55 | I44: 1 | J44: =G44*H44*I44 -> 3176.25 | K44: =G44*$B$6 -> 60.6375 | L44: =5*11 -> 55 | M44: 1 | N44: =K44*L44*M44 -> 3335.0625 | O44: =K44*$B$6 -> 63.669375 | P44: =5*11 -> 55 | Q44: 1 | R44: =O44*P44*Q44 -> 3501.8156 | S44: =O44*$B$6 -> 66.852844 | T44: 0 | U44: 1 | V44: =S44*T44*U44 -> 0 | W44: =F44+J44+N44+V44+R44 -> 10288.128 | X44: =+W44 -> 10288.128
...

Sheet Personnel & LOE Summary
B1: Partners of the Americas – FY 2025 McGovern-Dole Honduras
B2: NOFO: USDA-FAS-10.608-0700-25-(522)
B3: Duration: 6 Years
B4: Country: Honduras
B5: Level of Effort (LOE) Breakdown by Activity
C7: Months in Year 1 | D7: Year 1 LOE | E7: Total Salary Amount Year 1 | F7: Months in Year 2 | G7: Year 2 LOE | H7: Total Salary Amount Year 2 | I7: Months in Year 3 | J7: Year 3 LOE | K7: Total Salary Amount Year 3 | L7: Months in Year 4 | M7: Year 4 LOE | N7: Total Salary Amount Year 4 | O7: Months in Year 5 | P7: Year 5 LOE | Q7: Total Salary Amount Year 5 | R7: Months in Year 6 | S7: Year 6 LOE | T7: Total Salary Amount Year 6 | U7: Total Amount LOP | V7: Total Months Worked | W7: Average Salary
C8: LOE | D8: LOE | E8: LOE | F8: LOE | G8: LOE | H8: LOE | I8: LOE | J8: LOE | K8: LOE | L8: LOE | M8: LOE | N8: LOE | O8: LOE | P8: LOE | Q8: LOE | R8: LOE | S8: LOE | T8: LOE | U8: LOE | W8: LOE
B9: Personnel (Administration)
B10: Honduran National Staff
B11: ='Program Budget'!D12 -> Key Personnel: Chief of Party - Roger Sanchez O’Neill | C11: ='Program Budget'!G12 -> 11 | D11: ='Program Budget'!E12+'Program Budget'!E153+'Program Budget'!E215+'Program Budget'!E274+'Program Budget'!E343+'Program Budget'!E410+'Program Budget'!E482+'Program Budget'!E557+'Program Budget'!E612+'Program Budget'!E686+'Program Budget'!E760+'Program Budget'!E832+'Program Budget'!E891 -> 1 | E11: ='Program Budget'!I12+'Program Budget'!I153+'Program Budget'!I215+'Program Budget'!I274+'Program Budget'!I343+'Program Budget'!I410+'Program Budget'!I482+'Program Budget'!I557+'Program Budget'!I612+'Program Budget'!I686+'Program Budget'!I760+'Program Budget'!I832+'Program Budget'!I891 -> 105416.67 | F11: ='Program Budget'!K12 -> 12 | G11: ='Program Budget'!J12+'Program Budget'!J153+'Program Budget'!J215+'Program Budget'!J274+'Program Budget'!J343+'Program Budget'!J410+'Program Budget'!J482+'Program Budget'!J557+'Program Budget'!J612+'Program Budget'!J686+'Program Budget'!J760+'Program Budget'!J832+'Program Budget'!J891 -> 1 | H11: ='Program Budget'!L12+'Program Budget'!L153+'Program Budget'!L215+'Program Budget'!L274+'Program Budget'!L343+'Program Budget'!L410+'Program Budget'!L482+'Program Budget'!L557+'Program Budget'!L612+'Program Budget'!L686+'Program Budget'!L760+'Program Budget'!L832+'Program Budget'!L891 -> 120750 | I11: ='Program Budget'!N12 -> 12 | J11: ='Program Budget'!M12+'Program Budget'!M153+'Program Budget'!M215+'Program Budget'!M274+'Program Budget'!M343+'Program Budget'!M410+'Program Budget'!M482+'Program Budget'!M557+'Program Budget'!M612+'Program Budget'!M686+'Program Budget'!M760+'Program Budget'!M832+'Program Budget'!M891 -> 1 | K11: ='Program Budget'!O12+'Program Budget'!O153+'Program Budget'!O215+'Program Budget'!O274+'Program Budget'!O343+'Program Budget'!O410+'Program Budget'!O482+'Program Budget'!O557+'Program Budget'!O612+'Program Budget'!O686+'Program Budget'!O760+'Program Budget'!O832+'Program Budget'!O891 -> 126787.5 | L11: ='Program Budget'!Q12 -> 12 | M11: ='Program Budget'!P12+'Program Budget'!P153+'Program Budget'!P215+'Program Budget'!P274+'Program Budget'!P343+'Program Budget'!P410+'Program Budget'!P482+'Program Budget'!P557+'Program Budget'!P612+'Program Budget'!P686+'Program Budget'!P760+'Program Budget'!P832+'Program Budget'!P891 -> 1 | N11: ='Program Budget'!R12+'Program Budget'!R153+'Program Budget'!R215+'Program Budget'!R274+'Program Budget'!R343+'Program Budget'!R410+'Program Budget'!R482+'Program Budget'!R557+'Program Budget'!R612+'Program Budget'!R686+'Program Budget'!R760+'Program Budget'!R832+'Program Budget'!R891 -> 133126.88 | O11: ='Program Budget'!T12 -> 12 | P11: ='Program Budget'!S12+'Program Budget'!S153+'Program Budget'!S215+'Program Budget'!S274+'Program Budget'!S343+'Program Budget'!S410+'Program Budget'!S482+'Program Budget'!S557+'Program Budget'!S612+'Program Budget'!S686+'Program Budget'!S760+'Program Budget'!S832+'Program Budget'!S891 -> 1 | Q11: ='Program Budget'!U12+'Program Budget'!U153+'Program Budget'!U215+'Program Budget'!U274+'Program Budget'!U343+'Program Budget'!U410+'Program Budget'!U482+'Program Budget'!U557+'Program Budget'!U612+'Program Budget'!U686+'Program Budget'!U760+'Program Budget'!U832+'Program Budget'!U891 -> 139783.22 | R11: ='Program Budget'!W12 -> 12 | S11: ='Program Budget'!V12+'Program Budget'!V153+'Program Budget'!V215+'Program Budget'!V274+'Program Budget'!V343+'Program Budget'!V410+'Program Budget'!V482+'Program Budget'!V557+'Program Budget'!V612+'Program Budget'!V686+'Program Budget'!V760+'Program Budget'!V832+'Program Budget'!V891 -> 1 | T11: ='Program Budget'!X12+'Program Budget'!X153+'Program Budget'!X215+'Program Budget'!X274+'Program Budget'!X343+'Program Budget'!X410+'Program Budget'!X482+'Program Budget'!X557+'Program Budget'!X612+'Program Budget'!X686+'Program Budget'!X760+'Program Budget'!X832+'Program Budget'!X891 -> 146772.38 | U11: =E11+H11+K11+N11+Q11+T11 -> 772636.64 | V11: =C11+F11+I11+L11+O11+R11 -> 71 | W11: =U11/V11 -> 10882.206
B12: ='Program Budget'!D13 -> Key Personnel: Deputy Chief of Party - David Medina Mayo | C12: ='Program Budget'!G13 -> 11 | D12: ='Program Budget'!E13+'Program Budget'!E154+'Program Budget'!E216+'Program Budget'!E275+'Program Budget'!E344+'Program Budget'!E411+'Program Budget'!E483+'Program Budget'!E558+'Program Budget'!E613+'Program Budget'!E687+'Program Budget'!E761+'Program Budget'!E833+'Program Budget'!E892 -> 1 | E12: ='Program Budget'!I13+'Program Budget'!I154+'Program Budget'!I216+'Program Budget'!I275+'Program Budget'!I344+'Program Budget'!I411+'Program Budget'!I483+'Program Budget'!I558+'Program Budget'!I613+'Program Budget'!I687+'Program Budget'!I761+'Program Budget'!I833+'Program Budget'!I892 -> 71500 | F12: ='Program Budget'!K13 -> 12 | G12: ='Program Budget'!J13+'Program Budget'!J154+'Program Budget'!J216+'Program Budget'!J275+'Program Budget'!J344+'Program Budget'!J411+'Program Budget'!J483+'Program Budget'!J558+'Program Budget'!J613+'Program Budget'!J687+'Program Budget'!J761+'Program Budget'!J833+'Program Budget'!J892 -> 1 | H12: ='Program Budget'!L13+'Program Budget'!L154+'Program Budget'!L216+'Program Budget'!L275+'Program Budget'!L344+'Program Budget'!L411+'Program Budget'!L483+'Program Budget'!L558+'Program Budget'!L613+'Program Budget'!L687+'Program Budget'!L761+'Program Budget'!L833+'Program Budget'!L892 -> 81900 | I12: ='Program Budget'!N13 -> 12 | J12: ='Program Budget'!M13+'Program Budget'!M154+'Program Budget'!M216+'Program Budget'!M275+'Program Budget'!M344+'Program Budget'!M411+'Program Budget'!M483+'Program Budget'!M558+'Program Budget'!M613+'Program Budget'!M687+'Program Budget'!M761+'Program Budget'!M833+'Program Budget'!M892 -> 1 | K12: ='Program Budget'!O13+'Program Budget'!O154+'Program Budget'!O216+'Program Budget'!O275+'Program Budget'!O344+'Program Budget'!O411+'Program Budget'!O483+'Program Budget'!O558+'Program Budget'!O613+'Program Budget'!O687+'Program Budget'!O761+'Program Budget'!O833+'Program Budget'!O892 -> 85995 | L12: ='Program Budget'!Q13 -> 12 | M12: ='Program Budget'!P13+'Program Budget'!P154+'Program Budget'!P216+'Program Budget'!P275+'Program Budget'!P344+'Program Budget'!P411+'Program Budget'!P483+'Program Budget'!P558+'Program Budget'!P613+'Program Budget'!P687+'Program Budget'!P761+'Program Budget'!P833+'Program Budget'!P892 -> 1 | N12: ='Program Budget'!R13+'Program Budget'!R154+'Program Budget'!R216+'Program Budget'!R275+'Program Budget'!R344+'Program Budget'!R411+'Program Budget'!R483+'Program Budget'!R558+'Program Budget'!R613+'Program Budget'!R687+'Program Budget'!R761+'Program Budget'!R833+'Program Budget'!R892 -> 90294.75 | O12: ='Program Budget'!T13 -> 12 | P12: ='Program Budget'!S13+'Program Budget'!S154+'Program Budget'!S216+'Program Budget'!S275+'Program Budget'!S344+'Program Budget'!S411+'Program Budget'!S483+'Program Budget'!S558+'Program Budget'!S613+'Program Budget'!S687+'Program Budget'!S761+'Program Budget'!S833+'Program Budget'!S892 -> 1 | Q12: ='Program Budget'!U13+'Program Budget'!U154+'Program Budget'!U216+'Program Budget'!U275+'Program Budget'!U344+'Program Budget'!U411+'Program Budget'!U483+'Program Budget'!U558+'Program Budget'!U613+'Program Budget'!U687+'Program Budget'!U761+'Program Budget'!U833+'Program Budget'!U892 -> 94809.488 | R12: ='Program Budget'!W13 -> 12 | S12: ='Program Budget'!V13+'Program Budget'!V154+'Program Budget'!V216+'Program Budget'!V275+'Program Budget'!V344+'Program Budget'!V411+'Program Budget'!V483+'Program Budget'!V558+'Program Budget'!V613+'Program Budget'!V687+'Program Budget'!V761+'Program Budget'!V833+'Program Budget'!V892 -> 1 | T12: ='Program Budget'!X13+'Program Budget'!X154+'Program Budget'!X216+'Program Budget'!X275+'Program Budget'!X344+'Program Budget'!X411+'Program Budget'!X483+'Program Budget'!X558+'Program Budget'!X613+'Program Budget'!X687+'Program Budget'!X761+'Program Budget'!X833+'Program Budget'!X892 -> 99549.962 | U12: =E12+H12+K12+N12+Q12+T12 -> 524049.2 | V12: =C12+F12+I12+L12+O12+R12 -> 71 | W12: =U12/V12 -> 7380.9746
B13: ='Program Budget'!D14 -> Policy & Sustainability Specialist | C13: ='Program Budget'!G14 -> 0 | D13: ='Program Budget'!E14+'Program Budget'!E155+'Program Budget'!E217+'Program Budget'!E276+'Program Budget'!E345+'Program Budget'!E412+'Program Budget'!E484+'Program Budget'!E559+'Program Budget'!E614+'Program Budget'!E688+'Program Budget'!E762+'Program Budget'!E834+'Program Budget'!E893 -> 1 | E13: ='Program Budget'!I14+'Program Budget'!I155+'Program Budget'!I217+'Program Budget'!I276+'Program Budget'!I345+'Program Budget'!I412+'Program Budget'!I484+'Program Budget'!I559+'Program Budget'!I614+'Program Budget'!I688+'Program Budget'!I762+'Program Budget'!I834+'Program Budget'!I893 -> 0 | F13: ='Program Budget'!K14 -> 0 | G13: ='Program Budget'!J14+'Program Budget'!J155+'Program Budget'!J217+'Program Budget'!J276+'Program Budget'!J345+'Program Budget'!J412+'Program Budget'!J484+'Program Budget'!J559+'Program Budget'!J614+'Program Budget'!J688+'Program Budget'!J762+'Program Budget'!J834+'Program Budget'!J893 -> 1 | H13: ='Program Budget'!L14+'Program Budget'!L155+'Program Budget'!L217+'Program Budget'!L276+'Program Budget'!L345+'Program Budget'!L412+'Program Budget'!L484+'Program Budget'!L559+'Program Budget'!L614+'Program Budget'!L688+'Program Budget'!L762+'Program Budget'!L834+'Program Budget'!L893 -> 0 | I13: ='Program Budget'!N14 -> 7 | J13: ='Program Budget'!M14+'Program Budget'!M155+'Program Budget'!M217+'Program Budget'!M276+'Program Budget'!M345+'Program Budget'!M412+'Program Budget'!M484+'Program Budget'!M559+'Program Budget'!M614+'Program Budget'!M688+'Program Budget'!M762+'Program Budget'!M834+'Program Budget'!M893 -> 1 | K13: ='Program Budget'!O14+'Program Budget'!O155+'Program Budget'!O217+'Program Budget'!O276+'Program Budget'!O345+'Program Budget'!O412+'Program Budget'!O484+'Program Budget'!O559+'Program Budget'!O614+'Program Budget'!O688+'Program Budget'!O762+'Program Budget'!O834+'Program Budget'!O893 -> 11576.25 | L13: ='Program Budget'!Q14 -> 12 | M13: ='Program Budget'!P14+'Program Budget'!P155+'Program Budget'!P217+'Program Budget'!P276+'Program Budget'!P345+'Program Budget'!P412+'Program Budget'!P484+'Program Budget'!P559+'Program Budget'!P614+'Program Budget'!P688+'Program Budget'!P762+'Program Budget'!P834+'Program Budget'!P893 -> 1 | N13: ='Program Budget'!R14+'Program Budget'!R155+'Program Budget'!R217+'Program Budget'!R276+'Program Budget'!R345+'Program Budget'!R412+'Program Budget'!R484+'Program Budget'!R559+'Program Budget'!R614+'Program Budget'!R688+'Program Budget'!R762+'Program Budget'!R834+'Program Budget'!R893 -> 20837.25 | O13: ='Program Budget'!T14 -> 12 | P13: ='Program Budget'!S14+'Program Budget'!S155+'Program Budget'!S217+'Program Budget'!S276+'Program Budget'!S345+'Program Budget'!S412+'Program Budget'!S484+'Program Budget'!S559+'Program Budget'!S614+'Program Budget'!S688+'Program Budget'!S762+'Program Budget'!S834+'Program Budget'!S893 -> 1 | Q13: ='Program Budget'!U14+'Program Budget'!U155+'Program Budget'!U217+'Program Budget'!U276+'Program Budget'!U345+'Program Budget'!U412+'Program Budget'!U484+'Program Budget'!U559+'Program Budget'!U614+'Program Budget'!U688+'Program Budget'!U762+'Program Budget'!U834+'Program Budget'!U893 -> 21879.113 | R13: ='Program Budget'!W14 -> 6 | S13: ='Program Budget'!V14+'Program Budget'!V155+'Program Budget'!V217+'Program Budget'!V276+'Program Budget'!V345+'Program Budget'!V412+'Program Budget'!V484+'Program Budget'!V559+'Program Budget'!V614+'Program Budget'!V688+'Program Budget'!V762+'Program Budget'!V834+'Program Budget'!V893 -> 1 | T13: ='Program Budget'!X14+'Program Budget'!X155+'Program Budget'!X217+'Program Budget'!X276+'Program Budget'!X345+'Program Budget'!X412+'Program Budget'!X484+'Program Budget'!X559+'Program Budget'!X614+'Program Budget'!X688+'Program Budget'!X762+'Program Budget'!X834+'Program Budget'!X893 -> 11486.534 | U13: =E13+H13+K13+N13+Q13+T13 -> 65779.147 | V13: =C13+F13+I13+L13+O13+R13 -> 37 | W13: =U13/V13 -> 1777.8148
