Workbook

Sheet Budget Summary
A1: PARTNERS OF THE AMERICAS
A2: SUMMARY BUDGET
A3: Funding Opportunity: , CFDA: 19.019
A4: Program Name
A5: 48 Months
A6: BUDGET SUMMARY CATEGORIES | B6: Year 1 | E6: Year 2 | H6: Year 3 | K6: Year 4 | N6: Total
B7: JTIP | C7: Cost Share | D7: Total | E7: JTIP | F7: Cost Share | G7: Total | H7: JTIP | I7: Cost Share | J7: Total | K7: JTIP | L7: Cost Share | M7: Total | N7: JTIP | O7: Cost Share | P7: Total
A8: 1. Personnel | B8: ='Line Item Budget'!H16 -> 0 | C8: ='Line Item Budget'!I16 -> 0 | D8: =B8+C8 -> 0 | E8: ='Line Item Budget'!N16 -> 0 | F8: ='Line Item Budget'!O16 -> 0 | G8: =E8+F8 -> 0 | H8: ='Line Item Budget'!T16 -> 0 | I8: ='Line Item Budget'!U16 -> 0 | J8: =H8+I8 -> 0 | K8: ='Line Item Budget'!Z16 -> 0 | L8: ='Line Item Budget'!AA16 -> 0 | M8: =K8+L8 -> 0 | N8: ='Line Item Budget'!AB16 -> 0 | O8: ='Line Item Budget'!AC16 -> 0 | P8: =N8+O8 -> 0
A9: 2. Fringe Benefits | B9: ='Line Item Budget'!H25 -> 0 | C9: ='Line Item Budget'!I25 -> 0 | D9: =B9+C9 -> 0 | E9: ='Line Item Budget'!N25 -> 0 | F9: ='Line Item Budget'!O25 -> 0 | G9: =E9+F9 -> 0 | H9: ='Line Item Budget'!T25 -> 0 | I9: ='Line Item Budget'!U25 -> 0 | J9: =H9+I9 -> 0 | K9: ='Line Item Budget'!Z25 -> 0 | L9: ='Line Item Budget'!AA25 -> 0 | M9: =K9+L9 -> 0 | N9: ='Line Item Budget'!AB25 -> 0 | O9: ='Line Item Budget'!AC25 -> 0 | P9: =N9+O9 -> 0
A10: 3. Travel | B10: ='Line Item Budget'!H41 -> 0 | C10: ='Line Item Budget'!I41 -> 0 | D10: =B10+C10 -> 0 | E10: ='Line Item Budget'!N41 -> 0 | F10: ='Line Item Budget'!O41 -> 0 | G10: =E10+F10 -> 0 | H10: ='Line Item Budget'!T41 -> 0 | I10: ='Line Item Budget'!U41 -> 0 | J10: =H10+I10 -> 0 | K10: ='Line Item Budget'!Z41 -> 0 | L10: ='Line Item Budget'!AA41 -> 0 | M10: =K10+L10 -> 0 | N10: ='Line Item Budget'!AB41 -> 0 | O10: ='Line Item Budget'!AC41 -> 0 | P10: =N10+O10 -> 0
A11: 4. Equipment
A12: 5. Supplies | B12: ='Line Item Budget'!H48 -> 0 | C12: ='Line Item Budget'!I48 -> 0 | D12: =B12+C12 -> 0 | E12: ='Line Item Budget'!N48 -> 0 | F12: ='Line Item Budget'!O48 -> 0 | G12: =E12+F12 -> 0 | H12: ='Line Item Budget'!T48 -> 0 | I12: ='Line Item Budget'!U48 -> 0 | J12: =H12+I12 -> 0 | K12: ='Line Item Budget'!Z48 -> 0 | L12: ='Line Item Budget'!AA48 -> 0 | M12: =K12+L12 -> 0 | N12: ='Line Item Budget'!AB48 -> 0 | O12: ='Line Item Budget'!AC48 -> 0 | P12: =N12+O12 -> 0
A13: 6. Contractual | B13: ='Line Item Budget'!H54 -> 0 | C13: ='Line Item Budget'!I54 -> 0 | D13: =B13+C13 -> 0 | E13: ='Line Item Budget'!N54 -> 0 | F13: ='Line Item Budget'!O54 -> 0 | G13: =E13+F13 -> 0 | H13: ='Line Item Budget'!T54 -> 0 | I13: ='Line Item Budget'!U54 -> 0 | J13: =H13+I13 -> 0 | K13: ='Line Item Budget'!Z54 -> 0 | L13: ='Line Item Budget'!AA54 -> 0 | M13: =K13+L13 -> 0 | N13: ='Line Item Budget'!AB54 -> 0 | O13: ='Line Item Budget'!AC54 -> 0 | P13: =N13+O13 -> 0
A14: 7. Construction
A15: 8. Other Direct Costs | B15: ='Line Item Budget'!H85 -> 0 | C15: ='Line Item Budget'!I85 -> 0 | D15: =B15+C15 -> 0 | E15: ='Line Item Budget'!N85 -> 0 | F15: ='Line Item Budget'!O85 -> 0 | G15: =E15+F15 -> 0 | H15: ='Line Item Budget'!T85 -> 0 | I15: ='Line Item Budget'!U85 -> 0 | J15: =H15+I15 -> 0 | K15: ='Line Item Budget'!Z85 -> 0 | L15: ='Line Item Budget'!AA85 -> 0 | M15: =K15+L15 -> 0 | N15: ='Line Item Budget'!AB85 -> 0 | O15: ='Line Item Budget'!AC85 -> 0 | P15: =N15+O15 -> 0
A16: 9. Total Direct Costs | B16: =SUM(B8:B15) -> 0 | C16: =SUM(C8:C15) -> 0 | D16: =SUM(D8:D15) -> 0 | E16: =SUM(E8:E15) -> 0 | F16: =SUM(F8:F15) -> 0 | G16: =SUM(G8:G15) -> 0 | H16: =SUM(H8:H15) -> 0 | I16: =SUM(I8:I15) -> 0 | ... P16: =SUM(P8:P15) -> 0
A17: 10. Indirect Costs | B17: ='Line Item Budget'!H87 -> 0 | C17: ='Line Item Budget'!I87 -> 0 | D17: =B17+C17 -> 0 | E17: ='Line Item Budget'!N87 -> 0 | F17: ='Line Item Budget'!O87 -> 0 | G17: =E17+F17 -> 0 | H17: ='Line Item Budget'!T87 -> 0 | I17: ='Line Item Budget'!U87 -> 0 | J17: =H17+I17 -> 0 | K17: ='Line Item Budget'!Z87 -> 0 | L17: ='Line Item Budget'!AA87 -> 0 | M17: =K17+L17 -> 0 | N17: ='Line Item Budget'!AB87 -> 0 | O17: ='Line Item Budget'!AC87 -> 0 | P17: =N17+O17 -> 0
A18: 11. Total Costs | B18: =B16+B17 -> 0 | C18: =C16+C17 -> 0 | D18: =D16+D17 -> 0 | E18: =E16+E17 -> 0 | F18: =F16+F17 -> 0 | G18: =G16+G17 -> 0 | H18: =H16+H17 -> 0 | I18: =I16+I17 -> 0 | ... P18: =P16+P17 -> 0

Sheet Line Item Budget
A1: PARTNERS OF THE AMERICAS
A2: Detailed Budget
A3: Funding Opportunity: , CFDA: 19.019
A4: Name of Project
A5: PARTNERS OF THE AMERICAS
A6: All costs in US$ | B6: Year 1 | J6: Year 2 | P6: Year 3 | V6: Year 4 | AB6: Total
A7: Budget Line Items | B7: No. | C7: Unit Type | D7: Freq. | E7: % | F7: Rate | G7: Total | H7: JTIP | I7: Cost Share | J7: No. | K7: Freq. | L7: Rate | M7: Total | N7: JTIP | O7: Cost Share | P7: No. | Q7: Freq. | R7: Rate | S7: Total | T7: JTIP | U7: Cost Share | V7: No. | W7: Freq. | X7: Rate | Y7: Total | Z7: JTIP | AA7: Cost Share | AB7: JTIP | AC7: Cost Share | AD7: Grand Total
A8: Personnel
A9: Project Coordinator (XX%) | B9: 0 | C9: FTE/month | D9: 0 | E9: 0 | F9: 0 | G9: =B9*F9*D9*E9 -> 0 | H9: =G9 -> 0 | I9: =G9-H9 -> 0 | J9: 0 | K9: 0 | L9: =F9*1.04 -> 0 | M9: =J9*L9*K9*E9 -> 0 | N9: =M9 -> 0 | O9: =M9-N9 -> 0 | P9: 0 | Q9: 0 | R9: =L9*1.04 -> 0 | S9: =P9*R9*Q9*E9 -> 0 | T9: =S9 -> 0 | U9: =S9-T9 -> 0 | V9: 0 | W9: 0 | X9: =R9*1.04 -> 0 | Y9: =V9*X9*W9*K9 -> 0 | Z9: =Y9 -> 0 | AA9: =Y9-Z9 -> 0 | AB9: =H9+N9+T9+Z9 -> 0 | AC9: =I9+O9+U9+AA9 -> 0 | AD9: =AB9+AC9 -> 0
A10: M&E Specialist (XX%) | B10: 0 | C10: FTE/month | D10: 0 | E10: 0 | F10: 0 | G10: =B10*F10*D10*E10 -> 0 | H10: =G10 -> 0 | I10: =G10-H10 -> 0 | J10: 0 | K10: 0 | L10: =F10*1.04 -> 0 | M10: =J10*L10*K10*E10 -> 0 | N10: =M10 -> 0 | O10: =M10-N10 -> 0 | P10: 0 | Q10: 0 | R10: =L10*1.04 -> 0 | S10: =P10*R10*Q10*E10 -> 0 | T10: =S10 -> 0 | U10: =S10-T10 -> 0 | V10: 0 | W10: 0 | X10: =R10*1.04 -> 0 | Y10: =V10*X10*W10*K10 -> 0 | Z10: =Y10 -> 0 | AA10: =Y10-Z10 -> 0 | AB10: =H10+N10+T10+Z10 -> 0 | AC10: =I10+O10+U10+AA10 -> 0 | AD10: =AB10+AC10 -> 0
A11: Position (XX%) | B11: 0 | C11: FTE/month | D11: 0 | E11: 0 | F11: 0 | G11: =B11*F11*D11*E11 -> 0 | H11: =G11 -> 0 | I11: 0 | J11: 0 | K11: 0 | L11: =F11*1.04 -> 0 | M11: =J11*L11*K11*E11 -> 0 | N11: =M11 -> 0 | O11: 0 | P11: 0 | Q11: 0 | R11: =L11*1.04 -> 0 | S11: =P11*R11*Q11*E11 -> 0 | T11: =S11 -> 0 | U11: 0 | V11: 0 | W11: 0 | X11: =R11*1.04 -> 0 | Y11: =V11*X11*W11*K11 -> 0 | Z11: =Y11 -> 0 | AA11: 0 | AB11: =H11+N11+T11+Z11 -> 0 | AC11: =I11+O11+U11+AA11 -> 0 | AD11: =AB11+AC11 -> 0
A12: Position (XX%) | B12: 0 | C12: FTE/month | D12: 0 | E12: 0 | F12: 0 | G12: =B12*F12*D12*E12 -> 0 | H12: =G12 -> 0 | I12: 0 | J12: 0 | K12: 0 | L12: =F12*1.04 -> 0 | M12: =J12*L12*K12*E12 -> 0 | N12: =M12 -> 0 | O12: 0 | P12: 0 | Q12: 0 | R12: =L12*1.04 -> 0 | S12: =P12*R12*Q12*E12 -> 0 | T12: =S12 -> 0 | U12: 0 | V12: 0 | W12: 0 | X12: =R12*1.04 -> 0 | Y12: =V12*X12*W12*K12 -> 0 | Z12: =Y12 -> 0 | AA12: 0 | AB12: =H12+N12+T12+Z12 -> 0 | AC12: =I12+O12+U12+AA12 -> 0 | AD12: =AB12+AC12 -> 0
A13: Position (XX%) | B13: 0 | C13: FTE/month | D13: 0 | E13: 0 | F13: 0 | G13: =B13*F13*D13*E13 -> 0 | H13: =G13 -> 0 | I13: =G13-H13 -> 0 | J13: 0 | K13: 0 | L13: =F13*1.04 -> 0 | M13: =J13*L13*K13*E13 -> 0 | N13: =M13 -> 0 | O13: =M13-N13 -> 0 | P13: 0 | Q13: 0 | R13: =L13*1.04 -> 0 | S13: =P13*R13*Q13*E13 -> 0 | T13: =S13 -> 0 | U13: =S13-T13 -> 0 | V13: 0 | W13: 0 | X13: =R13*1.04 -> 0 | Y13: =V13*X13*W13*K13 -> 0 | Z13: =Y13 -> 0 | AA13: =Y13-Z13 -> 0 | AB13: =H13+N13+T13+Z13 -> 0 | AC13: =I13+O13+U13+AA13 -> 0 | AD13: =AB13+AC13 -> 0
A14: Position (XX%) | B14: 0 | C14: FTE/month | D14: 0 | E14: 0 | F14: 0 | G14: =B14*F14*D14*E14 -> 0 | H14: =G14 -> 0 | I14: =G14-H14 -> 0 | J14: 0 | K14: 0 | L14: =F14*1.04 -> 0 | M14: =J14*L14*K14*E14 -> 0 | N14: =M14 -> 0 | O14: =M14-N14 -> 0 | P14: 0 | Q14: 0 | R14: =L14*1.04 -> 0 | S14: =P14*R14*Q14*E14 -> 0 | T14: =S14 -> 0 | U14: =S14-T14 -> 0 | V14: 0 | W14: 0 | X14: =R14*1.04 -> 0 | Y14: =V14*X14*W14*K14 -> 0 | Z14: =Y14 -> 0 | AA14: =Y14-Z14 -> 0 | AB14: =H14+N14+T14+Z14 -> 0 | AC14: =I14+O14+U14+AA14 -> 0 | AD14: =AB14+AC14 -> 0
A15: Position (XX%) | B15: 0 | C15: FTE/month | D15: 0 | E15: 0 | F15: 0 | G15: =B15*F15*D15*E15 -> 0 | H15: =G15 -> 0 | I15: =G15-H15 -> 0 | J15: 0 | K15: 0 | L15: =F15*1.04 -> 0 | M15: =J15*L15*K15*E15 -> 0 | N15: =M15 -> 0 | O15: =M15-N15 -> 0 | P15: 0 | Q15: 0 | R15: =L15*1.04 -> 0 | S15: =P15*R15*Q15*E15 -> 0 | T15: =S15 -> 0 | U15: =S15-T15 -> 0 | V15: 0 | W15: 0 | X15: =R15*1.04 -> 0 | Y15: =V15*X15*W15*K15 -> 0 | Z15: =Y15 -> 0 | AA15: =Y15-Z15 -> 0 | AB15: =H15+N15+T15+Z15 -> 0 | AC15: =I15+O15+U15+AA15 -> 0 | AD15: =AB15+AC15 -> 0
A16: Subtotal Personnel | G16: =SUM(G9:G15) -> 0 | H16: =SUM(H9:H15) -> 0 | I16: =SUM(I9:I15) -> 0 | M16: =SUM(M9:M15) -> 0 | N16: =SUM(N9:N15) -> 0 | O16: =SUM(O9:O15) -> 0 | S16: =SUM(S9:S15) -> 0 | T16: =SUM(T9:T15) -> 0 | U16: =SUM(U9:U15) -> 0 | Y16: =SUM(Y9:Y15) -> 0 | Z16: =SUM(Z9:Z15) -> 0 | AA16: =SUM(AA9:AA15) -> 0 | AB16: =SUM(AB9:AB15) -> 0 | AC16: =SUM(AC9:AC15) -> 0 | AD16: =SUM(AD9:AD15) -> 0
A17: Fringe Benefits
A18: =A9 -> Project Coordinator (XX%) | B18: =B9 -> 0 | C18: Month | D18: =D9 -> 0 | E18: 0 | F18: =F9 -> 0 | G18: =B18*F18*D18*E18 -> 0 | H18: =G18 -> 0 | I18: 0 | J18: =J9 -> 0 | K18: =K9 -> 0 | L18: =L9 -> 0 | M18: =E18*L18*J18*K18 -> 0 | N18: =M18 -> 0 | O18: =M18-N18 -> 0 | P18: =P9 -> 0 | Q18: =Q9 -> 0 | R18: =R9 -> 0 | S18: =E18*R18*P18*Q18 -> 0 | T18: =S18 -> 0 | U18: =S18-T18 -> 0 | V18: =V9 -> 0 | W18: =W9 -> 0 | X18: =X9 -> 0 | Y18: =K18*X18*V18*W18 -> 0 | Z18: =Y18 -> 0 | AA18: =Y18-Z18 -> 0 | AB18: =H18+N18+T18+Z18 -> 0 | AC18: =I18+O18+U18+AA18 -> 0 | AD18: =AB18+AC18 -> 0
A19: =A10 -> M&E Specialist (XX%) | B19: =B10 -> 0 | C19: Month | D19: =D10 -> 0 | E19: 0 | F19: =F10 -> 0 | G19: =B19*F19*D19*E19 -> 0 | H19: =G19 -> 0 | I19: 0 | J19: =J10 -> 0 | K19: =K10 -> 0 | L19: =L10 -> 0 | M19: =E19*L19*J19*K19 -> 0 | N19: =M19 -> 0 | O19: =M19-N19 -> 0 | P19: =P10 -> 0 | Q19: =Q10 -> 0 | R19: =R10 -> 0 | S19: =E19*R19*P19*Q19 -> 0 | T19: =S19 -> 0 | U19: =S19-T19 -> 0 | V19: =V10 -> 0 | W19: =W10 -> 0 | X19: =X10 -> 0 | Y19: =K19*X19*V19*W19 -> 0 | Z19: =Y19 -> 0 | AA19: =Y19-Z19 -> 0 | AB19: =H19+N19+T19+Z19 -> 0 | AC19: =I19+O19+U19+AA19 -> 0 | AD19: =AB19+AC19 -> 0
A20: =A11 -> Position (XX%) | B20: =B11 -> 0 | C20: Month | D20: =D11 -> 0 | E20: 0 | F20: =F11 -> 0 | G20: =B20*F20*D20*E20 -> 0 | H20: =G20 -> 0 | I20: 0 | J20: =J11 -> 0 | K20: =K11 -> 0 | L20: =L11 -> 0 | M20: =E20*L20*J20*K20 -> 0 | N20: =M20 -> 0 | O20: =M20-N20 -> 0 | P20: =P11 -> 0 | Q20: =Q11 -> 0 | R20: =R11 -> 0 | S20: =E20*R20*P20*Q20 -> 0 | T20: =S20 -> 0 | U20: =S20-T20 -> 0 | V20: =V11 -> 0 | W20: =W11 -> 0 | X20: =X11 -> 0 | Y20: =K20*X20*V20*W20 -> 0 | Z20: =Y20 -> 0 | AA20: =Y20-Z20 -> 0 | AB20: =H20+N20+T20+Z20 -> 0 | AC20: =I20+O20+U20+AA20 -> 0 | AD20: =AB20+AC20 -> 0
A21: =A12 -> Position (XX%) | B21: =B12 -> 0 | C21: Month | D21: =D12 -> 0 | E21: 0 | F21: =F12 -> 0 | G21: =B21*F21*D21*E21 -> 0 | H21: =G21 -> 0 | I21: 0 | J21: =J12 -> 0 | K21: =K12 -> 0 | L21: =L12 -> 0 | M21: =E21*L21*J21*K21 -> 0 | N21: =M21 -> 0 | O21: =M21-N21 -> 0 | P21: =P12 -> 0 | Q21: =Q12 -> 0 | R21: =R12 -> 0 | S21: =E21*R21*P21*Q21 -> 0 | T21: =S21 -> 0 | U21: =S21-T21 -> 0 | V21: =V12 -> 0 | W21: =W12 -> 0 | X21: =X12 -> 0 | Y21: =K21*X21*V21*W21 -> 0 | Z21: =Y21 -> 0 | AA21: =Y21-Z21 -> 0 | AB21: =H21+N21+T21+Z21 -> 0 | AC21: =I21+O21+U21+AA21 -> 0 | AD21: =AB21+AC21 -> 0
A22: =A13 -> Position (XX%) | B22: =B13 -> 0 | C22: Month | D22: =D13 -> 0 | E22: 0 | F22: =F13 -> 0 | G22: =B22*F22*D22*E22 -> 0 | H22: =G22 -> 0 | I22: 0 | J22: =J13 -> 0 | K22: =K13 -> 0 | L22: =L13 -> 0 | M22: =E22*L22*J22*K22 -> 0 | N22: =M22 -> 0 | O22: =M22-N22 -> 0 | P22: =P13 -> 0 | Q22: =Q13 -> 0 | R22: =R13 -> 0 | S22: =E22*R22*P22*Q22 -> 0 | T22: =S22 -> 0 | U22: =S22-T22 -> 0 | V22: =V13 -> 0 | W22: =W13 -> 0 | X22: =X13 -> 0 | Y22: =K22*X22*V22*W22 -> 0 | Z22: =Y22 -> 0 | AA22: =Y22-Z22 -> 0 | AB22: =H22+N22+T22+Z22 -> 0 | AC22: =I22+O22+U22+AA22 -> 0 | AD22: =AB22+AC22 -> 0
A23: =A14 -> Position (XX%) | B23: =B14 -> 0 | C23: Month | D23: =D14 -> 0 | E23: 0 | F23: =F14 -> 0 | G23: =B23*F23*D23*E23 -> 0 | H23: =G23 -> 0 | I23: 0 | J23: =J14 -> 0 | K23: =K14 -> 0 | L23: =L14 -> 0 | M23: =E23*L23*J23*K23 -> 0 | N23: =M23 -> 0 | O23: =M23-N23 -> 0 | P23: =P14 -> 0 | Q23: =Q14 -> 0 | R23: =R14 -> 0 | S23: =E23*R23*P23*Q23 -> 0 | T23: =S23 -> 0 | U23: =S23-T23 -> 0 | V23: =V14 -> 0 | W23: =W14 -> 0 | X23: =X14 -> 0 | Y23: =K23*X23*V23*W23 -> 0 | Z23: =Y23 -> 0 | AA23: =Y23-Z23 -> 0 | AB23: =H23+N23+T23+Z23 -> 0 | AC23: =I23+O23+U23+AA23 -> 0 | AD23: =AB23+AC23 -> 0
A24: =A15 -> Position (XX%) | B24: =B15 -> 0 | C24: Month | D24: =D15 -> 0 | E24: 0 | F24: =F15 -> 0 | G24: =B24*F24*D24*E24 -> 0 | H24: =G24 -> 0 | I24: 0 | J24: =J15 -> 0 | K24: =K15 -> 0 | L24: =L15 -> 0 | M24: =E24*L24*J24*K24 -> 0 | N24: =M24 -> 0 | O24: =M24-N24 -> 0 | P24: =P15 -> 0 | Q24: =Q15 -> 0 | R24: =R15 -> 0 | S24: =E24*R24*P24*Q24 -> 0 | T24: =S24 -> 0 | U24: =S24-T24 -> 0 | V24: =V15 -> 0 | W24: =W15 -> 0 | X24: =X15 -> 0 | Y24: =K24*X24*V24*W24 -> 0 | Z24: =Y24 -> 0 | AA24: =Y24-Z24 -> 0 | AB24: =H24+N24+T24+Z24 -> 0 | AC24: =I24+O24+U24+AA24 -> 0 | AD24: =AB24+AC24 -> 0
A25: Subtotal Fringe Benefits | G25: =SUM(G18:G24) -> 0 | H25: =SUM(H18:H24) -> 0 | I25: =SUM(I18:I24) -> 0 | M25: =SUM(M18:M24) -> 0 | N25: =SUM(N18:N24) -> 0 | O25: =SUM(O18:O24) -> 0 | S25: =SUM(S18:S24) -> 0 | T25: =SUM(T18:T24) -> 0 | U25: =SUM(U18:U24) -> 0 | Y25: =SUM(Y18:Y24) -> 0 | Z25: =SUM(Z18:Z24) -> 0 | AA25: =SUM(AA18:AA24) -> 0 | AB25: =SUM(AB18:AB24) -> 0 | AC25: =SUM(AC18:AC24) -> 0 | AD25: =SUM(AD18:AD24) -> 0
A26: Travel
A27: 1. HQ Staff International Travel
A28: International Airfare (Washington, XXX) | B28: 0 | C28: Trip | D28: 0 | E28: 1 | F28: 0 | G28: =B28*F28*D28 -> 0 | H28: =G28 -> 0 | I28: =G28-H28 -> 0 | J28: 0 | K28: 0 | L28: =F28*1.03 -> 0 | M28: =J28*L28*K28*E28 -> 0 | N28: =M28 -> 0 | O28: =M28-N28 -> 0 | P28: 0 | Q28: 0 | R28: =L28*1.03 -> 0 | S28: =P28*R28*Q28*E28 -> 0 | T28: =S28 -> 0 | U28: =S28-T28 -> 0 | V28: 0 | W28: 0 | X28: =R28*1.03 -> 0 | Y28: =V28*X28*W28*K28 -> 0 | Z28: =Y28 -> 0 | AA28: =Y28-Z28 -> 0 | AB28: =H28+N28+T28+Z28 -> 0 | AC28: =I28+O28+U28+AA28 -> 0 | AD28: =AB28+AC28 -> 0
A29: Domestic Airfare (Mexico City - XXXX) | B29: 0 | C29: Trip | D29: 0 | E29: 1 | F29: 0 | G29: =B29*F29*D29 -> 0 | H29: =G29 -> 0 | I29: =G29-H29 -> 0 | J29: 0 | K29: 0 | L29: =F29*1.03 -> 0 | M29: =J29*L29*K29*E29 -> 0 | N29: =M29 -> 0 | O29: =M29-N29 -> 0 | P29: 0 | Q29: 0 | R29: =L29*1.03 -> 0 | S29: =P29*R29*Q29*E29 -> 0 | T29: =S29 -> 0 | U29: =S29-T29 -> 0 | V29: 0 | W29: 0 | X29: =R29*1.03 -> 0 | Y29: =V29*X29*W29*K29 -> 0 | Z29: =Y29 -> 0 | AA29: =Y29-Z29 -> 0 | AB29: =H29+N29+T29+Z29 -> 0 | AC29: =I29+O29+U29+AA29 -> 0 | AD29: =AB29+AC29 -> 0
A30: Ground Transportation | B30: 0 | C30: Trip | D30: 0 | E30: 1 | F30: 0 | G30: =B30*F30*D30 -> 0 | H30: =G30 -> 0 | I30: =G30-H30 -> 0 | J30: 0 | K30: 0 | L30: =F30*1.03 -> 0 | M30: =J30*L30*K30*E30 -> 0 | N30: =M30 -> 0 | O30: =M30-N30 -> 0 | P30: 0 | Q30: 0 | R30: =L30*1.03 -> 0 | S30: =P30*R30*Q30*E30 -> 0 | T30: =S30 -> 0 | U30: =S30-T30 -> 0 | V30: 0 | W30: 0 | X30: =R30*1.03 -> 0 | Y30: =V30*X30*W30*K30 -> 0 | Z30: =Y30 -> 0 | AA30: =Y30-Z30 -> 0 | AB30: =H30+N30+T30+Z30 -> 0 | AC30: =I30+O30+U30+AA30 -> 0 | AD30: =AB30+AC30 -> 0
A31: Lodging in XXX | B31: 0 | C31: Night | D31: 0 | E31: 1 | F31: 0 | G31: =B31*F31*D31 -> 0 | H31: =G31 -> 0 | I31: =G31-H31 -> 0 | J31: 0 | K31: 0 | L31: =F31*1.03 -> 0 | M31: =J31*L31*K31*E31 -> 0 | N31: =M31 -> 0 | O31: =M31-N31 -> 0 | P31: 0 | Q31: 0 | R31: =L31*1.03 -> 0 | S31: =P31*R31*Q31*E31 -> 0 | T31: =S31 -> 0 | U31: =S31-T31 -> 0 | V31: 0 | W31: 0 | X31: =R31*1.03 -> 0 | Y31: =V31*X31*W31*K31 -> 0 | Z31: =Y31 -> 0 | AA31: =Y31-Z31 -> 0 | AB31: =H31+N31+T31+Z31 -> 0 | AC31: =I31+O31+U31+AA31 -> 0 | AD31: =AB31+AC31 -> 0
A32: M&IE in XXX | B32: 0 | C32: Day | D32: 0 | E32: 1 | F32: 0 | G32: =B32*F32*D32 -> 0 | H32: =G32 -> 0 | I32: =G32-H32 -> 0 | J32: 0 | K32: 0 | L32: =F32*1.03 -> 0 | M32: =J32*L32*K32*E32 -> 0 | N32: =M32 -> 0 | O32: =M32-N32 -> 0 | P32: 0 | Q32: 0 | R32: =L32*1.03 -> 0 | S32: =P32*R32*Q32*E32 -> 0 | T32: =S32 -> 0 | U32: =S32-T32 -> 0 | V32: 0 | W32: 0 | X32: =R32*1.03 -> 0 | Y32: =V32*X32*W32*K32 -> 0 | Z32: =Y32 -> 0 | AA32: =Y32-Z32 -> 0 | AB32: =H32+N32+T32+Z32 -> 0 | AC32: =I32+O32+U32+AA32 -> 0 | AD32: =AB32+AC32 -> 0
A33: 2. Local Staff In-Country Travel
A34: Domestic Airfare (location - location) | B34: 0 | C34: Trip | D34: 0 | E34: 1 | F34: 0 | G34: =B34*F34*D34 -> 0 | H34: =G34 -> 0 | I34: =G34-H34 -> 0 | J34: 0 | K34: 0 | L34: =F34*1.03 -> 0 | M34: =J34*L34*K34*E34 -> 0 | N34: =M34 -> 0 | O34: =M34-N34 -> 0 | P34: 0 | Q34: 0 | R34: =L34*1.03 -> 0 | S34: =P34*R34*Q34*E34 -> 0 | T34: =S34 -> 0 | U34: =S34-T34 -> 0 | V34: 0 | W34: 0 | X34: =R34*1.03 -> 0 | Y34: =V34*X34*W34*K34 -> 0 | Z34: =Y34 -> 0 | AA34: =Y34-Z34 -> 0 | AB34: =H34+N34+T34+Z34 -> 0 | AC34: =I34+O34+U34+AA34 -> 0 | AD34: =AB34+AC34 -> 0
A35: Lodging - XXX | B35: 0 | C35: Night | D35: 0 | E35: 1 | F35: 0 | G35: =B35*F35*D35 -> 0 | H35: =G35 -> 0 | I35: =G35-H35 -> 0 | J35: 0 | K35: 0 | L35: =F35*1.03 -> 0 | M35: =J35*L35*K35*E35 -> 0 | N35: =M35 -> 0 | O35: =M35-N35 -> 0 | P35: 0 | Q35: 0 | R35: =L35*1.03 -> 0 | S35: =P35*R35*Q35*E35 -> 0 | T35: =S35 -> 0 | U35: =S35-T35 -> 0 | V35: 0 | W35: 0 | X35: =R35*1.03 -> 0 | Y35: =V35*X35*W35*K35 -> 0 | Z35: =Y35 -> 0 | AA35: =Y35-Z35 -> 0 | AB35: =H35+N35+T35+Z35 -> 0 | AC35: =I35+O35+U35+AA35 -> 0 | AD35: =AB35+AC35 -> 0
A36: M&IE - XXX | B36: 0 | C36: Day | D36: 0 | E36: 1 | F36: 0 | G36: =B36*F36*D36 -> 0 | H36: =G36 -> 0 | I36: =G36-H36 -> 0 | J36: 0 | K36: 0 | L36: =F36*1.03 -> 0 | M36: =J36*L36*K36*E36 -> 0 | N36: =M36 -> 0 | O36: =M36-N36 -> 0 | P36: 0 | Q36: 0 | R36: =L36*1.03 -> 0 | S36: =P36*R36*Q36*E36 -> 0 | T36: =S36 -> 0 | U36: =S36-T36 -> 0 | V36: 0 | W36: 0 | X36: =R36*1.03 -> 0 | Y36: =V36*X36*W36*K36 -> 0 | Z36: =Y36 -> 0 | AA36: =Y36-Z36 -> 0 | AB36: =H36+N36+T36+Z36 -> 0 | AC36: =I36+O36+U36+AA36 -> 0 | AD36: =AB36+AC36 -> 0
A37: Lodging - XXX | B37: 0 | C37: Night | D37: 0 | E37: 1 | F37: 0 | G37: =B37*F37*D37 -> 0 | H37: =G37 -> 0 | I37: =G37-H37 -> 0 | J37: 0 | K37: 0 | L37: =F37*1.03 -> 0 | M37: =J37*L37*K37*E37 -> 0 | N37: =M37 -> 0 | O37: =M37-N37 -> 0 | P37: 0 | Q37: 0 | R37: =L37*1.03 -> 0 | S37: =P37*R37*Q37*E37 -> 0 | T37: =S37 -> 0 | U37: =S37-T37 -> 0 | V37: 0 | W37: 0 | X37: =R37*1.03 -> 0 | Y37: =V37*X37*W37*K37 -> 0 | Z37: =Y37 -> 0 | AA37: =Y37-Z37 -> 0 | AB37: =H37+N37+T37+Z37 -> 0 | AC37: =I37+O37+U37+AA37 -> 0 | AD37: =AB37+AC37 -> 0
A38: M&IE - XXX | B38: 0 | C38: Day | D38: 0 | E38: 1 | F38: 0 | G38: =B38*F38*D38 -> 0 | H38: =G38 -> 0 | I38: =G38-H38 -> 0 | J38: 0 | K38: 0 | L38: =F38*1.03 -> 0 | M38: =J38*L38*K38*E38 -> 0 | N38: =M38 -> 0 | O38: =M38-N38 -> 0 | P38: 0 | Q38: 0 | R38: =L38*1.03 -> 0 | S38: =P38*R38*Q38*E38 -> 0 | T38: =S38 -> 0 | U38: =S38-T38 -> 0 | V38: 0 | W38: 0 | X38: =R38*1.03 -> 0 | Y38: =V38*X38*W38*K38 -> 0 | Z38: =Y38 -> 0 | AA38: =Y38-Z38 -> 0 | AB38: =H38+N38+T38+Z38 -> 0 | AC38: =I38+O38+U38+AA38 -> 0 | AD38: =AB38+AC38 -> 0
A39: Transportation Stipend | B39: 0 | C39: Person | D39: 0 | E39: 1 | F39: 0 | G39: =B39*F39*D39 -> 0 | H39: =G39 -> 0 | I39: =G39-H39 -> 0 | J39: 0 | K39: 0 | L39: =F39*1.03 -> 0 | M39: =J39*L39*K39*E39 -> 0 | N39: =M39 -> 0 | O39: =M39-N39 -> 0 | P39: 0 | Q39: 0 | R39: =L39*1.03 -> 0 | S39: =P39*R39*Q39*E39 -> 0 | T39: =S39 -> 0 | U39: =S39-T39 -> 0 | V39: 0 | W39: 0 | X39: =R39*1.03 -> 0 | Y39: =V39*X39*W39*K39 -> 0 | Z39: =Y39 -> 0 | AA39: =Y39-Z39 -> 0 | AB39: =H39+N39+T39+Z39 -> 0 | AC39: =I39+O39+U39+AA39 -> 0 | AD39: =AB39+AC39 -> 0
A40: Ground Transportation | B40: 0 | C40: Month | D40: 0 | E40: 1 | F40: 0 | G40: =B40*F40*D40 -> 0 | H40: =G40 -> 0 | I40: =G40-H40 -> 0 | J40: 0 | K40: 0 | L40: =F40*1.03 -> 0 | M40: =J40*L40*K40*E40 -> 0 | N40: =M40 -> 0 | O40: =M40-N40 -> 0 | P40: 0 | Q40: 0 | R40: =L40*1.03 -> 0 | S40: =P40*R40*Q40*E40 -> 0 | T40: =S40 -> 0 | U40: =S40-T40 -> 0 | V40: 0 | W40: 0 | X40: =R40*1.03 -> 0 | Y40: =V40*X40*W40*K40 -> 0 | Z40: =Y40 -> 0 | AA40: =Y40-Z40 -> 0 | AB40: =H40+N40+T40+Z40 -> 0 | AC40: =I40+O40+U40+AA40 -> 0 | AD40: =AB40+AC40 -> 0
...
