Workbook
Name __pd1: [1]Rates!$J$24
Name __pd6: [1]Rates!$J$30
Name __tix1: [1]Rates!$J$40
Name __tix2: [1]Rates!$J$41
Name __tix6: [1]Rates!$J$47
Name ANPDH: '[2]Salary & PR Tax'!#REF!
Name Board: '[3]Schedule E - Other'!$F$102
Name CEE_Consult: #REF!
Name CENIDH: #REF!
Name Consultants: #REF!
Name Equipment: '[4]Schedule D - Equipment'!$E$26
Name fg: #REF!
Name Housing: '[2]Salary & PR Tax'!#REF!
Name inf: [5]Assumptions!$C$75
Name Inflation: '[6]Detail-1'!$J$2
Name Interns: #REF!
Name jenn: #REF!
Name Local_Hire: #REF!
Name Local_Hires: #REF!
Name Merit: '[6]Detail-1'!$J$1
Name padf01: '[7]Level of Effort'!$C$14
Name padf02: '[7]Level of Effort'!$C$15
Name padf03: '[7]Level of Effort'!$C$16
Name padf04: '[7]Level of Effort'!$C$17
Name padf05: [7]Rates!$J$23
Name postdif01: [7]Rates!$J$34
Name postdif02: [7]Rates!$J$65
Name Print_Titles_MI: #REF!
Name sdf: #REF!
Name Travel_Regional: #REF!
Name Travel_WDC: #REF!

Sheet Budget Summary
B1: Name of Subawardee:
B2: USAID RFA No. XXXXX
A4: Line Items | B4: Year 1 | E4: Year 2 | H4: Year 3 | K4: Year 4 | N4: Year 5 | Q4: Total | R4: Total | S4: Grand
B5: USAID | C5: Leverage | D5: Total | E5: USAID | F5: Leverage | G5: Total | H5: USAID | I5: Leverage | J5: Total | K5: USAID | L5: Leverage | M5: Total | N5: USAID | O5: Leverage | P5: Total | Q5: USAID | R5: Leverage | S5: Total
A7: Personnel | B7: =Budget!F28 -> 0 | C7: =Budget!G28 -> 0 | D7: =SUM(B7:C7) -> 0 | E7: =Budget!L28 -> 0 | F7: =Budget!M28 -> 0 | G7: =SUM(E7:F7) -> 0 | H7: =Budget!R28 -> 0 | I7: =Budget!S28 -> 0 | J7: =SUM(H7:I7) -> 0 | K7: =Budget!X28 -> 0 | L7: =Budget!Y28 -> 0 | M7: =SUM(K7:L7) -> 0 | N7: =Budget!AD28 -> 0 | O7: =Budget!AE28 -> 0 | P7: =SUM(N7:O7) -> 0 | Q7: =Budget!AG28 -> 0 | R7: =Budget!AH28 -> 0 | S7: =Budget!AI28 -> 0
A9: Fringe Benefits | B9: =Budget!F34 -> 0 | C9: =Budget!G34 -> 0 | D9: =Budget!H34 -> 0 | E9: =Budget!L34 -> 0 | F9: =Budget!M34 -> 0 | G9: =Budget!N34 -> 0 | H9: =Budget!R34 -> 0 | I9: =Budget!S34 -> 0 | J9: =Budget!T34 -> 0 | K9: =Budget!X34 -> 0 | L9: =Budget!Y34 -> 0 | M9: =Budget!Z34 -> 0 | N9: =Budget!AD34 -> 0 | O9: =Budget!AE34 -> 0 | P9: =Budget!AF34 -> 0 | Q9: =Budget!AG34 -> 0 | R9: =Budget!AH34 -> 0 | S9: =Budget!AI34 -> 0
A11: Travel | B11: =Budget!F59 -> 0 | C11: =Budget!G59 -> 0 | D11: =Budget!H59 -> 0 | E11: =Budget!L59 -> 0 | F11: =Budget!M59 -> 0 | G11: =Budget!N59 -> 0 | H11: =Budget!R59 -> 0 | I11: =Budget!S59 -> 0 | J11: =Budget!T59 -> 0 | K11: =Budget!X59 -> 0 | L11: =Budget!Y59 -> 0 | M11: =Budget!Z59 -> 0 | N11: =Budget!AD59 -> 0 | O11: =Budget!AE59 -> 0 | P11: =Budget!AF59 -> 0 | Q11: =Budget!AG59 -> 0 | R11: =Budget!AH59 -> 0 | S11: =Budget!AI59 -> 0
A13: Equipment | B13: =Budget!F66 -> 0 | C13: =Budget!G66 -> 0 | D13: =Budget!H66 -> 0 | E13: =Budget!L66 -> 0 | F13: =Budget!M66 -> 0 | G13: =Budget!N66 -> 0 | H13: =Budget!R66 -> 0 | I13: =Budget!S66 -> 0 | J13: =Budget!T66 -> 0 | K13: =Budget!X66 -> 0 | L13: =Budget!Y66 -> 0 | M13: =Budget!Z66 -> 0 | N13: =Budget!AD66 -> 0 | O13: =Budget!AE66 -> 0 | P13: =Budget!AF66 -> 0 | Q13: =Budget!AG66 -> 0 | R13: =Budget!AH66 -> 0 | S13: =Budget!AI66 -> 0
A15: Supplies | B15: =Budget!F88 -> 0 | C15: =Budget!G88 -> 0 | D15: =Budget!H88 -> 0 | E15: =Budget!L88 -> 0 | F15: =Budget!M88 -> 0 | G15: =Budget!N88 -> 0 | H15: =Budget!R88 -> 0 | I15: =Budget!S88 -> 0 | J15: =Budget!T88 -> 0 | K15: =Budget!X88 -> 0 | L15: =Budget!Y88 -> 0 | M15: =Budget!Z88 -> 0 | N15: =Budget!AD88 -> 0 | O15: =Budget!AE88 -> 0 | P15: =Budget!AF88 -> 0 | Q15: =Budget!AG88 -> 0 | R15: =Budget!AH88 -> 0 | S15: =Budget!AI88 -> 0
A17: Contractual | B17: =Budget!F106 -> 0 | C17: =Budget!G106 -> 0 | D17: =Budget!H106 -> 0 | E17: =Budget!L106 -> 0 | F17: =Budget!M106 -> 0 | G17: =Budget!N106 -> 0 | H17: =Budget!R106 -> 0 | I17: =Budget!S106 -> 0 | J17: =Budget!T106 -> 0 | K17: =Budget!X106 -> 0 | L17: =Budget!Y106 -> 0 | M17: =Budget!Z106 -> 0 | N17: =Budget!AD106 -> 0 | O17: =Budget!AE106 -> 0 | P17: =Budget!AF106 -> 0 | Q17: =Budget!AG106 -> 0 | R17: =Budget!AH106 -> 0 | S17: =Budget!AI106 -> 0
A19: Other Direct Costs | B19: =Budget!F140 -> 0 | C19: =Budget!G140 -> 0 | D19: =Budget!H140 -> 0 | E19: =Budget!L140 -> 0 | F19: =Budget!M140 -> 0 | G19: =Budget!N140 -> 0 | H19: =Budget!R140 -> 0 | I19: =Budget!S140 -> 0 | J19: =Budget!T140 -> 0 | K19: =Budget!X140 -> 0 | L19: =Budget!Y140 -> 0 | M19: =Budget!Z140 -> 0 | N19: =Budget!AD140 -> 0 | O19: =Budget!AE140 -> 0 | P19: =Budget!AF140 -> 0 | Q19: =Budget!AG140 -> 0 | R19: =Budget!AH140 -> 0 | S19: =Budget!AI140 -> 0
A21: Total Direct Costs | B21: =Budget!F142 -> 0 | C21: =Budget!G142 -> 0 | D21: =Budget!H142 -> 0 | E21: =Budget!L142 -> 0 | F21: =Budget!M142 -> 0 | G21: =Budget!N142 -> 0 | H21: =Budget!R142 -> 0 | I21: =Budget!S142 -> 0 | J21: =Budget!T142 -> 0 | K21: =Budget!X142 -> 0 | L21: =Budget!Y142 -> 0 | M21: =Budget!Z142 -> 0 | N21: =Budget!AD142 -> 0 | O21: =Budget!AE142 -> 0 | P21: =Budget!AF142 -> 0 | Q21: =Budget!AG142 -> 0 | R21: =Budget!AH142 -> 0 | S21: =Budget!AI142 -> 0
A22: Indirect Costs | B22: =Budget!F143 -> 0 | C22: =Budget!G143 -> 0 | D22: =Budget!H143 -> 0 | E22: =Budget!L143 -> 0 | F22: =Budget!M143 -> 0 | G22: =Budget!N143 -> 0 | H22: =Budget!R143 -> 0 | I22: =Budget!S143 -> 0 | J22: =Budget!T143 -> 0 | K22: =Budget!X143 -> 0 | L22: =Budget!Y143 -> 0 | M22: =Budget!Z143 -> 0 | N22: =Budget!AD143 -> 0 | O22: =Budget!AE143 -> 0 | P22: =Budget!AF143 -> 0 | Q22: =Budget!AG143 -> 0 | R22: =Budget!AH143 -> 0 | S22: =Budget!AI143 -> 0
A23: Total | B23: =Budget!F144 -> 0 | C23: =Budget!G144 -> 0 | D23: =Budget!H144 -> 0 | E23: =Budget!L144 -> 0 | F23: =Budget!M144 -> 0 | G23: =Budget!N144 -> 0 | H23: =Budget!R144 -> 0 | I23: =Budget!S144 -> 0 | J23: =Budget!T144 -> 0 | K23: =Budget!X144 -> 0 | L23: =Budget!Y144 -> 0 | M23: =Budget!Z144 -> 0 | N23: =Budget!AD144 -> 0 | O23: =Budget!AE144 -> 0 | P23: =Budget!AF144 -> 0 | Q23: =Budget!AG144 -> 0 | R23: =Budget!AH144 -> 0 | S23: =Budget!AI144 -> 0

Sheet Budget
B1: Name of Project:
B2: Name of Subawardee:
B3: Subaward Budget
B4: Country: XXX
A5: Budget Assumptions
A6: Inflation - Locally Purchased Goods/Services - XXXX% | B6: 1
A7: Merit Based Increases for Staff - XXXX% | B7: 1
A11: Line Items | F11: Year 1 | L11: Year 2 | O11: Year 3 | X11: Year 4 | AD11: Year 5 | AG11: Total | AH11: Total | AI11: Grand
B12: Unit | C12: Cost | D12: Duration | E12: Type | F12: USAID | G12: Leverage | H12: Total | I12: Unit | J12: Cost | K12: Duration | L12: USAID | M12: Leverage | N12: Total | O12: Unit | P12: Cost | Q12: Duration | R12: USAID | S12: Leverage | T12: Total | U12: Unit | V12: Cost | W12: Duration | X12: USAID | Y12: Leverage | Z12: Total | AA12: Unit | AB12: Cost | AC12: Duration | AD12: USAID | AE12: Leverage | AF12: Total | AG12: USAID | AH12: Leverage | AI12: Total
A14: Personnel
A15: Headquarters Personnel (include Level of Effort) | B15: LOE
A16: Position 1 | B16: 0 | C16: 0 | D16: 0 | E16: /months | F16: =D16*C16*B16 -> 0 | G16: 0 | H16: =SUM(F16:G16) -> 0 | I16: =B16 -> 0 | J16: =C16*$B$7 -> 0 | K16: 0 | L16: =I16*J16*K16 -> 0 | M16: 0 | N16: =SUM(L16:M16) -> 0 | O16: =B16 -> 0 | P16: =C16*$B$7*$B$7 -> 0 | Q16: 0 | R16: =O16*P16*Q16 -> 0 | S16: 0 | T16: =SUM(R16:S16) -> 0 | U16: =O16 -> 0 | V16: =C16*$B$7*$B$7*$B$7 -> 0 | W16: 0 | X16: =U16*V16*W16 -> 0 | Y16: 0 | Z16: =SUM(X16:Y16) -> 0 | AA16: =U16 -> 0 | AB16: =C16*$B$7*$B$7*$B$7*$B$7 -> 0 | AC16: 0 | AD16: =AA16*AB16*AC16 -> 0 | AE16: 0 | AF16: =SUM(AD16:AE16) -> 0 | AG16: =F16+L16+R16+X16+AD16 -> 0 | AH16: =G16+M16+S16+Y16+AE16 -> 0 | AI16: =SUM(AG16:AH16) -> 0
A17: Position 2 | B17: 0 | C17: 0 | D17: 0 | E17: /months | F17: =D17*C17*B17 -> 0 | G17: 0 | H17: =SUM(F17:G17) -> 0 | I17: =B17 -> 0 | J17: =C17*$B$7 -> 0 | K17: 0 | L17: =I17*J17*K17 -> 0 | M17: 0 | N17: =SUM(L17:M17) -> 0 | O17: =I17 -> 0 | P17: =C17*$B$7*$B$7 -> 0 | Q17: 0 | R17: =O17*P17*Q17 -> 0 | S17: 0 | T17: =SUM(R17:S17) -> 0 | U17: =O17 -> 0 | V17: =C17*$B$7*$B$7*$B$7 -> 0 | W17: 0 | X17: =U17*V17*W17 -> 0 | Y17: 0 | Z17: =SUM(X17:Y17) -> 0 | AA17: =U17 -> 0 | AB17: =C17*$B$7*$B$7*$B$7*$B$7 -> 0 | AC17: 0 | AD17: =AA17*AB17*AC17 -> 0 | AE17: 0 | AF17: =SUM(AD17:AE17) -> 0 | AG17: =F17+L17+R17+X17+AD17 -> 0 | AH17: =G17+M17+S17+Y17+AE17 -> 0 | AI17: =SUM(AG17:AH17) -> 0
A18: Subtotal HQ Personnel | F18: =SUM(F16:F17) -> 0 | G18: =SUM(G16:G17) -> 0 | H18: =SUM(H16:H17) -> 0 | L18: =SUM(L16:L17) -> 0 | M18: =SUM(M16:M17) -> 0 | N18: =SUM(N16:N17) -> 0 | R18: =SUM(R16:R17) -> 0 | S18: =SUM(S16:S17) -> 0 | T18: =SUM(T16:T17) -> 0 | X18: =SUM(X16:X17) -> 0 | Y18: =SUM(Y16:Y17) -> 0 | Z18: =SUM(Z16:Z17) -> 0 | AD18: =SUM(AD16:AD17) -> 0 | AE18: =SUM(AE16:AE17) -> 0 | AF18: =SUM(AF16:AF17) -> 0 | AG18: =SUM(AG16:AG17) -> 0 | AH18: =SUM(AH16:AH17) -> 0 | AI18: =SUM(AI16:AI17) -> 0
A19: *Key Personnel
A20: Field Personnel (include Level of Effort) | B20: LOE
A21: Field Position 1 | B21: 0 | C21: 0 | D21: 0 | E21: /months | F21: =D21*C21*B21 -> 0 | G21: 0 | H21: =SUM(F21:G21) -> 0 | I21: 0 | J21: =C21*$B$7 -> 0 | K21: 0 | L21: =J21*K21*I21 -> 0 | M21: 0 | N21: =SUM(L21:M21) -> 0 | O21: 0 | P21: =C21*$B$7*$B$7 -> 0 | Q21: 0 | R21: =Q21*P21*O21 -> 0 | S21: 0 | T21: =SUM(R21:S21) -> 0 | U21: 0 | V21: =C21*$B$7*$B$7*$B$7 -> 0 | W21: 0 | X21: =W21*V21*U21 -> 0 | Y21: 0 | Z21: =SUM(X21:Y21) -> 0 | AA21: 0 | AB21: =C21*$B$7*$B$7*$B$7*$B$7 -> 0 | AC21: 0 | AD21: =AC21*AB21*AA21 -> 0 | AE21: 0 | AF21: =SUM(AD21:AE21) -> 0 | AG21: =F21+L21+R21+X21+AD21 -> 0 | AH21: =G21+M21+S21+Y21+AE21 -> 0 | AI21: =SUM(AG21:AH21) -> 0
A22: Field Position 2 | B22: 0 | C22: 0 | D22: 0 | E22: /months | F22: =D22*C22*B22 -> 0 | G22: 0 | H22: =SUM(F22:G22) -> 0 | I22: 0 | J22: =C22*$B$7 -> 0 | K22: 0 | L22: =J22*K22*I22 -> 0 | M22: 0 | N22: =SUM(L22:M22) -> 0 | O22: 0 | P22: =C22*$B$7*$B$7 -> 0 | Q22: 0 | R22: =Q22*P22*O22 -> 0 | S22: 0 | T22: =SUM(R22:S22) -> 0 | U22: 0 | V22: =C22*$B$7*$B$7*$B$7 -> 0 | W22: 0 | X22: =W22*V22*U22 -> 0 | Y22: 0 | Z22: =SUM(X22:Y22) -> 0 | AA22: 0 | AB22: =C22*$B$7*$B$7*$B$7*$B$7 -> 0 | AC22: 0 | AD22: =AC22*AB22*AA22 -> 0 | AE22: 0 | AF22: =SUM(AD22:AE22) -> 0 | AG22: =F22+L22+R22+X22+AD22 -> 0 | AH22: =G22+M22+S22+Y22+AE22 -> 0 | AI22: =SUM(AG22:AH22) -> 0
A23: Field Position 3 | B23: 0 | C23: 0 | D23: 0 | E23: /months | F23: =D23*C23*B23 -> 0 | G23: 0 | H23: =SUM(F23:G23) -> 0 | I23: 0 | J23: =C23*$B$7 -> 0 | K23: 0 | L23: =J23*K23*I23 -> 0 | M23: 0 | N23: =SUM(L23:M23) -> 0 | O23: 0 | P23: =C23*$B$7*$B$7 -> 0 | Q23: 0 | R23: =Q23*P23*O23 -> 0 | S23: 0 | T23: =SUM(R23:S23) -> 0 | U23: 0 | V23: =C23*$B$7*$B$7*$B$7 -> 0 | W23: 0 | X23: =W23*V23*U23 -> 0 | Y23: 0 | Z23: =SUM(X23:Y23) -> 0 | AA23: 0 | AB23: =C23*$B$7*$B$7*$B$7*$B$7 -> 0 | AC23: 0 | AD23: =AC23*AB23*AA23 -> 0 | AE23: 0 | AF23: =SUM(AD23:AE23) -> 0 | AG23: =F23+L23+R23+X23+AD23 -> 0 | AH23: =G23+M23+S23+Y23+AE23 -> 0 | AI23: =SUM(AG23:AH23) -> 0
A24: Field Position 4 | B24: 0 | C24: 0 | D24: 0 | E24: /months | F24: =D24*C24*B24 -> 0 | G24: 0 | H24: =SUM(F24:G24) -> 0 | I24: 0 | J24: =C24*$B$7 -> 0 | K24: 0 | L24: =J24*K24*I24 -> 0 | M24: 0 | N24: =SUM(L24:M24) -> 0 | O24: 0 | P24: =C24*$B$7*$B$7 -> 0 | Q24: 0 | R24: =Q24*P24*O24 -> 0 | S24: 0 | T24: =SUM(R24:S24) -> 0 | U24: 0 | V24: =C24*$B$7*$B$7*$B$7 -> 0 | W24: 0 | X24: =W24*V24*U24 -> 0 | Y24: 0 | Z24: =SUM(X24:Y24) -> 0 | AA24: 0 | AB24: =C24*$B$7*$B$7*$B$7*$B$7 -> 0 | AC24: 0 | AD24: =AC24*AB24*AA24 -> 0 | AE24: 0 | AF24: =SUM(AD24:AE24) -> 0 | AG24: =F24+L24+R24+X24+AD24 -> 0 | AH24: =G24+M24+S24+Y24+AE24 -> 0 | AI24: =SUM(AG24:AH24) -> 0
A25: Field Position 5 | B25: 0 | C25: 0 | D25: 0 | E25: /months | F25: =D25*C25*B25 -> 0 | G25: 0 | H25: =SUM(F25:G25) -> 0 | I25: 0 | J25: =C25*$B$7 -> 0 | K25: 0 | L25: =J25*K25*I25 -> 0 | M25: 0 | N25: =SUM(L25:M25) -> 0 | O25: 0 | P25: =C25*$B$7*$B$7 -> 0 | Q25: 0 | R25: =Q25*P25*O25 -> 0 | S25: 0 | T25: =SUM(R25:S25) -> 0 | U25: 0 | V25: =C25*$B$7*$B$7*$B$7 -> 0 | W25: 0 | X25: =W25*V25*U25 -> 0 | Y25: 0 | Z25: =SUM(X25:Y25) -> 0 | AA25: 0 | AB25: =C25*$B$7*$B$7*$B$7*$B$7 -> 0 | AC25: 0 | AD25: =AC25*AB25*AA25 -> 0 | AE25: 0 | AF25: =SUM(AD25:AE25) -> 0 | AG25: =F25+L25+R25+X25+AD25 -> 0 | AH25: =G25+M25+S25+Y25+AE25 -> 0 | AI25: =SUM(AG25:AH25) -> 0
A26: Subtotal Field Personnel | F26: =SUM(F21:F25) -> 0 | G26: =SUM(G21:G25) -> 0 | H26: =SUM(H21:H25) -> 0 | L26: =SUM(L21:L25) -> 0 | M26: =SUM(M21:M25) -> 0 | N26: =SUM(N21:N25) -> 0 | R26: =SUM(R21:R25) -> 0 | S26: =SUM(S21:S25) -> 0 | T26: =SUM(T21:T25) -> 0 | X26: =SUM(X21:X25) -> 0 | Y26: =SUM(Y21:Y25) -> 0 | Z26: =SUM(Z21:Z25) -> 0 | AD26: =SUM(AD21:AD25) -> 0 | AE26: =SUM(AE21:AE25) -> 0 | AF26: =SUM(AF21:AF25) -> 0 | AG26: =F26+L26+R26+X26+AD26 -> 0 | AH26: =G26+M26+S26+Y26+AE26 -> 0 | AI26: =SUM(AG26:AH26) -> 0
A28: Personnel Total | F28: =F26+F18 -> 0 | G28: =G26+G18 -> 0 | H28: =H26+H18 -> 0 | L28: =L26+L18 -> 0 | M28: =M26+M18 -> 0 | N28: =N26+N18 -> 0 | R28: =R26+R18 -> 0 | S28: =S26+S18 -> 0 | T28: =T26+T18 -> 0 | X28: =X26+X18 -> 0 | Y28: =Y26+Y18 -> 0 | Z28: =Z26+Z18 -> 0 | AD28: =AD26+AD18 -> 0 | AE28: =AE26+AE18 -> 0 | AF28: =AF26+AF18 -> 0 | AG28: =AG26+AG18 -> 0 | AH28: =AH26+AH18 -> 0 | AI28: =AI26+AI18 -> 0
A30: Fringe Benefits
A31: Fringe Benefits - Headquarters | B31: 0 | F31: =F18*B31 -> 0 | G31: 0 | H31: =SUM(F31:G31) -> 0 | L31: =L18*$B$31 -> 0 | M31: 0 | N31: =SUM(L31:M31) -> 0 | R31: =R18*$B$31 -> 0 | S31: 0 | T31: =SUM(R31:S31) -> 0 | X31: =X18*$B$31 -> 0 | Y31: 0 | Z31: =SUM(X31:Y31) -> 0 | AD31: =AD18*$B$31 -> 0 | AE31: 0 | AF31: =SUM(AD31:AE31) -> 0 | AG31: =F31+L31+R31+X31+AD31 -> 0 | AH31: =G31+M31+S31+Y31+AE31 -> 0 | AI31: =SUM(AG31:AH31) -> 0
A32: Fringe Benefits CCN | B32: 0 | F32: =F26*$B$32 -> 0 | G32: 0 | H32: =SUM(F32:G32) -> 0 | L32: =L26*$B$32 -> 0 | M32: 0 | N32: =SUM(L32:M32) -> 0 | R32: =R26*$B$32 -> 0 | S32: 0 | T32: =SUM(R32:S32) -> 0 | X32: =X26*$B$32 -> 0 | Y32: 0 | Z32: =SUM(X32:Y32) -> 0 | AD32: =AD26*$B$32 -> 0 | AE32: 0 | AF32: =SUM(AD32:AE32) -> 0 | AG32: =F32+L32+R32+X32+AD32 -> 0 | AH32: =G32+M32+S32+Y32+AE32 -> 0 | AI32: =SUM(AG32:AH32) -> 0
A34: Fringe Benefits Total | F34: =SUM(F31:F33) -> 0 | G34: =SUM(G31:G33) -> 0 | H34: =SUM(H31:H33) -> 0 | L34: =SUM(L31:L33) -> 0 | M34: =SUM(M31:M33) -> 0 | N34: =SUM(N31:N33) -> 0 | R34: =SUM(R31:R33) -> 0 | S34: =SUM(S31:S33) -> 0 | T34: =SUM(T31:T33) -> 0 | X34: =SUM(X31:X33) -> 0 | Y34: =SUM(Y31:Y33) -> 0 | Z34: =SUM(Z31:Z33) -> 0 | AD34: =SUM(AD31:AD33) -> 0 | AE34: =SUM(AE31:AE33) -> 0 | AF34: =SUM(AF31:AF33) -> 0 | AG34: =SUM(AG31:AG33) -> 0 | AH34: =SUM(AH31:AH33) -> 0 | AI34: =SUM(AI31:AI33) -> 0
A36: Travel
A38: HQ Staff Travel
A39: HQ Staff - Airfare | B39: 0 | C39: 0 | D39: 0 | E39: /RT | F39: =D39*C39*B39 -> 0 | G39: 0 | H39: =SUM(F39:G39) -> 0 | I39: 0 | J39: =C39*$B$6 -> 0 | K39: 0 | L39: =I39*J39*K39 -> 0 | M39: 0 | N39: =SUM(L39:M39) -> 0 | O39: 0 | P39: =C39*$B$6*$B$6 -> 0 | Q39: 0 | R39: =O39*P39*Q39 -> 0 | S39: 0 | T39: =SUM(R39:S39) -> 0 | U39: 0 | V39: =C39*$B$6*$B$6*$B$6 -> 0 | W39: 0 | X39: =U39*V39*W39 -> 0 | Y39: 0 | Z39: =SUM(X39:Y39) -> 0 | AA39: 0 | AB39: =C39*$B$6*$B$6*$B$6*$B$6 -> 0 | AC39: 0 | AD39: =AA39*AB39*AC39 -> 0 | AE39: 0 | AF39: =SUM(AD39:AE39) -> 0 | AG39: =F39+L39+R39+X39+AD39 -> 0 | AH39: =G39+M39+S39+Y39+AE39 -> 0 | AI39: =SUM(AG39:AH39) -> 0
A40: HQ Staff - Lodging | B40: 0 | C40: 0 | D40: 0 | E40: /day | F40: =D40*C40*B40 -> 0 | G40: 0 | H40: =SUM(F40:G40) -> 0 | I40: 0 | J40: =C40*$B$6 -> 0 | K40: 0 | L40: =I40*J40*K40 -> 0 | M40: 0 | N40: =SUM(L40:M40) -> 0 | O40: 0 | P40: =C40*$B$6*$B$6 -> 0 | Q40: 0 | R40: =O40*P40*Q40 -> 0 | S40: 0 | T40: =SUM(R40:S40) -> 0 | U40: 0 | V40: =C40*$B$6*$B$6*$B$6 -> 0 | W40: 0 | X40: =U40*V40*W40 -> 0 | Y40: 0 | Z40: =SUM(X40:Y40) -> 0 | AA40: 0 | AB40: =C40*$B$6*$B$6*$B$6*$B$6 -> 0 | AC40: 0 | AD40: =AA40*AB40*AC40 -> 0 | AE40: 0 | AF40: =SUM(AD40:AE40) -> 0 | AG40: =F40+L40+R40+X40+AD40 -> 0 | AH40: =G40+M40+S40+Y40+AE40 -> 0 | AI40: =SUM(AG40:AH40) -> 0
A41: HQ Staff - Ground Transportation | B41: 0 | C41: 0 | D41: 0 | E41: /day | F41: =D41*C41*B41 -> 0 | G41: 0 | H41: =SUM(F41:G41) -> 0 | I41: 0 | J41: =C41*$B$6 -> 0 | K41: 0 | L41: =I41*J41*K41 -> 0 | M41: 0 | N41: =SUM(L41:M41) -> 0 | O41: 0 | P41: =C41*$B$6*$B$6 -> 0 | Q41: 0 | R41: =O41*P41*Q41 -> 0 | S41: 0 | T41: =SUM(R41:S41) -> 0 | U41: =U39 -> 0 | V41: =C41*$B$6*$B$6*$B$6 -> 0 | W41: 0 | X41: =U41*V41*W41 -> 0 | Y41: 0 | Z41: =SUM(X41:Y41) -> 0 | AA41: 0 | AB41: =C41*$B$6*$B$6*$B$6*$B$6 -> 0 | AC41: 0 | AD41: =AA41*AB41*AC41 -> 0 | AE41: 0 | AF41: =SUM(AD41:AE41) -> 0 | AG41: =F41+L41+R41+X41+AD41 -> 0 | AH41: =G41+M41+S41+Y41+AE41 -> 0 | AI41: =SUM(AG41:AH41) -> 0
A42: HQ Staff - Misc. Staff Travel Related Expenses | B42: 0 | C42: 0 | D42: 0 | E42: /trip | F42: =D42*C42*B42 -> 0 | G42: 0 | H42: =SUM(F42:G42) -> 0 | I42: 0 | J42: =C42*$B$6 -> 0 | K42: 0 | L42: =I42*J42*K42 -> 0 | M42: 0 | N42: =SUM(L42:M42) -> 0 | O42: 0 | P42: =C42*$B$6*$B$6 -> 0 | Q42: 0 | R42: =O42*P42*Q42 -> 0 | S42: 0 | T42: =SUM(R42:S42) -> 0 | U42: 0 | V42: =C42*$B$6*$B$6*$B$6 -> 0 | W42: 0 | X42: =U42*V42*W42 -> 0 | Y42: 0 | Z42: =SUM(X42:Y42) -> 0 | AA42: 0 | AB42: =C42*$B$6*$B$6*$B$6*$B$6 -> 0 | AC42: 0 | AD42: =AA42*AB42*AC42 -> 0 | AE42: 0 | AF42: =SUM(AD42:AE42) -> 0 | AG42: =F42+L42+R42+X42+AD42 -> 0 | AH42: =G42+M42+S42+Y42+AE42 -> 0 | AI42: =SUM(AG42:AH42) -> 0
A43: HQ Staff - M&IE | B43: 0 | C43: 0 | D43: 0 | E43: /trip | F43: =D43*C43*B43 -> 0 | G43: 0 | H43: =SUM(F43:G43) -> 0 | I43: 0 | J43: =C43*$B$6 -> 0 | K43: 0 | L43: =I43*J43*K43 -> 0 | M43: 0 | N43: =SUM(L43:M43) -> 0 | O43: 0 | P43: =C43*$B$6*$B$6 -> 0 | Q43: 0 | R43: =O43*P43*Q43 -> 0 | S43: 0 | T43: =SUM(R43:S43) -> 0 | U43: 0 | V43: =C43*$B$6*$B$6*$B$6 -> 0 | W43: 0 | X43: =U43*V43*W43 -> 0 | Y43: 0 | Z43: =SUM(X43:Y43) -> 0 | AA43: 0 | AB43: =C43*$B$6*$B$6*$B$6*$B$6 -> 0 | AC43: 0 | AD43: =AA43*AB43*AC43 -> 0 | AE43: 0 | AF43: =SUM(AD43:AE43) -> 0 | AG43: =F43+L43+R43+X43+AD43 -> 0 | AH43: =G43+M43+S43+Y43+AE43 -> 0 | AI43: =SUM(AG43:AH43) -> 0
A44: Total HQ Staff Travel | F44: =SUM(F39:F43) -> 0 | G44: =SUM(G39:G43) -> 0 | H44: =SUM(H39:H43) -> 0 | L44: =SUM(L39:L43) -> 0 | M44: =SUM(M39:M43) -> 0 | N44: =SUM(N39:N43) -> 0 | P44: =C44*$B$6*$B$6 -> 0 | R44: =SUM(R39:R43) -> 0 | S44: =SUM(S39:S43) -> 0 | T44: =SUM(T39:T43) -> 0 | V44: =C44*$B$6*$B$6*$B$6 -> 0 | X44: =SUM(X39:X43) -> 0 | Y44: =SUM(Y39:Y43) -> 0 | Z44: =SUM(Z39:Z43) -> 0 | AB44: =C44*$B$6*$B$6*$B$6*$B$6 -> 0 | AD44: =SUM(AD39:AD43) -> 0 | AE44: =SUM(AE39:AE43) -> 0 | AF44: =SUM(AF39:AF43) -> 0 | AG44: =SUM(AG39:AG43) -> 0 | AH44: =SUM(AH39:AH43) -> 0 | AI44: =SUM(AI39:AI43) -> 0
A46: Local Staff Travel
A47: Airfare for: XXX | B47: =B28 -> 0 | C47: 0 | D47: 0 | E47: /day | F47: =D47*C47*B47 -> 0 | G47: 0 | H47: =SUM(F47:G47) -> 0 | I47: 0 | J47: =C47*$B$6 -> 0 | K47: 0 | L47: =I47*J47*K47 -> 0 | M47: 0 | N47: =SUM(L47:M47) -> 0 | O47: =O28 -> 0 | P47: =C47*$B$6*$B$6 -> 0 | Q47: 0 | R47: =O47*P47*Q47 -> 0 | S47: 0 | T47: =SUM(R47:S47) -> 0 | U47: =U28 -> 0 | V47: =C47*$B$6*$B$6*$B$6 -> 0 | W47: 0 | X47: =U47*V47*W47 -> 0 | Y47: 0 | Z47: =SUM(X47:Y47) -> 0 | AA47: =AA28 -> 0 | AB47: =C47*$B$6*$B$6*$B$6*$B$6 -> 0 | AC47: 0 | AD47: =AA47*AB47*AC47 -> 0 | AE47: 0 | AF47: =SUM(AD47:AE47) -> 0 | AG47: =F47+L47+R47+X47+AD47 -> 0 | AH47: =G47+M47+S47+Y47+AE47 -> 0 | AI47: =SUM(AG47:AH47) -> 0
A48: Lodging for: XXX | B48: =B29 -> 0 | C48: 0 | D48: 0 | E48: /day | F48: =D48*C48*B48 -> 0 | G48: 0 | H48: =SUM(F48:G48) -> 0 | I48: 0 | J48: =C48*$B$6 -> 0 | K48: 0 | L48: =I48*J48*K48 -> 0 | M48: 0 | N48: =SUM(L48:M48) -> 0 | O48: =O29 -> 0 | P48: =C48*$B$6*$B$6 -> 0 | Q48: 0 | R48: =O48*P48*Q48 -> 0 | S48: 0 | T48: =SUM(R48:S48) -> 0 | U48: =U29 -> 0 | V48: =C48*$B$6*$B$6*$B$6 -> 0 | W48: 0 | X48: =U48*V48*W48 -> 0 | Y48: 0 | Z48: =SUM(X48:Y48) -> 0 | AA48: =AA29 -> 0 | AB48: =C48*$B$6*$B$6*$B$6*$B$6 -> 0 | AC48: 0 | AD48: =AA48*AB48*AC48 -> 0 | AE48: 0 | AF48: =SUM(AD48:AE48) -> 0 | AG48: =F48+L48+R48+X48+AD48 -> 0 | AH48: =G48+M48+S48+Y48+AE48 -> 0 | AI48: =SUM(AG48:AH48) -> 0
A49: Ground Transportation for: XXX | B49: =B30 -> 0 | C49: 0 | D49: 0 | E49: /trip | F49: =D49*C49*B49 -> 0 | G49: 0 | H49: =SUM(F49:G49) -> 0 | I49: 0 | J49: =C49*$B$6 -> 0 | K49: 0 | L49: =I49*J49*K49 -> 0 | M49: 0 | N49: =SUM(L49:M49) -> 0 | O49: 0 | P49: =C49*$B$6*$B$6 -> 0 | Q49: 0 | R49: =O49*P49*Q49 -> 0 | S49: 0 | T49: =SUM(R49:S49) -> 0 | U49: =U30 -> 0 | V49: =C49*$B$6*$B$6*$B$6 -> 0 | W49: 0 | X49: =U49*V49*W49 -> 0 | Y49: 0 | Z49: =SUM(X49:Y49) -> 0 | AA49: =AA30 -> 0 | AB49: =C49*$B$6*$B$6*$B$6*$B$6 -> 0 | AC49: 0 | AD49: =AA49*AB49*AC49 -> 0 | AE49: 0 | AF49: =SUM(AD49:AE49) -> 0 | AG49: =F49+L49+R49+X49+AD49 -> 0 | AH49: =G49+M49+S49+Y49+AE49 -> 0 | AI49: =SUM(AG49:AH49) -> 0
A50: Misc. Staff Travel Related Expenses for: XXX | B50: =B30 -> 0 | C50: 0 | D50: 0 | E50: /trip | F50: =D50*C50*B50 -> 0 | G50: 0 | H50: =SUM(F50:G50) -> 0 | I50: 0 | J50: =C50*$B$6 -> 0 | K50: 0 | L50: =I50*J50*K50 -> 0 | M50: 0 | N50: =SUM(L50:M50) -> 0 | O50: 0 | P50: =C50*$B$6*$B$6 -> 0 | Q50: 0 | R50: =O50*P50*Q50 -> 0 | S50: 0 | T50: =SUM(R50:S50) -> 0 | U50: =U30 -> 0 | V50: =C50*$B$6*$B$6*$B$6 -> 0 | W50: 0 | X50: =U50*V50*W50 -> 0 | Y50: 0 | Z50: =SUM(X50:Y50) -> 0 | AA50: =AA30 -> 0 | AB50: =C50*$B$6*$B$6*$B$6*$B$6 -> 0 | AC50: 0 | AD50: =AA50*AB50*AC50 -> 0 | AE50: 0 | AF50: =SUM(AD50:AE50) -> 0 | AG50: =F50+L50+R50+X50+AD50 -> 0 | AH50: =G50+M50+S50+Y50+AE50 -> 0 | AI50: =SUM(AG50:AH50) -> 0
...
